Workbook
Name __123Graph_A: [1]Base_série!#REF!
Name __123Graph_A: [1]Base_série!#REF!
Name __123Graph_A: [1]Base_série!#REF!
Name __123Graph_A: [1]Base_série!#REF!
Name __123Graph_A: [1]Base_série!#REF!
Name __123Graph_AFacture: [1]Base_série!#REF!
Name __123Graph_AFacture: [1]Base_série!#REF!
Name __123Graph_AFacture: [1]Base_série!#REF!
Name __123Graph_AFacture: [1]Base_série!#REF!
Name __123Graph_APrix: [1]Base_série!#REF!
Name __123Graph_APrix: [1]Base_série!#REF!
Name __123Graph_APrix_brut: [1]Base_série!#REF!
Name __123Graph_APrix_brut: [1]Base_série!#REF!
Name __123Graph_B: [1]Base_série!#REF!
Name __123Graph_B: [1]Base_série!#REF!
Name __123Graph_BFacture: [1]Base_série!#REF!
Name __123Graph_BFacture: [1]Base_série!#REF!
Name __123Graph_BPrix: [1]Base_série!#REF!
Name __123Graph_BPrix: [1]Base_série!#REF!
Name __123Graph_BPrix_brut: [1]Base_série!#REF!
Name __123Graph_BPrix_brut: [1]Base_série!#REF!
Name __123Graph_C: [1]Base_série!#REF!
Name __123Graph_C: [1]Base_série!#REF!
Name __123Graph_CFacture: [1]Base_série!#REF!
Name __123Graph_CFacture: [1]Base_série!#REF!
Name __123Graph_CPrix: [1]Base_série!#REF!
Name __123Graph_CPrix: [1]Base_série!#REF!
Name __123Graph_CPrix_brut: [1]Base_série!#REF!
Name __123Graph_CPrix_brut: [1]Base_série!#REF!
Name __123Graph_DFacture: [1]Base_série!#REF!
Name __123Graph_DFacture: [1]Base_série!#REF!
Name __123Graph_DPrix: [1]Base_série!#REF!
Name __123Graph_DPrix: [1]Base_série!#REF!
Name __123Graph_EFacture: [1]Base_série!#REF!
Name __123Graph_EFacture: [1]Base_série!#REF!
Name __123Graph_FFacture: [1]Base_série!#REF!
Name __123Graph_FFacture: [1]Base_série!#REF!
Name __123Graph_X: [1]Base_série!#REF!
Name __123Graph_X: [1]Base_série!#REF!
Name __123Graph_XFacture: [1]Base_série!#REF!
Name __123Graph_XFacture: [1]Base_série!#REF!
Name __123Graph_XPrix: [1]Base_série!#REF!
Name __123Graph_XPrix: [1]Base_série!#REF!
Name __123Graph_XPrix_brut: [1]Base_série!#REF!
Name __123Graph_XPrix_brut: [1]Base_série!#REF!
Name a: #REF!
Name a: #REF!
Name a: #REF!
Name Annees: #REF!
Name Branche_usage: #REF!
Name Branche_usage: #REF!
Name Branche_usage: #REF!
Name Brut_imp_qu: #REF!
Name Brut_imp_qu: #REF!
Name Brut_imp_qu: #REF!
Name CMS_imp_qu: #REF!
Name CMS_imp_qu: #REF!
Name CMS_imp_qu: #REF!
Name Code_série: #REF!
Name communes: #REF!

Sheet Cibles THREEME
B1: 2015 | C1: 2020 | D1: 2023 | E1: 2025 | F1: 2028 | G1: 2030 | H1: 2033 | I1: 2035 | J1: 2038 | K1: 2040 | L1: 2045 | M1: 2050 | R1: 2015 | S1: 2020 | T1: 2023 | U1: 2025 | V1: 2028 | W1: 2030 | X1: 2033 | Y1: 2035 | Z1: 2038 | AA1: 2040 | AB1: 2045 | AC1: 2050 | AF1: 2015 | AG1: 2020 | AH1: 2023 | AI1: 2025 | AJ1: 2028 | AK1: 2030 | AL1: 2033 | AM1: 2035 | AN1: 2038 | AO1: 2040 | AP1: 2045 | AQ1: 2050 | AT1: 2015 | AU1: 2020 | AV1: 2023 | AW1: 2025 | AX1: 2028 | AY1: 2030 | AZ1: 2033 | BA1: 2035 | BB1: 2038 | BC1: 2040 | BD1: 2045 | BE1: 2050
A2: Total | B2: =B3+B9+B28+B38 -> 255.89472 | C2: =C3+C9+C28+C38 -> 2559.78 | D2: =D3+D9+D28+D38 -> 2530.4302 | E2: =E3+E9+E28+E38 -> 2724.2957 | F2: =F3+F9+F28+F38 -> 2678.5123 | G2: =G3+G9+G28+G38 -> 2645.6935 | H2: =H3+H9+H28+H38 -> 2557.1578 | I2: =I3+I9+I28+I38 -> 2498.2261 | ... M2: =M3+M9+M28+M38 -> 2161.9321 | N2: =C2-'Bilan 2020'!$C$5 -> 0 | O2: =G2-'Bilan 2030'!$C$5 -> 0 | P2: =M2-'Bilan 2050'!$C$5 -> 0 | Q2: Total primaire, export et conso non énergétique incluses | R2: =R3+R7+R16+R23 -> 255.90472 | S2: =S3+S7+S16+S23 -> 2559.79 | T2: =T3+T7+T16+T23 -> 2530.4402 | U2: =U3+U7+U16+U23 -> 2724.3058 | V2: =V3+V7+V16+V23 -> 2678.5224 | W2: =W3+W7+W16+W23 -> 2645.7036 | X2: =X3+X7+X16+X23 -> 2557.1679 | Y2: =Y3+Y7+Y16+Y23 -> 2498.2362 | ... AC2: =AC3+AC7+AC16+AC23 -> 2161.9423 | AE2: Total final hors conso non énergétique | AF2: =AF3+AF8+AF18+AF27 -> 138.33585 | AG2: =AG3+AG8+AG18+AG27 -> 1463.325 | AH2: =AH3+AH8+AH18+AH27 -> 1494.1459 | AI2: =AI3+AI8+AI18+AI27 -> 1507.8024 | AJ2: =AJ3+AJ8+AJ18+AJ27 -> 1462.5806 | AK2: =AK3+AK8+AK18+AK27 -> 1432.475 | AL2: =AL3+AL8+AL18+AL27 -> 1409.9429 | AM2: =AM3+AM8+AM18+AM27 -> 1394.8737 | ... AQ2: =AQ3+AQ8+AQ18+AQ27 -> 1337.3206 | AS2: Total final conso non énergétique incluses | AT2: =AT3+AT8+AT18+AT27 -> 155.11476 | AU2: =AU3+AU8+AU18+AU27 -> 1633.6423 | AV2: =AV3+AV8+AV18+AV27 -> 1654.8166 | AW2: =AW3+AW8+AW18+AW27 -> 1689.5031 | AX2: =AX3+AX8+AX18+AX27 -> 1638.9269 | AY2: =AY3+AY8+AY18+AY27 -> 1605.2455 | AZ2: =AZ3+AZ8+AZ18+AZ27 -> 1579.5552 | BA2: =BA3+BA8+BA18+BA27 -> 1562.3714 | ... BE2: =BE3+BE8+BE18+BE27 -> 1492.0979 | BF2: =BE2-('Bilan 2050'!Q5+SUM('Bilan 2050'!E52:E57)) -> 1.7113099
A3: Produits pétroliers et biocarburants | B3: =SUM(B4:B5) -> 72.689475 | C3: =SUM(C4:C5) -> 711.27843 | D3: =SUM(D4:D5) -> 735.07689 | E3: =SUM(E4:E5) -> 733.06474 | F3: =SUM(F4:F5) -> 673.75374 | G3: =SUM(G4:G5) -> 634.13189 | H3: =SUM(H4:H5) -> 586.47864 | I3: =SUM(I4:I5) -> 554.66248 | ... M3: =SUM(M4:M5) -> 420.4664 | N3: =C3-'Bilan 2020'!$C$33-'Bilan 2020'!$C$41-'Bilan 2020'!$C$42-'Bilan 2020'!$C$43 -> 0 | O3: =G3-'Bilan 2030'!$C$33-'Bilan 2030'!$C$41-'Bilan 2030'!$C$42-'Bilan 2030'!$C$43 -> 0 | P3: =M3-'Bilan 2050'!$C$33-'Bilan 2050'!$C$41-'Bilan 2050'!$C$42-'Bilan 2050'!$C$43 -> 0 | Q3: Produits pétroliers et biocarburants | R3: =SUM(R4:R6) -> 72.689475 | S3: =SUM(S4:S6) -> 711.27843 | T3: =SUM(T4:T6) -> 735.07689 | U3: =SUM(U4:U6) -> 733.06474 | V3: =SUM(V4:V6) -> 673.75374 | W3: =SUM(W4:W6) -> 634.13189 | X3: =SUM(X4:X6) -> 586.47864 | Y3: =SUM(Y4:Y6) -> 554.66248 | ... AC3: =SUM(AC4:AC6) -> 420.4664 | AE3: Produits pétroliers et biocarburants | AF3: =SUM(AF4:AF7) -> 57.95773 | AG3: =SUM(AG4:AG7) -> 566.67043 | AH3: =SUM(AH4:AH7) -> 619.10865 | AI3: =SUM(AI4:AI7) -> 575.35059 | AJ3: =SUM(AJ4:AJ7) -> 520.45028 | AK3: =SUM(AK4:AK7) -> 483.77338 | AL3: =SUM(AL4:AL7) -> 440.38619 | AM3: =SUM(AM4:AM7) -> 411.42147 | ... AQ3: =SUM(AQ4:AQ7) -> 296.17625 | AS3: Produits pétroliers et biocarburants | AT3: =SUM(AT4:AT7) -> 70.41073 | AU3: =SUM(AU4:AU7) -> 697.15455 | AV3: =SUM(AV4:AV7) -> 732.20926 | AW3: =SUM(AW4:AW7) -> 702.60194 | AX3: =SUM(AX4:AX7) -> 643.65698 | AY3: =SUM(AY4:AY7) -> 604.27915 | AZ3: =SUM(AZ4:AZ7) -> 557.46349 | BA3: =SUM(BA4:BA7) -> 526.20573 | ... BE3: =SUM(BE4:BE7) -> 396.23141 | BF3: =BE3-(SUM('Bilan 2050'!G41:G43)-'Bilan 2050'!L41-'Bilan 2050'!I54-'Bilan 2050'!E56) -> 0 | BG3: Coefficient d'autoconsommation | BH3: 2020 | BI3: 2020 | BJ3: 2023 | BK3: 2025 | BL3: 2028 | BM3: 2030 | BN3: 2033 | BO3: 2035 | BP3: 2038 | BQ3: 2040 | BR3: 2045 | BS3: 2050 | BU3: Autoconsommation | BV3: 2015 | BW3: 2020 | BX3: 2023 | BY3: 2025 | BZ3: 2028 | CA3: 2030 | CB3: 2033 | CC3: 2035 | CD3: 2038 | CE3: 2040 | CF3: 2045 | CG3: 2050 | CJ3: coefficient de perte de reseaux et de distribution | CK3: 2015 | CL3: 2020 | CM3: 2023 | CN3: 2025 | CO3: 2028 | CP3: 2030 | CQ3: 2033 | CR3: 2035 | CS3: 2038 | CT3: 2040 | CU3: 2045 | CV3: 2050 | CY3: Pertes de reseaux et de distribution | CZ3: QMtep_losses_losses | DA3: 2015 | DB3: 2020 | DC3: 2023 | DD3: 2025 | DE3: 2028 | DF3: 2030 | DG3: 2033 | DH3: 2035 | DI3: 2038 | DJ3: 2040 | DK3: 2045 | DL3: 2050
A4: Produits pétroliers | B4: ='Bilan 2015'!$C$33+'Bilan 2015'!$C$42+'Bilan 2015'!$C$43 -> 69.569 | C4: ='Bilan 2020'!$C$33+'Bilan 2020'!$C$42+'Bilan 2020'!$C$43 -> 677.547 | D4: ='Bilan 2023 réel'!$C$33+'Bilan 2023 réel'!$C$42+'Bilan 2023 réel'!$C$43 -> 714.42945 | E4: ='Bilan 2025'!$C$33+'Bilan 2025'!$C$42+'Bilan 2025'!$C$43 -> 691.74732 | F4: ='Bilan 2028'!$C$33+'Bilan 2028'!$C$42+'Bilan 2028'!$C$43 -> 635.72622 | G4: ='Bilan 2030'!$C$33+'Bilan 2030'!$C$42+'Bilan 2030'!$C$43 -> 598.27946 | H4: ='Bilan 2033'!$C$33+'Bilan 2033'!$C$42+'Bilan 2033'!$C$43 -> 553.73432 | I4: ='Bilan 2035'!$C$33+'Bilan 2035'!$C$42+'Bilan 2035'!$C$43 -> 523.98391 | J4: ='Bilan 2038'!$C$33+'Bilan 2038'!$C$42+'Bilan 2038'!$C$43 -> 486.93215 | K4: ='Bilan 2040'!$C$33+'Bilan 2040'!$C$42+'Bilan 2040'!$C$43 -> 462.24944 | L4: ='Bilan 2045'!$C$33+'Bilan 2045'!$C$42+'Bilan 2045'!$C$43 -> 420.3522 | M4: ='Bilan 2050'!$C$33+'Bilan 2050'!$C$42+'Bilan 2050'!$C$43 -> 397.39751 | Q4: Produits pétroliers | R4: =B4 -> 69.569 | S4: =C4 -> 677.547 | T4: =D4 -> 714.42945 | U4: =E4 -> 691.74732 | V4: =F4 -> 635.72622 | W4: =G4 -> 598.27946 | X4: =H4 -> 553.73432 | Y4: =I4 -> 523.98391 | ... AC4: =M4 -> 397.39751 | AD4: =2201 -> 2201 | AE4: Produits pétroliers | AF4: ='Bilan 2015'!$G$42+'Bilan 2015'!$G$43-'Bilan 2015'!$E$54+'Bilan 2015'!$G$33*(1-SUM('Bilan 2015'!$K$26:$P$34)/'Bilan 2015'!$H$30)-AF6 -> 39.418884 | AG4: ='Bilan 2020'!$G$42+'Bilan 2020'!$G$43-'Bilan 2020'!$E$54+'Bilan 2020'!$G$33*(1-SUM('Bilan 2020'!$K$26:$P$34)/'Bilan 2020'!$H$30)-AG6 -> 384.22485 | AH4: ='Bilan 2023 réel'!$G$42+'Bilan 2023 réel'!$G$43-'Bilan 2023 réel'!$E$54+'Bilan 2023 réel'!$G$33*(1-SUM('Bilan 2023 réel'!$K$26:$P$34)/'Bilan 2023 réel'!$H$30)-AH6 -> 454.24007 | AI4: ='Bilan 2025'!$G$42+'Bilan 2025'!$G$43-'Bilan 2025'!$E$54+'Bilan 2025'!$G$33*(1-SUM('Bilan 2025'!$K$26:$P$34)/'Bilan 2025'!$H$30)-AI6 -> 408.63289 | AJ4: ='Bilan 2028'!$G$42+'Bilan 2028'!$G$43-'Bilan 2028'!$E$54+'Bilan 2028'!$G$33*(1-SUM('Bilan 2028'!$K$26:$P$34)/'Bilan 2028'!$H$30)-AJ6 -> 369.95523 | AK4: ='Bilan 2030'!$G$42+'Bilan 2030'!$G$43-'Bilan 2030'!$E$54+'Bilan 2030'!$G$33*(1-SUM('Bilan 2030'!$K$26:$P$34)/'Bilan 2030'!$H$30)-AK6 -> 344.17012 | AL4: ='Bilan 2033'!$G$42+'Bilan 2033'!$G$43-'Bilan 2033'!$E$54+'Bilan 2033'!$G$33*(1-SUM('Bilan 2033'!$K$26:$P$34)/'Bilan 2033'!$H$30)-AL6 -> 312.50053 | AM4: ='Bilan 2035'!$G$42+'Bilan 2035'!$G$43-'Bilan 2035'!$E$54+'Bilan 2035'!$G$33*(1-SUM('Bilan 2035'!$K$26:$P$34)/'Bilan 2035'!$H$30)-AM6 -> 291.38746 | AN4: ='Bilan 2038'!$G$42+'Bilan 2038'!$G$43-'Bilan 2038'!$E$54+'Bilan 2038'!$G$33*(1-SUM('Bilan 2038'!$K$26:$P$34)/'Bilan 2038'!$H$30)-AN6 -> 266.09529 | AO4: ='Bilan 2040'!$G$42+'Bilan 2040'!$G$43-'Bilan 2040'!$E$54+'Bilan 2040'!$G$33*(1-SUM('Bilan 2040'!$K$26:$P$34)/'Bilan 2040'!$H$30)-AO6 -> 249.23385 | AP4: ='Bilan 2045'!$G$42+'Bilan 2045'!$G$43-'Bilan 2045'!$E$54+'Bilan 2045'!$G$33*(1-SUM('Bilan 2045'!$K$26:$P$34)/'Bilan 2045'!$H$30)-AP6 -> 225.72325 | AQ4: ='Bilan 2050'!$G$42+'Bilan 2050'!$G$43-'Bilan 2050'!$E$54+'Bilan 2050'!$G$33*(1-SUM('Bilan 2050'!$K$26:$P$34)/'Bilan 2050'!$H$30)-AQ6 -> 216.87515 | AS4: Carburants pétroliers | AT4: ='Bilan 2015'!$G$42+'Bilan 2015'!$G$43-'Bilan 2015'!$E$54+'Bilan 2015'!$G$33*(1-SUM('Bilan 2015'!$K$26:$P$34)/'Bilan 2015'!$H$30)+'Bilan 2015'!$E$54-AT6 -> 51.871884 | AU4: ='Bilan 2020'!$G$42+'Bilan 2020'!$G$43-'Bilan 2020'!$E$54+'Bilan 2020'!$G$33*(1-SUM('Bilan 2020'!$K$26:$P$34)/'Bilan 2020'!$H$30)+'Bilan 2020'!$E$54-AU6 -> 514.70897 | AV4: ='Bilan 2023 réel'!$G$42+'Bilan 2023 réel'!$G$43-'Bilan 2023 réel'!$E$54+'Bilan 2023 réel'!$G$33*(1-SUM('Bilan 2023 réel'!$K$26:$P$34)/'Bilan 2023 réel'!$H$30)+'Bilan 2023 réel'!$E$54-AV6 -> 567.34069 | AW4: ='Bilan 2025'!$G$42+'Bilan 2025'!$G$43-'Bilan 2025'!$E$54+'Bilan 2025'!$G$33*(1-SUM('Bilan 2025'!$K$26:$P$34)/'Bilan 2025'!$H$30)+'Bilan 2025'!$E$54-AW6 -> 535.88425 | AX4: ='Bilan 2028'!$G$42+'Bilan 2028'!$G$43-'Bilan 2028'!$E$54+'Bilan 2028'!$G$33*(1-SUM('Bilan 2028'!$K$26:$P$34)/'Bilan 2028'!$H$30)+'Bilan 2028'!$E$54-AX6 -> 493.16193 | AY4: ='Bilan 2030'!$G$42+'Bilan 2030'!$G$43-'Bilan 2030'!$E$54+'Bilan 2030'!$G$33*(1-SUM('Bilan 2030'!$K$26:$P$34)/'Bilan 2030'!$H$30)+'Bilan 2030'!$E$54-AY6 -> 464.6759 | AZ4: ='Bilan 2033'!$G$42+'Bilan 2033'!$G$43-'Bilan 2033'!$E$54+'Bilan 2033'!$G$33*(1-SUM('Bilan 2033'!$K$26:$P$34)/'Bilan 2033'!$H$30)+'Bilan 2033'!$E$54-AZ6 -> 429.57783 | BA4: ='Bilan 2035'!$G$42+'Bilan 2035'!$G$43-'Bilan 2035'!$E$54+'Bilan 2035'!$G$33*(1-SUM('Bilan 2035'!$K$26:$P$34)/'Bilan 2035'!$H$30)+'Bilan 2035'!$E$54-BA6 -> 406.17172 | BB4: ='Bilan 2038'!$G$42+'Bilan 2038'!$G$43-'Bilan 2038'!$E$54+'Bilan 2038'!$G$33*(1-SUM('Bilan 2038'!$K$26:$P$34)/'Bilan 2038'!$H$30)+'Bilan 2038'!$E$54-BB6 -> 377.83249 | BC4: ='Bilan 2040'!$G$42+'Bilan 2040'!$G$43-'Bilan 2040'!$E$54+'Bilan 2040'!$G$33*(1-SUM('Bilan 2040'!$K$26:$P$34)/'Bilan 2040'!$H$30)+'Bilan 2040'!$E$54-BC6 -> 358.92693 | BD4: ='Bilan 2045'!$G$42+'Bilan 2045'!$G$43-'Bilan 2045'!$E$54+'Bilan 2045'!$G$33*(1-SUM('Bilan 2045'!$K$26:$P$34)/'Bilan 2045'!$H$30)+'Bilan 2045'!$E$54-BD6 -> 330.63328 | BE4: ='Bilan 2050'!$G$42+'Bilan 2050'!$G$43-'Bilan 2050'!$E$54+'Bilan 2050'!$G$33*(1-SUM('Bilan 2050'!$K$26:$P$34)/'Bilan 2050'!$H$30)+'Bilan 2050'!$E$54-BE6 -> 316.93031 | BG4: Carburants pétroliers | BH4: =IF(AT4>0,BV4/AT4,0) -> 0.043279708 | BI4: =IF(AU4>0,BW4/AU4,0) -> 0.027361945 | BJ4: =IF(AV4>0,BX4/AV4,0) -> 0.039926619 | BK4: =IF(AW4>0,BY4/AW4,0) -> 0.059527953 | BL4: =IF(AX4>0,BZ4/AX4,0) -> 0.063327687 | BM4: =IF(AY4>0,CA4/AY4,0) -> 0.066249643 | BN4: =IF(AZ4>0,CB4/AZ4,0) -> 0.070104467 | BO4: =IF(BA4>0,CC4/BA4,0) -> 0.073045788 | ... BS4: =IF(BE4>0,CG4/BE4,0) -> 0.083055152 | BU4: Carburants pétroliers | BV4: ='Bilan 2015'!$E$42 -> 2.245 | BW4: ='Bilan 2020'!$E$42 -> 14.083438 | BX4: ='Bilan 2023 réel'!$E$42 -> 22.651995 | BY4: ='Bilan 2025'!$E$42 -> 31.900092 | BZ4: ='Bilan 2028'!$E$42 -> 31.230804 | CA4: ='Bilan 2030'!$E$42 -> 30.784613 | CB4: ='Bilan 2033'!$E$42 -> 30.115325 | CC4: ='Bilan 2035'!$E$42 -> 29.669133 | CD4: ='Bilan 2038'!$E$42 -> 28.999846 | CE4: ='Bilan 2040'!$E$42 -> 28.553654 | CF4: ='Bilan 2045'!$E$42 -> 27.438174 | CG4: ='Bilan 2050'!$E$42 -> 26.322695 | CJ4: Carburants pétroliers | CK4: =IF(AT4>0,DA4/AT4,0) -> 0 | CL4: =IF(AU4>0,DB4/AU4,0) -> 0 | CM4: =IF(AV4>0,DC4/AV4,0) -> 0 | CN4: =IF(AW4>0,DD4/AW4,0) -> 0 | CO4: =IF(AX4>0,DE4/AX4,0) -> 0 | CP4: =IF(AY4>0,DF4/AY4,0) -> 0 | CQ4: =IF(AZ4>0,DG4/AZ4,0) -> 0 | CR4: =IF(BA4>0,DH4/BA4,0) -> 0 | ... CV4: =IF(BE4>0,DL4/BE4,0) -> 0 | CX4: =2201 -> 2201 | CY4: Carburants pétroliers | CZ4: QMtep_losses_2201 | DA4: 0 | DB4: =DA4 -> 0 | DC4: =DB4 -> 0 | DD4: =DC4 -> 0 | DE4: =DD4 -> 0 | DF4: =DE4 -> 0 | DG4: =DF4 -> 0 | DH4: =DG4 -> 0 | DI4: =DH4 -> 0 | ... DL4: =DK4 -> 0
A5: Biocarburants liquides et gazeux | B5: ='Bilan 2015'!$C$41 -> 3.1204748 | C5: ='Bilan 2020'!$C$41 -> 33.73143 | D5: ='Bilan 2023 réel'!$C$41 -> 20.647434 | E5: ='Bilan 2025'!$C$41 -> 41.317421 | F5: ='Bilan 2028'!$C$41 -> 38.027521 | G5: ='Bilan 2030'!$C$41 -> 35.852434 | H5: ='Bilan 2033'!$C$41 -> 32.744325 | I5: ='Bilan 2035'!$C$41 -> 30.678568 | J5: ='Bilan 2038'!$C$41 -> 28.189429 | K5: ='Bilan 2040'!$C$41 -> 26.520712 | L5: ='Bilan 2045'!$C$41 -> 24.110477 | M5: ='Bilan 2050'!$C$41 -> 23.068884 | Q5: Biocarburants liquides et gazeux | R5: =B5 -> 3.1204748 | S5: =C5 -> 33.73143 | T5: =D5 -> 20.647434 | U5: =E5 -> 41.317421 | V5: =F5 -> 38.027521 | W5: =G5 -> 35.852434 | X5: =H5 -> 32.744325 | Y5: =I5 -> 30.678568 | ... AC5: =M5 -> 23.068884 | AD5: =AD4+1 -> 2202 | AE5: Biocarburants liquides et gazeux | AF5: ='Bilan 2015'!$G$41-'Bilan 2015'!$E$56-'Bilan 2015'!$L$41-AF7 -> 2.9416968 | AG5: ='Bilan 2020'!$G$41-'Bilan 2020'!$E$56-'Bilan 2020'!$L$41-AG7 -> 30.751352 | AH5: ='Bilan 2023 réel'!$G$41-'Bilan 2023 réel'!$E$56-'Bilan 2023 réel'!$L$41-AH7 -> 37.852872 | AI5: ='Bilan 2025'!$G$41-'Bilan 2025'!$E$56-'Bilan 2025'!$L$41-AI7 -> 39.661036 | AJ5: ='Bilan 2028'!$G$41-'Bilan 2028'!$E$56-'Bilan 2028'!$L$41-AJ7 -> 35.944972 | AK5: ='Bilan 2030'!$G$41-'Bilan 2030'!$E$56-'Bilan 2030'!$L$41-AK7 -> 33.467596 | AL5: ='Bilan 2033'!$G$41-'Bilan 2033'!$E$56-'Bilan 2033'!$L$41-AL7 -> 30.354491 | AM5: ='Bilan 2035'!$G$41-'Bilan 2035'!$E$56-'Bilan 2035'!$L$41-AM7 -> 28.279088 | AN5: ='Bilan 2038'!$G$41-'Bilan 2038'!$E$56-'Bilan 2038'!$L$41-AN7 -> 25.786282 | AO5: ='Bilan 2040'!$G$41-'Bilan 2040'!$E$56-'Bilan 2040'!$L$41-AO7 -> 24.124412 | AP5: ='Bilan 2045'!$G$41-'Bilan 2045'!$E$56-'Bilan 2045'!$L$41-AP7 -> 21.777537 | AQ5: ='Bilan 2050'!$G$41-'Bilan 2050'!$E$56-'Bilan 2050'!$L$41-AQ7 -> 20.88662 | AS5: Biocarburants liquides et gazeux | AT5: ='Bilan 2015'!$G$41-'Bilan 2015'!$E$56-'Bilan 2015'!$L$41+'Bilan 2015'!$E$56-AT7 -> 2.9416968 | AU5: ='Bilan 2020'!$G$41-'Bilan 2020'!$E$56-'Bilan 2020'!$L$41+'Bilan 2020'!$E$56-AU7 -> 30.751352 | AV5: ='Bilan 2023 réel'!$G$41-'Bilan 2023 réel'!$E$56-'Bilan 2023 réel'!$L$41+'Bilan 2023 réel'!$E$56-AV7 -> 37.852872 | AW5: ='Bilan 2025'!$G$41-'Bilan 2025'!$E$56-'Bilan 2025'!$L$41+'Bilan 2025'!$E$56-AW7 -> 39.661036 | AX5: ='Bilan 2028'!$G$41-'Bilan 2028'!$E$56-'Bilan 2028'!$L$41+'Bilan 2028'!$E$56-AX7 -> 35.944972 | AY5: ='Bilan 2030'!$G$41-'Bilan 2030'!$E$56-'Bilan 2030'!$L$41+'Bilan 2030'!$E$56-AY7 -> 33.467596 | AZ5: ='Bilan 2033'!$G$41-'Bilan 2033'!$E$56-'Bilan 2033'!$L$41+'Bilan 2033'!$E$56-AZ7 -> 30.354491 | BA5: ='Bilan 2035'!$G$41-'Bilan 2035'!$E$56-'Bilan 2035'!$L$41+'Bilan 2035'!$E$56-BA7 -> 28.279088 | BB5: ='Bilan 2038'!$G$41-'Bilan 2038'!$E$56-'Bilan 2038'!$L$41+'Bilan 2038'!$E$56-BB7 -> 25.786282 | BC5: ='Bilan 2040'!$G$41-'Bilan 2040'!$E$56-'Bilan 2040'!$L$41+'Bilan 2040'!$E$56-BC7 -> 24.124412 | BD5: ='Bilan 2045'!$G$41-'Bilan 2045'!$E$56-'Bilan 2045'!$L$41+'Bilan 2045'!$E$56-BD7 -> 21.777537 | BE5: ='Bilan 2050'!$G$41-'Bilan 2050'!$E$56-'Bilan 2050'!$L$41+'Bilan 2050'!$E$56-BE7 -> 20.88662 | BG5: Biocarburants liquides et gazeux | BH5: =IF(AT5>0,BV5/AT5,0) -> 0 | BI5: =IF(AU5>0,BW5/AU5,0) -> 0 | BJ5: =IF(AV5>0,BX5/AV5,0) -> 0 | BK5: =IF(AW5>0,BY5/AW5,0) -> 0 | BL5: =IF(AX5>0,BZ5/AX5,0) -> 0 | BM5: =IF(AY5>0,CA5/AY5,0) -> 0 | BN5: =IF(AZ5>0,CB5/AZ5,0) -> 0 | BO5: =IF(BA5>0,CC5/BA5,0) -> 0 | ... BS5: =IF(BE5>0,CG5/BE5,0) -> 0 | BU5: Biocarburants liquides et gazeux | BV5: ='Bilan 2015'!$E$41*'Bilan 2015'!$X$41/SUM('Bilan 2015'!$T$41:$X$41) -> 0 | BW5: ='Bilan 2020'!$E$41*'Bilan 2020'!$X$41/SUM('Bilan 2020'!$T$41:$X$41) -> 0 | BX5: ='Bilan 2023 réel'!$E$41*'Bilan 2023 réel'!$X$41/SUM('Bilan 2023 réel'!$T$41:$X$41) -> 0 | BY5: ='Bilan 2025'!$E$41*'Bilan 2025'!$X$41/SUM('Bilan 2025'!$T$41:$X$41) -> 0 | BZ5: ='Bilan 2028'!$E$41*'Bilan 2028'!$X$41/SUM('Bilan 2028'!$T$41:$X$41) -> 0 | CA5: ='Bilan 2030'!$E$41*'Bilan 2030'!$X$41/SUM('Bilan 2030'!$T$41:$X$41) -> 0 | CB5: ='Bilan 2033'!$E$41*'Bilan 2033'!$X$41/SUM('Bilan 2033'!$T$41:$X$41) -> 0 | CC5: ='Bilan 2035'!$E$41*'Bilan 2035'!$X$41/SUM('Bilan 2035'!$T$41:$X$41) -> 0 | CD5: ='Bilan 2038'!$E$41*'Bilan 2038'!$X$41/SUM('Bilan 2038'!$T$41:$X$41) -> 0 | CE5: ='Bilan 2040'!$E$41*'Bilan 2040'!$X$41/SUM('Bilan 2040'!$T$41:$X$41) -> 0 | CF5: ='Bilan 2045'!$E$41*'Bilan 2045'!$X$41/SUM('Bilan 2045'!$T$41:$X$41) -> 0 | CG5: ='Bilan 2050'!$E$41*'Bilan 2050'!$X$41/SUM('Bilan 2050'!$T$41:$X$41) -> 0 | CJ5: Biocarburants liquides et gazeux | CK5: =IF(AT5>0,DA5/AT5,0) -> 0 | CL5: =IF(AU5>0,DB5/AU5,0) -> 0 | CM5: =IF(AV5>0,DC5/AV5,0) -> 0 | CN5: =IF(AW5>0,DD5/AW5,0) -> 0 | CO5: =IF(AX5>0,DE5/AX5,0) -> 0 | CP5: =IF(AY5>0,DF5/AY5,0) -> 0 | CQ5: =IF(AZ5>0,DG5/AZ5,0) -> 0 | CR5: =IF(BA5>0,DH5/BA5,0) -> 0 | ... CV5: =IF(BE5>0,DL5/BE5,0) -> 0 | CX5: =CX4+1 -> 2202 | CY5: Biocarburants liquides et gazeux | CZ5: QMtep_losses_2202 | DA5: 0 | DB5: =DA5 -> 0 | DC5: =DB5 -> 0 | DD5: =DC5 -> 0 | DE5: =DD5 -> 0 | DF5: =DE5 -> 0 | DG5: =DF5 -> 0 | DH5: =DG5 -> 0 | DI5: =DH5 -> 0 | ... DL5: =DK5 -> 0
A6: Biocarburants liquides | AE6: Fioul chaleur fossile | AF6: =SUM('Bilan 2015'!$T$43:$W$43) -> 15.418371 | AG6: =SUM('Bilan 2020'!$T$43:$W$43) -> 148.71415 | AH6: =SUM('Bilan 2023 réel'!$T$43:$W$43) -> 124.01531 | AI6: =SUM('Bilan 2025'!$T$43:$W$43) -> 123.96298 | AJ6: =SUM('Bilan 2028'!$T$43:$W$43) -> 111.33348 | AK6: =SUM('Bilan 2030'!$T$43:$W$43) -> 102.81895 | AL6: =SUM('Bilan 2033'!$T$43:$W$43) -> 94.04116 | AM6: =SUM('Bilan 2035'!$T$43:$W$43) -> 88.143061 | AN6: =SUM('Bilan 2038'!$T$43:$W$43) -> 80.099813 | AO6: =SUM('Bilan 2040'!$T$43:$W$43) -> 74.768857 | AP6: =SUM('Bilan 2045'!$T$43:$W$43) -> 62.280747 | AQ6: =SUM('Bilan 2050'!$T$43:$W$43) -> 54.144514 | AS6: Fioul chaleur fossile | AT6: =SUM('Bilan 2015'!$T$43:$W$43) -> 15.418371 | AU6: =SUM('Bilan 2020'!$T$43:$W$43) -> 148.71415 | AV6: =SUM('Bilan 2023 réel'!$T$43:$W$43) -> 124.01531 | AW6: =SUM('Bilan 2025'!$T$43:$W$43) -> 123.96298 | AX6: =SUM('Bilan 2028'!$T$43:$W$43) -> 111.33348 | AY6: =SUM('Bilan 2030'!$T$43:$W$43) -> 102.81895 | AZ6: =SUM('Bilan 2033'!$T$43:$W$43) -> 94.04116 | BA6: =SUM('Bilan 2035'!$T$43:$W$43) -> 88.143061 | BB6: =SUM('Bilan 2038'!$T$43:$W$43) -> 80.099813 | BC6: =SUM('Bilan 2040'!$T$43:$W$43) -> 74.768857 | BD6: =SUM('Bilan 2045'!$T$43:$W$43) -> 62.280747 | BE6: =SUM('Bilan 2050'!$T$43:$W$43) -> 54.144514 | BG6: Fioul chaleur fossile | BH6: =IF(AT6>0,BV6/AT6,0) -> 0.0010274938 | BI6: =IF(AU6>0,BW6/AU6,0) -> 0.00016652658 | BJ6: =IF(AV6>0,BX6/AV6,0) -> 0.0019222205 | BK6: =IF(AW6>0,BY6/AW6,0) -> 0 | BL6: =IF(AX6>0,BZ6/AX6,0) -> 0 | BM6: =IF(AY6>0,CA6/AY6,0) -> 0 | BN6: =IF(AZ6>0,CB6/AZ6,0) -> 0 | BO6: =IF(BA6>0,CC6/BA6,0) -> 0 | ... BS6: =IF(BE6>0,CG6/BE6,0) -> 0 | BU6: Fioul chaleur fossile | BV6: ='Bilan 2015'!$E$43+'Bilan 2015'!$E$33 -> 0.015842281 | BW6: ='Bilan 2020'!$E$43+'Bilan 2020'!$E$33 -> 0.024764858 | BX6: ='Bilan 2023 réel'!$E$43+'Bilan 2023 réel'!$E$33 -> 0.23838477 | BY6: ='Bilan 2025'!$E$43+'Bilan 2025'!$E$33 -> 0 | BZ6: ='Bilan 2028'!$E$43+'Bilan 2028'!$E$33 -> 0 | CA6: ='Bilan 2030'!$E$43+'Bilan 2030'!$E$33 -> 0 | CB6: ='Bilan 2033'!$E$43+'Bilan 2033'!$E$33 -> 0 | CC6: ='Bilan 2035'!$E$43+'Bilan 2035'!$E$33 -> 0 | CD6: ='Bilan 2038'!$E$43+'Bilan 2038'!$E$33 -> 0 | CE6: ='Bilan 2040'!$E$43+'Bilan 2040'!$E$33 -> 0 | CF6: ='Bilan 2045'!$E$43+'Bilan 2045'!$E$33 -> 0 | CG6: ='Bilan 2050'!$E$43+'Bilan 2050'!$E$33 -> 0 | CJ6: Fioul chaleur fossile | CK6: =IF(AT6>0,DA6/AT6,0) -> 0.0007769186 | CL6: =IF(AU6>0,DB6/AU6,0) -> 0.00010543234 | CM6: =IF(AV6>0,DC6/AV6,0) -> 0.0014762614 | CN6: =IF(AW6>0,DD6/AW6,0) -> 0 | CO6: =IF(AX6>0,DE6/AX6,0) -> 0 | CP6: =IF(AY6>0,DF6/AY6,0) -> 0 | CQ6: =IF(AZ6>0,DG6/AZ6,0) -> 0 | CR6: =IF(BA6>0,DH6/BA6,0) -> 0 | ... CV6: =IF(BE6>0,DL6/BE6,0) -> 0 | CY6: Fioul chaleur fossile | DA6: ='Bilan 2015'!$K$30*'Bilan 2015'!$G$33/'Bilan 2015'!$H$30 -> 0.011978819 | DB6: ='Bilan 2020'!$K$30*'Bilan 2020'!$G$33/'Bilan 2020'!$H$30 -> 0.015679281 | DC6: ='Bilan 2023 réel'!$K$30*'Bilan 2023 réel'!$G$33/'Bilan 2023 réel'!$H$30 -> 0.18307901 | DD6: ='Bilan 2025'!$K$30*'Bilan 2025'!$G$33/'Bilan 2025'!$H$30 -> 0 | DE6: ='Bilan 2028'!$K$30*'Bilan 2028'!$G$33/'Bilan 2028'!$H$30 -> 0 | DF6: ='Bilan 2030'!$K$30*'Bilan 2030'!$G$33/'Bilan 2030'!$H$30 -> 0 | DG6: ='Bilan 2033'!$K$30*'Bilan 2033'!$G$33/'Bilan 2033'!$H$30 -> 0 | DH6: ='Bilan 2035'!$K$30*'Bilan 2035'!$G$33/'Bilan 2035'!$H$30 -> 0 | DI6: ='Bilan 2038'!$K$30*'Bilan 2038'!$G$33/'Bilan 2038'!$H$30 -> 0 | DJ6: ='Bilan 2040'!$K$30*'Bilan 2040'!$G$33/'Bilan 2040'!$H$30 -> 0 | DK6: ='Bilan 2045'!$K$30*'Bilan 2045'!$G$33/'Bilan 2045'!$H$30 -> 0 | DL6: ='Bilan 2050'!$K$30*'Bilan 2050'!$G$33/'Bilan 2050'!$H$30 -> 0
A7: Biocarburants gazeux | Q7: Electricité | R7: =SUM(R8:R15) -> 132.33104 | S7: =SUM(S8:S15) -> 1284.6691 | T7: =SUM(T8:T15) -> 1256.7448 | U7: =SUM(U8:U15) -> 1420.9156 | V7: =SUM(V8:V15) -> 1438.1293 | W7: =SUM(W8:W15) -> 1446.9192 | X7: =SUM(X8:X15) -> 1401.3128 | Y7: =SUM(Y8:Y15) -> 1370.9712 | ... AC7: =SUM(AC8:AC15) -> 1168.9599 | AE7: Biofuel chaleur renouvelable | AF7: =SUM('Bilan 2015'!$T$41:$W$41) -> 0.17877806 | AG7: =SUM('Bilan 2020'!$T$41:$W$41) -> 2.9800775 | AH7: =SUM('Bilan 2023 réel'!$T$41:$W$41) -> 3.0003986 | AI7: =SUM('Bilan 2025'!$T$41:$W$41) -> 3.0936817 | AJ7: =SUM('Bilan 2028'!$T$41:$W$41) -> 3.2165908 | AK7: =SUM('Bilan 2030'!$T$41:$W$41) -> 3.31671 | AL7: =SUM('Bilan 2033'!$T$41:$W$41) -> 3.4900106 | AM7: =SUM('Bilan 2035'!$T$41:$W$41) -> 3.6118596 | AN7: =SUM('Bilan 2038'!$T$41:$W$41) -> 3.800258 | AO7: =SUM('Bilan 2040'!$T$41:$W$41) -> 3.916566 | AP7: =SUM('Bilan 2045'!$T$41:$W$41) -> 4.1544557 | AQ7: =SUM('Bilan 2050'!$T$41:$W$41) -> 4.2699665 | AS7: Biofuel chaleur renouvelable | AT7: =SUM('Bilan 2015'!$T$41:$W$41) -> 0.17877806 | AU7: =SUM('Bilan 2020'!$T$41:$W$41) -> 2.9800775 | AV7: =SUM('Bilan 2023 réel'!$T$41:$W$41) -> 3.0003986 | AW7: =SUM('Bilan 2025'!$T$41:$W$41) -> 3.0936817 | AX7: =SUM('Bilan 2028'!$T$41:$W$41) -> 3.2165908 | AY7: =SUM('Bilan 2030'!$T$41:$W$41) -> 3.31671 | AZ7: =SUM('Bilan 2033'!$T$41:$W$41) -> 3.4900106 | BA7: =SUM('Bilan 2035'!$T$41:$W$41) -> 3.6118596 | BB7: =SUM('Bilan 2038'!$T$41:$W$41) -> 3.800258 | BC7: =SUM('Bilan 2040'!$T$41:$W$41) -> 3.916566 | BD7: =SUM('Bilan 2045'!$T$41:$W$41) -> 4.1544557 | BE7: =SUM('Bilan 2050'!$T$41:$W$41) -> 4.2699665 | BG7: Biofuel chaleur renouvelable | BH7: =IF(AT7>0,BV7/AT7,0) -> 0 | BI7: =IF(AU7>0,BW7/AU7,0) -> 0 | BJ7: =IF(AV7>0,BX7/AV7,0) -> 0 | BK7: =IF(AW7>0,BY7/AW7,0) -> 0 | BL7: =IF(AX7>0,BZ7/AX7,0) -> 0 | BM7: =IF(AY7>0,CA7/AY7,0) -> 0 | BN7: =IF(AZ7>0,CB7/AZ7,0) -> 0 | BO7: =IF(BA7>0,CC7/BA7,0) -> 0 | ... BS7: =IF(BE7>0,CG7/BE7,0) -> 0 | BU7: Biofuel chaleur renouvelable | BV7: ='Bilan 2015'!$E$41*SUM('Bilan 2015'!$T$41:$W$41)/SUM('Bilan 2015'!$T$41:$X$41) -> 0 | BW7: ='Bilan 2020'!$E$41*SUM('Bilan 2020'!$T$41:$W$41)/SUM('Bilan 2020'!$T$41:$X$41) -> 0 | BX7: ='Bilan 2023 réel'!$E$41*SUM('Bilan 2023 réel'!$T$41:$W$41)/SUM('Bilan 2023 réel'!$T$41:$X$41) -> 0 | BY7: ='Bilan 2025'!$E$41*SUM('Bilan 2025'!$T$41:$W$41)/SUM('Bilan 2025'!$T$41:$X$41) -> 0 | BZ7: ='Bilan 2028'!$E$41*SUM('Bilan 2028'!$T$41:$W$41)/SUM('Bilan 2028'!$T$41:$X$41) -> 0 | CA7: ='Bilan 2030'!$E$41*SUM('Bilan 2030'!$T$41:$W$41)/SUM('Bilan 2030'!$T$41:$X$41) -> 0 | CB7: ='Bilan 2033'!$E$41*SUM('Bilan 2033'!$T$41:$W$41)/SUM('Bilan 2033'!$T$41:$X$41) -> 0 | CC7: ='Bilan 2035'!$E$41*SUM('Bilan 2035'!$T$41:$W$41)/SUM('Bilan 2035'!$T$41:$X$41) -> 0 | CD7: ='Bilan 2038'!$E$41*SUM('Bilan 2038'!$T$41:$W$41)/SUM('Bilan 2038'!$T$41:$X$41) -> 0 | CE7: ='Bilan 2040'!$E$41*SUM('Bilan 2040'!$T$41:$W$41)/SUM('Bilan 2040'!$T$41:$X$41) -> 0 | CF7: ='Bilan 2045'!$E$41*SUM('Bilan 2045'!$T$41:$W$41)/SUM('Bilan 2045'!$T$41:$X$41) -> 0 | CG7: ='Bilan 2050'!$E$41*SUM('Bilan 2050'!$T$41:$W$41)/SUM('Bilan 2050'!$T$41:$X$41) -> 0 | CJ7: Biofuel chaleur renouvelable | CK7: =IF(AT7>0,DA7/AT7,0) -> 0 | CL7: =IF(AU7>0,DB7/AU7,0) -> 0 | CM7: =IF(AV7>0,DC7/AV7,0) -> 0 | CN7: =IF(AW7>0,DD7/AW7,0) -> 0 | CO7: =IF(AX7>0,DE7/AX7,0) -> 0 | CP7: =IF(AY7>0,DF7/AY7,0) -> 0 | CQ7: =IF(AZ7>0,DG7/AZ7,0) -> 0 | CR7: =IF(BA7>0,DH7/BA7,0) -> 0 | ... CV7: =IF(BE7>0,DL7/BE7,0) -> 0 | CY7: Biofuel chaleur renouvelable | DA7: 0 | DB7: 0 | DC7: =DB7 -> 0 | DD7: =DC7 -> 0 | DE7: =DD7 -> 0 | DF7: =DE7 -> 0 | DG7: =DF7 -> 0 | DH7: =DG7 -> 0 | DI7: =DH7 -> 0 | DJ7: =DI7 -> 0 | ... DL7: =DK7 -> 0
A8: GNV | Q8: Nucléaire | R8: =B10 -> 114.07243 | S8: =C10 -> 1068.7282 | T8: =D10 -> 1024.8554 | U8: =E10 -> 1190.9091 | V8: =F10 -> 1190.8538 | W8: =G10 -> 1190.8368 | X8: =H10 -> 1121.1895 | Y8: =I10 -> 1074.7551 | ... AC8: =M10 -> 726.54022 | AD8: 2301 | AE8: Electricité | AF8: =SUM(AF9:AF17) -> 38.082514 | AG8: =SUM(AG9:AG17) -> 404.64507 | AH8: =SUM(AH9:AH17) -> 400.85872 | AI8: =SUM(AI9:AI17) -> 436.18192 | AJ8: =SUM(AJ9:AJ17) -> 447.36659 | AK8: =SUM(AK9:AK17) -> 454.71078 | AL8: =SUM(AL9:AL17) -> 471.00003 | AM8: =SUM(AM9:AM17) -> 481.7813 | ... AQ8: =SUM(AQ9:AQ17) -> 541.9072 | AS8: Electricité | AT8: =SUM(AT9:AT17) -> 38.082514 | AU8: =SUM(AU9:AU17) -> 404.64507 | AV8: =SUM(AV9:AV17) -> 400.85872 | AW8: =SUM(AW9:AW17) -> 436.18192 | AX8: =SUM(AX9:AX17) -> 447.36659 | AY8: =SUM(AY9:AY17) -> 454.71078 | AZ8: =SUM(AZ9:AZ17) -> 471.00003 | BA8: =SUM(BA9:BA17) -> 481.7813 | ... BE8: =SUM(BE9:BE17) -> 541.9072 | BG8: Nucléaire | BH8: =IF(AT9>0,BV8/AT9,0) -> 2.6091413 | BI8: =IF(AU9>0,BW8/AU9,0) -> 2.6076964 | BJ8: =IF(AV9>0,BX8/AV9,0) -> 2.6162289 | BK8: =IF(AW9>0,BY8/AW9,0) -> 2.741711 | BL8: =IF(AX9>0,BZ8/AX9,0) -> 2.7766517 | BM8: =IF(AY9>0,CA8/AY9,0) -> 2.7869633 | BN8: =IF(AZ9>0,CB8/AZ9,0) -> 2.6983136 | BO8: =IF(BA9>0,CC8/BA9,0) -> 2.6431355 | ... BS8: =IF(BE9>0,CG8/BE9,0) -> 2.4852161 | BU8: Nucléaire | BV8: ='Bilan 2015'!$E10+'Bilan 2015'!$I$13*'Bilan 2015'!$G$10/'Bilan 2015'!$H$13 -> 77.10988 | BW8: ='Bilan 2020'!$E10+'Bilan 2020'!$I$13*'Bilan 2020'!$G$10/'Bilan 2020'!$H$13 -> 732.38827 | BX8: ='Bilan 2023 réel'!$E10+'Bilan 2023 réel'!$I$13*'Bilan 2023 réel'!$G$10/'Bilan 2023 réel'!$H$13 -> 700.09324 | BY8: ='Bilan 2025'!$E10+'Bilan 2025'!$I$13*'Bilan 2025'!$G$10/'Bilan 2025'!$H$13 -> 820.69122 | BZ8: ='Bilan 2028'!$E10+'Bilan 2028'!$I$13*'Bilan 2028'!$G$10/'Bilan 2028'!$H$13 -> 821.26987 | CA8: ='Bilan 2030'!$E10+'Bilan 2030'!$I$13*'Bilan 2030'!$G$10/'Bilan 2030'!$H$13 -> 821.77976 | CB8: ='Bilan 2033'!$E10+'Bilan 2033'!$I$13*'Bilan 2033'!$G$10/'Bilan 2033'!$H$13 -> 772.82879 | CC8: ='Bilan 2035'!$E10+'Bilan 2035'!$I$13*'Bilan 2035'!$G$10/'Bilan 2035'!$H$13 -> 740.27947 | CD8: ='Bilan 2038'!$E10+'Bilan 2038'!$I$13*'Bilan 2038'!$G$10/'Bilan 2038'!$H$13 -> 693.52996 | CE8: ='Bilan 2040'!$E10+'Bilan 2040'!$I$13*'Bilan 2040'!$G$10/'Bilan 2040'!$H$13 -> 662.45518 | CF8: ='Bilan 2045'!$E10+'Bilan 2045'!$I$13*'Bilan 2045'!$G$10/'Bilan 2045'!$H$13 -> 581.9005 | CG8: ='Bilan 2050'!$E10+'Bilan 2050'!$I$13*'Bilan 2050'!$G$10/'Bilan 2050'!$H$13 -> 502.34541 | CJ8: Nucléaire | CK8: =IF(AT9>0,DA8/AT9,0) -> 0.07992104 | CL8: =IF(AU9>0,DB8/AU9,0) -> 0.087045 | CM8: =IF(AV9>0,DC8/AV9,0) -> 0.08870692 | CN8: =IF(AW9>0,DD8/AW9,0) -> 0.089854061 | CO8: =IF(AX9>0,DE8/AX9,0) -> 0.089671267 | CP8: =IF(AY9>0,DF8/AY9,0) -> 0.089556555 | CQ8: =IF(AZ9>0,DG8/AZ9,0) -> 0.089042391 | CR8: =IF(BA9>0,DH8/BA9,0) -> 0.088721272 | ... CV8: =IF(BE9>0,DL8/BE9,0) -> 0.086973825 | CX8: 2301 | CY8: Nucléaire | CZ8: QMtep_losses_2301 | DA8: ='Bilan 2015'!$K$13*'Bilan 2015'!$G$10/SUM('Bilan 2015'!$G$7:$G$19) -> 2.3619655 | DB8: ='Bilan 2020'!$K$13*'Bilan 2020'!$G$10/SUM('Bilan 2020'!$G$7:$G$19) -> 24.447147 | DC8: ='Bilan 2023 réel'!$K$13*'Bilan 2023 réel'!$G$10/SUM('Bilan 2023 réel'!$G$7:$G$19) -> 23.737646 | DD8: ='Bilan 2025'!$K$13*'Bilan 2025'!$G$10/SUM('Bilan 2025'!$G$7:$G$19) -> 26.896504 | DE8: ='Bilan 2028'!$K$13*'Bilan 2028'!$G$10/SUM('Bilan 2028'!$G$7:$G$19) -> 26.522704 | DF8: ='Bilan 2030'!$K$13*'Bilan 2030'!$G$10/SUM('Bilan 2030'!$G$7:$G$19) -> 26.407152 | DG8: ='Bilan 2033'!$K$13*'Bilan 2033'!$G$10/SUM('Bilan 2033'!$G$7:$G$19) -> 25.502789 | DH8: ='Bilan 2035'!$K$13*'Bilan 2035'!$G$10/SUM('Bilan 2035'!$G$7:$G$19) -> 24.848721 | DI8: ='Bilan 2038'!$K$13*'Bilan 2038'!$G$10/SUM('Bilan 2038'!$G$7:$G$19) -> 23.582963 | DJ8: ='Bilan 2040'!$K$13*'Bilan 2040'!$G$10/SUM('Bilan 2040'!$G$7:$G$19) -> 22.689985 | DK8: ='Bilan 2045'!$K$13*'Bilan 2045'!$G$10/SUM('Bilan 2045'!$G$7:$G$19) -> 20.371405 | DL8: ='Bilan 2050'!$K$13*'Bilan 2050'!$G$10/SUM('Bilan 2050'!$G$7:$G$19) -> 17.580323
A9: Electricité | B9: =SUM(B10:B19) -> 132.32104 | C9: =SUM(C10:C19) -> 1284.6591 | D9: =SUM(D10:D19) -> 1256.7348 | E9: =SUM(E10:E19) -> 1420.9055 | F9: =SUM(F10:F19) -> 1438.1192 | G9: =SUM(G10:G19) -> 1446.9091 | H9: =SUM(H10:H19) -> 1401.3027 | I9: =SUM(I10:I19) -> 1370.9611 | ... M9: =SUM(M10:M19) -> 1168.9497 | N9: =C9-('Bilan 2020'!$D$13-SUM('Bilan 2020'!$M$13:$P$13)) -> 0 | O9: =G9-('Bilan 2030'!$D$13-SUM('Bilan 2030'!$M$13:$P$13)) -> 0 | P9: =M9-('Bilan 2050'!$D$13-SUM('Bilan 2050'!$M$13:$P$13)) -> 0 | Q9: Fioul | R9: =B11+0.01 -> 0.712 | S9: =C11+0.01 -> 3.4306184 | T9: =D11+0.01 -> 8.1195694 | U9: =E11+0.01 -> 7.8309554 | V9: =F11+0.01 -> 7.6564888 | W9: =G11+0.01 -> 7.5403124 | X9: =H11+0.01 -> 7.8029014 | Y9: =I11+0.01 -> 7.9778577 | ... AC9: =M11+0.01 -> 8.0617926 | AD9: =AD8+1 -> 2302 | AE9: Nucléaire | AF9: ='Bilan 2015'!$S$13*'Bilan 2015'!$G$10/SUM('Bilan 2015'!$G$7:$G$19) -> 29.553739 | AG9: ='Bilan 2020'!$S$13*'Bilan 2020'!$G$10/SUM('Bilan 2020'!$G$7:$G$19) -> 280.85642 | AH9: ='Bilan 2023 réel'!$S$13*'Bilan 2023 réel'!$G$10/SUM('Bilan 2023 réel'!$G$7:$G$19) -> 267.59632 | AI9: ='Bilan 2025'!$S$13*'Bilan 2025'!$G$10/SUM('Bilan 2025'!$G$7:$G$19) -> 299.33543 | AJ9: ='Bilan 2028'!$S$13*'Bilan 2028'!$G$10/SUM('Bilan 2028'!$G$7:$G$19) -> 295.77706 | AK9: ='Bilan 2030'!$S$13*'Bilan 2030'!$G$10/SUM('Bilan 2030'!$G$7:$G$19) -> 294.86566 | AL9: ='Bilan 2033'!$S$13*'Bilan 2033'!$G$10/SUM('Bilan 2033'!$G$7:$G$19) -> 286.41178 | AM9: ='Bilan 2035'!$S$13*'Bilan 2035'!$G$10/SUM('Bilan 2035'!$G$7:$G$19) -> 280.07625 | AN9: ='Bilan 2038'!$S$13*'Bilan 2038'!$G$10/SUM('Bilan 2038'!$G$7:$G$19) -> 267.13215 | AO9: ='Bilan 2040'!$S$13*'Bilan 2040'!$G$10/SUM('Bilan 2040'!$G$7:$G$19) -> 257.82317 | AP9: ='Bilan 2045'!$S$13*'Bilan 2045'!$G$10/SUM('Bilan 2045'!$G$7:$G$19) -> 233.09896 | AQ9: ='Bilan 2050'!$S$13*'Bilan 2050'!$G$10/SUM('Bilan 2050'!$G$7:$G$19) -> 202.13349 | AS9: Nucléaire | AT9: ='Bilan 2015'!$S$13*'Bilan 2015'!$G$10/SUM('Bilan 2015'!$G$7:$G$19) -> 29.553739 | AU9: ='Bilan 2020'!$S$13*'Bilan 2020'!$G$10/SUM('Bilan 2020'!$G$7:$G$19) -> 280.85642 | AV9: ='Bilan 2023 réel'!$S$13*'Bilan 2023 réel'!$G$10/SUM('Bilan 2023 réel'!$G$7:$G$19) -> 267.59632 | AW9: ='Bilan 2025'!$S$13*'Bilan 2025'!$G$10/SUM('Bilan 2025'!$G$7:$G$19) -> 299.33543 | AX9: ='Bilan 2028'!$S$13*'Bilan 2028'!$G$10/SUM('Bilan 2028'!$G$7:$G$19) -> 295.77706 | AY9: ='Bilan 2030'!$S$13*'Bilan 2030'!$G$10/SUM('Bilan 2030'!$G$7:$G$19) -> 294.86566 | AZ9: ='Bilan 2033'!$S$13*'Bilan 2033'!$G$10/SUM('Bilan 2033'!$G$7:$G$19) -> 286.41178 | BA9: ='Bilan 2035'!$S$13*'Bilan 2035'!$G$10/SUM('Bilan 2035'!$G$7:$G$19) -> 280.07625 | BB9: ='Bilan 2038'!$S$13*'Bilan 2038'!$G$10/SUM('Bilan 2038'!$G$7:$G$19) -> 267.13215 | BC9: ='Bilan 2040'!$S$13*'Bilan 2040'!$G$10/SUM('Bilan 2040'!$G$7:$G$19) -> 257.82317 | BD9: ='Bilan 2045'!$S$13*'Bilan 2045'!$G$10/SUM('Bilan 2045'!$G$7:$G$19) -> 233.09896 | BE9: ='Bilan 2050'!$S$13*'Bilan 2050'!$G$10/SUM('Bilan 2050'!$G$7:$G$19) -> 202.13349 | BG9: Fioul | BH9: =IF(AT10>0,BV9/AT10,0) -> 1.7578309 | BI9: =IF(AU10>0,BW9/AU10,0) -> 1.7088159 | BJ9: =IF(AV10>0,BX9/AV10,0) -> 1.8178904 | BK9: =IF(AW10>0,BY9/AW10,0) -> 1.7631997 | BL9: =IF(AX10>0,BZ9/AX10,0) -> 1.7749333 | BM9: =IF(AY10>0,CA9/AY10,0) -> 1.7746797 | BN9: =IF(AZ10>0,CB9/AZ10,0) -> 1.7158907 | BO9: =IF(BA10>0,CC9/BA10,0) -> 1.6791788 | ... BS9: =IF(BE10>0,CG9/BE10,0) -> 1.525832 | BU9: Fioul | BV9: ='Bilan 2015'!$E17+'Bilan 2015'!$I$13*'Bilan 2015'!$G$17/'Bilan 2015'!$H$13 -> 0.41016749 | BW9: ='Bilan 2020'!$E17+'Bilan 2020'!$I$13*'Bilan 2020'!$G$17/'Bilan 2020'!$H$13 -> 2.011173 | BX9: ='Bilan 2023 AMS'!$E17+'Bilan 2023 AMS'!$I$13*'Bilan 2023 AMS'!$G$17/'Bilan 2023 AMS'!$H$13 -> 4.7570322 | BY9: ='Bilan 2025'!$E17+'Bilan 2025'!$I$13*'Bilan 2025'!$G$17/'Bilan 2025'!$H$13 -> 4.5966369 | BZ9: ='Bilan 2028'!$E17+'Bilan 2028'!$I$13*'Bilan 2028'!$G$17/'Bilan 2028'!$H$13 -> 4.4873332 | CA9: ='Bilan 2030'!$E17+'Bilan 2030'!$I$13*'Bilan 2030'!$G$17/'Bilan 2030'!$H$13 -> 4.4158422 | CB9: ='Bilan 2033'!$E17+'Bilan 2033'!$I$13*'Bilan 2033'!$G$17/'Bilan 2033'!$H$13 -> 4.5601065 | CC9: ='Bilan 2035'!$E17+'Bilan 2035'!$I$13*'Bilan 2035'!$G$17/'Bilan 2035'!$H$13 -> 4.6559445 | CD9: ='Bilan 2038'!$E17+'Bilan 2038'!$I$13*'Bilan 2038'!$G$17/'Bilan 2038'!$H$13 -> 4.4890054 | CE9: ='Bilan 2040'!$E17+'Bilan 2040'!$I$13*'Bilan 2040'!$G$17/'Bilan 2040'!$H$13 -> 4.3781376 | CF9: ='Bilan 2045'!$E17+'Bilan 2045'!$I$13*'Bilan 2045'!$G$17/'Bilan 2045'!$H$13 -> 4.5950215 | CG9: ='Bilan 2050'!$E17+'Bilan 2050'!$I$13*'Bilan 2050'!$G$17/'Bilan 2050'!$H$13 -> 4.6608345 | CJ9: Fioul | CK9: =IF(AT10>0,DA9/AT10,0) -> 0.07992104 | CL9: =IF(AU10>0,DB9/AU10,0) -> 0.087045 | CM9: =IF(AV10>0,DC9/AV10,0) -> 0.096511255 | CN9: =IF(AW10>0,DD9/AW10,0) -> 0.089854061 | CO9: =IF(AX10>0,DE9/AX10,0) -> 0.089671267 | CP9: =IF(AY10>0,DF9/AY10,0) -> 0.089556555 | CQ9: =IF(AZ10>0,DG9/AZ10,0) -> 0.089042391 | CR9: =IF(BA10>0,DH9/BA10,0) -> 0.088721272 | ... CV9: =IF(BE10>0,DL9/BE10,0) -> 0.086973825 | CX9: =CX8+1 -> 2302 | CY9: Fioul | CZ9: QMtep_losses_2302 | DA9: ='Bilan 2015'!$K$13*'Bilan 2015'!$G$17/SUM('Bilan 2015'!$G$7:$G$19) -> 0.018648559 | DB9: ='Bilan 2020'!$K$13*'Bilan 2020'!$G$17/SUM('Bilan 2020'!$G$7:$G$19) -> 0.1024467 | DC9: ='Bilan 2023 AMS'!$K$13*'Bilan 2023 AMS'!$G$17/SUM('Bilan 2023 AMS'!$G$7:$G$19) -> 0.25254941 | DD9: ='Bilan 2025'!$K$13*'Bilan 2025'!$G$17/SUM('Bilan 2025'!$G$7:$G$19) -> 0.23424827 | DE9: ='Bilan 2028'!$K$13*'Bilan 2028'!$G$17/SUM('Bilan 2028'!$G$7:$G$19) -> 0.22670421 | DF9: ='Bilan 2030'!$K$13*'Bilan 2030'!$G$17/SUM('Bilan 2030'!$G$7:$G$19) -> 0.22283886 | DG9: ='Bilan 2033'!$K$13*'Bilan 2033'!$G$17/SUM('Bilan 2033'!$G$7:$G$19) -> 0.23663675 | DH9: ='Bilan 2035'!$K$13*'Bilan 2035'!$G$17/SUM('Bilan 2035'!$G$7:$G$19) -> 0.24600199 | DI9: ='Bilan 2038'!$K$13*'Bilan 2038'!$G$17/SUM('Bilan 2038'!$G$7:$G$19) -> 0.24283381 | DJ9: ='Bilan 2040'!$K$13*'Bilan 2040'!$G$17/SUM('Bilan 2040'!$G$7:$G$19) -> 0.24045497 | DK9: ='Bilan 2045'!$K$13*'Bilan 2045'!$G$17/SUM('Bilan 2045'!$G$7:$G$19) -> 0.25947963 | DL9: ='Bilan 2050'!$K$13*'Bilan 2050'!$G$17/SUM('Bilan 2050'!$G$7:$G$19) -> 0.26567185
A10: Nucléaire | B10: ='Bilan 2015'!$C10 -> 114.07243 | C10: ='Bilan 2020'!$C10 -> 1068.7282 | D10: ='Bilan 2023 réel'!$C10*(1-SUM('Bilan 2023 réel'!$M$13:$P$13)/'Bilan 2023 réel'!$D$13) -> 1024.8554 | E10: ='Bilan 2025'!$C10 -> 1190.9091 | F10: ='Bilan 2028'!$C10*(1-SUM('Bilan 2028'!$M$13:$P$13)/'Bilan 2028'!$D$13) -> 1190.8538 | G10: ='Bilan 2030'!$C10*(1-SUM('Bilan 2030'!$M$13:$P$13)/'Bilan 2030'!$D$13) -> 1190.8368 | H10: ='Bilan 2033'!$C10*(1-SUM('Bilan 2033'!$M$13:$P$13)/'Bilan 2033'!$D$13) -> 1121.1895 | I10: ='Bilan 2035'!$C10*(1-SUM('Bilan 2035'!$M$13:$P$13)/'Bilan 2035'!$D$13) -> 1074.7551 | J10: ='Bilan 2038'!$C10*(1-SUM('Bilan 2038'!$M$13:$P$13)/'Bilan 2038'!$D$13) -> 1005.0926 | K10: ='Bilan 2040'!$C10*(1-SUM('Bilan 2040'!$M$13:$P$13)/'Bilan 2040'!$D$13) -> 958.64961 | L10: ='Bilan 2045'!$C10*(1-SUM('Bilan 2045'!$M$13:$P$13)/'Bilan 2045'!$D$13) -> 842.56165 | M10: ='Bilan 2050'!$C10*(1-SUM('Bilan 2050'!$M$13:$P$13)/'Bilan 2050'!$D$13) -> 726.54022 | Q10: Gaz naturel | R10: =B12 -> 3.8621596 | S10: =C12 -> 60.547801 | T10: =D12 -> 52.478364 | U10: =E12 -> 18.968953 | V10: =F12 -> 18.552278 | W10: =G12 -> 18.284948 | X10: =H12 -> 18.050612 | Y10: =I12 -> 17.897866 | ... AC10: =M12 -> 47.558513 | AD10: =AD9+1 -> 2303 | AE10: Fioul | AF10: ='Bilan 2015'!$S$13*'Bilan 2015'!$G$17/SUM('Bilan 2015'!$G$7:$G$19) -> 0.23333729 | AG10: ='Bilan 2020'!$S$13*'Bilan 2020'!$G$17/SUM('Bilan 2020'!$G$7:$G$19) -> 1.1769395 | AH10: ='Bilan 2023 AMS'!$S$13*'Bilan 2023 AMS'!$G$17/SUM('Bilan 2023 AMS'!$G$7:$G$19) -> 2.6167872 | AI10: ='Bilan 2025'!$S$13*'Bilan 2025'!$G$17/SUM('Bilan 2025'!$G$7:$G$19) -> 2.6069859 | AJ10: ='Bilan 2028'!$S$13*'Bilan 2028'!$G$17/SUM('Bilan 2028'!$G$7:$G$19) -> 2.52817 | AK10: ='Bilan 2030'!$S$13*'Bilan 2030'!$G$17/SUM('Bilan 2030'!$G$7:$G$19) -> 2.4882474 | AL10: ='Bilan 2033'!$S$13*'Bilan 2033'!$G$17/SUM('Bilan 2033'!$G$7:$G$19) -> 2.657574 | AM10: ='Bilan 2035'!$S$13*'Bilan 2035'!$G$17/SUM('Bilan 2035'!$G$7:$G$19) -> 2.7727509 | AN10: ='Bilan 2038'!$S$13*'Bilan 2038'!$G$17/SUM('Bilan 2038'!$G$7:$G$19) -> 2.7506602 | AO10: ='Bilan 2040'!$S$13*'Bilan 2040'!$G$17/SUM('Bilan 2040'!$G$7:$G$19) -> 2.7322567 | AP10: ='Bilan 2045'!$S$13*'Bilan 2045'!$G$17/SUM('Bilan 2045'!$G$7:$G$19) -> 2.969085 | AQ10: ='Bilan 2050'!$S$13*'Bilan 2050'!$G$17/SUM('Bilan 2050'!$G$7:$G$19) -> 3.0546184 | AS10: Fioul | AT10: ='Bilan 2015'!$S$13*'Bilan 2015'!$G$17/SUM('Bilan 2015'!$G$7:$G$19) -> 0.23333729 | AU10: ='Bilan 2020'!$S$13*'Bilan 2020'!$G$17/SUM('Bilan 2020'!$G$7:$G$19) -> 1.1769395 | AV10: ='Bilan 2023 AMS'!$S$13*'Bilan 2023 AMS'!$G$17/SUM('Bilan 2023 AMS'!$G$7:$G$19) -> 2.6167872 | AW10: ='Bilan 2025'!$S$13*'Bilan 2025'!$G$17/SUM('Bilan 2025'!$G$7:$G$19) -> 2.6069859 | AX10: ='Bilan 2028'!$S$13*'Bilan 2028'!$G$17/SUM('Bilan 2028'!$G$7:$G$19) -> 2.52817 | AY10: ='Bilan 2030'!$S$13*'Bilan 2030'!$G$17/SUM('Bilan 2030'!$G$7:$G$19) -> 2.4882474 | AZ10: ='Bilan 2033'!$S$13*'Bilan 2033'!$G$17/SUM('Bilan 2033'!$G$7:$G$19) -> 2.657574 | BA10: ='Bilan 2035'!$S$13*'Bilan 2035'!$G$17/SUM('Bilan 2035'!$G$7:$G$19) -> 2.7727509 | BB10: ='Bilan 2038'!$S$13*'Bilan 2038'!$G$17/SUM('Bilan 2038'!$G$7:$G$19) -> 2.7506602 | BC10: ='Bilan 2040'!$S$13*'Bilan 2040'!$G$17/SUM('Bilan 2040'!$G$7:$G$19) -> 2.7322567 | BD10: ='Bilan 2045'!$S$13*'Bilan 2045'!$G$17/SUM('Bilan 2045'!$G$7:$G$19) -> 2.969085 | BE10: ='Bilan 2050'!$S$13*'Bilan 2050'!$G$17/SUM('Bilan 2050'!$G$7:$G$19) -> 3.0546184 | BG10: Gaz naturel | BH10: =IF(AT11>0,BV10/AT11,0) -> 1.2659435 | BI10: =IF(AU11>0,BW10/AU11,0) -> 1.2336304 | BJ10: =IF(AV11>0,BX10/AV11,0) -> 1.2525634 | BK10: =IF(AW11>0,BY10/AW11,0) -> 1.2537659 | BL10: =IF(AX11>0,BZ10/AX11,0) -> 1.2057177 | BM10: =IF(AY11>0,CA10/AY11,0) -> 1.1693726 | BN10: =IF(AZ11>0,CB10/AZ11,0) -> 1.0977686 | BO10: =IF(BA11>0,CC10/BA11,0) -> 1.0532236 | ... BS10: =IF(BE11>0,CG10/BE11,0) -> 0.82220581 | BU10: Gaz naturel | BV10: ='Bilan 2015'!$E19+'Bilan 2015'!$I$13*'Bilan 2015'!$G$19/'Bilan 2015'!$H$13 -> 1.9287506 | BW10: ='Bilan 2020'!$E19+'Bilan 2020'!$I$13*'Bilan 2020'!$G$19/'Bilan 2020'!$H$13 -> 28.129408 | BX10: ='Bilan 2023 réel'!$E19+'Bilan 2023 réel'!$I$13*'Bilan 2023 réel'!$G$19/'Bilan 2023 réel'!$H$13 -> 23.415695 | BY10: ='Bilan 2025'!$E19+'Bilan 2025'!$I$13*'Bilan 2025'!$G$19/'Bilan 2025'!$H$13 -> 9.308265 | BZ10: ='Bilan 2028'!$E19+'Bilan 2028'!$I$13*'Bilan 2028'!$G$19/'Bilan 2028'!$H$13 -> 8.8785711 | CA10: ='Bilan 2030'!$E19+'Bilan 2030'!$I$13*'Bilan 2030'!$G$19/'Bilan 2030'!$H$13 -> 8.6055872 | CB10: ='Bilan 2033'!$E19+'Bilan 2033'!$I$13*'Bilan 2033'!$G$19/'Bilan 2033'!$H$13 -> 8.3368686 | CC10: ='Bilan 2035'!$E19+'Bilan 2035'!$I$13*'Bilan 2035'!$G$19/'Bilan 2035'!$H$13 -> 8.161394 | CD10: ='Bilan 2038'!$E19+'Bilan 2038'!$I$13*'Bilan 2038'!$G$19/'Bilan 2038'!$H$13 -> 7.9034753 | CE10: ='Bilan 2040'!$E19+'Bilan 2040'!$I$13*'Bilan 2040'!$G$19/'Bilan 2040'!$H$13 -> 7.7349715 | CF10: ='Bilan 2045'!$E19+'Bilan 2045'!$I$13*'Bilan 2045'!$G$19/'Bilan 2045'!$H$13 -> 7.3252837 | CG10: ='Bilan 2050'!$E19+'Bilan 2050'!$I$13*'Bilan 2050'!$G$19/'Bilan 2050'!$H$13 -> 19.771615 | CJ10: Gaz naturel | CK10: =IF(AT11>0,DA10/AT11,0) -> 0.07992104 | CL10: =IF(AU11>0,DB10/AU11,0) -> 0.087045 | CM10: =IF(AV11>0,DC10/AV11,0) -> 0.08870692 | CN10: =IF(AW11>0,DD10/AW11,0) -> 0.089854061 | CO10: =IF(AX11>0,DE10/AX11,0) -> 0.089671267 | CP10: =IF(AY11>0,DF10/AY11,0) -> 0.089556555 | CQ10: =IF(AZ11>0,DG10/AZ11,0) -> 0.089042391 | CR10: =IF(BA11>0,DH10/BA11,0) -> 0.088721272 | ... CV10: =IF(BE11>0,DL10/BE11,0) -> 0.086973825 | CX10: =CX9+1 -> 2303 | CY10: Gaz naturel | CZ10: QMtep_losses_2303 | DA10: ='Bilan 2015'!$K$13*'Bilan 2015'!$G$19/SUM('Bilan 2015'!$G$7:$G$19) -> 0.12176511 | DB10: ='Bilan 2020'!$K$13*'Bilan 2020'!$G$19/SUM('Bilan 2020'!$G$7:$G$19) -> 1.9848119 | DC10: ='Bilan 2023 réel'!$K$13*'Bilan 2023 réel'!$G$19/SUM('Bilan 2023 réel'!$G$7:$G$19) -> 1.6583067 | DD10: ='Bilan 2025'!$K$13*'Bilan 2025'!$G$19/SUM('Bilan 2025'!$G$7:$G$19) -> 0.66709853 | DE10: ='Bilan 2028'!$K$13*'Bilan 2028'!$G$19/SUM('Bilan 2028'!$G$7:$G$19) -> 0.66031438 | DF10: ='Bilan 2030'!$K$13*'Bilan 2030'!$G$19/SUM('Bilan 2030'!$G$7:$G$19) -> 0.65906003 | DG10: ='Bilan 2033'!$K$13*'Bilan 2033'!$G$19/SUM('Bilan 2033'!$G$7:$G$19) -> 0.67622148 | DH10: ='Bilan 2035'!$K$13*'Bilan 2035'!$G$19/SUM('Bilan 2035'!$G$7:$G$19) -> 0.68749811 | DI10: ='Bilan 2038'!$K$13*'Bilan 2038'!$G$19/SUM('Bilan 2038'!$G$7:$G$19) -> 0.70233036 | DJ10: ='Bilan 2040'!$K$13*'Bilan 2040'!$G$19/SUM('Bilan 2040'!$G$7:$G$19) -> 0.71201764 | DK10: ='Bilan 2045'!$K$13*'Bilan 2045'!$G$19/SUM('Bilan 2045'!$G$7:$G$19) -> 0.72942854 | DL10: ='Bilan 2050'!$K$13*'Bilan 2050'!$G$19/SUM('Bilan 2050'!$G$7:$G$19) -> 2.0914629
A11: Fioul | B11: ='Bilan 2015'!$C$17 -> 0.702 | C11: ='Bilan 2020'!$C$17 -> 3.4206184 | D11: ='Bilan 2023 AMS'!$C$17*(1-SUM('Bilan 2023 AMS'!$M$13:$P$13)/'Bilan 2023 AMS'!$D$13) -> 8.1095694 | E11: ='Bilan 2025'!$C$17 -> 7.8209554 | F11: ='Bilan 2028'!$C$17*(1-SUM('Bilan 2028'!$M$13:$P$13)/'Bilan 2028'!$D$13) -> 7.6464888 | G11: ='Bilan 2030'!$C$17*(1-SUM('Bilan 2030'!$M$13:$P$13)/'Bilan 2030'!$D$13) -> 7.5303124 | H11: ='Bilan 2033'!$C$17*(1-SUM('Bilan 2033'!$M$13:$P$13)/'Bilan 2033'!$D$13) -> 7.7929014 | I11: ='Bilan 2035'!$C$17*(1-SUM('Bilan 2035'!$M$13:$P$13)/'Bilan 2035'!$D$13) -> 7.9678577 | J11: ='Bilan 2038'!$C$17*(1-SUM('Bilan 2038'!$M$13:$P$13)/'Bilan 2038'!$D$13) -> 7.6981211 | K11: ='Bilan 2040'!$C$17*(1-SUM('Bilan 2040'!$M$13:$P$13)/'Bilan 2040'!$D$13) -> 7.5182459 | L11: ='Bilan 2045'!$C$17*(1-SUM('Bilan 2045'!$M$13:$P$13)/'Bilan 2045'!$D$13) -> 7.9172502 | M11: ='Bilan 2050'!$C$17*(1-SUM('Bilan 2050'!$M$13:$P$13)/'Bilan 2050'!$D$13) -> 8.0517926 | Q11: Charbon | R11: =B13 -> 2.9935125 | S11: =C13 -> 9.3252829 | T11: =D13 -> 8.0663799 | U11: =E13+0.0001 -> 2.830867 | V11: =F13+0.0001 -> 2.8283469 | W11: =G13+0.0001 -> 2.8267141 | X11: =H13+0.0001 -> 2.8264467 | Y11: =I13+0.0001 -> 2.8262417 | Z11: =J13+0.0001 -> 2.825868 | AA11: =K13+0.0001 -> 2.825585 | AB11: =L13+0.0001 -> 2.8248065 | AC11: =M13+0.0001 -> 2.8240385 | AD11: =AD10+1 -> 2304 | AE11: Gaz naturel | AF11: ='Bilan 2015'!$S$13*'Bilan 2015'!$G$19/SUM('Bilan 2015'!$G$7:$G$19) -> 1.5235677 | AG11: ='Bilan 2020'!$S$13*'Bilan 2020'!$G$19/SUM('Bilan 2020'!$G$7:$G$19) -> 22.802136 | AH11: ='Bilan 2023 réel'!$S$13*'Bilan 2023 réel'!$G$19/SUM('Bilan 2023 réel'!$G$7:$G$19) -> 18.69422 | AI11: ='Bilan 2025'!$S$13*'Bilan 2025'!$G$19/SUM('Bilan 2025'!$G$7:$G$19) -> 7.4242446 | AJ11: ='Bilan 2028'!$S$13*'Bilan 2028'!$G$19/SUM('Bilan 2028'!$G$7:$G$19) -> 7.3637231 | AK11: ='Bilan 2030'!$S$13*'Bilan 2030'!$G$19/SUM('Bilan 2030'!$G$7:$G$19) -> 7.359149 | AL11: ='Bilan 2033'!$S$13*'Bilan 2033'!$G$19/SUM('Bilan 2033'!$G$7:$G$19) -> 7.594377 | AM11: ='Bilan 2035'!$S$13*'Bilan 2035'!$G$19/SUM('Bilan 2035'!$G$7:$G$19) -> 7.7489659 | AN11: ='Bilan 2038'!$S$13*'Bilan 2038'!$G$19/SUM('Bilan 2038'!$G$7:$G$19) -> 7.955532 | AO11: ='Bilan 2040'!$S$13*'Bilan 2040'!$G$19/SUM('Bilan 2040'!$G$7:$G$19) -> 8.0905586 | AP11: ='Bilan 2045'!$S$13*'Bilan 2045'!$G$19/SUM('Bilan 2045'!$G$7:$G$19) -> 8.3464561 | AQ11: ='Bilan 2050'!$S$13*'Bilan 2050'!$G$19/SUM('Bilan 2050'!$G$7:$G$19) -> 24.047039 | AS11: Gaz naturel | AT11: ='Bilan 2015'!$S$13*'Bilan 2015'!$G$19/SUM('Bilan 2015'!$G$7:$G$19) -> 1.5235677 | AU11: ='Bilan 2020'!$S$13*'Bilan 2020'!$G$19/SUM('Bilan 2020'!$G$7:$G$19) -> 22.802136 | AV11: ='Bilan 2023 réel'!$S$13*'Bilan 2023 réel'!$G$19/SUM('Bilan 2023 réel'!$G$7:$G$19) -> 18.69422 | AW11: ='Bilan 2025'!$S$13*'Bilan 2025'!$G$19/SUM('Bilan 2025'!$G$7:$G$19) -> 7.4242446 | AX11: ='Bilan 2028'!$S$13*'Bilan 2028'!$G$19/SUM('Bilan 2028'!$G$7:$G$19) -> 7.3637231 | AY11: ='Bilan 2030'!$S$13*'Bilan 2030'!$G$19/SUM('Bilan 2030'!$G$7:$G$19) -> 7.359149 | AZ11: ='Bilan 2033'!$S$13*'Bilan 2033'!$G$19/SUM('Bilan 2033'!$G$7:$G$19) -> 7.594377 | BA11: ='Bilan 2035'!$S$13*'Bilan 2035'!$G$19/SUM('Bilan 2035'!$G$7:$G$19) -> 7.7489659 | BB11: ='Bilan 2038'!$S$13*'Bilan 2038'!$G$19/SUM('Bilan 2038'!$G$7:$G$19) -> 7.955532 | BC11: ='Bilan 2040'!$S$13*'Bilan 2040'!$G$19/SUM('Bilan 2040'!$G$7:$G$19) -> 8.0905586 | BD11: ='Bilan 2045'!$S$13*'Bilan 2045'!$G$19/SUM('Bilan 2045'!$G$7:$G$19) -> 8.3464561 | BE11: ='Bilan 2050'!$S$13*'Bilan 2050'!$G$19/SUM('Bilan 2050'!$G$7:$G$19) -> 24.047039 | BG11: Charbon | BH11: =IF(AT12>0,BV11/AT12,0) -> 2.9105546 | BI11: =IF(AU12>0,BW11/AU12,0) -> 2.8223994 | BJ11: =IF(AV12>0,BX11/AV12,0) -> 2.8642105 | BK11: =IF(AW12>0,BY11/AW12,0) -> 2.9126585 | BL11: =IF(AX12>0,BZ11/AX12,0) -> 2.9338393 | BM11: =IF(AY12>0,CA11/AY12,0) -> 2.9343061 | BN11: =IF(AZ12>0,CB11/AZ12,0) -> 2.8395988 | BO11: =IF(BA12>0,CC11/BA12,0) -> 2.7804693 | ... BS11: =IF(BE12>0,CG11/BE12,0) -> 2.5368189 | BU11: Charbon | BV11: ='Bilan 2015'!$E18+'Bilan 2015'!$I$13*'Bilan 2015'!$G$18/'Bilan 2015'!$H$13 -> 2.0937925 | BW11: ='Bilan 2020'!$E18+'Bilan 2020'!$I$13*'Bilan 2020'!$G$18/'Bilan 2020'!$H$13 -> 6.5472625 | BX11: ='Bilan 2023 réel'!$E18+'Bilan 2023 réel'!$I$13*'Bilan 2023 réel'!$G$18/'Bilan 2023 réel'!$H$13 -> 5.6657013 | BY11: ='Bilan 2025'!$E18+'Bilan 2025'!$I$13*'Bilan 2025'!$G$18/'Bilan 2025'!$H$13 -> 1.9870204 | BZ11: ='Bilan 2028'!$E18+'Bilan 2028'!$I$13*'Bilan 2028'!$G$18/'Bilan 2028'!$H$13 -> 1.9834791 | CA11: ='Bilan 2030'!$E18+'Bilan 2030'!$I$13*'Bilan 2030'!$G$18/'Bilan 2030'!$H$13 -> 1.9814461 | CB11: ='Bilan 2033'!$E18+'Bilan 2033'!$I$13*'Bilan 2033'!$G$18/'Bilan 2033'!$H$13 -> 1.9787839 | CC11: ='Bilan 2035'!$E18+'Bilan 2035'!$I$13*'Bilan 2035'!$G$18/'Bilan 2035'!$H$13 -> 1.9770202 | CD11: ='Bilan 2038'!$E18+'Bilan 2038'!$I$13*'Bilan 2038'!$G$18/'Bilan 2038'!$H$13 -> 1.9743886 | CE11: ='Bilan 2040'!$E18+'Bilan 2040'!$I$13*'Bilan 2040'!$G$18/'Bilan 2040'!$H$13 -> 1.9726452 | CF11: ='Bilan 2045'!$E18+'Bilan 2045'!$I$13*'Bilan 2045'!$G$18/'Bilan 2045'!$H$13 -> 1.968327 | CG11: ='Bilan 2050'!$E18+'Bilan 2050'!$I$13*'Bilan 2050'!$G$18/'Bilan 2050'!$H$13 -> 1.9648927 | CJ11: Charbon | CK11: =IF(AT12>0,DA11/AT12,0) -> 0.07992104 | CL11: =IF(AU12>0,DB11/AU12,0) -> 0.087045 | CM11: =IF(AV12>0,DC11/AV12,0) -> 0.08870692 | CN11: =IF(AW12>0,DD11/AW12,0) -> 0.089854061 | CO11: =IF(AX12>0,DE11/AX12,0) -> 0.089671267 | CP11: =IF(AY12>0,DF11/AY12,0) -> 0.089556555 | CQ11: =IF(AZ12>0,DG11/AZ12,0) -> 0.089042391 | CR11: =IF(BA12>0,DH11/BA12,0) -> 0.088721272 | ... CV11: =IF(BE12>0,DL11/BE12,0) -> 0.086973825 | CX11: =CX10+1 -> 2304 | CY11: Charbon | CZ11: QMtep_losses_2304 | DA11: ='Bilan 2015'!$K$13*'Bilan 2015'!$G$18/SUM('Bilan 2015'!$G$7:$G$19) -> 0.057493534 | DB11: ='Bilan 2020'!$K$13*'Bilan 2020'!$G$18/SUM('Bilan 2020'!$G$7:$G$19) -> 0.20192269 | DC11: ='Bilan 2023 réel'!$K$13*'Bilan 2023 réel'!$G$18/SUM('Bilan 2023 réel'!$G$7:$G$19) -> 0.17547136 | DD11: ='Bilan 2025'!$K$13*'Bilan 2025'!$G$18/SUM('Bilan 2025'!$G$7:$G$19) -> 0.061298588 | DE11: ='Bilan 2028'!$K$13*'Bilan 2028'!$G$18/SUM('Bilan 2028'!$G$7:$G$19) -> 0.060624002 | DF11: ='Bilan 2030'!$K$13*'Bilan 2030'!$G$18/SUM('Bilan 2030'!$G$7:$G$19) -> 0.060474769 | DG11: ='Bilan 2033'!$K$13*'Bilan 2033'!$G$18/SUM('Bilan 2033'!$G$7:$G$19) -> 0.062049489 | DH11: ='Bilan 2035'!$K$13*'Bilan 2035'!$G$18/SUM('Bilan 2035'!$G$7:$G$19) -> 0.063084223 | DI11: ='Bilan 2038'!$K$13*'Bilan 2038'!$G$18/SUM('Bilan 2038'!$G$7:$G$19) -> 0.064445216 | DJ11: ='Bilan 2040'!$K$13*'Bilan 2040'!$G$18/SUM('Bilan 2040'!$G$7:$G$19) -> 0.065334113 | DK11: ='Bilan 2045'!$K$13*'Bilan 2045'!$G$18/SUM('Bilan 2045'!$G$7:$G$19) -> 0.066931722 | DL11: ='Bilan 2050'!$K$13*'Bilan 2050'!$G$18/SUM('Bilan 2050'!$G$7:$G$19) -> 0.067365565
A12: Gaz (naturel + biogaz) | B12: ='Bilan 2015'!$C$11+'Bilan 2015'!$C$19 -> 3.8621596 | C12: ='Bilan 2020'!$C$11+'Bilan 2020'!$C$19 -> 60.547801 | D12: =('Bilan 2023 réel'!$C$11+'Bilan 2023 réel'!$C$19)*(1-SUM('Bilan 2023 réel'!$M$13:$P$13)/'Bilan 2023 réel'!$D$13) -> 52.478364 | E12: ='Bilan 2025'!$C$11+'Bilan 2025'!$C$19 -> 18.968953 | F12: =('Bilan 2028'!$C$11+'Bilan 2028'!$C$19)*(1-SUM('Bilan 2028'!$M$13:$P$13)/'Bilan 2028'!$D$13) -> 18.552278 | G12: =('Bilan 2030'!$C$11+'Bilan 2030'!$C$19)*(1-SUM('Bilan 2030'!$M$13:$P$13)/'Bilan 2030'!$D$13) -> 18.284948 | H12: =('Bilan 2033'!$C$11+'Bilan 2033'!$C$19)*(1-SUM('Bilan 2033'!$M$13:$P$13)/'Bilan 2033'!$D$13) -> 18.050612 | I12: =('Bilan 2035'!$C$11+'Bilan 2035'!$C$19)*(1-SUM('Bilan 2035'!$M$13:$P$13)/'Bilan 2035'!$D$13) -> 17.897866 | J12: =('Bilan 2038'!$C$11+'Bilan 2038'!$C$19)*(1-SUM('Bilan 2038'!$M$13:$P$13)/'Bilan 2038'!$D$13) -> 17.662369 | K12: =('Bilan 2040'!$C$11+'Bilan 2040'!$C$19)*(1-SUM('Bilan 2040'!$M$13:$P$13)/'Bilan 2040'!$D$13) -> 17.508584 | L12: =('Bilan 2045'!$C$11+'Bilan 2045'!$C$19)*(1-SUM('Bilan 2045'!$M$13:$P$13)/'Bilan 2045'!$D$13) -> 17.134781 | M12: =('Bilan 2050'!$C$11+'Bilan 2050'!$C$19)*(1-SUM('Bilan 2050'!$M$13:$P$13)/'Bilan 2050'!$D$13) -> 47.558513 | Q12: Eolien | R12: =B14 -> 2.6944656 | S12: =C14 -> 43.44205 | T12: =D14 -> 50.187689 | U12: =E14 -> 64.725058 | V12: =F14 -> 78.241518 | W12: =G14 -> 84.29705 | X12: =H14 -> 96.490618 | Y12: =I14 -> 104.61652 | ... AC12: =M14 -> 165.52901 | AE12: Charbon | AF12: ='Bilan 2015'!$S$13*'Bilan 2015'!$G$18/SUM('Bilan 2015'!$G$7:$G$19) -> 0.7193792 | AG12: ='Bilan 2020'!$S$13*'Bilan 2020'!$G$18/SUM('Bilan 2020'!$G$7:$G$19) -> 2.3197506 | AH12: ='Bilan 2023 réel'!$S$13*'Bilan 2023 réel'!$G$18/SUM('Bilan 2023 réel'!$G$7:$G$19) -> 1.9781023 | AI12: ='Bilan 2025'!$S$13*'Bilan 2025'!$G$18/SUM('Bilan 2025'!$G$7:$G$19) -> 0.68220165 | AJ12: ='Bilan 2028'!$S$13*'Bilan 2028'!$G$18/SUM('Bilan 2028'!$G$7:$G$19) -> 0.67606943 | AK12: ='Bilan 2030'!$S$13*'Bilan 2030'!$G$18/SUM('Bilan 2030'!$G$7:$G$19) -> 0.67526905 | AL12: ='Bilan 2033'!$S$13*'Bilan 2033'!$G$18/SUM('Bilan 2033'!$G$7:$G$19) -> 0.69685335 | AM12: ='Bilan 2035'!$S$13*'Bilan 2035'!$G$18/SUM('Bilan 2035'!$G$7:$G$19) -> 0.7110383 | AN12: ='Bilan 2038'!$S$13*'Bilan 2038'!$G$18/SUM('Bilan 2038'!$G$7:$G$19) -> 0.72999263 | AO12: ='Bilan 2040'!$S$13*'Bilan 2040'!$G$18/SUM('Bilan 2040'!$G$7:$G$19) -> 0.74238254 | AP12: ='Bilan 2045'!$S$13*'Bilan 2045'!$G$18/SUM('Bilan 2045'!$G$7:$G$19) -> 0.76586347 | AQ12: ='Bilan 2050'!$S$13*'Bilan 2050'!$G$18/SUM('Bilan 2050'!$G$7:$G$19) -> 0.77454987 | AS12: Charbon | AT12: ='Bilan 2015'!$S$13*'Bilan 2015'!$G$18/SUM('Bilan 2015'!$G$7:$G$19) -> 0.7193792 | AU12: ='Bilan 2020'!$S$13*'Bilan 2020'!$G$18/SUM('Bilan 2020'!$G$7:$G$19) -> 2.3197506 | AV12: ='Bilan 2023 réel'!$S$13*'Bilan 2023 réel'!$G$18/SUM('Bilan 2023 réel'!$G$7:$G$19) -> 1.9781023 | AW12: ='Bilan 2025'!$S$13*'Bilan 2025'!$G$18/SUM('Bilan 2025'!$G$7:$G$19) -> 0.68220165 | AX12: ='Bilan 2028'!$S$13*'Bilan 2028'!$G$18/SUM('Bilan 2028'!$G$7:$G$19) -> 0.67606943 | AY12: ='Bilan 2030'!$S$13*'Bilan 2030'!$G$18/SUM('Bilan 2030'!$G$7:$G$19) -> 0.67526905 | AZ12: ='Bilan 2033'!$S$13*'Bilan 2033'!$G$18/SUM('Bilan 2033'!$G$7:$G$19) -> 0.69685335 | BA12: ='Bilan 2035'!$S$13*'Bilan 2035'!$G$18/SUM('Bilan 2035'!$G$7:$G$19) -> 0.7110383 | BB12: ='Bilan 2038'!$S$13*'Bilan 2038'!$G$18/SUM('Bilan 2038'!$G$7:$G$19) -> 0.72999263 | BC12: ='Bilan 2040'!$S$13*'Bilan 2040'!$G$18/SUM('Bilan 2040'!$G$7:$G$19) -> 0.74238254 | BD12: ='Bilan 2045'!$S$13*'Bilan 2045'!$G$18/SUM('Bilan 2045'!$G$7:$G$19) -> 0.76586347 | BE12: ='Bilan 2050'!$S$13*'Bilan 2050'!$G$18/SUM('Bilan 2050'!$G$7:$G$19) -> 0.77454987 | BG12: Methanisation | BH12: =IF(AT13>0,BV12/AT13,0) -> 1.2659435 | BI12: =IF(AU13>0,BW12/AU13,0) -> 1.2336304 | BJ12: =IF(AV13>0,BX12/AV13,0) -> 1.2525634 | BK12: =IF(AW13>0,BY12/AW13,0) -> 1.2537659 | BL12: =IF(AX13>0,BZ12/AX13,0) -> 1.2057177 | BM12: =IF(AY13>0,CA12/AY13,0) -> 1.1693726 | BN12: =IF(AZ13>0,CB12/AZ13,0) -> 1.0977686 | BO12: =IF(BA13>0,CC12/BA13,0) -> 1.0532236 | ... BS12: =IF(BE13>0,CG12/BE13,0) -> 0.82220581 | BU12: Methanisation | BV12: ='Bilan 2015'!$E$11+'Bilan 2015'!$I$13*'Bilan 2015'!$G$11/'Bilan 2015'!$H$13 -> 0.014033925 | BW12: ='Bilan 2020'!$E$11+'Bilan 2020'!$I$13*'Bilan 2020'!$G$11/'Bilan 2020'!$H$13 -> 2.5937613 | BX12: ='Bilan 2023 réel'!$E$11+'Bilan 2023 réel'!$I$13*'Bilan 2023 réel'!$G$11/'Bilan 2023 réel'!$H$13 -> 3.2377513 | BY12: ='Bilan 2025'!$E$11+'Bilan 2025'!$I$13*'Bilan 2025'!$G$11/'Bilan 2025'!$H$13 -> 0.24082301 | BZ12: ='Bilan 2028'!$E$11+'Bilan 2028'!$I$13*'Bilan 2028'!$G$11/'Bilan 2028'!$H$13 -> 0.23175037 | CA12: ='Bilan 2030'!$E$11+'Bilan 2030'!$I$13*'Bilan 2030'!$G$11/'Bilan 2030'!$H$13 -> 0.22596846 | CB12: ='Bilan 2033'!$E$11+'Bilan 2033'!$I$13*'Bilan 2033'!$G$11/'Bilan 2033'!$H$13 -> 0.22524785 | CC12: ='Bilan 2035'!$E$11+'Bilan 2035'!$I$13*'Bilan 2035'!$G$11/'Bilan 2035'!$H$13 -> 0.22472457 | CD12: ='Bilan 2038'!$E$11+'Bilan 2038'!$I$13*'Bilan 2038'!$G$11/'Bilan 2038'!$H$13 -> 0.21869718 | CE12: ='Bilan 2040'!$E$11+'Bilan 2040'!$I$13*'Bilan 2040'!$G$11/'Bilan 2040'!$H$13 -> 0.21474015 | CF12: ='Bilan 2045'!$E$11+'Bilan 2045'!$I$13*'Bilan 2045'!$G$11/'Bilan 2045'!$H$13 -> 0.20487857 | CG12: ='Bilan 2050'!$E$11+'Bilan 2050'!$I$13*'Bilan 2050'!$G$11/'Bilan 2050'!$H$13 -> 0.45726183 | CJ12: Methanisation | CK12: =IF(AT13>0,DA12/AT13,0) -> 0.07992104 | CL12: =IF(AU13>0,DB12/AU13,0) -> 0.087045 | CM12: =IF(AV13>0,DC12/AV13,0) -> 0.08870692 | CN12: =IF(AW13>0,DD12/AW13,0) -> 0.089854061 | CO12: =IF(AX13>0,DE12/AX13,0) -> 0.089671267 | CP12: =IF(AY13>0,DF12/AY13,0) -> 0.089556555 | CQ12: =IF(AZ13>0,DG12/AZ13,0) -> 0.089042391 | CR12: =IF(BA13>0,DH12/BA13,0) -> 0.088721272 | ... CV12: =IF(BE13>0,DL12/BE13,0) -> 0.086973825 | CY12: Méthanisation | DA12: ='Bilan 2015'!$K$13*'Bilan 2015'!$G$11/SUM('Bilan 2015'!$G$7:$G$19) -> 0.00088598412 | DB12: ='Bilan 2020'!$K$13*'Bilan 2020'!$G$11/SUM('Bilan 2020'!$G$7:$G$19) -> 0.18301588 | DC12: ='Bilan 2023 réel'!$K$13*'Bilan 2023 réel'!$G$11/SUM('Bilan 2023 réel'!$G$7:$G$19) -> 0.22929853 | DD12: ='Bilan 2025'!$K$13*'Bilan 2025'!$G$11/SUM('Bilan 2025'!$G$7:$G$19) -> 0.017259143 | DE12: ='Bilan 2028'!$K$13*'Bilan 2028'!$G$11/SUM('Bilan 2028'!$G$7:$G$19) -> 0.017235668 | DF12: ='Bilan 2030'!$K$13*'Bilan 2030'!$G$11/SUM('Bilan 2030'!$G$7:$G$19) -> 0.017305824 | DG12: ='Bilan 2033'!$K$13*'Bilan 2033'!$G$11/SUM('Bilan 2033'!$G$7:$G$19) -> 0.018270341 | DH12: ='Bilan 2035'!$K$13*'Bilan 2035'!$G$11/SUM('Bilan 2035'!$G$7:$G$19) -> 0.01893031 | DI12: ='Bilan 2038'!$K$13*'Bilan 2038'!$G$11/SUM('Bilan 2038'!$G$7:$G$19) -> 0.019434194 | DJ12: ='Bilan 2040'!$K$13*'Bilan 2040'!$G$11/SUM('Bilan 2040'!$G$7:$G$19) -> 0.019767206 | DK12: ='Bilan 2045'!$K$13*'Bilan 2045'!$G$11/SUM('Bilan 2045'!$G$7:$G$19) -> 0.020401158 | DL12: ='Bilan 2050'!$K$13*'Bilan 2050'!$G$11/SUM('Bilan 2050'!$G$7:$G$19) -> 0.048369654
