Workbook

Sheet Feuil1
B1: 2004 | C1: 2005 | D1: 2006 | E1: 2007 | F1: 2008 | G1: 2009 | H1: 2010 | I1: 2011 | J1: 2012 | K1: 2013 | L1: 2014 | M1: 2015 | N1: 2016 | O1: 2017 | P1: 2018 | Q1: 2019 | R1: 2020 | S1: 2021 | T1: 2022 | U1: 2023 | V1: 2024 | W1: 2025 | X1: 2026 | Y1: 2027 | Z1: 2028 | AA1: 2029 | AB1: 2030 | AC1: 2031 | AD1: 2032 | AE1: 2033 | AF1: 2034 | AG1: 2035 | AH1: 2036 | AI1: 2037 | AJ1: 2038 | AK1: 2039 | AL1: 2040 | AM1: 2041 | AN1: 2042 | AO1: 2043 | AP1: 2044 | AQ1: 2045 | AR1: 2046 | AS1: 2047 | AT1: 2048 | AU1: 2049 | AV1: 2050
A2: IA_FC_2401 | B2: 0 | C2: 0 | D2: 0 | E2: 0 | F2: 0 | G2: 0 | H2: 0 | I2: 0 | J2: 0 | K2: 0 | L2: 0 | M2: 0 | N2: 0 | O2: 0 | P2: 0 | Q2: 0 | R2: 0 | S2: 0 | T2: 0 | U2: 0 | V2: 0 | W2: 0 | X2: 0 | Y2: 0 | Z2: 0 | AA2: 0 | AB2: 0 | AC2: 0 | AD2: 0 | AE2: 0 | AF2: 0 | AG2: 0 | AH2: 0 | AI2: 0 | AJ2: 0 | AK2: 0 | AL2: 0 | AM2: 0 | AN2: 0 | AO2: 0 | AP2: 0 | AQ2: 0 | AR2: 0 | AS2: 0 | AT2: 0 | AU2: 0 | AV2: 0
A3: IA_FC_2402 | B3: 0 | C3: 0 | D3: 0 | E3: 0 | F3: 0 | G3: 0 | H3: 0 | I3: 0 | J3: 0 | K3: 0 | L3: 0 | M3: 0 | N3: 0 | O3: 0 | P3: 0 | Q3: 0 | R3: 0 | S3: 0 | T3: 0 | U3: 1132.0882 | V3: 1132.0882 | W3: 1132.0882 | X3: 1132.0882 | Y3: 1132.0882 | Z3: 1132.0882 | AA3: 1132.0882 | AB3: 1132.0882 | AC3: 1132.0882 | AD3: 1132.0882 | AE3: 1132.0882 | AF3: 1132.0882 | AG3: 1132.0882 | AH3: 1132.0882 | AI3: 1132.0882 | AJ3: 1132.0882 | AK3: 1132.0882 | AL3: 1132.0882 | AM3: 1132.0882 | AN3: 1132.0882 | AO3: 1132.0882 | AP3: 1132.0882 | AQ3: 1132.0882 | AR3: 1132.0882 | AS3: 1132.0882 | AT3: 1132.0882 | AU3: 1132.0882 | AV3: 1132.0882 | AW3: =SUM(G3:AV3) -> 31698.468
A4: IA_FC_2403 | B4: 0 | C4: 0 | D4: 0 | E4: 0 | F4: 0 | G4: 0 | H4: 0 | I4: 0 | J4: 0 | K4: 0 | L4: 0 | M4: 0 | N4: 0 | O4: 0 | P4: 0 | Q4: 0 | R4: 0 | S4: 0 | T4: 0 | U4: 161.58086 | V4: 161.58086 | W4: 161.58086 | X4: 161.58086 | Y4: 161.58086 | Z4: 161.58086 | AA4: 161.58086 | AB4: 161.58086 | AC4: 161.58086 | AD4: 161.58086 | AE4: 161.58086 | AF4: 161.58086 | AG4: 161.58086 | AH4: 161.58086 | AI4: 161.58086 | AJ4: 161.58086 | AK4: 161.58086 | AL4: 161.58086 | AM4: 161.58086 | AN4: 161.58086 | AO4: 161.58086 | AP4: 161.58086 | AQ4: 161.58086 | AR4: 161.58086 | AS4: 161.58086 | AT4: 161.58086 | AU4: 161.58086 | AV4: 161.58086
A5: IA_FC_2404 | B5: 0 | C5: 0 | D5: 0 | E5: 0 | F5: 0 | G5: 0 | H5: 0 | I5: 0 | J5: 0 | K5: 0 | L5: 0 | M5: 0 | N5: 0 | O5: 0 | P5: 0 | Q5: 0 | R5: 0 | S5: 0 | T5: 0 | U5: 35.189531 | V5: 35.189531 | W5: 35.189531 | X5: 35.189531 | Y5: 35.189531 | Z5: 35.189531 | AA5: 35.189531 | AB5: 35.189531 | AC5: 35.189531 | AD5: 35.189531 | AE5: 35.189531 | AF5: 35.189531 | AG5: 35.189531 | AH5: 35.189531 | AI5: 35.189531 | AJ5: 35.189531 | AK5: 35.189531 | AL5: 35.189531 | AM5: 35.189531 | AN5: 35.189531 | AO5: 35.189531 | AP5: 35.189531 | AQ5: 35.189531 | AR5: 35.189531 | AS5: 35.189531 | AT5: 35.189531 | AU5: 35.189531 | AV5: 35.189531
A6: IA_FC_2405 | B6: 0 | C6: 0 | D6: 0 | E6: 0 | F6: 0 | G6: 0 | H6: 0 | I6: 0 | J6: 0 | K6: 0 | L6: 0 | M6: 0 | N6: 0 | O6: 0 | P6: 0 | Q6: 0 | R6: 0 | S6: 0 | T6: 0 | U6: 250.47176 | V6: 250.47176 | W6: 250.47176 | X6: 250.47176 | Y6: 250.47176 | Z6: 250.47176 | AA6: 250.47176 | AB6: 250.47176 | AC6: 250.47176 | AD6: 250.47176 | AE6: 250.47176 | AF6: 250.47176 | AG6: 250.47176 | AH6: 250.47176 | AI6: 250.47176 | AJ6: 250.47176 | AK6: 250.47176 | AL6: 250.47176 | AM6: 250.47176 | AN6: 250.47176 | AO6: 250.47176 | AP6: 250.47176 | AQ6: 250.47176 | AR6: 250.47176 | AS6: 250.47176 | AT6: 250.47176 | AU6: 250.47176 | AV6: 250.47176
A7: IA_FC_2406 | B7: 0 | C7: 0 | D7: 0 | E7: 0 | F7: 0 | G7: 0 | H7: 0 | I7: 0 | J7: 0 | K7: 0 | L7: 0 | M7: 0 | N7: 0 | O7: 0 | P7: 0 | Q7: 0 | R7: 0 | S7: 0 | T7: 0 | U7: 123.80597 | V7: 123.80597 | W7: 123.80597 | X7: 123.80597 | Y7: 123.80597 | Z7: 123.80597 | AA7: 123.80597 | AB7: 123.80597 | AC7: 123.80597 | AD7: 123.80597 | AE7: 123.80597 | AF7: 123.80597 | AG7: 123.80597 | AH7: 123.80597 | AI7: 123.80597 | AJ7: 123.80597 | AK7: 123.80597 | AL7: 123.80597 | AM7: 123.80597 | AN7: 123.80597 | AO7: 123.80597 | AP7: 123.80597 | AQ7: 123.80597 | AR7: 123.80597 | AS7: 123.80597 | AT7: 123.80597 | AU7: 123.80597 | AV7: 123.80597
A8: IA_2401_1 | B8: 1593.0327 | C8: 1618.6093 | D8: 1727.143 | E8: 844.37484 | F8: 0.10000144 | G8: 0.10000277 | H8: 1351.8852 | I8: 473.99782 | J8: 0.10001733 | K8: 0.10002756 | L8: 674.58535 | M8: 1342.6111 | N8: 1492.1502 | O8: 699.82046 | P8: 0.10008548 | Q8: 0.10009398 | R8: 0.10010003 | S8: 0.10010437 | T8: 0.10010745 | U8: 0.10010966 | V8: 2158.3642 | W8: 2270.1134 | X8: 710.05805 | Y8: 913.46272 | Z8: 1000.0049 | AA8: 1055.945 | AB8: 1119.114 | AC8: 979.40625 | AD8: 996.6805 | AE8: 995.60424 | AF8: 1006.403 | AG8: 1030.1449 | AH8: 1113.81 | AI8: 1112.9846 | AJ8: 1137.7095 | AK8: 1153.4177 | AL8: 1168.4645 | AM8: 832.03808 | AN8: 833.63203 | AO8: 833.53713 | AP8: 839.11393 | AQ8: 834.0138 | AR8: 794.97712 | AS8: 791.92485 | AT8: 790.75913 | AU8: 789.04569 | AV8: 796.23993
A9: IA_2402_1 | B9: 43.535458 | C9: 44.234434 | D9: 47.032948 | E9: 505.35763 | F9: 475.60752 | G9: 442.87598 | H9: 533.11449 | I9: 469.9891 | J9: 352.80714 | K9: 352.38614 | L9: 350.6816 | M9: 338.4388 | N9: 297.99303 | O9: 205.69373 | P9: 34.725833 | Q9: 126.85727 | R9: 122.79613 | S9: 248.23198 | T9: 194.00723 | U9: 181.5035 | V9: 213.22443 | W9: 246.69623 | X9: 223.11265 | Y9: 255.79827 | Z9: 274.27119 | AA9: 293.49453 | AB9: 310.30084 | AC9: 293.50236 | AD9: 301.54905 | AE9: 306.3633 | AF9: 314.14746 | AG9: 323.16005 | AH9: 260.93537 | AI9: 261.95532 | AJ9: 271.33523 | AK9: 276.72308 | AL9: 282.44145 | AM9: 237.24347 | AN9: 238.79316 | AO9: 242.1428 | AP9: 245.11308 | AQ9: 245.86589 | AR9: 213.41057 | AS9: 213.57571 | AT9: 213.54606 | AU9: 214.01423 | AV9: 216.39592 | AW9: =SUM(G9:AV9) -> 11241.214
A10: IA_2403_1 | B10: 23.271712 | C10: 23.645346 | D10: 24.888875 | E10: 17.413176 | F10: 2.175284 | G10: 0.10000277 | H10: 19.036282 | I10: 6.4264608 | J10: 0.10001733 | K10: 1.8628794 | L10: 10.02245 | M10: 18.770681 | N10: 208.10267 | O10: 212.65718 | P10: 195.39996 | Q10: 217.88016 | R10: 228.67337 | S10: 677.13726 | T10: 649.31501 | U10: 655.43859 | V10: 0.10011113 | W10: 0.10011209 | X10: 6.5124674 | Y10: 35.45145 | Z10: 43.597674 | AA10: 47.520156 | AB10: 50.824043 | AC10: 83.094774 | AD10: 87.255049 | AE10: 90.463118 | AF10: 94.385071 | AG10: 98.270159 | AH10: 108.0227 | AI10: 111.08768 | AJ10: 115.70492 | AK10: 120.73515 | AL10: 124.97231 | AM10: 107.53157 | AN10: 109.27263 | AO10: 111.62396 | AP10: 114.03258 | AQ10: 115.83825 | AR10: 106.82835 | AS10: 108.34418 | AT10: 109.89292 | AU10: 111.6005 | AV10: 113.96441
A11: IA_2404_1 | B11: 32.111684 | C11: 32.627247 | D11: 34.690536 | E11: 39.576202 | F11: 16.268757 | G11: 5.3331602 | H11: 43.650771 | I11: 25.585776 | J11: 3.8663194 | K11: 16.041094 | L11: 31.889361 | M11: 47.388328 | N11: 336.78437 | O11: 342.99329 | P11: 309.54049 | Q11: 344.49325 | R11: 360.12081 | S11: 217.96152 | T11: 139.70181 | U11: 138.09916 | V11: 0.10011113 | W11: 0.10011209 | X11: 37.597671 | Y11: 57.161605 | Z11: 63.879983 | AA11: 67.657885 | AB11: 71.618372 | AC11: 56.170816 | AD11: 56.921331 | AE11: 56.967392 | AF11: 57.552186 | AG11: 58.6163 | AH11: 59.786288 | AI11: 59.59871 | AJ11: 61.204665 | AK11: 62.122659 | AL11: 63.038719 | AM11: 51.494556 | AN11: 51.513166 | AO11: 51.876108 | AP11: 52.267141 | AQ11: 52.132583 | AR11: 54.805078 | AS11: 54.878798 | AT11: 54.974031 | AU11: 55.165779 | AV11: 55.833835
A12: IA_2405_1 | B12: 24.700273 | C12: 25.096844 | D12: 26.683936 | E12: 54.922149 | F12: 39.820107 | G12: 32.94986 | H12: 65.777056 | I12: 52.569866 | J12: 35.934446 | K12: 49.169069 | L12: 66.368835 | M12: 86.793276 | N12: 201.33613 | O12: 198.12003 | P12: 165.51646 | Q12: 196.5436 | R12: 208.85339 | S12: 387.34386 | T12: 326.32141 | U12: 330.49336 | V12: 0.10011113 | W12: 0.10011209 | X12: 52.598318 | Y12: 72.80301 | Z12: 80.511179 | AA12: 85.820833 | AB12: 91.053833 | AC12: 61.580654 | AD12: 62.394196 | AE12: 62.490309 | AF12: 63.267091 | AG12: 64.484131 | AH12: 65.474457 | AI12: 65.313485 | AJ12: 67.080188 | AK12: 68.255877 | AL12: 69.298367 | AM12: 57.192361 | AN12: 57.259193 | AO12: 57.698583 | AP12: 58.177785 | AQ12: 58.089334 | AR12: 60.083471 | AS12: 60.19328 | AT12: 60.323025 | AU12: 60.552988 | AV12: 61.303778
A13: IA_2406_1 | B13: 60.912339 | C13: 61.890306 | D13: 65.804838 | E13: 453.68012 | F13: 538.55401 | G13: 663.01006 | H13: 989.28063 | I13: 1206.0699 | J13: 1422.1293 | K13: 1912.2761 | L13: 2616.4383 | M13: 3627.6439 | N13: 271.66193 | O13: 0.10007564 | P13: 0.10008548 | Q13: 0.10009398 | R13: 0.10010003 | S13: 2394.617 | T13: 2103.9046 | U13: 2143.5916 | V13: 0.10011113 | W13: 0.10011209 | X13: 950.35753 | Y13: 1091.9559 | Z13: 1174.9506 | AA13: 1278.7473 | AB13: 1359.0153 | AC13: 1137.7319 | AD13: 1173.6278 | AE13: 1201.9849 | AF13: 1261.001 | AG13: 1303.9192 | AH13: 1090.838 | AI13: 1104.9455 | AJ13: 1143.7055 | AK13: 1185.3302 | AL13: 1216.5194 | AM13: 1053.0993 | AN13: 1065.3045 | AO13: 1083.2059 | AP13: 1101.355 | AQ13: 1112.0933 | AR13: 1288.5776 | AS13: 1307.5524 | AT13: 1327.0372 | AU13: 1348.2208 | AV13: 1377.2702
A14: IA_2401_2 | B14: 1593.0327 | C14: 1618.6093 | D14: 1727.143 | E14: 844.37484 | F14: 0.10000144 | G14: 0.10000277 | H14: 1351.8852 | I14: 473.99782 | J14: 0.10001733 | K14: 0.10002756 | L14: 674.58535 | M14: 1342.6111 | N14: 1492.1502 | O14: 699.82046 | P14: 0.10008548 | Q14: 0.10009398 | R14: 0.10010003 | S14: 0.10010437 | T14: 0.10010745 | U14: 0.10010967 | V14: 2046.4313 | W14: 2080.4003 | X14: 517.05339 | Y14: 696.66734 | Z14: 770.06865 | AA14: 811.87407 | AB14: 875.54188 | AC14: 714.91044 | AD14: 726.14792 | AE14: 721.31665 | AF14: 729.15652 | AG14: 747.87026 | AH14: 815.32852 | AI14: 812.97911 | AJ14: 834.69867 | AK14: 846.66294 | AL14: 857.78488 | AM14: 551.63776 | AN14: 560.27322 | AO14: 561.09374 | AP14: 566.78433 | AQ14: 562.19154 | AR14: 528.58396 | AS14: 526.70981 | AT14: 527.40958 | AU14: 523.27473 | AV14: 533.53193
A15: IA_2402_2 | B15: 43.535458 | C15: 44.234434 | D15: 47.032948 | E15: 505.35763 | F15: 475.60752 | G15: 442.87598 | H15: 533.11449 | I15: 469.9891 | J15: 352.80714 | K15: 352.38614 | L15: 350.6816 | M15: 338.4388 | N15: 297.99303 | O15: 205.69373 | P15: 34.725833 | Q15: 126.85727 | R15: 122.79613 | S15: 248.23198 | T15: 194.00723 | U15: 1281.3524 | V15: 1287.4938 | W15: 1309.2166 | X15: 1287.2694 | Y15: 1314.1429 | Z15: 1327.2241 | AA15: 1339.4983 | AB15: 1352.4377 | AC15: 1326.2509 | AD15: 1327.2887 | AE15: 1325.6242 | AF15: 1327.1684 | AG15: 1329.5038 | AH15: 1263.2989 | AI15: 1259.0693 | AJ15: 1261.8171 | AK15: 1261.1502 | AL15: 1260.5175 | AM15: 1213.3397 | AN15: 1210.8303 | AO15: 1207.7063 | AP15: 1204.6551 | AQ15: 1199.3035 | AR15: 1165.6626 | AS15: 1160.616 | AT15: 1155.6692 | AU15: 1149.4596 | AV15: 1147.505 | AW15: =SUM(G15:AV15) -> 39325.67 | AX15: =AW15-AW9 -> 28084.456
A16: IA_2403_2 | B16: 23.271712 | C16: 23.645346 | D16: 24.888875 | E16: 17.413176 | F16: 2.175284 | G16: 0.10000277 | H16: 19.036282 | I16: 6.4264608 | J16: 0.10001733 | K16: 1.8628794 | L16: 10.02245 | M16: 18.770681 | N16: 208.10267 | O16: 212.65718 | P16: 195.39996 | Q16: 217.88016 | R16: 228.67337 | S16: 677.13726 | T16: 649.31501 | U16: 813.51186 | V16: 0.10011125 | W16: 0.10011234 | X16: 176.39405 | Y16: 195.15836 | Z16: 198.60689 | AA16: 199.39825 | AB16: 200.59443 | AC16: 231.70946 | AD16: 232.36224 | AE16: 232.39658 | AF16: 233.40724 | AG16: 234.40544 | AH16: 241.11843 | AI16: 241.29794 | AJ16: 243.34563 | AK16: 245.60085 | AL16: 247.05428 | AM16: 227.03166 | AN16: 226.9645 | AO16: 226.86256 | AP16: 226.75933 | AQ16: 225.95857 | AR16: 215.18648 | AS16: 214.45374 | AT16: 213.76046 | AU16: 212.71373 | AV16: 213.08787
A17: IA_2404_2 | B17: 32.111684 | C17: 32.627247 | D17: 34.690536 | E17: 39.576202 | F17: 16.268757 | G17: 5.3331602 | H17: 43.650771 | I17: 25.585776 | J17: 3.8663194 | K17: 16.041094 | L17: 31.889361 | M17: 47.388328 | N17: 336.78437 | O17: 342.99329 | P17: 309.54049 | Q17: 344.49325 | R17: 360.12081 | S17: 217.96152 | T17: 139.70181 | U17: 171.90198 | V17: 0.10011125 | W17: 0.10011234 | X17: 60.533822 | Y17: 76.982952 | Z17: 81.667317 | AA17: 83.533707 | AB17: 86.366389 | AC17: 68.98469 | AD17: 68.340661 | AE17: 67.097686 | AF17: 66.458942 | AG17: 66.21815 | AH17: 65.742703 | AI17: 64.481994 | AJ17: 64.881918 | AK17: 64.548237 | AL17: 64.195428 | AM17: 52.595883 | AN17: 51.90405 | AO17: 51.085984 | AP17: 50.284939 | AQ17: 48.945778 | AR17: 50.218475 | AS17: 49.133316 | AT17: 48.091366 | AU17: 46.789454 | AV17: 46.451585
A18: IA_2405_2 | B18: 24.700273 | C18: 25.096844 | D18: 26.683936 | E18: 54.922149 | F18: 39.820107 | G18: 32.94986 | H18: 65.777056 | I18: 52.569866 | J18: 35.934446 | K18: 49.169069 | L18: 66.368835 | M18: 86.793276 | N18: 201.33613 | O18: 198.12003 | P18: 165.51646 | Q18: 196.5436 | R18: 208.85339 | S18: 387.34386 | T18: 326.32141 | U18: 571.29274 | V18: 0.10011125 | W18: 0.10011234 | X18: 287.0611 | Y18: 296.71379 | Z18: 299.21372 | AA18: 300.43274 | AB18: 302.66148 | AC18: 267.68682 | AD18: 265.24608 | AE18: 262.03239 | AF18: 259.66781 | AG18: 257.69521 | AH18: 254.92263 | AI18: 251.76452 | AJ18: 250.35483 | AK18: 248.21694 | AL18: 245.87949 | AM18: 231.40561 | AN18: 228.87443 | AO18: 225.79209 | AP18: 222.79181 | AQ18: 219.07286 | AR18: 217.9926 | AS18: 214.73298 | AT18: 211.44851 | AU18: 207.61117 | AV18: 205.29302
A19: IA_2406_2 | B19: 60.912339 | C19: 61.890306 | D19: 65.804838 | E19: 453.68012 | F19: 538.55401 | G19: 663.01006 | H19: 989.28063 | I19: 1206.0699 | J19: 1422.1293 | K19: 1912.2761 | L19: 2616.4383 | M19: 3627.6439 | N19: 271.66193 | O19: 0.10007564 | P19: 0.10008548 | Q19: 0.10009398 | R19: 0.10010003 | S19: 2394.617 | T19: 2103.9046 | U19: 2269.4796 | V19: 0.10011125 | W19: 0.10011234 | X19: 964.2863 | Y19: 1080.499 | Z19: 1141.7011 | AA19: 1221.1924 | AB19: 1284.5377 | AC19: 1043.5055 | AD19: 1060.438 | AE19: 1070.8368 | AF19: 1110.4202 | AG19: 1133.7362 | AH19: 918.58232 | AI19: 920.08792 | AJ19: 944.39241 | AK19: 969.87697 | AL19: 985.58694 | AM19: 824.76842 | AN19: 829.41387 | AO19: 834.37086 | AP19: 839.31699 | AQ19: 836.96345 | AR19: 976.00824 | AS19: 979.22621 | AT19: 983.52993 | AU19: 984.68886 | AV19: 999.49503
A20: IA_N_2401_1 | B20: 1593.0327 | C20: 1618.6093 | D20: 1727.1427 | E20: 844.37105 | F20: 0.1 | G20: 0.1 | H20: 1351.8196 | I20: 473.95339 | J20: 0.1 | K20: 0.1 | L20: 674.31727 | M20: 1341.916 | N20: 1491.1892 | O20: 699.29153 | P20: 0.1 | Q20: 0.1 | R20: 0.1 | S20: 0.1 | T20: 0.1 | U20: 0.1 | V20: 2155.9683 | W20: 2267.5718 | X20: 709.25769 | Y20: 912.4267 | Z20: 998.86315 | AA20: 1054.7301 | AB20: 1117.8154 | AC20: 978.25952 | AD20: 995.50338 | AE20: 994.41914 | AF20: 1005.1969 | AG20: 1028.9033 | AH20: 1112.4613 | AI20: 1111.6318 | AJ20: 1136.3222 | AK20: 1152.007 | AL20: 1167.0313 | AM20: 831.01395 | AN20: 832.60171 | AO20: 832.50207 | AP20: 838.06642 | AQ20: 832.96668 | AR20: 793.97296 | AS20: 790.91826 | AT20: 789.74755 | AU20: 788.02971 | AV20: 795.20847
A21: IA_N_2402_1 | B21: 43.535458 | C21: 44.234434 | D21: 47.032938 | E21: 505.35537 | F21: 475.60067 | G21: 442.8637 | H21: 533.08863 | I21: 469.94504 | J21: 352.74603 | K21: 352.28903 | L21: 350.54223 | M21: 338.26359 | N21: 297.8011 | O21: 205.53826 | P21: 34.696173 | Q21: 126.73816 | R21: 122.67341 | S21: 247.97317 | T21: 193.79899 | U21: 181.30469 | V21: 212.98773 | W21: 246.42003 | X21: 222.86117 | Y21: 255.50815 | Z21: 273.95803 | AA21: 293.15686 | AB21: 309.94078 | AC21: 293.15872 | AD21: 301.19291 | AE21: 305.99862 | AF21: 313.77097 | AG21: 322.77055 | AH21: 260.6194 | AI21: 261.63692 | AJ21: 271.00436 | AK21: 276.38463 | AL21: 282.09501 | AM21: 236.95145 | AN21: 238.49802 | AO21: 241.84212 | AP21: 244.80709 | AQ21: 245.5572 | AR21: 213.141 | AS21: 213.30424 | AT21: 213.27288 | AU21: 213.73866 | AV21: 216.1156 | AW21: =AV33-AU33*(1-AV56) -> 216.1156
A22: IA_N_2403_1 | B22: 23.271712 | C22: 23.645346 | D22: 24.88887 | E22: 17.413098 | F22: 2.1752527 | G22: 0.1 | H22: 19.035359 | I22: 6.4258584 | J22: 0.1 | K22: 1.862366 | L22: 10.018467 | M22: 18.760963 | N22: 207.96864 | O22: 212.49645 | P22: 195.23306 | Q22: 217.6756 | R22: 228.44485 | S22: 676.43129 | T22: 648.61805 | U22: 654.72065 | V22: 0.1 | W22: 0.1 | X22: 6.5051267 | Y22: 35.411242 | Z22: 43.547895 | AA22: 47.465483 | AB22: 50.765068 | AC22: 82.997484 | AD22: 87.151997 | AE22: 90.355437 | AF22: 94.271954 | AG22: 98.151715 | AH22: 107.8919 | AI22: 110.95266 | AJ22: 115.56382 | AK22: 120.58749 | AL22: 124.81902 | AM22: 107.39921 | AN22: 109.13758 | AO22: 111.48535 | AP22: 113.89023 | AQ22: 115.69281 | AR22: 106.69341 | AS22: 108.20647 | AT22: 109.75234 | AU22: 111.4568 | AV22: 113.81678
A23: IA_N_2404_1 | B23: 32.111684 | C23: 32.627247 | D23: 34.690529 | E23: 39.576025 | F23: 16.268522 | G23: 5.3330123 | H23: 43.648653 | I23: 25.583377 | J23: 3.8656497 | K23: 16.036674 | L23: 31.876688 | M23: 47.363794 | N23: 336.56746 | O23: 342.73405 | P23: 309.27611 | Q23: 344.16981 | R23: 359.76093 | S23: 217.73428 | T23: 139.55186 | U23: 137.94789 | V23: 0.1 | W23: 0.1 | X23: 37.555292 | Y23: 57.096774 | Z23: 63.807046 | AA23: 67.580043 | AB23: 71.535268 | AC23: 56.105049 | AD23: 56.854104 | AE23: 56.899582 | AF23: 57.483211 | AG23: 58.54565 | AH23: 59.713892 | AI23: 59.526269 | AJ23: 61.130032 | AK23: 62.046681 | AL23: 62.961397 | AM23: 51.431173 | AN23: 51.449498 | AO23: 51.811689 | AP23: 52.201894 | AQ23: 52.06713 | AR23: 54.735852 | AS23: 54.809044 | AT23: 54.903706 | AU23: 55.094747 | AV23: 55.761507
A24: IA_N_2405_1 | B24: 24.700273 | C24: 25.096844 | D24: 26.68393 | E24: 54.921902 | F24: 39.819533 | G24: 32.948946 | H24: 65.773865 | I24: 52.564939 | J24: 35.928222 | K24: 49.15552 | L24: 66.34246 | M24: 86.748342 | N24: 201.20646 | O24: 197.97029 | P24: 165.37509 | Q24: 196.35907 | R24: 208.64467 | S24: 386.94002 | T24: 325.97114 | U24: 330.13135 | V24: 0.1 | W24: 0.1 | X24: 52.539031 | Y24: 72.72044 | Z24: 80.419252 | AA24: 85.722094 | AB24: 90.948176 | AC24: 61.508553 | AD24: 62.320506 | AE24: 62.415924 | AF24: 63.191267 | AG24: 64.40641 | AH24: 65.395172 | AI24: 65.234098 | AJ24: 66.99839 | AK24: 68.172397 | AL24: 69.213368 | AM24: 57.121964 | AN24: 57.188424 | AO24: 57.626934 | AP24: 58.105159 | AQ24: 58.016402 | AR24: 60.007578 | AS24: 60.116771 | AT24: 60.245857 | AU24: 60.475019 | AV24: 61.224363
A25: IA_N_2406_1 | B25: 60.912339 | C25: 61.890306 | D25: 65.804824 | E25: 453.67809 | F25: 538.54626 | G25: 662.99167 | H25: 989.23263 | I25: 1205.9569 | J25: 1421.883 | K25: 1911.7491 | L25: 2615.3985 | M25: 3625.7658 | N25: 271.48696 | O25: 0.1 | P25: 0.1 | Q25: 0.1 | R25: 0.1 | S25: 2392.1204 | T25: 2101.6463 | U25: 2141.2436 | V25: 0.1 | W25: 0.1 | X25: 949.28632 | Y25: 1090.7174 | Z25: 1173.6091 | AA25: 1277.2761 | AB25: 1357.4383 | AC25: 1136.3998 | AD25: 1172.2417 | AE25: 1200.5541 | AF25: 1259.4897 | AG25: 1302.3476 | AH25: 1089.5171 | AI25: 1103.6024 | AJ25: 1142.3109 | AK25: 1183.8805 | AL25: 1215.0273 | AM25: 1051.803 | AN25: 1063.9878 | AO25: 1081.8608 | AP25: 1099.9801 | AQ25: 1110.697 | AR25: 1286.9499 | AS25: 1305.8905 | AT25: 1325.3396 | AU25: 1346.4848 | AV25: 1375.4861
A26: IA_N_2401_2 | B26: 1593.0327 | C26: 1618.6093 | D26: 1727.1427 | E26: 844.37105 | F26: 0.1 | G26: 0.1 | H26: 1351.8196 | I26: 473.95339 | J26: 0.1 | K26: 0.1 | L26: 674.31727 | M26: 1341.916 | N26: 1491.1892 | O26: 699.29153 | P26: 0.1 | Q26: 0.1 | R26: 0.1 | S26: 0.1 | T26: 0.1 | U26: 0.1 | V26: 2044.1572 | W26: 2078.0659 | X26: 516.46887 | Y26: 695.87442 | Z26: 769.18577 | AA26: 810.93549 | AB26: 874.52039 | AC26: 714.06836 | AD26: 725.28467 | AE26: 720.45192 | AF26: 728.27599 | AG26: 746.96154 | AH26: 814.33269 | AI26: 811.98191 | AJ26: 833.67095 | AK26: 845.61679 | AL26: 856.72128 | AM26: 550.95092 | AN26: 559.57226 | AO26: 560.38793 | AP26: 566.06703 | AQ26: 561.47537 | AR26: 527.90596 | AS26: 526.02939 | AT26: 526.72329 | AU26: 522.58876 | AV26: 532.82763 | AX26: =SUM(B27:AV27)-SUM(B21:AV21) -> 28050.345
A27: IA_N_2402_2 | B27: 43.535458 | C27: 44.234434 | D27: 47.032938 | E27: 505.35537 | F27: 475.60067 | G27: 442.8637 | H27: 533.08863 | I27: 469.94504 | J27: 352.74603 | K27: 352.28903 | L27: 350.54223 | M27: 338.26359 | N27: 297.8011 | O27: 205.53826 | P27: 34.696173 | Q27: 126.73816 | R27: 122.67341 | S27: 247.97317 | T27: 193.79899 | U27: 1279.9486 | V27: 1286.0631 | W27: 1307.7475 | X27: 1285.8142 | Y27: 1312.6472 | Z27: 1325.7024 | AA27: 1337.9497 | AB27: 1350.8598 | AC27: 1324.6888 | AD27: 1325.7108 | AE27: 1324.035 | AF27: 1325.5657 | AG27: 1327.8884 | AH27: 1261.756 | AI27: 1257.525 | AJ27: 1260.2635 | AK27: 1259.5919 | AL27: 1258.9546 | AM27: 1211.829 | AN27: 1209.3154 | AO27: 1206.1871 | AP27: 1203.1305 | AQ27: 1197.7757 | AR27: 1164.1674 | AS27: 1159.1166 | AT27: 1154.1654 | AU27: 1147.9527 | AV27: 1145.9903
A28: IA_N_2403_2 | B28: 23.271712 | C28: 23.645346 | D28: 24.88887 | E28: 17.413098 | F28: 2.1752527 | G28: 0.1 | H28: 19.035359 | I28: 6.4258584 | J28: 0.1 | K28: 1.862366 | L28: 10.018467 | M28: 18.760963 | N28: 207.96864 | O28: 212.49645 | P28: 195.23306 | Q28: 217.6756 | R28: 228.44485 | S28: 676.43129 | T28: 648.61805 | U28: 812.62062 | V28: 0.1 | W28: 0.1 | X28: 176.19464 | Y28: 194.93623 | Z28: 198.37919 | AA28: 199.16773 | AB28: 200.3604 | AC28: 231.43653 | AD28: 232.08601 | AE28: 232.11797 | AF28: 233.12538 | AG28: 234.12061 | AH28: 240.82393 | AI28: 241.00196 | AJ28: 243.04601 | AK28: 245.29738 | AL28: 246.74794 | AM28: 226.74899 | AN28: 226.68055 | AO28: 226.57718 | AP28: 226.47235 | AQ28: 225.67072 | AR28: 214.91047 | AS28: 214.17671 | AT28: 213.4823 | AU28: 212.43488 | AV28: 212.80658
A29: IA_N_2404_2 | B29: 32.111684 | C29: 32.627247 | D29: 34.690529 | E29: 39.576025 | F29: 16.268522 | G29: 5.3330123 | H29: 43.648653 | I29: 25.583377 | J29: 3.8656497 | K29: 16.036674 | L29: 31.876688 | M29: 47.363794 | N29: 336.56746 | O29: 342.73405 | P29: 309.27611 | Q29: 344.16981 | R29: 359.76093 | S29: 217.73428 | T29: 139.55186 | U29: 171.71365 | V29: 0.1 | W29: 0.1 | X29: 60.46539 | Y29: 76.895333 | Z29: 81.573685 | AA29: 83.437137 | AB29: 86.265625 | AC29: 68.903434 | AD29: 68.259417 | AE29: 67.017248 | AF29: 66.378686 | AG29: 66.13769 | AH29: 65.662406 | AI29: 64.4029 | AJ29: 64.802033 | AK29: 64.46848 | AL29: 64.11583 | AM29: 52.530395 | AN29: 51.839112 | AO29: 51.021722 | AP29: 50.221301 | AQ29: 48.883426 | AR29: 50.154061 | AS29: 49.069844 | AT29: 48.028787 | AU29: 46.728117 | AV29: 46.390265
A30: IA_N_2405_2 | B30: 24.700273 | C30: 25.096844 | D30: 26.68393 | E30: 54.921902 | F30: 39.819533 | G30: 32.948946 | H30: 65.773865 | I30: 52.564939 | J30: 35.928222 | K30: 49.15552 | L30: 66.34246 | M30: 86.748342 | N30: 201.20646 | O30: 197.97029 | P30: 165.37509 | Q30: 196.35907 | R30: 208.64467 | S30: 386.94002 | T30: 325.97114 | U30: 570.66687 | V30: 0.1 | W30: 0.1 | X30: 286.73659 | Y30: 296.37609 | Z30: 298.87067 | AA30: 300.08542 | AB30: 302.30837 | AC30: 267.37152 | AD30: 264.93075 | AE30: 261.71826 | AF30: 259.35423 | AG30: 257.38209 | AH30: 254.61127 | AI30: 251.4557 | AJ30: 250.04658 | AK30: 247.91023 | AL30: 245.57462 | AM30: 231.11749 | AN30: 228.58808 | AO30: 225.50806 | AP30: 222.50985 | AQ30: 218.79378 | AR30: 217.71298 | AS30: 214.45558 | AT30: 211.17336 | AU30: 207.33901 | AV30: 205.02202
A31: IA_N_2406_2 | B31: 60.912339 | C31: 61.890306 | D31: 65.804824 | E31: 453.67809 | F31: 538.54626 | G31: 662.99167 | H31: 989.23263 | I31: 1205.9569 | J31: 1421.883 | K31: 1911.7491 | L31: 2615.3985 | M31: 3625.7658 | N31: 271.48696 | O31: 0.1 | P31: 0.1 | Q31: 0.1 | R31: 0.1 | S31: 2392.1204 | T31: 2101.6463 | U31: 2266.9933 | V31: 0.1 | W31: 0.1 | X31: 963.1962 | Y31: 1079.2693 | Z31: 1140.3921 | AA31: 1219.7806 | AB31: 1283.039 | AC31: 1042.2764 | AD31: 1059.1774 | AE31: 1069.553 | AF31: 1109.0793 | AG31: 1132.3586 | AH31: 917.46039 | AI31: 918.95933 | AJ31: 943.22964 | AK31: 968.67857 | AL31: 984.36487 | AM31: 823.7415 | AN31: 828.37619 | AO31: 833.32129 | AP31: 838.25479 | AQ31: 835.89725 | AR31: 974.75634 | AS31: 977.96122 | AT31: 982.25011 | AU31: 983.39801 | AV31: 998.17562
A32: K_2401_1 | B32: 39425.077 | C32: 40058.06 | D32: 40783.751 | E32: 40608.528 | F32: 39254.704 | G32: 37320.426 | H32: 37739.235 | I32: 37269.707 | J32: 35596.528 | K32: 34656.089 | L32: 34464.004 | M32: 34944.32 | N32: 35561.901 | O32: 35372.145 | P32: 33582.362 | Q32: 32601.767 | R32: 31538.661 | S32: 30075.688 | T32: 28709.646 | U32: 27373.348 | V32: 28844.982 | W32: 30391.429 | X32: 30340.901 | Y32: 30494.806 | Z32: 30731.299 | AA32: 31017.746 | AB32: 31360.118 | AC32: 31554.375 | AD32: 31761.019 | AE32: 31961.412 | AF32: 32167.574 | AG32: 32392.288 | AH32: 32694.942 | AI32: 32989.2 | AJ32: 33300.792 | AK32: 33620.28 | AL32: 33946.804 | AM32: 33929.148 | AN32: 33913.521 | AO32: 33898.185 | AP32: 33888.797 | AQ32: 33874.543 | AR32: 33821.653 | AS32: 33767.03 | AT32: 33712.601 | AU32: 33657.816 | AV32: 33611.579
A33: K_2402_1 | B33: 960.463 | C33: 975.88355 | D33: 993.63998 | E33: 1469.1861 | F33: 1900.7112 | G33: 2286.5536 | H33: 2751.0456 | I33: 3138.4593 | J33: 3397.0515 | K33: 3647.429 | L33: 3888.5484 | M33: 4110.1555 | N33: 4284.652 | O33: 4361.6507 | P33: 4265.4973 | Q33: 4264.2706 | R33: 4259.0159 | S33: 4379.2186 | T33: 4441.641 | U33: 4489.6964 | V33: 4567.9933 | W33: 4677.3735 | X33: 4759.9135 | Y33: 4872.6242 | Z33: 5000.4035 | AA33: 5143.5483 | AB33: 5299.1826 | AC33: 5433.3658 | AD33: 5571.5578 | AE33: 5710.4097 | AF33: 5852.8683 | AG33: 6000.0528 | AH33: 6080.6707 | AI33: 6159.8875 | AJ33: 6246.0952 | AK33: 6335.097 | AL33: 6427.1391 | AM33: 6471.2764 | AN33: 6515.6361 | AO33: 6562.0091 | AP33: 6609.9559 | AQ33: 6657.2145 | AR33: 6670.639 | AS33: 6683.8241 | AT33: 6696.5823 | AU33: 6709.4235 | AV33: 6724.2564 | AW33: =AV33-AU33*(1-AV56) -> 216.1156
A34: K_2403_1 | B34: 513.4118 | C34: 521.65479 | D34: 530.89402 | E34: 532.3803 | F34: 518.58414 | G34: 497.16966 | H34: 501.28993 | I34: 492.67709 | J34: 470.66307 | K34: 458.40555 | L34: 454.67185 | M34: 459.79265 | N34: 653.96751 | O34: 846.84494 | P34: 1016.6727 | Q34: 1203.8481 | R34: 1396.1775 | S34: 2030.7234 | T34: 2618.4198 | U34: 3194.5878 | V34: 1963.473 | W34: 837.9083 | X34: 819.27617 | Y34: 830.10913 | Z34: 848.75375 | AA34: 870.75662 | AB34: 895.39899 | AC34: 951.5345 | AD34: 1010.1405 | AE34: 1070.1917 | AF34: 1132.3579 | AG34: 1196.5389 | AH34: 1268.5346 | AI34: 1341.4312 | AJ34: 1416.7521 | AK34: 1494.837 | AL34: 1574.8109 | AM34: 1634.9658 | AN34: 1695.0544 | AO34: 1755.6881 | AP34: 1816.9077 | AQ34: 1878.0933 | AR34: 1928.4439 | AS34: 1978.7971 | AT34: 2029.1855 | AU34: 2079.7667 | AV34: 2131.1905
A35: K_2404_1 | B35: 708.43596 | C35: 719.81013 | D35: 732.90636 | E35: 750.49519 | F35: 744.24886 | G35: 727.25441 | H35: 749.08543 | I35: 752.19624 | J35: 733.496 | K35: 727.5278 | L35: 737.57865 | M35: 762.81509 | N35: 1076.4981 | O35: 1386.9372 | P35: 1654.6052 | Q35: 1949.1369 | R35: 2250.4237 | S35: 2400.6453 | T35: 2468.1778 | U35: 2532.0803 | V35: 1864.4971 | W35: 1241.3283 | X35: 1241.6437 | Y35: 1261.4912 | Z35: 1287.4535 | AA35: 1316.4099 | AB35: 1348.4529 | AC35: 1364.1044 | AD35: 1380.0353 | AE35: 1395.5339 | AF35: 1411.1511 | AG35: 1427.3622 | AH35: 1444.2552 | AI35: 1460.4538 | AJ35: 1477.7702 | AK35: 1495.4838 | AL35: 1513.5807 | AM35: 1519.6044 | AN35: 1525.4658 | AO35: 1531.5135 | AP35: 1537.77 | AQ35: 1543.704 | AR35: 1552.1288 | AS35: 1560.374 | AT35: 1568.4664 | AU35: 1576.5072 | AV35: 1584.9735
A36: K_2405_1 | B36: 544.92818 | C36: 553.67718 | D36: 563.75079 | E36: 601.76017 | F36: 623.5269 | G36: 637.77004 | H36: 684.4108 | I36: 716.44342 | J36: 730.87834 | K36: 758.10751 | L36: 801.70674 | M36: 864.40388 | N36: 1039.6782 | O36: 1206.4582 | P36: 1335.6395 | Q36: 1491.9294 | R36: 1655.8162 | S36: 1993.0817 | T36: 2259.2604 | U36: 2521.614 | V36: 1880.5579 | W36: 1285.6867 | X36: 1299.6552 | Y36: 1333.3859 | Z36: 1373.8036 | AA36: 1418.3116 | AB36: 1466.7104 | AC36: 1484.2177 | AD36: 1502.0116 | AE36: 1519.3672 | AF36: 1536.9775 | AG36: 1555.2746 | AH36: 1574.0115 | AI36: 1592.0252 | AJ36: 1611.2629 | AK36: 1631.0974 | AL36: 1651.3778 | AM36: 1658.9585 | AN36: 1666.3781 | AO36: 1674.0137 | AP36: 1681.8985 | AQ36: 1689.4579 | AR36: 1698.7818 | AS36: 1707.9351 | AT36: 1716.9429 | AU36: 1725.9096 | AV36: 1735.3567
A37: K_2406_1 | B37: 1343.8252 | C37: 1365.4008 | D37: 1390.2436 | E37: 1802.2144 | F37: 2286.6942 | G37: 2881.085 | H37: 3783.8851 | I37: 4876.3255 | J37: 6151.9187 | K37: 7879.1102 | L37: 10258.135 | M37: 13576.157 | N37: 13440.359 | O37: 12873.682 | P37: 11625.064 | Q37: 10674.977 | R37: 9720.0918 | S37: 11820.609 | T37: 13567.637 | U37: 15301.852 | V37: 13091.034 | W37: 11040.775 | X37: 11658.838 | Y37: 12399.791 | Z37: 13201.406 | AA37: 14082.64 | AB37: 15017.599 | AC37: 15703.471 | AD37: 16404.608 | AE37: 17113.024 | AF37: 17859.123 | AG37: 18625.697 | AH37: 19156.443 | AI37: 19685.352 | AJ37: 20237.103 | AK37: 20813.87 | AL37: 21404.481 | AM37: 21814.15 | AN37: 22223.713 | AO37: 22638.863 | AP37: 23059.677 | AQ37: 23478.584 | AR37: 24061.176 | AS37: 24645.231 | AT37: 25231.214 | AU37: 25820.762 | AV37: 26421.625
A38: K_2401_2 | B38: 39425.077 | C38: 40058.06 | D38: 40783.751 | E38: 40608.528 | F38: 39254.704 | G38: 37320.426 | H38: 37739.235 | I38: 37269.707 | J38: 35596.528 | K38: 34656.089 | L38: 34464.004 | M38: 34944.32 | N38: 35561.901 | O38: 35372.145 | P38: 33582.362 | Q38: 32601.767 | R38: 31538.661 | S38: 30075.688 | T38: 28709.646 | U38: 27402.334 | V38: 28761.433 | W38: 30120.463 | X38: 29883.92 | Y38: 29832.697 | Z38: 29856.065 | AA38: 29920.599 | AB38: 30047.104 | AC38: 30009.995 | AD38: 29985.03 | AE38: 29955.856 | AF38: 29935.236 | AG38: 29933.816 | AH38: 29999.804 | AI38: 30061.79 | AJ38: 30143.917 | AK38: 30235.935 | AL38: 30336.758 | AM38: 30129.29 | AN38: 29935.63 | AO38: 29747.627 | AP38: 29570.004 | AQ38: 29392.229 | AR38: 29185.329 | AS38: 28981.725 | AT38: 28783.906 | AU38: 28586.897 | AV38: 28405.052
A39: K_2402_2 | B39: 960.463 | C39: 975.88355 | D39: 993.63998 | E39: 1469.1861 | F39: 1900.7112 | G39: 2286.5536 | H39: 2751.0456 | I39: 3138.4593 | J39: 3397.0515 | K39: 3647.429 | L39: 3888.5484 | M39: 4110.1555 | N39: 4284.652 | O39: 4361.6507 | P39: 4265.4973 | Q39: 4264.2706 | R39: 4259.0159 | S39: 4379.2186 | T39: 4441.641 | U39: 5588.3404 | V39: 6706.7533 | W39: 7813.2982 | X39: 8864.7134 | Y39: 9911.4192 | Z39: 10939.779 | AA39: 11949.535 | AB39: 12941.909 | AC39: 13878.341 | AD39: 14787.701 | AE39: 15668.105 | AF39: 16523.628 | AG39: 17355.807 | AH39: 18096.889 | AI39: 18811.507 | AJ39: 19507.426 | AK39: 20181.795 | AL39: 20835.296 | AM39: 21422.066 | AN39: 21988.719 | AO39: 22535.245 | AP39: 23062.318 | AQ39: 23568.224 | AR39: 24025.345 | AS39: 24463.701 | AT39: 24883.955 | AU39: 25285.389 | AV39: 25672.818 | AW39: =AV39-AU39*(1-AV56) -> 1145.9903
A40: K_2403_2 | B40: 513.4118 | C40: 521.65479 | D40: 530.89402 | E40: 532.3803 | F40: 518.58414 | G40: 497.16966 | H40: 501.28993 | I40: 492.67709 | J40: 470.66307 | K40: 458.40555 | L40: 454.67185 | M40: 459.79265 | N40: 653.96751 | O40: 846.84494 | P40: 1016.6727 | Q40: 1203.8481 | R40: 1396.1775 | S40: 2030.7234 | T40: 2618.4198 | U40: 3352.4878 | V40: 2318.6487 | W40: 1425.4823 | X40: 1558.9125 | Y40: 1707.0813 | Z40: 1854.2481 | AA40: 1997.7883 | AB40: 2138.2151 | AC40: 2305.5052 | AD40: 2468.426 | AE40: 2626.4912 | AF40: 2780.8219 | AG40: 2931.5178 | AH40: 3084.3962 | AI40: 3232.8663 | AJ40: 3378.9263 | AK40: 3522.8559 | AL40: 3663.9182 | AM40: 3780.7496 | AN40: 3894.0077 | AO40: 4003.7646 | AP40: 4110.124 | AQ40: 4212.491 | AR40: 4301.0268 | AS40: 4386.1727 | AT40: 4468.0698 | AU40: 4546.4626 | AV40: 4622.8753
...

Sheet Feuil2
B1: 2004 | C1: 2005 | D1: 2006 | E1: 2007 | F1: 2008 | G1: 2009 | H1: 2010 | I1: 2011 | J1: 2012 | K1: 2013 | L1: 2014 | M1: 2015 | N1: 2016 | O1: 2017 | P1: 2018 | Q1: 2019 | R1: 2020 | S1: 2021 | T1: 2022 | U1: 2023 | V1: 2024 | W1: 2025 | X1: 2026 | Y1: 2027 | Z1: 2028 | AA1: 2029 | AB1: 2030 | AC1: 2031 | AD1: 2032 | AE1: 2033 | AF1: 2034 | AG1: 2035 | AH1: 2036 | AI1: 2037 | AJ1: 2038 | AK1: 2039 | AL1: 2040 | AM1: 2041 | AN1: 2042 | AO1: 2043 | AP1: 2044 | AQ1: 2045 | AR1: 2046 | AS1: 2047 | AT1: 2048 | AU1: 2049 | AV1: 2050 | AW1: total
A2: d_IA_2401 | B2: =Feuil1!B14-Feuil1!B8 -> 0 | C2: =Feuil1!C14-Feuil1!C8 -> 0 | D2: =Feuil1!D14-Feuil1!D8 -> 0 | E2: =Feuil1!E14-Feuil1!E8 -> 0 | F2: =Feuil1!F14-Feuil1!F8 -> 0 | G2: =Feuil1!G14-Feuil1!G8 -> 0 | H2: =Feuil1!H14-Feuil1!H8 -> 0 | I2: =Feuil1!I14-Feuil1!I8 -> 0 | ... AV2: =Feuil1!AV14-Feuil1!AV8 -> -262.708
A3: d_IA_2402 | B3: =Feuil1!B15-Feuil1!B9 -> 0 | C3: =Feuil1!C15-Feuil1!C9 -> 0 | D3: =Feuil1!D15-Feuil1!D9 -> 0 | E3: =Feuil1!E15-Feuil1!E9 -> 0 | F3: =Feuil1!F15-Feuil1!F9 -> 0 | G3: =Feuil1!G15-Feuil1!G9 -> 0 | H3: =Feuil1!H15-Feuil1!H9 -> 0 | I3: =Feuil1!I15-Feuil1!I9 -> 0 | ... AV3: =Feuil1!AV15-Feuil1!AV9 -> 931.10913
A4: d_IA_2403 | B4: =Feuil1!B16-Feuil1!B10 -> 0 | C4: =Feuil1!C16-Feuil1!C10 -> 0 | D4: =Feuil1!D16-Feuil1!D10 -> 0 | E4: =Feuil1!E16-Feuil1!E10 -> 0 | F4: =Feuil1!F16-Feuil1!F10 -> 0 | G4: =Feuil1!G16-Feuil1!G10 -> 0 | H4: =Feuil1!H16-Feuil1!H10 -> 0 | I4: =Feuil1!I16-Feuil1!I10 -> 0 | ... AV4: =Feuil1!AV16-Feuil1!AV10 -> 99.12346
A5: d_IA_2404 | B5: =Feuil1!B17-Feuil1!B11 -> 0 | C5: =Feuil1!C17-Feuil1!C11 -> 0 | D5: =Feuil1!D17-Feuil1!D11 -> 0 | E5: =Feuil1!E17-Feuil1!E11 -> 0 | F5: =Feuil1!F17-Feuil1!F11 -> 0 | G5: =Feuil1!G17-Feuil1!G11 -> 0 | H5: =Feuil1!H17-Feuil1!H11 -> 0 | I5: =Feuil1!I17-Feuil1!I11 -> 0 | ... AV5: =Feuil1!AV17-Feuil1!AV11 -> -9.3822501
A6: d_IA_2405 | B6: =Feuil1!B18-Feuil1!B12 -> 0 | C6: =Feuil1!C18-Feuil1!C12 -> 0 | D6: =Feuil1!D18-Feuil1!D12 -> 0 | E6: =Feuil1!E18-Feuil1!E12 -> 0 | F6: =Feuil1!F18-Feuil1!F12 -> 0 | G6: =Feuil1!G18-Feuil1!G12 -> 0 | H6: =Feuil1!H18-Feuil1!H12 -> 0 | I6: =Feuil1!I18-Feuil1!I12 -> 0 | ... AV6: =Feuil1!AV18-Feuil1!AV12 -> 143.98924
A7: d_IA_2406 | B7: =Feuil1!B19-Feuil1!B13 -> 0 | C7: =Feuil1!C19-Feuil1!C13 -> 0 | D7: =Feuil1!D19-Feuil1!D13 -> 0 | E7: =Feuil1!E19-Feuil1!E13 -> 0 | F7: =Feuil1!F19-Feuil1!F13 -> 0 | G7: =Feuil1!G19-Feuil1!G13 -> 0 | H7: =Feuil1!H19-Feuil1!H13 -> 0 | I7: =Feuil1!I19-Feuil1!I13 -> 0 | ... AV7: =Feuil1!AV19-Feuil1!AV13 -> -377.77519
A8: D_I_FC_2401 | B8: =B2-Feuil1!B2 -> 0 | C8: =C2-Feuil1!C2 -> 0 | D8: =D2-Feuil1!D2 -> 0 | E8: =E2-Feuil1!E2 -> 0 | F8: =F2-Feuil1!F2 -> 0 | G8: =G2-Feuil1!G2 -> 0 | H8: =H2-Feuil1!H2 -> 0 | I8: =I2-Feuil1!I2 -> 0 | ... AV8: =AV2-Feuil1!AV2 -> -262.708
A9: D_I_FC_2402 | B9: =B3-Feuil1!B3 -> 0 | C9: =C3-Feuil1!C3 -> 0 | D9: =D3-Feuil1!D3 -> 0 | E9: =E3-Feuil1!E3 -> 0 | F9: =F3-Feuil1!F3 -> 0 | G9: =G3-Feuil1!G3 -> 0 | H9: =H3-Feuil1!H3 -> 0 | I9: =I3-Feuil1!I3 -> 0 | ... AV9: =AV3-Feuil1!AV3 -> -200.97903 | AW9: =SUM(G9:AV9) -> -3614.0119
A10: D_I_FC_2403 | B10: =B4-Feuil1!B4 -> 0 | C10: =C4-Feuil1!C4 -> 0 | D10: =D4-Feuil1!D4 -> 0 | E10: =E4-Feuil1!E4 -> 0 | F10: =F4-Feuil1!F4 -> 0 | G10: =G4-Feuil1!G4 -> 0 | H10: =H4-Feuil1!H4 -> 0 | I10: =I4-Feuil1!I4 -> 0 | ... AV10: =AV4-Feuil1!AV4 -> -62.457403 | AW10: =SUM(G10:AV10) -> -1137.388
A11: D_I_FC_2404 | B11: =B5-Feuil1!B5 -> 0 | C11: =C5-Feuil1!C5 -> 0 | D11: =D5-Feuil1!D5 -> 0 | E11: =E5-Feuil1!E5 -> 0 | F11: =F5-Feuil1!F5 -> 0 | G11: =G5-Feuil1!G5 -> 0 | H11: =H5-Feuil1!H5 -> 0 | I11: =I5-Feuil1!I5 -> 0 | ... AV11: =AV5-Feuil1!AV5 -> -44.571781 | AW11: =SUM(G11:AV11) -> -830.80429
A12: D_I_FC_2405 | B12: =B6-Feuil1!B6 -> 0 | C12: =C6-Feuil1!C6 -> 0 | D12: =D6-Feuil1!D6 -> 0 | E12: =E6-Feuil1!E6 -> 0 | F12: =F6-Feuil1!F6 -> 0 | G12: =G6-Feuil1!G6 -> 0 | H12: =H6-Feuil1!H6 -> 0 | I12: =I6-Feuil1!I6 -> 0 | ... AV12: =AV6-Feuil1!AV6 -> -106.48252 | AW12: =SUM(G12:AV12) -> -2161.1451
A13: D_I_FC_2406 | B13: =B7-Feuil1!B7 -> 0 | C13: =C7-Feuil1!C7 -> 0 | D13: =D7-Feuil1!D7 -> 0 | E13: =E7-Feuil1!E7 -> 0 | F13: =F7-Feuil1!F7 -> 0 | G13: =G7-Feuil1!G7 -> 0 | H13: =H7-Feuil1!H7 -> 0 | I13: =I7-Feuil1!I7 -> 0 | ... AV13: =AV7-Feuil1!AV7 -> -501.58116 | AW13: =SUM(G13:AV13) -> -8141.5636
A14: D_I | G14: =SUM(Feuil1!G3:G7)-G8 -> 0 | H14: =SUM(Feuil1!H3:H7)-H8 -> 0 | I14: =SUM(Feuil1!I3:I7)-I8 -> 0 | J14: =SUM(Feuil1!J3:J7)-J8 -> 0 | K14: =SUM(Feuil1!K3:K7)-K8 -> 0 | L14: =SUM(Feuil1!L3:L7)-L8 -> 0 | M14: =SUM(Feuil1!M3:M7)-M8 -> 0 | N14: =SUM(Feuil1!N3:N7)-N8 -> 0 | ... AV14: =SUM(Feuil1!AV3:AV7)-AV8 -> 1965.8443
A16: D_I_FC_2402 | B16: 0 | C16: 0 | D16: 0 | E16: 0 | F16: 0 | G16: 0 | H16: 0 | I16: 0 | J16: 0 | K16: 0 | L16: 0 | M16: 0 | N16: 0 | O16: 0 | P16: 0 | Q16: 0 | R16: 0 | S16: 0 | T16: 0 | U16: -32.01631 | V16: -57.617839 | W16: -69.452965 | X16: -67.937954 | Y16: -73.807156 | Z16: -79.245742 | AA16: -86.221872 | AB16: -90.12245 | AC16: -99.532013 | AD16: -106.5581 | AE16: -113.05716 | AF16: -119.31836 | AG16: -126.0153 | AH16: -129.9904 | AI16: -135.25033 | AJ16: -141.89065 | AK16: -147.95964 | AL16: -154.324 | AM16: -156.30017 | AN16: -160.36578 | AO16: -166.8488 | AP16: -172.88235 | AQ16: -178.99941 | AR16: -180.18799 | AS16: -185.41039 | AT16: -190.33906 | AU16: -197.02863 | AV16: -201.37584 | AW16: -3620.0567
A17: D_I_FC_2403 | B17: 0 | C17: 0 | D17: 0 | E17: 0 | F17: 0 | G17: 0 | H17: 0 | I17: 0 | J17: 0 | K17: 0 | L17: 0 | M17: 0 | N17: 0 | O17: 0 | P17: 0 | Q17: 0 | R17: 0 | S17: 0 | T17: 0 | U17: -3.5864036 | V17: -161.58086 | W17: -161.58086 | X17: 7.9373725 | Y17: -2.2547888 | Z17: -6.9709727 | AA17: -10.126307 | AB17: -12.252584 | AC17: -13.55754 | AD17: -17.106037 | AE17: -20.317211 | AF17: -23.268272 | AG17: -26.196294 | AH17: -29.305886 | AI17: -32.229836 | AJ17: -34.848903 | AK17: -37.675184 | AL17: -40.508699 | AM17: -43.053459 | AN17: -44.893981 | AO17: -47.391849 | AP17: -49.947213 | AQ17: -52.596527 | AR17: -54.351544 | AS17: -56.638645 | AT17: -58.918522 | AU17: -61.719093 | AV17: -63.746422 | AW17: -1158.6865
A18: D_I_FC_2404 | B18: 0 | C18: 0 | D18: 0 | E18: 0 | F18: 0 | G18: 0 | H18: 0 | I18: 0 | J18: 0 | K18: 0 | L18: 0 | M18: 0 | N18: 0 | O18: 0 | P18: 0 | Q18: 0 | R18: 0 | S18: 0 | T18: 0 | U18: -1.4711862 | V18: -35.189531 | W18: -35.189531 | X18: -12.526718 | Y18: -15.654025 | Z18: -17.705626 | AA18: -19.637514 | AB18: -20.777093 | AC18: -22.732447 | AD18: -24.144838 | AE18: -25.449642 | AF18: -26.688502 | AG18: -28.010386 | AH18: -29.67787 | AI18: -30.764831 | AJ18: -31.987308 | AK18: -33.25612 | AL18: -34.542555 | AM18: -34.594406 | AN18: -35.314144 | AO18: -36.511431 | AP18: -37.720112 | AQ18: -38.941692 | AR18: -40.362912 | AS18: -41.538006 | AT18: -42.691393 | AU18: -44.206144 | AV18: -45.226461 | AW18: -842.51242
A19: D_I_FC_2405 | B19: 0 | C19: 0 | D19: 0 | E19: 0 | F19: 0 | G19: 0 | H19: 0 | I19: 0 | J19: 0 | K19: 0 | L19: 0 | M19: 0 | N19: 0 | O19: 0 | P19: 0 | Q19: 0 | R19: 0 | S19: 0 | T19: 0 | U19: -9.8161493 | V19: -250.47176 | W19: -250.47176 | X19: -16.662934 | Y19: -27.229686 | Z19: -32.511813 | AA19: -36.688566 | AB19: -39.762576 | AC19: -45.330743 | AD19: -48.664417 | AE19: -52.050034 | AF19: -55.265317 | AG19: -58.530683 | AH19: -62.379304 | AI19: -65.445379 | AJ19: -68.694737 | AK19: -72.084381 | AL19: -75.540882 | AM19: -77.944714 | AN19: -80.60101 | AO19: -84.199699 | AP19: -87.756679 | AQ19: -91.468346 | AR19: -94.617049 | AS19: -98.063027 | AT19: -101.55472 | AU19: -105.71249 | AV19: -108.85134 | AW19: -2198.3702
A20: D_I_FC_2406 | B20: 0 | C20: 0 | D20: 0 | E20: 0 | F20: 0 | G20: 0 | H20: 0 | I20: 0 | J20: 0 | K20: 0 | L20: 0 | M20: 0 | N20: 0 | O20: 0 | P20: 0 | Q20: 0 | R20: 0 | S20: 0 | T20: 0 | U20: 1.6272188 | V20: -123.80597 | W20: -123.80597 | X20: -112.18732 | Y20: -137.85459 | Z20: -159.95057 | AA20: -184.61629 | AB20: -201.79505 | AC20: -221.82691 | AD20: -241.09105 | AE20: -259.33264 | AF20: -279.08024 | AG20: -298.99969 | AH20: -301.06388 | AI20: -313.87014 | AJ20: -328.55491 | AK20: -344.9586 | AL20: -360.6887 | AM20: -358.01875 | AN20: -365.69647 | AO20: -378.84497 | AP20: -392.26068 | AQ20: -405.56404 | AR20: -443.65245 | AS20: -459.6639 | AT20: -475.09369 | AU20: -495.44036 | AV20: -509.91599 | AW20: -8276.0066
A21: D_I | G21: 0 | H21: 0 | I21: 0 | J21: 0 | K21: 0 | L21: 0 | M21: 0 | N21: 0 | O21: 0 | P21: 0 | Q21: 0 | R21: 0 | S21: 0 | T21: 0 | U21: 1703.1363 | V21: 1815.7049 | W21: 1893.5789 | X21: 1896.7333 | Y21: 1920.4091 | Z21: 1933.4591 | AA21: 1947.5139 | AB21: 1946.964 | AC21: 1967.8658 | AD21: 1973.8692 | AE21: 1977.5897 | AF21: 1980.5157 | AG21: 1985.5158 | AH21: 2001.7123 | AI21: 2003.212 | AJ21: 2006.2058 | AK21: 2009.935 | AL21: 2013.8492 | AM21: 1983.5235 | AN21: 1976.4695 | AO21: 1975.5505 | AP21: 1975.4305 | AQ21: 1974.9146 | AR21: 1969.4806 | AS21: 1968.2886 | AT21: 1966.4122 | AU21: 1968.8229 | AV21: 1965.7564
