Workbook
Name Agriculture: "$'agriculture 2015'.$a$#ref !"
Name Années: '[1]M-2'!$A$4:$AE$4
Name AnnéesR_BI: '[1]Bilan Energie Format SDES AME'!$A$54:$L$54
Name AnnéesResult: '[1]R-5'!$C$6:$H$6
Name AnneesShazam: [1]Outils!$E$104:$V$104
Name blabla: #REF!
Name BY: [1]Outils!$B$19
Name CalageAMEAgriculture: '[1]Calage bilan'!$B$65:$F$71
Name CalageAMEIndustrie: '[1]Calage bilan'!$B$33:$F$39
Name CalageAMERésidentiel: '[1]Calage bilan'!$B$49:$F$55
Name CalageAMETertiaire: '[1]Calage bilan'!$B$57:$F$63
Name CalageAMETransport: '[1]Calage bilan'!$B$41:$F$47
Name CalageAMSAgriculture: '[1]Calage bilan'!$I$65:$M$71
Name CalageAMSIndustrie: '[1]Calage bilan'!$I$33:$M$39
Name CalageAMSRésidentiel: '[1]Calage bilan'!$I$49:$M$55
Name CalageAMSTertiaire: '[1]Calage bilan'!$I$57:$M$63
Name CalageAMSTransport: '[1]Calage bilan'!$I$41:$M$47
Name CalageAnnées: '[1]Calage bilan'!$I$32:$M$32
Name CalageEnergies: '[1]Calage bilan'!$H$33:$H$39
Name Choix_scenario: [2]ReadMe!$H$10
Name CodeInd2: '[1]I-2'!$B$4:$B$353
Name Codeind4: '[1]I-4'!$B$323:$B$670
Name CodeMac: '[1]M-2'!$B$4:$B$123
Name CodeR_BI: '[1]Bilan Energie Format SDES AME'!$A$54:$A$84
Name CodeRes: '[1]R-2'!$B$4:$B$788
Name CodeResbis: '[1]R-2'!$B$828:$B$1291
Name CodeResultAgr: '[1]A-4'!$A$9:$A$14
Name CodeResultInd: '[1]I-5'!$A$10:$A$393
Name CodeResultMac: '[1]M-5'!$A$10:$A$124
Name CodeResultRes: '[1]R-5'!$A$10:$A$311
Name CodeResultTer: '[1]S-5'!$A$10:$A$293
Name CodeResultTra: '[1]T-5'!$A$10:$A$803
Name CodeTer: '[1]S-2'!$B$4:$B$298
Name CodeTra: '[1]T-2'!$B$4:$B$138
Name DataInd: '[1]I-2'!$A$4:$AE$353
Name DataInd4: '[1]I-4'!$A$323:$AE$670
Name DataMac2: '[1]M-2'!$A$4:$AE$141
Name DataRes: '[1]R-2'!$A$4:$AE$788
Name DataResbis: '[1]R-2'!$A$828:$AG$1291
Name DATAShazam: [1]Outils!$E$105:$V$132
Name DataTer: '[1]S-2'!$A$4:$AG$298
Name DataTra: '[1]T-2'!$A$4:$AG$138
Name NRD_CODEShazam: [1]Outils!$C$105:$C$132
Name R_BI2015: '[1]Bilan Energie Format SDES AME'!$A$10:$L$40
Name R_BI2015_2: '[1]Bilan Energie Format SDES AMS'!$A$10:$L$40
Name R_BI2020: '[1]Bilan Energie Format SDES AME'!$A$54:$L$84
Name R_BI2020_2: '[1]Bilan Energie Format SDES AMS'!$A$54:$L$84
Name R_BI2025: '[1]Bilan Energie Format SDES AME'!$A$98:$L$128
Name R_BI2025_2: '[1]Bilan Energie Format SDES AMS'!$A$98:$L$128
Name R_BI2030: '[1]Bilan Energie Format SDES AME'!$A$142:$L$172
Name R_BI2030_2: '[1]Bilan Energie Format SDES AMS'!$A$142:$L$172
Name R_BI2050: '[1]Bilan Energie Format SDES AME'!$A$186:$L$216
Name R_BI2050_2: '[1]Bilan Energie Format SDES AMS'!$A$186:$L$216
Name ResultAgrS1: '[1]A-4'!$C$9:$H$14
Name ResultAgrS2: '[1]A-4'!$K$9:$P$14
Name ResultIndS1: '[1]I-5'!$C$10:$H$393
Name ResultIndS2: '[1]I-5'!$K$10:$P$393
Name ResultMacS1: '[1]M-5'!$C$10:$H$124
Name ResultResS1: '[1]R-5'!$C$10:$H$311
Name ResultResS2: '[1]R-5'!$K$10:$P$311

Sheet ReadMe
A1: Données d'entrée MatMat pour ThreeME
A3: Nom Onglet | B3: Détails | D3: Statut
A4: Delta AMX_2030 | B4: Variation relative 2019-2030 des variables (coefficients techniques (A), vecteurs de demande finale, production et importation), annualisée sur 7 ans (2023-2030 pour coller avec le point de départ 3ME) selon les scénarios AME et AMS | D4: Données d'entrée pour ThreeME
A5: Delta AMX_2050 | B5: Variation relative 2030-2050 des variables (coefficients techniques (A), vecteurs de demande finale, production et importation), annualisée sur 20 ans selon les scénarios AME et AMS | D5: Données d'entrée pour ThreeME
A8: Données
A10: Nom Onglet | B10: Détails | D10: Statut
A11: 2019 | B11: SRIOT Monétaire issue de MatMat, agrégé sur les 37 secteurs de 3ME, pour l'année de calibration (2019) : A (= Matrice des coefficients techniques pour la production domestique selon l'origine France ou RoW - Reste du Monde ), 4 vecteurs de demande finale (Household, Government, GFCF, Exports), production intérieure et importations en volume. Unité EUR | D11: Information | E11: 2019 (Z) correspond à la version du SRIOT avec les consommations intermédiaires Z
A12: AME_20XX | B12: SRIOT pour 2030, 2040 et 2050 pour l'AME. Unité EUR | D12: Information | E12: AME_20XX (Z) correspond à la version du SRIOT avec les consommations intermédiaires Z
A13: AMS_20XX | B13: SRIOT pour 2030, 2040 et 2050 pour l'AMS. Unité EUR | D13: Information | E13: AMS_20XX (Z) correspond à la version du SRIOT avec les consommations intermédiaires Z
A15: Chocs_Run3_250409 | B15: Liste des chocs introduits dans MatMat (Run3 sectoriel DGEC) à date | D15: Information
A16: Bridge | B16: Matrice de passage entre secteurs MatMat et secteurs 3ME | D16: Information
A18: Points d'attention
A19: 1 | B19: Dans MatMat, pas de distinction entre les secteurs 15 et 16 de 3ME (transport de passagers et marchandises par la route), j'ai donc appliqué la même variation aux 2 secteurs
A20: 2 | B20: Compte tenu des différences observées entre les secteurs chimie de MatMat et 3ME, les variations sur les secteurs 07 et 08 ont été agrégés selon méthode décrite dans :
B21: Données 3ME pour informer MatMat.docx
B22: La même variation est appliquée aux 2 secteurs
A23: 3 | B23: Des différences s'observent entre les chocs introduits dans MatMat (Chocs_Run3_250409) et les variations obtenues dans les fichiers Delta (indépendamment de l'annualisation) du fait de l'agrégation de plusieurs secteurs MatMat dans un secteur 3ME
A24: 4 | B24: Des différences de variations peuvent s'observer entre la production française (FR) et les importations (RDM) pour un même vecteur (par exemple C). En effet, dans MatMat, les chocs sont introduits sur les variables A et Y agrégées (FR+RDM), les valeurs FR et RoW sont calculées à partir des M/P (rapport entre importations et production intérieure), ce qui peut induire de légères différences par rapport à la variation totale selon les valeurs du taux M/P (paramétrable). De plus, comme chaque secteur MatMat à un rapport M/P différent, au niveau du secteur agrégé 3ME on peut avoir des divergences FR / RoW plus marquées => comparer les variations sur le TOTAL
A25: 5 | B25: Concernant la variation de l'investissement pour les produits verre, acier, autres métaux non-ferreux, elle peut être ignorée car elle devrait être nulle (le choc portait sur la part de marché entre Matières primaires et secondaires et donc est transparant quand les deux sont agrégées comme dans 3ME). La variation est due aux valeurs nulles pour la FBCF FR ou RDM, qui déforme la projection.
A26: 6 | B26: Au niveau de l’investissement, le choc sur la FBCF de l’agriculture peut avoir du sens pour 3ME (évolution des cheptels suite à l’évolution des régimes alimentaires). Ceux sur les biens d’investissement construction et autres industries sont des résultantes des chocs de demande considérés (baisse des mètres carrés de bureau en AMS, changement des parts de marché dans les modes de traitement des déchets, sobriété sur les équipements électroniques en AMS).
A28: Principaux Chocs considérés par rapport à 2019
A29: RUN 3 20250417 | B29: Valeur des chocs dans onglet Chocs_Run3_250417
B30: AME | C30: AMS | D30: Détails
A31: Agriculture / IAA - Alimentation humaine | B31: Changement Régimes alimentaires | D31: Choc sur DF des Ménages + APU + Exports (hypothèse d'une même évolution des régimes alimentaires dans le RDM qu'en France pour tendre vers cibles de production DGEC)
D32: + choc sur A des Services (hôtels / restaurants, services publics et business services) pour traduire l’évolution des régimes alimentaires dans la restauration, y compris restauration collective dans les entreprises, établissements scolaires, hôpitaux, cliniques, maisons de retraite...
A33: Agriculture | B33: Evolution des cheptels | D33: Choc sur la Matrice d’investissement pour traduire les investissements en cheptels réalisés par les secteurs d’élevage (bovins viande et lait, porcins, ovins et caprins)
A34: Agriculture / IAA - Alimentation animale | B34: Changement Régimes alimentaires des animaux | D34: Choc sur A des activités d'élevage en céréales, fourrages, oléagineux et autres concentrés (orge, son, farines, fécules2)
A35: Agriculture / fertilisants | B35: Baisse de l’usage des engrais chimiques (proxy accroissement part de l'AB) | D35: Choc sur A des activités agricoles en fertilisants chimiques + Choc sur DF des ménages et APU en fertilisants chimiques (en lien avec interdiction de l'utilisation des engrais de synthèse dans les propriétés non agricoles)
A36: Sylviculture | B36: Evolution du stock de bois forêt (investissement productif de la filière), proportionnel à l'accroissement de la récolte | D36: Choc sur la Matrice d’investissement du secteur Forestry en produit Forestry (tout en amont de la chaine de valeur, n'évolue pas sous l'effet du choc de demande adressée à la filière)
A37: Bois énergie | B37: Evolution de la demande en bois énergie | D37: Choc sur DF des ménages (hypothèse que la DF des ménages en produit forestry = bois énergie)
A38: Recyclage | B38: Evolution des taux d'incorporation de MPR (part de marché entre matières vierges et MPR) pour la production française | D38: Choc sur A et tous vecteurs de DF
B39: (les parts de marché matières vierges / MPR sont maintenues constantes pour les matières importées)
A40: Automobile | B40: Allègement de véhicules (masse moyenne) + Nouvelle composition matières | D40: Choc sur A du secteur de la construction automobile
B41: Consommation matières Batteries | D41: Choc sur A du secteur de la construction automobile
A42: Emballage | B42: Fin des emballages plastiques à usage unique (2040) | C42: Fin des emballages plastiques à usage unique (2040) + sobriété | D42: Choc sur DF des ménages et des APU, + A des secteurs Agricoles et IAA, Chimie (pharma, cosmétique), Industrie manufacturière (emballages pour Transport des produits notamment) et Service (commerce notamment) au prorata de la part des emballages dans les consommations de papier, plastiques et verre
A43: Construction | B43: Substitution Acier et Ciment par Bois | D43: Choc sur A de la construction
A44: Services immobiliers | B44: Evolution de la demande des ménages en services immobiliers (hypothèse qu’elle évolue en fonction de l'évolution du parc immobilier en m²) | D44: Choc sur la DF des ménages en services immobiliers
C45: Evolution de la demande en services immobiliers des Administrations publiques et services marchands en fonction des m² de bureaux/employé (sous effet du télétravail notamment) | D45: Choc sur A en Real Estate des APU, services publics (uniquement public administration) et business services (hors commerce)
A46: Industrie | C46: Baisse Taux de Clinker dans Ciment | D46: Choc sur A de la demande en ciment de la filière ciment
A47: Produits Chimiques des ménages | B47: Sobriété sur consommation de produits chimiques (peintures, vernis, détergents, savons, produits pharmaceutiques) + arrêt de la vente de pesticides aux personnes publiques et aux particuliers (loi Labbé3) | D47: Choc sur DF des ménages et APU
...

Sheet Delta AME_2030
A1: Variation relative 2019-2030, annualisée sur 7 ans pour coller avec le point de départ 3ME (2023-2030) | D1: category | E1: 01 | F1: 02 | G1: 03 | H1: 04 | I1: 05 | J1: 06 | K1: 07 | L1: 08 | M1: 09 | N1: 10 | O1: 11 | P1: 12 | Q1: 13 | R1: 14 | S1: 15 | T1: 16 | U1: 17 | V1: 18 | W1: 19 | X1: 20 | Y1: 21 | Z1: 22 | AA1: 23 | AB1: 24 | AC1: 25 | AD1: 26 | AE1: 27 | AF1: 28 | AG1: 29 | AH1: 30 | AI1: 31 | AJ1: 32 | AK1: 33 | AL1: 34 | AM1: 35 | AN1: 36 | AO1: 37 | AP1: Household | AQ1: Government | AR1: GFCF | AS1: Exports | AT1: Supply | AU1: Imports
D2: sub_category | E2: 01 | F2: 02 | G2: 03 | H2: 04 | I2: 05 | J2: 06 | K2: 07 | L2: 08 | M2: 09 | N2: 10 | O2: 11 | P2: 12 | Q2: 13 | R2: 14 | S2: 15 | T2: 16 | U2: 17 | V2: 18 | W2: 19 | X2: 20 | Y2: 21 | Z2: 22 | AA2: 23 | AB2: 24 | AC2: 25 | AD2: 26 | AE2: 27 | AF2: 28 | AG2: 29 | AH2: 30 | AI2: 31 | AJ2: 32 | AK2: 33 | AL2: 34 | AM2: 35 | AN2: 36 | AO2: 37 | AP2: C | AQ2: G | AR2: I | AS2: E | AT2: x | AU2: M
D3: sector | E3: Products of agriculture, forestry and fishing | F3: Food products and beverages | G3: Motor vehicles, trailers and semi-trailers | H3: Glass and glass products | I3: Ceramic products and building materials | J3: Articles of paper and paperboard | K3: Inorganic basic chemicals | L3: Organic basic chemicals | M3: Plastics products | N3: Basic iron and steel and of ferro-alloys | O3: Non-ferrous metals | P3: Other industries | Q3: Construction of buildings and Civil engineering | R3: Rail transport (Passenger and Freight) | S3: Passenger transport by road | T3: Freight transport by road and transport via pipeline | U3: Water transport | V3: Air transport | W3: Business services | X3: Public services | Y3: Coal | Z3: Oil | AA3: Biofuel | AB3: Electricity by nuclear | AC3: Electricity by petroleum | AD3: Electricity by gas | AE3: Coal-fired electricity | AF3: Electricity by wind | AG3: Electricity by solar | AH3: Electricity by hydro | AI3: Other electricity | AJ3: Natural gas | AK3: Wood | AL3: Biogas | AM3: Waste incineration | AN3: Geothermal | AO3: Other natural gas and heat
A4: region | B4: category | C4: sub_category | D4: sector | E4: A | F4: A | G4: A | H4: A | I4: A | J4: A | K4: A | L4: A | M4: A | N4: A | O4: A | P4: A | Q4: A | R4: A | S4: A | T4: A | U4: A | V4: A | W4: A | X4: A | Y4: A | Z4: A | AA4: A | AB4: A | AC4: A | AD4: A | AE4: A | AF4: A | AG4: A | AH4: A | AI4: A | AJ4: A | AK4: A | AL4: A | AM4: A | AN4: A | AO4: A
A5: FR | B5: 01 | C5: 01 | D5: Products of agriculture, forestry and fishing | E5: =IF('2019'!E5=0,0,(AME_2030!E5/'2019'!E5)^(1/7)-1) -> 0.0013462924 | F5: =IF('2019'!F5=0,0,(AME_2030!F5/'2019'!F5)^(1/7)-1) -> -0.00013012775 | G5: =IF('2019'!G5=0,0,(AME_2030!G5/'2019'!G5)^(1/7)-1) -> -2.3353149e-09 | H5: =IF('2019'!H5=0,0,(AME_2030!H5/'2019'!H5)^(1/7)-1) -> 0 | I5: =IF('2019'!I5=0,0,(AME_2030!I5/'2019'!I5)^(1/7)-1) -> 0 | J5: =IF('2019'!J5=0,0,(AME_2030!J5/'2019'!J5)^(1/7)-1) -> -0.012228135 | K5: =IF('2019 (Z)'!AW5=0,0,('AME_2030 (Z)'!AW5/'2019 (Z)'!AW5)^(1/7)-1) -> 0.0022948862 | L5: =K5 -> 0.0022948862 | M5: =IF('2019'!M5=0,0,(AME_2030!M5/'2019'!M5)^(1/7)-1) -> -0.0046050638 | N5: =IF('2019'!N5=0,0,(AME_2030!N5/'2019'!N5)^(1/7)-1) -> 0 | O5: =IF('2019'!O5=0,0,(AME_2030!O5/'2019'!O5)^(1/7)-1) -> 0 | P5: =IF('2019'!P5=0,0,(AME_2030!P5/'2019'!P5)^(1/7)-1) -> 0.0092661175 | Q5: =IF('2019'!Q5=0,0,(AME_2030!Q5/'2019'!Q5)^(1/7)-1) -> 0.017204033 | R5: =IF('2019'!R5=0,0,(AME_2030!R5/'2019'!R5)^(1/7)-1) -> -2.0238261e-08 | S5: =T5 -> -1.5204104e-06 | T5: =IF('2019'!T5=0,0,(AME_2030!T5/'2019'!T5)^(1/7)-1) -> -1.5204104e-06 | U5: =IF('2019'!U5=0,0,(AME_2030!U5/'2019'!U5)^(1/7)-1) -> 0 | V5: =IF('2019'!V5=0,0,(AME_2030!V5/'2019'!V5)^(1/7)-1) -> 0 | W5: =IF('2019'!W5=0,0,(AME_2030!W5/'2019'!W5)^(1/7)-1) -> 0.0015931337 | X5: =IF('2019'!X5=0,0,(AME_2030!X5/'2019'!X5)^(1/7)-1) -> 0.0013137303 | Y5: =IF('2019'!Y5=0,0,(AME_2030!Y5/'2019'!Y5)^(1/7)-1) -> 0 | Z5: =IF('2019'!Z5=0,0,(AME_2030!Z5/'2019'!Z5)^(1/7)-1) -> 0.00016178189 | AA5: =IF('2019'!AA5=0,0,(AME_2030!AA5/'2019'!AA5)^(1/7)-1) -> 0.001344016 | ... AU5: =IF('2019'!AU5=0,0,(AME_2030!AU5/'2019'!AU5)^(1/7)-1) -> 0
B6: 02 | C6: 02 | D6: Food products and beverages | E6: =IF('2019'!E6=0,0,(AME_2030!E6/'2019'!E6)^(1/7)-1) -> -0.0017957746 | F6: =IF('2019'!F6=0,0,(AME_2030!F6/'2019'!F6)^(1/7)-1) -> 0.00049671425 | G6: =IF('2019'!G6=0,0,(AME_2030!G6/'2019'!G6)^(1/7)-1) -> -2.3353149e-09 | H6: =IF('2019'!H6=0,0,(AME_2030!H6/'2019'!H6)^(1/7)-1) -> 0.0062533597 | I6: =IF('2019'!I6=0,0,(AME_2030!I6/'2019'!I6)^(1/7)-1) -> -0.001083104 | J6: =IF('2019'!J6=0,0,(AME_2030!J6/'2019'!J6)^(1/7)-1) -> 0.00022818305 | K6: =IF('2019 (Z)'!AW6=0,0,('AME_2030 (Z)'!AW6/'2019 (Z)'!AW6)^(1/7)-1) -> 0.0022937804 | L6: =K6 -> 0.0022937804 | M6: =IF('2019'!M6=0,0,(AME_2030!M6/'2019'!M6)^(1/7)-1) -> 0.00084182489 | N6: =IF('2019'!N6=0,0,(AME_2030!N6/'2019'!N6)^(1/7)-1) -> -0.0016739372 | O6: =IF('2019'!O6=0,0,(AME_2030!O6/'2019'!O6)^(1/7)-1) -> -0.0038404385 | P6: =IF('2019'!P6=0,0,(AME_2030!P6/'2019'!P6)^(1/7)-1) -> 1.5350503e-05 | Q6: =IF('2019'!Q6=0,0,(AME_2030!Q6/'2019'!Q6)^(1/7)-1) -> 1.6442185e-07 | R6: =IF('2019'!R6=0,0,(AME_2030!R6/'2019'!R6)^(1/7)-1) -> -2.0238261e-08 | S6: =T6 -> -1.7908556e-07 | T6: =IF('2019'!T6=0,0,(AME_2030!T6/'2019'!T6)^(1/7)-1) -> -1.7908556e-07 | U6: =IF('2019'!U6=0,0,(AME_2030!U6/'2019'!U6)^(1/7)-1) -> -2.7153555e-06 | V6: =IF('2019'!V6=0,0,(AME_2030!V6/'2019'!V6)^(1/7)-1) -> -2.6346634e-08 | W6: =IF('2019'!W6=0,0,(AME_2030!W6/'2019'!W6)^(1/7)-1) -> 0.00016407789 | X6: =IF('2019'!X6=0,0,(AME_2030!X6/'2019'!X6)^(1/7)-1) -> 0.00049999123 | Y6: =IF('2019'!Y6=0,0,(AME_2030!Y6/'2019'!Y6)^(1/7)-1) -> 0.0024005377 | Z6: =IF('2019'!Z6=0,0,(AME_2030!Z6/'2019'!Z6)^(1/7)-1) -> -0.0011527271 | AA6: =IF('2019'!AA6=0,0,(AME_2030!AA6/'2019'!AA6)^(1/7)-1) -> 0.0013439975 | ... AU6: =IF('2019'!AU6=0,0,(AME_2030!AU6/'2019'!AU6)^(1/7)-1) -> 0
B7: 03 | C7: 03 | D7: Motor vehicles, trailers and semi-trailers | E7: =IF('2019'!E7=0,0,(AME_2030!E7/'2019'!E7)^(1/7)-1) -> -0.00017021846 | F7: =IF('2019'!F7=0,0,(AME_2030!F7/'2019'!F7)^(1/7)-1) -> 0.00023597294 | G7: =IF('2019'!G7=0,0,(AME_2030!G7/'2019'!G7)^(1/7)-1) -> -2.3353149e-09 | H7: =IF('2019'!H7=0,0,(AME_2030!H7/'2019'!H7)^(1/7)-1) -> 0.0039422071 | I7: =IF('2019'!I7=0,0,(AME_2030!I7/'2019'!I7)^(1/7)-1) -> 0.00057751563 | J7: =IF('2019'!J7=0,0,(AME_2030!J7/'2019'!J7)^(1/7)-1) -> 0.00049115518 | K7: =IF('2019 (Z)'!AW7=0,0,('AME_2030 (Z)'!AW7/'2019 (Z)'!AW7)^(1/7)-1) -> 0.0022946097 | L7: =K7 -> 0.0022946097 | M7: =IF('2019'!M7=0,0,(AME_2030!M7/'2019'!M7)^(1/7)-1) -> -0.0061150631 | N7: =IF('2019'!N7=0,0,(AME_2030!N7/'2019'!N7)^(1/7)-1) -> -0.0036935238 | O7: =IF('2019'!O7=0,0,(AME_2030!O7/'2019'!O7)^(1/7)-1) -> 0.0010519187 | P7: =IF('2019'!P7=0,0,(AME_2030!P7/'2019'!P7)^(1/7)-1) -> -0.00062554011 | Q7: =IF('2019'!Q7=0,0,(AME_2030!Q7/'2019'!Q7)^(1/7)-1) -> 1.6442185e-07 | R7: =IF('2019'!R7=0,0,(AME_2030!R7/'2019'!R7)^(1/7)-1) -> -2.0238261e-08 | S7: =T7 -> -2.5259452e-06 | T7: =IF('2019'!T7=0,0,(AME_2030!T7/'2019'!T7)^(1/7)-1) -> -2.5259452e-06 | U7: =IF('2019'!U7=0,0,(AME_2030!U7/'2019'!U7)^(1/7)-1) -> -7.2873332e-06 | V7: =IF('2019'!V7=0,0,(AME_2030!V7/'2019'!V7)^(1/7)-1) -> -2.6346634e-08 | W7: =IF('2019'!W7=0,0,(AME_2030!W7/'2019'!W7)^(1/7)-1) -> -7.9517814e-05 | X7: =IF('2019'!X7=0,0,(AME_2030!X7/'2019'!X7)^(1/7)-1) -> -8.8835412e-06 | Y7: =IF('2019'!Y7=0,0,(AME_2030!Y7/'2019'!Y7)^(1/7)-1) -> 0.0024005377 | Z7: =IF('2019'!Z7=0,0,(AME_2030!Z7/'2019'!Z7)^(1/7)-1) -> -0.0010689398 | AA7: =IF('2019'!AA7=0,0,(AME_2030!AA7/'2019'!AA7)^(1/7)-1) -> 0.0013439412 | ... AU7: =IF('2019'!AU7=0,0,(AME_2030!AU7/'2019'!AU7)^(1/7)-1) -> 0
B8: 04 | C8: 04 | D8: Glass and glass products | E8: =IF('2019'!E8=0,0,(AME_2030!E8/'2019'!E8)^(1/7)-1) -> 0.0097139469 | F8: =IF('2019'!F8=0,0,(AME_2030!F8/'2019'!F8)^(1/7)-1) -> 0.18429546 | G8: =IF('2019'!G8=0,0,(AME_2030!G8/'2019'!G8)^(1/7)-1) -> 0.15472004 | H8: =IF('2019'!H8=0,0,(AME_2030!H8/'2019'!H8)^(1/7)-1) -> -0.10254174 | I8: =IF('2019'!I8=0,0,(AME_2030!I8/'2019'!I8)^(1/7)-1) -> -0.0017907078 | J8: =IF('2019'!J8=0,0,(AME_2030!J8/'2019'!J8)^(1/7)-1) -> -0.02401975 | K8: =IF('2019 (Z)'!AW8=0,0,('AME_2030 (Z)'!AW8/'2019 (Z)'!AW8)^(1/7)-1) -> 0.12539748 | L8: =K8 -> 0.12539748 | M8: =IF('2019'!M8=0,0,(AME_2030!M8/'2019'!M8)^(1/7)-1) -> 0.004625971 | N8: =IF('2019'!N8=0,0,(AME_2030!N8/'2019'!N8)^(1/7)-1) -> -0.0043193728 | O8: =IF('2019'!O8=0,0,(AME_2030!O8/'2019'!O8)^(1/7)-1) -> 0.010489332 | P8: =IF('2019'!P8=0,0,(AME_2030!P8/'2019'!P8)^(1/7)-1) -> -0.024081264 | Q8: =IF('2019'!Q8=0,0,(AME_2030!Q8/'2019'!Q8)^(1/7)-1) -> -0.00060224332 | R8: =IF('2019'!R8=0,0,(AME_2030!R8/'2019'!R8)^(1/7)-1) -> 0.041595517 | S8: =T8 -> -0.0029746563 | T8: =IF('2019'!T8=0,0,(AME_2030!T8/'2019'!T8)^(1/7)-1) -> -0.0029746563 | U8: =IF('2019'!U8=0,0,(AME_2030!U8/'2019'!U8)^(1/7)-1) -> 0.013184157 | V8: =IF('2019'!V8=0,0,(AME_2030!V8/'2019'!V8)^(1/7)-1) -> 0.010740097 | W8: =IF('2019'!W8=0,0,(AME_2030!W8/'2019'!W8)^(1/7)-1) -> -0.0010671182 | X8: =IF('2019'!X8=0,0,(AME_2030!X8/'2019'!X8)^(1/7)-1) -> -0.0011118503 | Y8: =IF('2019'!Y8=0,0,(AME_2030!Y8/'2019'!Y8)^(1/7)-1) -> 0.0036117242 | Z8: =IF('2019'!Z8=0,0,(AME_2030!Z8/'2019'!Z8)^(1/7)-1) -> 0.0028796031 | AA8: =IF('2019'!AA8=0,0,(AME_2030!AA8/'2019'!AA8)^(1/7)-1) -> -0.0014651017 | ... AU8: =IF('2019'!AU8=0,0,(AME_2030!AU8/'2019'!AU8)^(1/7)-1) -> 0
B9: 05 | C9: 05 | D9: Ceramic products and building materials | E9: =IF('2019'!E9=0,0,(AME_2030!E9/'2019'!E9)^(1/7)-1) -> 0.0017572583 | F9: =IF('2019'!F9=0,0,(AME_2030!F9/'2019'!F9)^(1/7)-1) -> -4.4919097e-05 | G9: =IF('2019'!G9=0,0,(AME_2030!G9/'2019'!G9)^(1/7)-1) -> -2.3353151e-09 | H9: =IF('2019'!H9=0,0,(AME_2030!H9/'2019'!H9)^(1/7)-1) -> 0.0089782486 | I9: =IF('2019'!I9=0,0,(AME_2030!I9/'2019'!I9)^(1/7)-1) -> 0.00060127606 | J9: =IF('2019'!J9=0,0,(AME_2030!J9/'2019'!J9)^(1/7)-1) -> 2.6238372e-05 | K9: =IF('2019 (Z)'!AW9=0,0,('AME_2030 (Z)'!AW9/'2019 (Z)'!AW9)^(1/7)-1) -> 0.0022979577 | L9: =K9 -> 0.0022979577 | M9: =IF('2019'!M9=0,0,(AME_2030!M9/'2019'!M9)^(1/7)-1) -> 0.014006948 | N9: =IF('2019'!N9=0,0,(AME_2030!N9/'2019'!N9)^(1/7)-1) -> -0.0011153861 | O9: =IF('2019'!O9=0,0,(AME_2030!O9/'2019'!O9)^(1/7)-1) -> 0.010906863 | P9: =IF('2019'!P9=0,0,(AME_2030!P9/'2019'!P9)^(1/7)-1) -> -0.00033114175 | Q9: =IF('2019'!Q9=0,0,(AME_2030!Q9/'2019'!Q9)^(1/7)-1) -> -0.0014457745 | R9: =IF('2019'!R9=0,0,(AME_2030!R9/'2019'!R9)^(1/7)-1) -> -2.0238261e-08 | S9: =T9 -> 2.7218582e-05 | T9: =IF('2019'!T9=0,0,(AME_2030!T9/'2019'!T9)^(1/7)-1) -> 2.7218582e-05 | U9: =IF('2019'!U9=0,0,(AME_2030!U9/'2019'!U9)^(1/7)-1) -> 1.0886224e-07 | V9: =IF('2019'!V9=0,0,(AME_2030!V9/'2019'!V9)^(1/7)-1) -> -2.6346634e-08 | W9: =IF('2019'!W9=0,0,(AME_2030!W9/'2019'!W9)^(1/7)-1) -> -0.0065455441 | X9: =IF('2019'!X9=0,0,(AME_2030!X9/'2019'!X9)^(1/7)-1) -> -5.3954378e-06 | Y9: =IF('2019'!Y9=0,0,(AME_2030!Y9/'2019'!Y9)^(1/7)-1) -> 0.0024006946 | Z9: =IF('2019'!Z9=0,0,(AME_2030!Z9/'2019'!Z9)^(1/7)-1) -> -0.0007478664 | AA9: =IF('2019'!AA9=0,0,(AME_2030!AA9/'2019'!AA9)^(1/7)-1) -> 0.0013439296 | ... AU9: =IF('2019'!AU9=0,0,(AME_2030!AU9/'2019'!AU9)^(1/7)-1) -> 0
B10: 06 | C10: 06 | D10: Articles of paper and paperboard | E10: =IF('2019'!E10=0,0,(AME_2030!E10/'2019'!E10)^(1/7)-1) -> 0.0062781038 | F10: =IF('2019'!F10=0,0,(AME_2030!F10/'2019'!F10)^(1/7)-1) -> 0.0068410355 | G10: =IF('2019'!G10=0,0,(AME_2030!G10/'2019'!G10)^(1/7)-1) -> -2.3353149e-09 | H10: =IF('2019'!H10=0,0,(AME_2030!H10/'2019'!H10)^(1/7)-1) -> 0.010172025 | I10: =IF('2019'!I10=0,0,(AME_2030!I10/'2019'!I10)^(1/7)-1) -> -0.00051864438 | J10: =IF('2019'!J10=0,0,(AME_2030!J10/'2019'!J10)^(1/7)-1) -> -0.00029435215 | K10: =IF('2019 (Z)'!AW10=0,0,('AME_2030 (Z)'!AW10/'2019 (Z)'!AW10)^(1/7)-1) -> 0.008918326 | L10: =K10 -> 0.008918326 | M10: =IF('2019'!M10=0,0,(AME_2030!M10/'2019'!M10)^(1/7)-1) -> -0.021075676 | N10: =IF('2019'!N10=0,0,(AME_2030!N10/'2019'!N10)^(1/7)-1) -> 0.0035065052 | O10: =IF('2019'!O10=0,0,(AME_2030!O10/'2019'!O10)^(1/7)-1) -> -0.00076565264 | P10: =IF('2019'!P10=0,0,(AME_2030!P10/'2019'!P10)^(1/7)-1) -> 0.0047663682 | Q10: =IF('2019'!Q10=0,0,(AME_2030!Q10/'2019'!Q10)^(1/7)-1) -> 1.492857e-07 | R10: =IF('2019'!R10=0,0,(AME_2030!R10/'2019'!R10)^(1/7)-1) -> -6.9626286e-07 | S10: =T10 -> 0.0012561522 | T10: =IF('2019'!T10=0,0,(AME_2030!T10/'2019'!T10)^(1/7)-1) -> 0.0012561522 | U10: =IF('2019'!U10=0,0,(AME_2030!U10/'2019'!U10)^(1/7)-1) -> -4.6270329e-05 | V10: =IF('2019'!V10=0,0,(AME_2030!V10/'2019'!V10)^(1/7)-1) -> -2.6346634e-08 | W10: =IF('2019'!W10=0,0,(AME_2030!W10/'2019'!W10)^(1/7)-1) -> 0.0066178255 | X10: =IF('2019'!X10=0,0,(AME_2030!X10/'2019'!X10)^(1/7)-1) -> 0.0071120198 | Y10: =IF('2019'!Y10=0,0,(AME_2030!Y10/'2019'!Y10)^(1/7)-1) -> 0.0027175098 | Z10: =IF('2019'!Z10=0,0,(AME_2030!Z10/'2019'!Z10)^(1/7)-1) -> -0.0019560459 | AA10: =IF('2019'!AA10=0,0,(AME_2030!AA10/'2019'!AA10)^(1/7)-1) -> 0.0012614832 | ... AU10: =IF('2019'!AU10=0,0,(AME_2030!AU10/'2019'!AU10)^(1/7)-1) -> 0
B11: 07 | C11: 07 | D11: Inorganic basic chemicals | E11: =IF('2019 (Z)'!E127=0,0,('AME_2030 (Z)'!E127/'2019 (Z)'!E127)^(1/7)-1) -> -0.012232707 | F11: =IF('2019 (Z)'!F127=0,0,('AME_2030 (Z)'!F127/'2019 (Z)'!F127)^(1/7)-1) -> -0.014048726 | G11: =IF('2019 (Z)'!G127=0,0,('AME_2030 (Z)'!G127/'2019 (Z)'!G127)^(1/7)-1) -> -0.014938797 | H11: =IF('2019 (Z)'!H127=0,0,('AME_2030 (Z)'!H127/'2019 (Z)'!H127)^(1/7)-1) -> -0.0050049616 | I11: =IF('2019 (Z)'!I127=0,0,('AME_2030 (Z)'!I127/'2019 (Z)'!I127)^(1/7)-1) -> -0.015499316 | J11: =IF('2019 (Z)'!J127=0,0,('AME_2030 (Z)'!J127/'2019 (Z)'!J127)^(1/7)-1) -> -0.014491784 | K11: =IF('2019 (Z)'!K127=0,0,('AME_2030 (Z)'!K127/'2019 (Z)'!K127)^(1/7)-1) -> -0.012666102 | L11: =IF('2019 (Z)'!L127=0,0,('AME_2030 (Z)'!L127/'2019 (Z)'!L127)^(1/7)-1) -> -0.012666102 | ... R11: =IF('2019 (Z)'!R127=0,0,('AME_2030 (Z)'!R127/'2019 (Z)'!R127)^(1/7)-1) -> -0.014938037 | S11: =T11 -> -0.014142684 | T11: =IF('2019 (Z)'!T127=0,0,('AME_2030 (Z)'!T127/'2019 (Z)'!T127)^(1/7)-1) -> -0.014142684 | U11: =IF('2019 (Z)'!U127=0,0,('AME_2030 (Z)'!U127/'2019 (Z)'!U127)^(1/7)-1) -> -0.014950777 | V11: =IF('2019 (Z)'!V127=0,0,('AME_2030 (Z)'!V127/'2019 (Z)'!V127)^(1/7)-1) -> -0.014938821 | W11: =IF('2019 (Z)'!W127=0,0,('AME_2030 (Z)'!W127/'2019 (Z)'!W127)^(1/7)-1) -> -0.016532777 | X11: =IF('2019 (Z)'!X127=0,0,('AME_2030 (Z)'!X127/'2019 (Z)'!X127)^(1/7)-1) -> -0.014919871 | Y11: =IF('2019 (Z)'!Y127=0,0,('AME_2030 (Z)'!Y127/'2019 (Z)'!Y127)^(1/7)-1) -> -0.012574118 | Z11: =IF('2019 (Z)'!Z127=0,0,('AME_2030 (Z)'!Z127/'2019 (Z)'!Z127)^(1/7)-1) -> -0.015107417 | AA11: =IF('2019 (Z)'!AA127=0,0,('AME_2030 (Z)'!AA127/'2019 (Z)'!AA127)^(1/7)-1) -> -0.01360854 | ... AU11: =IF('2019 (Z)'!AU127=0,0,('AME_2030 (Z)'!AU127/'2019 (Z)'!AU127)^(1/7)-1) -> 0
B12: 08 | C12: 08 | D12: Organic basic chemicals | E12: =E11 -> -0.012232707 | F12: =F11 -> -0.014048726 | G12: =G11 -> -0.014938797 | H12: =H11 -> -0.0050049616 | I12: =I11 -> -0.015499316 | J12: =J11 -> -0.014491784 | K12: =K11 -> -0.012666102 | L12: =L11 -> -0.012666102 | ... R12: =R11 -> -0.014938037 | S12: =T12 -> -0.014142684 | T12: =T11 -> -0.014142684 | U12: =U11 -> -0.014950777 | V12: =V11 -> -0.014938821 | W12: =W11 -> -0.016532777 | X12: =X11 -> -0.014919871 | Y12: =Y11 -> -0.012574118 | Z12: =Z11 -> -0.015107417 | AA12: =AA11 -> -0.01360854 | ... AU12: =AU11 -> 0
B13: 09 | C13: 09 | D13: Plastics products | E13: =IF('2019'!E13=0,0,(AME_2030!E13/'2019'!E13)^(1/7)-1) -> -0.023041319 | F13: =IF('2019'!F13=0,0,(AME_2030!F13/'2019'!F13)^(1/7)-1) -> -0.022615798 | G13: =IF('2019'!G13=0,0,(AME_2030!G13/'2019'!G13)^(1/7)-1) -> 0.11375899 | H13: =IF('2019'!H13=0,0,(AME_2030!H13/'2019'!H13)^(1/7)-1) -> 0.0059118054 | I13: =IF('2019'!I13=0,0,(AME_2030!I13/'2019'!I13)^(1/7)-1) -> -0.00034247169 | J13: =IF('2019'!J13=0,0,(AME_2030!J13/'2019'!J13)^(1/7)-1) -> -5.6445795e-05 | K13: =IF('2019 (Z)'!AW13=0,0,('AME_2030 (Z)'!AW13/'2019 (Z)'!AW13)^(1/7)-1) -> -0.018506549 | L13: =K13 -> -0.018506549 | M13: =IF('2019'!M13=0,0,(AME_2030!M13/'2019'!M13)^(1/7)-1) -> 0.0009201994 | N13: =IF('2019'!N13=0,0,(AME_2030!N13/'2019'!N13)^(1/7)-1) -> 0.0053502517 | O13: =IF('2019'!O13=0,0,(AME_2030!O13/'2019'!O13)^(1/7)-1) -> 0.0023815501 | P13: =IF('2019'!P13=0,0,(AME_2030!P13/'2019'!P13)^(1/7)-1) -> -0.016447839 | Q13: =IF('2019'!Q13=0,0,(AME_2030!Q13/'2019'!Q13)^(1/7)-1) -> 1.6232408e-07 | R13: =IF('2019'!R13=0,0,(AME_2030!R13/'2019'!R13)^(1/7)-1) -> -3.3220551e-08 | S13: =T13 -> -9.3499141e-07 | T13: =IF('2019'!T13=0,0,(AME_2030!T13/'2019'!T13)^(1/7)-1) -> -9.3499141e-07 | U13: =IF('2019'!U13=0,0,(AME_2030!U13/'2019'!U13)^(1/7)-1) -> -3.1512674e-05 | V13: =IF('2019'!V13=0,0,(AME_2030!V13/'2019'!V13)^(1/7)-1) -> 0 | W13: =IF('2019'!W13=0,0,(AME_2030!W13/'2019'!W13)^(1/7)-1) -> -0.023033303 | X13: =IF('2019'!X13=0,0,(AME_2030!X13/'2019'!X13)^(1/7)-1) -> -0.018014984 | Y13: =IF('2019'!Y13=0,0,(AME_2030!Y13/'2019'!Y13)^(1/7)-1) -> 0.0021813868 | Z13: =IF('2019'!Z13=0,0,(AME_2030!Z13/'2019'!Z13)^(1/7)-1) -> -0.0011023493 | AA13: =IF('2019'!AA13=0,0,(AME_2030!AA13/'2019'!AA13)^(1/7)-1) -> 0.0010697181 | ... AU13: =IF('2019'!AU13=0,0,(AME_2030!AU13/'2019'!AU13)^(1/7)-1) -> 0
B14: 10 | C14: 10 | D14: Basic iron and steel and of ferro-alloys | E14: =IF('2019'!E14=0,0,(AME_2030!E14/'2019'!E14)^(1/7)-1) -> 0.0050285925 | F14: =IF('2019'!F14=0,0,(AME_2030!F14/'2019'!F14)^(1/7)-1) -> -0.0023069458 | G14: =IF('2019'!G14=0,0,(AME_2030!G14/'2019'!G14)^(1/7)-1) -> -0.012053245 | H14: =IF('2019'!H14=0,0,(AME_2030!H14/'2019'!H14)^(1/7)-1) -> 0 | I14: =IF('2019'!I14=0,0,(AME_2030!I14/'2019'!I14)^(1/7)-1) -> -0.0019348887 | J14: =IF('2019'!J14=0,0,(AME_2030!J14/'2019'!J14)^(1/7)-1) -> -0.0021898078 | K14: =IF('2019 (Z)'!AW14=0,0,('AME_2030 (Z)'!AW14/'2019 (Z)'!AW14)^(1/7)-1) -> -0.00010507523 | L14: =K14 -> -0.00010507523 | M14: =IF('2019'!M14=0,0,(AME_2030!M14/'2019'!M14)^(1/7)-1) -> -0.002268089 | N14: =IF('2019'!N14=0,0,(AME_2030!N14/'2019'!N14)^(1/7)-1) -> -0.0037918095 | O14: =IF('2019'!O14=0,0,(AME_2030!O14/'2019'!O14)^(1/7)-1) -> -0.0031344206 | P14: =IF('2019'!P14=0,0,(AME_2030!P14/'2019'!P14)^(1/7)-1) -> -0.0019326151 | Q14: =IF('2019'!Q14=0,0,(AME_2030!Q14/'2019'!Q14)^(1/7)-1) -> -0.0025180906 | R14: =IF('2019'!R14=0,0,(AME_2030!R14/'2019'!R14)^(1/7)-1) -> -0.0023932257 | S14: =T14 -> -0.0023611919 | T14: =IF('2019'!T14=0,0,(AME_2030!T14/'2019'!T14)^(1/7)-1) -> -0.0023611919 | U14: =IF('2019'!U14=0,0,(AME_2030!U14/'2019'!U14)^(1/7)-1) -> -0.0019414391 | V14: =IF('2019'!V14=0,0,(AME_2030!V14/'2019'!V14)^(1/7)-1) -> -0.0021169928 | W14: =IF('2019'!W14=0,0,(AME_2030!W14/'2019'!W14)^(1/7)-1) -> -0.0017053511 | X14: =IF('2019'!X14=0,0,(AME_2030!X14/'2019'!X14)^(1/7)-1) -> 0.0017720292 | Y14: =IF('2019'!Y14=0,0,(AME_2030!Y14/'2019'!Y14)^(1/7)-1) -> 1.5081308e-06 | Z14: =IF('2019'!Z14=0,0,(AME_2030!Z14/'2019'!Z14)^(1/7)-1) -> -0.0035080331 | AA14: =IF('2019'!AA14=0,0,(AME_2030!AA14/'2019'!AA14)^(1/7)-1) -> -0.0010524893 | ... AU14: =IF('2019'!AU14=0,0,(AME_2030!AU14/'2019'!AU14)^(1/7)-1) -> 0
B15: 11 | C15: 11 | D15: Non-ferrous metals | E15: =IF('2019'!E15=0,0,(AME_2030!E15/'2019'!E15)^(1/7)-1) -> 0.0073229277 | F15: =IF('2019'!F15=0,0,(AME_2030!F15/'2019'!F15)^(1/7)-1) -> 0.0013368051 | G15: =IF('2019'!G15=0,0,(AME_2030!G15/'2019'!G15)^(1/7)-1) -> 0.13511799 | H15: =IF('2019'!H15=0,0,(AME_2030!H15/'2019'!H15)^(1/7)-1) -> 0.010228447 | I15: =IF('2019'!I15=0,0,(AME_2030!I15/'2019'!I15)^(1/7)-1) -> -0.0010597021 | J15: =IF('2019'!J15=0,0,(AME_2030!J15/'2019'!J15)^(1/7)-1) -> 0.0011637374 | K15: =IF('2019 (Z)'!AW15=0,0,('AME_2030 (Z)'!AW15/'2019 (Z)'!AW15)^(1/7)-1) -> 0.0044523074 | L15: =K15 -> 0.0044523074 | M15: =IF('2019'!M15=0,0,(AME_2030!M15/'2019'!M15)^(1/7)-1) -> 0.0082998513 | N15: =IF('2019'!N15=0,0,(AME_2030!N15/'2019'!N15)^(1/7)-1) -> 0.011354835 | O15: =IF('2019'!O15=0,0,(AME_2030!O15/'2019'!O15)^(1/7)-1) -> -0.0022906053 | P15: =IF('2019'!P15=0,0,(AME_2030!P15/'2019'!P15)^(1/7)-1) -> 0.00073617879 | Q15: =IF('2019'!Q15=0,0,(AME_2030!Q15/'2019'!Q15)^(1/7)-1) -> 0.00012276543 | R15: =IF('2019'!R15=0,0,(AME_2030!R15/'2019'!R15)^(1/7)-1) -> 0.0006301505 | S15: =T15 -> -0.00028029166 | T15: =IF('2019'!T15=0,0,(AME_2030!T15/'2019'!T15)^(1/7)-1) -> -0.00028029166 | U15: =IF('2019'!U15=0,0,(AME_2030!U15/'2019'!U15)^(1/7)-1) -> 6.6664019e-07 | V15: =IF('2019'!V15=0,0,(AME_2030!V15/'2019'!V15)^(1/7)-1) -> -0.00015883153 | W15: =IF('2019'!W15=0,0,(AME_2030!W15/'2019'!W15)^(1/7)-1) -> 0.00075635299 | X15: =IF('2019'!X15=0,0,(AME_2030!X15/'2019'!X15)^(1/7)-1) -> 0.00049973744 | Y15: =IF('2019'!Y15=0,0,(AME_2030!Y15/'2019'!Y15)^(1/7)-1) -> 0.0023470849 | Z15: =IF('2019'!Z15=0,0,(AME_2030!Z15/'2019'!Z15)^(1/7)-1) -> 0.0025729491 | AA15: =IF('2019'!AA15=0,0,(AME_2030!AA15/'2019'!AA15)^(1/7)-1) -> 0.0035005856 | ... AU15: =IF('2019'!AU15=0,0,(AME_2030!AU15/'2019'!AU15)^(1/7)-1) -> 0
B16: 12 | C16: 12 | D16: Other industries | E16: =IF('2019'!E16=0,0,(AME_2030!E16/'2019'!E16)^(1/7)-1) -> 0.00015422655 | F16: =IF('2019'!F16=0,0,(AME_2030!F16/'2019'!F16)^(1/7)-1) -> 5.7738326e-05 | G16: =IF('2019'!G16=0,0,(AME_2030!G16/'2019'!G16)^(1/7)-1) -> 4.899458e-05 | H16: =IF('2019'!H16=0,0,(AME_2030!H16/'2019'!H16)^(1/7)-1) -> -0.032419922 | I16: =IF('2019'!I16=0,0,(AME_2030!I16/'2019'!I16)^(1/7)-1) -> -9.6930831e-05 | J16: =IF('2019'!J16=0,0,(AME_2030!J16/'2019'!J16)^(1/7)-1) -> -0.0016014158 | K16: =IF('2019 (Z)'!AW16=0,0,('AME_2030 (Z)'!AW16/'2019 (Z)'!AW16)^(1/7)-1) -> 0.0022992686 | L16: =K16 -> 0.0022992686 | M16: =IF('2019'!M16=0,0,(AME_2030!M16/'2019'!M16)^(1/7)-1) -> 0.0065322225 | N16: =IF('2019'!N16=0,0,(AME_2030!N16/'2019'!N16)^(1/7)-1) -> -0.00090129465 | O16: =IF('2019'!O16=0,0,(AME_2030!O16/'2019'!O16)^(1/7)-1) -> 0.0031666931 | P16: =IF('2019'!P16=0,0,(AME_2030!P16/'2019'!P16)^(1/7)-1) -> 2.9623938e-05 | Q16: =IF('2019'!Q16=0,0,(AME_2030!Q16/'2019'!Q16)^(1/7)-1) -> 0.0030159972 | R16: =IF('2019'!R16=0,0,(AME_2030!R16/'2019'!R16)^(1/7)-1) -> -2.0238261e-08 | S16: =T16 -> 2.588167e-05 | T16: =IF('2019'!T16=0,0,(AME_2030!T16/'2019'!T16)^(1/7)-1) -> 2.588167e-05 | U16: =IF('2019'!U16=0,0,(AME_2030!U16/'2019'!U16)^(1/7)-1) -> -3.2228987e-05 | V16: =IF('2019'!V16=0,0,(AME_2030!V16/'2019'!V16)^(1/7)-1) -> -2.6346634e-08 | W16: =IF('2019'!W16=0,0,(AME_2030!W16/'2019'!W16)^(1/7)-1) -> -0.00042156542 | X16: =IF('2019'!X16=0,0,(AME_2030!X16/'2019'!X16)^(1/7)-1) -> -1.6294352e-05 | Y16: =IF('2019'!Y16=0,0,(AME_2030!Y16/'2019'!Y16)^(1/7)-1) -> 0.0024005377 | Z16: =IF('2019'!Z16=0,0,(AME_2030!Z16/'2019'!Z16)^(1/7)-1) -> -0.0011357484 | AA16: =IF('2019'!AA16=0,0,(AME_2030!AA16/'2019'!AA16)^(1/7)-1) -> 0.0013440062 | ... AU16: =IF('2019'!AU16=0,0,(AME_2030!AU16/'2019'!AU16)^(1/7)-1) -> 0
B17: 13 | C17: 13 | D17: Construction of buildings and Civil engineering | E17: =IF('2019'!E17=0,0,(AME_2030!E17/'2019'!E17)^(1/7)-1) -> 0.0012955289 | F17: =IF('2019'!F17=0,0,(AME_2030!F17/'2019'!F17)^(1/7)-1) -> 0.00028725348 | G17: =IF('2019'!G17=0,0,(AME_2030!G17/'2019'!G17)^(1/7)-1) -> -2.3353151e-09 | H17: =IF('2019'!H17=0,0,(AME_2030!H17/'2019'!H17)^(1/7)-1) -> 0.014345032 | I17: =IF('2019'!I17=0,0,(AME_2030!I17/'2019'!I17)^(1/7)-1) -> 0.00011444342 | J17: =IF('2019'!J17=0,0,(AME_2030!J17/'2019'!J17)^(1/7)-1) -> 0.0002332246 | K17: =IF('2019 (Z)'!AW17=0,0,('AME_2030 (Z)'!AW17/'2019 (Z)'!AW17)^(1/7)-1) -> 0.0023042647 | L17: =K17 -> 0.0023042647 | M17: =IF('2019'!M17=0,0,(AME_2030!M17/'2019'!M17)^(1/7)-1) -> 0.0097190254 | N17: =IF('2019'!N17=0,0,(AME_2030!N17/'2019'!N17)^(1/7)-1) -> -0.00057882025 | O17: =IF('2019'!O17=0,0,(AME_2030!O17/'2019'!O17)^(1/7)-1) -> 0.0055832409 | P17: =IF('2019'!P17=0,0,(AME_2030!P17/'2019'!P17)^(1/7)-1) -> -0.00026971345 | Q17: =IF('2019'!Q17=0,0,(AME_2030!Q17/'2019'!Q17)^(1/7)-1) -> 1.6442185e-07 | R17: =IF('2019'!R17=0,0,(AME_2030!R17/'2019'!R17)^(1/7)-1) -> -2.0238261e-08 | S17: =T17 -> 1.8950996e-05 | T17: =IF('2019'!T17=0,0,(AME_2030!T17/'2019'!T17)^(1/7)-1) -> 1.8950996e-05 | U17: =IF('2019'!U17=0,0,(AME_2030!U17/'2019'!U17)^(1/7)-1) -> -1.4453742e-05 | V17: =IF('2019'!V17=0,0,(AME_2030!V17/'2019'!V17)^(1/7)-1) -> -2.6346634e-08 | W17: =IF('2019'!W17=0,0,(AME_2030!W17/'2019'!W17)^(1/7)-1) -> -0.00063346482 | X17: =IF('2019'!X17=0,0,(AME_2030!X17/'2019'!X17)^(1/7)-1) -> 1.8122132e-06 | Y17: =IF('2019'!Y17=0,0,(AME_2030!Y17/'2019'!Y17)^(1/7)-1) -> 0.0024005377 | Z17: =IF('2019'!Z17=0,0,(AME_2030!Z17/'2019'!Z17)^(1/7)-1) -> -0.0011430572 | AA17: =IF('2019'!AA17=0,0,(AME_2030!AA17/'2019'!AA17)^(1/7)-1) -> 0.0013439953 | ... AU17: =IF('2019'!AU17=0,0,(AME_2030!AU17/'2019'!AU17)^(1/7)-1) -> 0
B18: 14 | C18: 14 | D18: Rail transport (Passenger and Freight) | E18: =IF('2019'!E18=0,0,(AME_2030!E18/'2019'!E18)^(1/7)-1) -> -0.00038948296 | F18: =IF('2019'!F18=0,0,(AME_2030!F18/'2019'!F18)^(1/7)-1) -> 0.00011100964 | G18: =IF('2019'!G18=0,0,(AME_2030!G18/'2019'!G18)^(1/7)-1) -> -2.3353149e-09 | H18: =IF('2019'!H18=0,0,(AME_2030!H18/'2019'!H18)^(1/7)-1) -> 0.013548732 | I18: =IF('2019'!I18=0,0,(AME_2030!I18/'2019'!I18)^(1/7)-1) -> 6.2856168e-06 | J18: =IF('2019'!J18=0,0,(AME_2030!J18/'2019'!J18)^(1/7)-1) -> -0.0019709509 | K18: =IF('2019 (Z)'!AW18=0,0,('AME_2030 (Z)'!AW18/'2019 (Z)'!AW18)^(1/7)-1) -> 0.0023245323 | L18: =K18 -> 0.0023245323 | M18: =IF('2019'!M18=0,0,(AME_2030!M18/'2019'!M18)^(1/7)-1) -> 0.016341139 | N18: =IF('2019'!N18=0,0,(AME_2030!N18/'2019'!N18)^(1/7)-1) -> -0.01379648 | O18: =IF('2019'!O18=0,0,(AME_2030!O18/'2019'!O18)^(1/7)-1) -> 0.0020462945 | P18: =IF('2019'!P18=0,0,(AME_2030!P18/'2019'!P18)^(1/7)-1) -> 0.00011699906 | Q18: =IF('2019'!Q18=0,0,(AME_2030!Q18/'2019'!Q18)^(1/7)-1) -> 1.6442185e-07 | R18: =IF('2019'!R18=0,0,(AME_2030!R18/'2019'!R18)^(1/7)-1) -> -2.0238261e-08 | S18: =T18 -> -6.8356769e-07 | T18: =IF('2019'!T18=0,0,(AME_2030!T18/'2019'!T18)^(1/7)-1) -> -6.8356769e-07 | U18: =IF('2019'!U18=0,0,(AME_2030!U18/'2019'!U18)^(1/7)-1) -> -2.9816359e-05 | V18: =IF('2019'!V18=0,0,(AME_2030!V18/'2019'!V18)^(1/7)-1) -> -2.6346634e-08 | W18: =IF('2019'!W18=0,0,(AME_2030!W18/'2019'!W18)^(1/7)-1) -> -0.00018015969 | X18: =IF('2019'!X18=0,0,(AME_2030!X18/'2019'!X18)^(1/7)-1) -> 1.5750694e-05 | Y18: =IF('2019'!Y18=0,0,(AME_2030!Y18/'2019'!Y18)^(1/7)-1) -> 0.0024005377 | Z18: =IF('2019'!Z18=0,0,(AME_2030!Z18/'2019'!Z18)^(1/7)-1) -> -0.0011472953 | AA18: =IF('2019'!AA18=0,0,(AME_2030!AA18/'2019'!AA18)^(1/7)-1) -> 0.0013439994 | ... AU18: =IF('2019'!AU18=0,0,(AME_2030!AU18/'2019'!AU18)^(1/7)-1) -> 0
B19: 15 | C19: 15 | D19: Passenger transport by road | E19: =E20 -> -0.00037330182 | F19: =F20 -> 0.00021106379 | G19: =G20 -> -2.3353149e-09 | H19: =H20 -> 0.013591861 | I19: =I20 -> 0.00021342568 | J19: =J20 -> -0.00093420613 | K19: =K20 -> 0.002331404 | L19: =L20 -> 0.002331404 | ... R19: =R20 -> -2.0238261e-08 | S19: =T19 -> 2.220413e-05 | T19: =T20 -> 2.220413e-05 | U19: =U20 -> -2.9484693e-05 | V19: =V20 -> -2.6346634e-08 | W19: =W20 -> 0.00052784111 | X19: =X20 -> 4.2754041e-06 | Y19: =Y20 -> 0.0024005377 | Z19: =Z20 -> -0.0011542043 | AA19: =AA20 -> 0.0013439655 | ... AU19: =AU20 -> 0
B20: 16 | C20: 16 | D20: Freight transport by road and transport via pipeline | E20: =IF('2019'!E20=0,0,(AME_2030!E20/'2019'!E20)^(1/7)-1) -> -0.00037330182 | F20: =IF('2019'!F20=0,0,(AME_2030!F20/'2019'!F20)^(1/7)-1) -> 0.00021106379 | G20: =IF('2019'!G20=0,0,(AME_2030!G20/'2019'!G20)^(1/7)-1) -> -2.3353149e-09 | H20: =IF('2019'!H20=0,0,(AME_2030!H20/'2019'!H20)^(1/7)-1) -> 0.013591861 | I20: =IF('2019'!I20=0,0,(AME_2030!I20/'2019'!I20)^(1/7)-1) -> 0.00021342568 | J20: =IF('2019'!J20=0,0,(AME_2030!J20/'2019'!J20)^(1/7)-1) -> -0.00093420613 | K20: =IF('2019 (Z)'!AW20=0,0,('AME_2030 (Z)'!AW20/'2019 (Z)'!AW20)^(1/7)-1) -> 0.002331404 | L20: =K20 -> 0.002331404 | M20: =IF('2019'!M20=0,0,(AME_2030!M20/'2019'!M20)^(1/7)-1) -> 0.032518991 | N20: =IF('2019'!N20=0,0,(AME_2030!N20/'2019'!N20)^(1/7)-1) -> 0.0012240107 | O20: =IF('2019'!O20=0,0,(AME_2030!O20/'2019'!O20)^(1/7)-1) -> 0.0012463825 | P20: =IF('2019'!P20=0,0,(AME_2030!P20/'2019'!P20)^(1/7)-1) -> 0.00019809474 | Q20: =IF('2019'!Q20=0,0,(AME_2030!Q20/'2019'!Q20)^(1/7)-1) -> 1.6442185e-07 | R20: =IF('2019'!R20=0,0,(AME_2030!R20/'2019'!R20)^(1/7)-1) -> -2.0238261e-08 | S20: =T20 -> 2.220413e-05 | T20: =IF('2019'!T20=0,0,(AME_2030!T20/'2019'!T20)^(1/7)-1) -> 2.220413e-05 | U20: =IF('2019'!U20=0,0,(AME_2030!U20/'2019'!U20)^(1/7)-1) -> -2.9484693e-05 | V20: =IF('2019'!V20=0,0,(AME_2030!V20/'2019'!V20)^(1/7)-1) -> -2.6346634e-08 | W20: =IF('2019'!W20=0,0,(AME_2030!W20/'2019'!W20)^(1/7)-1) -> 0.00052784111 | X20: =IF('2019'!X20=0,0,(AME_2030!X20/'2019'!X20)^(1/7)-1) -> 4.2754041e-06 | Y20: =IF('2019'!Y20=0,0,(AME_2030!Y20/'2019'!Y20)^(1/7)-1) -> 0.0024005377 | Z20: =IF('2019'!Z20=0,0,(AME_2030!Z20/'2019'!Z20)^(1/7)-1) -> -0.0011542043 | AA20: =IF('2019'!AA20=0,0,(AME_2030!AA20/'2019'!AA20)^(1/7)-1) -> 0.0013439655 | ... AU20: =IF('2019'!AU20=0,0,(AME_2030!AU20/'2019'!AU20)^(1/7)-1) -> 0
B21: 17 | C21: 17 | D21: Water transport | E21: =IF('2019'!E21=0,0,(AME_2030!E21/'2019'!E21)^(1/7)-1) -> -0.00055841202 | F21: =IF('2019'!F21=0,0,(AME_2030!F21/'2019'!F21)^(1/7)-1) -> 0.00012750023 | G21: =IF('2019'!G21=0,0,(AME_2030!G21/'2019'!G21)^(1/7)-1) -> -2.3353149e-09 | H21: =IF('2019'!H21=0,0,(AME_2030!H21/'2019'!H21)^(1/7)-1) -> 0.013548732 | I21: =IF('2019'!I21=0,0,(AME_2030!I21/'2019'!I21)^(1/7)-1) -> -0.00021974685 | J21: =IF('2019'!J21=0,0,(AME_2030!J21/'2019'!J21)^(1/7)-1) -> -0.0032097826 | K21: =IF('2019 (Z)'!AW21=0,0,('AME_2030 (Z)'!AW21/'2019 (Z)'!AW21)^(1/7)-1) -> 0.0024052062 | L21: =K21 -> 0.0024052062 | M21: =IF('2019'!M21=0,0,(AME_2030!M21/'2019'!M21)^(1/7)-1) -> 0.047841231 | N21: =IF('2019'!N21=0,0,(AME_2030!N21/'2019'!N21)^(1/7)-1) -> 0.0018555418 | O21: =IF('2019'!O21=0,0,(AME_2030!O21/'2019'!O21)^(1/7)-1) -> 0.0020405095 | P21: =IF('2019'!P21=0,0,(AME_2030!P21/'2019'!P21)^(1/7)-1) -> 0.00057612029 | Q21: =IF('2019'!Q21=0,0,(AME_2030!Q21/'2019'!Q21)^(1/7)-1) -> 1.6442185e-07 | R21: =IF('2019'!R21=0,0,(AME_2030!R21/'2019'!R21)^(1/7)-1) -> -2.0238261e-08 | S21: =T21 -> 1.0622255e-05 | T21: =IF('2019'!T21=0,0,(AME_2030!T21/'2019'!T21)^(1/7)-1) -> 1.0622255e-05 | U21: =IF('2019'!U21=0,0,(AME_2030!U21/'2019'!U21)^(1/7)-1) -> 7.5672153e-06 | V21: =IF('2019'!V21=0,0,(AME_2030!V21/'2019'!V21)^(1/7)-1) -> -2.6346634e-08 | W21: =IF('2019'!W21=0,0,(AME_2030!W21/'2019'!W21)^(1/7)-1) -> -0.00088842062 | X21: =IF('2019'!X21=0,0,(AME_2030!X21/'2019'!X21)^(1/7)-1) -> 1.9605699e-06 | Y21: =IF('2019'!Y21=0,0,(AME_2030!Y21/'2019'!Y21)^(1/7)-1) -> 0.0024005377 | Z21: =IF('2019'!Z21=0,0,(AME_2030!Z21/'2019'!Z21)^(1/7)-1) -> -0.0011257782 | AA21: =IF('2019'!AA21=0,0,(AME_2030!AA21/'2019'!AA21)^(1/7)-1) -> 0.0013440024 | ... AU21: =IF('2019'!AU21=0,0,(AME_2030!AU21/'2019'!AU21)^(1/7)-1) -> 0
B22: 18 | C22: 18 | D22: Air transport | E22: =IF('2019'!E22=0,0,(AME_2030!E22/'2019'!E22)^(1/7)-1) -> -0.00075039922 | F22: =IF('2019'!F22=0,0,(AME_2030!F22/'2019'!F22)^(1/7)-1) -> 9.751166e-05 | G22: =IF('2019'!G22=0,0,(AME_2030!G22/'2019'!G22)^(1/7)-1) -> -2.3353149e-09 | H22: =IF('2019'!H22=0,0,(AME_2030!H22/'2019'!H22)^(1/7)-1) -> 0.014202559 | I22: =IF('2019'!I22=0,0,(AME_2030!I22/'2019'!I22)^(1/7)-1) -> -0.0002433484 | J22: =IF('2019'!J22=0,0,(AME_2030!J22/'2019'!J22)^(1/7)-1) -> -0.00029526049 | K22: =IF('2019 (Z)'!AW22=0,0,('AME_2030 (Z)'!AW22/'2019 (Z)'!AW22)^(1/7)-1) -> 0.0022977829 | L22: =K22 -> 0.0022977829 | M22: =IF('2019'!M22=0,0,(AME_2030!M22/'2019'!M22)^(1/7)-1) -> -0.0114786 | N22: =IF('2019'!N22=0,0,(AME_2030!N22/'2019'!N22)^(1/7)-1) -> -0.015944822 | O22: =IF('2019'!O22=0,0,(AME_2030!O22/'2019'!O22)^(1/7)-1) -> 0.0021432553 | P22: =IF('2019'!P22=0,0,(AME_2030!P22/'2019'!P22)^(1/7)-1) -> 0.00023977016 | Q22: =IF('2019'!Q22=0,0,(AME_2030!Q22/'2019'!Q22)^(1/7)-1) -> 1.6442185e-07 | R22: =IF('2019'!R22=0,0,(AME_2030!R22/'2019'!R22)^(1/7)-1) -> -2.0238261e-08 | S22: =T22 -> 3.8662049e-06 | T22: =IF('2019'!T22=0,0,(AME_2030!T22/'2019'!T22)^(1/7)-1) -> 3.8662049e-06 | U22: =IF('2019'!U22=0,0,(AME_2030!U22/'2019'!U22)^(1/7)-1) -> -1.2235463e-05 | V22: =IF('2019'!V22=0,0,(AME_2030!V22/'2019'!V22)^(1/7)-1) -> -2.6346634e-08 | W22: =IF('2019'!W22=0,0,(AME_2030!W22/'2019'!W22)^(1/7)-1) -> 0.00028336675 | X22: =IF('2019'!X22=0,0,(AME_2030!X22/'2019'!X22)^(1/7)-1) -> 1.0581962e-05 | Y22: =IF('2019'!Y22=0,0,(AME_2030!Y22/'2019'!Y22)^(1/7)-1) -> 0.0024005377 | Z22: =IF('2019'!Z22=0,0,(AME_2030!Z22/'2019'!Z22)^(1/7)-1) -> -0.0011566979 | AA22: =IF('2019'!AA22=0,0,(AME_2030!AA22/'2019'!AA22)^(1/7)-1) -> 0.0013439981 | ... AU22: =IF('2019'!AU22=0,0,(AME_2030!AU22/'2019'!AU22)^(1/7)-1) -> 0
B23: 19 | C23: 19 | D23: Business services | E23: =IF('2019'!E23=0,0,(AME_2030!E23/'2019'!E23)^(1/7)-1) -> -0.0003923783 | F23: =IF('2019'!F23=0,0,(AME_2030!F23/'2019'!F23)^(1/7)-1) -> -0.00021321895 | G23: =IF('2019'!G23=0,0,(AME_2030!G23/'2019'!G23)^(1/7)-1) -> -0.0003334965 | H23: =IF('2019'!H23=0,0,(AME_2030!H23/'2019'!H23)^(1/7)-1) -> 0.0029960267 | I23: =IF('2019'!I23=0,0,(AME_2030!I23/'2019'!I23)^(1/7)-1) -> -0.00085004437 | J23: =IF('2019'!J23=0,0,(AME_2030!J23/'2019'!J23)^(1/7)-1) -> -0.00029399541 | K23: =IF('2019 (Z)'!AW23=0,0,('AME_2030 (Z)'!AW23/'2019 (Z)'!AW23)^(1/7)-1) -> 0.0022735432 | L23: =K23 -> 0.0022735432 | M23: =IF('2019'!M23=0,0,(AME_2030!M23/'2019'!M23)^(1/7)-1) -> 0.0090651885 | N23: =IF('2019'!N23=0,0,(AME_2030!N23/'2019'!N23)^(1/7)-1) -> -0.006734809 | O23: =IF('2019'!O23=0,0,(AME_2030!O23/'2019'!O23)^(1/7)-1) -> 0.00096610984 | P23: =IF('2019'!P23=0,0,(AME_2030!P23/'2019'!P23)^(1/7)-1) -> -0.00040248313 | Q23: =IF('2019'!Q23=0,0,(AME_2030!Q23/'2019'!Q23)^(1/7)-1) -> -0.00022802669 | R23: =IF('2019'!R23=0,0,(AME_2030!R23/'2019'!R23)^(1/7)-1) -> -0.000112276 | S23: =T23 -> -2.1216306e-05 | T23: =IF('2019'!T23=0,0,(AME_2030!T23/'2019'!T23)^(1/7)-1) -> -2.1216306e-05 | U23: =IF('2019'!U23=0,0,(AME_2030!U23/'2019'!U23)^(1/7)-1) -> -0.00019648459 | V23: =IF('2019'!V23=0,0,(AME_2030!V23/'2019'!V23)^(1/7)-1) -> -0.00015338063 | W23: =IF('2019'!W23=0,0,(AME_2030!W23/'2019'!W23)^(1/7)-1) -> -9.0643037e-05 | X23: =IF('2019'!X23=0,0,(AME_2030!X23/'2019'!X23)^(1/7)-1) -> -0.00045293763 | Y23: =IF('2019'!Y23=0,0,(AME_2030!Y23/'2019'!Y23)^(1/7)-1) -> 0.0021769947 | Z23: =IF('2019'!Z23=0,0,(AME_2030!Z23/'2019'!Z23)^(1/7)-1) -> -0.0021494606 | AA23: =IF('2019'!AA23=0,0,(AME_2030!AA23/'2019'!AA23)^(1/7)-1) -> 0.0013104113 | ... AU23: =IF('2019'!AU23=0,0,(AME_2030!AU23/'2019'!AU23)^(1/7)-1) -> 0
B24: 20 | C24: 20 | D24: Public services | E24: =IF('2019'!E24=0,0,(AME_2030!E24/'2019'!E24)^(1/7)-1) -> 0.00059221996 | F24: =IF('2019'!F24=0,0,(AME_2030!F24/'2019'!F24)^(1/7)-1) -> 5.9725089e-05 | G24: =IF('2019'!G24=0,0,(AME_2030!G24/'2019'!G24)^(1/7)-1) -> -2.3353151e-09 | H24: =IF('2019'!H24=0,0,(AME_2030!H24/'2019'!H24)^(1/7)-1) -> 0.033808394 | I24: =IF('2019'!I24=0,0,(AME_2030!I24/'2019'!I24)^(1/7)-1) -> -0.00025619223 | J24: =IF('2019'!J24=0,0,(AME_2030!J24/'2019'!J24)^(1/7)-1) -> -0.0072948281 | K24: =IF('2019 (Z)'!AW24=0,0,('AME_2030 (Z)'!AW24/'2019 (Z)'!AW24)^(1/7)-1) -> 0.0022955051 | L24: =K24 -> 0.0022955051 | M24: =IF('2019'!M24=0,0,(AME_2030!M24/'2019'!M24)^(1/7)-1) -> 0.0035629826 | N24: =IF('2019'!N24=0,0,(AME_2030!N24/'2019'!N24)^(1/7)-1) -> 0.016156425 | O24: =IF('2019'!O24=0,0,(AME_2030!O24/'2019'!O24)^(1/7)-1) -> 0.0028134881 | P24: =IF('2019'!P24=0,0,(AME_2030!P24/'2019'!P24)^(1/7)-1) -> -0.00016399946 | Q24: =IF('2019'!Q24=0,0,(AME_2030!Q24/'2019'!Q24)^(1/7)-1) -> 1.6442185e-07 | R24: =IF('2019'!R24=0,0,(AME_2030!R24/'2019'!R24)^(1/7)-1) -> -2.0238261e-08 | S24: =T24 -> 2.1301747e-06 | T24: =IF('2019'!T24=0,0,(AME_2030!T24/'2019'!T24)^(1/7)-1) -> 2.1301747e-06 | U24: =IF('2019'!U24=0,0,(AME_2030!U24/'2019'!U24)^(1/7)-1) -> -4.0218943e-05 | V24: =IF('2019'!V24=0,0,(AME_2030!V24/'2019'!V24)^(1/7)-1) -> -2.6346634e-08 | W24: =IF('2019'!W24=0,0,(AME_2030!W24/'2019'!W24)^(1/7)-1) -> -0.00030544359 | X24: =IF('2019'!X24=0,0,(AME_2030!X24/'2019'!X24)^(1/7)-1) -> -7.4898273e-06 | Y24: =IF('2019'!Y24=0,0,(AME_2030!Y24/'2019'!Y24)^(1/7)-1) -> 0.0024005377 | Z24: =IF('2019'!Z24=0,0,(AME_2030!Z24/'2019'!Z24)^(1/7)-1) -> -0.0011439708 | AA24: =IF('2019'!AA24=0,0,(AME_2030!AA24/'2019'!AA24)^(1/7)-1) -> 0.0013438777 | ... AU24: =IF('2019'!AU24=0,0,(AME_2030!AU24/'2019'!AU24)^(1/7)-1) -> 0
B25: 21 | C25: 21 | D25: Coal | E25: =IF('2019'!E25=0,0,(AME_2030!E25/'2019'!E25)^(1/7)-1) -> 0 | F25: =IF('2019'!F25=0,0,(AME_2030!F25/'2019'!F25)^(1/7)-1) -> -0.00011650399 | G25: =IF('2019'!G25=0,0,(AME_2030!G25/'2019'!G25)^(1/7)-1) -> -2.3353149e-09 | H25: =IF('2019'!H25=0,0,(AME_2030!H25/'2019'!H25)^(1/7)-1) -> -0.080107715 | I25: =IF('2019'!I25=0,0,(AME_2030!I25/'2019'!I25)^(1/7)-1) -> -0.00040471178 | J25: =IF('2019'!J25=0,0,(AME_2030!J25/'2019'!J25)^(1/7)-1) -> 0 | K25: =IF('2019 (Z)'!AW25=0,0,('AME_2030 (Z)'!AW25/'2019 (Z)'!AW25)^(1/7)-1) -> 0.0023299226 | L25: =K25 -> 0.0023299226 | M25: =IF('2019'!M25=0,0,(AME_2030!M25/'2019'!M25)^(1/7)-1) -> -0.043752193 | N25: =IF('2019'!N25=0,0,(AME_2030!N25/'2019'!N25)^(1/7)-1) -> 0.068221988 | O25: =IF('2019'!O25=0,0,(AME_2030!O25/'2019'!O25)^(1/7)-1) -> -0.010778 | P25: =IF('2019'!P25=0,0,(AME_2030!P25/'2019'!P25)^(1/7)-1) -> 0.00051101568 | Q25: =IF('2019'!Q25=0,0,(AME_2030!Q25/'2019'!Q25)^(1/7)-1) -> 1.6442185e-07 | R25: =IF('2019'!R25=0,0,(AME_2030!R25/'2019'!R25)^(1/7)-1) -> 0 | S25: =T25 -> 0 | T25: =IF('2019'!T25=0,0,(AME_2030!T25/'2019'!T25)^(1/7)-1) -> 0 | U25: =IF('2019'!U25=0,0,(AME_2030!U25/'2019'!U25)^(1/7)-1) -> 0 | V25: =IF('2019'!V25=0,0,(AME_2030!V25/'2019'!V25)^(1/7)-1) -> 0 | W25: =IF('2019'!W25=0,0,(AME_2030!W25/'2019'!W25)^(1/7)-1) -> 0 | X25: =IF('2019'!X25=0,0,(AME_2030!X25/'2019'!X25)^(1/7)-1) -> 0 | Y25: =IF('2019'!Y25=0,0,(AME_2030!Y25/'2019'!Y25)^(1/7)-1) -> 0 | Z25: =IF('2019'!Z25=0,0,(AME_2030!Z25/'2019'!Z25)^(1/7)-1) -> -0.00094348629 | AA25: =IF('2019'!AA25=0,0,(AME_2030!AA25/'2019'!AA25)^(1/7)-1) -> 0.0013440117 | ... AU25: =IF('2019'!AU25=0,0,(AME_2030!AU25/'2019'!AU25)^(1/7)-1) -> 0
B26: 22 | C26: 22 | D26: Oil | E26: =IF('2019'!E26=0,0,(AME_2030!E26/'2019'!E26)^(1/7)-1) -> -0.00018706081 | F26: =IF('2019'!F26=0,0,(AME_2030!F26/'2019'!F26)^(1/7)-1) -> 0.00038140391 | G26: =IF('2019'!G26=0,0,(AME_2030!G26/'2019'!G26)^(1/7)-1) -> -2.3353149e-09 | H26: =IF('2019'!H26=0,0,(AME_2030!H26/'2019'!H26)^(1/7)-1) -> -0.057649093 | I26: =IF('2019'!I26=0,0,(AME_2030!I26/'2019'!I26)^(1/7)-1) -> -0.00074861532 | J26: =IF('2019'!J26=0,0,(AME_2030!J26/'2019'!J26)^(1/7)-1) -> -0.0031385328 | K26: =IF('2019 (Z)'!AW26=0,0,('AME_2030 (Z)'!AW26/'2019 (Z)'!AW26)^(1/7)-1) -> 0.0023451415 | L26: =K26 -> 0.0023451415 | M26: =IF('2019'!M26=0,0,(AME_2030!M26/'2019'!M26)^(1/7)-1) -> 0.0051330029 | N26: =IF('2019'!N26=0,0,(AME_2030!N26/'2019'!N26)^(1/7)-1) -> -0.038887703 | O26: =IF('2019'!O26=0,0,(AME_2030!O26/'2019'!O26)^(1/7)-1) -> -0.010259007 | P26: =IF('2019'!P26=0,0,(AME_2030!P26/'2019'!P26)^(1/7)-1) -> 0.0012818787 | Q26: =IF('2019'!Q26=0,0,(AME_2030!Q26/'2019'!Q26)^(1/7)-1) -> 1.6442185e-07 | R26: =IF('2019'!R26=0,0,(AME_2030!R26/'2019'!R26)^(1/7)-1) -> -2.0238261e-08 | S26: =T26 -> -2.5547003e-06 | T26: =IF('2019'!T26=0,0,(AME_2030!T26/'2019'!T26)^(1/7)-1) -> -2.5547003e-06 | U26: =IF('2019'!U26=0,0,(AME_2030!U26/'2019'!U26)^(1/7)-1) -> -3.8892926e-05 | V26: =IF('2019'!V26=0,0,(AME_2030!V26/'2019'!V26)^(1/7)-1) -> -2.6346634e-08 | W26: =IF('2019'!W26=0,0,(AME_2030!W26/'2019'!W26)^(1/7)-1) -> 2.1101728e-05 | X26: =IF('2019'!X26=0,0,(AME_2030!X26/'2019'!X26)^(1/7)-1) -> -3.416616e-06 | Y26: =IF('2019'!Y26=0,0,(AME_2030!Y26/'2019'!Y26)^(1/7)-1) -> 0.0024005377 | Z26: =IF('2019'!Z26=0,0,(AME_2030!Z26/'2019'!Z26)^(1/7)-1) -> -0.0011564822 | AA26: =IF('2019'!AA26=0,0,(AME_2030!AA26/'2019'!AA26)^(1/7)-1) -> 0.0013438091 | ... AU26: =IF('2019'!AU26=0,0,(AME_2030!AU26/'2019'!AU26)^(1/7)-1) -> 0
B27: 23 | C27: 23 | D27: Biofuel | E27: =IF('2019'!E27=0,0,(AME_2030!E27/'2019'!E27)^(1/7)-1) -> 0.00015631919 | F27: =IF('2019'!F27=0,0,(AME_2030!F27/'2019'!F27)^(1/7)-1) -> 0.00081507841 | G27: =IF('2019'!G27=0,0,(AME_2030!G27/'2019'!G27)^(1/7)-1) -> -2.3353151e-09 | H27: =IF('2019'!H27=0,0,(AME_2030!H27/'2019'!H27)^(1/7)-1) -> 0.11976939 | I27: =IF('2019'!I27=0,0,(AME_2030!I27/'2019'!I27)^(1/7)-1) -> -0.00037575257 | J27: =IF('2019'!J27=0,0,(AME_2030!J27/'2019'!J27)^(1/7)-1) -> 0 | K27: =IF('2019 (Z)'!AW27=0,0,('AME_2030 (Z)'!AW27/'2019 (Z)'!AW27)^(1/7)-1) -> 0.0022936901 | L27: =K27 -> 0.0022936901 | M27: =IF('2019'!M27=0,0,(AME_2030!M27/'2019'!M27)^(1/7)-1) -> -0.001024403 | N27: =IF('2019'!N27=0,0,(AME_2030!N27/'2019'!N27)^(1/7)-1) -> -0.0013528264 | O27: =IF('2019'!O27=0,0,(AME_2030!O27/'2019'!O27)^(1/7)-1) -> -0.020719813 | P27: =IF('2019'!P27=0,0,(AME_2030!P27/'2019'!P27)^(1/7)-1) -> 0.0002651138 | Q27: =IF('2019'!Q27=0,0,(AME_2030!Q27/'2019'!Q27)^(1/7)-1) -> 1.6442185e-07 | R27: =IF('2019'!R27=0,0,(AME_2030!R27/'2019'!R27)^(1/7)-1) -> 0 | S27: =T27 -> 0 | T27: =IF('2019'!T27=0,0,(AME_2030!T27/'2019'!T27)^(1/7)-1) -> 0 | U27: =IF('2019'!U27=0,0,(AME_2030!U27/'2019'!U27)^(1/7)-1) -> 7.6186279e-06 | V27: =IF('2019'!V27=0,0,(AME_2030!V27/'2019'!V27)^(1/7)-1) -> 0 | W27: =IF('2019'!W27=0,0,(AME_2030!W27/'2019'!W27)^(1/7)-1) -> 0 | X27: =IF('2019'!X27=0,0,(AME_2030!X27/'2019'!X27)^(1/7)-1) -> 0 | Y27: =IF('2019'!Y27=0,0,(AME_2030!Y27/'2019'!Y27)^(1/7)-1) -> 0.0024005377 | Z27: =IF('2019'!Z27=0,0,(AME_2030!Z27/'2019'!Z27)^(1/7)-1) -> 0.00028114157 | AA27: =IF('2019'!AA27=0,0,(AME_2030!AA27/'2019'!AA27)^(1/7)-1) -> 0.0013438004 | ... AU27: =IF('2019'!AU27=0,0,(AME_2030!AU27/'2019'!AU27)^(1/7)-1) -> 0
B28: 24 | C28: 24 | D28: Electricity by nuclear | E28: =IF('2019'!E28=0,0,(AME_2030!E28/'2019'!E28)^(1/7)-1) -> -0.00010709151 | F28: =IF('2019'!F28=0,0,(AME_2030!F28/'2019'!F28)^(1/7)-1) -> -1.9086806e-05 | G28: =IF('2019'!G28=0,0,(AME_2030!G28/'2019'!G28)^(1/7)-1) -> -2.3353151e-09 | H28: =IF('2019'!H28=0,0,(AME_2030!H28/'2019'!H28)^(1/7)-1) -> 0.024072717 | I28: =IF('2019'!I28=0,0,(AME_2030!I28/'2019'!I28)^(1/7)-1) -> 9.0622935e-05 | J28: =IF('2019'!J28=0,0,(AME_2030!J28/'2019'!J28)^(1/7)-1) -> -0.011161848 | K28: =IF('2019 (Z)'!AW28=0,0,('AME_2030 (Z)'!AW28/'2019 (Z)'!AW28)^(1/7)-1) -> 0.0022982979 | L28: =K28 -> 0.0022982979 | M28: =IF('2019'!M28=0,0,(AME_2030!M28/'2019'!M28)^(1/7)-1) -> -0.0097233183 | N28: =IF('2019'!N28=0,0,(AME_2030!N28/'2019'!N28)^(1/7)-1) -> 0.035415322 | O28: =IF('2019'!O28=0,0,(AME_2030!O28/'2019'!O28)^(1/7)-1) -> -0.039170238 | P28: =IF('2019'!P28=0,0,(AME_2030!P28/'2019'!P28)^(1/7)-1) -> -4.6226709e-05 | Q28: =IF('2019'!Q28=0,0,(AME_2030!Q28/'2019'!Q28)^(1/7)-1) -> 1.6442185e-07 | R28: =IF('2019'!R28=0,0,(AME_2030!R28/'2019'!R28)^(1/7)-1) -> -2.0238261e-08 | S28: =T28 -> 6.4570597e-07 | T28: =IF('2019'!T28=0,0,(AME_2030!T28/'2019'!T28)^(1/7)-1) -> 6.4570597e-07 | U28: =IF('2019'!U28=0,0,(AME_2030!U28/'2019'!U28)^(1/7)-1) -> 0 | V28: =IF('2019'!V28=0,0,(AME_2030!V28/'2019'!V28)^(1/7)-1) -> -2.6346634e-08 | W28: =IF('2019'!W28=0,0,(AME_2030!W28/'2019'!W28)^(1/7)-1) -> -5.1907287e-05 | X28: =IF('2019'!X28=0,0,(AME_2030!X28/'2019'!X28)^(1/7)-1) -> 5.6582395e-06 | Y28: =IF('2019'!Y28=0,0,(AME_2030!Y28/'2019'!Y28)^(1/7)-1) -> 0.0024005377 | Z28: =IF('2019'!Z28=0,0,(AME_2030!Z28/'2019'!Z28)^(1/7)-1) -> -0.0011572408 | AA28: =IF('2019'!AA28=0,0,(AME_2030!AA28/'2019'!AA28)^(1/7)-1) -> 0.0013440072 | ... AU28: =IF('2019'!AU28=0,0,(AME_2030!AU28/'2019'!AU28)^(1/7)-1) -> 0
B29: 25 | C29: 25 | D29: Electricity by petroleum | E29: =IF('2019'!E29=0,0,(AME_2030!E29/'2019'!E29)^(1/7)-1) -> 0.00028618511 | F29: =IF('2019'!F29=0,0,(AME_2030!F29/'2019'!F29)^(1/7)-1) -> 7.7730447e-05 | G29: =IF('2019'!G29=0,0,(AME_2030!G29/'2019'!G29)^(1/7)-1) -> -2.3353149e-09 | H29: =IF('2019'!H29=0,0,(AME_2030!H29/'2019'!H29)^(1/7)-1) -> 0.023963905 | I29: =IF('2019'!I29=0,0,(AME_2030!I29/'2019'!I29)^(1/7)-1) -> 4.4246249e-05 | J29: =IF('2019'!J29=0,0,(AME_2030!J29/'2019'!J29)^(1/7)-1) -> -0.016824633 | K29: =IF('2019 (Z)'!AW29=0,0,('AME_2030 (Z)'!AW29/'2019 (Z)'!AW29)^(1/7)-1) -> 0.0023015954 | L29: =K29 -> 0.0023015954 | M29: =IF('2019'!M29=0,0,(AME_2030!M29/'2019'!M29)^(1/7)-1) -> -0.0077400527 | N29: =IF('2019'!N29=0,0,(AME_2030!N29/'2019'!N29)^(1/7)-1) -> 0.035993886 | O29: =IF('2019'!O29=0,0,(AME_2030!O29/'2019'!O29)^(1/7)-1) -> -0.035001999 | P29: =IF('2019'!P29=0,0,(AME_2030!P29/'2019'!P29)^(1/7)-1) -> 1.0724485e-05 | Q29: =IF('2019'!Q29=0,0,(AME_2030!Q29/'2019'!Q29)^(1/7)-1) -> 1.6442185e-07 | R29: =IF('2019'!R29=0,0,(AME_2030!R29/'2019'!R29)^(1/7)-1) -> -2.0238261e-08 | S29: =T29 -> 6.1823798e-07 | T29: =IF('2019'!T29=0,0,(AME_2030!T29/'2019'!T29)^(1/7)-1) -> 6.1823798e-07 | U29: =IF('2019'!U29=0,0,(AME_2030!U29/'2019'!U29)^(1/7)-1) -> 0 | V29: =IF('2019'!V29=0,0,(AME_2030!V29/'2019'!V29)^(1/7)-1) -> 0 | W29: =IF('2019'!W29=0,0,(AME_2030!W29/'2019'!W29)^(1/7)-1) -> 0.0001050394 | X29: =IF('2019'!X29=0,0,(AME_2030!X29/'2019'!X29)^(1/7)-1) -> 4.9522659e-06 | Y29: =IF('2019'!Y29=0,0,(AME_2030!Y29/'2019'!Y29)^(1/7)-1) -> 0 | Z29: =IF('2019'!Z29=0,0,(AME_2030!Z29/'2019'!Z29)^(1/7)-1) -> -0.0011567087 | AA29: =IF('2019'!AA29=0,0,(AME_2030!AA29/'2019'!AA29)^(1/7)-1) -> 0.0013440083 | ... AU29: =IF('2019'!AU29=0,0,(AME_2030!AU29/'2019'!AU29)^(1/7)-1) -> 0
B30: 26 | C30: 26 | D30: Electricity by gas | E30: =IF('2019'!E30=0,0,(AME_2030!E30/'2019'!E30)^(1/7)-1) -> -0.00034769384 | F30: =IF('2019'!F30=0,0,(AME_2030!F30/'2019'!F30)^(1/7)-1) -> -4.9613883e-05 | G30: =IF('2019'!G30=0,0,(AME_2030!G30/'2019'!G30)^(1/7)-1) -> -2.3353149e-09 | H30: =IF('2019'!H30=0,0,(AME_2030!H30/'2019'!H30)^(1/7)-1) -> 0.024043467 | I30: =IF('2019'!I30=0,0,(AME_2030!I30/'2019'!I30)^(1/7)-1) -> 4.3750642e-05 | J30: =IF('2019'!J30=0,0,(AME_2030!J30/'2019'!J30)^(1/7)-1) -> -0.016675543 | K30: =IF('2019 (Z)'!AW30=0,0,('AME_2030 (Z)'!AW30/'2019 (Z)'!AW30)^(1/7)-1) -> 0.0022969912 | L30: =K30 -> 0.0022969912 | M30: =IF('2019'!M30=0,0,(AME_2030!M30/'2019'!M30)^(1/7)-1) -> -0.017517297 | N30: =IF('2019'!N30=0,0,(AME_2030!N30/'2019'!N30)^(1/7)-1) -> 0.036012664 | O30: =IF('2019'!O30=0,0,(AME_2030!O30/'2019'!O30)^(1/7)-1) -> -0.034848707 | P30: =IF('2019'!P30=0,0,(AME_2030!P30/'2019'!P30)^(1/7)-1) -> 1.0539391e-05 | Q30: =IF('2019'!Q30=0,0,(AME_2030!Q30/'2019'!Q30)^(1/7)-1) -> 1.6442185e-07 | R30: =IF('2019'!R30=0,0,(AME_2030!R30/'2019'!R30)^(1/7)-1) -> -2.0238261e-08 | S30: =T30 -> 6.1887672e-07 | T30: =IF('2019'!T30=0,0,(AME_2030!T30/'2019'!T30)^(1/7)-1) -> 6.1887672e-07 | U30: =IF('2019'!U30=0,0,(AME_2030!U30/'2019'!U30)^(1/7)-1) -> 0 | V30: =IF('2019'!V30=0,0,(AME_2030!V30/'2019'!V30)^(1/7)-1) -> 0 | W30: =IF('2019'!W30=0,0,(AME_2030!W30/'2019'!W30)^(1/7)-1) -> -0.00014457011 | X30: =IF('2019'!X30=0,0,(AME_2030!X30/'2019'!X30)^(1/7)-1) -> 7.5031978e-06 | Y30: =IF('2019'!Y30=0,0,(AME_2030!Y30/'2019'!Y30)^(1/7)-1) -> 0 | Z30: =IF('2019'!Z30=0,0,(AME_2030!Z30/'2019'!Z30)^(1/7)-1) -> -0.0011548758 | AA30: =IF('2019'!AA30=0,0,(AME_2030!AA30/'2019'!AA30)^(1/7)-1) -> 0.0013440104 | ... AU30: =IF('2019'!AU30=0,0,(AME_2030!AU30/'2019'!AU30)^(1/7)-1) -> 0
B31: 27 | C31: 27 | D31: Coal-fired electricity | E31: =IF('2019'!E31=0,0,(AME_2030!E31/'2019'!E31)^(1/7)-1) -> -0.00035105714 | F31: =IF('2019'!F31=0,0,(AME_2030!F31/'2019'!F31)^(1/7)-1) -> -4.9633278e-05 | G31: =IF('2019'!G31=0,0,(AME_2030!G31/'2019'!G31)^(1/7)-1) -> -2.3353149e-09 | H31: =IF('2019'!H31=0,0,(AME_2030!H31/'2019'!H31)^(1/7)-1) -> 0.023945085 | I31: =IF('2019'!I31=0,0,(AME_2030!I31/'2019'!I31)^(1/7)-1) -> 4.4363113e-05 | J31: =IF('2019'!J31=0,0,(AME_2030!J31/'2019'!J31)^(1/7)-1) -> -0.016785347 | K31: =IF('2019 (Z)'!AW31=0,0,('AME_2030 (Z)'!AW31/'2019 (Z)'!AW31)^(1/7)-1) -> 0.0023015778 | L31: =K31 -> 0.0023015778 | M31: =IF('2019'!M31=0,0,(AME_2030!M31/'2019'!M31)^(1/7)-1) -> -0.0077535753 | N31: =IF('2019'!N31=0,0,(AME_2030!N31/'2019'!N31)^(1/7)-1) -> 0.035989456 | O31: =IF('2019'!O31=0,0,(AME_2030!O31/'2019'!O31)^(1/7)-1) -> -0.034875294 | P31: =IF('2019'!P31=0,0,(AME_2030!P31/'2019'!P31)^(1/7)-1) -> 1.1197482e-05 | Q31: =IF('2019'!Q31=0,0,(AME_2030!Q31/'2019'!Q31)^(1/7)-1) -> 1.6442185e-07 | R31: =IF('2019'!R31=0,0,(AME_2030!R31/'2019'!R31)^(1/7)-1) -> -2.0238261e-08 | S31: =T31 -> 6.174893e-07 | T31: =IF('2019'!T31=0,0,(AME_2030!T31/'2019'!T31)^(1/7)-1) -> 6.174893e-07 | U31: =IF('2019'!U31=0,0,(AME_2030!U31/'2019'!U31)^(1/7)-1) -> 0 | V31: =IF('2019'!V31=0,0,(AME_2030!V31/'2019'!V31)^(1/7)-1) -> 0 | W31: =IF('2019'!W31=0,0,(AME_2030!W31/'2019'!W31)^(1/7)-1) -> -0.00015945868 | X31: =IF('2019'!X31=0,0,(AME_2030!X31/'2019'!X31)^(1/7)-1) -> 4.9720396e-06 | Y31: =IF('2019'!Y31=0,0,(AME_2030!Y31/'2019'!Y31)^(1/7)-1) -> 0 | Z31: =IF('2019'!Z31=0,0,(AME_2030!Z31/'2019'!Z31)^(1/7)-1) -> -0.0011567048 | AA31: =IF('2019'!AA31=0,0,(AME_2030!AA31/'2019'!AA31)^(1/7)-1) -> 0.0013440083 | ... AU31: =IF('2019'!AU31=0,0,(AME_2030!AU31/'2019'!AU31)^(1/7)-1) -> 0
