Workbook

Sheet T energie vecteurs
A1: Energie par vecteur énergétique | D1: c
A3: Energie primaire (Mtep)
A4: =Résultats!B1 -> SNBC3
E5: =Résultats!E1 -> 4 | F5: =E5+9 -> 13 | G5: =F5+3 -> 16 | H5: =G5+1 -> 17 | I5: =H5+1 -> 18 | J5: =I5+1 -> 19 | K5: =J5+1 -> 20 | L5: =K5+1 -> 21 | M5: =L5+1 -> 22 | N5: =M5+1 -> 23 | O5: =N5+1 -> 24 | ... S5: =R5+1 -> 28 | T5: =S5+5 -> 33 | U5: =T5+5 -> 38 | V5: =U5+5 -> 43 | W5: =V5+5 -> 48
E6: 2006 | F6: 2015 | G6: 2018 | H6: 2019 | I6: 2020 | J6: 2021 | K6: 2022 | L6: 2023 | M6: 2024 | N6: 2025 | O6: 2026 | P6: 2027 | Q6: 2028 | R6: 2029 | S6: 2030 | T6: 2035 | U6: 2040 | V6: 2045 | W6: 2050 | Z6: Cf. onglet "G énergie"
B7: Refined petroleum products | C7: Total | E7: =SUM(E8:E9) -> 85.512306 | F7: =SUM(F8:F9) -> 73.793814 | G7: =SUM(G8:G9) -> 67.845464 | H7: =SUM(H8:H9) -> 66.427641 | I7: =SUM(I8:I9) -> 64.656103 | J7: =SUM(J8:J9) -> 64.200373 | K7: =SUM(K8:K9) -> 63.674742 | L7: =SUM(L8:L9) -> 62.836219 | ... W7: =SUM(W8:W9) -> 18.912755 | AA7: 2020 | AB7: 2030 | AC7: 2050
C8: Oil | D8: Q_Mtep_ep_2201_2 | E8: =VLOOKUP($D8,Résultats!$B$2:$AX$476,E$5,FALSE) -> 84.844841 | F8: =VLOOKUP($D8,Résultats!$B$2:$AX$476,F$5,FALSE) -> 70.625169 | G8: =VLOOKUP($D8,Résultats!$B$2:$AX$476,G$5,FALSE) -> 64.761067 | H8: =VLOOKUP($D8,Résultats!$B$2:$AX$476,H$5,FALSE) -> 63.344633 | I8: =VLOOKUP($D8,Résultats!$B$2:$AX$476,I$5,FALSE) -> 61.589811 | J8: =VLOOKUP($D8,Résultats!$B$2:$AX$476,J$5,FALSE) -> 61.006712 | K8: =VLOOKUP($D8,Résultats!$B$2:$AX$476,K$5,FALSE) -> 60.365601 | L8: =VLOOKUP($D8,Résultats!$B$2:$AX$476,L$5,FALSE) -> 59.436634 | ... W8: =VLOOKUP($D8,Résultats!$B$2:$AX$476,W$5,FALSE) -> 6.6802508 | X8: =W8-'[1]Cibles THREEME'!$H4 -> -3.7203565 | Z8: Energie primaire | AA8: =I27 -> 232.56144 | AB8: =S27 -> 214.06918 | AC8: =W27 -> 129.97749
C9: Biofuels | D9: Q_Mtep_ep_2202_2 | E9: =VLOOKUP($D9,Résultats!$B$2:$AX$476,E$5,FALSE) -> 0.66746538 | F9: =VLOOKUP($D9,Résultats!$B$2:$AX$476,F$5,FALSE) -> 3.1686457 | G9: =VLOOKUP($D9,Résultats!$B$2:$AX$476,G$5,FALSE) -> 3.0843969 | H9: =VLOOKUP($D9,Résultats!$B$2:$AX$476,H$5,FALSE) -> 3.0830077 | I9: =VLOOKUP($D9,Résultats!$B$2:$AX$476,I$5,FALSE) -> 3.0662927 | J9: =VLOOKUP($D9,Résultats!$B$2:$AX$476,J$5,FALSE) -> 3.193661 | K9: =VLOOKUP($D9,Résultats!$B$2:$AX$476,K$5,FALSE) -> 3.3091416 | L9: =VLOOKUP($D9,Résultats!$B$2:$AX$476,L$5,FALSE) -> 3.3995855 | ... W9: =VLOOKUP($D9,Résultats!$B$2:$AX$476,W$5,FALSE) -> 12.232504 | X9: =W9-'[1]Cibles THREEME'!$H5 -> 8.735663
B10: Electric power generation, transmission and distribution | C10: Total | E10: =SUM(E11:E18) -> 135.21135 | F10: =SUM(F11:F18) -> 149.50095 | G10: =SUM(G11:G18) -> 139.02163 | H10: =SUM(H11:H18) -> 134.54298 | I10: =SUM(I11:I18) -> 130.06616 | J10: =SUM(J11:J18) -> 128.29469 | K10: =SUM(K11:K18) -> 126.98505 | L10: =SUM(L11:L18) -> 124.58548 | ... W10: =SUM(W11:W18) -> 86.793706
C11: Nuclear | D11: Q_Mtep_ep_2301_2 | E11: =VLOOKUP($D11,Résultats!$B$2:$AX$476,E$5,FALSE) -> 118.47247 | F11: =VLOOKUP($D11,Résultats!$B$2:$AX$476,F$5,FALSE) -> 129.76891 | G11: =VLOOKUP($D11,Résultats!$B$2:$AX$476,G$5,FALSE) -> 118.48489 | H11: =VLOOKUP($D11,Résultats!$B$2:$AX$476,H$5,FALSE) -> 113.84746 | I11: =VLOOKUP($D11,Résultats!$B$2:$AX$476,I$5,FALSE) -> 109.20083 | J11: =VLOOKUP($D11,Résultats!$B$2:$AX$476,J$5,FALSE) -> 107.13507 | K11: =VLOOKUP($D11,Résultats!$B$2:$AX$476,K$5,FALSE) -> 105.4577 | L11: =VLOOKUP($D11,Résultats!$B$2:$AX$476,L$5,FALSE) -> 102.88088 | ... W11: =VLOOKUP($D11,Résultats!$B$2:$AX$476,W$5,FALSE) -> 52.051401 | X11: =W11-'[1]Cibles THREEME'!$H10 -> 49.393697
C12: Fuel | D12: Q_Mtep_ep_2302_2 | E12: =VLOOKUP($D12,Résultats!$B$2:$AX$476,E$5,FALSE) -> 1.3210359 | F12: =VLOOKUP($D12,Résultats!$B$2:$AX$476,F$5,FALSE) -> 0.78813533 | G12: =VLOOKUP($D12,Résultats!$B$2:$AX$476,G$5,FALSE) -> 0.52850563 | H12: =VLOOKUP($D12,Résultats!$B$2:$AX$476,H$5,FALSE) -> 0.43727701 | I12: =VLOOKUP($D12,Résultats!$B$2:$AX$476,I$5,FALSE) -> 0.34627987 | J12: =VLOOKUP($D12,Résultats!$B$2:$AX$476,J$5,FALSE) -> 0.45074562 | K12: =VLOOKUP($D12,Résultats!$B$2:$AX$476,K$5,FALSE) -> 0.55608677 | L12: =VLOOKUP($D12,Résultats!$B$2:$AX$476,L$5,FALSE) -> 0.65534673 | ... W12: =VLOOKUP($D12,Résultats!$B$2:$AX$476,W$5,FALSE) -> 0.0074177753 | X12: =W12-'[1]Cibles THREEME'!$H11 -> 0.0074177753
C13: Combined gas | D13: Q_Mtep_ep_2303_2 | E13: =VLOOKUP($D13,Résultats!$B$2:$AX$476,E$5,FALSE) -> 3.5861751 | F13: =VLOOKUP($D13,Résultats!$B$2:$AX$476,F$5,FALSE) -> 4.2850458 | G13: =VLOOKUP($D13,Résultats!$B$2:$AX$476,G$5,FALSE) -> 5.3965378 | H13: =VLOOKUP($D13,Résultats!$B$2:$AX$476,H$5,FALSE) -> 5.7390882 | I13: =VLOOKUP($D13,Résultats!$B$2:$AX$476,I$5,FALSE) -> 6.0820907 | J13: =VLOOKUP($D13,Résultats!$B$2:$AX$476,J$5,FALSE) -> 5.7800069 | K13: =VLOOKUP($D13,Résultats!$B$2:$AX$476,K$5,FALSE) -> 5.4982092 | L13: =VLOOKUP($D13,Résultats!$B$2:$AX$476,L$5,FALSE) -> 5.1698632 | ... W13: =VLOOKUP($D13,Résultats!$B$2:$AX$476,W$5,FALSE) -> 0.52863515 | X13: =W13-'[1]Cibles THREEME'!$H12 -> -1.7642855
C14: Coal | D14: Q_Mtep_ep_2304_2 | E14: =VLOOKUP($D14,Résultats!$B$2:$AX$476,E$5,FALSE) -> 5.2639752 | F14: =VLOOKUP($D14,Résultats!$B$2:$AX$476,F$5,FALSE) -> 3.416841 | G14: =VLOOKUP($D14,Résultats!$B$2:$AX$476,G$5,FALSE) -> 1.9590989 | H14: =VLOOKUP($D14,Résultats!$B$2:$AX$476,H$5,FALSE) -> 1.4555758 | I14: =VLOOKUP($D14,Résultats!$B$2:$AX$476,I$5,FALSE) -> 0.95436361 | J14: =VLOOKUP($D14,Résultats!$B$2:$AX$476,J$5,FALSE) -> 0.90709862 | K14: =VLOOKUP($D14,Résultats!$B$2:$AX$476,K$5,FALSE) -> 0.86294362 | L14: =VLOOKUP($D14,Résultats!$B$2:$AX$476,L$5,FALSE) -> 0.81140993 | ... W14: =VLOOKUP($D14,Résultats!$B$2:$AX$476,W$5,FALSE) -> 0.0074177753 | X14: =W14-'[1]Cibles THREEME'!$H13 -> 0.0074177753
C15: Wind | D15: Q_Mtep_ep_2305_2 | E15: =VLOOKUP($D15,Résultats!$B$2:$AX$476,E$5,FALSE) -> 0.36837996 | F15: =VLOOKUP($D15,Résultats!$B$2:$AX$476,F$5,FALSE) -> 2.6163824 | G15: =VLOOKUP($D15,Résultats!$B$2:$AX$476,G$5,FALSE) -> 3.3935444 | H15: =VLOOKUP($D15,Résultats!$B$2:$AX$476,H$5,FALSE) -> 3.6388344 | I15: =VLOOKUP($D15,Résultats!$B$2:$AX$476,I$5,FALSE) -> 3.8860842 | J15: =VLOOKUP($D15,Résultats!$B$2:$AX$476,J$5,FALSE) -> 4.0511886 | K15: =VLOOKUP($D15,Résultats!$B$2:$AX$476,K$5,FALSE) -> 4.2301318 | L15: =VLOOKUP($D15,Résultats!$B$2:$AX$476,L$5,FALSE) -> 4.3708877 | ... W15: =VLOOKUP($D15,Résultats!$B$2:$AX$476,W$5,FALSE) -> 17.963845 | X15: =W15-'[1]Cibles THREEME'!$H14 -> 0.19084445
C16: Solar | D16: Q_Mtep_ep_2306_2 | E16: =VLOOKUP($D16,Résultats!$B$2:$AX$476,E$5,FALSE) -> 0.082885491 | F16: =VLOOKUP($D16,Résultats!$B$2:$AX$476,F$5,FALSE) -> 1.1530532 | G16: =VLOOKUP($D16,Résultats!$B$2:$AX$476,G$5,FALSE) -> 1.4955524 | H16: =VLOOKUP($D16,Résultats!$B$2:$AX$476,H$5,FALSE) -> 1.603653 | I16: =VLOOKUP($D16,Résultats!$B$2:$AX$476,I$5,FALSE) -> 1.7126173 | J16: =VLOOKUP($D16,Résultats!$B$2:$AX$476,J$5,FALSE) -> 1.7608415 | K16: =VLOOKUP($D16,Résultats!$B$2:$AX$476,K$5,FALSE) -> 1.8151681 | L16: =VLOOKUP($D16,Résultats!$B$2:$AX$476,L$5,FALSE) -> 1.8533059 | ... W16: =VLOOKUP($D16,Résultats!$B$2:$AX$476,W$5,FALSE) -> 9.3413419 | X16: =W16-'[1]Cibles THREEME'!$H17 -> -1.1487699
C17: Hydraulic | D17: Q_Mtep_ep_2307_2 | E17: =VLOOKUP($D17,Résultats!$B$2:$AX$476,E$5,FALSE) -> 4.6467107 | F17: =VLOOKUP($D17,Résultats!$B$2:$AX$476,F$5,FALSE) -> 3.4133941 | G17: =VLOOKUP($D17,Résultats!$B$2:$AX$476,G$5,FALSE) -> 4.4449886 | H17: =VLOOKUP($D17,Résultats!$B$2:$AX$476,H$5,FALSE) -> 4.7725683 | I17: =VLOOKUP($D17,Résultats!$B$2:$AX$476,I$5,FALSE) -> 5.1035522 | J17: =VLOOKUP($D17,Résultats!$B$2:$AX$476,J$5,FALSE) -> 5.298675 | K17: =VLOOKUP($D17,Résultats!$B$2:$AX$476,K$5,FALSE) -> 5.5122374 | L17: =VLOOKUP($D17,Résultats!$B$2:$AX$476,L$5,FALSE) -> 5.6764703 | ... W17: =VLOOKUP($D17,Résultats!$B$2:$AX$476,W$5,FALSE) -> 4.5529204 | X17: =W17-'[1]Cibles THREEME'!$H18 -> -0.90709675
C18: Cogeneration (CHP) | D18: Q_Mtep_ep_2308_2 | E18: =VLOOKUP($D18,Résultats!$B$2:$AX$476,E$5,FALSE) -> 1.4697215 | F18: =VLOOKUP($D18,Résultats!$B$2:$AX$476,F$5,FALSE) -> 4.0591902 | G18: =VLOOKUP($D18,Résultats!$B$2:$AX$476,G$5,FALSE) -> 3.3185127 | H18: =VLOOKUP($D18,Résultats!$B$2:$AX$476,H$5,FALSE) -> 3.0485188 | I18: =VLOOKUP($D18,Résultats!$B$2:$AX$476,I$5,FALSE) -> 2.7803421 | J18: =VLOOKUP($D18,Résultats!$B$2:$AX$476,J$5,FALSE) -> 2.9110568 | K18: =VLOOKUP($D18,Résultats!$B$2:$AX$476,K$5,FALSE) -> 3.0525725 | L18: =VLOOKUP($D18,Résultats!$B$2:$AX$476,L$5,FALSE) -> 3.1673147 | ... W18: =VLOOKUP($D18,Résultats!$B$2:$AX$476,W$5,FALSE) -> 2.3407274 | X18: =W18-'[1]Cibles THREEME'!$H19 -> 1.1786004
B19: Gas and heat | C19: Total | E19: =SUM(E20:E25) -> 38.516187 | F19: =SUM(F20:F25) -> 39.559006 | G19: =SUM(G20:G25) -> 37.816821 | H19: =SUM(H20:H25) -> 36.396972 | I19: =SUM(I20:I25) -> 35.786557 | J19: =SUM(J20:J25) -> 35.401283 | K19: =SUM(K20:K25) -> 35.102814 | L19: =SUM(L20:L25) -> 35.17339 | ... W19: =SUM(W20:W25) -> 24.164373
C20: Natural gas | D20: Q_Mtep_ep_2401_2 | E20: =VLOOKUP($D20,Résultats!$B$2:$AX$476,E$5,FALSE) -> 35.359287 | F20: =VLOOKUP($D20,Résultats!$B$2:$AX$476,F$5,FALSE) -> 27.834732 | G20: =VLOOKUP($D20,Résultats!$B$2:$AX$476,G$5,FALSE) -> 26.166317 | H20: =VLOOKUP($D20,Résultats!$B$2:$AX$476,H$5,FALSE) -> 25.069344 | I20: =VLOOKUP($D20,Résultats!$B$2:$AX$476,I$5,FALSE) -> 24.549517 | J20: =VLOOKUP($D20,Résultats!$B$2:$AX$476,J$5,FALSE) -> 23.31725 | K20: =VLOOKUP($D20,Résultats!$B$2:$AX$476,K$5,FALSE) -> 22.136537 | L20: =VLOOKUP($D20,Résultats!$B$2:$AX$476,L$5,FALSE) -> 20.922506 | ... W20: =VLOOKUP($D20,Résultats!$B$2:$AX$476,W$5,FALSE) -> 3.7726666 | X20: =W20-'[1]Cibles THREEME'!$H28 -> -1.6661162
C21: Wood | D21: Q_Mtep_ep_2402_2 | E21: =VLOOKUP($D21,Résultats!$B$2:$AX$476,E$5,FALSE) -> 1.6086113 | F21: =VLOOKUP($D21,Résultats!$B$2:$AX$476,F$5,FALSE) -> 7.0411192 | G21: =VLOOKUP($D21,Résultats!$B$2:$AX$476,G$5,FALSE) -> 6.9876733 | H21: =VLOOKUP($D21,Résultats!$B$2:$AX$476,H$5,FALSE) -> 6.8149874 | I21: =VLOOKUP($D21,Résultats!$B$2:$AX$476,I$5,FALSE) -> 6.7927124 | J21: =VLOOKUP($D21,Résultats!$B$2:$AX$476,J$5,FALSE) -> 6.9065706 | K21: =VLOOKUP($D21,Résultats!$B$2:$AX$476,K$5,FALSE) -> 7.0384943 | L21: =VLOOKUP($D21,Résultats!$B$2:$AX$476,L$5,FALSE) -> 7.4566851 | ... W21: =VLOOKUP($D21,Résultats!$B$2:$AX$476,W$5,FALSE) -> 6.015123 | X21: =W21-'[1]Cibles THREEME'!$H29 -> -5.8960628
C22: Biogas | D22: Q_Mtep_ep_2403_2 | E22: =VLOOKUP($D22,Résultats!$B$2:$AX$476,E$5,FALSE) -> 0.20107641 | F22: =VLOOKUP($D22,Résultats!$B$2:$AX$476,F$5,FALSE) -> 0.11900138 | G22: =VLOOKUP($D22,Résultats!$B$2:$AX$476,G$5,FALSE) -> 0.285656 | H22: =VLOOKUP($D22,Résultats!$B$2:$AX$476,H$5,FALSE) -> 0.330476 | I22: =VLOOKUP($D22,Résultats!$B$2:$AX$476,I$5,FALSE) -> 0.37988942 | J22: =VLOOKUP($D22,Résultats!$B$2:$AX$476,J$5,FALSE) -> 0.58598983 | K22: =VLOOKUP($D22,Résultats!$B$2:$AX$476,K$5,FALSE) -> 0.79495402 | L22: =VLOOKUP($D22,Résultats!$B$2:$AX$476,L$5,FALSE) -> 1.028522 | ... W22: =VLOOKUP($D22,Résultats!$B$2:$AX$476,W$5,FALSE) -> 6.9299889 | X22: =W22-'[1]Cibles THREEME'!$H30 -> -5.3956204
C23: Waste incineration | D23: Q_Mtep_ep_2404_2 | E23: =VLOOKUP($D23,Résultats!$B$2:$AX$476,E$5,FALSE) -> 0.74398272 | F23: =VLOOKUP($D23,Résultats!$B$2:$AX$476,F$5,FALSE) -> 0.59907668 | G23: =VLOOKUP($D23,Résultats!$B$2:$AX$476,G$5,FALSE) -> 1.2173629 | H23: =VLOOKUP($D23,Résultats!$B$2:$AX$476,H$5,FALSE) -> 1.3404487 | I23: =VLOOKUP($D23,Résultats!$B$2:$AX$476,I$5,FALSE) -> 1.4656076 | J23: =VLOOKUP($D23,Résultats!$B$2:$AX$476,J$5,FALSE) -> 1.4994943 | K23: =VLOOKUP($D23,Résultats!$B$2:$AX$476,K$5,FALSE) -> 1.5366182 | L23: =VLOOKUP($D23,Résultats!$B$2:$AX$476,L$5,FALSE) -> 1.5968495 | ... W23: =VLOOKUP($D23,Résultats!$B$2:$AX$476,W$5,FALSE) -> 0.84754389 | X23: =W23-'[1]Cibles THREEME'!$H31 -> 0.056023344
C24: Geothermal | D24: Q_Mtep_ep_2405_2 | E24: =VLOOKUP($D24,Résultats!$B$2:$AX$476,E$5,FALSE) -> 0.20107641 | F24: =VLOOKUP($D24,Résultats!$B$2:$AX$476,F$5,FALSE) -> 0.20230993 | G24: =VLOOKUP($D24,Résultats!$B$2:$AX$476,G$5,FALSE) -> 0.2874068 | H24: =VLOOKUP($D24,Résultats!$B$2:$AX$476,H$5,FALSE) -> 0.30712736 | I24: =VLOOKUP($D24,Résultats!$B$2:$AX$476,I$5,FALSE) -> 0.33223022 | J24: =VLOOKUP($D24,Résultats!$B$2:$AX$476,J$5,FALSE) -> 0.39156072 | K24: =VLOOKUP($D24,Résultats!$B$2:$AX$476,K$5,FALSE) -> 0.45227369 | L24: =VLOOKUP($D24,Résultats!$B$2:$AX$476,L$5,FALSE) -> 0.54026797 | ... W24: =VLOOKUP($D24,Résultats!$B$2:$AX$476,W$5,FALSE) -> 0.8930943 | X24: =W24-'[1]Cibles THREEME'!$H32 -> 0.63514073
C25: Cogeneration (CHP) | D25: Q_Mtep_ep_2406_2 | E25: =VLOOKUP($D25,Résultats!$B$2:$AX$476,E$5,FALSE) -> 0.40215282 | F25: =VLOOKUP($D25,Résultats!$B$2:$AX$476,F$5,FALSE) -> 3.7627669 | G25: =VLOOKUP($D25,Résultats!$B$2:$AX$476,G$5,FALSE) -> 2.8724051 | H25: =VLOOKUP($D25,Résultats!$B$2:$AX$476,H$5,FALSE) -> 2.5345883 | I25: =VLOOKUP($D25,Résultats!$B$2:$AX$476,I$5,FALSE) -> 2.2666003 | J25: =VLOOKUP($D25,Résultats!$B$2:$AX$476,J$5,FALSE) -> 2.7004176 | K25: =VLOOKUP($D25,Résultats!$B$2:$AX$476,K$5,FALSE) -> 3.1439362 | L25: =VLOOKUP($D25,Résultats!$B$2:$AX$476,L$5,FALSE) -> 3.6285589 | ... W25: =VLOOKUP($D25,Résultats!$B$2:$AX$476,W$5,FALSE) -> 5.7059559 | X25: =W25-'[1]Cibles THREEME'!$H33 -> -1.7752075
B26: Coal | D26: Q_Mtep_ep_21_2 | E26: =VLOOKUP($D26,Résultats!$B$2:$AX$476,E$5,FALSE) -> 5.7508898 | F26: =VLOOKUP($D26,Résultats!$B$2:$AX$476,F$5,FALSE) -> 4.190327 | G26: =VLOOKUP($D26,Résultats!$B$2:$AX$476,G$5,FALSE) -> 2.4425633 | H26: =VLOOKUP($D26,Résultats!$B$2:$AX$476,H$5,FALSE) -> 2.2292431 | I26: =VLOOKUP($D26,Résultats!$B$2:$AX$476,I$5,FALSE) -> 2.052617 | J26: =VLOOKUP($D26,Résultats!$B$2:$AX$476,J$5,FALSE) -> 2.0139273 | K26: =VLOOKUP($D26,Résultats!$B$2:$AX$476,K$5,FALSE) -> 1.9885554 | L26: =VLOOKUP($D26,Résultats!$B$2:$AX$476,L$5,FALSE) -> 1.6858133 | ... W26: =VLOOKUP($D26,Résultats!$B$2:$AX$476,W$5,FALSE) -> 0.10665656
B27: Total | E27: =E26+E19+E10+E7 -> 264.99074 | F27: =F26+F19+F10+F7 -> 267.0441 | G27: =G26+G19+G10+G7 -> 247.12648 | H27: =H26+H19+H10+H7 -> 239.59684 | I27: =I26+I19+I10+I7 -> 232.56144 | J27: =J26+J19+J10+J7 -> 229.91027 | K27: =K26+K19+K10+K7 -> 227.75116 | L27: =L26+L19+L10+L7 -> 224.2809 | ... W27: =W26+W19+W10+W7 -> 129.97749
A30: Energie finale (Mtep)
A31: =Résultats!B1 -> SNBC3 | Z31: Cf. onglet "G mix elec" | AE31: Cf. onglet "G mix carb" | AJ31: Cf. onglet "G mix gaz"
E32: 2006 | F32: 2015 | G32: 2018 | H32: 2019 | I32: 2020 | J32: 2021 | K32: 2022 | L32: 2023 | M32: 2024 | N32: 2025 | O32: 2026 | P32: 2027 | Q32: 2028 | R32: 2029 | S32: 2030 | T32: 2035 | U32: 2040 | V32: 2045 | W32: 2050 | AA32: 2020 | AB32: 2030 | AC32: 2050 | AF32: 2020 | AG32: 2030 | AH32: 2050 | AK32: 2020 | AL32: 2030 | AM32: 2050
B33: Refined petroleum products | C33: Total | D33: ER_Oil_2 | E33: =SUM(E34:E35) -> 80.671203 | F33: =SUM(F34:F35) -> 71.498434 | G33: =SUM(G34:G35) -> 66.192346 | H33: =SUM(H34:H35) -> 64.959362 | I33: =SUM(I34:I35) -> 63.373763 | J33: =SUM(J34:J35) -> 62.700539 | K33: =SUM(K34:K35) -> 61.965191 | L33: =SUM(L34:L35) -> 60.93266 | ... W33: =SUM(W34:W35) -> 18.386356 | Z33: charbon | AA33: =(I38+I40)/I36 -> 0.0086413758 | AB33: =(S38+S40)/S36 -> 0.00094212087 | AC33: =(W38+W40)/W36 -> 0.00034818942 | AE33: carburants fossiles | AF33: =I34/I33 -> 0.95161574 | AG33: =S34/S33 -> 0.91402602 | AH33: =W34/W33 -> 0.33469666 | AJ33: gaz naturel | AK33: =I46/(I46+I48) -> 0.98439656 | AL33: =S46/(S46+S48) -> 0.84505794 | AM33: =W46/(W46+W48) -> 0.35227008
C34: Oil | D34: ER_oil_2201_2 | E34: =VLOOKUP($D34,Résultats!$B$2:$AX$476,E$5,FALSE) -> 80.003737 | F34: =VLOOKUP($D34,Résultats!$B$2:$AX$476,F$5,FALSE) -> 68.329788 | G34: =VLOOKUP($D34,Résultats!$B$2:$AX$476,G$5,FALSE) -> 63.107949 | H34: =VLOOKUP($D34,Résultats!$B$2:$AX$476,H$5,FALSE) -> 61.876354 | I34: =VLOOKUP($D34,Résultats!$B$2:$AX$476,I$5,FALSE) -> 60.30747 | J34: =VLOOKUP($D34,Résultats!$B$2:$AX$476,J$5,FALSE) -> 59.506878 | K34: =VLOOKUP($D34,Résultats!$B$2:$AX$476,K$5,FALSE) -> 58.656049 | L34: =VLOOKUP($D34,Résultats!$B$2:$AX$476,L$5,FALSE) -> 57.533075 | ... W34: =VLOOKUP($D34,Résultats!$B$2:$AX$476,W$5,FALSE) -> 6.153852 | X34: =W34-'[1]Cibles THREEME'!$AJ4 -> -3.5282506 | Z34: nucléaire | AA34: =I37/I36 -> 0.69408091 | AB34: =S37/S36 -> 0.62114144 | AC34: =W37/W36 -> 0.32025253 | AE34: biocarburants | AF34: =I35/I33 -> 0.048384262 | AG34: =S35/S33 -> 0.085973979 | AH34: =W35/W33 -> 0.66530334 | AJ34: biogaz | AK34: =I48/(I46+I48) -> 0.015603437 | AL34: =S48/(S46+S48) -> 0.15494206 | AM34: =W48/(W46+W48) -> 0.64772992
C35: Biofuels | D35: ER_oil_2202_2 | E35: =VLOOKUP($D35,Résultats!$B$2:$AX$476,E$5,FALSE) -> 0.66746538 | F35: =VLOOKUP($D35,Résultats!$B$2:$AX$476,F$5,FALSE) -> 3.1686457 | G35: =VLOOKUP($D35,Résultats!$B$2:$AX$476,G$5,FALSE) -> 3.0843969 | H35: =VLOOKUP($D35,Résultats!$B$2:$AX$476,H$5,FALSE) -> 3.0830077 | I35: =VLOOKUP($D35,Résultats!$B$2:$AX$476,I$5,FALSE) -> 3.0662927 | J35: =VLOOKUP($D35,Résultats!$B$2:$AX$476,J$5,FALSE) -> 3.193661 | K35: =VLOOKUP($D35,Résultats!$B$2:$AX$476,K$5,FALSE) -> 3.3091416 | L35: =VLOOKUP($D35,Résultats!$B$2:$AX$476,L$5,FALSE) -> 3.3995855 | ... W35: =VLOOKUP($D35,Résultats!$B$2:$AX$476,W$5,FALSE) -> 12.232504 | X35: =W35-'[1]Cibles THREEME'!$AJ5 -> 8.735663 | Z35: hydraulique | AA35: =I43/I36 -> 0.10258601 | AB35: =S43/S36 -> 0.10094479 | AC35: =W43/W36 -> 0.085931447 | AE35: Total | AF35: =SUM(AF33:AF34) -> 1 | AG35: =SUM(AG33:AG34) -> 1 | AH35: =SUM(AH33:AH34) -> 1 | AJ35: Total | AK35: =SUM(AK33:AK34) -> 1 | AL35: =SUM(AL33:AL34) -> 1 | AM35: =SUM(AM33:AM34) -> 1
B36: Electric power generation, transmission and distribution | C36: Total | D36: ER_elec_2 | E36: =SUM(E37:E44) -> 37.199368 | F36: =SUM(F37:F44) -> 39.878134 | G36: =SUM(G37:G44) -> 39.553918 | H36: =SUM(H37:H44) -> 39.148654 | I36: =SUM(I37:I44) -> 38.745095 | J36: =SUM(J37:J44) -> 39.013104 | K36: =SUM(K37:K44) -> 39.433226 | L36: =SUM(L37:L44) -> 39.512261 | ... W36: =SUM(W37:W44) -> 42.607566 | Z36: solaire | AA36: =I42/I36 -> 0.036998234 | AB36: =S42/S36 -> 0.087555324 | AC36: =W42/W36 -> 0.19408802
C37: Nuclear | D37: ER_Elec_2301_2 | E37: =VLOOKUP($D37,Résultats!$B$2:$AX$476,E$5,FALSE) -> 29.720949 | F37: =VLOOKUP($D37,Résultats!$B$2:$AX$476,F$5,FALSE) -> 30.94722 | G37: =VLOOKUP($D37,Résultats!$B$2:$AX$476,G$5,FALSE) -> 28.821975 | H37: =VLOOKUP($D37,Résultats!$B$2:$AX$476,H$5,FALSE) -> 27.86219 | I37: =VLOOKUP($D37,Résultats!$B$2:$AX$476,I$5,FALSE) -> 26.892231 | J37: =VLOOKUP($D37,Résultats!$B$2:$AX$476,J$5,FALSE) -> 26.743234 | K37: =VLOOKUP($D37,Résultats!$B$2:$AX$476,K$5,FALSE) -> 26.690278 | L37: =VLOOKUP($D37,Résultats!$B$2:$AX$476,L$5,FALSE) -> 26.399789 | ... W37: =VLOOKUP($D37,Résultats!$B$2:$AX$476,W$5,FALSE) -> 13.645181 | X37: =W37-'[1]Cibles THREEME'!$AJ8 -> 13.024121 | Z37: éolien | AA37: =I41/I36 -> 0.083952357 | AB37: =S41/S36 -> 0.12657892 | AC37: =W41/W36 -> 0.37324051
C38: Fuel | D38: ER_elec_2302_2 | E38: =VLOOKUP($D38,Résultats!$B$2:$AX$476,E$5,FALSE) -> 0.38143295 | F38: =VLOOKUP($D38,Résultats!$B$2:$AX$476,F$5,FALSE) -> 0.24433932 | G38: =VLOOKUP($D38,Résultats!$B$2:$AX$476,G$5,FALSE) -> 0.16877833 | H38: =VLOOKUP($D38,Résultats!$B$2:$AX$476,H$5,FALSE) -> 0.14095614 | I38: =VLOOKUP($D38,Résultats!$B$2:$AX$476,I$5,FALSE) -> 0.11269292 | J38: =VLOOKUP($D38,Résultats!$B$2:$AX$476,J$5,FALSE) -> 0.14899317 | K38: =VLOOKUP($D38,Résultats!$B$2:$AX$476,K$5,FALSE) -> 0.18674726 | L38: =VLOOKUP($D38,Résultats!$B$2:$AX$476,L$5,FALSE) -> 0.22359305 | ... W38: =VLOOKUP($D38,Résultats!$B$2:$AX$476,W$5,FALSE) -> 0.0074177517 | X38: =W38-'[1]Cibles THREEME'!$AJ9 -> -0.0025822483 | Z38: autres renouvelables | AA38: =(I39+I44)/I36 -> 0.073741107 | AB38: =(S39+S44)/S36 -> 0.062837405 | AC38: =(W39+W44)/W36 -> 0.026139309
C39: Combined gas | D39: ER_Elec_2303_2 | E39: =VLOOKUP($D39,Résultats!$B$2:$AX$476,E$5,FALSE) -> 1.5232799 | F39: =VLOOKUP($D39,Résultats!$B$2:$AX$476,F$5,FALSE) -> 1.6070135 | G39: =VLOOKUP($D39,Résultats!$B$2:$AX$476,G$5,FALSE) -> 2.0796826 | H39: =VLOOKUP($D39,Résultats!$B$2:$AX$476,H$5,FALSE) -> 2.2306383 | I39: =VLOOKUP($D39,Résultats!$B$2:$AX$476,I$5,FALSE) -> 2.3846433 | J39: =VLOOKUP($D39,Résultats!$B$2:$AX$476,J$5,FALSE) -> 2.2924332 | K39: =VLOOKUP($D39,Résultats!$B$2:$AX$476,K$5,FALSE) -> 2.20649 | L39: =VLOOKUP($D39,Résultats!$B$2:$AX$476,L$5,FALSE) -> 2.0992975 | ... W39: =VLOOKUP($D39,Résultats!$B$2:$AX$476,W$5,FALSE) -> 0.23568073 | X39: =W39-'[1]Cibles THREEME'!$AJ10 -> -0.86030597 | Z39: Total | AA39: =SUM(AA33:AA38) -> 1 | AB39: =SUM(AB33:AB38) -> 1 | AC39: =SUM(AC33:AC38) -> 1
C40: Coal | D40: ER_elec_2304_2 | E40: =VLOOKUP($D40,Résultats!$B$2:$AX$476,E$5,FALSE) -> 1.5199084 | F40: =VLOOKUP($D40,Résultats!$B$2:$AX$476,F$5,FALSE) -> 0.75329847 | G40: =VLOOKUP($D40,Résultats!$B$2:$AX$476,G$5,FALSE) -> 0.44640929 | H40: =VLOOKUP($D40,Résultats!$B$2:$AX$476,H$5,FALSE) -> 0.33517036 | I40: =VLOOKUP($D40,Résultats!$B$2:$AX$476,I$5,FALSE) -> 0.22211801 | J40: =VLOOKUP($D40,Résultats!$B$2:$AX$476,J$5,FALSE) -> 0.21340186 | K40: =VLOOKUP($D40,Résultats!$B$2:$AX$476,K$5,FALSE) -> 0.20526583 | L40: =VLOOKUP($D40,Résultats!$B$2:$AX$476,L$5,FALSE) -> 0.19515023 | ... W40: =VLOOKUP($D40,Résultats!$B$2:$AX$476,W$5,FALSE) -> 0.0074177517 | X40: =W40-'[1]Cibles THREEME'!$AJ11 -> -0.0025822483
C41: Wind | D41: ER_Elec_2305_2 | E41: =VLOOKUP($D41,Résultats!$B$2:$AX$476,E$5,FALSE) -> 0.30706949 | F41: =VLOOKUP($D41,Résultats!$B$2:$AX$476,F$5,FALSE) -> 2.1314552 | G41: =VLOOKUP($D41,Résultats!$B$2:$AX$476,G$5,FALSE) -> 2.8114068 | H41: =VLOOKUP($D41,Résultats!$B$2:$AX$476,H$5,FALSE) -> 3.0298895 | I41: =VLOOKUP($D41,Résultats!$B$2:$AX$476,I$5,FALSE) -> 3.2527421 | J41: =VLOOKUP($D41,Résultats!$B$2:$AX$476,J$5,FALSE) -> 3.4385807 | K41: =VLOOKUP($D41,Résultats!$B$2:$AX$476,K$5,FALSE) -> 3.6418406 | L41: =VLOOKUP($D41,Résultats!$B$2:$AX$476,L$5,FALSE) -> 3.8168505 | ... W41: =VLOOKUP($D41,Résultats!$B$2:$AX$476,W$5,FALSE) -> 15.902869 | X41: =W41-'[1]Cibles THREEME'!$AJ12 -> 3.3172887
C42: Solar | D42: ER_elec_2306_2 | E42: =VLOOKUP($D42,Résultats!$B$2:$AX$476,E$5,FALSE) -> 0.069090635 | F42: =VLOOKUP($D42,Résultats!$B$2:$AX$476,F$5,FALSE) -> 0.93934323 | G42: =VLOOKUP($D42,Résultats!$B$2:$AX$476,G$5,FALSE) -> 1.2390014 | H42: =VLOOKUP($D42,Résultats!$B$2:$AX$476,H$5,FALSE) -> 1.3352878 | I42: =VLOOKUP($D42,Résultats!$B$2:$AX$476,I$5,FALSE) -> 1.4335001 | J42: =VLOOKUP($D42,Résultats!$B$2:$AX$476,J$5,FALSE) -> 1.4945726 | K42: =VLOOKUP($D42,Résultats!$B$2:$AX$476,K$5,FALSE) -> 1.5627298 | L42: =VLOOKUP($D42,Résultats!$B$2:$AX$476,L$5,FALSE) -> 1.6183878 | ... W42: =VLOOKUP($D42,Résultats!$B$2:$AX$476,W$5,FALSE) -> 8.269618 | X42: =W42-'[1]Cibles THREEME'!$AJ13 -> 0.84126373 | Z42: Cf. onglet "G mix energie"
C43: Hydraulic | D43: ER_Elec_2307_2 | E43: =VLOOKUP($D43,Résultats!$B$2:$AX$476,E$5,FALSE) -> 3.4538971 | F43: =VLOOKUP($D43,Résultats!$B$2:$AX$476,F$5,FALSE) -> 2.6045426 | G43: =VLOOKUP($D43,Résultats!$B$2:$AX$476,G$5,FALSE) -> 3.435413 | H43: =VLOOKUP($D43,Résultats!$B$2:$AX$476,H$5,FALSE) -> 3.702389 | I43: =VLOOKUP($D43,Résultats!$B$2:$AX$476,I$5,FALSE) -> 3.9747049 | J43: =VLOOKUP($D43,Résultats!$B$2:$AX$476,J$5,FALSE) -> 4.1820071 | K43: =VLOOKUP($D43,Résultats!$B$2:$AX$476,K$5,FALSE) -> 4.4100339 | L43: =VLOOKUP($D43,Résultats!$B$2:$AX$476,L$5,FALSE) -> 4.6034939 | ... W43: =VLOOKUP($D43,Résultats!$B$2:$AX$476,W$5,FALSE) -> 3.6613298 | X43: =W43-'[1]Cibles THREEME'!$AJ14 -> -0.20506778 | AA43: 2020 | AB43: 2030 | AC43: 2050
...

Sheet T energie usages
A1: Energie par usage
A3: Energie finale (Mtep)
A4: =Résultats!B1 -> SNBC3
C7: Consos résultats de ThreeME | N7: Consos cibles d'Enerdata | U7: Consos résultats de ThreeME
C8: Hors bois domestique non marchand, avec consommation à double usage | N8: Hors bois domestique auto produit (8MTEP entre 2015 et 2030 4 Mtep en 2050) | U8: Hors bois domestique non marchand, avec consommation à double usage
C10: 2015 | H10: coal | I10: fuel and biofuel | J10: elec | K10: gas biogas biomass | L10: Total | N10: 2015 | O10: coal | P10: fuel and biofuel | Q10: elec | R10: gas biogas biomass | S10: Total | U10: 2015 | Z10: coal | AA10: fuel and biofuel | AB10: elec | AC10: gas biogas biomass | AD10: Total
C11: Transport | H11: =SUM(H12:H13) -> 0 | I11: =SUM(I12:I13) -> 43.235242 | J11: =SUM(J12:J13) -> 1.215759 | K11: =SUM(K12:K13) -> 0.22964514 | L11: =SUM(H11:K11) -> 44.680646 | N11: Transport | O11: ='[2]Bilan 2015'!$X$46 -> 0 | P11: =SUM('[2]Bilan 2015'!$X$41:$X$43) -> 42.748697 | Q11: ='[2]Bilan 2015'!$X$13 -> 0.94471195 | R11: =('[2]Bilan 2015'!$X$22+'[2]Bilan 2015'!$X$30+SUM('[2]Bilan 2015'!$X$36:$X$40)+SUM('[2]Bilan 2015'!$X$44:$X$45)+'[2]Bilan 2015'!$X$47) -> 0.072674067 | S11: =SUM(O11:R11) -> 43.766083 | U11: Transport | Z11: 0 | AA11: 43.655445 | AB11: 1.3708613 | AC11: 0.26944764 | AD11: 45.295754
C12: Personal vehicles | D12: ER_TRANS_PRIVATE_coal_2 | E12: ER_TRANS_PRIVATE_oil_2 | F12: ER_TRANS_PRIVATE_elec_2 | G12: ER_TRANS_PRIVATE_gas_2 | H12: =VLOOKUP(D12,Résultats!$B$2:$AX$476,'T energie vecteurs'!F5,FALSE) -> 0 | I12: =VLOOKUP(E12,Résultats!$B$2:$AX$476,'T energie vecteurs'!F5,FALSE) -> 24.202574 | J12: =VLOOKUP(F12,Résultats!$B$2:$AX$476,'T energie vecteurs'!F5,FALSE) -> 0.028859426 | K12: =VLOOKUP(G12,Résultats!$B$2:$AX$476,'T energie vecteurs'!F5,FALSE) -> 1.0452388e-05 | L12: =SUM(H12:K12) -> 24.231444 | N12: Personal vehicles | U12: Personal vehicles | V12: ER_TRANS_PRIVATE_coal_2 | W12: ER_TRANS_PRIVATE_oil_2 | X12: ER_TRANS_PRIVATE_elec_2 | Y12: ER_TRANS_PRIVATE_gas_2 | Z12: 0 | AA12: 24.375675 | AB12: 0.028638346 | AC12: 6.2334451e-06 | AD12: 24.40432
C13: Public and freight transport | D13: ER_TRANS_PUBLIC_coal_2 | E13: ER_TRANS_PUBLIC_oil_2 | F13: ER_TRANS_PUBLIC_elec_2 | G13: ER_TRANS_PUBLIC_gas_2 | H13: =VLOOKUP(D13,Résultats!$B$2:$AX$476,'T energie vecteurs'!F5,FALSE) -> 0 | I13: =VLOOKUP(E13,Résultats!$B$2:$AX$476,'T energie vecteurs'!F5,FALSE) -> 19.032668 | J13: =VLOOKUP(F13,Résultats!$B$2:$AX$476,'T energie vecteurs'!F5,FALSE) -> 1.1868996 | K13: =VLOOKUP(G13,Résultats!$B$2:$AX$476,'T energie vecteurs'!F5,FALSE) -> 0.22963469 | L13: =SUM(H13:K13) -> 20.449203 | N13: Public and freight transport | U13: Public and freight transport | V13: ER_TRANS_PUBLIC_coal_2 | W13: ER_TRANS_PUBLIC_oil_2 | X13: ER_TRANS_PUBLIC_elec_2 | Y13: ER_TRANS_PUBLIC_gas_2 | Z13: 0 | AA13: 19.27977 | AB13: 1.3422229 | AC13: 0.26944141 | AD13: 20.891434
C14: Residential | D14: ER_RESIDENTIAL_coal_2 | E14: ER_RESIDENTIAL_oil_2 | F14: ER_RESIDENTIAL_elec_2 | G14: ER_RESIDENTIAL_gas_2 | H14: =VLOOKUP(D14,Résultats!$B$2:$AX$476,'T energie vecteurs'!F5,FALSE) -> 0.29368456 | I14: =VLOOKUP(E14,Résultats!$B$2:$AX$476,'T energie vecteurs'!F5,FALSE) -> 7.1747672 | J14: =VLOOKUP(F14,Résultats!$B$2:$AX$476,'T energie vecteurs'!F5,FALSE) -> 14.024228 | K14: =VLOOKUP(G14,Résultats!$B$2:$AX$476,'T energie vecteurs'!F5,FALSE)+5 -> 21.106097 | L14: =SUM(H14:K14) -> 42.598777 | N14: Residential | O14: ='[2]Bilan 2015'!$V$46 -> 0.036764197 | P14: =SUM('[2]Bilan 2015'!$V$41:$V$43) -> 6.6752954 | Q14: ='[2]Bilan 2015'!$V$13 -> 13.620367 | R14: =('[2]Bilan 2015'!$V$22+'[2]Bilan 2015'!$V$30+SUM('[2]Bilan 2015'!$V$36:$V$40)+SUM('[2]Bilan 2015'!$V$44:$V$45)+'[2]Bilan 2015'!$V$47) -> 21.832864 | S14: =SUM(O14:R14) -> 42.16529 | U14: Residential | V14: ER_RESIDENTIAL_coal_2 | W14: ER_RESIDENTIAL_oil_2 | X14: ER_RESIDENTIAL_elec_2 | Y14: ER_RESIDENTIAL_gas_2 | Z14: 0.29143291 | AA14: 6.750666 | AB14: 14.411191 | AC14: 20.636263 | AD14: 42.089554
C15: Service | D15: ER_TERTIARY_coal_2 | E15: ER_TERTIARY_oil_2 | F15: ER_TERTIARY_elec_2 | G15: ER_TERTIARY_gas_2 | H15: =VLOOKUP(D15,Résultats!$B$2:$AX$476,'T energie vecteurs'!F5,FALSE) -> 0 | I15: =VLOOKUP(E15,Résultats!$B$2:$AX$476,'T energie vecteurs'!F5,FALSE) -> 4.2755146 | J15: =VLOOKUP(F15,Résultats!$B$2:$AX$476,'T energie vecteurs'!F5,FALSE) -> 13.311593 | K15: =VLOOKUP(G15,Résultats!$B$2:$AX$476,'T energie vecteurs'!F5,FALSE) -> 9.726067 | L15: =SUM(H15:K15) -> 27.313174 | N15: Service | O15: ='[2]Bilan 2015'!$W$46 -> 0.043073392 | P15: =SUM('[2]Bilan 2015'!$W$41:$W$43) -> 3.0154656 | Q15: ='[2]Bilan 2015'!$W$13 -> 12.701365 | R15: =('[2]Bilan 2015'!$W$22+'[2]Bilan 2015'!$W$30+SUM('[2]Bilan 2015'!$W$36:$W$40)+SUM('[2]Bilan 2015'!$W$44:$W$45)+'[2]Bilan 2015'!$W$47) -> 8.7461122 | S15: =SUM(O15:R15) -> 24.506017 | U15: Service | V15: ER_TERTIARY_coal_2 | W15: ER_TERTIARY_oil_2 | X15: ER_TERTIARY_elec_2 | Y15: ER_TERTIARY_gas_2 | Z15: 0 | AA15: 3.5686169 | AB15: 12.769876 | AC15: 9.0390918 | AD15: 25.377585
C16: Industry and agriculture | H16: =SUM(H17:H18) -> 4.8875364 | I16: =SUM(I17:I18) -> 16.278152 | J16: =SUM(J17:J18) -> 11.010773 | K16: =SUM(K17:K18) -> 13.712766 | L16: =SUM(H16:K16) -> 45.889227 | N16: Industry | O16: =O17+O18 -> 4.2636281 | P16: =P17+P18 -> 14.865721 | Q16: =Q17+Q18 -> 10.069552 | R16: =R17+R18 -> 13.7564 | S16: =SUM(O16:R16) -> 42.955301 | U16: Industry and agriculture | Z16: 4.1729011 | AA16: 15.619453 | AB16: 10.978162 | AC16: 14.084083 | AD16: 44.854599
C17: Industry | D17: ER_INDUS_coal_2 | E17: ER_INDUS_oil_2 | F17: ER_INDUS_elec_2 | G17: ER_INDUS_gas_2 | H17: =VLOOKUP(D17,Résultats!$B$2:$AX$476,'T energie vecteurs'!F5,FALSE) -> 3.8966424 | I17: =VLOOKUP(E17,Résultats!$B$2:$AX$476,'T energie vecteurs'!F5,FALSE) -> 14.380357 | J17: =VLOOKUP(F17,Résultats!$B$2:$AX$476,'T energie vecteurs'!F5,FALSE) -> 11.010773 | K17: =VLOOKUP(G17,Résultats!$B$2:$AX$476,'T energie vecteurs'!F5,FALSE) -> 11.965566 | L17: =SUM(H17:K17) -> 41.253338 | N17: Industry energetic uses | O17: ='[2]Bilan 2015'!$U$46 -> 1.0493093 | P17: =SUM('[2]Bilan 2015'!$U$41:$U$43) -> 2.4127207 | Q17: ='[2]Bilan 2015'!$U$13 -> 10.069552 | R17: =('[2]Bilan 2015'!$U$22+'[2]Bilan 2015'!$U$30+SUM('[2]Bilan 2015'!$U$36:$U$40)+SUM('[2]Bilan 2015'!$U$44:$U$45)+'[2]Bilan 2015'!$U$47) -> 12.654814 | S17: =SUM(O17:R17) -> 26.186396 | U17: Industry | V17: ER_INDUS_coal_2 | W17: ER_INDUS_oil_2 | X17: ER_INDUS_elec_2 | Y17: ER_INDUS_gas_2 | Z17: 3.2526652 | AA17: 13.839453 | AB17: 10.978162 | AC17: 12.365702 | AD17: 40.435983
C18: Industry non energetic uses | D18: Q_Mtep_indus_21_2 | E18: Q_Mtep_indus_22_2 | F18: Q_Mtep_indus_23_2 | G18: Q_Mtep_indus_24_2 | H18: =VLOOKUP(D18,Résultats!$B$2:$AX$476,'T energie vecteurs'!F5,FALSE) -> 0.99089399 | I18: =VLOOKUP(E18,Résultats!$B$2:$AX$476,'T energie vecteurs'!F5,FALSE) -> 1.8977947 | J18: =VLOOKUP(F18,Résultats!$B$2:$AX$476,'T energie vecteurs'!F5,FALSE) -> 0 | K18: =VLOOKUP(G18,Résultats!$B$2:$AX$476,'T energie vecteurs'!F5,FALSE) -> 1.7471999 | L18: =SUM(H18:K18) -> 4.6358887 | N18: Industry non energetic uses | O18: ='[2]Bilan 2015'!$E$52 -> 3.2143188 | P18: =('[2]Bilan 2015'!$E$54+'[2]Bilan 2015'!$E$56) -> 12.453 | Q18: 0 | R18: =('[2]Bilan 2015'!$E$53+'[2]Bilan 2015'!$E$55+'[2]Bilan 2015'!$E$57) -> 1.1015862 | S18: =SUM(O18:R18) -> 16.768905 | U18: Industry non energetic uses | V18: Q_Mtep_indus_21_2 | W18: Q_Mtep_indus_22_2 | X18: Q_Mtep_indus_23_2 | Y18: Q_Mtep_indus_24_2 | Z18: 0.92023592 | AA18: 1.7799997 | AB18: 0 | AC18: 1.7183807 | AD18: 4.4186164
C19: Agriculture | D19: ER_AGRICULTURE_coal_2 | E19: ER_AGRICULTURE_oil_2 | F19: ER_AGRICULTURE_elec_2 | G19: ER_AGRICULTURE_gas_2 | H19: =VLOOKUP(D19,Résultats!$B$2:$AX$476,'T energie vecteurs'!F5,FALSE) -> 0 | I19: =VLOOKUP(E19,Résultats!$B$2:$AX$476,'T energie vecteurs'!F5,FALSE) -> 2.4325525 | J19: =VLOOKUP(F19,Résultats!$B$2:$AX$476,'T energie vecteurs'!F5,FALSE) -> 0.31578116 | K19: =VLOOKUP(G19,Résultats!$B$2:$AX$476,'T energie vecteurs'!F5,FALSE) -> 0.36471241 | L19: =SUM(H19:K19) -> 3.1130461 | N19: Agriculture | O19: ='[2]Bilan 2015'!$T$46 -> 0.0022137193 | P19: =SUM('[2]Bilan 2015'!$T$41:$T$43) -> 3.4936668 | Q19: ='[2]Bilan 2015'!$T$13 -> 0.74651763 | R19: =('[2]Bilan 2015'!$T$22+'[2]Bilan 2015'!$T$30+SUM('[2]Bilan 2015'!$T$36:$T$40)+SUM('[2]Bilan 2015'!$T$44:$T$45)+'[2]Bilan 2015'!$T$47) -> 0.24365267 | S19: =SUM(O19:R19) -> 4.4860508 | U19: Agriculture | V19: ER_AGRICULTURE_coal_2 | W19: ER_AGRICULTURE_oil_2 | X19: ER_AGRICULTURE_elec_2 | Y19: ER_AGRICULTURE_gas_2 | Z19: 0 | AA19: 2.4208977 | AB19: 0.33677654 | AC19: 0.36234122 | AD19: 3.1200155
C20: Total Final Mtep | H20: =SUM(H11,H14:H16,H19) -> 5.181221 | I20: =SUM(I11,I14:I16,I19) -> 73.396228 | J20: =SUM(J11,J14:J16,J19) -> 39.878134 | K20: =SUM(K11,K14:K16,K19) -> 45.139287 | L20: =SUM(H20:K20) -> 163.59487 | N20: Total Final Mtep | O20: =O11+O14+O15+O16+O19 -> 4.3456794 | P20: =P11+P14+P15+P16+P19 -> 70.798845 | Q20: =Q11+Q14+Q15+Q16+Q19 -> 38.082514 | R20: =R11+R14+R15+R16+R19 -> 44.651703 | S20: =SUM(O20:R20) -> 157.87874 | U20: Total Final Mtep | Z20: 4.464334 | AA20: 72.015078 | AB20: 39.866868 | AC20: 44.391227 | AD20: 160.73751
L21: =L11+L14+L15+L16+L19 -> 163.59487 | AD21: 160.73751
C23: 2020 | H23: coal | I23: fuel and biofuel | J23: elec | K23: gas biogas biomass | L23: Total | N23: 2020 | O23: coal | P23: fuel and biofuel | Q23: elec | R23: gas biogas biomass | S23: Total | U23: 2020 | Z23: coal | AA23: fuel and biofuel | AB23: elec | AC23: gas biogas biomass | AD23: Total
C24: Transport | H24: =SUM(H25:H26) -> 0 | I24: =SUM(I25:I26) -> 42.251962 | J24: =SUM(J25:J26) -> 1.428452 | K24: =SUM(K25:K26) -> 0.25528918 | L24: =SUM(H24:K24) -> 43.935704 | N24: Transport | O24: ='[2]Bilan 2020'!$X$46/11.63 -> 0 | P24: =SUM('[2]Bilan 2020'!$X$41:$X$43)/11.63 -> 35.668036 | Q24: ='[2]Bilan 2020'!$X$13/11.63 -> 0.71687008 | R24: =('[2]Bilan 2020'!$X$22+'[2]Bilan 2020'!$X$30+SUM('[2]Bilan 2020'!$X$36:$X$40)+SUM('[2]Bilan 2020'!$X$44:$X$45)+'[2]Bilan 2020'!$X$47)/11.63 -> 0.19326866 | S24: =SUM(O24:R24) -> 36.578175 | U24: Transport | Z24: 0 | AA24: 43.018744 | AB24: 1.8220352 | AC24: 0.31541142 | AD24: 45.156191
C25: Personal vehicles | D25: ER_TRANS_PRIVATE_coal_2 | E25: ER_TRANS_PRIVATE_oil_2 | F25: ER_TRANS_PRIVATE_elec_2 | G25: ER_TRANS_PRIVATE_gas_2 | H25: =VLOOKUP(D25,Résultats!$B$2:$AX$476,'T energie vecteurs'!I5,FALSE) -> 0 | I25: =VLOOKUP(E25,Résultats!$B$2:$AX$476,'T energie vecteurs'!I5,FALSE) -> 23.698841 | J25: =VLOOKUP(F25,Résultats!$B$2:$AX$476,'T energie vecteurs'!I5,FALSE) -> 0.10937869 | K25: =VLOOKUP(G77,Résultats!$B$2:$AX$476,'T energie vecteurs'!I5,FALSE) -> 1.6040599e-05 | L25: =SUM(H25:K25) -> 23.808236 | N25: Personal vehicles | U25: Personal vehicles | V25: ER_TRANS_PRIVATE_coal_2 | W25: ER_TRANS_PRIVATE_oil_2 | X25: ER_TRANS_PRIVATE_elec_2 | Y25: ER_TRANS_PRIVATE_gas_2 | Z25: 0 | AA25: 23.922501 | AB25: 0.10584781 | AC25: 9.2348089e-06 | AD25: 24.028358
C26: Public and freight transport | D26: ER_TRANS_PUBLIC_coal_2 | E26: ER_TRANS_PUBLIC_oil_2 | F26: ER_TRANS_PUBLIC_elec_2 | G26: ER_TRANS_PUBLIC_gas_2 | H26: =VLOOKUP(D26,Résultats!$B$2:$AX$476,'T energie vecteurs'!I5,FALSE) -> 0 | I26: =VLOOKUP(E26,Résultats!$B$2:$AX$476,'T energie vecteurs'!I5,FALSE) -> 18.553121 | J26: =VLOOKUP(F26,Résultats!$B$2:$AX$476,'T energie vecteurs'!I5,FALSE) -> 1.3190733 | K26: =VLOOKUP(G26,Résultats!$B$2:$AX$476,'T energie vecteurs'!I5,FALSE) -> 0.25527314 | L26: =SUM(H26:K26) -> 20.127468 | N26: Public and freight transport | U26: Public and freight transport | V26: ER_TRANS_PUBLIC_coal_2 | W26: ER_TRANS_PUBLIC_oil_2 | X26: ER_TRANS_PUBLIC_elec_2 | Y26: ER_TRANS_PUBLIC_gas_2 | Z26: 0 | AA26: 19.096243 | AB26: 1.7161874 | AC26: 0.31540219 | AD26: 21.127833
C27: Residential | D27: ER_RESIDENTIAL_coal_2 | E27: ER_RESIDENTIAL_oil_2 | F27: ER_RESIDENTIAL_elec_2 | G27: ER_RESIDENTIAL_gas_2 | H27: =VLOOKUP(D27,Résultats!$B$2:$AX$476,'T energie vecteurs'!I5,FALSE) -> 0.26291969 | I27: =VLOOKUP(E27,Résultats!$B$2:$AX$476,'T energie vecteurs'!I5,FALSE) -> 6.2714561 | J27: =VLOOKUP(F27,Résultats!$B$2:$AX$476,'T energie vecteurs'!I5,FALSE) -> 14.695407 | K27: =VLOOKUP(G27,Résultats!$B$2:$AX$476,'T energie vecteurs'!I5,FALSE)+6 -> 20.495942 | L27: =SUM(H27:K27) -> 41.725725 | N27: Residential | O27: ='[2]Bilan 2020'!$V$46/11.63 -> 0.020700735 | P27: =SUM('[2]Bilan 2020'!$V$41:$V$43)/11.63 -> 4.2874728 | Q27: ='[2]Bilan 2020'!$V$13/11.63 -> 13.618732 | R27: =('[2]Bilan 2020'!$V$22+'[2]Bilan 2020'!$V$30+SUM('[2]Bilan 2020'!$V$36:$V$40)+SUM('[2]Bilan 2020'!$V$44:$V$45)+'[2]Bilan 2020'!$V$47)/11.63 -> 20.40841 | S27: =SUM(O27:R27) -> 38.335315 | U27: Residential | V27: ER_RESIDENTIAL_coal_2 | W27: ER_RESIDENTIAL_oil_2 | X27: ER_RESIDENTIAL_elec_2 | Y27: ER_RESIDENTIAL_gas_2 | Z27: 0.26184971 | AA27: 5.7024644 | AB27: 15.25919 | AC27: 20.182441 | AD27: 41.405944
C28: Service | D28: ER_TERTIARY_coal_2 | E28: ER_TERTIARY_oil_2 | F28: ER_TERTIARY_elec_2 | G28: ER_TERTIARY_gas_2 | H28: =VLOOKUP(D28,Résultats!$B$2:$AX$476,'T energie vecteurs'!I5,FALSE) -> 0 | I28: =VLOOKUP(E28,Résultats!$B$2:$AX$476,'T energie vecteurs'!I5,FALSE) -> 3.1173306 | J28: =VLOOKUP(F28,Résultats!$B$2:$AX$476,'T energie vecteurs'!I5,FALSE) -> 12.975212 | K28: =VLOOKUP(G28,Résultats!$B$2:$AX$476,'T energie vecteurs'!I5,FALSE) -> 7.935653 | L28: =SUM(H28:K28) -> 24.028196 | N28: Service | O28: =('[2]Bilan 2020'!$W$46)/11.63 -> 0.030546421 | P28: =SUM('[2]Bilan 2020'!$W$41:$W$43)/11.63 -> 2.7068356 | Q28: =('[2]Bilan 2020'!$W$13)/11.63 -> 10.724851 | R28: =('[2]Bilan 2020'!$W$22+'[2]Bilan 2020'!$W$30+SUM('[2]Bilan 2020'!$W$36:$W$40)+SUM('[2]Bilan 2020'!$W$44:$W$45)+'[2]Bilan 2020'!$W$47)/11.63 -> 7.1906336 | S28: =SUM(O28:R28) -> 20.652866 | U28: Service | V28: ER_TERTIARY_coal_2 | W28: ER_TERTIARY_oil_2 | X28: ER_TERTIARY_elec_2 | Y28: ER_TERTIARY_gas_2 | Z28: 0 | AA28: 2.5782826 | AB28: 12.104467 | AC28: 7.6832677 | AD28: 22.366018
C29: Industry and agriculture | H29: =SUM(H30:H32) -> 2.6579612 | I29: =SUM(I30:I32) -> 13.620348 | J29: =SUM(J30:J32) -> 9.6460239 | K29: =SUM(K30:K32) -> 14.365485 | L29: =SUM(H29:K29) -> 40.289818 | N29: Industry | O29: =O30+O31 -> 3.1626378 | P29: =P30+P31 -> 13.919974 | Q29: =Q30+Q31 -> 9.0413235 | R29: =R30+R31 -> 14.312071 | S29: =SUM(O29:R29) -> 40.436006 | U29: Industry and agriculture | Z29: 2.9352594 | AA29: 14.864282 | AB29: 9.5134154 | AC29: 13.758628 | AD29: 41.071585
C30: Industry | D30: ER_INDUS_coal_2 | E30: ER_INDUS_oil_2 | F30: ER_INDUS_elec_2 | G30: ER_INDUS_gas_2 | H30: =VLOOKUP(D30,Résultats!$B$2:$AX$476,'T energie vecteurs'!I5,FALSE) -> 1.7896973 | I30: =VLOOKUP(E30,Résultats!$B$2:$AX$476,'T energie vecteurs'!I5,FALSE) -> 9.3519632 | J30: =VLOOKUP(F30,Résultats!$B$2:$AX$476,'T energie vecteurs'!I5,FALSE) -> 9.3345403 | K30: =VLOOKUP(G30,Résultats!$B$2:$AX$476,'T energie vecteurs'!I5,FALSE) -> 11.999935 | L30: =SUM(H30:K30) -> 32.476135 | N30: Industry energetic uses | O30: ='[2]Bilan 2020'!$U$46/11.63 -> 0.77267988 | P30: =SUM('[2]Bilan 2020'!$U$41:$U$43)/11.63 -> 2.7003588 | Q30: ='[2]Bilan 2020'!$U$13/11.63 -> 9.0413235 | R30: =('[2]Bilan 2020'!$U$22+'[2]Bilan 2020'!$U$30+SUM('[2]Bilan 2020'!$U$36:$U$40)+SUM('[2]Bilan 2020'!$U$44:$U$45)+'[2]Bilan 2020'!$U$47)/11.63 -> 13.277855 | S30: =SUM(O30:R30) -> 25.792217 | U30: Industry | V30: ER_INDUS_coal_2 | W30: ER_INDUS_oil_2 | X30: ER_INDUS_elec_2 | Y30: ER_INDUS_gas_2 | Z30: 2.0907212 | AA30: 10.561312 | AB30: 9.1722502 | AC30: 11.439848 | AD30: 33.264131
C31: Industry non energetic uses | D31: Q_Mtep_indus_21_2 | E31: Q_Mtep_indus_22_2 | F31: Q_Mtep_indus_23_2 | G31: Q_Mtep_indus_24_2 | H31: =VLOOKUP(D31,Résultats!$B$2:$AX$476,'T energie vecteurs'!I5,FALSE) -> 0.86826389 | I31: =VLOOKUP(E31,Résultats!$B$2:$AX$476,'T energie vecteurs'!I5,FALSE) -> 1.8873345 | J31: =VLOOKUP(F31,Résultats!$B$2:$AX$476,'T energie vecteurs'!I5,FALSE) -> 0 | K31: =VLOOKUP(G31,Résultats!$B$2:$AX$476,'T energie vecteurs'!I5,FALSE) -> 2.0350648 | L31: =SUM(H31:K31) -> 4.7906631 | N31: Industry non energetic uses | O31: ='[2]Bilan 2020'!$E$52/11.63 -> 2.3899579 | P31: =('[2]Bilan 2020'!$E$54+'[2]Bilan 2020'!$E$56)/11.63 -> 11.219615 | Q31: 0 | R31: =('[2]Bilan 2020'!$E$53+'[2]Bilan 2020'!$E$55+'[2]Bilan 2020'!$E$57)/11.63 -> 1.0342164 | S31: =SUM(O31:R31) -> 14.643789 | U31: Industry non energetic uses | V31: Q_Mtep_indus_21_2 | W31: Q_Mtep_indus_22_2 | X31: Q_Mtep_indus_23_2 | Y31: Q_Mtep_indus_24_2 | Z31: 0.84453811 | AA31: 1.8990812 | AB31: 0 | AC31: 1.9869123 | AD31: 4.7305316
C32: Agriculture | D32: ER_AGRICULTURE_coal_2 | E32: ER_AGRICULTURE_oil_2 | F32: ER_AGRICULTURE_elec_2 | G32: ER_AGRICULTURE_gas_2 | H32: =VLOOKUP(D32,Résultats!$B$2:$AX$476,'T energie vecteurs'!I5,FALSE) -> 0 | I32: =VLOOKUP(E32,Résultats!$B$2:$AX$476,'T energie vecteurs'!I5,FALSE) -> 2.3810507 | J32: =VLOOKUP(F32,Résultats!$B$2:$AX$476,'T energie vecteurs'!I5,FALSE) -> 0.31148359 | K32: =VLOOKUP(G32,Résultats!$B$2:$AX$476,'T energie vecteurs'!I5,FALSE) -> 0.33048569 | L32: =SUM(H32:K32) -> 3.02302 | N32: Agriculture | O32: ='[2]Bilan 2020'!$T$46/11.63 -> 0.001321701 | P32: =SUM('[2]Bilan 2020'!$T$41:$T$43)/11.63 -> 3.3486885 | Q32: ='[2]Bilan 2020'!$T$13/11.63 -> 0.69143728 | R32: =('[2]Bilan 2020'!$T$22+'[2]Bilan 2020'!$T$30+SUM('[2]Bilan 2020'!$T$36:$T$40)+SUM('[2]Bilan 2020'!$T$44:$T$45)+'[2]Bilan 2020'!$T$47)/11.63 -> 0.41959097 | S32: =SUM(O32:R32) -> 4.4610384 | U32: Agriculture | V32: ER_AGRICULTURE_coal_2 | W32: ER_AGRICULTURE_oil_2 | X32: ER_AGRICULTURE_elec_2 | Y32: ER_AGRICULTURE_gas_2 | Z32: 0 | AA32: 2.4038891 | AB32: 0.34116511 | AC32: 0.33186802 | AD32: 3.0769222
C33: Total Final Mtep | H33: =SUM(H24,H27:H29) -> 2.9208809 | I33: =SUM(I24,I27:I29) -> 65.261097 | J33: =SUM(J24,J27:J29) -> 38.745095 | K33: =SUM(K24,K27:K29) -> 43.052369 | L33: =SUM(H33:K33) -> 149.97944 | N33: Total Final Mtep | O33: =O24+O27+O28+O29+O32 -> 3.2152067 | P33: =P24+P27+P28+P29+P32 -> 59.931007 | Q33: =Q24+Q27+Q28+Q29+Q32 -> 34.793213 | R33: =R24+R27+R28+R29+R32 -> 42.523975 | S33: =SUM(O33:R33) -> 140.4634 | U33: Total Final Mtep | Z33: 3.1971091 | AA33: 66.163774 | AB33: 38.699107 | AC33: 41.939748 | AD33: 149.99974
C36: 2022 | H36: coal | I36: fuel and biofuel | J36: elec | K36: gas biogas biomass | L36: Total | N36: 2022 | O36: coal | P36: fuel and biofuel | Q36: elec | R36: gas biogas biomass | S36: Total | U36: 2022 | Z36: coal | AA36: fuel and biofuel | AB36: elec | AC36: gas biogas biomass | AD36: Total
C37: Transport | H37: =SUM(H38:H39) -> 0 | I37: =SUM(I38:I39) -> 41.582451 | J37: =SUM(J38:J39) -> 1.5231817 | K37: =SUM(K38:K39) -> 0.36256658 | L37: =SUM(H37:K37) -> 43.4682 | N37: Transport | O37: ='[3]Bilan 2022 réel'!$X$46/11.63 -> 0 | P37: =SUM('[3]Bilan 2022 réel'!$X$41:$X$43)/11.63 -> 43.395883 | Q37: ='[3]Bilan 2022 réel'!$X$13/11.63 -> 0.93062752 | R37: =('[3]Bilan 2022 réel'!$X$22+'[3]Bilan 2022 réel'!$X$30+SUM('[3]Bilan 2022 réel'!$X$36:$X$40)+SUM('[3]Bilan 2022 réel'!$X$44:$X$45)+'[3]Bilan 2022 réel'!$X$47)/11.63 -> 0.31885684 | S37: =SUM(O37:R37) -> 44.645367 | U37: Transport | Z37: 0 | AA37: 42.948465 | AB37: 1.9847766 | AC37: 0.4409919 | AD37: 45.374233
C38: Personal vehicles | D38: ER_TRANS_PRIVATE_coal_2 | E38: ER_TRANS_PRIVATE_oil_2 | F38: ER_TRANS_PRIVATE_elec_2 | G38: ER_TRANS_PRIVATE_gas_2 | H38: =VLOOKUP(D38,Résultats!$B$2:$AX$476,'T energie vecteurs'!K5,FALSE) -> 0 | I38: =VLOOKUP(E38,Résultats!$B$2:$AX$476,'T energie vecteurs'!K5,FALSE) -> 22.858451 | J38: =VLOOKUP(F38,Résultats!$B$2:$AX$476,'T energie vecteurs'!K5,FALSE) -> 0.16593726 | K38: =VLOOKUP(G51,Résultats!$B$2:$AX$476,'T energie vecteurs'!K5,FALSE) -> 1.8981503e-05 | L38: =SUM(H38:K38) -> 23.024407 | N38: Personal vehicles | U38: Personal vehicles | V38: ER_TRANS_PRIVATE_coal_2 | W38: ER_TRANS_PRIVATE_oil_2 | X38: ER_TRANS_PRIVATE_elec_2 | Y38: ER_TRANS_PRIVATE_gas_2 | Z38: 0 | AA38: 23.089158 | AB38: 0.16078565 | AC38: 1.1513368e-05 | AD38: 23.249955
C39: Public and freight transport | D39: ER_TRANS_PUBLIC_coal_2 | E39: ER_TRANS_PUBLIC_oil_2 | F39: ER_TRANS_PUBLIC_elec_2 | G39: ER_TRANS_PUBLIC_gas_2 | H39: =VLOOKUP(D39,Résultats!$B$2:$AX$476,'T energie vecteurs'!K5,FALSE) -> 0 | I39: =VLOOKUP(E39,Résultats!$B$2:$AX$476,'T energie vecteurs'!K5,FALSE) -> 18.724 | J39: =VLOOKUP(F39,Résultats!$B$2:$AX$476,'T energie vecteurs'!K5,FALSE) -> 1.3572444 | K39: =VLOOKUP(G39,Résultats!$B$2:$AX$476,'T energie vecteurs'!K5,FALSE) -> 0.3625476 | L39: =SUM(H39:K39) -> 20.443792 | N39: Public and freight transport | U39: Public and freight transport | V39: ER_TRANS_PUBLIC_coal_2 | W39: ER_TRANS_PUBLIC_oil_2 | X39: ER_TRANS_PUBLIC_elec_2 | Y39: ER_TRANS_PUBLIC_gas_2 | Z39: 0 | AA39: 19.859307 | AB39: 1.8239909 | AC39: 0.44098038 | AD39: 22.124278
C40: Residential | D40: ER_RESIDENTIAL_coal_2 | E40: ER_RESIDENTIAL_oil_2 | F40: ER_RESIDENTIAL_elec_2 | G40: ER_RESIDENTIAL_gas_2 | H40: =VLOOKUP(D40,Résultats!$B$2:$AX$476,'T energie vecteurs'!K5,FALSE) -> 0.24509812 | I40: =VLOOKUP(E40,Résultats!$B$2:$AX$476,'T energie vecteurs'!K5,FALSE) -> 5.9260819 | J40: =VLOOKUP(F40,Résultats!$B$2:$AX$476,'T energie vecteurs'!K5,FALSE) -> 14.791503 | K40: =VLOOKUP(G40,Résultats!$B$2:$AX$476,'T energie vecteurs'!K5,FALSE)+8 -> 21.758443 | L40: =SUM(H40:K40) -> 42.721126 | N40: Residential | O40: ='[3]Bilan 2022 réel'!$V$46/11.63 -> 0.026476317 | P40: =SUM('[3]Bilan 2022 réel'!$V$41:$V$43)/11.63 -> 3.5006052 | Q40: ='[3]Bilan 2022 réel'!$V$13/11.63 -> 13.359407 | R40: =('[3]Bilan 2022 réel'!$V$22+'[3]Bilan 2022 réel'!$V$30+SUM('[3]Bilan 2022 réel'!$V$36:$V$40)+SUM('[3]Bilan 2022 réel'!$V$44:$V$45)+'[3]Bilan 2022 réel'!$V$47)/11.63 -> 20.358937 | S40: =SUM(O40:R40) -> 37.245425 | U40: Residential | V40: ER_RESIDENTIAL_coal_2 | W40: ER_RESIDENTIAL_oil_2 | X40: ER_RESIDENTIAL_elec_2 | Y40: ER_RESIDENTIAL_gas_2 | Z40: 0.24256246 | AA40: 5.5365794 | AB40: 15.029563 | AC40: 21.678189 | AD40: 42.486894
C41: Service | D41: ER_TERTIARY_coal_2 | E41: ER_TERTIARY_oil_2 | F41: ER_TERTIARY_elec_2 | G41: ER_TERTIARY_gas_2 | H41: =VLOOKUP(D41,Résultats!$B$2:$AX$476,'T energie vecteurs'!K5,FALSE) -> 0 | I41: =VLOOKUP(E41,Résultats!$B$2:$AX$476,'T energie vecteurs'!K5,FALSE) -> 3.1162613 | J41: =VLOOKUP(F41,Résultats!$B$2:$AX$476,'T energie vecteurs'!K5,FALSE) -> 13.110018 | K41: =VLOOKUP(G41,Résultats!$B$2:$AX$476,'T energie vecteurs'!K5,FALSE) -> 7.7875307 | L41: =SUM(H41:K41) -> 24.01381 | N41: Service | O41: =('[3]Bilan 2022 réel'!$W$46)/11.63 -> 0.032835728 | P41: =SUM('[3]Bilan 2022 réel'!$W$41:$W$43)/11.63 -> 2.081572 | Q41: =('[3]Bilan 2022 réel'!$W$13)/11.63 -> 11.43888 | R41: =('[3]Bilan 2022 réel'!$W$22+'[3]Bilan 2022 réel'!$W$30+SUM('[3]Bilan 2022 réel'!$W$36:$W$40)+SUM('[3]Bilan 2022 réel'!$W$44:$W$45)+'[3]Bilan 2022 réel'!$W$47)/11.63 -> 7.4016622 | S41: =SUM(O41:R41) -> 20.95495 | U41: Service | V41: ER_TERTIARY_coal_2 | W41: ER_TERTIARY_oil_2 | X41: ER_TERTIARY_elec_2 | Y41: ER_TERTIARY_gas_2 | Z41: 0 | AA41: 2.6025409 | AB41: 12.087616 | AC41: 7.5277159 | AD41: 22.217873
C42: Industry and agriculture | H42: =SUM(H43:H45) -> 2.627281 | I42: =SUM(I43:I45) -> 13.255116 | J42: =SUM(J43:J45) -> 10.008524 | K42: =SUM(K43:K45) -> 14.579111 | L42: =SUM(H42:K42) -> 40.470031 | N42: Industry | O42: =O43+O44 -> 4.5030918 | P42: =P43+P44 -> 11.747675 | Q42: =Q43+Q44 -> 9.2559822 | R42: =R43+R44 -> 13.798624 | S42: =SUM(O42:R42) -> 39.305373 | U42: Industry and agriculture | Z42: 2.9997859 | AA42: 15.435561 | AB42: 9.8670525 | AC42: 14.598026 | AD42: 42.900425
C43: Industry | D43: ER_INDUS_coal_2 | E43: ER_INDUS_oil_2 | F43: ER_INDUS_elec_2 | G43: ER_INDUS_gas_2 | H43: =VLOOKUP(D43,Résultats!$B$2:$AX$476,'T energie vecteurs'!K5,FALSE) -> 1.7434572 | I43: =VLOOKUP(E43,Résultats!$B$2:$AX$476,'T energie vecteurs'!K5,FALSE) -> 8.925026 | J43: =VLOOKUP(F43,Résultats!$B$2:$AX$476,'T energie vecteurs'!K5,FALSE) -> 9.6873319 | K43: =VLOOKUP(G43,Résultats!$B$2:$AX$476,'T energie vecteurs'!K5,FALSE) -> 12.183993 | L43: =SUM(H43:K43) -> 32.539808 | N43: Industry energetic uses | O43: ='[3]Bilan 2022 réel'!$U$46/11.63 -> 0.63402045 | P43: =SUM('[3]Bilan 2022 réel'!$U$41:$U$43)/11.63 -> 2.477583 | Q43: ='[3]Bilan 2022 réel'!$U$13/11.63 -> 9.2559822 | R43: =('[3]Bilan 2022 réel'!$U$22+'[3]Bilan 2022 réel'!$U$30+SUM('[3]Bilan 2022 réel'!$U$36:$U$40)+SUM('[3]Bilan 2022 réel'!$U$44:$U$45)+'[3]Bilan 2022 réel'!$U$47)/11.63 -> 12.926273 | S43: =SUM(O43:R43) -> 25.293858 | U43: Industry | V43: ER_INDUS_coal_2 | W43: ER_INDUS_oil_2 | X43: ER_INDUS_elec_2 | Y43: ER_INDUS_gas_2 | Z43: 2.1242764 | AA43: 10.968729 | AB43: 9.5295109 | AC43: 12.124861 | AD43: 34.747377
C44: Industry non energetic uses | D44: Q_Mtep_indus_21_2 | E44: Q_Mtep_indus_22_2 | F44: Q_Mtep_indus_23_2 | G44: Q_Mtep_indus_24_2 | H44: =VLOOKUP(D44,Résultats!$B$2:$AX$476,'T energie vecteurs'!K5,FALSE) -> 0.88382376 | I44: =VLOOKUP(E44,Résultats!$B$2:$AX$476,'T energie vecteurs'!K5,FALSE) -> 1.9147194 | J44: =VLOOKUP(F44,Résultats!$B$2:$AX$476,'T energie vecteurs'!K5,FALSE) -> 0 | K44: =VLOOKUP(G44,Résultats!$B$2:$AX$476,'T energie vecteurs'!K5,FALSE) -> 2.0568753 | L44: =SUM(H44:K44) -> 4.8554184 | N44: Industry non energetic uses | O44: ='[3]Bilan 2022 réel'!$E$52/11.63 -> 3.8690713 | P44: =('[3]Bilan 2022 réel'!$E$54+'[3]Bilan 2022 réel'!$E$56)/11.63 -> 9.270092 | Q44: 0 | R44: =('[3]Bilan 2022 réel'!$E$53+'[3]Bilan 2022 réel'!$E$55+'[3]Bilan 2022 réel'!$E$57)/11.63 -> 0.87235178 | S44: =SUM(O44:R44) -> 14.011515 | U44: Industry non energetic uses | V44: Q_Mtep_indus_21_2 | W44: Q_Mtep_indus_22_2 | X44: Q_Mtep_indus_23_2 | Y44: Q_Mtep_indus_24_2 | Z44: 0.87550951 | AA44: 2.0332827 | AB44: 0 | AC44: 2.138633 | AD44: 5.0474252
C45: Agriculture | D45: ER_AGRICULTURE_coal_2 | E45: ER_AGRICULTURE_oil_2 | F45: ER_AGRICULTURE_elec_2 | G45: ER_AGRICULTURE_gas_2 | H45: =VLOOKUP(D45,Résultats!$B$2:$AX$476,'T energie vecteurs'!K5,FALSE) -> 0 | I45: =VLOOKUP(E45,Résultats!$B$2:$AX$476,'T energie vecteurs'!K5,FALSE) -> 2.4153704 | J45: =VLOOKUP(F45,Résultats!$B$2:$AX$476,'T energie vecteurs'!K5,FALSE) -> 0.3211921 | K45: =VLOOKUP(G45,Résultats!$B$2:$AX$476,'T energie vecteurs'!K5,FALSE) -> 0.3382424 | L45: =SUM(H45:K45) -> 3.0748049 | N45: Agriculture | O45: ='[3]Bilan 2022 réel'!$T$46/11.63 -> 0.001651664 | P45: =SUM('[3]Bilan 2022 réel'!$T$41:$T$43)/11.63 -> 3.5697769 | Q45: ='[3]Bilan 2022 réel'!$T$13/11.63 -> 0.67291488 | R45: =('[3]Bilan 2022 réel'!$T$22+'[3]Bilan 2022 réel'!$T$30+SUM('[3]Bilan 2022 réel'!$T$36:$T$40)+SUM('[3]Bilan 2022 réel'!$T$44:$T$45)+'[3]Bilan 2022 réel'!$T$47)/11.63 -> 0.43996563 | S45: =SUM(O45:R45) -> 4.6843091 | U45: Agriculture | V45: ER_AGRICULTURE_coal_2 | W45: ER_AGRICULTURE_oil_2 | X45: ER_AGRICULTURE_elec_2 | Y45: ER_AGRICULTURE_gas_2 | Z45: 0 | AA45: 2.4335495 | AB45: 0.33754154 | AC45: 0.33453191 | AD45: 3.105623
C46: Total Final Mtep | H46: =SUM(H37,H40:H42) -> 2.8723791 | I46: =SUM(I37,I40:I42) -> 63.87991 | J46: =SUM(J37,J40:J42) -> 39.433226 | K46: =SUM(K37,K40:K42) -> 44.487651 | L46: =SUM(H46:K46) -> 150.67317 | N46: Total Final Mtep | O46: =O37+O40+O41+O42+O45 -> 4.5640555 | P46: =P37+P40+P41+P42+P45 -> 64.295512 | Q46: =Q37+Q40+Q41+Q42+Q45 -> 35.657811 | R46: =R37+R40+R41+R42+R45 -> 42.318046 | S46: =SUM(O46:R46) -> 146.83542 | U46: Total Final Mtep | Z46: 3.2423484 | AA46: 66.523146 | AB46: 38.969008 | AC46: 44.244923 | AD46: 152.97943
C49: 2023 | H49: coal | I49: fuel and biofuel | J49: elec | K49: gas biogas biomass | L49: Total | N49: 2023 | O49: coal | P49: fuel and biofuel | Q49: elec | R49: gas biogas biomass | S49: Total | U49: 2023 | Z49: coal | AA49: fuel and biofuel | AB49: elec | AC49: gas biogas biomass | AD49: Total
...

Sheet T transport
A1: =Résultats!B1 -> SNBC3 | B1: Transport (milliers de km voyageurs) | C1: 2006 | D1: 2007 | E1: 2008 | F1: 2009 | G1: 2010 | H1: 2011 | I1: 2012 | J1: 2013 | K1: 2014 | L1: 2015 | M1: 2016 | N1: 2017 | O1: 2018 | P1: 2019 | Q1: 2020 | R1: 2021 | S1: 2022 | T1: 2023 | U1: 2024 | V1: 2025 | W1: 2026 | X1: 2027 | Y1: 2028 | Z1: 2029 | AA1: 2030 | AB1: 2031 | AC1: 2032 | AD1: 2033 | AE1: 2034 | AF1: 2035 | AG1: 2036 | AH1: 2037 | AI1: 2038 | AJ1: 2039 | AK1: 2040 | AL1: 2041 | AM1: 2042 | AN1: 2043 | AO1: 2044 | AP1: 2045 | AQ1: 2046 | AR1: 2047 | AS1: 2048 | AT1: 2049 | AU1: 2050 | AW1: Part modale hors avion | AX1: 2020 | AY1: 2030 | AZ1: 2050
B2: Total | C2: =C3+C4+C7 -> 842942.38 | D2: =D3+D4+D7 -> 878459.86 | E2: =E3+E4+E7 -> 895073.07 | F2: =F3+F4+F7 -> 922447.58 | G2: =G3+G4+G7 -> 944843.65 | H2: =H3+H4+H7 -> 983088.66 | I2: =I3+I4+I7 -> 1023626.7 | J2: =J3+J4+J7 -> 1068215.3 | ... AU2: =AU3+AU4+AU7 -> 1104711.8 | AW2: voiture CD | AX2: =Q8/Q7 -> 0.92268454 | AY2: =AA8/AA7 -> 0.90656364 | AZ2: =AU8/AU7 -> 0.88156461
B3: Avion (France + RDM) | C3: =Résultats!E286 -> 13442.055 | D3: =Résultats!F286 -> 13710.533 | E3: =Résultats!G286 -> 14052.662 | F3: =Résultats!H286 -> 13551.264 | G3: =Résultats!I286 -> 13076.845 | H3: =Résultats!J286 -> 13351.989 | I3: =Résultats!K286 -> 13561.709 | J3: =Résultats!L286 -> 13434.458 | ... AU3: =Résultats!AW286 -> 7187.3533 | AW3: voiture LD | AX3: =Q5/Q4 -> 0.63445403 | AY3: =AA5/AA4 -> 0.55810148 | AZ3: =AU5/AU4 -> 0.44812277
B4: Longue Distance (LD) | C4: =Résultats!E292 -> 248850.1 | D4: =Résultats!F292 -> 266931.55 | E4: =Résultats!G292 -> 279010.91 | F4: =Résultats!H292 -> 295035.9 | G4: =Résultats!I292 -> 308744.22 | H4: =Résultats!J292 -> 330162.05 | I4: =Résultats!K292 -> 355210.86 | J4: =Résultats!L292 -> 380667.45 | ... P4: =Résultats!R292 -> 431638.33 | Q4: =SUM(Q5:Q6) -> 438896.71 | R4: =SUM(R5:R6) -> 342401.16 | S4: =SUM(S5:S6) -> 344535.47 | T4: =SUM(T5:T6) -> 345336.82 | U4: =SUM(U5:U6) -> 328894.26 | V4: =SUM(V5:V6) -> 316243.43 | W4: =SUM(W5:W6) -> 321491.69 | X4: =SUM(X5:X6) -> 323087.95 | ... AU4: =SUM(AU5:AU6) -> 502556.81 | AW4: voiture CD+LD | AX4: =Q10/(Q7+Q4) -> 0.81444854 | AY4: =AA10/(AA7+AA4) -> 0.76831677 | AZ4: =AU10/(AU7+AU4) -> 0.68309145
B5: voiture LD | C5: =Résultats!E287 -> 163461.3 | D5: =Résultats!F287 -> 173277.53 | E5: =Résultats!G287 -> 180525.77 | F5: =Résultats!H287 -> 188717.15 | G5: =Résultats!I287 -> 196734.65 | H5: =Résultats!J287 -> 206682.56 | I5: =Résultats!K287 -> 222217.52 | J5: =Résultats!L287 -> 238372.94 | ... AU5: =Résultats!AW287 -> 225207.15
B6: train | C6: =Résultats!E290 -> 47168.088 | D6: =Résultats!F290 -> 48543.657 | E6: =Résultats!G290 -> 48452.153 | F6: =Résultats!H290 -> 49450.099 | G6: =Résultats!I290 -> 50052.596 | H6: =Résultats!J290 -> 51514.113 | I6: =Résultats!K290 -> 52007.677 | J6: =Résultats!L290 -> 53048.385 | ... P6: =Résultats!R290 -> 56826.888 | Q6: =Résultats!S289 -> 160436.93 | R6: =Résultats!T290 -> 55747.73 | S6: =Résultats!U290 -> 55771.068 | T6: =Résultats!V290 -> 56044.438 | U6: =Résultats!W290 -> 59372.938 | V6: =Résultats!X290 -> 62088.291 | W6: =Résultats!Y290 -> 62152.601 | X6: =Résultats!Z290 -> 62605.11 | Y6: =Résultats!AA290 -> 63204.69 | Z6: =Résultats!AB290 -> 63929.834 | AA6: =Résultats!AC289 -> 201194.28 | AB6: =Résultats!AD290 -> 64922.776 | AC6: =Résultats!AE290 -> 65198.948 | AD6: =Résultats!AF290 -> 65419.148 | AE6: =Résultats!AG290 -> 65632.654 | AF6: =Résultats!AH290 -> 65831.701 | AG6: =Résultats!AI290 -> 66200.801 | AH6: =Résultats!AJ290 -> 66559.129 | AI6: =Résultats!AK290 -> 66856.547 | ... AT6: =Résultats!AV290 -> 70430.368 | AU6: =Résultats!AW289 -> 277349.66 | BB6: Cibles DGEC
B7: Courte Distance (CD) | C7: =Résultats!E291 -> 580650.23 | D7: =Résultats!F291 -> 597817.78 | E7: =Résultats!G291 -> 602009.49 | F7: =Résultats!H291 -> 613860.42 | G7: =Résultats!I291 -> 623022.58 | H7: =Résultats!J291 -> 639574.62 | I7: =Résultats!K291 -> 654854.1 | J7: =Résultats!L291 -> 674113.35 | ... P7: =Résultats!R291 -> 725082.39 | Q7: =SUM(Q8:Q9) -> 729877.28 | R7: =SUM(R8:R9) -> 833943.9 | S7: =SUM(S8:S9) -> 835476.47 | T7: =SUM(T8:T9) -> 837997.52 | U7: =SUM(U8:U9) -> 841257.07 | V7: =SUM(V8:V9) -> 843027.89 | W7: =SUM(W8:W9) -> 840671.61 | X7: =SUM(X8:X9) -> 838057.52 | ... AU7: =SUM(AU8:AU9) -> 594967.64 | AW7: Avion | AX7: =Q3/Q2 -> 0.012702 | AY7: =AA3/AA2 -> 0.011044989 | AZ7: =AU3/AU2 -> 0.0065060889 | BB7: =[4]Trafic!$H$27/([4]Trafic!$H$30-[4]Trafic!$H$29) -> 0.0096732537 | BC7: =[4]Trafic!$J$27/([4]Trafic!$J$30-[4]Trafic!$J$29) -> 0.014577968 | BD7: =[4]Trafic!$N$27/([4]Trafic!$N$30-[4]Trafic!$N$29) -> 0.0065864877
B8: voiture CD | C8: =Résultats!E288 -> 533482.14 | D8: =Résultats!F288 -> 549274.13 | E8: =Résultats!G288 -> 553559.43 | F8: =Résultats!H288 -> 564412.48 | G8: =Résultats!I288 -> 572972.37 | H8: =Résultats!J288 -> 588063.14 | I8: =Résultats!K288 -> 602854.78 | J8: =Résultats!L288 -> 621076.01 | ... AU8: =Résultats!AW288 -> 524502.42 | AW8: train | AX8: =+Q6/Q2 -> 0.13552582 | AY8: =+AA6/AA2 -> 0.17337991 | AZ8: =+AU6/AU2 -> 0.25106065 | BB8: =[4]Trafic!$H$25/[4]Trafic!$H$31 -> 0.086581999 | BC8: =[4]Trafic!$J$25/[4]Trafic!$J$31 -> 0.14233557 | BD8: =[4]Trafic!$N$25/[4]Trafic!$N$31 -> 0.18954037
B9: bus | C9: =Résultats!E289 -> 85388.793 | D9: =Résultats!F289 -> 93689.859 | E9: =Résultats!G289 -> 98525.392 | F9: =Résultats!H289 -> 106396.98 | G9: =Résultats!I289 -> 112095.42 | H9: =Résultats!J289 -> 123662.94 | I9: =Résultats!K289 -> 133190.83 | J9: =Résultats!L289 -> 142506.46 | ... P9: =Résultats!R289 -> 161701.19 | Q9: =Résultats!S290 -> 56430.796 | R9: =Résultats!T289 -> 158577.18 | S9: =Résultats!U289 -> 158556.69 | T9: =Résultats!V289 -> 159301.99 | U9: =Résultats!W289 -> 172828.14 | V9: =Résultats!X289 -> 184625.13 | W9: =Résultats!Y289 -> 186632.01 | X9: =Résultats!Z289 -> 189620.16 | Y9: =Résultats!AA289 -> 193112.78 | Z9: =Résultats!AB289 -> 197082.15 | AA9: =Résultats!AC290 -> 64687.145 | AB9: =Résultats!AD289 -> 204255.17 | AC9: =Résultats!AE289 -> 207549.28 | AD9: =Résultats!AF289 -> 210839.81 | AE9: =Résultats!AG289 -> 214173.45 | AF9: =Résultats!AH289 -> 217539.82 | AG9: =Résultats!AI289 -> 221137.99 | AH9: =Résultats!AJ289 -> 224842.07 | AI9: =Résultats!AK289 -> 228508.81 | ... AT9: =Résultats!AV289 -> 272909.55 | AU9: =Résultats!AW290 -> 70465.223 | AW9: bus | AX9: =Q9/Q2 -> 0.047668764 | AY9: =AA9/AA2 -> 0.055744383 | AZ9: =AU9/AU2 -> 0.063786069 | BB9: =[4]Trafic!$H$26/[4]Trafic!$H$31 -> 0.050587052 | BC9: =[4]Trafic!$J$26/[4]Trafic!$J$31 -> 0.076007848 | BD9: =[4]Trafic!$N$26/[4]Trafic!$N$31 -> 0.098293993
B10: Voiture CD+LD | C10: =C5+C8 -> 696943.45 | D10: =D5+D8 -> 722551.66 | E10: =E5+E8 -> 734085.2 | F10: =F5+F8 -> 753129.63 | G10: =G5+G8 -> 769707.03 | H10: =H5+H8 -> 794745.7 | I10: =I5+I8 -> 825072.3 | J10: =J5+J8 -> 859448.94 | ... AU10: =AU5+AU8 -> 749709.57 | AW10: route | AX10: =1-SUM(AX7:AX9) -> 0.80410341 | AY10: =1-SUM(AY7:AY9) -> 0.75983072 | AZ10: =1-SUM(AZ7:AZ9) -> 0.67864719 | BB10: =([4]Trafic!$H$23+[4]Trafic!$H$28)/[4]Trafic!$H$30 -> 0.84698145 | BC10: =([4]Trafic!$J$23+[4]Trafic!$J$28)/[4]Trafic!$J$30 -> 0.75252159 | BD10: =([4]Trafic!$N$23+[4]Trafic!$N$28)/[4]Trafic!$N$30 -> 0.68588807
A12: TEND | B12: Transport (milliers de km voyageurs) | C12: 2006 | D12: 2007 | E12: 2008 | F12: 2009 | G12: 2010 | H12: 2011 | I12: 2012 | J12: 2013 | K12: 2014 | L12: 2015 | M12: 2016 | N12: 2017 | O12: 2018 | P12: 2019 | Q12: 2020 | R12: 2021 | S12: 2022 | T12: 2023 | U12: 2024 | V12: 2025 | W12: 2026 | X12: 2027 | Y12: 2028 | Z12: 2029 | AA12: 2030 | AB12: 2031 | AC12: 2032 | AD12: 2033 | AE12: 2034 | AF12: 2035 | AG12: 2036 | AH12: 2037 | AI12: 2038 | AJ12: 2039 | AK12: 2040 | AL12: 2041 | AM12: 2042 | AN12: 2043 | AO12: 2044 | AP12: 2045 | AQ12: 2046 | AR12: 2047 | AS12: 2048 | AT12: 2049 | AU12: 2050 | AW12: Part modale hors avion | AX12: 2020 | AY12: 2030 | AZ12: 2050
B13: Total | C13: =C14+C15+C18 -> 842942.38 | D13: =D14+D15+D18 -> 878459.86 | E13: =E14+E15+E18 -> 895073.07 | F13: =F14+F15+F18 -> 922447.58 | G13: =G14+G15+G18 -> 944843.65 | H13: =H14+H15+H18 -> 983088.66 | I13: =I14+I15+I18 -> 1023626.7 | J13: =J14+J15+J18 -> 1068215.3 | ... AU13: =AU14+AU15+AU18 -> 1322883 | AW13: voiture CD | AX13: =Q19/Q18 -> 0.92272326 | AY13: =AA19/AA18 -> 0.91217426 | AZ13: =AU19/AU18 -> 0.89747798
B14: Avion (France + RDM) | C14: =Résultats!E294 -> 13442.055 | D14: =Résultats!F294 -> 13710.533 | E14: =Résultats!G294 -> 14052.662 | F14: =Résultats!H294 -> 13551.264 | G14: =Résultats!I294 -> 13076.845 | H14: =Résultats!J294 -> 13351.989 | I14: =Résultats!K294 -> 13561.709 | J14: =Résultats!L294 -> 13434.458 | ... AU14: =Résultats!AW294 -> 23522.359 | AW14: voiture LD | AX14: =Q16/Q15 -> 0.63520091 | AY14: =AA16/AA15 -> 0.63970119 | AZ14: =AU16/AU15 -> 0.66883457
