Workbook

Sheet Résultats
A1: 1) Copier-coller sorties Eviews en B2 2) veillez à ce que les données commencent en 2004 3) modifier le scénario si besoin en B1 | B1: TEND | C1: 2 | D1: =C1+1 -> 3 | E1: =D1+1 -> 4 | F1: =E1+1 -> 5 | G1: =F1+1 -> 6 | H1: =G1+1 -> 7 | I1: =H1+1 -> 8 | J1: =I1+1 -> 9 | K1: =J1+1 -> 10 | ... AW1: =AV1+1 -> 48
C2: 2004 | D2: 2005 | E2: 2006 | F2: 2007 | G2: 2008 | H2: 2009 | I2: 2010 | J2: 2011 | K2: 2012 | L2: 2013 | M2: 2014 | N2: 2015 | O2: 2016 | P2: 2017 | Q2: 2018 | R2: 2019 | S2: 2020 | T2: 2021 | U2: 2022 | V2: 2023 | W2: 2024 | X2: 2025 | Y2: 2026 | Z2: 2027 | AA2: 2028 | AB2: 2029 | AC2: 2030 | AD2: 2031 | AE2: 2032 | AF2: 2033 | AG2: 2034 | AH2: 2035 | AI2: 2036 | AJ2: 2037 | AK2: 2038 | AL2: 2039 | AM2: 2040 | AN2: 2041 | AO2: 2042 | AP2: 2043 | AQ2: 2044 | AR2: 2045 | AS2: 2046 | AT2: 2047 | AU2: 2048 | AV2: 2049 | AW2: 2050
B3: ER_OIL_1 | C3: 78.155731 | D3: 79.410547 | E3: 80.671203 | F3: 81.230879 | G3: 78.337043 | H3: 76.35819 | I3: 75.168414 | J3: 73.713688 | K3: 71.891901 | L3: 70.627817 | M3: 70.711585 | N3: 71.498434 | O3: 70.101705 | P3: 68.524865 | Q3: 66.192346 | R3: 64.959362 | S3: 63.373763 | T3: 62.700539 | U3: 61.965191 | V3: 61.382814 | W3: 60.625151 | X3: 59.534732 | Y3: 58.915502 | Z3: 58.538522 | AA3: 58.275218 | AB3: 58.080125 | AC3: 57.959791 | AD3: 57.424112 | AE3: 56.882652 | AF3: 56.3449 | AG3: 55.827497 | AH3: 55.317663 | AI3: 54.931604 | AJ3: 54.577974 | AK3: 54.253462 | AL3: 53.953523 | AM3: 53.670863 | AN3: 53.373499 | AO3: 53.070489 | AP3: 52.761079 | AQ3: 52.459196 | AR3: 52.154721 | AS3: 52.04612 | AT3: 51.962466 | AU3: 51.897643 | AV3: 51.841849 | AW3: 51.814351
B4: ER_OIL_2201_1 | C4: 77.477679 | D4: 78.721608 | E4: 80.003737 | F4: 80.228086 | G4: 77.052367 | H4: 74.797652 | I4: 73.329929 | J4: 71.615586 | K4: 69.558933 | L4: 68.055349 | M4: 67.856364 | N4: 68.329788 | O4: 66.944968 | P4: 65.387163 | Q4: 63.107949 | R4: 61.876354 | S4: 60.30747 | T4: 59.506878 | U4: 58.656049 | V4: 57.958113 | W4: 57.092524 | X4: 55.911926 | Y4: 55.330557 | Z4: 54.976704 | AA4: 54.729621 | AB4: 54.545532 | AC4: 54.431603 | AD4: 53.931458 | AE4: 53.425987 | AF4: 52.924111 | AG4: 52.440997 | AH4: 51.96511 | AI4: 51.601013 | AJ4: 51.267325 | AK4: 50.960929 | AL4: 50.678107 | AM4: 50.411466 | AN4: 50.120482 | AO4: 49.823881 | AP4: 49.520938 | AQ4: 49.224708 | AR4: 48.925668 | AS4: 48.808096 | AT4: 48.71363 | AU4: 48.636507 | AV4: 48.567515 | AW4: 48.524677
B5: ER_OIL_2202_1 | C5: 0.67805251 | D5: 0.68893886 | E5: 0.66746538 | F5: 1.0027933 | G5: 1.284676 | H5: 1.5605372 | I5: 1.8384849 | J5: 2.0981018 | K5: 2.3329679 | L5: 2.5724686 | M5: 2.8552211 | N5: 3.1686457 | O5: 3.1567371 | P5: 3.137703 | Q5: 3.0843969 | R5: 3.0830077 | S5: 3.0662927 | T5: 3.193661 | U5: 3.3091416 | V5: 3.4247007 | W5: 3.5326271 | X5: 3.6228062 | Y5: 3.5849455 | Z5: 3.5618178 | AA5: 3.5455976 | AB5: 3.5345924 | AC5: 3.5281884 | AD5: 3.4926537 | AE5: 3.4566645 | AF5: 3.4207891 | AG5: 3.3864998 | AH5: 3.3525531 | AI5: 3.3305909 | AJ5: 3.3106491 | AK5: 3.2925338 | AL5: 3.2754167 | AM5: 3.2593971 | AN5: 3.2530162 | AO5: 3.2466079 | AP5: 3.2401407 | AQ5: 3.2344887 | AR5: 3.2290526 | AS5: 3.2380242 | AT5: 3.2488358 | AU5: 3.261136 | AV5: 3.2743343 | AW5: 3.2896741
B6: ER_ELEC_2301_1 | C6: 28.634797 | D6: 29.094538 | E6: 29.720949 | F6: 30.551326 | G6: 31.268226 | H6: 29.125055 | I6: 30.256846 | J6: 31.323004 | K6: 31.689898 | L6: 31.571325 | M6: 31.465978 | N6: 30.94722 | O6: 29.332225 | P6: 28.892747 | Q6: 28.821975 | R6: 27.86219 | S6: 26.892231 | T6: 26.743234 | U6: 26.690278 | V6: 26.733146 | W6: 27.649655 | X6: 28.608337 | Y6: 28.696213 | Z6: 28.815891 | AA6: 28.954207 | AB6: 29.177098 | AC6: 29.423354 | AD6: 29.127383 | AE6: 28.834691 | AF6: 28.546026 | AG6: 28.233271 | AH6: 27.927478 | AI6: 27.52731 | AJ6: 27.120949 | AK6: 26.710483 | AL6: 26.265914 | AM6: 25.81385 | AN6: 25.331185 | AO6: 24.841389 | AP6: 24.344859 | AQ6: 23.846982 | AR6: 23.345351 | AS6: 22.720492 | AT6: 22.087837 | AU6: 21.459071 | AV6: 20.826056 | AW6: 20.198802
B7: ER_ELEC_2302_1 | C7: 0.3674935 | D7: 0.37339372 | E7: 0.38143295 | F7: 0.37148643 | G7: 0.36022471 | H7: 0.3179028 | I7: 0.31290219 | J7: 0.30690623 | K7: 0.29418498 | L7: 0.27768333 | M7: 0.26221383 | N7: 0.24433932 | O7: 0.21316768 | P7: 0.19039124 | Q7: 0.16877833 | R7: 0.14095614 | S7: 0.11269292 | T7: 0.14899317 | U7: 0.18674726 | V7: 0.22641642 | W7: 0.23767877 | X7: 0.24915704 | Y7: 0.24838803 | Z7: 0.24787086 | AA7: 0.24748761 | AB7: 0.24780548 | AC7: 0.24829132 | AD7: 0.25379467 | AE7: 0.25931923 | AF7: 0.26487451 | AG7: 0.27064268 | AH7: 0.27648165 | AI7: 0.27604891 | AJ7: 0.27556121 | AK7: 0.27503789 | AL7: 0.27433539 | AM7: 0.27355984 | AN7: 0.27843875 | AO7: 0.28324657 | AP7: 0.28797944 | AQ7: 0.29269482 | AR7: 0.2973601 | AS7: 0.29901274 | AT7: 0.30055516 | AU7: 0.30214051 | AV7: 0.3036549 | AW7: 0.305242
B8: ER_ELEC_2303_1 | C8: 1.4676116 | D8: 1.4911746 | E8: 1.5232799 | F8: 1.5681164 | G8: 1.6072472 | H8: 1.4992616 | I8: 1.5597878 | J8: 1.6170984 | K8: 1.6384195 | L8: 1.6346632 | M8: 1.6315782 | N8: 1.6070135 | O8: 1.7058576 | P8: 1.8745305 | Q8: 2.0796826 | R8: 2.2306383 | S8: 2.3846433 | T8: 2.2924332 | U8: 2.20649 | V8: 2.1258058 | W8: 1.4092509 | X8: 0.72791374 | Y8: 0.7311169 | Z8: 0.73514503 | AA8: 0.73966532 | AB8: 0.74633435 | AC8: 0.75361978 | AD8: 0.76145496 | AE8: 0.76936166 | AF8: 0.77736524 | AG8: 0.78555933 | AH8: 0.79395494 | AI8: 0.80192168 | AJ8: 0.8097471 | AK8: 0.81748337 | AL8: 0.82511211 | AM8: 0.83253403 | AN8: 0.83824612 | AO8: 0.84373774 | AP8: 0.84900456 | AQ8: 0.85422109 | AR8: 0.85929457 | AS8: 1.1800084 | AT8: 1.5000455 | AU8: 1.8199889 | AV8: 2.139174 | AW8: 2.4585472
B9: ER_ELEC_2304_1 | C9: 1.4643634 | D9: 1.4878742 | E9: 1.5199084 | F9: 1.4386712 | G9: 1.3558495 | H9: 1.1629251 | I9: 1.1124625 | J9: 1.0604785 | K9: 0.98795248 | L9: 0.90632667 | M9: 0.83178279 | N9: 0.75329847 | O9: 0.63402697 | P9: 0.53952358 | Q9: 0.44640929 | R9: 0.33517036 | S9: 0.22211801 | T9: 0.21340186 | U9: 0.20526583 | V9: 0.19761444 | W9: 0.12974487 | X9: 0.065199948 | Y9: 0.065463667 | Z9: 0.065800899 | AA9: 0.066181785 | AB9: 0.066754628 | AC9: 0.067382145 | AD9: 0.068065544 | AE9: 0.068755352 | AF9: 0.069453828 | AG9: 0.070168098 | AH9: 0.07090036 | AI9: 0.071608579 | AJ9: 0.072304172 | AK9: 0.072991798 | AL9: 0.073669659 | AM9: 0.074329049 | AN9: 0.074835946 | AO9: 0.075323157 | AP9: 0.075790299 | AQ9: 0.076252952 | AR9: 0.076702837 | AS9: 0.076861242 | AT9: 0.076991525 | AU9: 0.07713306 | AV9: 0.077256765 | AW9: 0.077399242
B10: ER_ELEC_2305_1 | C10: 0.29584764 | D10: 0.30059757 | E10: 0.30706949 | F10: 0.65529597 | G10: 0.99168066 | H10: 1.1960421 | I10: 1.4948095 | J10: 1.7726596 | K10: 1.9787878 | L10: 2.1055701 | M10: 2.1709373 | N10: 2.1314552 | O10: 2.2791746 | P10: 2.5203105 | Q10: 2.8114068 | R10: 3.0298895 | S10: 3.2527421 | T10: 3.4385807 | U10: 3.6418406 | V10: 3.8650468 | W10: 4.2783073 | X10: 4.6863329 | Y10: 5.0325319 | Z10: 5.3893694 | AA10: 5.7554063 | AB10: 6.0315438 | AC10: 6.3169618 | AD10: 6.6954236 | AE10: 7.0742324 | AF10: 7.4537255 | AG10: 7.8509575 | AH10: 8.2503493 | AI10: 8.6623532 | AJ10: 9.0734802 | AK10: 9.484149 | AL10: 9.9082188 | AM10: 10.330246 | AN10: 10.74756 | AO10: 11.162293 | AP10: 11.574114 | AQ10: 11.985198 | AR10: 12.39415 | AS10: 12.771478 | AT10: 13.143863 | AU10: 13.517824 | AV10: 13.888288 | AW10: 14.261761
B11: ER_ELEC_2306_1 | C11: 0.066565719 | D11: 0.067634453 | E11: 0.069090635 | F11: 0.094486438 | G11: 0.12865468 | H11: 0.15943071 | I11: 0.22034936 | J11: 0.30348306 | K11: 0.40848376 | L11: 0.54141422 | M11: 0.7178951 | N11: 0.93934323 | O11: 1.0044439 | P11: 1.1107137 | Q11: 1.2390014 | R11: 1.3352878 | S11: 1.4335001 | T11: 1.4945726 | U11: 1.5627298 | V11: 1.6388236 | W11: 1.7763351 | X11: 1.9131493 | Y11: 2.0675212 | Z11: 2.2264494 | AA11: 2.3893747 | AB11: 2.5608174 | AC11: 2.7372487 | AD11: 3.092749 | AE11: 3.448245 | AF11: 3.8039594 | AG11: 4.1769408 | AH11: 4.5511459 | AI11: 4.9396057 | AJ11: 5.3278713 | AK11: 5.7161134 | AL11: 6.1186653 | AM11: 6.5201422 | AN11: 6.9252124 | AO11: 7.3287167 | AP11: 7.7303318 | AQ11: 8.1314367 | AR11: 8.5310495 | AS11: 8.7395854 | AT11: 8.9447769 | AU11: 9.1510886 | AV11: 9.3550826 | AW11: 9.5611513
B12: ER_ELEC_2307_1 | C12: 3.3276745 | D12: 3.3811014 | E12: 3.4538971 | F12: 3.4253584 | G12: 3.3822713 | H12: 3.0394933 | I12: 3.0464027 | J12: 3.0426801 | K12: 2.9699078 | L12: 2.8545928 | M12: 2.7448702 | N12: 2.6045426 | O12: 2.7850491 | P12: 3.0797063 | Q12: 3.435413 | R12: 3.702389 | S12: 3.9747049 | T12: 4.1820071 | U12: 4.4100339 | V12: 4.6616234 | W12: 4.566256 | X12: 4.4885426 | Y12: 4.5062424 | Z12: 4.5289956 | AA12: 4.5547455 | AB12: 4.5945455 | AC12: 4.6381159 | AD12: 4.6830886 | AE12: 4.728504 | AF12: 4.774517 | AG12: 4.821903 | AH12: 4.8705246 | AI12: 4.9177168 | AJ12: 4.9640391 | AK12: 5.009812 | AL12: 5.0550833 | AM12: 5.0990855 | AN12: 5.1327741 | AO12: 5.1651116 | AP12: 5.1960728 | AQ12: 5.2267264 | AR12: 5.2565052 | AS12: 5.2669325 | AT12: 5.275433 | AU12: 5.284705 | AV12: 5.2927557 | AW12: 5.302093
B13: ER_ELEC_2308_1 | C13: 0.21556469 | D13: 0.21902565 | E13: 0.22374131 | F13: 0.25780654 | G13: 0.29576549 | H13: 0.30881003 | I13: 0.35960744 | J13: 0.41730039 | K13: 0.47324562 | L13: 0.52849264 | M13: 0.59042909 | N13: 0.65092138 | O13: 0.59972683 | P13: 0.57242878 | Q13: 0.55125163 | R13: 0.5121329 | S13: 0.47246286 | T13: 0.4998806 | U13: 0.52984087 | V13: 0.56271577 | W13: 0.75873686 | X13: 0.94851227 | Y13: 0.9929042 | Z13: 1.0390292 | AA13: 1.0865404 | AB13: 1.1367267 | AC13: 1.1886261 | AD13: 1.2101661 | AE13: 1.2318116 | AF13: 1.253606 | AG13: 1.2763515 | AH13: 1.2994287 | AI13: 1.3857641 | AJ13: 1.4719999 | AK13: 1.558194 | AL13: 1.6477091 | AM13: 1.7369097 | AN13: 1.7627103 | AO13: 1.788057 | AP13: 1.8129298 | AQ13: 1.8376932 | AR13: 1.8621439 | AS13: 1.8875679 | AT13: 1.9122847 | AU13: 1.9372599 | AV13: 1.9617644 | AW13: 1.9867231
B14: ER_ELEC_1 | C14: 35.839918 | D14: 36.41534 | E14: 37.199368 | F14: 38.362547 | G14: 39.38992 | H14: 36.808921 | I14: 38.363167 | J14: 39.84361 | K14: 40.44088 | L14: 40.420068 | M14: 40.415684 | N14: 39.878134 | O14: 38.553672 | P14: 38.780352 | Q14: 39.553918 | R14: 39.148654 | S14: 38.745095 | T14: 39.013104 | U14: 39.433227 | V14: 40.011193 | W14: 40.805965 | X14: 41.687144 | Y14: 42.340382 | Z14: 43.048551 | AA14: 43.793608 | AB14: 44.561626 | AC14: 45.3736 | AD14: 45.892126 | AE14: 46.41492 | AF14: 46.943528 | AG14: 47.485794 | AH14: 48.040264 | AI14: 48.582329 | AJ14: 49.115952 | AK14: 49.644265 | AL14: 50.168708 | AM14: 50.680656 | AN14: 51.090962 | AO14: 51.487875 | AP14: 51.871081 | AQ14: 52.251205 | AR14: 52.622557 | AS14: 52.941939 | AT14: 53.241787 | AU14: 53.549211 | AV14: 53.844032 | AW14: 54.151719
... B300: KM_TRAVELER_LD_H01_0 | C300: 241047.76 | D300: 244917.86 | E300: 248850.1 | F300: 262898.28 | G300: 272241.58 | H300: 287790.76 | I300: 299414.87 | J300: 315293.48 | K300: 335053.54 | L300: 357361.83 | M300: 382940.68 | N300: 405801.79 | O300: 397150.76 | P300: 389429.72 | Q300: 380440.77 | R300: 367234.37 | S300: 367295.06 | T300: 369726.25 | U300: 370764.53 | V300: 371535.69 | W300: 371853.41 | X300: 371807.57 | Y300: 372051.41 | Z300: 372710.07 | AA300: 373762.64 | AB300: 374944.13 | AC300: 376224.46 | AD300: 377619.6 | AE300: 379035.48 | AF300: 380428.51 | AG300: 381779.74 | AH300: 383095.71 | AI300: 384359.57 | AJ300: 385593.47 | AK300: 386828.81 | AL300: 388088.06 | AM300: 389387.17 | AN300: 390681.6 | AO300: 392042.84 | AP300: 393477.44 | AQ300: 394983.08 | AR300: 396547.2 | AS300: 398153.67 | AT300: 399798.97 | AU300: 401477.56 | AV300: 403184.8 | AW300: 404934.19

Sheet T energie vecteurs
A1: Energie par vecteur énergétique
A3: Energie primaire (Mtep)
A4: =Résultats!B1 -> TEND
E5: 4 | F5: =E5+9 -> 13 | G5: =F5+3 -> 16 | H5: =G5+1 -> 17 | I5: =H5+1 -> 18 | J5: =I5+1 -> 19 | K5: =J5+1 -> 20 | L5: =K5+1 -> 21 | M5: =L5+1 -> 22 | N5: =M5+1 -> 23 | O5: =N5+1 -> 24 | ... S5: =R5+1 -> 28 | T5: =S5+5 -> 33 | U5: =T5+5 -> 38 | V5: =U5+5 -> 43 | W5: =V5+5 -> 48
E6: 2006 | F6: 2015 | G6: 2018 | H6: 2019 | I6: 2020 | J6: 2021 | K6: 2022 | L6: 2023 | M6: 2024 | N6: 2025 | O6: 2026 | P6: 2027 | Q6: 2028 | R6: 2029 | S6: 2030 | T6: 2035 | U6: 2040 | V6: 2045 | W6: 2050 | Z6: Cf. onglet "G énergie"
B7: Refined petroleum products | C7: Total | E7: =SUM(E8:E9) -> #N/A | F7: =SUM(F8:F9) -> #N/A | G7: =SUM(G8:G9) -> #N/A | H7: =SUM(H8:H9) -> #N/A | I7: =SUM(I8:I9) -> #N/A | J7: =SUM(J8:J9) -> #N/A | K7: =SUM(K8:K9) -> #N/A | L7: =SUM(L8:L9) -> #N/A | ... W7: =SUM(W8:W9) -> #N/A | AA7: 2020 | AB7: 2030 | AC7: 2050
C8: Oil | D8: Q_Mtep_ep_2201_0 | E8: =VLOOKUP($D8,Résultats!$B$2:$AX$476,E$5,FALSE) -> #N/A | F8: =VLOOKUP($D8,Résultats!$B$2:$AX$476,F$5,FALSE) -> #N/A | G8: =VLOOKUP($D8,Résultats!$B$2:$AX$476,G$5,FALSE) -> #N/A | H8: =VLOOKUP($D8,Résultats!$B$2:$AX$476,H$5,FALSE) -> #N/A | I8: =VLOOKUP($D8,Résultats!$B$2:$AX$476,I$5,FALSE) -> #N/A | J8: =VLOOKUP($D8,Résultats!$B$2:$AX$476,J$5,FALSE) -> #N/A | K8: =VLOOKUP($D8,Résultats!$B$2:$AX$476,K$5,FALSE) -> #N/A | L8: =VLOOKUP($D8,Résultats!$B$2:$AX$476,L$5,FALSE) -> #N/A | ... W8: =VLOOKUP($D8,Résultats!$B$2:$AX$476,W$5,FALSE) -> #N/A | Z8: Energie primaire | AA8: =I27 -> #N/A | AB8: =S27 -> #N/A | AC8: =W27 -> #N/A
C9: Biofuels | D9: Q_Mtep_ep_2202_0 | E9: =VLOOKUP($D9,Résultats!$B$2:$AX$476,E$5,FALSE) -> #N/A | F9: =VLOOKUP($D9,Résultats!$B$2:$AX$476,F$5,FALSE) -> #N/A | G9: =VLOOKUP($D9,Résultats!$B$2:$AX$476,G$5,FALSE) -> #N/A | H9: =VLOOKUP($D9,Résultats!$B$2:$AX$476,H$5,FALSE) -> #N/A | I9: =VLOOKUP($D9,Résultats!$B$2:$AX$476,I$5,FALSE) -> #N/A | J9: =VLOOKUP($D9,Résultats!$B$2:$AX$476,J$5,FALSE) -> #N/A | K9: =VLOOKUP($D9,Résultats!$B$2:$AX$476,K$5,FALSE) -> #N/A | L9: =VLOOKUP($D9,Résultats!$B$2:$AX$476,L$5,FALSE) -> #N/A | ... W9: =VLOOKUP($D9,Résultats!$B$2:$AX$476,W$5,FALSE) -> #N/A
B10: Electric power generation, transmission and distribution | C10: Total | E10: =SUM(E11:E18) -> #N/A | F10: =SUM(F11:F18) -> #N/A | G10: =SUM(G11:G18) -> #N/A | H10: =SUM(H11:H18) -> #N/A | I10: =SUM(I11:I18) -> #N/A | J10: =SUM(J11:J18) -> #N/A | K10: =SUM(K11:K18) -> #N/A | L10: =SUM(L11:L18) -> #N/A | ... W10: =SUM(W11:W18) -> #N/A
C11: Nuclear | D11: Q_Mtep_ep_2301_0 | E11: =VLOOKUP($D11,Résultats!$B$2:$AX$476,E$5,FALSE) -> #N/A | F11: =VLOOKUP($D11,Résultats!$B$2:$AX$476,F$5,FALSE) -> #N/A | G11: =VLOOKUP($D11,Résultats!$B$2:$AX$476,G$5,FALSE) -> #N/A | H11: =VLOOKUP($D11,Résultats!$B$2:$AX$476,H$5,FALSE) -> #N/A | I11: =VLOOKUP($D11,Résultats!$B$2:$AX$476,I$5,FALSE) -> #N/A | J11: =VLOOKUP($D11,Résultats!$B$2:$AX$476,J$5,FALSE) -> #N/A | K11: =VLOOKUP($D11,Résultats!$B$2:$AX$476,K$5,FALSE) -> #N/A | L11: =VLOOKUP($D11,Résultats!$B$2:$AX$476,L$5,FALSE) -> #N/A | ... W11: =VLOOKUP($D11,Résultats!$B$2:$AX$476,W$5,FALSE) -> #N/A
C12: Fuel | D12: Q_Mtep_ep_2302_0 | E12: =VLOOKUP($D12,Résultats!$B$2:$AX$476,E$5,FALSE) -> #N/A | F12: =VLOOKUP($D12,Résultats!$B$2:$AX$476,F$5,FALSE) -> #N/A | G12: =VLOOKUP($D12,Résultats!$B$2:$AX$476,G$5,FALSE) -> #N/A | H12: =VLOOKUP($D12,Résultats!$B$2:$AX$476,H$5,FALSE) -> #N/A | I12: =VLOOKUP($D12,Résultats!$B$2:$AX$476,I$5,FALSE) -> #N/A | J12: =VLOOKUP($D12,Résultats!$B$2:$AX$476,J$5,FALSE) -> #N/A | K12: =VLOOKUP($D12,Résultats!$B$2:$AX$476,K$5,FALSE) -> #N/A | L12: =VLOOKUP($D12,Résultats!$B$2:$AX$476,L$5,FALSE) -> #N/A | ... W12: =VLOOKUP($D12,Résultats!$B$2:$AX$476,W$5,FALSE) -> #N/A
C13: Combined gas | D13: Q_Mtep_ep_2303_0 | E13: =VLOOKUP($D13,Résultats!$B$2:$AX$476,E$5,FALSE) -> #N/A | F13: =VLOOKUP($D13,Résultats!$B$2:$AX$476,F$5,FALSE) -> #N/A | G13: =VLOOKUP($D13,Résultats!$B$2:$AX$476,G$5,FALSE) -> #N/A | H13: =VLOOKUP($D13,Résultats!$B$2:$AX$476,H$5,FALSE) -> #N/A | I13: =VLOOKUP($D13,Résultats!$B$2:$AX$476,I$5,FALSE) -> #N/A | J13: =VLOOKUP($D13,Résultats!$B$2:$AX$476,J$5,FALSE) -> #N/A | K13: =VLOOKUP($D13,Résultats!$B$2:$AX$476,K$5,FALSE) -> #N/A | L13: =VLOOKUP($D13,Résultats!$B$2:$AX$476,L$5,FALSE) -> #N/A | ... W13: =VLOOKUP($D13,Résultats!$B$2:$AX$476,W$5,FALSE) -> #N/A
C14: Coal | D14: Q_Mtep_ep_2304_0 | E14: =VLOOKUP($D14,Résultats!$B$2:$AX$476,E$5,FALSE) -> #N/A | F14: =VLOOKUP($D14,Résultats!$B$2:$AX$476,F$5,FALSE) -> #N/A | G14: =VLOOKUP($D14,Résultats!$B$2:$AX$476,G$5,FALSE) -> #N/A | H14: =VLOOKUP($D14,Résultats!$B$2:$AX$476,H$5,FALSE) -> #N/A | I14: =VLOOKUP($D14,Résultats!$B$2:$AX$476,I$5,FALSE) -> #N/A | J14: =VLOOKUP($D14,Résultats!$B$2:$AX$476,J$5,FALSE) -> #N/A | K14: =VLOOKUP($D14,Résultats!$B$2:$AX$476,K$5,FALSE) -> #N/A | L14: =VLOOKUP($D14,Résultats!$B$2:$AX$476,L$5,FALSE) -> #N/A | ... W14: =VLOOKUP($D14,Résultats!$B$2:$AX$476,W$5,FALSE) -> #N/A
C15: Wind | D15: Q_Mtep_ep_2305_0 | E15: =VLOOKUP($D15,Résultats!$B$2:$AX$476,E$5,FALSE) -> #N/A | F15: =VLOOKUP($D15,Résultats!$B$2:$AX$476,F$5,FALSE) -> #N/A | G15: =VLOOKUP($D15,Résultats!$B$2:$AX$476,G$5,FALSE) -> #N/A | H15: =VLOOKUP($D15,Résultats!$B$2:$AX$476,H$5,FALSE) -> #N/A | I15: =VLOOKUP($D15,Résultats!$B$2:$AX$476,I$5,FALSE) -> #N/A | J15: =VLOOKUP($D15,Résultats!$B$2:$AX$476,J$5,FALSE) -> #N/A | K15: =VLOOKUP($D15,Résultats!$B$2:$AX$476,K$5,FALSE) -> #N/A | L15: =VLOOKUP($D15,Résultats!$B$2:$AX$476,L$5,FALSE) -> #N/A | ... W15: =VLOOKUP($D15,Résultats!$B$2:$AX$476,W$5,FALSE) -> #N/A
C16: Solar | D16: Q_Mtep_ep_2306_0 | E16: =VLOOKUP($D16,Résultats!$B$2:$AX$476,E$5,FALSE) -> #N/A | F16: =VLOOKUP($D16,Résultats!$B$2:$AX$476,F$5,FALSE) -> #N/A | G16: =VLOOKUP($D16,Résultats!$B$2:$AX$476,G$5,FALSE) -> #N/A | H16: =VLOOKUP($D16,Résultats!$B$2:$AX$476,H$5,FALSE) -> #N/A | I16: =VLOOKUP($D16,Résultats!$B$2:$AX$476,I$5,FALSE) -> #N/A | J16: =VLOOKUP($D16,Résultats!$B$2:$AX$476,J$5,FALSE) -> #N/A | K16: =VLOOKUP($D16,Résultats!$B$2:$AX$476,K$5,FALSE) -> #N/A | L16: =VLOOKUP($D16,Résultats!$B$2:$AX$476,L$5,FALSE) -> #N/A | ... W16: =VLOOKUP($D16,Résultats!$B$2:$AX$476,W$5,FALSE) -> #N/A
C17: Hydraulic | D17: Q_Mtep_ep_2307_0 | E17: =VLOOKUP($D17,Résultats!$B$2:$AX$476,E$5,FALSE) -> #N/A | F17: =VLOOKUP($D17,Résultats!$B$2:$AX$476,F$5,FALSE) -> #N/A | G17: =VLOOKUP($D17,Résultats!$B$2:$AX$476,G$5,FALSE) -> #N/A | H17: =VLOOKUP($D17,Résultats!$B$2:$AX$476,H$5,FALSE) -> #N/A | I17: =VLOOKUP($D17,Résultats!$B$2:$AX$476,I$5,FALSE) -> #N/A | J17: =VLOOKUP($D17,Résultats!$B$2:$AX$476,J$5,FALSE) -> #N/A | K17: =VLOOKUP($D17,Résultats!$B$2:$AX$476,K$5,FALSE) -> #N/A | L17: =VLOOKUP($D17,Résultats!$B$2:$AX$476,L$5,FALSE) -> #N/A | ... W17: =VLOOKUP($D17,Résultats!$B$2:$AX$476,W$5,FALSE) -> #N/A
C18: Cogeneration (CHP) | D18: Q_Mtep_ep_2308_0 | E18: =VLOOKUP($D18,Résultats!$B$2:$AX$476,E$5,FALSE) -> #N/A | F18: =VLOOKUP($D18,Résultats!$B$2:$AX$476,F$5,FALSE) -> #N/A | G18: =VLOOKUP($D18,Résultats!$B$2:$AX$476,G$5,FALSE) -> #N/A | H18: =VLOOKUP($D18,Résultats!$B$2:$AX$476,H$5,FALSE) -> #N/A | I18: =VLOOKUP($D18,Résultats!$B$2:$AX$476,I$5,FALSE) -> #N/A | J18: =VLOOKUP($D18,Résultats!$B$2:$AX$476,J$5,FALSE) -> #N/A | K18: =VLOOKUP($D18,Résultats!$B$2:$AX$476,K$5,FALSE) -> #N/A | L18: =VLOOKUP($D18,Résultats!$B$2:$AX$476,L$5,FALSE) -> #N/A | ... W18: =VLOOKUP($D18,Résultats!$B$2:$AX$476,W$5,FALSE) -> #N/A
B19: Gas and heat | C19: Total | E19: =SUM(E20:E25) -> #N/A | F19: =SUM(F20:F25) -> #N/A | G19: =SUM(G20:G25) -> #N/A | H19: =SUM(H20:H25) -> #N/A | I19: =SUM(I20:I25) -> #N/A | J19: =SUM(J20:J25) -> #N/A | K19: =SUM(K20:K25) -> #N/A | L19: =SUM(L20:L25) -> #N/A | ... W19: =SUM(W20:W25) -> #N/A
C20: Natural gas | D20: Q_Mtep_ep_2401_0 | E20: =VLOOKUP($D20,Résultats!$B$2:$AX$476,E$5,FALSE) -> #N/A | F20: =VLOOKUP($D20,Résultats!$B$2:$AX$476,F$5,FALSE) -> #N/A | G20: =VLOOKUP($D20,Résultats!$B$2:$AX$476,G$5,FALSE) -> #N/A | H20: =VLOOKUP($D20,Résultats!$B$2:$AX$476,H$5,FALSE) -> #N/A | I20: =VLOOKUP($D20,Résultats!$B$2:$AX$476,I$5,FALSE) -> #N/A | J20: =VLOOKUP($D20,Résultats!$B$2:$AX$476,J$5,FALSE) -> #N/A | K20: =VLOOKUP($D20,Résultats!$B$2:$AX$476,K$5,FALSE) -> #N/A | L20: =VLOOKUP($D20,Résultats!$B$2:$AX$476,L$5,FALSE) -> #N/A | ... W20: =VLOOKUP($D20,Résultats!$B$2:$AX$476,W$5,FALSE) -> #N/A
C21: Wood | D21: Q_Mtep_ep_2402_0 | E21: =VLOOKUP($D21,Résultats!$B$2:$AX$476,E$5,FALSE) -> #N/A | F21: =VLOOKUP($D21,Résultats!$B$2:$AX$476,F$5,FALSE) -> #N/A | G21: =VLOOKUP($D21,Résultats!$B$2:$AX$476,G$5,FALSE) -> #N/A | H21: =VLOOKUP($D21,Résultats!$B$2:$AX$476,H$5,FALSE) -> #N/A | I21: =VLOOKUP($D21,Résultats!$B$2:$AX$476,I$5,FALSE) -> #N/A | J21: =VLOOKUP($D21,Résultats!$B$2:$AX$476,J$5,FALSE) -> #N/A | K21: =VLOOKUP($D21,Résultats!$B$2:$AX$476,K$5,FALSE) -> #N/A | L21: =VLOOKUP($D21,Résultats!$B$2:$AX$476,L$5,FALSE) -> #N/A | ... W21: =VLOOKUP($D21,Résultats!$B$2:$AX$476,W$5,FALSE) -> #N/A
C22: Biogas | D22: Q_Mtep_ep_2403_0 | E22: =VLOOKUP($D22,Résultats!$B$2:$AX$476,E$5,FALSE) -> #N/A | F22: =VLOOKUP($D22,Résultats!$B$2:$AX$476,F$5,FALSE) -> #N/A | G22: =VLOOKUP($D22,Résultats!$B$2:$AX$476,G$5,FALSE) -> #N/A | H22: =VLOOKUP($D22,Résultats!$B$2:$AX$476,H$5,FALSE) -> #N/A | I22: =VLOOKUP($D22,Résultats!$B$2:$AX$476,I$5,FALSE) -> #N/A | J22: =VLOOKUP($D22,Résultats!$B$2:$AX$476,J$5,FALSE) -> #N/A | K22: =VLOOKUP($D22,Résultats!$B$2:$AX$476,K$5,FALSE) -> #N/A | L22: =VLOOKUP($D22,Résultats!$B$2:$AX$476,L$5,FALSE) -> #N/A | ... W22: =VLOOKUP($D22,Résultats!$B$2:$AX$476,W$5,FALSE) -> #N/A
C23: Waste incineration | D23: Q_Mtep_ep_2404_0 | E23: =VLOOKUP($D23,Résultats!$B$2:$AX$476,E$5,FALSE) -> #N/A | F23: =VLOOKUP($D23,Résultats!$B$2:$AX$476,F$5,FALSE) -> #N/A | G23: =VLOOKUP($D23,Résultats!$B$2:$AX$476,G$5,FALSE) -> #N/A | H23: =VLOOKUP($D23,Résultats!$B$2:$AX$476,H$5,FALSE) -> #N/A | I23: =VLOOKUP($D23,Résultats!$B$2:$AX$476,I$5,FALSE) -> #N/A | J23: =VLOOKUP($D23,Résultats!$B$2:$AX$476,J$5,FALSE) -> #N/A | K23: =VLOOKUP($D23,Résultats!$B$2:$AX$476,K$5,FALSE) -> #N/A | L23: =VLOOKUP($D23,Résultats!$B$2:$AX$476,L$5,FALSE) -> #N/A | ... W23: =VLOOKUP($D23,Résultats!$B$2:$AX$476,W$5,FALSE) -> #N/A
C24: Geothermal | D24: Q_Mtep_ep_2405_0 | E24: =VLOOKUP($D24,Résultats!$B$2:$AX$476,E$5,FALSE) -> #N/A | F24: =VLOOKUP($D24,Résultats!$B$2:$AX$476,F$5,FALSE) -> #N/A | G24: =VLOOKUP($D24,Résultats!$B$2:$AX$476,G$5,FALSE) -> #N/A | H24: =VLOOKUP($D24,Résultats!$B$2:$AX$476,H$5,FALSE) -> #N/A | I24: =VLOOKUP($D24,Résultats!$B$2:$AX$476,I$5,FALSE) -> #N/A | J24: =VLOOKUP($D24,Résultats!$B$2:$AX$476,J$5,FALSE) -> #N/A | K24: =VLOOKUP($D24,Résultats!$B$2:$AX$476,K$5,FALSE) -> #N/A | L24: =VLOOKUP($D24,Résultats!$B$2:$AX$476,L$5,FALSE) -> #N/A | ... W24: =VLOOKUP($D24,Résultats!$B$2:$AX$476,W$5,FALSE) -> #N/A
C25: Cogeneration (CHP) | D25: Q_Mtep_ep_2406_0 | E25: =VLOOKUP($D25,Résultats!$B$2:$AX$476,E$5,FALSE) -> #N/A | F25: =VLOOKUP($D25,Résultats!$B$2:$AX$476,F$5,FALSE) -> #N/A | G25: =VLOOKUP($D25,Résultats!$B$2:$AX$476,G$5,FALSE) -> #N/A | H25: =VLOOKUP($D25,Résultats!$B$2:$AX$476,H$5,FALSE) -> #N/A | I25: =VLOOKUP($D25,Résultats!$B$2:$AX$476,I$5,FALSE) -> #N/A | J25: =VLOOKUP($D25,Résultats!$B$2:$AX$476,J$5,FALSE) -> #N/A | K25: =VLOOKUP($D25,Résultats!$B$2:$AX$476,K$5,FALSE) -> #N/A | L25: =VLOOKUP($D25,Résultats!$B$2:$AX$476,L$5,FALSE) -> #N/A | ... W25: =VLOOKUP($D25,Résultats!$B$2:$AX$476,W$5,FALSE) -> #N/A
B26: Coal | D26: Q_Mtep_ep_21_0 | E26: =VLOOKUP($D26,Résultats!$B$2:$AX$476,E$5,FALSE) -> #N/A | F26: =VLOOKUP($D26,Résultats!$B$2:$AX$476,F$5,FALSE) -> #N/A | G26: =VLOOKUP($D26,Résultats!$B$2:$AX$476,G$5,FALSE) -> #N/A | H26: =VLOOKUP($D26,Résultats!$B$2:$AX$476,H$5,FALSE) -> #N/A | I26: =VLOOKUP($D26,Résultats!$B$2:$AX$476,I$5,FALSE) -> #N/A | J26: =VLOOKUP($D26,Résultats!$B$2:$AX$476,J$5,FALSE) -> #N/A | K26: =VLOOKUP($D26,Résultats!$B$2:$AX$476,K$5,FALSE) -> #N/A | L26: =VLOOKUP($D26,Résultats!$B$2:$AX$476,L$5,FALSE) -> #N/A | ... W26: =VLOOKUP($D26,Résultats!$B$2:$AX$476,W$5,FALSE) -> #N/A
B27: Total | E27: =E26+E19+E10+E7 -> #N/A | F27: =F26+F19+F10+F7 -> #N/A | G27: =G26+G19+G10+G7 -> #N/A | H27: =H26+H19+H10+H7 -> #N/A | I27: =I26+I19+I10+I7 -> #N/A | J27: =J26+J19+J10+J7 -> #N/A | K27: =K26+K19+K10+K7 -> #N/A | L27: =L26+L19+L10+L7 -> #N/A | ... W27: =W26+W19+W10+W7 -> #N/A
A30: Energie finale (Mtep)
A31: =Résultats!B1 -> TEND | Z31: Cf. onglet "G mix elec" | AE31: Cf. onglet "G mix carb" | AJ31: Cf. onglet "G mix gaz"
E32: 2006 | F32: 2015 | G32: 2018 | H32: 2019 | I32: 2020 | J32: 2021 | K32: 2022 | L32: 2023 | M32: 2024 | N32: 2025 | O32: 2026 | P32: 2027 | Q32: 2028 | R32: 2029 | S32: 2030 | T32: 2035 | U32: 2040 | V32: 2045 | W32: 2050 | AA32: 2020 | AB32: 2030 | AC32: 2050 | AF32: 2020 | AG32: 2030 | AH32: 2050 | AK32: 2020 | AL32: 2030 | AM32: 2050
B33: Refined petroleum products | C33: Total | D33: ER_Oil_0 | E33: =SUM(E34:E35) -> #N/A | F33: =SUM(F34:F35) -> #N/A | G33: =SUM(G34:G35) -> #N/A | H33: =SUM(H34:H35) -> #N/A | I33: =SUM(I34:I35) -> #N/A | J33: =SUM(J34:J35) -> #N/A | K33: =SUM(K34:K35) -> #N/A | L33: =SUM(L34:L35) -> #N/A | ... W33: =SUM(W34:W35) -> #N/A | Z33: charbon | AA33: =(I38+I40)/I36 -> #N/A | AB33: =(S38+S40)/S36 -> #N/A | AC33: =(W38+W40)/W36 -> #N/A | AE33: carburants fossiles | AF33: =I34/I33 -> #N/A | AG33: =S34/S33 -> #N/A | AH33: =W34/W33 -> #N/A | AJ33: gaz naturel | AK33: =I46/(I46+I48) -> #N/A | AL33: =S46/(S46+S48) -> #N/A | AM33: =W46/(W46+W48) -> #N/A
C34: Oil | D34: ER_oil_2201_0 | E34: =VLOOKUP($D34,Résultats!$B$2:$AX$476,E$5,FALSE) -> #N/A | F34: =VLOOKUP($D34,Résultats!$B$2:$AX$476,F$5,FALSE) -> #N/A | G34: =VLOOKUP($D34,Résultats!$B$2:$AX$476,G$5,FALSE) -> #N/A | H34: =VLOOKUP($D34,Résultats!$B$2:$AX$476,H$5,FALSE) -> #N/A | I34: =VLOOKUP($D34,Résultats!$B$2:$AX$476,I$5,FALSE) -> #N/A | J34: =VLOOKUP($D34,Résultats!$B$2:$AX$476,J$5,FALSE) -> #N/A | K34: =VLOOKUP($D34,Résultats!$B$2:$AX$476,K$5,FALSE) -> #N/A | L34: =VLOOKUP($D34,Résultats!$B$2:$AX$476,L$5,FALSE) -> #N/A | ... W34: =VLOOKUP($D34,Résultats!$B$2:$AX$476,W$5,FALSE) -> #N/A | Z34: nucléaire | AA34: =I37/I36 -> #N/A | AB34: =S37/S36 -> #N/A | AC34: =W37/W36 -> #N/A | AE34: biocarburants | AF34: =I35/I33 -> #N/A | AG34: =S35/S33 -> #N/A | AH34: =W35/W33 -> #N/A | AJ34: biogaz | AK34: =I48/(I46+I48) -> #N/A | AL34: =S48/(S46+S48) -> #N/A | AM34: =W48/(W46+W48) -> #N/A
C35: Biofuels | D35: ER_oil_2202_0 | E35: =VLOOKUP($D35,Résultats!$B$2:$AX$476,E$5,FALSE) -> #N/A | F35: =VLOOKUP($D35,Résultats!$B$2:$AX$476,F$5,FALSE) -> #N/A | G35: =VLOOKUP($D35,Résultats!$B$2:$AX$476,G$5,FALSE) -> #N/A | H35: =VLOOKUP($D35,Résultats!$B$2:$AX$476,H$5,FALSE) -> #N/A | I35: =VLOOKUP($D35,Résultats!$B$2:$AX$476,I$5,FALSE) -> #N/A | J35: =VLOOKUP($D35,Résultats!$B$2:$AX$476,J$5,FALSE) -> #N/A | K35: =VLOOKUP($D35,Résultats!$B$2:$AX$476,K$5,FALSE) -> #N/A | L35: =VLOOKUP($D35,Résultats!$B$2:$AX$476,L$5,FALSE) -> #N/A | ... W35: =VLOOKUP($D35,Résultats!$B$2:$AX$476,W$5,FALSE) -> #N/A | Z35: hydraulique | AA35: =I43/I36 -> #N/A | AB35: =S43/S36 -> #N/A | AC35: =W43/W36 -> #N/A | AE35: Total | AF35: =SUM(AF33:AF34) -> #N/A | AG35: =SUM(AG33:AG34) -> #N/A | AH35: =SUM(AH33:AH34) -> #N/A | AJ35: Total | AK35: =SUM(AK33:AK34) -> #N/A | AL35: =SUM(AL33:AL34) -> #N/A | AM35: =SUM(AM33:AM34) -> #N/A
B36: Electric power generation, transmission and distribution | C36: Total | D36: ER_elec_0 | E36: =SUM(E37:E44) -> #N/A | F36: =SUM(F37:F44) -> #N/A | G36: =SUM(G37:G44) -> #N/A | H36: =SUM(H37:H44) -> #N/A | I36: =SUM(I37:I44) -> #N/A | J36: =SUM(J37:J44) -> #N/A | K36: =SUM(K37:K44) -> #N/A | L36: =SUM(L37:L44) -> #N/A | ... W36: =SUM(W37:W44) -> #N/A | Z36: solaire | AA36: =I42/I36 -> #N/A | AB36: =S42/S36 -> #N/A | AC36: =W42/W36 -> #N/A
C37: Nuclear | D37: ER_Elec_2301_0 | E37: =VLOOKUP($D37,Résultats!$B$2:$AX$476,E$5,FALSE) -> #N/A | F37: =VLOOKUP($D37,Résultats!$B$2:$AX$476,F$5,FALSE) -> #N/A | G37: =VLOOKUP($D37,Résultats!$B$2:$AX$476,G$5,FALSE) -> #N/A | H37: =VLOOKUP($D37,Résultats!$B$2:$AX$476,H$5,FALSE) -> #N/A | I37: =VLOOKUP($D37,Résultats!$B$2:$AX$476,I$5,FALSE) -> #N/A | J37: =VLOOKUP($D37,Résultats!$B$2:$AX$476,J$5,FALSE) -> #N/A | K37: =VLOOKUP($D37,Résultats!$B$2:$AX$476,K$5,FALSE) -> #N/A | L37: =VLOOKUP($D37,Résultats!$B$2:$AX$476,L$5,FALSE) -> #N/A | ... W37: =VLOOKUP($D37,Résultats!$B$2:$AX$476,W$5,FALSE) -> #N/A | Z37: éolien | AA37: =I41/I36 -> #N/A | AB37: =S41/S36 -> #N/A | AC37: =W41/W36 -> #N/A
C38: Fuel | D38: ER_elec_2302_0 | E38: =VLOOKUP($D38,Résultats!$B$2:$AX$476,E$5,FALSE) -> #N/A | F38: =VLOOKUP($D38,Résultats!$B$2:$AX$476,F$5,FALSE) -> #N/A | G38: =VLOOKUP($D38,Résultats!$B$2:$AX$476,G$5,FALSE) -> #N/A | H38: =VLOOKUP($D38,Résultats!$B$2:$AX$476,H$5,FALSE) -> #N/A | I38: =VLOOKUP($D38,Résultats!$B$2:$AX$476,I$5,FALSE) -> #N/A | J38: =VLOOKUP($D38,Résultats!$B$2:$AX$476,J$5,FALSE) -> #N/A | K38: =VLOOKUP($D38,Résultats!$B$2:$AX$476,K$5,FALSE) -> #N/A | L38: =VLOOKUP($D38,Résultats!$B$2:$AX$476,L$5,FALSE) -> #N/A | ... W38: =VLOOKUP($D38,Résultats!$B$2:$AX$476,W$5,FALSE) -> #N/A | Z38: autres renouvelables | AA38: =(I39+I44)/I36 -> #N/A | AB38: =(S39+S44)/S36 -> #N/A | AC38: =(W39+W44)/W36 -> #N/A
C39: Combined gas | D39: ER_Elec_2303_0 | E39: =VLOOKUP($D39,Résultats!$B$2:$AX$476,E$5,FALSE) -> #N/A | F39: =VLOOKUP($D39,Résultats!$B$2:$AX$476,F$5,FALSE) -> #N/A | G39: =VLOOKUP($D39,Résultats!$B$2:$AX$476,G$5,FALSE) -> #N/A | H39: =VLOOKUP($D39,Résultats!$B$2:$AX$476,H$5,FALSE) -> #N/A | I39: =VLOOKUP($D39,Résultats!$B$2:$AX$476,I$5,FALSE) -> #N/A | J39: =VLOOKUP($D39,Résultats!$B$2:$AX$476,J$5,FALSE) -> #N/A | K39: =VLOOKUP($D39,Résultats!$B$2:$AX$476,K$5,FALSE) -> #N/A | L39: =VLOOKUP($D39,Résultats!$B$2:$AX$476,L$5,FALSE) -> #N/A | ... W39: =VLOOKUP($D39,Résultats!$B$2:$AX$476,W$5,FALSE) -> #N/A | Z39: Total | AA39: =SUM(AA33:AA38) -> #N/A | AB39: =SUM(AB33:AB38) -> #N/A | AC39: =SUM(AC33:AC38) -> #N/A
C40: Coal | D40: ER_elec_2304_0 | E40: =VLOOKUP($D40,Résultats!$B$2:$AX$476,E$5,FALSE) -> #N/A | F40: =VLOOKUP($D40,Résultats!$B$2:$AX$476,F$5,FALSE) -> #N/A | G40: =VLOOKUP($D40,Résultats!$B$2:$AX$476,G$5,FALSE) -> #N/A | H40: =VLOOKUP($D40,Résultats!$B$2:$AX$476,H$5,FALSE) -> #N/A | I40: =VLOOKUP($D40,Résultats!$B$2:$AX$476,I$5,FALSE) -> #N/A | J40: =VLOOKUP($D40,Résultats!$B$2:$AX$476,J$5,FALSE) -> #N/A | K40: =VLOOKUP($D40,Résultats!$B$2:$AX$476,K$5,FALSE) -> #N/A | L40: =VLOOKUP($D40,Résultats!$B$2:$AX$476,L$5,FALSE) -> #N/A | ... W40: =VLOOKUP($D40,Résultats!$B$2:$AX$476,W$5,FALSE) -> #N/A
C41: Wind | D41: ER_Elec_2305_0 | E41: =VLOOKUP($D41,Résultats!$B$2:$AX$476,E$5,FALSE) -> #N/A | F41: =VLOOKUP($D41,Résultats!$B$2:$AX$476,F$5,FALSE) -> #N/A | G41: =VLOOKUP($D41,Résultats!$B$2:$AX$476,G$5,FALSE) -> #N/A | H41: =VLOOKUP($D41,Résultats!$B$2:$AX$476,H$5,FALSE) -> #N/A | I41: =VLOOKUP($D41,Résultats!$B$2:$AX$476,I$5,FALSE) -> #N/A | J41: =VLOOKUP($D41,Résultats!$B$2:$AX$476,J$5,FALSE) -> #N/A | K41: =VLOOKUP($D41,Résultats!$B$2:$AX$476,K$5,FALSE) -> #N/A | L41: =VLOOKUP($D41,Résultats!$B$2:$AX$476,L$5,FALSE) -> #N/A | ... W41: =VLOOKUP($D41,Résultats!$B$2:$AX$476,W$5,FALSE) -> #N/A
C42: Solar | D42: ER_elec_2306_0 | E42: =VLOOKUP($D42,Résultats!$B$2:$AX$476,E$5,FALSE) -> #N/A | F42: =VLOOKUP($D42,Résultats!$B$2:$AX$476,F$5,FALSE) -> #N/A | G42: =VLOOKUP($D42,Résultats!$B$2:$AX$476,G$5,FALSE) -> #N/A | H42: =VLOOKUP($D42,Résultats!$B$2:$AX$476,H$5,FALSE) -> #N/A | I42: =VLOOKUP($D42,Résultats!$B$2:$AX$476,I$5,FALSE) -> #N/A | J42: =VLOOKUP($D42,Résultats!$B$2:$AX$476,J$5,FALSE) -> #N/A | K42: =VLOOKUP($D42,Résultats!$B$2:$AX$476,K$5,FALSE) -> #N/A | L42: =VLOOKUP($D42,Résultats!$B$2:$AX$476,L$5,FALSE) -> #N/A | ... W42: =VLOOKUP($D42,Résultats!$B$2:$AX$476,W$5,FALSE) -> #N/A
C43: Hydraulic | D43: ER_Elec_2307_0 | E43: =VLOOKUP($D43,Résultats!$B$2:$AX$476,E$5,FALSE) -> #N/A | F43: =VLOOKUP($D43,Résultats!$B$2:$AX$476,F$5,FALSE) -> #N/A | G43: =VLOOKUP($D43,Résultats!$B$2:$AX$476,G$5,FALSE) -> #N/A | H43: =VLOOKUP($D43,Résultats!$B$2:$AX$476,H$5,FALSE) -> #N/A | I43: =VLOOKUP($D43,Résultats!$B$2:$AX$476,I$5,FALSE) -> #N/A | J43: =VLOOKUP($D43,Résultats!$B$2:$AX$476,J$5,FALSE) -> #N/A | K43: =VLOOKUP($D43,Résultats!$B$2:$AX$476,K$5,FALSE) -> #N/A | L43: =VLOOKUP($D43,Résultats!$B$2:$AX$476,L$5,FALSE) -> #N/A | ... W43: =VLOOKUP($D43,Résultats!$B$2:$AX$476,W$5,FALSE) -> #N/A
...

Sheet T energie usages
A1: Energie par usage
A3: Energie finale (Mtep)
A4: =Résultats!B1 -> TEND
C7: Consos résultats de ThreeME | N7: Consos cibles d'Enerdata | U7: Consos résultats de ThreeME
C8: Hors bois domestique non marchand, avec consommation à double usage | N8: Hors bois domestique auto produit (8MTEP entre 2015 et 2030 4 Mtep en 2050) | U8: Hors bois domestique non marchand, avec consommation à double usage
C10: 2015 | H10: coal | I10: fuel and biofuel | J10: elec | K10: gas biogas biomass | L10: Total | N10: 2015 | O10: coal | P10: fuel and biofuel | Q10: elec | R10: gas biogas biomass | S10: Total | U10: 2015 | Z10: coal | AA10: fuel and biofuel | AB10: elec | AC10: gas biogas biomass | AD10: Total
C11: Transport | H11: =SUM(H12:H13) -> 0 | I11: =SUM(I12:I13) -> 43.235242 | J11: =SUM(J12:J13) -> 1.215759 | K11: =SUM(K12:K13) -> 0.22964514 | L11: =SUM(H11:K11) -> 44.680646 | N11: Transport | O11: ='[1]Bilan 2015'!$X$46 -> 0 | P11: =SUM('[1]Bilan 2015'!$X$41:$X$43) -> 42.748697 | Q11: ='[1]Bilan 2015'!$X$13 -> 0.94471195 | R11: =('[1]Bilan 2015'!$X$22+'[1]Bilan 2015'!$X$30+SUM('[1]Bilan 2015'!$X$36:$X$40)+SUM('[1]Bilan 2015'!$X$44:$X$45)+'[1]Bilan 2015'!$X$47) -> 0.072674067 | S11: =SUM(O11:R11) -> 43.766083 | U11: Transport | Z11: 0 | AA11: 43.655445 | AB11: 1.3708613 | AC11: 0.26944764 | AD11: 45.295754
C12: Personal vehicles | D12: ER_TRANS_PRIVATE_coal_1 | E12: ER_TRANS_PRIVATE_oil_1 | F12: ER_TRANS_PRIVATE_elec_1 | G12: ER_TRANS_PRIVATE_gas_1 | H12: =VLOOKUP(D12,Résultats!$B$2:$AX$476,'T energie vecteurs'!F5,FALSE) -> 0 | I12: =VLOOKUP(E12,Résultats!$B$2:$AX$476,'T energie vecteurs'!F5,FALSE) -> 24.202574 | J12: =VLOOKUP(F12,Résultats!$B$2:$AX$476,'T energie vecteurs'!F5,FALSE) -> 0.028859426 | K12: =VLOOKUP(G12,Résultats!$B$2:$AX$476,'T energie vecteurs'!F5,FALSE) -> 1.0452388e-05 | L12: =SUM(H12:K12) -> 24.231444 | N12: Personal vehicles | U12: Personal vehicles | V12: ER_TRANS_PRIVATE_coal_0 | W12: ER_TRANS_PRIVATE_oil_0 | X12: ER_TRANS_PRIVATE_elec_0 | Y12: ER_TRANS_PRIVATE_gas_0 | Z12: 0 | AA12: 24.375675 | AB12: 0.028638346 | AC12: 6.2334451e-06 | AD12: 24.40432
C13: Public and freight transport | D13: ER_TRANS_PUBLIC_coal_1 | E13: ER_TRANS_PUBLIC_oil_1 | F13: ER_TRANS_PUBLIC_elec_1 | G13: ER_TRANS_PUBLIC_gas_1 | H13: =VLOOKUP(D13,Résultats!$B$2:$AX$476,'T energie vecteurs'!F5,FALSE) -> 0 | I13: =VLOOKUP(E13,Résultats!$B$2:$AX$476,'T energie vecteurs'!F5,FALSE) -> 19.032668 | J13: =VLOOKUP(F13,Résultats!$B$2:$AX$476,'T energie vecteurs'!F5,FALSE) -> 1.1868996 | K13: =VLOOKUP(G13,Résultats!$B$2:$AX$476,'T energie vecteurs'!F5,FALSE) -> 0.22963469 | L13: =SUM(H13:K13) -> 20.449203 | N13: Public and freight transport | U13: Public and freight transport | V13: ER_TRANS_PUBLIC_coal_0 | W13: ER_TRANS_PUBLIC_oil_0 | X13: ER_TRANS_PUBLIC_elec_0 | Y13: ER_TRANS_PUBLIC_gas_0 | Z13: 0 | AA13: 19.27977 | AB13: 1.3422229 | AC13: 0.26944141 | AD13: 20.891434
C14: Residential | D14: ER_RESIDENTIAL_coal_1 | E14: ER_RESIDENTIAL_oil_1 | F14: ER_RESIDENTIAL_elec_1 | G14: ER_RESIDENTIAL_gas_1 | H14: =VLOOKUP(D14,Résultats!$B$2:$AX$476,'T energie vecteurs'!F5,FALSE) -> 0.29368456 | I14: =VLOOKUP(E14,Résultats!$B$2:$AX$476,'T energie vecteurs'!F5,FALSE) -> 7.1747672 | J14: =VLOOKUP(F14,Résultats!$B$2:$AX$476,'T energie vecteurs'!F5,FALSE) -> 14.024228 | K14: =VLOOKUP(G14,Résultats!$B$2:$AX$476,'T energie vecteurs'!F5,FALSE)+5 -> 21.106097 | L14: =SUM(H14:K14) -> 42.598777 | N14: Residential | O14: ='[1]Bilan 2015'!$V$46 -> 0.036764197 | P14: =SUM('[1]Bilan 2015'!$V$41:$V$43) -> 6.6752954 | Q14: ='[1]Bilan 2015'!$V$13 -> 13.620367 | R14: =('[1]Bilan 2015'!$V$22+'[1]Bilan 2015'!$V$30+SUM('[1]Bilan 2015'!$V$36:$V$40)+SUM('[1]Bilan 2015'!$V$44:$V$45)+'[1]Bilan 2015'!$V$47) -> 21.832864 | S14: =SUM(O14:R14) -> 42.16529 | U14: Residential | V14: ER_RESIDENTIAL_coal_0 | W14: ER_RESIDENTIAL_oil_0 | X14: ER_RESIDENTIAL_elec_0 | Y14: ER_RESIDENTIAL_gas_0 | Z14: 0.29143291 | AA14: 6.750666 | AB14: 14.411191 | AC14: 20.636263 | AD14: 42.089554
C15: Service | D15: ER_TERTIARY_coal_1 | E15: ER_TERTIARY_oil_1 | F15: ER_TERTIARY_elec_1 | G15: ER_TERTIARY_gas_1 | H15: =VLOOKUP(D15,Résultats!$B$2:$AX$476,'T energie vecteurs'!F5,FALSE) -> 0 | I15: =VLOOKUP(E15,Résultats!$B$2:$AX$476,'T energie vecteurs'!F5,FALSE) -> 4.2755146 | J15: =VLOOKUP(F15,Résultats!$B$2:$AX$476,'T energie vecteurs'!F5,FALSE) -> 13.311593 | K15: =VLOOKUP(G15,Résultats!$B$2:$AX$476,'T energie vecteurs'!F5,FALSE) -> 9.726067 | L15: =SUM(H15:K15) -> 27.313174 | N15: Service | O15: ='[1]Bilan 2015'!$W$46 -> 0.043073392 | P15: =SUM('[1]Bilan 2015'!$W$41:$W$43) -> 3.0154656 | Q15: ='[1]Bilan 2015'!$W$13 -> 12.701365 | R15: =('[1]Bilan 2015'!$W$22+'[1]Bilan 2015'!$W$30+SUM('[1]Bilan 2015'!$W$36:$W$40)+SUM('[1]Bilan 2015'!$W$44:$W$45)+'[1]Bilan 2015'!$W$47) -> 8.7461122 | S15: =SUM(O15:R15) -> 24.506017 | U15: Service | V15: ER_TERTIARY_coal_0 | W15: ER_TERTIARY_oil_0 | X15: ER_TERTIARY_elec_0 | Y15: ER_TERTIARY_gas_0 | Z15: 0 | AA15: 3.5686169 | AB15: 12.769876 | AC15: 9.0390918 | AD15: 25.377585
C16: Industry and agriculture | H16: =SUM(H17:H19) -> 4.8875364 | I16: =SUM(I17:I19) -> 18.710705 | J16: =SUM(J17:J19) -> 11.326554 | K16: =SUM(K17:K19) -> 14.077478 | L16: =SUM(H16:K16) -> 49.002273 | N16: Industry | O16: =O17+O18 -> 4.2636281 | P16: =P17+P18 -> 14.865721 | Q16: =Q17+Q18 -> 10.069552 | R16: =R17+R18 -> 13.7564 | S16: =SUM(O16:R16) -> 42.955301 | U16: Industry and agriculture | Z16: 4.1729011 | AA16: 18.04035 | AB16: 11.314939 | AC16: 14.446424 | AD16: 47.974614
C17: Industry | D17: ER_INDUS_coal_1 | E17: ER_INDUS_oil_1 | F17: ER_INDUS_elec_1 | G17: ER_INDUS_gas_1 | H17: =VLOOKUP(D17,Résultats!$B$2:$AX$476,'T energie vecteurs'!F5,FALSE) -> 3.8966424 | I17: =VLOOKUP(E17,Résultats!$B$2:$AX$476,'T energie vecteurs'!F5,FALSE) -> 14.380357 | J17: =VLOOKUP(F17,Résultats!$B$2:$AX$476,'T energie vecteurs'!F5,FALSE) -> 11.010773 | K17: =VLOOKUP(G17,Résultats!$B$2:$AX$476,'T energie vecteurs'!F5,FALSE) -> 11.965566 | L17: =SUM(H17:K17) -> 41.253338 | N17: Industry energetic uses | O17: ='[1]Bilan 2015'!$U$46 -> 1.0493093 | P17: =SUM('[1]Bilan 2015'!$U$41:$U$43) -> 2.4127207 | Q17: ='[1]Bilan 2015'!$U$13 -> 10.069552 | R17: =('[1]Bilan 2015'!$U$22+'[1]Bilan 2015'!$U$30+SUM('[1]Bilan 2015'!$U$36:$U$40)+SUM('[1]Bilan 2015'!$U$44:$U$45)+'[1]Bilan 2015'!$U$47) -> 12.654814 | S17: =SUM(O17:R17) -> 26.186396 | U17: Industry | V17: ER_INDUS_coal_0 | W17: ER_INDUS_oil_0 | X17: ER_INDUS_elec_0 | Y17: ER_INDUS_gas_0 | Z17: 3.2526652 | AA17: 13.839453 | AB17: 10.978162 | AC17: 12.365702 | AD17: 40.435983
C18: Industry non energetic uses | D18: Q_Mtep_indus_21_1 | E18: Q_Mtep_indus_22_1 | F18: Q_Mtep_indus_23_1 | G18: Q_Mtep_indus_24_1 | H18: =VLOOKUP(D18,Résultats!$B$2:$AX$476,'T energie vecteurs'!F5,FALSE) -> 0.99089399 | I18: =VLOOKUP(E18,Résultats!$B$2:$AX$476,'T energie vecteurs'!F5,FALSE) -> 1.8977947 | J18: =VLOOKUP(F18,Résultats!$B$2:$AX$476,'T energie vecteurs'!F5,FALSE) -> 0 | K18: =VLOOKUP(G18,Résultats!$B$2:$AX$476,'T energie vecteurs'!F5,FALSE) -> 1.7471999 | L18: =SUM(H18:K18) -> 4.6358887 | N18: Industry non energetic uses | O18: ='[1]Bilan 2015'!$E$52 -> 3.2143188 | P18: =('[1]Bilan 2015'!$E$54+'[1]Bilan 2015'!$E$56) -> 12.453 | Q18: 0 | R18: =('[1]Bilan 2015'!$E$53+'[1]Bilan 2015'!$E$55+'[1]Bilan 2015'!$E$57) -> 1.1015862 | S18: =SUM(O18:R18) -> 16.768905 | U18: Industry non energetic uses | V18: Q_Mtep_indus_21_0 | W18: Q_Mtep_indus_22_0 | X18: Q_Mtep_indus_23_0 | Y18: Q_Mtep_indus_24_0 | Z18: 0.92023592 | AA18: 1.7799997 | AB18: 0 | AC18: 1.7183807 | AD18: 4.4186164
C19: Agriculture | D19: ER_AGRICULTURE_coal_1 | E19: ER_AGRICULTURE_oil_1 | F19: ER_AGRICULTURE_elec_1 | G19: ER_AGRICULTURE_gas_1 | H19: =VLOOKUP(D19,Résultats!$B$2:$AX$476,'T energie vecteurs'!F5,FALSE) -> 0 | I19: =VLOOKUP(E19,Résultats!$B$2:$AX$476,'T energie vecteurs'!F5,FALSE) -> 2.4325525 | J19: =VLOOKUP(F19,Résultats!$B$2:$AX$476,'T energie vecteurs'!F5,FALSE) -> 0.31578116 | K19: =VLOOKUP(G19,Résultats!$B$2:$AX$476,'T energie vecteurs'!F5,FALSE) -> 0.36471241 | L19: =SUM(H19:K19) -> 3.1130461 | N19: Agriculture | O19: ='[1]Bilan 2015'!$T$46 -> 0.0022137193 | P19: =SUM('[1]Bilan 2015'!$T$41:$T$43) -> 3.4936668 | Q19: ='[1]Bilan 2015'!$T$13 -> 0.74651763 | R19: =('[1]Bilan 2015'!$T$22+'[1]Bilan 2015'!$T$30+SUM('[1]Bilan 2015'!$T$36:$T$40)+SUM('[1]Bilan 2015'!$T$44:$T$45)+'[1]Bilan 2015'!$T$47) -> 0.24365267 | S19: =SUM(O19:R19) -> 4.4860508 | U19: Agriculture | V19: ER_AGRICULTURE_coal_0 | W19: ER_AGRICULTURE_oil_0 | X19: ER_AGRICULTURE_elec_0 | Y19: ER_AGRICULTURE_gas_0 | Z19: 0 | AA19: 2.4208977 | AB19: 0.33677654 | AC19: 0.36234122 | AD19: 3.1200155
C20: Total Final Mtep | H20: =SUM(H11,H14:H16) -> 5.181221 | I20: =SUM(I11,I14:I16) -> 73.396228 | J20: =SUM(J11,J14:J16) -> 39.878134 | K20: =SUM(K11,K14:K16) -> 45.139287 | L20: =SUM(H20:K20) -> 163.59487 | N20: Total Final Mtep | O20: =O11+O14+O15+O16+O19 -> 4.3456794 | P20: =P11+P14+P15+P16+P19 -> 70.798845 | Q20: =Q11+Q14+Q15+Q16+Q19 -> 38.082514 | R20: =R11+R14+R15+R16+R19 -> 44.651703 | S20: =SUM(O20:R20) -> 157.87874 | U20: Total Final Mtep | Z20: 4.464334 | AA20: 72.015078 | AB20: 39.866868 | AC20: 44.391227 | AD20: 160.73751
S21: =S11+S14+S15+S16+S19 -> 157.87874
C23: 2020 | H23: coal | I23: fuel and biofuel | J23: elec | K23: gas biogas biomass | L23: Total | N23: 2020 | O23: coal | P23: fuel and biofuel | Q23: elec | R23: gas biogas biomass | S23: Total | U23: 2020 | Z23: coal | AA23: fuel and biofuel | AB23: elec | AC23: gas biogas biomass | AD23: Total
C24: Transport | H24: =SUM(H25:H26) -> 0 | I24: =SUM(I25:I26) -> 42.251962 | J24: =SUM(J25:J26) -> 1.428452 | K24: =SUM(K25:K26) -> 0.25528918 | L24: =SUM(H24:K24) -> 43.935704 | N24: Transport | O24: ='[1]Bilan 2020'!$X$46/11.63 -> 0 | P24: =SUM('[1]Bilan 2020'!$X$41:$X$43)/11.63 -> 35.668036 | Q24: ='[1]Bilan 2020'!$X$13/11.63 -> 0.71687008 | R24: =('[1]Bilan 2020'!$X$22+'[1]Bilan 2020'!$X$30+SUM('[1]Bilan 2020'!$X$36:$X$40)+SUM('[1]Bilan 2020'!$X$44:$X$45)+'[1]Bilan 2020'!$X$47)/11.63 -> 0.19326866 | S24: =SUM(O24:R24) -> 36.578175 | U24: Transport | Z24: 0 | AA24: 43.018744 | AB24: 1.8220352 | AC24: 0.31541142 | AD24: 45.156191
C25: Personal vehicles | D25: ER_TRANS_PRIVATE_coal_1 | E25: ER_TRANS_PRIVATE_oil_1 | F25: ER_TRANS_PRIVATE_elec_1 | G25: ER_TRANS_PRIVATE_gas_1 | H25: =VLOOKUP(D25,Résultats!$B$2:$AX$476,'T energie vecteurs'!I5,FALSE) -> 0 | I25: =VLOOKUP(E25,Résultats!$B$2:$AX$476,'T energie vecteurs'!I5,FALSE) -> 23.698841 | J25: =VLOOKUP(F25,Résultats!$B$2:$AX$476,'T energie vecteurs'!I5,FALSE) -> 0.10937869 | K25: =VLOOKUP(G77,Résultats!$B$2:$AX$476,'T energie vecteurs'!I5,FALSE) -> 1.6040599e-05 | L25: =SUM(H25:K25) -> 23.808236 | N25: Personal vehicles | U25: Personal vehicles | V25: ER_TRANS_PRIVATE_coal_0 | W25: ER_TRANS_PRIVATE_oil_0 | X25: ER_TRANS_PRIVATE_elec_0 | Y25: ER_TRANS_PRIVATE_gas_0 | Z25: 0 | AA25: 23.922501 | AB25: 0.10584781 | AC25: 9.2348089e-06 | AD25: 24.028358
C26: Public and freight transport | D26: ER_TRANS_PUBLIC_coal_1 | E26: ER_TRANS_PUBLIC_oil_1 | F26: ER_TRANS_PUBLIC_elec_1 | G26: ER_TRANS_PUBLIC_gas_1 | H26: =VLOOKUP(D26,Résultats!$B$2:$AX$476,'T energie vecteurs'!I5,FALSE) -> 0 | I26: =VLOOKUP(E26,Résultats!$B$2:$AX$476,'T energie vecteurs'!I5,FALSE) -> 18.553121 | J26: =VLOOKUP(F26,Résultats!$B$2:$AX$476,'T energie vecteurs'!I5,FALSE) -> 1.3190733 | K26: =VLOOKUP(G26,Résultats!$B$2:$AX$476,'T energie vecteurs'!I5,FALSE) -> 0.25527314 | L26: =SUM(H26:K26) -> 20.127468 | N26: Public and freight transport | U26: Public and freight transport | V26: ER_TRANS_PUBLIC_coal_0 | W26: ER_TRANS_PUBLIC_oil_0 | X26: ER_TRANS_PUBLIC_elec_0 | Y26: ER_TRANS_PUBLIC_gas_0 | Z26: 0 | AA26: 19.096243 | AB26: 1.7161874 | AC26: 0.31540219 | AD26: 21.127833
C27: Residential | D27: ER_RESIDENTIAL_coal_1 | E27: ER_RESIDENTIAL_oil_1 | F27: ER_RESIDENTIAL_elec_1 | G27: ER_RESIDENTIAL_gas_1 | H27: =VLOOKUP(D27,Résultats!$B$2:$AX$476,'T energie vecteurs'!I5,FALSE) -> 0.26291969 | I27: =VLOOKUP(E27,Résultats!$B$2:$AX$476,'T energie vecteurs'!I5,FALSE) -> 6.2714561 | J27: =VLOOKUP(F27,Résultats!$B$2:$AX$476,'T energie vecteurs'!I5,FALSE) -> 14.695407 | K27: =VLOOKUP(G27,Résultats!$B$2:$AX$476,'T energie vecteurs'!I5,FALSE)+6 -> 20.495942 | L27: =SUM(H27:K27) -> 41.725725 | N27: Residential | O27: ='[1]Bilan 2020'!$V$46/11.63 -> 0.020700735 | P27: =SUM('[1]Bilan 2020'!$V$41:$V$43)/11.63 -> 4.2874728 | Q27: ='[1]Bilan 2020'!$V$13/11.63 -> 13.618732 | R27: =('[1]Bilan 2020'!$V$22+'[1]Bilan 2020'!$V$30+SUM('[1]Bilan 2020'!$V$36:$V$40)+SUM('[1]Bilan 2020'!$V$44:$V$45)+'[1]Bilan 2020'!$V$47)/11.63 -> 20.40841 | S27: =SUM(O27:R27) -> 38.335315 | U27: Residential | V27: ER_RESIDENTIAL_coal_0 | W27: ER_RESIDENTIAL_oil_0 | X27: ER_RESIDENTIAL_elec_0 | Y27: ER_RESIDENTIAL_gas_0 | Z27: 0.26184971 | AA27: 5.7024644 | AB27: 15.25919 | AC27: 20.182441 | AD27: 41.405944
C28: Service | D28: ER_TERTIARY_coal_1 | E28: ER_TERTIARY_oil_1 | F28: ER_TERTIARY_elec_1 | G28: ER_TERTIARY_gas_1 | H28: =VLOOKUP(D28,Résultats!$B$2:$AX$476,'T energie vecteurs'!I5,FALSE) -> 0 | I28: =VLOOKUP(E28,Résultats!$B$2:$AX$476,'T energie vecteurs'!I5,FALSE) -> 3.1173306 | J28: =VLOOKUP(F28,Résultats!$B$2:$AX$476,'T energie vecteurs'!I5,FALSE) -> 12.975212 | K28: =VLOOKUP(G28,Résultats!$B$2:$AX$476,'T energie vecteurs'!I5,FALSE) -> 7.935653 | L28: =SUM(H28:K28) -> 24.028196 | N28: Service | O28: =('[1]Bilan 2020'!$W$46)/11.63 -> 0.030546421 | P28: =SUM('[1]Bilan 2020'!$W$41:$W$43)/11.63 -> 2.7068356 | Q28: =('[1]Bilan 2020'!$W$13)/11.63 -> 10.724851 | R28: =('[1]Bilan 2020'!$W$22+'[1]Bilan 2020'!$W$30+SUM('[1]Bilan 2020'!$W$36:$W$40)+SUM('[1]Bilan 2020'!$W$44:$W$45)+'[1]Bilan 2020'!$W$47)/11.63 -> 7.1906336 | S28: =SUM(O28:R28) -> 20.652866 | U28: Service | V28: ER_TERTIARY_coal_0 | W28: ER_TERTIARY_oil_0 | X28: ER_TERTIARY_elec_0 | Y28: ER_TERTIARY_gas_0 | Z28: 0 | AA28: 2.5782826 | AB28: 12.104467 | AC28: 7.6832677 | AD28: 22.366018
C29: Industry and agriculture | H29: =SUM(H30:H32) -> 2.6579612 | I29: =SUM(I30:I32) -> 13.620348 | J29: =SUM(J30:J32) -> 9.6460239 | K29: =SUM(K30:K32) -> 14.365485 | L29: =SUM(H29:K29) -> 40.289818 | N29: Industry | O29: =O30+O31 -> 3.1626378 | P29: =P30+P31 -> 13.919974 | Q29: =Q30+Q31 -> 9.0413235 | R29: =R30+R31 -> 14.312071 | S29: =SUM(O29:R29) -> 40.436006 | U29: Industry and agriculture | Z29: 2.9352594 | AA29: 14.864282 | AB29: 9.5134154 | AC29: 13.758628 | AD29: 41.071585
C30: Industry | D30: ER_INDUS_coal_1 | E30: ER_INDUS_oil_1 | F30: ER_INDUS_elec_1 | G30: ER_INDUS_gas_1 | H30: =VLOOKUP(D30,Résultats!$B$2:$AX$476,'T energie vecteurs'!I5,FALSE) -> 1.7896973 | I30: =VLOOKUP(E30,Résultats!$B$2:$AX$476,'T energie vecteurs'!I5,FALSE) -> 9.3519632 | J30: =VLOOKUP(F30,Résultats!$B$2:$AX$476,'T energie vecteurs'!I5,FALSE) -> 9.3345403 | K30: =VLOOKUP(G30,Résultats!$B$2:$AX$476,'T energie vecteurs'!I5,FALSE) -> 11.999935 | L30: =SUM(H30:K30) -> 32.476135 | N30: Industry energetic uses | O30: ='[1]Bilan 2020'!$U$46/11.63 -> 0.77267988 | P30: =SUM('[1]Bilan 2020'!$U$41:$U$43)/11.63 -> 2.7003588 | Q30: ='[1]Bilan 2020'!$U$13/11.63 -> 9.0413235 | R30: =('[1]Bilan 2020'!$U$22+'[1]Bilan 2020'!$U$30+SUM('[1]Bilan 2020'!$U$36:$U$40)+SUM('[1]Bilan 2020'!$U$44:$U$45)+'[1]Bilan 2020'!$U$47)/11.63 -> 13.277855 | S30: =SUM(O30:R30) -> 25.792217 | U30: Industry | V30: ER_INDUS_coal_0 | W30: ER_INDUS_oil_0 | X30: ER_INDUS_elec_0 | Y30: ER_INDUS_gas_0 | Z30: 2.0907212 | AA30: 10.561312 | AB30: 9.1722502 | AC30: 11.439848 | AD30: 33.264131
C31: Industry non energetic uses | D31: Q_Mtep_indus_21_1 | E31: Q_Mtep_indus_22_1 | F31: Q_Mtep_indus_23_1 | G31: Q_Mtep_indus_24_1 | H31: =VLOOKUP(D31,Résultats!$B$2:$AX$476,'T energie vecteurs'!I5,FALSE) -> 0.86826389 | I31: =VLOOKUP(E31,Résultats!$B$2:$AX$476,'T energie vecteurs'!I5,FALSE) -> 1.8873345 | J31: =VLOOKUP(F31,Résultats!$B$2:$AX$476,'T energie vecteurs'!I5,FALSE) -> 0 | K31: =VLOOKUP(G31,Résultats!$B$2:$AX$476,'T energie vecteurs'!I5,FALSE) -> 2.0350648 | L31: =SUM(H31:K31) -> 4.7906631 | N31: Industry non energetic uses | O31: ='[1]Bilan 2020'!$E$52/11.63 -> 2.3899579 | P31: =('[1]Bilan 2020'!$E$54+'[1]Bilan 2020'!$E$56)/11.63 -> 11.219615 | Q31: 0 | R31: =('[1]Bilan 2020'!$E$53+'[1]Bilan 2020'!$E$55+'[1]Bilan 2020'!$E$57)/11.63 -> 1.0342164 | S31: =SUM(O31:R31) -> 14.643789 | U31: Industry non energetic uses | V31: Q_Mtep_indus_21_0 | W31: Q_Mtep_indus_22_0 | X31: Q_Mtep_indus_23_0 | Y31: Q_Mtep_indus_24_0 | Z31: 0.84453811 | AA31: 1.8990812 | AB31: 0 | AC31: 1.9869123 | AD31: 4.7305316
C32: Agriculture | D32: ER_AGRICULTURE_coal_1 | E32: ER_AGRICULTURE_oil_1 | F32: ER_AGRICULTURE_elec_1 | G32: ER_AGRICULTURE_gas_1 | H32: =VLOOKUP(D32,Résultats!$B$2:$AX$476,'T energie vecteurs'!I5,FALSE) -> 0 | I32: =VLOOKUP(E32,Résultats!$B$2:$AX$476,'T energie vecteurs'!I5,FALSE) -> 2.3810507 | J32: =VLOOKUP(F32,Résultats!$B$2:$AX$476,'T energie vecteurs'!I5,FALSE) -> 0.31148359 | K32: =VLOOKUP(G32,Résultats!$B$2:$AX$476,'T energie vecteurs'!I5,FALSE) -> 0.33048569 | L32: =SUM(H32:K32) -> 3.02302 | N32: Agriculture | O32: ='[1]Bilan 2020'!$T$46/11.63 -> 0.001321701 | P32: =SUM('[1]Bilan 2020'!$T$41:$T$43)/11.63 -> 3.3486885 | Q32: ='[1]Bilan 2020'!$T$13/11.63 -> 0.69143728 | R32: =('[1]Bilan 2020'!$T$22+'[1]Bilan 2020'!$T$30+SUM('[1]Bilan 2020'!$T$36:$T$40)+SUM('[1]Bilan 2020'!$T$44:$T$45)+'[1]Bilan 2020'!$T$47)/11.63 -> 0.41959097 | S32: =SUM(O32:R32) -> 4.4610384 | U32: Agriculture | V32: ER_AGRICULTURE_coal_0 | W32: ER_AGRICULTURE_oil_0 | X32: ER_AGRICULTURE_elec_0 | Y32: ER_AGRICULTURE_gas_0 | Z32: 0 | AA32: 2.4038891 | AB32: 0.34116511 | AC32: 0.33186802 | AD32: 3.0769222
C33: Total Final Mtep | H33: =SUM(H24,H27:H29) -> 2.9208809 | I33: =SUM(I24,I27:I29) -> 65.261097 | J33: =SUM(J24,J27:J29) -> 38.745095 | K33: =SUM(K24,K27:K29) -> 43.052369 | L33: =SUM(H33:K33) -> 149.97944 | N33: Total Final Mtep | O33: =O24+O27+O28+O29+O32 -> 3.2152067 | P33: =P24+P27+P28+P29+P32 -> 59.931007 | Q33: =Q24+Q27+Q28+Q29+Q32 -> 34.793213 | R33: =R24+R27+R28+R29+R32 -> 42.523975 | S33: =SUM(O33:R33) -> 140.4634 | U33: Total Final Mtep | Z33: 3.1971091 | AA33: 66.163774 | AB33: 38.699107 | AC33: 41.939748 | AD33: 149.99974
C36: 2022 | H36: coal | I36: fuel and biofuel | J36: elec | K36: gas biogas biomass | L36: Total | N36: 2022 | O36: coal | P36: fuel and biofuel | Q36: elec | R36: gas biogas biomass | S36: Total | U36: 2022 | Z36: coal | AA36: fuel and biofuel | AB36: elec | AC36: gas biogas biomass | AD36: Total
C37: Transport | H37: =SUM(H38:H39) -> 0 | I37: =SUM(I38:I39) -> 41.582451 | J37: =SUM(J38:J39) -> 1.5231817 | K37: =SUM(K38:K39) -> 0.36256658 | L37: =SUM(H37:K37) -> 43.4682 | N37: Transport | O37: ='[1]Bilan 2022 réel'!$X$46/11.63 -> 0 | P37: =SUM('[1]Bilan 2022 réel'!$X$41:$X$43)/11.63 -> 43.395883 | Q37: ='[1]Bilan 2022 réel'!$X$13/11.63 -> 0.93062752 | R37: =('[1]Bilan 2022 réel'!$X$22+'[1]Bilan 2022 réel'!$X$30+SUM('[1]Bilan 2022 réel'!$X$36:$X$40)+SUM('[1]Bilan 2022 réel'!$X$44:$X$45)+'[1]Bilan 2022 réel'!$X$47)/11.63 -> 0.31885684 | S37: =SUM(O37:R37) -> 44.645367 | U37: Transport | Z37: 0 | AA37: 42.966689 | AB37: 1.9854484 | AC37: 0.44041369 | AD37: 45.392551
C38: Personal vehicles | D38: ER_TRANS_PRIVATE_coal_1 | E38: ER_TRANS_PRIVATE_oil_1 | F38: ER_TRANS_PRIVATE_elec_1 | G38: ER_TRANS_PRIVATE_gas_1 | H38: =VLOOKUP(D38,Résultats!$B$2:$AX$476,'T energie vecteurs'!K5,FALSE) -> 0 | I38: =VLOOKUP(E38,Résultats!$B$2:$AX$476,'T energie vecteurs'!K5,FALSE) -> 22.858451 | J38: =VLOOKUP(F38,Résultats!$B$2:$AX$476,'T energie vecteurs'!K5,FALSE) -> 0.16593726 | K38: =VLOOKUP(G51,Résultats!$B$2:$AX$476,'T energie vecteurs'!K5,FALSE) -> 1.8981503e-05 | L38: =SUM(H38:K38) -> 23.024407 | N38: Personal vehicles | U38: Personal vehicles | V38: ER_TRANS_PRIVATE_coal_0 | W38: ER_TRANS_PRIVATE_oil_0 | X38: ER_TRANS_PRIVATE_elec_0 | Y38: ER_TRANS_PRIVATE_gas_0 | Z38: 0 | AA38: 23.091051 | AB38: 0.1608671 | AC38: 1.1521844e-05 | AD38: 23.251929
C39: Public and freight transport | D39: ER_TRANS_PUBLIC_coal_1 | E39: ER_TRANS_PUBLIC_oil_1 | F39: ER_TRANS_PUBLIC_elec_1 | G39: ER_TRANS_PUBLIC_gas_1 | H39: =VLOOKUP(D39,Résultats!$B$2:$AX$476,'T energie vecteurs'!K5,FALSE) -> 0 | I39: =VLOOKUP(E39,Résultats!$B$2:$AX$476,'T energie vecteurs'!K5,FALSE) -> 18.724 | J39: =VLOOKUP(F39,Résultats!$B$2:$AX$476,'T energie vecteurs'!K5,FALSE) -> 1.3572444 | K39: =VLOOKUP(G39,Résultats!$B$2:$AX$476,'T energie vecteurs'!K5,FALSE) -> 0.3625476 | L39: =SUM(H39:K39) -> 20.443792 | N39: Public and freight transport | U39: Public and freight transport | V39: ER_TRANS_PUBLIC_coal_0 | W39: ER_TRANS_PUBLIC_oil_0 | X39: ER_TRANS_PUBLIC_elec_0 | Y39: ER_TRANS_PUBLIC_gas_0 | Z39: 0 | AA39: 19.875638 | AB39: 1.8245813 | AC39: 0.44040217 | AD39: 22.140621
C40: Residential | D40: ER_RESIDENTIAL_coal_1 | E40: ER_RESIDENTIAL_oil_1 | F40: ER_RESIDENTIAL_elec_1 | G40: ER_RESIDENTIAL_gas_1 | H40: =VLOOKUP(D40,Résultats!$B$2:$AX$476,'T energie vecteurs'!K5,FALSE) -> 0.24509812 | I40: =VLOOKUP(E40,Résultats!$B$2:$AX$476,'T energie vecteurs'!K5,FALSE) -> 5.9260819 | J40: =VLOOKUP(F40,Résultats!$B$2:$AX$476,'T energie vecteurs'!K5,FALSE) -> 14.791503 | K40: =VLOOKUP(G40,Résultats!$B$2:$AX$476,'T energie vecteurs'!K5,FALSE)+8 -> 21.758443 | L40: =SUM(H40:K40) -> 42.721126 | N40: Residential | O40: ='[1]Bilan 2022 réel'!$V$46/11.63 -> 0.026476317 | P40: =SUM('[1]Bilan 2022 réel'!$V$41:$V$43)/11.63 -> 3.5006052 | Q40: ='[1]Bilan 2022 réel'!$V$13/11.63 -> 13.359407 | R40: =('[1]Bilan 2022 réel'!$V$22+'[1]Bilan 2022 réel'!$V$30+SUM('[1]Bilan 2022 réel'!$V$36:$V$40)+SUM('[1]Bilan 2022 réel'!$V$44:$V$45)+'[1]Bilan 2022 réel'!$V$47)/11.63 -> 20.358937 | S40: =SUM(O40:R40) -> 37.245425 | U40: Residential | V40: ER_RESIDENTIAL_coal_0 | W40: ER_RESIDENTIAL_oil_0 | X40: ER_RESIDENTIAL_elec_0 | Y40: ER_RESIDENTIAL_gas_0 | Z40: 0.24246651 | AA40: 5.559917 | AB40: 15.062818 | AC40: 21.524609 | AD40: 42.38981
C41: Service | D41: ER_TERTIARY_coal_1 | E41: ER_TERTIARY_oil_1 | F41: ER_TERTIARY_elec_1 | G41: ER_TERTIARY_gas_1 | H41: =VLOOKUP(D41,Résultats!$B$2:$AX$476,'T energie vecteurs'!K5,FALSE) -> 0 | I41: =VLOOKUP(E41,Résultats!$B$2:$AX$476,'T energie vecteurs'!K5,FALSE) -> 3.1162613 | J41: =VLOOKUP(F41,Résultats!$B$2:$AX$476,'T energie vecteurs'!K5,FALSE) -> 13.110018 | K41: =VLOOKUP(G41,Résultats!$B$2:$AX$476,'T energie vecteurs'!K5,FALSE) -> 7.7875307 | L41: =SUM(H41:K41) -> 24.01381 | N41: Service | O41: =('[1]Bilan 2022 réel'!$W$46)/11.63 -> 0.032835728 | P41: =SUM('[1]Bilan 2022 réel'!$W$41:$W$43)/11.63 -> 2.081572 | Q41: =('[1]Bilan 2022 réel'!$W$13)/11.63 -> 11.43888 | R41: =('[1]Bilan 2022 réel'!$W$22+'[1]Bilan 2022 réel'!$W$30+SUM('[1]Bilan 2022 réel'!$W$36:$W$40)+SUM('[1]Bilan 2022 réel'!$W$44:$W$45)+'[1]Bilan 2022 réel'!$W$47)/11.63 -> 7.4016622 | S41: =SUM(O41:R41) -> 20.95495 | U41: Service | V41: ER_TERTIARY_coal_0 | W41: ER_TERTIARY_oil_0 | X41: ER_TERTIARY_elec_0 | Y41: ER_TERTIARY_gas_0 | Z41: 0 | AA41: 2.6093376 | AB41: 12.111769 | AC41: 7.4488842 | AD41: 22.169991
C42: Industry and agriculture | H42: =SUM(H43:H45) -> 2.627281 | I42: =SUM(I43:I45) -> 13.255116 | J42: =SUM(J43:J45) -> 10.008524 | K42: =SUM(K43:K45) -> 14.579111 | L42: =SUM(H42:K42) -> 40.470031 | N42: Industry | O42: =O43+O44 -> 4.5030918 | P42: =P43+P44 -> 11.747675 | Q42: =Q43+Q44 -> 9.2559822 | R42: =R43+R44 -> 13.798624 | S42: =SUM(O42:R42) -> 39.305373 | U42: Industry and agriculture | Z42: 3.0042873 | AA42: 15.481105 | AB42: 9.8959557 | AC42: 14.553169 | AD42: 42.934517
C43: Industry | D43: ER_INDUS_coal_1 | E43: ER_INDUS_oil_1 | F43: ER_INDUS_elec_1 | G43: ER_INDUS_gas_1 | H43: =VLOOKUP(D43,Résultats!$B$2:$AX$476,'T energie vecteurs'!K5,FALSE) -> 1.7434572 | I43: =VLOOKUP(E43,Résultats!$B$2:$AX$476,'T energie vecteurs'!K5,FALSE) -> 8.925026 | J43: =VLOOKUP(F43,Résultats!$B$2:$AX$476,'T energie vecteurs'!K5,FALSE) -> 9.6873319 | K43: =VLOOKUP(G43,Résultats!$B$2:$AX$476,'T energie vecteurs'!K5,FALSE) -> 12.183993 | L43: =SUM(H43:K43) -> 32.539808 | N43: Industry energetic uses | O43: ='[1]Bilan 2022 réel'!$U$46/11.63 -> 0.63402045 | P43: =SUM('[1]Bilan 2022 réel'!$U$41:$U$43)/11.63 -> 2.477583 | Q43: ='[1]Bilan 2022 réel'!$U$13/11.63 -> 9.2559822 | R43: =('[1]Bilan 2022 réel'!$U$22+'[1]Bilan 2022 réel'!$U$30+SUM('[1]Bilan 2022 réel'!$U$36:$U$40)+SUM('[1]Bilan 2022 réel'!$U$44:$U$45)+'[1]Bilan 2022 réel'!$U$47)/11.63 -> 12.926273 | S43: =SUM(O43:R43) -> 25.293858 | U43: Industry | V43: ER_INDUS_coal_0 | W43: ER_INDUS_oil_0 | X43: ER_INDUS_elec_0 | Y43: ER_INDUS_gas_0 | Z43: 2.1281616 | AA43: 11.012907 | AB43: 9.5584666 | AC43: 12.088159 | AD43: 34.787695
C44: Industry non energetic uses | D44: Q_Mtep_indus_21_1 | E44: Q_Mtep_indus_22_1 | F44: Q_Mtep_indus_23_1 | G44: Q_Mtep_indus_24_1 | H44: =VLOOKUP(D44,Résultats!$B$2:$AX$476,'T energie vecteurs'!K5,FALSE) -> 0.88382376 | I44: =VLOOKUP(E44,Résultats!$B$2:$AX$476,'T energie vecteurs'!K5,FALSE) -> 1.9147194 | J44: =VLOOKUP(F44,Résultats!$B$2:$AX$476,'T energie vecteurs'!K5,FALSE) -> 0 | K44: =VLOOKUP(G44,Résultats!$B$2:$AX$476,'T energie vecteurs'!K5,FALSE) -> 2.0568753 | L44: =SUM(H44:K44) -> 4.8554184 | N44: Industry non energetic uses | O44: ='[1]Bilan 2022 réel'!$E$52/11.63 -> 3.8690713 | P44: =('[1]Bilan 2022 réel'!$E$54+'[1]Bilan 2022 réel'!$E$56)/11.63 -> 9.270092 | Q44: 0 | R44: =('[1]Bilan 2022 réel'!$E$53+'[1]Bilan 2022 réel'!$E$55+'[1]Bilan 2022 réel'!$E$57)/11.63 -> 0.87235178 | S44: =SUM(O44:R44) -> 14.011515 | U44: Industry non energetic uses | V44: Q_Mtep_indus_21_0 | W44: Q_Mtep_indus_22_0 | X44: Q_Mtep_indus_23_0 | Y44: Q_Mtep_indus_24_0 | Z44: 0.87612567 | AA44: 2.0341134 | AB44: 0 | AC44: 2.1331637 | AD44: 5.0434027
C45: Agriculture | D45: ER_AGRICULTURE_coal_1 | E45: ER_AGRICULTURE_oil_1 | F45: ER_AGRICULTURE_elec_1 | G45: ER_AGRICULTURE_gas_1 | H45: =VLOOKUP(D45,Résultats!$B$2:$AX$476,'T energie vecteurs'!K5,FALSE) -> 0 | I45: =VLOOKUP(E45,Résultats!$B$2:$AX$476,'T energie vecteurs'!K5,FALSE) -> 2.4153704 | J45: =VLOOKUP(F45,Résultats!$B$2:$AX$476,'T energie vecteurs'!K5,FALSE) -> 0.3211921 | K45: =VLOOKUP(G45,Résultats!$B$2:$AX$476,'T energie vecteurs'!K5,FALSE) -> 0.3382424 | L45: =SUM(H45:K45) -> 3.0748049 | N45: Agriculture | O45: ='[1]Bilan 2022 réel'!$T$46/11.63 -> 0.001651664 | P45: =SUM('[1]Bilan 2022 réel'!$T$41:$T$43)/11.63 -> 3.5697769 | Q45: ='[1]Bilan 2022 réel'!$T$13/11.63 -> 0.67291488 | R45: =('[1]Bilan 2022 réel'!$T$22+'[1]Bilan 2022 réel'!$T$30+SUM('[1]Bilan 2022 réel'!$T$36:$T$40)+SUM('[1]Bilan 2022 réel'!$T$44:$T$45)+'[1]Bilan 2022 réel'!$T$47)/11.63 -> 0.43996563 | S45: =SUM(O45:R45) -> 4.6843091 | U45: Agriculture | V45: ER_AGRICULTURE_coal_0 | W45: ER_AGRICULTURE_oil_0 | X45: ER_AGRICULTURE_elec_0 | Y45: ER_AGRICULTURE_gas_0 | Z45: 0 | AA45: 2.4340845 | AB45: 0.33748916 | AC45: 0.33184613 | AD45: 3.1034198
C46: Total Final Mtep | H46: =SUM(H37,H40:H42) -> 2.8723791 | I46: =SUM(I37,I40:I42) -> 63.87991 | J46: =SUM(J37,J40:J42) -> 39.433226 | K46: =SUM(K37,K40:K42) -> 44.487651 | L46: =SUM(H46:K46) -> 150.67317 | N46: Total Final Mtep | O46: =O37+O40+O41+O42+O45 -> 4.5640555 | P46: =P37+P40+P41+P42+P45 -> 64.295512 | Q46: =Q37+Q40+Q41+Q42+Q45 -> 35.657811 | R46: =R37+R40+R41+R42+R45 -> 42.318046 | S46: =SUM(O46:R46) -> 146.83542 | U46: Total Final Mtep | Z46: 3.2467538 | AA46: 66.617049 | AB46: 39.055991 | AC46: 43.967076 | AD46: 152.88687
C49: 2023 | H49: coal | I49: fuel and biofuel | J49: elec | K49: gas biogas biomass | L49: Total | N49: 2023 | O49: coal | P49: fuel and biofuel | Q49: elec | R49: gas biogas biomass | S49: Total | U49: 2023 | Z49: coal | AA49: fuel and biofuel | AB49: elec | AC49: gas biogas biomass | AD49: Total
...

Sheet T CO2
A1: Emissions CO2 (MtCO2)
A3: =Résultats!B1 -> TEND
A5: 2015 | B5: coal | C5: oil | D5: elec | E5: gas | F5: decarb | G5: Total
A6: Transport | B6: =B7+B8 -> 0 | C6: =C7+C8 -> 130.10436 | D6: =D7+D8 -> 0.59898157 | E6: =E7+E8 -> 0.38537939 | F6: =F7+F8 -> 0 | G6: =SUM(B6:F6) -> 131.08872 | K6: Cf. onglet "G emissions"
