Workbook
Name année: [1]Calcul_hypotheses!$D$6
Name anneeAffiche: #REF!
Name anneeAffiche: #REF!
Name anneeAffiche: #REF!
Name anneeDataSet: [2]Dataset!$H$2:$AH$2
Name calIntAnnee: [2]Calculs_intermediaires!$B$328:$AP$328
Name calIntcode: [2]Calculs_intermediaires!$B:$B
Name calIntData: [2]Calculs_intermediaires!$B:$AM
Name convktoeGWh: [2]Intro!$C$40
Name convMtoeGWh: [2]Intro!$C$41
Name dataSet: [2]Dataset!$H:$AH
Name odsAnnee: [2]Odyssee!$A$8:$AMJ$8
Name odsCode: [2]Odyssee!$A:$A
Name odsData: [2]Odyssee!$A:$AMJ
Name Résultats_annuels: [3]RES_annuels!$N$3:$BW$858
Name Résultats_annuels_années: [3]RES_annuels!$N$1:$AX$1
Name Résultats_annuels_choix: [3]RES_annuels!$D$3:$D$858
Name tagOutDataSet: [2]Dataset!$H:$H

Sheet Récap
V1: Combustibles coproduits
V3: 0
B4: Consommation | V4: 0
V5: 0
A7: AMS run 2 | B7: Sorties brutes | V7: 0
A8: Consommation | B8: 2015 | C8: 2019 | D8: 2020 | E8: 2021 | G8: 2025 | H8: 2030 | I8: 2035 | J8: 2040 | K8: 2045 | L8: 2050 | V8: 0
A9: Acier | B9: 12.452717 | C9: 12.240884 | D9: 12.189214 | E9: 12.137543 | G9: 11.930863 | H9: 11.672511 | I9: 11.592389 | J9: 11.512266 | K9: 11.432144 | L9: 11.352021 | V9: 0
A10: Alu | B10: 1.3666521 | C10: 1.4419886 | D10: 1.4608831 | E10: 1.4797776 | G10: 1.5553557 | H10: 1.6498282 | I10: 1.802221 | J10: 1.9546138 | K10: 2.1070066 | L10: 2.2593994
A11: Verre | B11: 4.930894 | C11: 4.8770764 | D11: 4.8560722 | E11: 4.835068 | G11: 4.7510511 | H11: 4.6460301 | I11: 4.3485869 | J11: 4.0511438 | K11: 3.7537006 | L11: 3.4562575 | V11: 0
A12: Clinker | B12: 13.307547 | C12: 12.468566 | D12: 12.251611 | E12: 12.034655 | G12: 11.166834 | H12: 10.082056 | I12: 9.4886314 | J12: 8.8952064 | K12: 8.3017814 | L12: 7.7083564 | V12: 0
A13: NH3 | B13: 2.1547623 | C13: 2.1062658 | D13: 2.0891688 | E13: 2.0720718 | G13: 2.0036836 | H13: 1.9181985 | I13: 1.7642275 | J13: 1.6102564 | K13: 1.4562854 | L13: 1.3023144 | V13: 0
A14: Cl2 | B14: 1.1275838 | C14: 1.1070518 | D14: 1.0992268 | E14: 1.0914018 | G14: 1.0601018 | H14: 1.0209768 | I14: 0.98722775 | J14: 0.95347868 | K14: 0.9197296 | L14: 0.88598053
A15: Ethylène | B15: 3.2018183 | C15: 3.1799101 | D15: 3.0946419 | E15: 3.0093738 | G15: 2.6683013 | H15: 2.2419606 | I15: 2.0976228 | J15: 1.953285 | K15: 1.8089472 | L15: 1.6646095 | V15: 0
A16: Papiers cartons | B16: 8.346785 | C16: 8.7020144 | D16: 8.7503332 | E16: 8.7986521 | G16: 8.9919273 | H16: 9.2335213 | I16: 9.5397952 | J16: 9.8460691 | K16: 10.152343 | L16: 10.458617 | V16: 0
A17: Sucre | B17: 3.7597692 | C17: 3.7715222 | D17: 3.7657544 | E17: 3.7599866 | G17: 3.7369153 | H17: 3.7080761 | I17: 3.6038129 | J17: 3.4995497 | K17: 3.3952865 | L17: 3.2910233 | V17: 0
A18: Total | B18: =SUM(B9:B17) -> 50.648529 | C18: =SUM(C9:C17) -> 49.89528 | D18: =SUM(D9:D17) -> 49.556905 | E18: =SUM(E9:E17) -> 49.218531 | G18: =SUM(G9:G17) -> 47.865032 | H18: =SUM(H9:H17) -> 46.173159 | I18: =SUM(I9:I17) -> 45.224514 | J18: =SUM(J9:J17) -> 44.275869 | K18: =SUM(K9:K17) -> 43.327224 | L18: =SUM(L9:L17) -> 42.378579
V19: 0
V20: 0
V21: 0
B22: Balance commerciale
V23: 0
V24: 0
D25: Nouvelle interpolation de 2025 à 2030 (basée sur 2019) qui donne des valeurs différentes du run 2 avant 2030 (permet de ne pas avoir la BC du clinker qui augente comme dans le run 2 jusqu'à 2030 puis diminue jusqu'à 2050 suite à l'arbitrage) | V25: 0
C26: Observé | D26: Repris de l'observé | G26: Projeté | H26: Projeté | I26: Projeté | J26: Projeté | K26: Projeté | L26: Projeté
B27: Rapport Production / Consommation | C27: 2019 | D27: 2020 | E27: 2021 | G27: 2025 | H27: 2030 | I27: 2035 | J27: 2040 | K27: 2045 | L27: 2050 | V27: 0
B28: Acier | C28: =C42/C9 -> 1.191735 | D28: =D42/D9 -> 0.95085804 | E28: =E42/E9 -> 1.1157222 | G28: =E28+(H28-E28)/9*4 -> 1.193179 | H28: 1.29 | I28: =$H28+($L28-$H28)/20*(I$27-$H$27) -> 1.305 | J28: =$H28+($L28-$H28)/20*(J$27-$H$27) -> 1.32 | K28: =$H28+($L28-$H28)/20*(K$27-$H$27) -> 1.335 | L28: 1.35 | V28: 0
B29: aluminium | C29: =C46/C10 -> 0.61997716 | D29: =D46/D10 -> 0.55993529 | E29: =E46/E10 -> 0.57778952 | G29: =E29+(H29-E29)/9*4 -> 0.6232164 | H29: 0.68 | I29: =$H29+($L29-$H29)/20*(I$27-$H$27) -> 0.7225 | J29: =$H29+($L29-$H29)/20*(J$27-$H$27) -> 0.765 | K29: =$H29+($L29-$H29)/20*(K$27-$H$27) -> 0.8075 | L29: 0.85 | V29: 0
B30: clinker | C30: =C51/C12 -> 1.0374835 | D30: =D51/D12 -> 0.9607754 | E30: =E51/E12 -> 1.0172355 | G30: 1.05 | H30: 1.21 | I30: =$H30+($L30-$H30)/20*(I$27-$H$27) -> 1.1575 | J30: =$H30+($L30-$H30)/20*(J$27-$H$27) -> 1.105 | K30: =$H30+($L30-$H30)/20*(K$27-$H$27) -> 1.0525 | L30: 1
B31: verre | C31: =C52/C11 -> 1.1766629 | D31: =D52/D11 -> 1.0395698 | E31: =E52/E11 -> 1.1730436 | G31: =E31+(H31-E31)/9*4 -> 1.1708664 | H31: 1.168145 | I31: 1.168145 | J31: 1.168145 | K31: 1.168145 | L31: 1.168145 | V31: Combustibles coproduits
B32: ammoniac | C32: =C50/C13 -> 0.5102916 | D32: =D50/D13 -> 0.47861762 | E32: =E50/E13 -> 0.44230767 | G32: =E32+(H32-E32)/9*4 -> 0.53461537 | H32: 0.65 | I32: =$H32+($L32-$H32)/20*(I$27-$H$27) -> 0.6875 | J32: =$H32+($L32-$H32)/20*(J$27-$H$27) -> 0.725 | K32: =$H32+($L32-$H32)/20*(K$27-$H$27) -> 0.7625 | L32: 0.8 | V32: 0
B33: Chlore | C33: =C49/C14 -> 0.26852936 | D33: =D49/D14 -> 0.25325011 | E33: =E49/E14 -> 0.30573709 | G33: =C33 -> 0.26852936 | H33: =G33 -> 0.26852936 | I33: =$H33+($L33-$H33)/20*(I$27-$H$27) -> 0.26852936 | J33: =$H33+($L33-$H33)/20*(J$27-$H$27) -> 0.26852936 | K33: =$H33+($L33-$H33)/20*(K$27-$H$27) -> 0.26852936 | L33: =$C$33 -> 0.26852936 | M33: BC cste comme dans le run 2, mais à un niveau différent du fait du changement de périmètre de la prod historique fournie par le Citepa | V33: 0
B34: Ethylène | C34: =C48/C15 -> 0.73594394 | D34: =D48/D15 -> 0.73441966 | E34: =E48/E15 -> 0.76887807 | G34: =E34 -> 0.76887807 | H34: 0.92 | I34: =$H34+($L34-$H34)/20*(I$27-$H$27) -> 0.94 | J34: =$H34+($L34-$H34)/20*(J$27-$H$27) -> 0.96 | K34: =$H34+($L34-$H34)/20*(K$27-$H$27) -> 0.98 | L34: 1 | V34: 0
B35: Sucre | C35: =C54/C17 -> 1.3175052 | D35: =D54/D17 -> 0.91482334 | E35: =E54/E17 -> 1.2101107 | G35: =E35+(H35-E35)/9*4 -> 1.256781 | H35: 1.3151189 | I35: =$H35+($L35-$H35)/20*(I$27-$H$27) -> 1.3157154 | J35: =$H35+($L35-$H35)/20*(J$27-$H$27) -> 1.316312 | K35: =$H35+($L35-$H35)/20*(K$27-$H$27) -> 1.3169086 | L35: =C35 -> 1.3175052
B36: papier | C36: =C53/C16 -> 0.84152929 | D36: =D53/D16 -> 0.7854558 | E36: =E53/E16 -> 0.8361508 | G36: 0.795 | H36: 0.795 | I36: =$H36+($L36-$H36)/20*(I$27-$H$27) -> 0.77125 | J36: =$H36+($L36-$H36)/20*(J$27-$H$27) -> 0.7475 | K36: =$H36+($L36-$H36)/20*(K$27-$H$27) -> 0.72375 | L36: 0.7 | M36: balance commerciale diminuée pour obtenir une production de pâte à papier stable (suite au retour de Aurélie Lécureuil et de Anne Menez de la DGE), cela ne reflète pas forcément la réalité de la balance commerciale car l'augmentation de la consommation modélisée par Pepito semble ne pas prendre en compte l'effet du recyclage : on pourrait avoir une consommation de pâte à papier primaire stable et une hausse de la consommation de papier recyclé | V36: =#REF!/(#REF!+#REF!) -> #REF!
H37: Valeurs du run 2 | V37: =V36/(V36+H36)*#REF! -> #REF!
B38: Production | V38: =V37/(V37+H37)*#REF! -> #REF!
A39: Attention au périmètre des productions, recyclage inclus ou non
B40: Productions arbitrées AMS run 3 | C40: Observé | D40: Repris de l'observé | H40: Projeté | I40: Projeté | J40: Projeté | K40: Projeté | L40: Projeté | M40: Projeté | N40: Focus acier 2026-2029 | V40: 0
B41: Production (Mt) | C41: 2019 | D41: 2020 | E41: 2021 | F41: 2022 | G41: 2023 | H41: 2025 | I41: 2030 | J41: 2035 | K41: 2040 | L41: 2045 | M41: 2050 | N41: 2026 | O41: 2027 | P41: 2028 | Q41: 2029 | V41: 0
B42: Acier | C42: ='Production historique IGCE'!F3 -> 14.58789 | D42: ='Production historique IGCE'!G3 -> 11.590212 | E42: ='Production historique IGCE'!H3 -> 13.542126 | F42: ='Production historique IGCE'!I3 -> 12.217998 | G42: ='Production historique IGCE'!J3 -> 10.010885 | H42: =G28*G9 -> 14.235654 | I42: =H28*H9 -> 15.05754 | J42: =I28*I9 -> 15.128067 | K42: =J28*J9 -> 15.196191 | L42: =K28*K9 -> 15.261912 | M42: =L28*L9 -> 15.325229 | N42: =$H42+($I42-$H42)/5*(N41-$H$41) -> 14.400031 | O42: =$H42+($I42-$H42)/5*(O41-$H$41) -> 14.564408 | P42: =$H42+($I42-$H42)/5*(P41-$H$41) -> 14.728786 | Q42: =$H42+($I42-$H42)/5*(Q41-$H$41) -> 14.893163 | V42: 0
...

Sheet Substitutions NE autres chimies
A1: Substitutions NE autres chimies
B2: 2021 | C2: 2030 | D2: 2040 | E2: 2050 | F2: Source
A3: Part du gaz destiné à la production d'H2 en historique | B3: 0.4 | F3: DGE (Tom Gagnebet)
A4: Quantité de gaz non énergétique | B4: =5558.50477255434/1000 -> 5.5585048
A5: Quantité de gaz vaporeformage 2021 (TWh) | B5: =B3*B4 -> 2.2234019 | E5: =E7/0.72 -> 0
A6: Rendement PCI H2/gaz vaporeformage | B6: 0.72 | F6: AFHYPAC | G6: https://s3.production.france-hydrogene.org/uploads/sites/4/2021/11/Fiche_203.1.1_20-_20Production_20_C3_A0_20partir_20de_20fossiles_20-_20rev_20nov2019_20Th_20A.pdf
A7: quantité d'H2 vaporéformé en 2021 | B7: =B5*B6 -> 1.6008494 | E7: 0 | F7: prise en compte de l'augmentation des besoins en H2 proportionnellement à la production
A8: quantité d'H2 électrolysé pré run 3 v1 | B8: 0 | C8: 0 | E8: =3761.05133095219/1000 -> 3.7610513
A9: quantité d'H2 électrolysé pré run 3 v2 | E9: =$B7*Récap!K87/Récap!$E87 -> 2.0392858 | F9: 2,2TWh au final dans Enermed pré run 3 v2
A10: Part H2 pré run 3 v1 | C10: 0 | D10: 0.2 | E10: 0.4
A11: Part H2 pré run 3 v2 | C11: 0 | D11: =AVERAGE(C11,E11) -> 0.10844233 | E11: =E9/E8*E10 -> 0.21688465

Sheet Production historique IGCE
A2: Production (Mt) | B2: 2015 | C2: 2016 | D2: 2017 | E2: 2018 | F2: 2019 | G2: 2020 | H2: 2021 | I2: 2022 | J2: 2023 | K2: source
A3: Acier | B3: =SUM(B4:B6) -> 15.08646 | C3: 14.45 | D3: 15.6 | E3: =SUM(E4:E6) -> 15.449049 | F3: =SUM(F4:F6) -> 14.58789 | G3: =SUM(G4:G6) -> 11.590212 | H3: =SUM(H4:H6) -> 13.542126 | I3: =SUM(I4:I6) -> 12.217998 | J3: =SUM(J4:J6) -> 10.010885 | K3: CITEPA
A4: dont haut fourneaux | B4: =F44/1000 -> 9.985539 | C4: =C3-C5 -> 9.59 | D4: =D3-D5 -> 10.73 | E4: =G44/1000 -> 10.598281 | F4: =H44/1000 -> 10.130063 | G4: =I44/1000 -> 7.872834 | H4: =J44/1000 -> 8.937677 | I4: =K44/1000 -> 8.222646 | J4: =L44/1000 -> 6.413039 | K4: CITEPA
A5: dont procédé électrique | B5: =F45/1000 -> 5.1009214 | C5: 4.86 | D5: 4.87 | E5: =G45/1000 -> 4.8507678 | F5: =H45/1000 -> 4.4578274 | G5: =I45/1000 -> 3.7173779 | H5: =J45/1000 -> 4.6044492 | I5: =K45/1000 -> 3.9953518 | J5: =L45/1000 -> 3.5978462 | K5: CITEPA
A6: dont DRI | B6: 0 | C6: 0 | D6: 0 | E6: 0 | F6: 0 | G6: 0 | H6: 0 | I6: 0 | J6: 0
A7: Aluminium | B7: 0.893 | C7: 0.918 | D7: 0.942 | E7: 0.878 | F7: 0.894 | G7: 0.818 | H7: 0.855 | I7: =H7*I9/H9 -> 0.78249187 | J7: =I7*J9/I9 -> 0.74907454 | K7: BNR 2012-2021, valeur 2022 et 2023 calculée à partir du taux de variation 2021-2022 du CITEPA
A8: dont aluminium recyclé | B8: 0.472 | C8: 0.488 | D8: 0.508 | E8: 0.496 | F8: =0.292+0.184 -> 0.476 | G8: =0.251+0.15 -> 0.401 | H8: =0.282+0.143 -> 0.425 | I8: =H8*I7/H7 -> 0.38895795 | J8: =I8*J7/I7 -> 0.372347 | K8: BNR 2012-2021, valeur 2022 et 2023 à partir du taux de variation 2021-2022 de l'aluminium
A9: Aluminium | B9: =B11+F51/1000000 -> 0.59606631 | C9: 0.62261217 | D9: 0.6369988 | E9: =E11+G51/1000000 -> 0.583051 | F9: =F11+H51/1000000 -> 0.60604568 | G9: =G11+I51/1000000 -> 0.54386673 | H9: =SUM(H10:H11) -> 0.5774852 | I9: =SUM(I10:I11) -> 0.52851166 | J9: =SUM(J10:J11) -> 0.50594089 | K9: CITEPA
A10: dont 1ère fusion | B10: =B9-B11 -> 0.41880998 | C10: =C9-C11 -> 0.42861217 | D10: =D9-D11 -> 0.4319988 | E10: =E9-E11 -> 0.382927 | F10: =F9-F11 -> 0.4219487 | G10: =G9-G11 -> 0.41854734 | H10: =J51/1000000 -> 0.42623765 | I10: =K51/1000000 -> 0.39181055 | J10: =L51/1000000 -> 0.3794109 | K10: CITEPA
A11: dont 2e fusion | B11: =F52/1000000 -> 0.17725633 | C11: 0.194 | D11: 0.205 | E11: =G52/1000000 -> 0.200124 | F11: =H52/1000000 -> 0.18409698 | G11: =I52/1000000 -> 0.12531939 | H11: =J52/1000000 -> 0.15124755 | I11: =K52/1000000 -> 0.13670111 | J11: =L52/1000000 -> 0.12652999 | K11: CITEPA
A12: Ethylène | B12: =F72/1000000 -> 2.5145758 | C12: 2.24 | D12: 2.59 | E12: =G72/1000000 -> 2.158317 | F12: =H72/1000000 -> 2.3402355 | G12: =I72/1000000 -> 2.2727659 | H12: =J72/1000000 -> 2.3138415 | I12: =K72/1000000 -> 1.626623 | J12: =L72/1000000 -> 1.8421029 | K12: CITEPA
A13: Chlore | B13: =F79/1000000 -> 0.613219 | C13: =B13+(E13-B13)/3*1 -> 0.50602933 | D13: =B13+(E13-B13)/3*2 -> 0.39883967 | E13: =G79/1000000 -> 0.29165 | F13: =H79/1000000 -> 0.2972759 | G13: =I79/1000000 -> 0.2783793 | H13: =J79/1000000 -> 0.333682 | I13: =K79/1000000 -> 0.251754 | J13: =L79/1000000 -> 0.255626 | K13: CITEPA | L13: (erreur auparavant, monochlorure de vinyle à la place)
A14: Ammoniac | B14: =F65/1000000 -> 1.068785 | C14: 1.1 | D14: 0.91 | E14: =G65/1000000 -> 1.112167 | F14: =H65/1000000 -> 1.0748098 | G14: =I65/1000000 -> 0.999913 | H14: =J65/1000000 -> 0.91649323 | I14: =K65/1000000 -> 0.85601795 | J14: =L65/1000000 -> 0.69479755 | K14: CITEPA
A15: Clinker | B15: =F30/1000 -> 12.540861 | C15: 12.67 | D15: 12.36 | E15: =G30/1000 -> 12.844855 | F15: =H30/1000 -> 12.935931 | G15: =I30/1000 -> 11.771046 | H15: =J30/1000 -> 12.242079 | I15: =K30/1000 -> 12.044779 | J15: =L30/1000 -> 10.672455 | K15: CITEPA
A16: Verre | B16: =F37/1000000 -> 5.5025794 | C16: 5.168369 | D16: 5.5996366 | E16: =G37/1000000 -> 5.7240104 | F16: =H37/1000000 -> 5.7386751 | G16: =I37/1000000 -> 5.048226 | H16: =J37/1000000 -> 5.6717456 | I16: =K37/1000000 -> 5.5682739 | J16: =L37/1000000 -> 5.0170238 | K16: CITEPA
A17: Papier cartons | B17: 7.986 | C17: 7.984 | D17: 8.021 | E17: 7.87 | F17: 7.323 | G17: 6.873 | H17: 7.357 | I17: =7091800/1000000 -> 7.0918 | J17: =6135600/1000000 -> 6.1356 | K17: BNR 2012-2021 et ADEME pour 2022 et 2023 (venant de rapports statistiques Copacel)
A18: Papier | B18: =F58/1000 -> 1.44732 | C18: 1.423 | D18: 1.406 | E18: =G58/1000 -> 1.284535 | F18: =H58/1000 -> 1.322728 | G18: =I58/1000 -> 1.351074 | H18: =J58/1000 -> 1.309766 | I18: =K58/1000 -> 1.318604 | J18: =L58/1000 -> 1.211874 | K18: CITEPA (pâte à papier) - pas cohérent avec BNR car CITEPA ne prend en compte que la pâte à papier (kraft ou bisulfite)
A19: Sucre | B19: =F86/1000 -> 4.515 | C19: 4.68 | D19: 6.24 | E19: =G86/1000 -> 5.092 | F19: =H86/1000 -> 4.969 | G19: =I86/1000 -> 3.445 | H19: =J86/1000 -> 4.55 | I19: =K86/1000 -> 3.95 | J19: =L86/1000 -> 4.225 | K19: CITEPA
A21: Productions industrielles utilisées dans l'inventaire CITEPA édition 2024 :
A27: Clinker (kt) :
B29: 1990 | C29: 2000 | D29: 2005 | E29: 2010 | F29: 2015 | G29: 2018 | H29: 2019 | I29: 2020 | J29: 2021 | K29: 2022 | L29: 2023
A30: Prod (kt) | B30: 20854 | C30: 16323 | D30: 17328.763 | E30: 14982.373 | F30: 12540.861 | G30: 12844.855 | H30: 12935.931 | I30: 11771.046 | J30: 12242.079 | K30: 12044.779 | L30: 10672.455
A34: Verre (t) :
B36: 1990 | C36: 2000 | D36: 2005 | E36: 2010 | F36: 2015 | G36: 2018 | H36: 2019 | I36: 2020 | J36: 2021 | K36: 2022 | L36: 2023
A37: Prod totale (t) | B37: 5266354 | C37: 6216566 | D37: 6053081.5 | E37: 5267170.2 | F37: 5502579.4 | G37: 5724010.5 | H37: 5738675.1 | I37: 5048226 | J37: 5671745.6 | K37: 5568273.9 | L37: 5017023.8
A38: Verre neuf (t) (hors calcin externe) | B38: 4333354 | C38: 4227566 | D38: 3969081.5 | E38: 2921170.2 | F38: 3161579.4 | G38: 3468010.5 | H38: 3403865.1 | I38: 3012226 | J38: 3512474.6 | K38: 3477611.9 | L38: 2747226.8
A41: Acier (kt) :
B43: 1990 | C43: 2000 | D43: 2005 | E43: 2010 | F43: 2015 | G43: 2018 | H43: 2019 | I43: 2020 | J43: 2021 | K43: 2022 | L43: 2023
A44: Acier O2 (kt) | B44: 13625.295 | C44: 12755.319 | D44: 12349.004 | E44: 10017.557 | F44: 9985.539 | G44: 10598.281 | H44: 10130.063 | I44: 7872.834 | J44: 8937.677 | K44: 8222.646 | L44: 6413.039
A45: Acier élec (kt) | B45: 5448 | C45: 8460 | D45: 7308 | E45: 5728.919 | F45: 5100.9214 | G45: 4850.7678 | H45: 4457.8274 | I45: 3717.3779 | J45: 4604.4492 | K45: 3995.3518 | L45: 3597.8462
A48: Aluminium (t) :
B50: 1990 | C50: 2000 | D50: 2005 | E50: 2010 | F50: 2015 | G50: 2018 | H50: 2019 | I50: 2020 | J50: 2021 | K50: 2022 | L50: 2023
A51: 1ère fusion (t) | B51: 325900 | C51: 437718 | D51: 442588 | E51: 357546 | F51: 418809.98 | G51: 382927 | H51: 421948.7 | I51: 418547.34 | J51: 426237.65 | K51: 391810.55 | L51: 379410.9
A52: 2nde fusion (t) | B52: 224700 | C52: 259788 | D52: 222688 | E52: 199343.16 | F52: 177256.33 | G52: 200124 | H52: 184096.98 | I52: 125319.39 | J52: 151247.55 | K52: 136701.11 | L52: 126529.99
A55: Pâte à papier (kt) :
B57: 1990 | C57: 2000 | D57: 2005 | E57: 2010 | F57: 2015 | G57: 2018 | H57: 2019 | I57: 2020 | J57: 2021 | K57: 2022 | L57: 2023
A58: Prod (kt) | B58: 1644.8 | C58: 1817.4 | D58: 1927.003 | E58: 1369.537 | F58: 1447.32 | G58: 1284.535 | H58: 1322.728 | I58: 1351.074 | J58: 1309.766 | K58: 1318.604 | L58: 1211.874
A62: Ammoniac (t) :
B64: 1990 | C64: 2000 | D64: 2005 | E64: 2010 | F64: 2015 | G64: 2018 | H64: 2019 | I64: 2020 | J64: 2021 | K64: 2022 | L64: 2023
A65: Prod (t) | B65: 1927800 | C65: 1854457.1 | D65: 1474656.9 | E65: 955951 | F65: 1068785 | G65: 1112167 | H65: 1074809.8 | I65: 999913 | J65: 916493.23 | K65: 856017.95 | L65: 694797.55
...

Sheet A renseigner
B1: Balance commerciale
B4: AMS | C4: Observé | D4: Repris de l'observé | F4: Projeté | G4: Projeté | H4: Projeté | I4: Projeté | J4: Projeté | K4: Projeté
B5: Production (Mt) | C5: 2019 | D5: 2020 | E5: 2021 | F5: 2025 | G5: 2030 | H5: 2035 | I5: 2040 | J5: 2045 | K5: 2050
B6: Acier | C6: =Récap!C42 -> 14.58789 | D6: =Récap!D42 -> 11.590212 | E6: =Récap!E42 -> 13.542126 | F6: =Récap!H42 -> 14.235654 | G6: =Récap!I42 -> 15.05754 | H6: =Récap!J42 -> 15.128067 | I6: =Récap!K42 -> 15.196191 | J6: =Récap!L42 -> 15.261912 | K6: =Récap!M42 -> 15.325229
B7: dont haut fourneaux | C7: =Récap!C43 -> 10.130063 | D7: =Récap!D43 -> 7.872834 | E7: =Récap!E43 -> 8.937677 | F7: =Récap!H43 -> 8.8125479 | G7: =Récap!I43 -> 5.2457955 | H7: =Récap!J43 -> 3.2441297 | I7: =Récap!K43 -> 3.2790028 | J7: =Récap!L43 -> 0 | K7: =Récap!M43 -> 0
B8: dont procédé électrique | C8: =Récap!C44 -> 4.4578274 | D8: =Récap!D44 -> 3.7173779 | E8: =Récap!E44 -> 4.6044492 | F8: =Récap!H44 -> 5.4231064 | G8: =Récap!I44 -> 6.8117441 | H8: =Récap!J44 -> 7.3839377 | I8: =Récap!K44 -> 7.4171887 | J8: =Récap!L44 -> 9.2619118 | K8: =Récap!M44 -> 9.3252285
B9: dont DRI | C9: =Récap!C45 -> 0 | D9: =Récap!D45 -> 0 | E9: =Récap!E45 -> 0 | F9: =Récap!H45 -> 0 | G9: =Récap!I45 -> 3 | H9: =Récap!J45 -> 4.5 | I9: =Récap!K45 -> 4.5 | J9: =Récap!L45 -> 6 | K9: =Récap!M45 -> 6
B10: Aluminium | C10: =Récap!C46 -> 0.894 | D10: =Récap!D46 -> 0.818 | E10: =Récap!E46 -> 0.855 | F10: =Récap!H46 -> 0.96932316 | G10: =Récap!I46 -> 1.1218832 | H10: =Récap!J46 -> 1.3021047 | I10: =Récap!K46 -> 1.4952796 | J10: =Récap!L46 -> 1.7014078 | K10: =Récap!M46 -> 1.9204895
B11: dont aluminium recyclé | C11: =Récap!C47 -> 0.476 | D11: =Récap!D47 -> 0.401 | E11: =Récap!E47 -> 0.425 | F11: =Récap!H47 -> 0.54884942 | G11: =Récap!I47 -> 0.67312992 | H11: =Récap!J47 -> 0.81381543 | I11: =Récap!K47 -> 0.97193172 | J11: =Récap!L47 -> 1.1484503 | K11: =Récap!M47 -> 1.3443426
B12: Ethylène | C12: =Récap!C48 -> 2.3402355 | D12: =Récap!D48 -> 2.2727659 | E12: =Récap!E48 -> 2.3138415 | F12: =Récap!H48 -> 2.0515983 | G12: =Récap!I48 -> 2.0626038 | H12: =Récap!J48 -> 1.9717655 | I12: =Récap!K48 -> 1.8751536 | J12: =Récap!L48 -> 1.7727683 | K12: =Récap!M48 -> 1.6646095
B13: Chlore | C13: =Récap!C49 -> 0.2972759 | D13: =Récap!D49 -> 0.2783793 | E13: =Récap!E49 -> 0.333682 | F13: =Récap!H49 -> 0.28466846 | G13: =Récap!I49 -> 0.27365818 | H13: =Récap!J49 -> 0.26509964 | I13: =Récap!K49 -> 0.25603702 | J13: =Récap!L49 -> 0.2469744 | K13: =Récap!M49 -> 0.23791178
B14: Ammoniac | C14: =Récap!C50 -> 1.0748098 | D14: =Récap!D50 -> 0.999913 | E14: =Récap!E50 -> 0.91649323 | F14: =Récap!H50 -> 1.0712001 | G14: =Récap!I50 -> 1.246829 | H14: =Récap!J50 -> 1.2129064 | I14: =Récap!K50 -> 1.1674359 | J14: =Récap!L50 -> 1.1104176 | K14: =Récap!M50 -> 1.0418515
B15: Clinker | C15: =Récap!C51 -> 12.935931 | D15: =Récap!D51 -> 11.771046 | E15: =Récap!E51 -> 12.242079 | F15: =Récap!H51 -> 11.725175 | G15: =Récap!I51 -> 12.199288 | H15: =Récap!J51 -> 10.983091 | I15: =Récap!K51 -> 9.8292031 | J15: =Récap!L51 -> 8.7376249 | K15: =Récap!M51 -> 7.7083564
B16: Verre | C16: =Récap!C52 -> 5.7386751 | D16: =Récap!D52 -> 5.048226 | E16: =Récap!E52 -> 5.6717456 | F16: =Récap!H52 -> 5.5628464 | G16: =Récap!I52 -> 5.4272367 | H16: =Récap!J52 -> 5.07978 | I16: =Récap!K52 -> 4.7323233 | J16: =Récap!L52 -> 4.3848666 | K16: =Récap!M52 -> 4.0374099
B17: Papier | C17: =Récap!C53 -> 7.323 | D17: =Récap!D53 -> 6.873 | E17: =Récap!E53 -> 7.357 | F17: =Récap!H53 -> 7.1485822 | G17: =Récap!I53 -> 7.3406495 | H17: =Récap!J53 -> 7.357567 | I17: =Récap!K53 -> 7.3599366 | J17: =Récap!L53 -> 7.3477582 | K17: =Récap!M53 -> 7.3210317
B18: Sucre | C18: =Récap!C54 -> 4.969 | D18: =Récap!D54 -> 3.445 | E18: =Récap!E54 -> 4.55 | F18: =Récap!H54 -> 4.6964841 | G18: =Récap!I54 -> 4.8765609 | H18: =Récap!J54 -> 4.7415923 | I18: =Récap!K54 -> 4.6064994 | J18: =Récap!L54 -> 4.471282 | K18: =Récap!M54 -> 4.3359403
B20: TOTAL | C20: =SUM(C6,C10,C12:C18) -> 50.160818 | D20: =SUM(D6,D10,D12:D18) -> 43.096543 | E20: =SUM(E6,E10,E12:E18) -> 47.781968 | F20: =SUM(F6,F10,F12:F18) -> 47.745532 | G20: =SUM(G6,G10,G12:G18) -> 49.606249 | H20: =SUM(H6,H10,H12:H18) -> 48.041974 | I20: =SUM(I6,I10,I12:I18) -> 46.51806 | J20: =SUM(J6,J10,J12:J18) -> 45.035012 | K20: =SUM(K6,K10,K12:K18) -> 43.592829
B22: Total run1 | C22: 50.771132 | D22: 43.535749 | E22: 44.535749 | F22: 50.440979 | G22: 49.219427 | H22: 47.038856 | I22: 44.943856 | J22: 42.896681 | K22: 40.85488
B23: Diffus
B27: Coefficient de décorrélation VA / production physique
B29: Indice 2019 | C29: 2019 | D29: 2020 | E29: 2021 | F29: 2025 | G29: 2030 | H29: 2035 | I29: 2040 | J29: 2045 | K29: 2050
B30: Métaux primaires | C30: 1 | D30: 0.99354839 | E30: 1 | F30: 0.98 | G30: 0.96 | H30: 0.94 | I30: 0.93 | J30: 0.92 | K30: 0.92
B31: Chimie | C31: 1 | D31: 0.99354839 | E31: 1 | F31: 0.99 | G31: 0.98 | H31: 0.96 | I31: 0.94 | J31: 0.92 | K31: 0.9
B32: Minéraux non-métalliques | C32: 1 | D32: 0.99354839 | E32: 1 | F32: 0.99 | G32: 0.98 | H32: 0.955 | I32: 0.93 | J32: 0.915 | K32: 0.9
B33: IAA | C33: 1 | D33: 0.99354839 | E33: 1 | F33: 0.983 | G33: 0.95 | H33: 0.925 | I33: 0.9 | J33: 0.9 | K33: 0.9
B34: Equipements | C34: 1 | D34: 0.99354839 | E34: 1 | F34: 0.983 | G34: 0.95 | H34: 0.925 | I34: 0.9 | J34: 0.875 | K34: 0.85
B35: Autres (textile, etc.) | C35: 1 | D35: 0.99354839 | E35: 1 | F35: 0.96129032 | G35: 0.92903226 | H35: 0.89677419 | I35: 0.86451613 | J35: 0.83225806 | K35: 0.8
B36: Total diffus | C36: 1 | D36: 0.99354839 | E36: 1 | F36: 0.9819561 | G36: 0.95680443 | H36: 0.93240837 | I36: 0.90944275 | J36: 0.89277507 | K36: 0.87752987
B37: Construction | C37: 1 | D37: 1 | E37: 1 | F37: 1 | G37: 1 | H37: 1 | I37: 1 | J37: 1 | K37: 1
B39: Production physique | C39: 2019 | D39: 2020 | E39: 2021 | F39: 2025 | G39: 2030 | H39: 2035 | I39: 2040 | J39: 2045 | K39: 2050 | L39: Sortie
B40: Métaux primaires | C40: 25.805 | D40: 22.681716 | E40: 24.457 | F40: 25.256465 | G40: 25.999582 | H40: 25.792603 | I40: 27.173359 | J40: 29.152709 | K40: 31.637862
B41: Chimie | C41: 47.175 | D41: 45.592942 | E41: 46.328 | F41: 47.193941 | G41: 49.753115 | H41: 50.176378 | I41: 53.132595 | J41: 56.770454 | K41: 60.357468
B42: Minéraux non-métalliques | C42: 8.359 | D42: 7.4158452 | E42: 8.172 | F42: 8.4325674 | G42: 8.5533775 | H42: 8.5034645 | I42: 8.6816195 | J42: 9.0563404 | K42: 9.526558
B43: IAA | C43: 45.598 | D43: 43.804555 | E43: 44.859 | F43: 46.746123 | G43: 48.929058 | H43: 51.121043 | I43: 54.054345 | J43: 58.743109 | K43: 63.611128
B44: Equipements | C44: 63.615 | D44: 49.485665 | E44: 52.09 | F44: 54.610634 | G44: 57.416369 | H44: 60.121795 | I44: 63.484649 | J44: 67.302902 | K44: 71.385616
B45: Autres (textile, etc.) | C45: 23.724 | D45: 22.1144 | E45: 23.781 | F45: 24.381141 | G45: 25.634135 | H45: 26.610256 | I45: 27.840374 | J45: 29.225336 | K45: 30.67309
B46: Total diffus | C46: 214.276 | D46: 191.09512 | E46: 199.687 | F46: 206.63582 | G46: 216.34704 | H46: 222.42227 | I46: 234.52717 | J46: 250.50895 | K46: 267.68291
B47: Construction | C47: 114.882 | D47: 101.443 | E47: 108.227 | F47: 111.90446 | G47: 111.60903 | H47: 110.28798 | I47: 110.67153 | J47: 112.51429 | K47: 116.70087
B50: Leviers
B53: Mix énergétique
...

Sheet Estimations consommations énerg
B1: Estimation des consommations énergétiques en 2030 à partir des hypothèses (des petites différences peuvent exister avec la modélisation EnerMED) | H1: Hypothèses | Z1: Mix run 2 (ancien mix)
E2: Attention, la variation de production est calculée par rapport à 2019 et pas 2021
B3: Sidérurgie HF | C3: 2021 | D3: 2030 | E3: 2050 | F3: Hausse | I3: Matrice de passage | J3: Charbon | K3: Coke | L3: Produits pétroliers raffinés | M3: Gaz de réseau | N3: Biomasse solide | O3: Déchets | P3: Biocarburants | Q3: Gaz renouvelable | R3: Chaleur de l'environnement | S3: Solaire thermique et géothermie | T3: Électricité | U3: Electricité PAC | V3: Chaleur vendue | W3: Hydrogène (consommation finale)
B4: Electricité | C4: 0 | D4: {=MMULT(J4:W16,TRANSPOSE('A renseigner'!E59:R59))*C17*'A renseigner'!E154*'A renseigner'!G7/'A renseigner'!C7} -> 0 | E4: {=MMULT(J4:W16,TRANSPOSE('A renseigner'!E60:R60))*C17*'A renseigner'!G154*'A renseigner'!K7/'A renseigner'!C7} -> 0 | F4: =D4-C4 -> 0 | I4: Electricité | J4: 0 | K4: 0 | L4: 0 | M4: 0 | N4: 0 | O4: 0 | P4: 0 | Q4: 0 | R4: 0 | S4: 0 | T4: 1 | U4: 0 | V4: 0 | W4: 0 | AA4: Mix énergétique | AD4: Charbon | AE4: Coke | AF4: Produits pétroliers raffinés | AG4: Gaz de réseau | AH4: Biomasse solide | AI4: Déchets | AJ4: Biocarburants | AK4: Gaz renouvelable | AL4: Chaleur de l'environnement | AM4: Solaire thermique et géothermie | AN4: Électricité | AO4: Electricité PAC | AP4: Chaleur vendue | AQ4: Hydrogène (consommation finale) | AR4: Total
B5: Electricité PAC | C5: 0 | D5: 0 | E5: 0 | F5: =D5-C5 -> 0 | I5: Electricité PAC | J5: 0 | K5: 0 | L5: 0 | M5: 0 | N5: 0 | O5: 0 | P5: 0 | Q5: 0 | R5: 0 | S5: 0 | T5: 0 | U5: 1 | V5: 0 | W5: 0 | AA5: Métaux primaires
B6: Produits liquides (fossile, bio, et synthétique) | C6: 0 | D6: 0 | E6: 0 | F6: =D6-C6 -> 0 | I6: Produits liquides (fossile, bio, et synthétique) | J6: 0 | K6: 0 | L6: 1 | M6: 0 | N6: 0 | O6: 0 | P6: 0 | Q6: 0 | R6: 0 | S6: 0 | T6: 0 | U6: 0 | V6: 0 | W6: 0 | AA6: Dont sidérurgie (hauts fourneaux) | AB6: 2021 | AC6: % | AD6: 0.59926162 | AE6: 0.40073838 | AF6: 0 | AG6: 0 | AH6: 0 | AI6: 0 | AJ6: 0 | AK6: 0 | AL6: 0 | AM6: 0 | AN6: 0 | AO6: 0 | AP6: 0 | AQ6: 0 | AR6: 1 | AT6: 0.59926162 | AU6: 0.40073838 | AV6: 0 | AW6: 0 | AX6: 0 | AY6: 0 | AZ6: 0 | BA6: 0 | BB6: 0 | BC6: 0 | BD6: 0 | BE6: 0 | BF6: 0 | BG6: 0 | BI6: =AT6=AD6 -> TRUE | BJ6: =AU6=AE6 -> TRUE | BK6: =AV6=AF6 -> TRUE | BL6: =AW6=AG6 -> TRUE | BM6: =AX6=AH6 -> TRUE | BN6: =AY6=AI6 -> TRUE | BO6: =AZ6=AJ6 -> TRUE | BP6: =BA6=AK6 -> TRUE | ... BV6: =BG6=AQ6 -> TRUE
B7: Gaz de réseau | C7: 0 | D7: 0 | E7: 0 | F7: =D7-C7 -> 0 | I7: Gaz de réseau | J7: 0 | K7: 0 | L7: 0 | M7: =1-M16 -> 0.85 | N7: 0 | O7: 0 | P7: 0 | Q7: 0 | R7: 0 | S7: 0 | T7: 0 | U7: 0 | V7: 0 | W7: 0 | AA7: Dont sidérurgie (hauts fourneaux) | AB7: 2030 | AC7: % | AD7: 0.3782048 | AE7: 0.5617952 | AF7: 0 | AG7: 0 | AH7: 0.03 | AI7: 0.03 | AJ7: 0 | AK7: 0 | AL7: 0 | AM7: 0 | AN7: 0 | AO7: 0 | AP7: 0 | AQ7: 0 | AR7: 1 | AT7: 0.4082048 | AU7: 0.5917952 | AV7: 0 | AW7: 0 | AX7: 0.015 | AY7: 0 | AZ7: 0 | BA7: 0 | BB7: 0 | BC7: 0 | BD7: 0 | BE7: 0 | BF7: 0 | BG7: 0 | BI7: =AT7=AD7 -> FALSE | BJ7: =AU7=AE7 -> FALSE | BK7: =AV7=AF7 -> TRUE | BL7: =AW7=AG7 -> TRUE | BM7: =AX7=AH7 -> FALSE | BN7: =AY7=AI7 -> FALSE | BO7: =AZ7=AJ7 -> TRUE | BP7: =BA7=AK7 -> TRUE | ... BV7: =BG7=AQ7 -> TRUE
B8: Hydrogène | D8: 0 | E8: 0 | F8: =D8-C8 -> 0 | I8: Hydrogène | J8: 0 | K8: 0 | L8: 0 | M8: 0 | N8: 0 | O8: 0 | P8: 0 | Q8: 0 | R8: 0 | S8: 0 | T8: 0 | U8: 0 | V8: 0 | W8: 1 | AA8: Dont sidérurgie (hauts fourneaux) | AB8: 2050 | AC8: % | AD8: 0.33394679 | AE8: 0.49605321 | AF8: 0 | AG8: 0 | AH8: 0.05 | AI8: 0.12 | AJ8: 0 | AK8: 0 | AL8: 0 | AM8: 0 | AN8: 0 | AO8: 0 | AP8: 0 | AQ8: 0 | AR8: 1 | AT8: 0.33394679 | AU8: 0.49605321 | AV8: 0 | AW8: 0 | AX8: 0.05 | AY8: 0.12 | AZ8: 0 | BA8: 0 | BB8: 0 | BC8: 0 | BD8: 0 | BE8: 0 | BF8: 0 | BG8: 0 | BI8: =AT8=AD8 -> TRUE | BJ8: =AU8=AE8 -> TRUE | BK8: =AV8=AF8 -> TRUE | BL8: =AW8=AG8 -> TRUE | BM8: =AX8=AH8 -> TRUE | BN8: =AY8=AI8 -> TRUE | BO8: =AZ8=AJ8 -> TRUE | BP8: =BA8=AK8 -> TRUE | ... BV8: =BG8=AQ8 -> TRUE
B9: Biomasse | C9: 0 | D9: 602.96596 | E9: 0 | F9: =D9-C9 -> 602.96596 | I9: Biomasse | J9: 0 | K9: 0 | L9: 0 | M9: 0 | N9: 1 | O9: 0 | P9: 0 | Q9: 0 | R9: 0 | S9: 0 | T9: 0 | U9: 0 | V9: 0 | W9: 0 | AR9: 0 | BI9: =AT9=AD9 -> TRUE | BJ9: =AU9=AE9 -> TRUE | BK9: =AV9=AF9 -> TRUE | BL9: =AW9=AG9 -> TRUE | BM9: =AX9=AH9 -> TRUE | BN9: =AY9=AI9 -> TRUE | BO9: =AZ9=AJ9 -> TRUE | BP9: =BA9=AK9 -> TRUE | ... BV9: =BG9=AQ9 -> TRUE
B10: Dechets | C10: 0 | D10: 1205.9319 | E10: 0 | F10: =D10-C10 -> 1205.9319 | I10: Dechets | J10: 0 | K10: 0 | L10: 0 | M10: 0 | N10: 0 | O10: 1 | P10: 0 | Q10: 0 | R10: 0 | S10: 0 | T10: 0 | U10: 0 | V10: 0 | W10: 0 | AA10: Dont sidérurgie (arc électrique) | AB10: 2021 | AC10: % | AD10: 0.035 | AE10: 0 | AF10: 0.02 | AG10: 0.22 | AH10: 0 | AI10: 0 | AJ10: 0 | AK10: 0 | AL10: 0 | AM10: 0 | AN10: 0.725 | AO10: 0 | AP10: 0 | AQ10: 0 | AR10: 1 | AT10: 0.035 | AU10: 0 | AV10: 0.02 | AW10: 0.22 | AX10: 0 | AY10: 0 | AZ10: 0 | BA10: 0 | BB10: 0 | BC10: 0 | BD10: 0.725 | BE10: 0 | BF10: 0 | BG10: 0 | BI10: =AT10=AD10 -> TRUE | BJ10: =AU10=AE10 -> TRUE | BK10: =AV10=AF10 -> TRUE | BL10: =AW10=AG10 -> TRUE | BM10: =AX10=AH10 -> TRUE | BN10: =AY10=AI10 -> TRUE | BO10: =AZ10=AJ10 -> TRUE | BP10: =BA10=AK10 -> TRUE | ... BV10: =BG10=AQ10 -> TRUE
B11: Charbon | C11: 17351.18 | D11: 7346.1352 | E11: 0 | F11: =D11-C11 -> -10005.044 | I11: Charbon | J11: 1 | K11: 0 | L11: 0 | M11: 0 | N11: 0 | O11: 0 | P11: 0 | Q11: 0 | R11: 0 | S11: 0 | T11: 0 | U11: 0 | V11: 0 | W11: 0 | AA11: Dont sidérurgie (arc électrique) | AB11: 2030 | AC11: % | AD11: 0.02 | AE11: 0 | AF11: 0.02 | AG11: 0.2 | AH11: 0.01 | AI11: 0 | AJ11: 0 | AK11: 0 | AL11: 0 | AM11: 0 | AN11: 0.75 | AO11: 0 | AP11: 0 | AQ11: 0 | AR11: 1 | AT11: 0.02 | AU11: 0 | AV11: 0.02 | AW11: 0.2 | AX11: 0.01 | AY11: 0 | AZ11: 0 | BA11: 0 | BB11: 0 | BC11: 0 | BD11: 0.75 | BE11: 0 | BF11: 0 | BG11: 0 | BI11: =AT11=AD11 -> TRUE | BJ11: =AU11=AE11 -> TRUE | BK11: =AV11=AF11 -> TRUE | BL11: =AW11=AG11 -> TRUE | BM11: =AX11=AH11 -> TRUE | BN11: =AY11=AI11 -> TRUE | BO11: =AZ11=AJ11 -> TRUE | BP11: =BA11=AK11 -> TRUE | ... BV11: =BG11=AQ11 -> TRUE
B12: Coke | C12: 25773.893 | D12: 10943.832 | E12: 0 | F12: =D12-C12 -> -14830.06 | I12: Coke | J12: 0 | K12: 1 | L12: 0 | M12: 0 | N12: 0 | O12: 0 | P12: 0 | Q12: 0 | R12: 0 | S12: 0 | T12: 0 | U12: 0 | V12: 0 | W12: 0 | AA12: Dont sidérurgie (arc électrique) | AB12: 2050 | AC12: % | AD12: 0.010514068 | AE12: 0 | AF12: 0.016095174 | AG12: 0.1441397 | AH12: 0.0219856 | AI12: 0 | AJ12: 0 | AK12: 0 | AL12: 0 | AM12: 0 | AN12: 0.80726546 | AO12: 0 | AP12: 0 | AQ12: 0 | AR12: 1 | AT12: 0.010514068 | AU12: 0 | AV12: 0.016095174 | AW12: 0.1441397 | AX12: 0.0219856 | AY12: 0 | AZ12: 0 | BA12: 0 | BB12: 0 | BC12: 0 | BD12: 0.80726546 | BE12: 0 | BF12: 0 | BG12: 0 | BI12: =AT12=AD12 -> TRUE | BJ12: =AU12=AE12 -> TRUE | BK12: =AV12=AF12 -> TRUE | BL12: =AW12=AG12 -> TRUE | BM12: =AX12=AH12 -> TRUE | BN12: =AY12=AI12 -> TRUE | BO12: =AZ12=AJ12 -> TRUE | BP12: =BA12=AK12 -> TRUE | ... BV12: =BG12=AQ12 -> TRUE
B13: Chaleur | C13: 0 | D13: 0 | E13: 0 | F13: =D13-C13 -> 0 | I13: Chaleur | J13: 0 | K13: 0 | L13: 0 | M13: 0 | N13: 0 | O13: 0 | P13: 0 | Q13: 0 | R13: 0 | S13: 0 | T13: 0 | U13: 0 | V13: 1 | W13: 0 | AR13: 0 | BI13: =AT13=AD13 -> TRUE | BJ13: =AU13=AE13 -> TRUE | BK13: =AV13=AF13 -> TRUE | BL13: =AW13=AG13 -> TRUE | BM13: =AX13=AH13 -> TRUE | BN13: =AY13=AI13 -> TRUE | BO13: =AZ13=AJ13 -> TRUE | BP13: =BA13=AK13 -> TRUE | ... BV13: =BG13=AQ13 -> TRUE
B14: Solar & Geothermie | C14: 0 | D14: 0 | E14: 0 | F14: =D14-C14 -> 0 | I14: Solar & Geothermie | J14: 0 | K14: 0 | L14: 0 | M14: 0 | N14: 0 | O14: 0 | P14: 0 | Q14: 0 | R14: 0 | S14: 1 | T14: 0 | U14: 0 | V14: 0 | W14: 0 | AA14: Dont sidérurgie (réduction directe) | AB14: 2021 | AC14: % | AD14: 0 | AE14: 0 | AF14: 0 | AG14: 0.84803256 | AH14: 0 | AI14: 0 | AJ14: 0 | AK14: 0 | AL14: 0 | AM14: 0 | AN14: 0.15196744 | AO14: 0 | AP14: 0 | AQ14: 0 | AR14: 1 | AT14: 0 | AU14: 0 | AV14: 0 | AW14: 0.84803256 | AX14: 0 | AY14: 0 | AZ14: 0 | BA14: 0 | BB14: 0 | BC14: 0 | BD14: 0.15196744 | BE14: 0 | BF14: 0 | BG14: 0 | BI14: =AT14=AD14 -> TRUE | BJ14: =AU14=AE14 -> TRUE | BK14: =AV14=AF14 -> TRUE | BL14: =AW14=AG14 -> TRUE | BM14: =AX14=AH14 -> TRUE | BN14: =AY14=AI14 -> TRUE | BO14: =AZ14=AJ14 -> TRUE | BP14: =BA14=AK14 -> TRUE | ... BV14: =BG14=AQ14 -> TRUE
B15: Chaleur Env | C15: 0 | D15: 0 | E15: 0 | F15: =D15-C15 -> 0 | I15: Chaleur Env | J15: 0 | K15: 0 | L15: 0 | M15: 0 | N15: 0 | O15: 0 | P15: 0 | Q15: 0 | R15: 1 | S15: 0 | T15: 0 | U15: 0 | V15: 0 | W15: 0 | AA15: Dont sidérurgie (réduction directe) | AB15: 2030 | AC15: % | AD15: 0 | AE15: 0 | AF15: 0 | AG15: 0.54803256 | AH15: 0 | AI15: 0 | AJ15: 0 | AK15: 0 | AL15: 0 | AM15: 0 | AN15: 0.15196744 | AO15: 0 | AP15: 0 | AQ15: 0.3 | AR15: 1 | AT15: 0 | AU15: 0 | AV15: 0 | AW15: 0.54803256 | AX15: 0 | AY15: 0 | AZ15: 0 | BA15: 0 | BB15: 0 | BC15: 0 | BD15: 0.15196744 | BE15: 0 | BF15: 0 | BG15: 0.3 | BI15: =AT15=AD15 -> TRUE | BJ15: =AU15=AE15 -> TRUE | BK15: =AV15=AF15 -> TRUE | BL15: =AW15=AG15 -> TRUE | BM15: =AX15=AH15 -> TRUE | BN15: =AY15=AI15 -> TRUE | BO15: =AZ15=AJ15 -> TRUE | BP15: =BA15=AK15 -> TRUE | ... BV15: =BG15=AQ15 -> TRUE
B16: Biogaz autoconsommé | C16: 0 | D16: 0 | E16: 0 | F16: =D16-C16 -> 0 | I16: Biogaz autoconsommé | J16: 0 | K16: 0 | L16: 0 | M16: =M22 -> 0.15 | N16: 0 | O16: 0 | P16: 0 | Q16: 1 | R16: 0 | S16: 0 | T16: 0 | U16: 0 | V16: 0 | W16: 0 | AA16: Dont sidérurgie (réduction directe) | AB16: 2050 | AC16: % | AD16: 0 | AE16: 0 | AF16: 0 | AG16: 0.15207756 | AH16: 0 | AI16: 0 | AJ16: 0 | AK16: 0 | AL16: 0 | AM16: 0 | AN16: 0.13767313 | AO16: 0 | AP16: 0 | AQ16: 0.71024931 | AR16: 1 | AT16: 0 | AU16: 0 | AV16: 0 | AW16: 0.15207756 | AX16: 0 | AY16: 0 | AZ16: 0 | BA16: 0 | BB16: 0 | BC16: 0 | BD16: 0.13767313 | BE16: 0 | BF16: 0 | BG16: 0.71024931 | BI16: =AT16=AD16 -> TRUE | BJ16: =AU16=AE16 -> TRUE | BK16: =AV16=AF16 -> TRUE | BL16: =AW16=AG16 -> TRUE | BM16: =AX16=AH16 -> TRUE | BN16: =AY16=AI16 -> TRUE | BO16: =AZ16=AJ16 -> TRUE | BP16: =BA16=AK16 -> TRUE | ... BV16: =BG16=AQ16 -> TRUE
B17: Total | C17: 43125.07 | D17: =SUM(D4:D16) -> 20098.865 | E17: =SUM(E4:E16) -> 0 | F17: =D17-C17 -> -23026.205 | AR17: 0 | BI17: =AT17=AD17 -> TRUE | BJ17: =AU17=AE17 -> TRUE | BK17: =AV17=AF17 -> TRUE | BL17: =AW17=AG17 -> TRUE | BM17: =AX17=AH17 -> TRUE | BN17: =AY17=AI17 -> TRUE | BO17: =AZ17=AJ17 -> TRUE | BP17: =BA17=AK17 -> TRUE | ... BV17: =BG17=AQ17 -> TRUE
AA18: Dont sidérurgie (mise en forme de l'acier) | AB18: 2021 | AD18: 0.051378863 | AE18: 0.028814188 | AF18: 0.0084139056 | AG18: 0.43763064 | AH18: 0 | AI18: 0 | AJ18: 0 | AK18: 0 | AL18: 0 | AM18: 0 | AN18: 0.46695971 | AO18: 0 | AP18: 0.0068027007 | AQ18: 0 | AR18: 1 | AT18: 0.051378863 | AU18: 0.028814188 | AV18: 0.0084139056 | AW18: 0.43763064 | AX18: 0 | AY18: 0 | AZ18: 0 | BA18: 0 | BB18: 0 | BC18: 0 | BD18: 0.46695971 | BE18: 0 | BF18: 0.0068027007 | BG18: 0 | BI18: =AT18=AD18 -> TRUE | BJ18: =AU18=AE18 -> TRUE | BK18: =AV18=AF18 -> TRUE | BL18: =AW18=AG18 -> TRUE | BM18: =AX18=AH18 -> TRUE | BN18: =AY18=AI18 -> TRUE | BO18: =AZ18=AJ18 -> TRUE | BP18: =BA18=AK18 -> TRUE | ... BV18: =BG18=AQ18 -> TRUE
B19: Sidérurgie AC | C19: 2021 | D19: 2030 | E19: 2030 | F19: Hausse | AA19: Dont sidérurgie (mise en forme de l'acier) | AB19: 2030 | AD19: 0.04 | AE19: 0 | AF19: 0.01 | AG19: 0.31 | AH19: 0.03 | AI19: 0 | AJ19: 0 | AK19: 0 | AL19: 0 | AM19: 0 | AN19: 0.6 | AO19: 0 | AP19: 0.01 | AQ19: 0 | AR19: 1 | AT19: 0.04 | AU19: 0 | AV19: 0.01 | AW19: 0.31 | AX19: 0.03 | AY19: 0 | AZ19: 0 | BA19: 0 | BB19: 0 | BC19: 0 | BD19: 0.6 | BE19: 0 | BF19: 0.01 | BG19: 0 | BI19: =AT19=AD19 -> TRUE | BJ19: =AU19=AE19 -> TRUE | BK19: =AV19=AF19 -> TRUE | BL19: =AW19=AG19 -> TRUE | BM19: =AX19=AH19 -> TRUE | BN19: =AY19=AI19 -> TRUE | BO19: =AZ19=AJ19 -> TRUE | BP19: =BA19=AK19 -> TRUE | ... BV19: =BG19=AQ19 -> TRUE
B20: Electricité | C20: 1416.4016 | D20: {=MMULT(J4:W16,TRANSPOSE('A renseigner'!E63:R63))*C33*'A renseigner'!E155*'A renseigner'!G8/'A renseigner'!C8} -> 2127.0042 | E20: {=MMULT(J4:W16,TRANSPOSE('A renseigner'!E64:R64))*C33*'A renseigner'!G155*'A renseigner'!K8/'A renseigner'!C8} -> 2969.2278 | F20: =D20-C20 -> 710.60257 | G20: =E20-C20 -> 1552.8262 | I20: Taux d'incorporation de biogaz | AA20: Dont sidérurgie (mise en forme de l'acier) | AB20: 2050 | AD20: 0.03 | AE20: 0 | AF20: 0.01 | AG20: 0.2 | AH20: 0.05 | AI20: 0 | AJ20: 0 | AK20: 0 | AL20: 0 | AM20: 0 | AN20: 0.7 | AO20: 0 | AP20: 0.01 | AQ20: 0 | AR20: 1 | AT20: 0.03 | AU20: 0 | AV20: 0.01 | AW20: 0.2 | AX20: 0.05 | AY20: 0 | AZ20: 0 | BA20: 0 | BB20: 0 | BC20: 0 | BD20: 0.7 | BE20: 0 | BF20: 0.01 | BG20: 0 | BI20: =AT20=AD20 -> TRUE | BJ20: =AU20=AE20 -> TRUE | BK20: =AV20=AF20 -> TRUE | BL20: =AW20=AG20 -> TRUE | BM20: =AX20=AH20 -> TRUE | BN20: =AY20=AI20 -> TRUE | BO20: =AZ20=AJ20 -> TRUE | BP20: =BA20=AK20 -> TRUE | ... BV20: =BG20=AQ20 -> TRUE
B21: Electricité PAC | C21: 0 | D21: 0 | E21: 0 | F21: =D21-C21 -> 0 | G21: =E21-C21 -> 0 | J21: 2019 | K21: 2020 | L21: 2025 | M21: 2030 | N21: 2035 | O21: 2040 | P21: 2045 | Q21: 2050 | AR21: 0 | BI21: =AT21=AD21 -> TRUE | BJ21: =AU21=AE21 -> TRUE | BK21: =AV21=AF21 -> TRUE | BL21: =AW21=AG21 -> TRUE | BM21: =AX21=AH21 -> TRUE | BN21: =AY21=AI21 -> TRUE | BO21: =AZ21=AJ21 -> TRUE | BP21: =BA21=AK21 -> TRUE | ... BV21: =BG21=AQ21 -> TRUE
B22: Produits liquides (fossile, bio, et synthétique) | C22: 39.073151 | D22: 56.720111 | E22: 0 | F22: =D22-C22 -> 17.646961 | G22: =E22-C22 -> -39.073151 | I22: % gaz non-fossile réseau (conso finale) | J22: 0 | K22: 0.001 | L22: 0.05 | M22: 0.15 | N22: 0.27 | O22: 0.45 | P22: 0.61 | Q22: 1 | AA22: Dont aluminium (primaire) | AB22: 2021 | AC22: % | AD22: 0 | AE22: 0 | AF22: 0.02811245 | AG22: 0.25100402 | AH22: 0 | AI22: 0 | AJ22: 0 | AK22: 0 | AL22: 0 | AM22: 0 | AN22: 0.71285141 | AO22: 0 | AP22: 0.0080321285 | AQ22: 0 | AR22: 1 | AT22: 0 | AU22: 0 | AV22: 0.02811245 | AW22: 0.25100402 | AX22: 0 | AY22: 0 | AZ22: 0 | BA22: 0 | BB22: 0 | BC22: 0 | BD22: 0.71285141 | BE22: 0 | BF22: 0.0080321285 | BG22: 0 | BI22: =AT22=AD22 -> TRUE | BJ22: =AU22=AE22 -> TRUE | BK22: =AV22=AF22 -> TRUE | BL22: =AW22=AG22 -> TRUE | BM22: =AX22=AH22 -> TRUE | BN22: =AY22=AI22 -> TRUE | BO22: =AZ22=AJ22 -> TRUE | BP22: =BA22=AK22 -> TRUE | ... BV22: =BG22=AQ22 -> TRUE
B23: Gaz de réseau | C23: 429.80463 | D23: 482.12095 | E23: 450.63993 | F23: =D23-C23 -> 52.316321 | G23: =E23-C23 -> 20.835302 | I23: dont méthane de synthèse | J23: 0 | K23: 0 | L23: 0 | M23: 0 | N23: 0 | O23: 0 | P23: 0.01 | Q23: 0.05 | AA23: Dont aluminium (primaire) | AB23: 2030 | AC23: % | AD23: 0 | AE23: 0 | AF23: 0 | AG23: 0.15 | AH23: 0 | AI23: 0 | AJ23: 0 | AK23: 0 | AL23: 0 | AM23: 0 | AN23: 0.85 | AO23: 0 | AP23: 0 | AQ23: 0 | AR23: 1 | AT23: 0 | AU23: 0 | AV23: 0 | AW23: 0.15 | AX23: 0 | AY23: 0 | AZ23: 0 | BA23: 0 | BB23: 0 | BC23: 0 | BD23: 0.85 | BE23: 0 | BF23: 0 | BG23: 0 | BI23: =AT23=AD23 -> TRUE | BJ23: =AU23=AE23 -> TRUE | BK23: =AV23=AF23 -> TRUE | BL23: =AW23=AG23 -> TRUE | BM23: =AX23=AH23 -> TRUE | BN23: =AY23=AI23 -> TRUE | BO23: =AZ23=AJ23 -> TRUE | BP23: =BA23=AK23 -> TRUE | ... BV23: =BG23=AQ23 -> TRUE
B24: Hydrogène | D24: 0 | E24: 0 | F24: =D24-C24 -> 0 | G24: =E24-C24 -> 0 | I24: dont biogaz | J24: 0 | K24: 0.001 | L24: 0.05 | M24: 0.15 | N24: 0.27 | O24: 0.45 | P24: 0.6 | Q24: 0.95 | AA24: Dont aluminium (primaire) | AB24: 2050 | AC24: % | AD24: 0 | AE24: 0 | AF24: 0 | AG24: 0.11 | AH24: 0 | AI24: 0 | AJ24: 0 | AK24: 0 | AL24: 0 | AM24: 0 | AN24: 0.87 | AO24: 0 | AP24: 0 | AQ24: 0.02 | AR24: 1 | AT24: 0 | AU24: 0 | AV24: 0 | AW24: 0.11 | AX24: 0 | AY24: 0 | AZ24: 0 | BA24: 0 | BB24: 0 | BC24: 0 | BD24: 0.87 | BE24: 0 | BF24: 0 | BG24: 0.02 | BI24: =AT24=AD24 -> TRUE | BJ24: =AU24=AE24 -> TRUE | BK24: =AV24=AF24 -> TRUE | BL24: =AW24=AG24 -> TRUE | BM24: =AX24=AH24 -> TRUE | BN24: =AY24=AI24 -> TRUE | BO24: =AZ24=AJ24 -> TRUE | BP24: =BA24=AK24 -> TRUE | ... BV24: =BG24=AQ24 -> TRUE
B25: Biomasse | C25: 0 | D25: 28.360056 | E25: 36.781306 | F25: =D25-C25 -> 28.360056 | G25: =E25-C25 -> 36.781306 | I25: % gaz non-fossile pour prod chaleur | J25: 0.1205 | K25: 0.1258 | L25: 0.15 | M25: 0.2 | N25: 0.25 | O25: 0.45 | P25: 0.7 | Q25: 1 | AR25: 0 | BI25: =AT25=AD25 -> TRUE | BJ25: =AU25=AE25 -> TRUE | BK25: =AV25=AF25 -> TRUE | BL25: =AW25=AG25 -> TRUE | BM25: =AX25=AH25 -> TRUE | BN25: =AY25=AI25 -> TRUE | BO25: =AZ25=AJ25 -> TRUE | BP25: =BA25=AK25 -> TRUE | ... BV25: =BG25=AQ25 -> TRUE
B26: Dechets | C26: 0 | D26: 0 | E26: 103.28475 | F26: =D26-C26 -> 0 | G26: =E26-C26 -> 103.28475 | I26: dont méthane de synthèse | J26: 0 | K26: 0 | L26: 0 | M26: 0 | N26: 0 | O26: 0 | P26: 0 | Q26: 0 | AA26: Dont aluminium (recyclé) | AB26: 2021 | AC26: % | AD26: 0 | AE26: 0 | AF26: 0.02461934 | AG26: 0.63990508 | AH26: 0 | AI26: 0 | AJ26: 0 | AK26: 0 | AL26: 0 | AM26: 0 | AN26: 0.33547558 | AO26: 0 | AP26: 0 | AQ26: 0 | AR26: 1 | AT26: 0 | AU26: 0 | AV26: 0.02461934 | AW26: 0.63990508 | AX26: 0 | AY26: 0 | AZ26: 0 | BA26: 0 | BB26: 0 | BC26: 0 | BD26: 0.33547558 | BE26: 0 | BF26: 0 | BG26: 0 | BI26: =AT26=AD26 -> TRUE | BJ26: =AU26=AE26 -> TRUE | BK26: =AV26=AF26 -> TRUE | BL26: =AW26=AG26 -> TRUE | BM26: =AX26=AH26 -> TRUE | BN26: =AY26=AI26 -> TRUE | BO26: =AZ26=AJ26 -> TRUE | BP26: =BA26=AK26 -> TRUE | ... BV26: =BG26=AQ26 -> TRUE
B27: Charbon | C27: 68.378014 | D27: 56.720111 | E27: 38.672114 | F27: =D27-C27 -> -11.657902 | G27: =E27-C27 -> -29.705899 | I27: dont biogaz | J27: 0.1205 | K27: 0.1258 | L27: 0.15 | M27: 0.2 | N27: 0.25 | O27: 0.45 | P27: 0.7 | Q27: 1 | AA27: Dont aluminium (recyclé) | AB27: 2030 | AC27: % | AD27: 0 | AE27: 0 | AF27: 0 | AG27: 0.55 | AH27: 0 | AI27: 0 | AJ27: 0 | AK27: 0 | AL27: 0 | AM27: 0 | AN27: 0.45 | AO27: 0 | AP27: 0 | AQ27: 0 | AR27: 1 | AT27: 0 | AU27: 0 | AV27: 0 | AW27: 0.55 | AX27: 0 | AY27: 0 | AZ27: 0 | BA27: 0 | BB27: 0 | BC27: 0 | BD27: 0.45 | BE27: 0 | BF27: 0 | BG27: 0 | BI27: =AT27=AD27 -> TRUE | BJ27: =AU27=AE27 -> TRUE | BK27: =AV27=AF27 -> TRUE | BL27: =AW27=AG27 -> TRUE | BM27: =AX27=AH27 -> TRUE | BN27: =AY27=AI27 -> TRUE | BO27: =AZ27=AJ27 -> TRUE | BP27: =BA27=AK27 -> TRUE | ... BV27: =BG27=AQ27 -> TRUE
B28: Coke | C28: 0 | D28: 0 | E28: 0 | F28: =D28-C28 -> 0 | G28: =E28-C28 -> 0 | I28: % gaz non-fossile prod élec | J28: 0.0695 | K28: 0.0844 | L28: 0.13 | M28: 0.15 | N28: 0.2 | O28: 0.2 | P28: 0.2 | Q28: 0.2 | AA28: Dont aluminium (recyclé) | AB28: 2050 | AC28: % | AD28: 0 | AE28: 0 | AF28: 0 | AG28: 0.2 | AH28: 0 | AI28: 0 | AJ28: 0 | AK28: 0 | AL28: 0 | AM28: 0 | AN28: 0.8 | AO28: 0 | AP28: 0 | AQ28: 0 | AR28: 1 | AT28: 0 | AU28: 0 | AV28: 0 | AW28: 0.2 | AX28: 0 | AY28: 0 | AZ28: 0 | BA28: 0 | BB28: 0 | BC28: 0 | BD28: 0.8 | BE28: 0 | BF28: 0 | BG28: 0 | BI28: =AT28=AD28 -> TRUE | BJ28: =AU28=AE28 -> TRUE | BK28: =AV28=AF28 -> TRUE | BL28: =AW28=AG28 -> TRUE | BM28: =AX28=AH28 -> TRUE | BN28: =AY28=AI28 -> TRUE | BO28: =AZ28=AJ28 -> TRUE | BP28: =BA28=AK28 -> TRUE | ... BV28: =BG28=AQ28 -> TRUE
B29: Chaleur | C29: 0 | D29: 0 | E29: 0 | F29: =D29-C29 -> 0 | G29: =E29-C29 -> 0 | I29: dont méthane de synthèse | J29: 0 | K29: 0 | L29: 0 | M29: 0 | N29: 0 | O29: 0 | P29: 0 | Q29: 0 | AR29: 0 | BI29: =AT29=AD29 -> TRUE | BJ29: =AU29=AE29 -> TRUE | BK29: =AV29=AF29 -> TRUE | BL29: =AW29=AG29 -> TRUE | BM29: =AX29=AH29 -> TRUE | BN29: =AY29=AI29 -> TRUE | BO29: =AZ29=AJ29 -> TRUE | BP29: =BA29=AK29 -> TRUE | ... BV29: =BG29=AQ29 -> TRUE
B30: Solar & Geothermie | C30: 0 | D30: 0 | E30: 0 | F30: =D30-C30 -> 0 | G30: =E30-C30 -> 0 | I30: dont biogaz | J30: 0.0695 | K30: 0.0844 | L30: 0.13 | M30: 0.15 | N30: 0.2 | O30: 0.2 | P30: 0.2 | Q30: 0.2 | AA30: Dont autres métaux primaires | AB30: 2021 | AC30: % | AD30: 0 | AE30: 0 | AF30: 0 | AG30: 0.28501215 | AH30: 0.0025709966 | AI30: 0 | AJ30: 0 | AK30: 0 | AL30: 0 | AM30: 0 | AN30: 0.67273231 | AO30: 0 | AP30: 0.039684538 | AQ30: 0 | AR30: 1 | AT30: 0 | AU30: 0 | AV30: 0 | AW30: 0.28501215 | AX30: 0.0025709966 | AY30: 0 | AZ30: 0 | BA30: 0 | BB30: 0 | BC30: 0 | BD30: 0.67273231 | BE30: 0 | BF30: 0.039684538 | BG30: 0 | BI30: =AT30=AD30 -> TRUE | BJ30: =AU30=AE30 -> TRUE | BK30: =AV30=AF30 -> TRUE | BL30: =AW30=AG30 -> TRUE | BM30: =AX30=AH30 -> TRUE | BN30: =AY30=AI30 -> TRUE | BO30: =AZ30=AJ30 -> TRUE | BP30: =BA30=AK30 -> TRUE | ... BV30: =BG30=AQ30 -> TRUE
B31: Chaleur Env | C31: 0 | D31: 0 | E31: 0 | F31: =D31-C31 -> 0 | G31: =E31-C31 -> 0 | AA31: Dont autres métaux primaires | AB31: 2030 | AC31: % | AD31: 0 | AE31: 0 | AF31: 0 | AG31: 0.20888383 | AH31: 0.03 | AI31: 0 | AJ31: 0 | AK31: 0 | AL31: 0 | AM31: 0 | AN31: 0.70111617 | AO31: 0 | AP31: 0.03 | AQ31: 0.03 | AR31: 1 | AT31: 0 | AU31: 0 | AV31: 0 | AW31: 0.219 | AX31: 0.02 | AY31: 0 | AZ31: 0 | BA31: 0 | BB31: 0 | BC31: 0 | BD31: 0.70111617 | BE31: 0 | BF31: 0.03 | BG31: 0.03 | BI31: =AT31=AD31 -> TRUE | BJ31: =AU31=AE31 -> TRUE | BK31: =AV31=AF31 -> TRUE | BL31: =AW31=AG31 -> FALSE | BM31: =AX31=AH31 -> FALSE | BN31: =AY31=AI31 -> TRUE | BO31: =AZ31=AJ31 -> TRUE | BP31: =BA31=AK31 -> TRUE | ... BV31: =BG31=AQ31 -> TRUE
B32: Biogaz autoconsommé | C32: 0 | D32: 85.080167 | E32: 79.524693 | F32: =D32-C32 -> 85.080167 | G32: =E32-C32 -> 79.524693 | AA32: Dont autres métaux primaires | AB32: 2050 | AC32: % | AD32: 0 | AE32: 0 | AF32: 0 | AG32: 0.08 | AH32: 0.05 | AI32: 0 | AJ32: 0 | AK32: 0 | AL32: 0 | AM32: 0 | AN32: 0.79 | AO32: 0 | AP32: 0 | AQ32: 0.08 | AR32: 1 | AT32: 0 | AU32: 0 | AV32: 0 | AW32: 0.08 | AX32: 0.05 | AY32: 0 | AZ32: 0 | BA32: 0 | BB32: 0 | BC32: 0 | BD32: 0.79 | BE32: 0 | BF32: 0 | BG32: 0.08 | BI32: =AT32=AD32 -> TRUE | BJ32: =AU32=AE32 -> TRUE | BK32: =AV32=AF32 -> TRUE | BL32: =AW32=AG32 -> TRUE | BM32: =AX32=AH32 -> TRUE | BN32: =AY32=AI32 -> TRUE | BO32: =AZ32=AJ32 -> TRUE | BP32: =BA32=AK32 -> TRUE | ... BV32: =BG32=AQ32 -> TRUE
B33: Total | C33: 1953.6573 | D33: =SUM(D20:D32) -> 2836.0056 | E33: =SUM(E20:E32) -> 3678.1306 | F33: =D33-C33 -> 882.34822 | G33: =E33-C33 -> 1724.4732 | AR33: 0 | BI33: =AT33=AD33 -> TRUE | BJ33: =AU33=AE33 -> TRUE | BK33: =AV33=AF33 -> TRUE | BL33: =AW33=AG33 -> TRUE | BM33: =AX33=AH33 -> TRUE | BN33: =AY33=AI33 -> TRUE | BO33: =AZ33=AJ33 -> TRUE | BP33: =BA33=AK33 -> TRUE | ... BV33: =BG33=AQ33 -> TRUE
H34: Résultats | AA34: Chimie | AD34: Charbon | AE34: Coke | AF34: Produits pétroliers raffinés | AG34: Gaz naturel | AH34: Biomasse solide | AI34: Déchets | AJ34: Biocarburants | AK34: Gaz renouvelable | AL34: Chaleur de l'environnement | AM34: Solaire thermique et géothermie | AN34: Électricité | AO34: Electricité PAC | AP34: Chaleur vendue | AQ34: Hydrogène | AR34: 0 | AT34: Charbon | AU34: Coke | AV34: Produits pétroliers raffinés | AW34: Gaz naturel | AX34: Biomasse solide | AY34: Déchets | AZ34: Biocarburants | BA34: Gaz renouvelable | BB34: Chaleur de l'environnement | BC34: Solaire thermique et géothermie | BD34: Électricité | BE34: Electricité PAC | BF34: Chaleur vendue | BG34: Hydrogène | BI34: =AT34=AD34 -> TRUE | BJ34: =AU34=AE34 -> TRUE | BK34: =AV34=AF34 -> TRUE | BL34: =AW34=AG34 -> TRUE | BM34: =AX34=AH34 -> TRUE | BN34: =AY34=AI34 -> TRUE | BO34: =AZ34=AJ34 -> TRUE | BP34: =BA34=AK34 -> TRUE | ... BV34: =BG34=AQ34 -> TRUE
B35: Sidérurgie RD | C35: 2021 | D35: 2030 | E35: 2030 | F35: Hausse | AA35: Dont Ammoniac (vaporeformage) | AB35: 2021 | AC35: % | AD35: 0 | AE35: 0 | AF35: 0.005 | AG35: 0.93 | AH35: 0.005 | AI35: 0 | AJ35: 0 | AK35: 0 | AL35: 0 | AM35: 0 | AN35: 0.06 | AO35: 0 | AP35: 0 | AQ35: 0 | AR35: 1 | AT35: 0 | AU35: 0 | AV35: 0.005 | AW35: 0.93 | AX35: 0.005 | AY35: 0 | AZ35: 0 | BA35: 0 | BB35: 0 | BC35: 0 | BD35: 0.06 | BE35: 0 | BF35: 0 | BG35: 0 | BI35: =AT35=AD35 -> TRUE | BJ35: =AU35=AE35 -> TRUE | BK35: =AV35=AF35 -> TRUE | BL35: =AW35=AG35 -> TRUE | BM35: =AX35=AH35 -> TRUE | BN35: =AY35=AI35 -> TRUE | BO35: =AZ35=AJ35 -> TRUE | BP35: =BA35=AK35 -> TRUE | ... BV35: =BG35=AQ35 -> TRUE
B36: Electricité | C36: 0.56 | D36: {=MMULT($J$4:$W$16,TRANSPOSE('A renseigner'!$E67:$R67))*$C$49*'A renseigner'!E156*9825/4} -> 1306.725 | E36: {=MMULT($J$4:$W$16,TRANSPOSE('A renseigner'!$E68:$R68))*$C$49*'A renseigner'!G156*18616/4} -> 2124.9835 | F36: =D36-C36 -> 1306.165 | AA36: Dont Ammoniac (vaporeformage) | AB36: 2030 | AC36: % | AD36: 0 | AE36: 0 | AF36: 0.005 | AG36: 0.93 | AH36: 0.005 | AI36: 0 | AJ36: 0 | AK36: 0 | AL36: 0 | AM36: 0 | AN36: 0.06 | AO36: 0 | AP36: 0 | AQ36: 0 | AR36: 1 | AT36: 0 | AU36: 0 | AV36: 0.005 | AW36: 0.93 | AX36: 0.005 | AY36: 0 | AZ36: 0 | BA36: 0 | BB36: 0 | BC36: 0 | BD36: 0.06 | BE36: 0 | BF36: 0 | BG36: 0 | BI36: =AT36=AD36 -> TRUE | BJ36: =AU36=AE36 -> TRUE | BK36: =AV36=AF36 -> TRUE | BL36: =AW36=AG36 -> TRUE | BM36: =AX36=AH36 -> TRUE | BN36: =AY36=AI36 -> TRUE | BO36: =AZ36=AJ36 -> TRUE | BP36: =BA36=AK36 -> TRUE | ... BV36: =BG36=AQ36 -> TRUE
B37: Electricité PAC | C37: 0 | D37: 0 | E37: 0 | F37: =D37-C37 -> 0 | AA37: Dont Ammoniac (vaporeformage) | AB37: 2050 | AC37: % | AD37: 0 | AE37: 0 | AF37: 0.005 | AG37: 0.93 | AH37: 0.005 | AI37: 0 | AJ37: 0 | AK37: 0 | AL37: 0 | AM37: 0 | AN37: 0.06 | AO37: 0 | AP37: 0 | AQ37: 0 | AR37: 1 | AT37: 0 | AU37: 0 | AV37: 0.005 | AW37: 0.93 | AX37: 0.005 | AY37: 0 | AZ37: 0 | BA37: 0 | BB37: 0 | BC37: 0 | BD37: 0.06 | BE37: 0 | BF37: 0 | BG37: 0 | BI37: =AT37=AD37 -> TRUE | BJ37: =AU37=AE37 -> TRUE | BK37: =AV37=AF37 -> TRUE | BL37: =AW37=AG37 -> TRUE | BM37: =AX37=AH37 -> TRUE | BN37: =AY37=AI37 -> TRUE | BO37: =AZ37=AJ37 -> TRUE | BP37: =BA37=AK37 -> TRUE | ... BV37: =BG37=AQ37 -> TRUE
B38: Produits liquides (fossile, bio, et synthétique) | C38: 0 | D38: 0 | E38: 0 | F38: =D38-C38 -> 0 | J38: Où est incluse la consommation de biomasse pour les métaux primaires ? | AR38: 0 | BI38: =AT38=AD38 -> TRUE | BJ38: =AU38=AE38 -> TRUE | BK38: =AV38=AF38 -> TRUE | BL38: =AW38=AG38 -> TRUE | BM38: =AX38=AH38 -> TRUE | BN38: =AY38=AI38 -> TRUE | BO38: =AZ38=AJ38 -> TRUE | BP38: =BA38=AK38 -> TRUE | ... BV38: =BG38=AQ38 -> TRUE
B39: Gaz de réseau | C39: 3.125 | D39: 4005.5204 | E39: 1995.2184 | F39: =D39-C39 -> 4002.3954 | I39: Chiffres FdR DGE | J39: Chimie | K39: Papier-carton | L39: Ciment | M39: Agro-alimentaire | N39: Chaux | O39: Briques et tuiles | P39: Biens d'équipements, matériels de transport | Q39: Autres (détails ?) | R39: Total | AA39: Dont pétrochimie de base | AB39: 2021 | AC39: % | AD39: 0 | AE39: 0 | AF39: 0.022797872 | AG39: 0.64404567 | AH39: 0.014462768 | AI39: 0 | AJ39: 0 | AK39: 0 | AL39: 0 | AM39: 0 | AN39: 0.1746663 | AO39: 0 | AP39: 0.14402739 | AQ39: 0 | AR39: 1 | AT39: 0 | AU39: 0 | AV39: 0.022797872 | AW39: 0.64404567 | AX39: 0.014462768 | AY39: 0 | AZ39: 0 | BA39: 0 | BB39: 0 | BC39: 0 | BD39: 0.1746663 | BE39: 0 | BF39: 0.14402739 | BG39: 0 | BI39: =AT39=AD39 -> TRUE | BJ39: =AU39=AE39 -> TRUE | BK39: =AV39=AF39 -> TRUE | BL39: =AW39=AG39 -> TRUE | BM39: =AX39=AH39 -> TRUE | BN39: =AY39=AI39 -> TRUE | BO39: =AZ39=AJ39 -> TRUE | BP39: =BA39=AK39 -> TRUE | ... BV39: =BG39=AQ39 -> TRUE
B40: Hydrogène | D40: 2579.6151 | E40: 10962.691 | F40: =D40-C40 -> 2579.6151 | I40: Besoins supplémentaires en biomasse en 2030 (TWh) | J40: 7.3913043 | K40: 3.4782609 | L40: 1.7391304 | M40: 6.9565217 | N40: 1.5130435 | O40: 0.54956522 | P40: 1.3043478 | Q40: 1.3 | R40: 24.232174 | AA40: Dont pétrochimie de base | AB40: 2030 | AC40: % | AD40: 0 | AE40: 0 | AF40: 0.02 | AG40: 0.35 | AH40: 0.014 | AI40: 0 | AJ40: 0 | AK40: 0 | AL40: 0 | AM40: 0 | AN40: 0.476 | AO40: 0 | AP40: 0.14 | AQ40: 0 | AR40: 1 | AT40: 0 | AU40: 0 | AV40: 0.02 | AW40: 0.334 | AX40: 0.03 | AY40: 0 | AZ40: 0 | BA40: 0 | BB40: 0 | BC40: 0 | BD40: 0.476 | BE40: 0 | BF40: 0.14 | BG40: 0 | BI40: =AT40=AD40 -> TRUE | BJ40: =AU40=AE40 -> TRUE | BK40: =AV40=AF40 -> TRUE | BL40: =AW40=AG40 -> FALSE | BM40: =AX40=AH40 -> FALSE | BN40: =AY40=AI40 -> TRUE | BO40: =AZ40=AJ40 -> TRUE | BP40: =BA40=AK40 -> TRUE | ... BV40: =BG40=AQ40 -> TRUE
...

Sheet Diffus
B1: Cadrage AMS run 2 | C1: 2019 | D1: 2020 | E1: 2021 | F1: 2025 | G1: 2030 | H1: 2035 | I1: 2040 | J1: 2045 | K1: 2050
B2: industrie (hors correction) | C2: 260.68485 | D2: 235.28544 | E2: 244.90887 | F2: 247.64108 | G2: 260.18351 | H2: 275.00144 | I2: 294.71462 | J2: 319.32509 | K2: 345.78526
B3: dont sidérurgie | C3: 3.4365522 | D3: 2.7321756 | E3: 5.2177233 | F3: 5.2481932 | G3: 5.3741724 | H3: 5.441197 | I3: 5.7309247 | J3: 6.1596607 | K3: 6.6449343
B4: dont métaux non-ferreux | C4: 2.2910348 | D4: 1.8214504 | E4: 3.4784822 | F4: 3.750326 | G4: 4.0122333 | H4: 3.9761485 | I4: 4.1714048 | J4: 4.464064 | K4: 4.7914431
B5: dont chimie | C5: 52.462654 | D5: 51.129802 | E5: 53.025615 | F5: 53.554882 | G5: 56.623341 | H5: 57.755283 | I5: 61.726253 | J5: 66.70407 | K5: 71.933909
B6: dont minéraux non-métalliques | C6: 10.005872 | D6: 9.476369 | E6: 9.6003547 | F6: 9.8241243 | G6: 9.9846511 | H6: 10.086062 | I6: 10.429099 | J6: 10.917187 | K6: 11.561558
B7: dont papier pâtes | C7: 5.2611182 | D7: 5.1356951 | E7: 5.1306308 | F7: 5.1887157 | G7: 5.3781099 | H7: 5.5670169 | I7: 5.9113743 | J7: 6.3435855 | K7: 6.8323863
B8: dont IAA | C8: 53.627666 | D8: 54.703848 | E8: 51.664645 | F8: 53.787515 | G8: 57.871473 | H8: 61.635582 | I8: 66.27904 | J8: 71.349193 | K8: 76.7004
B9: dont autres (hors correction) | C9: 173.5554 | D9: 151.84077 | E9: 158.2249 | F9: 155.74388 | G9: 159.15276 | H9: 166.25811 | I9: 175.40217 | J9: 186.93083 | K9: 200.7026
B11: dont construction | C11: 124.11577 | D11: 112.21961 | E11: 123.89472 | F11: 128.10456 | G11: 127.76635 | H11: 126.25407 | I11: 126.69314 | J11: 128.80267 | K11: 133.59533
B14: dont autres correction run 2 | C14: 0 | D14: 0 | E14: 0 | F14: 10 | G14: 20 | H14: 25 | I14: 30 | J14: 35 | K14: 40
B15: autres cadrage | C15: =C9 -> 173.5554 | D15: =D9 -> 151.84077 | E15: =E9 -> 158.2249 | F15: =F9 -> 155.74388 | G15: =G9 -> 159.15276 | H15: =H9 -> 166.25811 | I15: =I9 -> 175.40217 | J15: =J9 -> 186.93083 | K15: =K9 -> 200.7026
B16: autres run 2 | C16: =C15+C14 -> 173.5554 | D16: =D15+D14 -> 151.84077 | E16: =E15+E14 -> 158.2249 | F16: =F15+F14 -> 165.74388 | G16: =G15+G14 -> 179.15276 | H16: =H15+H14 -> 191.25811 | I16: =I15+I14 -> 205.40217 | J16: =J15+J14 -> 221.93083 | K16: =K15+K14 -> 240.7026
D18: Valeur ajoutée brute (Md€) - cf Cadrage | L18: Evolution / 2021 brute | R18: Evolution / 2021 corrigée
C19: Md€2015 | D19: 2020 | E19: 2021 | F19: 2025 | G19: 2030 | H19: 2035 | I19: 2040 | J19: 2045 | K19: 2050 | L19: 2025 | M19: 2030 | N19: 2035 | O19: 2040 | P19: 2045 | Q19: 2050 | R19: 2025 | S19: 2030 | T19: 2035 | U19: 2040 | V19: 2045 | W19: 2050
B20: Métaux primaires | D20: =D4+D3 -> 4.553626 | E20: =E4+E3 -> 8.6962056 | F20: =F4+F3 -> 8.9985192 | G20: =G4+G3 -> 9.3864057 | H20: =H4+H3 -> 9.4173455 | I20: =I4+I3 -> 9.9023295 | J20: =J4+J3 -> 10.623725 | K20: =K4+K3 -> 11.436377 | L20: =F20/$E20 -> 1.0347639 | M20: =G20/$E20 -> 1.079368 | N20: =H20/$E20 -> 1.0829258 | O20: =I20/$E20 -> 1.1386954 | P20: =J20/$E20 -> 1.2216506 | Q20: =K20/$E20 -> 1.3150997 | R20: =L20+0.019 -> 1.0537639 | S20: =M20+0.028 -> 1.107368 | T20: =N20+0.039 -> 1.1219258 | U20: =O20+0.056 -> 1.1946954 | V20: =P20+0.074 -> 1.2956506 | W20: =Q20+0.091 -> 1.4060997
B21: Chimie | D21: =D5 -> 51.129802 | E21: =E5 -> 53.025615 | F21: =F5 -> 53.554882 | G21: =G5 -> 56.623341 | H21: =H5 -> 57.755283 | I21: =I5 -> 61.726253 | J21: =J5 -> 66.70407 | K21: =K5 -> 71.933909 | L21: =F21/$E21 -> 1.0099813 | M21: =G21/$E21 -> 1.0678488 | N21: =H21/$E21 -> 1.0891959 | O21: =I21/$E21 -> 1.1640837 | P21: =J21/$E21 -> 1.2579594 | Q21: =K21/$E21 -> 1.3565879 | R21: =L21+0.019 -> 1.0289813 | S21: =M21+0.028 -> 1.0958488 | T21: =N21+0.039 -> 1.1281959 | U21: =O21+0.056 -> 1.2200837 | V21: =P21+0.074 -> 1.3319594 | W21: =Q21+0.091 -> 1.4475879
B22: Minéraux non-métalliques | D22: =D6 -> 9.476369 | E22: =E6 -> 9.6003547 | F22: =F6 -> 9.8241243 | G22: =G6 -> 9.9846511 | H22: =H6 -> 10.086062 | I22: =I6 -> 10.429099 | J22: =J6 -> 10.917187 | K22: =K6 -> 11.561558 | L22: =F22/$E22 -> 1.0233085 | M22: =G22/$E22 -> 1.0400294 | N22: =H22/$E22 -> 1.0505927 | O22: =I22/$E22 -> 1.0863244 | P22: =J22/$E22 -> 1.1371649 | Q22: =K22/$E22 -> 1.2042844 | R22: =L22+0.019 -> 1.0423085 | S22: =M22+0.028 -> 1.0680294 | T22: =N22+0.039 -> 1.0895927 | U22: =O22+0.056 -> 1.1423244 | V22: =P22+0.074 -> 1.2111649 | W22: =Q22+0.091 -> 1.2952844
B23: IAA | D23: =D8 -> 54.703848 | E23: =E8 -> 51.664645 | F23: =F8 -> 53.787515 | G23: =G8 -> 57.871473 | H23: =H8 -> 61.635582 | I23: =I8 -> 66.27904 | J23: =J8 -> 71.349193 | K23: =K8 -> 76.7004 | L23: =F23/$E23 -> 1.0410894 | M23: =G23/$E23 -> 1.1201369 | N23: =H23/$E23 -> 1.1929934 | O23: =I23/$E23 -> 1.2828703 | P23: =J23/$E23 -> 1.3810062 | Q23: =K23/$E23 -> 1.484582 | R23: =L23+0.019 -> 1.0600894 | S23: =M23+0.028 -> 1.1481369 | T23: =N23+0.039 -> 1.2319934 | U23: =O23+0.056 -> 1.3388703 | V23: =P23+0.074 -> 1.4550062 | W23: =Q23+0.091 -> 1.575582
B24: Autres | D24: =D16 -> 151.84077 | E24: =E16 -> 158.2249 | F24: =F16 -> 165.74388 | G24: =G16 -> 179.15276 | H24: =H16 -> 191.25811 | I24: =I16 -> 205.40217 | J24: =J16 -> 221.93083 | K24: =K16 -> 240.7026 | L24: =F24/$E24 -> 1.0475208 | M24: =G24/$E24 -> 1.1322665 | N24: =H24/$E24 -> 1.2087738 | O24: =I24/$E24 -> 1.2981659 | P24: =J24/$E24 -> 1.402629 | Q24: =K24/$E24 -> 1.5212687 | R24: =L24+0.019 -> 1.0665208 | S24: =M24+0.028 -> 1.1602665 | T24: =N24+0.039 -> 1.2477738 | U24: =O24+0.056 -> 1.3541659 | V24: =P24+0.074 -> 1.476629 | W24: =Q24+0.091 -> 1.6122687
B25: Total industrie | D25: =SUM(D20:D24) -> 271.70442 | E25: =SUM(E20:E24) -> 281.21172 | F25: =SUM(F20:F24) -> 291.90892 | G25: =SUM(G20:G24) -> 313.01863 | H25: =SUM(H20:H24) -> 330.15238 | I25: =SUM(I20:I24) -> 353.73889 | J25: =SUM(J20:J24) -> 381.52501 | K25: =SUM(K20:K24) -> 412.33484
B26: Construction | D26: =D11 -> 112.21961 | E26: =E11 -> 123.89472 | F26: =F11 -> 128.10456 | G26: =G11 -> 127.76635 | H26: =H11 -> 126.25407 | I26: =I11 -> 126.69314 | J26: =J11 -> 128.80267 | K26: =K11 -> 133.59533 | L26: =F26/$E26 -> 1.0339792 | M26: =G26/$E26 -> 1.0312494 | N26: =H26/$E26 -> 1.0190432 | O26: =I26/$E26 -> 1.0225871 | P26: =J26/$E26 -> 1.0396139 | Q26: =K26/$E26 -> 1.0782972
B29: Md€2015 | C29: 2019 | D29: 2020 | E29: 2021 | F29: 2025 | G29: 2030 | H29: 2035 | I29: 2040 | J29: 2045 | K29: 2050
B30: Métaux primaires | C30: 25.805 | D30: 22.829 | E30: 24.457 | F30: =$E30*R20 -> 25.771903 | G30: =$E30*S20 -> 27.082898 | H30: =$E30*T20 -> 27.438939 | I30: =$E30*U20 -> 29.218666 | J30: =$E30*V20 -> 31.687727 | K30: =$E30*W20 -> 34.388981
B31: Chimie | C31: 47.175 | D31: 45.889 | E31: 46.328 | F31: =$E31*R21 -> 47.670648 | G31: =$E31*S21 -> 50.768485 | H31: =$E31*T21 -> 52.267061 | I31: =$E31*U21 -> 56.524037 | J31: =$E31*V21 -> 61.707015 | K31: =$E31*W21 -> 67.063853
B32: Minéraux non-métalliques | C32: 8.359 | D32: 7.464 | E32: 8.172 | F32: =$E32*R22 -> 8.5177449 | G32: =$E32*S22 -> 8.7279363 | H32: =$E32*T22 -> 8.9041513 | I32: =$E32*U22 -> 9.3350748 | J32: =$E32*V22 -> 9.8976398 | K32: =$E32*W22 -> 10.585064
B33: IAA | C33: 45.598 | D33: 44.089 | E33: 44.859 | F33: =$E33*R23 -> 47.554551 | G33: =$E33*S23 -> 51.504271 | H33: =$E33*T23 -> 55.265993 | I33: =$E33*U23 -> 60.060384 | J33: =$E33*V23 -> 65.270121 | K33: =$E33*W23 -> 70.679032
B34: Equipements | C34: 63.615 | D34: 49.807 | E34: 52.09 | F34: =$E34*R24 -> 55.555071 | G34: =$E34*S24 -> 60.438283 | H34: =$E34*T24 -> 64.996535 | I34: =$E34*U24 -> 70.538499 | J34: =$E34*V24 -> 76.917603 | K34: =$E34*W24 -> 83.983077
