Workbook

Sheet TER_RENO
A1: Sources | B1: Intro | C1: Rénovation des bâtiments tertiaires | H1: 2015 | I1: 2016 | J1: 2017 | K1: 2018 | L1: 2019 | M1: 2020 | N1: 2021 | O1: 2022 | P1: 2023 | Q1: 2024 | S1: 2015 | T1: 2016 | U1: 2017 | V1: 2018 | W1: 2019 | X1: 2020 | Y1: 2021 | Z1: 2022 | AA1: 2023 | AB1: 2024 | AC1: 2025 | AD1: 2026 | AE1: 2027 | AF1: 2028 | AG1: 2029 | AH1: 2030 | AI1: 2031 | AJ1: 2032 | AK1: 2033 | AL1: 2034 | AM1: 2035 | AN1: 2036 | AO1: 2037 | AP1: 2038 | AQ1: 2039 | AR1: 2040 | AS1: 2041 | AT1: 2042 | AU1: 2043 | AV1: 2044 | AW1: 2045 | AX1: 2046 | AY1: 2047 | AZ1: 2048 | BA1: 2049 | BB1: 2050 | BD1: 2015 | BE1: 2016 | BF1: 2017 | BG1: 2018 | BH1: 2019 | BI1: 2020 | BJ1: 2021 | BK1: 2022 | BL1: 2023 | BM1: 2024 | BN1: 2025 | BO1: 2026 | BP1: 2027 | BQ1: 2028 | BR1: 2029 | BS1: 2030 | BT1: 2031 | BU1: 2032 | BV1: 2033 | BW1: 2034 | BX1: 2035 | BY1: 2036 | BZ1: 2037 | CA1: 2038 | CB1: 2039 | CC1: 2040 | CD1: 2041 | CE1: 2042 | CF1: 2043 | CG1: 2044 | CH1: 2045 | CI1: 2046 | CJ1: 2047 | CK1: 2048 | CL1: 2049 | CM1: 2050 | CO1: 2015 | CP1: 2016 | CQ1: 2017 | CR1: 2018 | CS1: 2019 | CT1: 2020 | CU1: 2021 | CV1: 2022 | CW1: 2023 | CX1: 2024 | CY1: 2025 | CZ1: 2026 | DA1: 2027 | DB1: 2028 | DC1: 2029 | DD1: 2030 | DE1: 2031 | DF1: 2032 | DG1: 2033 | DH1: 2034 | DI1: 2035 | DJ1: 2036 | DK1: 2037 | DL1: 2038 | DM1: 2039 | DN1: 2040 | DO1: 2041 | DP1: 2042 | DQ1: 2043 | DR1: 2044 | DS1: 2045 | DT1: 2046 | DU1: 2047 | DV1: 2048 | DW1: 2049 | DX1: 2050 | DZ1: 2015 | EA1: 2016 | EB1: 2017 | EC1: 2018 | ED1: 2019 | EE1: 2020 | EF1: 2021 | EG1: 2022 | EH1: 2023 | EI1: 2024 | EJ1: 2025 | EK1: 2026 | EL1: 2027 | EM1: 2028 | EN1: 2029 | EO1: 2030 | EP1: 2031 | EQ1: 2032 | ER1: 2033 | ES1: 2034 | ET1: 2035 | EU1: 2036 | EV1: 2037 | EW1: 2038 | EX1: 2039 | EY1: 2040 | EZ1: 2041 | FA1: 2042 | FB1: 2043 | FC1: 2044 | FD1: 2045 | FE1: 2046 | FF1: 2047 | FG1: 2048 | FH1: 2049 | FI1: 2050 | FK1: 2015 | FL1: 2016 | FM1: 2017 | FN1: 2018 | FO1: 2019 | FP1: 2020 | FQ1: 2021 | FR1: 2022 | FS1: 2023 | FT1: 2024 | FU1: 2025 | FV1: 2026 | FW1: 2027 | FX1: 2028 | FY1: 2029 | FZ1: 2030 | GA1: 2031 | GB1: 2032 | GC1: 2033 | GD1: 2034 | GE1: 2035 | GF1: 2036 | GG1: 2037 | GH1: 2038 | GI1: 2039 | GJ1: 2040 | GK1: 2041 | GL1: 2042 | GM1: 2043 | GN1: 2044 | GO1: 2045 | GP1: 2046 | GQ1: 2047 | GR1: 2048 | GS1: 2049 | GT1: 2050 | GV1: 2015 | GW1: 2016 | GX1: 2017 | GY1: 2018 | GZ1: 2019 | HA1: 2020 | HB1: 2021 | HC1: 2022 | HD1: 2023 | HE1: 2024 | HF1: 2025 | HG1: 2026 | HH1: 2027 | HI1: 2028 | HJ1: 2029 | HK1: 2030 | HL1: 2031 | HM1: 2032 | HN1: 2033 | HO1: 2034 | HP1: 2035 | HQ1: 2036 | HR1: 2037 | HS1: 2038 | HT1: 2039 | HU1: 2040 | HV1: 2041 | HW1: 2042 | HX1: 2043 | HY1: 2044 | HZ1: 2045 | IA1: 2046 | IB1: 2047 | IC1: 2048 | ID1: 2049 | IE1: 2050 | IG1: 2015 | IH1: 2016 | II1: 2017 | IJ1: 2018 | IK1: 2019 | IL1: 2020 | IM1: 2021 | IN1: 2022 | IO1: 2023 | IP1: 2024 | IQ1: 2025 | IR1: 2026 | IS1: 2027 | IT1: 2028 | IU1: 2029 | IV1: 2030 | IW1: 2031 | IX1: 2032 | IY1: 2033 | IZ1: 2034 | JA1: 2035 | JB1: 2036 | JC1: 2037 | JD1: 2038 | JE1: 2039 | JF1: 2040 | JG1: 2041 | JH1: 2042 | JI1: 2043 | JJ1: 2044 | JK1: 2045 | JL1: 2046 | JM1: 2047 | JN1: 2048 | JO1: 2049 | JP1: 2050 | JR1: 2015 | JS1: 2016 | JT1: 2017 | JU1: 2018 | JV1: 2019 | JW1: 2020 | JX1: 2021 | JY1: 2022 | JZ1: 2023 | KA1: 2024 | KB1: 2025 | KC1: 2026 | KD1: 2027 | KE1: 2028 | KF1: 2029 | KG1: 2030 | KH1: 2031 | KI1: 2032 | KJ1: 2033 | KK1: 2034 | KL1: 2035 | KM1: 2036 | KN1: 2037 | KO1: 2038 | KP1: 2039 | KQ1: 2040 | KR1: 2041 | KS1: 2042 | KT1: 2043 | KU1: 2044 | KV1: 2045 | KW1: 2046 | KX1: 2047 | KY1: 2048 | KZ1: 2049 | LA1: 2050 | LC1: 2015 | LD1: 2016 | LE1: 2017 | LF1: 2018 | LG1: 2019 | LH1: 2020 | LI1: 2021 | LJ1: 2022 | LK1: 2023 | LL1: 2024 | LM1: 2025 | LN1: 2026 | LO1: 2027 | LP1: 2028 | LQ1: 2029 | LR1: 2030 | LS1: 2031 | LT1: 2032 | LU1: 2033 | LV1: 2034 | LW1: 2035 | LX1: 2036 | LY1: 2037 | LZ1: 2038 | MA1: 2039 | MB1: 2040 | MC1: 2041 | MD1: 2042 | ME1: 2043 | MF1: 2044 | MG1: 2045 | MH1: 2046 | MI1: 2047 | MJ1: 2048 | MK1: 2049 | ML1: 2050
H2: Historique | S2: AMS 2018 | BD2: ADEME Tend. | CO2: ADEME S1 | DZ2: ADEME S2 | FK2: ADEME S3 | GV2: ADEME S4 | IG2: AME 2023 | JR2: AMS run 2 2023 | LC2: AMS run 3 2025
C4: Dernière modif. | D4: 44816 | H4: Historique | I4: Historique | J4: Historique | K4: Historique | L4: Historique | M4: Historique | N4: Historique | O4: Historique | P4: Historique | Q4: Historique | S4: SNBC | T4: SNBC | U4: SNBC | V4: SNBC | W4: SNBC | X4: SNBC | Y4: SNBC | Z4: SNBC | AA4: SNBC | AB4: SNBC | AC4: SNBC | AD4: SNBC | AE4: SNBC | AF4: SNBC | AG4: SNBC | AH4: SNBC | AI4: SNBC | AJ4: SNBC | AK4: SNBC | AL4: SNBC | AM4: SNBC | AN4: SNBC | AO4: SNBC | AP4: SNBC | AQ4: SNBC | AR4: SNBC | AS4: SNBC | AT4: SNBC | AU4: SNBC | AV4: SNBC | AW4: SNBC | AX4: SNBC | AY4: SNBC | AZ4: SNBC | BA4: SNBC | BB4: SNBC | BD4: S0 | BE4: S0 | BF4: S0 | BG4: S0 | BH4: S0 | BI4: S0 | BJ4: S0 | BK4: S0 | BL4: S0 | BM4: S0 | BN4: S0 | BO4: S0 | BP4: S0 | BQ4: S0 | BR4: S0 | BS4: S0 | BT4: S0 | BU4: S0 | BV4: S0 | BW4: S0 | BX4: S0 | BY4: S0 | BZ4: S0 | CA4: S0 | CB4: S0 | CC4: S0 | CD4: S0 | CE4: S0 | CF4: S0 | CG4: S0 | CH4: S0 | CI4: S0 | CJ4: S0 | CK4: S0 | CL4: S0 | CM4: S0 | CO4: S1 | CP4: S1 | CQ4: S1 | CR4: S1 | CS4: S1 | CT4: S1 | CU4: S1 | CV4: S1 | CW4: S1 | CX4: S1 | CY4: S1 | CZ4: S1 | DA4: S1 | DB4: S1 | DC4: S1 | DD4: S1 | DE4: S1 | DF4: S1 | DG4: S1 | DH4: S1 | DI4: S1 | DJ4: S1 | DK4: S1 | DL4: S1 | DM4: S1 | DN4: S1 | DO4: S1 | DP4: S1 | DQ4: S1 | DR4: S1 | DS4: S1 | DT4: S1 | DU4: S1 | DV4: S1 | DW4: S1 | DX4: S1 | DZ4: S2 | EA4: S2 | EB4: S2 | EC4: S2 | ED4: S2 | EE4: S2 | EF4: S2 | EG4: S2 | EH4: S2 | EI4: S2 | EJ4: S2 | EK4: S2 | EL4: S2 | EM4: S2 | EN4: S2 | EO4: S2 | EP4: S2 | EQ4: S2 | ER4: S2 | ES4: S2 | ET4: S2 | EU4: S2 | EV4: S2 | EW4: S2 | EX4: S2 | EY4: S2 | EZ4: S2 | FA4: S2 | FB4: S2 | FC4: S2 | FD4: S2 | FE4: S2 | FF4: S2 | FG4: S2 | FH4: S2 | FI4: S2 | FK4: S3 | FL4: S3 | FM4: S3 | FN4: S3 | FO4: S3 | FP4: S3 | FQ4: S3 | FR4: S3 | FS4: S3 | FT4: S3 | FU4: S3 | FV4: S3 | FW4: S3 | FX4: S3 | FY4: S3 | FZ4: S3 | GA4: S3 | GB4: S3 | GC4: S3 | GD4: S3 | GE4: S3 | GF4: S3 | GG4: S3 | GH4: S3 | GI4: S3 | GJ4: S3 | GK4: S3 | GL4: S3 | GM4: S3 | GN4: S3 | GO4: S3 | GP4: S3 | GQ4: S3 | GR4: S3 | GS4: S3 | GT4: S3 | GV4: S4 | GW4: S4 | GX4: S4 | GY4: S4 | GZ4: S4 | HA4: S4 | HB4: S4 | HC4: S4 | HD4: S4 | HE4: S4 | HF4: S4 | HG4: S4 | HH4: S4 | HI4: S4 | HJ4: S4 | HK4: S4 | HL4: S4 | HM4: S4 | HN4: S4 | HO4: S4 | HP4: S4 | HQ4: S4 | HR4: S4 | HS4: S4 | HT4: S4 | HU4: S4 | HV4: S4 | HW4: S4 | HX4: S4 | HY4: S4 | HZ4: S4 | IA4: S4 | IB4: S4 | IC4: S4 | ID4: S4 | IE4: S4 | IG4: AME 2023 | IH4: AME 2023 | II4: AME 2023 | IJ4: AME 2023 | IK4: AME 2023 | IL4: AME 2023 | IM4: AME 2023 | IN4: AME 2023 | IO4: AME 2023 | IP4: AME 2023 | IQ4: AME 2023 | IR4: AME 2023 | IS4: AME 2023 | IT4: AME 2023 | IU4: AME 2023 | IV4: AME 2023 | IW4: AME 2023 | IX4: AME 2023 | IY4: AME 2023 | IZ4: AME 2023 | JA4: AME 2023 | JB4: AME 2023 | JC4: AME 2023 | JD4: AME 2023 | JE4: AME 2023 | JF4: AME 2023 | JG4: AME 2023 | JH4: AME 2023 | JI4: AME 2023 | JJ4: AME 2023 | JK4: AME 2023 | JL4: AME 2023 | JM4: AME 2023 | JN4: AME 2023 | JO4: AME 2023 | JP4: AME 2023 | JR4: AMS2 2023 | JS4: AMS2 2023 | JT4: AMS2 2023 | JU4: AMS2 2023 | JV4: AMS2 2023 | JW4: AMS2 2023 | JX4: AMS2 2023 | JY4: AMS2 2023 | JZ4: AMS2 2023 | KA4: AMS2 2023 | KB4: AMS2 2023 | KC4: AMS2 2023 | KD4: AMS2 2023 | KE4: AMS2 2023 | KF4: AMS2 2023 | KG4: AMS2 2023 | KH4: AMS2 2023 | KI4: AMS2 2023 | KJ4: AMS2 2023 | KK4: AMS2 2023 | KL4: AMS2 2023 | KM4: AMS2 2023 | KN4: AMS2 2023 | KO4: AMS2 2023 | KP4: AMS2 2023 | KQ4: AMS2 2023 | KR4: AMS2 2023 | KS4: AMS2 2023 | KT4: AMS2 2023 | KU4: AMS2 2023 | KV4: AMS2 2023 | KW4: AMS2 2023 | KX4: AMS2 2023 | KY4: AMS2 2023 | KZ4: AMS2 2023 | LA4: AMS2 2023 | LC4: AMS3 2025 | LD4: AMS3 2025 | LE4: AMS3 2025 | LF4: AMS3 2025 | LG4: AMS3 2025 | LH4: AMS3 2025 | LI4: AMS3 2025 | LJ4: AMS3 2025 | LK4: AMS3 2025 | LL4: AMS3 2025 | LM4: AMS3 2025 | LN4: AMS3 2025 | LO4: AMS3 2025 | LP4: AMS3 2025 | LQ4: AMS3 2025 | LR4: AMS3 2025 | LS4: AMS3 2025 | LT4: AMS3 2025 | LU4: AMS3 2025 | LV4: AMS3 2025 | LW4: AMS3 2025 | LX4: AMS3 2025 | LY4: AMS3 2025 | LZ4: AMS3 2025 | MA4: AMS3 2025 | MB4: AMS3 2025 | MC4: AMS3 2025 | MD4: AMS3 2025 | ME4: AMS3 2025 | MF4: AMS3 2025 | MG4: AMS3 2025 | MH4: AMS3 2025 | MI4: AMS3 2025 | MJ4: AMS3 2025 | MK4: AMS3 2025 | ML4: AMS3 2025
C6: Contenu | D6: Les travaux d'entretien-amélioration et de rénovation des bâtiments tertiaires.
C8: Sommaire
C10: Définitions
C11: Parc de bâtiments
C12: Consommation d'énergie
C13: Nombre de rénovations
C14: Le dispositif éco-énergie tertiaire (DEET) et les rénovations basse consommation (BBC)
C15: Les autres rénovations
C16: Coûts
C17: Investissements
B20: retour | C20: Définitions
C22: Parc tertiaire
C24: Les bâtiments tertiaires font partie des bâtiments non-résidentiels et hébergent les activités économiques du secteur tertiaire (par opposition aux locaux agricoles et industriels).
C25: Les surfaces chauffées de ces bâtiments sont recensées par le CEREN qui les regroupe en huit branches.
C26: Les consommations énergétiques du tertiaire comprennent non seulement les consommations des bâtiments, mais aussi de l'éclairage public, des armées, des grands centres de recherche, des télécommunications, du secteur de l'eau ou encore des data centers.
C27: Toutes ces consommations "hors bâtiment" ne sont pas étudiées ici.
C29: Travaux de rénovation énergétique
C31: Différentes études retiennent des périmètres légèrement différents pour caractériser les coûts de rénovation énergétique
C33: Ministère de la Transition Ecologique et Solidaire et Ministère de la Cohésion des Territoires, « Calcul des niveaux optimaux en fonction des coûts des exigences minimales en matière de performance énergétique », pp.26-27
C34: Les coûts d’investissement initiaux recouvrent tous les coûts supportés jusqu’à la livraison (...) de l’élément de bâtiment, prêt à l’emploi. (...) tous les coûts des éléments qui n’ont pas d’incidence sur [la performance énergétique] ont été omis (…).
C35: rénovation il a cependant été choisi d’intégrer les coûts suivants : échafaudages, ensemble des déposes (systèmes ou isolation préexistante, le cas échéant) finitions « minimales » (par exemple : (…) enduit sur ITE)
C37: Observatoire BBC, « Guide méthodologique : comment analyser les coûts associés à la rénovation énergétique ? »
C38: Les travaux de rénovation énergétique regroupent les lots « Enveloppe – Rénovation Energétique » et « Equipements – Rénovation Energétique »
... C63: European Commission, « Guidelines Accompanying Commission Delegated Regulation (EU) No 244/2012 ».
B64: [LIEN] | C64: Dans ses recommandations accompagnant la directive de 2012 sur la performance énergétique des bâtiments, la Commission Européenne fournit (p.6)une liste indicative d'équipements liés à la performance énergétique.
C65: Les dépenses listées peuvent concerner la structure (ou enveloppe) du bâtiment (isolation des murs, des toitures…), ou les systèmes (chauffage, eau chaude sanitaire, ventilateurs, calorifugeage des conduites, etc.)
C66: Cependant, nous ne sommes pas en mesure de déterminer si toutes les sources exploitées dans ce document se réfèrent au même périmètre de travaux.
C68: Rénovation énergétique et investissements favorables au climat
C70: Au sein des investissements historiques du secteur, les dépenses d'installation de systèmes de chauffage gaz et fioul, qui sont classés comme investissements fossiles.
C71: Faute d'une représentation aussi détaillée des travaux, dans cet onglet prospectif, tous les travaux anticipés sont considérés favorables au climat. On considère que les ventes de chaudières gaz et fioul sont négligeables dans les totaux simulés.
C73: Les autres travaux de rénovation et le coût des opérations
C75: Les données de référence de l'Observatoire BBC font apparaitre une distinciton importante entre le coût des rénovations énergétiques, le coût des autres travaux de rénovation et le coût total des opérations.
C76: Le coût des travaux énergétiques est décrit ci-dessus, le champ exact varie peu d'une étude à l'autre
C77: Les autres travaux de rénovation comprennent la démolition, le nettoyage, les échafaudages, le gros œuvre, l'étanchéité, la plomberie, la peinture, les ascenseurs… liste non exhautive (voir source Observatoire BBC op. cit., pp.56)
C78: Le coût complet des opérations comprend, outre les travaux de rénovation ci-dessus, le coût du foncier, de la MOE et de l'assistance à MOA, l'ingénierie, les labels et frais de concours, l'instrumentation, l'aménagement et le poste VRD, les frais et taxes, ainsi que les frais pour imprévus
C81: Input ADEME
B83: Zone input
...

Sheet axTER
C1: Scénarios de rénovation tertiaire
C3: Commissariat Général au Développement Durable et al., « Scénarios de rénovation énergétique des bâtiments tertiaires - Quelles solutions pour quels coûts à l’horizon 2050 ? »
C5: Aperçu des résultats
C6: Nom | G6: P0 | H6: P0 | I6: P0 | J6: REF | K6: AME | L6: AMSDec0
C7: Couverture | G7: parc existant | H7: parc existant | I7: parc total | J7: parc total | K7: parc total | L7: parc total
C8: Année | G8: 2019 | H8: 2050 | I8: 2050 | J8: 2050 | K8: 2050 | L8: 2050
B9: p.71 | C9: Conso. unitaire moy. (kWhEF/m² par an) | G9: 109 | H9: 74 | I9: 59 | J9: 52 | K9: 41 | L9: 28
B10: idem | C10: Besoin unitaire moy. (kWhEF/m² par an) | G10: 97 | H10: 82 | I10: 68 | J10: 64 | K10: 55 | L10: 46
C11: gain sur besoin moyen (% 2019) | H11: =(H10-$G$10)/$G$10 -> -0.15463918 | I11: =(I10-$G$10)/$G$10 -> -0.29896907 | J11: =(J10-$G$10)/$G$10 -> -0.34020619 | K11: =(K10-$G$10)/$G$10 -> -0.43298969 | L11: =(L10-$G$10)/$G$10 -> -0.5257732
B12: idem | C12: Rendement moyen | G12: 0.9 | H12: 1.1 | I12: 1.2 | J12: 1.2 | K12: 1.3 | L12: 1.6
B13: p.69 | C13: Consommations en énergie primaire (kWhEP/m² par an) | G13: 284 | H13: 194 | I13: n.d. | J13: 187 | K13: 176 | L13: 130
C15: Corrections pour séparer les effets de la construction neuve et des rénovations.
C18: Dynamiques de construction
C19: Surfaces construites (en mm²) | G19: en 2010 | H19: en 2020 | I19: en 2030 | J19: en 2040 | K19: en 2050
C20: Scénarios REF & AME | G20: 10 | H20: 112 | I20: 152 | J20: 194 | K20: 345
C21: Scénarios AMS | G21: 10 | H21: 112 | I21: 148 | J21: 186 | K21: 319
C22: source: op. cit. pp.54-55, tableaux 13 et 14
C24: Dynamiques de construction, par période
C25: Surfaces construites (en mm²) | G25: 2010-2020 | H25: 2021-2030 | I25: 2031-2040 | J25: 2041-2050 | K25: Ensemble
C26: Scénarios REF & AME | G26: =H20 -> 112 | H26: =I20-H20 -> 40 | I26: =J20-I20 -> 42 | J26: =K20-J20 -> 151 | K26: =SUM(G26:J26) -> 345
C27: Scénarios AMS | G27: =H21 -> 112 | H27: =I21-H21 -> 36 | I27: =J21-I21 -> 38 | J27: =K21-J21 -> 133 | K27: =SUM(G27:J27) -> 319
C28: Ancien : 818 millions de m²
C31: Besoins unitaires des bâtiments neufs pour le chauffage, scénarios REF et AME
G32: Parc existant | H32: Parc total | I32: Parc neuf
C33: Besoin unitaire moy. (kWhEF/m² par an) | G33: 82 | H33: 68 | I33: =(H33*H34-G33*G34)/I34 -> 34.724638
C34: Nombre de logements | G34: 820 | H34: =820+345 -> 1165 | I34: 345
C36: Besoins unitaires des bâtiments neufs pour le chauffage
C37: (en kWhEF/m² par an) | G37: 2010-2020 | H37: 2021-2030 | I37: 2031-2040 | J37: 2041-2050 | K37: Ensemble
C38: Scénarios REF & AME | G38: 35 | H38: 35 | I38: 35 | J38: 35
C39: Scénarios AMS | G39: 35 | H39: =$G$38*(1-5%) -> 33.25 | I39: =$G$38*(1-15%) -> 29.75 | J39: =$G$38*(1-30%) -> 24.5 | K39: =SUMPRODUCT(G39:J39,G27:J27)/K27 -> 29.799373
C40: source: op. cit. p.55, Pour les scénarios AMS, (…), l’hypothèse retenue est de faire baisser les besoins unitaires des bâtiments entrants progressivement entre 2020 et 2050.
C43: Besoins unitaires des bâtiments neufs pour le chauffage, scénarios AMS
G44: Parc existant | H44: Parc total | I44: Parc neuf
C45: Besoin unitaire moy. (kWhEF/m² par an) | G45: =(H45*H46-I45*I46)/G46 -> 52.239609 | H45: 46 | I45: 30
C46: Nombre de logements | G46: 818 | H46: =818+319 -> 1137 | I46: 319
C49: Coûts unitaires rénovations tertiaires
C51: Agence de l’Environnement et de la Maîtrise de l’Energie, « Retours d’expérience : 12 projets de rénovation énergétique de bâtiments tertiaires en Auvergne Rhône-Alpes ».
C52: Région Auvergne-Rhône-Alpes, « Fiches projet rénovation énergétique », 2017
G54: Consommation (GWh) | J54: Surface | K54: Coût des travaux
G55: Avant travaux | H55: Après travaux | I55: Gain | K55: Total | L55: dont conception - réalisation | M55: dont EE | N55: total / m² | O55: EE / m²
...
