Workbook

Sheet Parc et émission
J1: 2023 | K1: 2024 | L1: 2025 | M1: 2026 | N1: 2027 | O1: 2028 | P1: 2029 | Q1: 2030 | R1: 2031 | S1: 2032 | T1: 2033 | U1: 2034 | V1: 2035 | W1: 2036 | X1: 2037 | Y1: 2038 | Z1: 2039 | AA1: 2040 | AB1: 2041 | AC1: 2042 | AD1: 2043 | AE1: 2044 | AF1: 2045 | AG1: 2046 | AH1: 2047 | AI1: 2048 | AJ1: 2049 | AK1: 2050
H2: Emissions (calculées par le modèle)
H3: Emission Natural gas (MtCO2) | I3: Emissions du gaz (MtCO2) | J3: 20.029027 | K3: 19.411973 | L3: 18.814169 | M3: 17.709596 | N3: 16.390503 | O3: 15.312056 | P3: 14.157466 | Q3: 12.991709 | R3: 11.875064 | S3: 10.772317 | T3: 9.7862683 | U3: 8.9065488 | V3: 8.108356 | W3: 7.1768011 | X3: 6.3278906 | Y3: 5.5623376 | Z3: 4.9445608 | AA3: 3.5846932 | AB3: 3.8216626 | AC3: 3.4012273 | AD3: 3.0332031 | AE3: 2.7097249 | AF3: 2.4235973 | AG3: 1.860759 | AH3: 1.3507376 | AI3: 0.86911672 | AJ3: 0.41692318 | AK3: 0
H4: Emission Oil fuel (MtCO2) | I4: Emissions du fioul (MtCO2) | J4: 10.044 | K4: 9.04 | L4: 8.097 | M4: 7.01 | N4: 5.831 | O4: 4.898 | P4: 4.019 | Q4: 3.234 | R4: 2.495 | S4: 1.814 | T4: 1.177 | U4: 0.575 | V4: 0 | W4: 0 | X4: 0 | Y4: 0 | Z4: 0 | AA4: 0 | AB4: 0 | AC4: 0 | AD4: 0 | AE4: 0 | AF4: 0 | AG4: 0 | AH4: 0 | AI4: 0 | AJ4: 0 | AK4: 0
H5: Emission Electricity (MtCO2) | I5: Emissions de l'électricité (MtCO2) | J5: 4.021 | K5: 3.938 | L5: 3.908 | M5: 3.882 | N5: 3.888 | O5: 3.888 | P5: 3.876 | Q5: 3.84 | R5: 3.824 | S5: 3.802 | T5: 3.791 | U5: 3.791 | V5: 3.801 | W5: 3.779 | X5: 3.761 | Y5: 3.745 | Z5: 3.726 | AA5: 3.705 | AB5: 3.674 | AC5: 3.647 | AD5: 3.618 | AE5: 3.623 | AF5: 3.623 | AG5: 3.635 | AH5: 3.64 | AI5: 3.65 | AJ5: 3.664 | AK5: 3.68
I7: Directes | J7: 30.073027 | K7: 28.451973 | L7: 26.911169 | M7: 24.719596 | N7: 22.221503 | O7: 20.210056 | P7: 18.176466 | Q7: 16.225709 | R7: 14.370064 | S7: 12.586317 | T7: 10.963268 | U7: 9.4815488 | V7: 8.108356 | W7: 7.1768011 | X7: 6.3278906 | Y7: 5.5623376 | Z7: 4.9445608 | AA7: 3.5846932 | AB7: 3.8216626 | AC7: 3.4012273 | AD7: 3.0332031 | AE7: 2.7097249 | AF7: 2.4235973 | AG7: 1.860759 | AH7: 1.3507376 | AI7: 0.86911672 | AJ7: 0.41692318 | AK7: 0
I8: Gain annuel | K8: 1.5408046 | L8: 2.1915729 | M8: 2.4980925 | N8: 2.0114475 | O8: 2.0335901 | P8: 1.9507562 | Q8: 1.8556452 | R8: 1.7837469 | S8: 1.623049 | T8: 1.4817194 | U8: 1.3731928 | V8: 0.93155488 | W8: 0.84891054 | X8: 0.76555296 | Y8: 0.61777687 | Z8: 1.3598676 | AA8: -0.23696939 | AB8: 0.42043533 | AC8: 0.3680242 | AD8: 0.32347818 | AE8: 0.2861276 | AF8: 0.56283833 | AG8: 0.51002133 | AH8: 0.48162091 | AI8: 0.45219353 | AJ8: 0.41692318 | AK8: #REF!
H10: Année historique de sobriété : on estime que 2/3 du chemin est fait entre 2020 et 2023
H11: Hyp sobriété | I11: Economie d'énergie (2030/2020) | L11: 0.07
I12: Economie d'énergie (2050/2030) | L12: 0.03
I13: Chemin parcouru en 2023 | L13: 0.66666667 | P13: Par rapport à 2023
H14: Hypothèse de sobriété (baisse température de consigne & individualisation frais en collectif) | J14: 1 | K14: 0.99666667 | L14: 0.99333333 | M14: 0.99 | N14: 0.98666667 | O14: 0.98333333 | P14: 0.98 | Q14: 0.97666667 | R14: 0.97516667 | S14: 0.97366667 | T14: 0.97216667 | U14: 0.97066667 | V14: 0.96916667 | W14: 0.96766667 | X14: 0.96616667 | Y14: 0.96466667 | Z14: 0.96316667 | AA14: 0.96166667 | AB14: 0.96016667 | AC14: 0.95866667 | AD14: 0.95716667 | AE14: 0.95566667 | AF14: 0.95416667 | AG14: 0.95266667 | AH14: 0.95116667 | AI14: 0.94966667 | AJ14: 0.94816667 | AK14: 0.94666667
H15: Impact du changement climatique (RCP2.6) | J15: 1 | K15: 0.99 | L15: 0.98 | M15: 0.97 | N15: 0.96 | O15: 0.95 | P15: 0.94 | Q15: 0.93 | R15: 0.9275 | S15: 0.925 | T15: 0.9225 | U15: 0.92 | V15: 0.9175 | W15: 0.915 | X15: 0.9125 | Y15: 0.91 | Z15: 0.9075 | AA15: 0.905 | AB15: 0.9025 | AC15: 0.9 | AD15: 0.8975 | AE15: 0.895 | AF15: 0.8925 | AG15: 0.89 | AH15: 0.8875 | AI15: 0.885 | AJ15: 0.8825 | AK15: 0.88
H16: Variation de la demande induite | J16: 1 | K16: 0.9867 | L16: 0.97346667 | M16: 0.9603 | N16: 0.9472 | O16: 0.93416667 | P16: 0.9212 | Q16: 0.9083 | R16: 0.90446708 | S16: 0.90064167 | T16: 0.89682375 | U16: 0.89301333 | V16: 0.88921042 | W16: 0.885415 | X16: 0.88162708 | Y16: 0.87784667 | Z16: 0.87407375 | AA16: 0.87030833 | AB16: 0.86655042 | AC16: 0.8628 | AD16: 0.85905708 | AE16: 0.85532167 | AF16: 0.85159375 | AG16: 0.84787333 | AH16: 0.84416042 | AI16: 0.840455 | AJ16: 0.83675708 | AK16: 0.83306667
H18: Emissions (incluant CC)
H19: Emissions du gaz (MtCO2) | J19: 20.029027 | K19: 19.153794 | L19: 18.314966 | M19: 17.006525 | N19: 15.525085 | O19: 14.304012 | P19: 13.041857 | Q19: 11.80037 | R19: 10.740605 | S19: 9.7019977 | T19: 8.7765578 | U19: 7.9536669 | V19: 7.2100346 | W19: 6.3544474 | X19: 5.5788397 | Y19: 4.8828795 | Z19: 4.3219108 | AA19: 3.1197884 | AB19: 3.3116633 | AC19: 2.9345789 | AD19: 2.6056946 | AE19: 2.3176864 | AF19: 2.0639203 | AG19: 1.5776879 | AH19: 1.1402392 | AI19: 0.73045349 | AJ19: 0.34886343 | AK19: 0
H20: Emissions du fioul (MtCO2) | J20: 10.044 | K20: 8.919768 | L20: 7.8821596 | M20: 6.731703 | N20: 5.5231232 | O20: 4.5755483 | P20: 3.7023028 | Q20: 2.9374422 | R20: 2.2566454 | S20: 1.633764 | T20: 1.0555616 | U20: 0.51348267 | V20: 0 | W20: 0 | X20: 0 | Y20: 0 | Z20: 0 | AA20: 0 | AB20: 0 | AC20: 0 | AD20: 0 | AE20: 0 | AF20: 0 | AG20: 0 | AH20: 0 | AI20: 0 | AJ20: 0 | AK20: 0
H21: Emissions de l'électricité (MtCO2) | J21: 4.021 | K21: 3.8856246 | L21: 3.8043077 | M21: 3.7278846 | N21: 3.6827136 | O21: 3.63204 | P21: 3.5705712 | Q21: 3.487872 | R21: 3.4586821 | S21: 3.4242396 | T21: 3.3998588 | U21: 3.3854135 | V21: 3.3798888 | W21: 3.3459833 | X21: 3.3157995 | Y21: 3.2875358 | Z21: 3.2567988 | AA21: 3.2244924 | AB21: 3.1837062 | AC21: 3.1466316 | AD21: 3.1080685 | AE21: 3.0988304 | AF21: 3.0853242 | AG21: 3.0820196 | AH21: 3.0727439 | AI21: 3.0676608 | AJ21: 3.065878 | AK21: 3.0656853
H23: Directes | J23: 30.073027 | K23: 28.073562 | L23: 26.197126 | M23: 23.738228 | N23: 21.048208 | O23: 18.87956 | P23: 16.74416 | Q23: 14.737812 | R23: 12.99725 | S23: 11.335762 | T23: 9.8321194 | U23: 8.4671495 | V23: 7.2100346 | W23: 6.3544474 | X23: 5.5788397 | Y23: 4.8828795 | Z23: 4.3219108 | AA23: 3.1197884 | AB23: 3.3116633 | AC23: 2.9345789 | AD23: 2.6056946 | AE23: 2.3176864 | AF23: 2.0639203 | AG23: 1.5776879 | AH23: 1.1402392 | AI23: 0.73045349 | AJ23: 0.34886343 | AK23: 0
H24: Gain annuel | K24: -1.9994652 | L24: -1.8764364 | M24: -2.4588979 | N24: -2.6900199 | O24: -2.1686475 | P24: -2.1354003 | Q24: -2.0063483 | R24: -1.7405618 | S24: -1.6614883 | T24: -1.5036424 | U24: -1.3649698 | V24: -1.2571149 | W24: -0.85558726 | X24: -0.77560765 | Y24: -0.69596018 | Z24: -0.56096878 | AA24: -1.2021224 | AB24: 0.19187494 | AC24: -0.37708443 | AD24: -0.32888431 | AE24: -0.28800817 | AF24: -0.2537661 | AG24: -0.4862324 | AH24: -0.43744866 | AI24: -0.40978574 | AJ24: -0.38159006 | AK24: -0.34886343
H25: Réduction vs 2019 | L25: -0.066839983 | M25: -0.15442765 | N25: -0.25024805 | O25: -0.3274968 | P25: -0.40356125 | Q25: -0.47502879 | R25: -0.53702882 | S25: -0.5962122 | T25: -0.649773 | U25: -0.69839419 | V25: -0.7431735 | W25: -0.77365012 | X25: -0.80127781 | Y25: -0.8260684 | Z25: -0.8460505 | AA25: -0.88887095 | AB25: -0.88203623 | AC25: -0.89546824 | AD25: -0.90718333 | AE25: -0.91744238 | AF25: -0.92648171 | AG25: -0.94380165 | AH25: -0.95938388 | AI25: -0.97398073 | AJ25: -0.98757324 | AK25: -1
H27: Parc DPE | K27: 28.565027
H29: Stock A (Million) | I29: A | J29: 0.397 | K29: 0.545 | L29: 0.775 | M29: 1.014 | N29: 1.262 | O29: 1.51 | P29: 1.759 | Q29: 1.947 | R29: 2.151 | S29: 2.352 | T29: 2.561 | U29: 2.779 | V29: 3.006 | W29: 3.225 | X29: 3.456 | Y29: 3.696 | Z29: 3.938 | AA29: 4.114 | AB29: 4.287 | AC29: 4.464 | AD29: 4.639 | AE29: 4.768 | AF29: 4.894 | AG29: 5.018 | AH29: 5.14 | AI29: 5.259 | AJ29: 5.377 | AK29: 5.496 | AL29: 0.53053502
H30: Stock B (Million) | I30: B | J30: 2.156 | K30: 2.435 | L30: 2.759 | M30: 3.108 | N30: 3.485 | O30: 3.88 | P30: 4.298 | Q30: 4.71 | R30: 5.155 | S30: 5.623 | T30: 6.116 | U30: 6.629 | V30: 7.16 | W30: 7.629 | X30: 8.12 | Y30: 8.624 | Z30: 9.106 | AA30: 9.578 | AB30: 10.029 | AC30: 10.477 | AD30: 10.901 | AE30: 11.173 | AF30: 11.425 | AG30: 11.68 | AH30: 11.916 | AI30: 12.146 | AJ30: 12.371 | AK30: 12.591
H31: Stock C (Million) | I31: C | J31: 5.55 | K31: 6.018 | L31: 6.422 | M31: 7.002 | N31: 7.583 | O31: 8.166 | P31: 8.769 | Q31: 9.379 | R31: 9.978 | S31: 10.547 | T31: 11.045 | U31: 11.486 | V31: 11.86 | W31: 12.102 | X31: 12.431 | Y31: 12.671 | Z31: 12.821 | AA31: 13.044 | AB31: 13.095 | AC31: 13.098 | AD31: 13.046 | AE31: 13.008 | AF31: 12.963 | AG31: 12.908 | AH31: 12.849 | AI31: 12.783 | AJ31: 12.712 | AK31: 12.637
H32: Stock D (Million) | I32: D | J32: 12.774 | K32: 12.688 | L32: 12.589 | M32: 12.482 | N32: 12.31 | O32: 12.033 | P32: 11.681 | Q32: 11.26 | R32: 10.956 | S32: 10.538 | T32: 10.066 | U32: 9.524 | V32: 8.953 | W32: 8.478 | X32: 7.845 | Y32: 7.25 | Z32: 6.732 | AA32: 6.126 | AB32: 5.639 | AC32: 5.18 | AD32: 4.785 | AE32: 4.554 | AF32: 4.344 | AG32: 4.134 | AH32: 3.945 | AI32: 3.764 | AJ32: 3.545 | AK32: 3.327
H33: Stock E (Million) | I33: E | J33: 5.024 | K33: 4.841 | L33: 4.622 | M33: 4.394 | N33: 4.143 | O33: 3.882 | P33: 3.616 | Q33: 3.352 | R33: 2.86 | S33: 2.433 | T33: 2.055 | U33: 1.74 | V33: 1.467 | W33: 1.266 | X33: 1.089 | Y33: 0.93 | Z33: 0.795 | AA33: 0.622 | AB33: 0.513 | AC33: 0.416 | AD33: 0.331 | AE33: 0.262 | AF33: 0.199 | AG33: 0.142 | AH33: 0.09 | AI33: 0.043 | AJ33: 0.039 | AK33: 0.036
H34: Stock F (Million) | I34: F | J34: 2.927 | K34: 2.755 | L34: 2.573 | M34: 2.23 | N34: 1.912 | O34: 1.639 | P34: 1.38 | Q34: 1.116 | R34: 0.901 | S34: 0.725 | T34: 0.582 | U34: 0.465 | V34: 0.369 | W34: 0.299 | X34: 0.242 | Y34: 0.192 | Z34: 0.152 | AA34: 0.113 | AB34: 0.087 | AC34: 0.065 | AD34: 0.048 | AE34: 0.037 | AF34: 0.027 | AG34: 0.019 | AH34: 0.012 | AI34: 0.006 | AJ34: 0.005 | AK34: 0.005
H35: Stock G (Million) | I35: G | J35: 1.398 | K35: 1.162 | L35: 0.973 | M35: 0.751 | N35: 0.553 | O35: 0.405 | P35: 0.28 | Q35: 0.195 | R35: 0.137 | S35: 0.097 | T35: 0.068 | U35: 0.049 | V35: 0.035 | W35: 0.027 | X35: 0.021 | Y35: 0.016 | Z35: 0.012 | AA35: 0.009 | AB35: 0.007 | AC35: 0.005 | AD35: 0.003 | AE35: 0.002 | AF35: 0.002 | AG35: 0.001 | AH35: 0.001 | AI35: 0 | AJ35: 0 | AK35: 0
I37: Passoires | J37: 4.325 | K37: 3.917 | L37: 3.546 | M37: 2.981 | N37: 2.465 | O37: 2.044 | P37: 1.66 | Q37: 1.311 | R37: 1.038 | S37: 0.822 | T37: 0.65 | U37: 0.514 | V37: 0.404 | W37: 0.326 | X37: 0.263 | Y37: 0.208 | Z37: 0.164 | AA37: 0.122 | AB37: 0.094 | AC37: 0.07 | AD37: 0.051 | AE37: 0.039 | AF37: 0.029 | AG37: 0.02 | AH37: 0.013 | AI37: 0.006 | AJ37: 0.005 | AK37: 0.005
L38: -0.69687861
J39: 0.084463707
H41: Parc de logements
H42: Stock new (Million) | I42: Neuf | J42: 0 | K42: 0.25 | L42: 0.548 | M42: 0.847 | N42: 1.145 | O42: 1.444 | P42: 1.742 | Q42: 1.952 | R42: 2.162 | S42: 2.372 | T42: 2.582 | U42: 2.792 | V42: 3.002 | W42: 3.212 | X42: 3.422 | Y42: 3.632 | Z42: 3.842 | AA42: 3.942 | AB42: 4.042 | AC42: 4.142 | AD42: 4.242 | AE42: 4.342 | AF42: 4.442 | AG42: 4.542 | AH42: 4.642 | AI42: 4.742 | AJ42: 4.842 | AK42: 4.942
H43: Stock existing (Million) | I43: Existant | J43: 30.225 | K43: 30.195 | L43: 30.165 | M43: 30.134 | N43: 30.103 | O43: 30.072 | P43: 30.04 | Q43: 30.008 | R43: 29.976 | S43: 29.944 | T43: 29.912 | U43: 29.879 | V43: 29.847 | W43: 29.814 | X43: 29.781 | Y43: 29.748 | Z43: 29.714 | AA43: 29.664 | AB43: 29.614 | AC43: 29.563 | AD43: 29.513 | AE43: 29.462 | AF43: 29.411 | AG43: 29.36 | AH43: 29.31 | AI43: 29.259 | AJ43: 29.208 | AK43: 29.15
H45: Stock (Million) | J45: 30.225 | K45: 30.445 | L45: 30.713 | M45: 30.981 | N45: 31.248 | O45: 31.515 | P45: 31.782 | Q45: 31.961 | R45: 32.139 | S45: 32.316 | T45: 32.494 | U45: 32.672 | V45: 32.849 | W45: 33.026 | X45: 33.203 | Y45: 33.38 | Z45: 33.557 | AA45: 33.606 | AB45: 33.656 | AC45: 33.705 | AD45: 33.755 | AE45: 33.804 | AF45: 33.853 | AG45: 33.903 | AH45: 33.952 | AI45: 34.001 | AJ45: 34.05 | AK45: 34.092

Sheet Bilan consommation
B1: 2022 | C1: 2023 | D1: 2024 | E1: 2025 | F1: 2026 | G1: 2027 | H1: 2028 | I1: 2029 | J1: 2030 | K1: 2031 | L1: 2032 | M1: 2033 | N1: 2034 | O1: 2035 | P1: 2036 | Q1: 2037 | R1: 2038 | S1: 2039 | T1: 2040 | U1: 2041 | V1: 2042 | W1: 2043 | X1: 2044 | Y1: 2045 | Z1: 2046 | AA1: 2047 | AB1: 2048 | AC1: 2049 | AD1: 2050
A2: Consommation (incluant CC)
A3: Chauffage urbain | C3: 11.458 | D3: 12.267641 | E3: 12.208245 | F3: 13.523905 | G3: 14.286618 | H3: 16.005078 | I3: 18.748262 | J3: 22.345997 | K3: 24.338305 | L3: 27.323667 | M3: 29.812215 | N3: 31.749303 | O3: 33.213787 | P3: 34.234571 | Q3: 34.577414 | R3: 34.620517 | S3: 34.391306 | T3: 33.736632 | U3: 33.227876 | V3: 32.724278 | W3: 32.249862 | X3: 31.770923 | Y3: 31.306289 | Z3: 30.856654 | AA3: 30.418476 | AB3: 29.992477 | AC3: 29.831227 | AD3: 29.662172
A4: Gaz - Effet rebond | C4: 91.073101 | D4: 96.810133 | E4: 93.553526 | F4: 88.769941 | G4: 82.852804 | H4: 78.08513 | I4: 72.867245 | J4: 67.520762 | K4: 63.404245 | L4: 59.158789 | M4: 55.345027 | N4: 51.935912 | O4: 48.816965 | P4: 45.488281 | Q4: 42.361686 | R4: 39.469858 | S4: 37.316451 | T4: 29.211602 | U4: 32.847982 | V4: 31.268532 | W4: 29.957946 | X4: 28.900666 | Y4: 28.069752 | Z4: 27.065807 | AA4: 26.309127 | AB4: 25.519119 | AC4: 24.633593 | AD4: 23.69458
A5: dont gaz - chaudière | C5: 91 | D5: 87.91201 | E5: 84.929126 | F5: 80.557646 | G5: 75.156531 | H5: 70.801426 | I5: 66.038064 | J5: 61.157656 | K5: 57.282614 | L5: 53.291868 | M5: 49.695694 | N5: 46.469735 | O5: 43.509955 | P5: 40.335966 | Q5: 37.350131 | R5: 34.582769 | S5: 32.490195 | T5: 24.988293 | U5: 28.163755 | V5: 26.600124 | W5: 25.283768 | X5: 24.194484 | Y5: 23.313231 | Z5: 22.276176 | AA5: 21.466155 | AB5: 20.627287 | AC5: 19.703119 | AD5: 18.73317
A6: dont gaz - PAC hybride | C6: 0.073100697 | D6: 0.097202215 | E6: 0.11953408 | F6: 0.14230038 | G6: 0.16419992 | H6: 0.185056 | I6: 0.20488531 | J6: 0.22485534 | K6: 0.35760896 | L6: 0.48884893 | M6: 0.61796674 | N6: 0.74473069 | O6: 0.86910423 | P6: 1.0170171 | Q6: 1.1604925 | R6: 1.2989194 | S6: 1.4338512 | T6: 1.5677089 | U6: 1.6980465 | V6: 1.8258138 | W6: 1.9507282 | X6: 2.0788488 | Y6: 2.2047257 | Z6: 2.3291026 | AA6: 2.4512325 | AB6: 2.5719123 | AC6: 2.6910569 | AD6: 2.8073574
A7: Fioul | C7: 31 | D7: 27.53189 | E7: 24.328879 | F7: 20.77513 | G7: 17.047706 | H7: 14.122732 | I7: 11.426565 | J7: 9.0666506 | K7: 6.9634921 | L7: 5.0408914 | M7: 3.2572639 | N7: 1.5833126 | O7: 0 | P7: 0 | Q7: 0 | R7: 0 | S7: 0 | T7: 0 | U7: 0 | V7: 0 | W7: 0 | X7: 0 | Y7: 0 | Z7: 0 | AA7: 0 | AB7: 0 | AC7: 0 | AD7: 0
A8: Bois | C8: 76.103 | D8: 73.572299 | E8: 71.268468 | F8: 68.384884 | G8: 65.213773 | H8: 62.570483 | I8: 59.876158 | J8: 57.152053 | K8: 55.165256 | L8: 53.228823 | M8: 51.467818 | N8: 49.863185 | O8: 48.38016 | P8: 47.260796 | Q8: 46.169929 | R8: 45.146776 | S8: 44.297184 | T8: 41.955824 | U8: 42.384714 | V8: 41.599039 | W8: 40.885104 | X8: 40.28394 | Y8: 39.738771 | Z8: 39.185314 | AA8: 38.68956 | AB8: 38.202042 | AC8: 37.625619 | AD8: 37.012319
A9: dont chauffage principal | C9: 43.212696 | D9: 42.313859 | E9: 41.536484 | F9: 40.66752 | G9: 39.825102 | H9: 39.024819 | I9: 38.230837 | J9: 37.35855 | K9: 36.866512 | L9: 36.41381 | M9: 35.992303 | N9: 35.597345 | O9: 35.226322 | P9: 34.836627 | Q9: 34.425249 | R9: 34.027909 | S9: 33.639455 | T9: 33.160119 | U9: 32.707682 | V9: 32.265963 | W9: 31.838618 | X9: 31.515579 | Y9: 31.199763 | Z9: 30.903147 | AA9: 30.610416 | AB9: 30.331026 | AC9: 29.983103 | AD9: 29.609636
A10: dont chauffage secondaire | C10: 32.890304 | D10: 31.25844 | E10: 29.731984 | F10: 27.717363 | G10: 25.388671 | H10: 23.545664 | I10: 21.645321 | J10: 19.793503 | K10: 18.298744 | L10: 16.815013 | M10: 15.475516 | N10: 14.26584 | O10: 13.153838 | P10: 12.424169 | Q10: 11.74468 | R10: 11.118867 | S10: 10.657729 | T10: 8.7957056 | U10: 9.6770318 | V10: 9.3330761 | W10: 9.0464862 | X10: 8.7683608 | Y10: 8.5390082 | Z10: 8.2821672 | AA10: 8.0791442 | AB10: 7.8710154 | AC10: 7.6425159 | AD10: 7.4026833
A11: Electricité PAC effet rebond | C11: 6.8116286 | D11: 9.5653716 | E11: 10.642718 | F11: 13.766432 | G11: 14.421999 | H11: 17.711066 | I11: 17.561252 | J11: 20.628961 | K11: 20.185847 | L11: 23.62998 | M11: 22.794815 | N11: 26.546918 | O11: 25.499386 | P11: 29.137969 | Q11: 27.496667 | R11: 31.315374 | S11: 29.323258 | T11: 33.128059 | U11: 30.748053 | V11: 34.495656 | W11: 31.893187 | X11: 35.237197 | Y11: 32.12378 | Z11: 35.494574 | AA11: 32.358146 | AB11: 35.698603 | AC11: 32.54476 | AD11: 35.882576
A12: dont PAC air/air | C12: 1.397 | D12: 2.5788391 | E12: 3.2932377 | F12: 4.5179234 | G12: 4.9358592 | H12: 6.2261274 | I12: 6.2862688 | J12: 7.4904776 | K12: 7.4446686 | L12: 8.8192633 | M12: 8.5978493 | N12: 10.107036 | O12: 9.7902067 | P12: 11.273546 | Q12: 10.715296 | R12: 12.284762 | S12: 11.571862 | T12: 13.150011 | U12: 12.267754 | V12: 13.829994 | W12: 12.844622 | X12: 14.146678 | Y12: 12.851401 | Z12: 14.197893 | AA12: 12.938447 | AB12: 14.279835 | AC12: 13.033328 | AD12: 14.396225
A13: dont PAC air/eau | C13: 4.8818483 | D13: 6.2707997 | E13: 6.5821544 | F13: 8.2757933 | G13: 8.4854928 | H13: 10.257025 | I13: 10.043771 | J13: 11.657625 | K13: 11.160126 | L13: 12.814415 | M13: 12.149848 | N13: 13.934318 | O13: 13.202382 | P13: 14.889477 | Q13: 13.882251 | R13: 15.631339 | S13: 14.472441 | T13: 16.164439 | U13: 14.827857 | V13: 16.445858 | W13: 15.030614 | X13: 16.468384 | Y13: 14.888004 | Z13: 16.274334 | AA13: 14.674091 | AB13: 16.001881 | AC13: 14.409219 | AD13: 15.680536
A14: dont PAC géothermique | C14: 0.48214286 | D14: 0.64166667 | E14: 0.68452381 | F14: 0.86428571 | G14: 0.88690476 | H14: 1.0869048 | I14: 1.0892857 | J14: 1.3095238 | K14: 1.3333333 | L14: 1.6238095 | M14: 1.6190476 | N14: 1.9380952 | O14: 1.9047619 | P14: 2.2 | Q14: 2.0952381 | R14: 2.4095238 | S14: 2.2857143 | T14: 2.6190476 | U14: 2.4761905 | V14: 2.8285714 | W14: 2.6666667 | X14: 3.0380952 | Y14: 2.8571429 | Z14: 3.247619 | AA14: 3.047619 | AB14: 3.4571429 | AC14: 3.2380952 | AD14: 3.6666667
... A16: Electricité Joule effet rebond | C16: 43.913 | D16: 44.306974 | E16: 37.259437 | F16: 37.828234 | G16: 31.86665 | H16: 32.462385 | I16: 27.229751 | J16: 27.452096 | K16: 23.069337 | L16: 23.378676 | M16: 19.54717 | N16: 19.739613 | O16: 16.435276 | P16: 16.435516 | Q16: 13.474788 | R16: 13.283225 | S16: 10.7581 | T16: 10.440741 | U16: 8.2729568 | V16: 7.8375026 | W16: 6.0408894 | X16: 6.2849036 | Y16: 5.3803693 | Z16: 5.642597 | AA16: 4.8606757 | AB16: 5.0939978 | AC16: 4.457405 | AD16: 4.7468139
A20: Parc de logements par énergie
A21: Stock Direct electric (Million) | C21: 8.317 | D21: 8.012 | E21: 7.72 | F21: 7.404 | G21: 7.099 | H21: 6.781 | I21: 6.45 | J21: 6.089 | K21: 5.755 | L21: 5.407 | M21: 5.066 | N21: 4.736 | O21: 4.414 | P21: 4.089 | Q21: 3.778 | R21: 3.477 | S21: 3.179 | T21: 2.888 | U21: 2.593 | V21: 2.303 | W21: 2.017 | X21: 1.947 | Y21: 1.87 | Z21: 1.816 | AA21: 1.754 | AB21: 1.701 | AC21: 1.66 | AD21: 1.629
A22: Stock Heat pump (Million) | C22: 2.896 | D22: 3.642 | E22: 4.498 | F22: 5.316 | G22: 6.185 | H22: 6.996 | I22: 7.745 | J22: 8.373 | K22: 9.092 | L22: 9.751 | M22: 10.437 | N22: 11.154 | O22: 11.902 | P22: 12.522 | Q22: 13.178 | R22: 13.848 | S22: 14.472 | T22: 15.061 | U22: 15.583 | V22: 16.099 | W22: 16.582 | X22: 16.832 | Y22: 17.056 | Z22: 17.302 | AA22: 17.522 | AB22: 17.742 | AC22: 17.959 | AD22: 18.172
A23: PAC air/air | C23: 0.579 | D23: 0.913 | E23: 1.286 | F23: 1.612 | G23: 1.958 | H23: 2.275 | I23: 2.562 | J23: 2.808 | K23: 3.095 | L23: 3.353 | M23: 3.621 | N23: 3.903 | O23: 4.198 | P23: 4.448 | Q23: 4.714 | R23: 4.987 | S23: 5.242 | T23: 5.488 | U23: 5.706 | V23: 5.922 | W23: 6.125 | X23: 6.189 | Y23: 6.241 | Z23: 6.32 | AA23: 6.388 | AB23: 6.46 | AC23: 6.536 | AD23: 6.613
A24: PAC air/eau | C24: 2.0245646 | D24: 2.3706187 | E24: 2.782236 | F24: 3.2056033 | G24: 3.6555253 | H24: 4.0734574 | I24: 4.4583702 | J24: 4.7627941 | K24: 5.04578 | L24: 5.2978753 | M24: 5.5630299 | N24: 5.8441361 | O24: 6.1402783 | P24: 6.3660965 | Q24: 6.6082702 | R24: 6.8542603 | S24: 7.0717581 | T24: 7.262008 | U24: 7.4123467 | V24: 7.557607 | W24: 7.6824197 | X24: 7.7141646 | Y24: 7.7336979 | Z24: 7.7456324 | AA24: 7.7432681 | AB24: 7.7352547 | AC24: 7.719474 | AD24: 7.696786
A25: PAC géothermique | C25: 0.2624354 | D25: 0.31838131 | E25: 0.37976398 | F25: 0.4393967 | G25: 0.5014747 | H25: 0.56654259 | I25: 0.63462976 | J25: 0.70220585 | K25: 0.79122001 | L25: 0.88112466 | M25: 0.97297009 | N25: 1.0668639 | O25: 1.1627217 | P25: 1.2345701 | Q25: 1.3090631 | R25: 1.3867397 | S25: 1.4659085 | T25: 1.5443254 | U25: 1.6246533 | V25: 1.7060597 | W25: 1.7889136 | X25: 1.8678354 | Y25: 1.9479688 | Z25: 2.028701 | AA25: 2.1107319 | AB25: 2.193412 | AC25: 2.2768593 | AD25: 2.362214
A26: PAC hybride | C26: 0.03 | D26: 0.04 | E26: 0.05 | F26: 0.06 | G26: 0.07 | H26: 0.08 | I26: 0.09 | J26: 0.1 | K26: 0.16 | L26: 0.22 | M26: 0.28 | N26: 0.34 | O26: 0.4 | P26: 0.47333333 | Q26: 0.54666667 | R26: 0.62 | S26: 0.69333333 | T26: 0.76666667 | U26: 0.84 | V26: 0.91333333 | W26: 0.98666667 | X26: 1.06 | Y26: 1.1333333 | Z26: 1.2066667 | AA26: 1.28 | AB26: 1.3533333 | AC26: 1.4266667 | AD26: 1.5
A27: Stock Oil fuel (Million) | C27: 3.049 | D27: 2.788 | E27: 2.528 | F27: 2.27 | G27: 2.013 | H27: 1.758 | I27: 1.504 | J27: 1.251 | K27: 0.999 | L27: 0.748 | M27: 0.497 | N27: 0.247 | O27: 0 | P27: 0 | Q27: 0 | R27: 0 | S27: 0 | T27: 0 | U27: 0 | V27: 0 | W27: 0 | X27: 0 | Y27: 0 | Z27: 0 | AA27: 0 | AB27: 0 | AC27: 0 | AD27: 0
A28: Stock Wood fuel (Million) | C28: 2.733 | D28: 2.763 | E28: 2.796 | F28: 2.828 | G28: 2.86 | H28: 2.892 | I28: 2.923 | J28: 2.95 | K28: 2.977 | L28: 3.003 | M28: 3.03 | N28: 3.056 | O28: 3.082 | P28: 3.102 | Q28: 3.121 | R28: 3.141 | S28: 3.158 | T28: 3.172 | U28: 3.184 | V28: 3.195 | W28: 3.205 | X28: 3.207 | Y28: 3.209 | Z28: 3.211 | AA28: 3.212 | AB28: 3.213 | AC28: 3.206 | AD28: 3.196
A29: Stock Natural gas (Million) | C29: 11.809 | D29: 11.674 | E29: 11.552 | F29: 11.295 | G29: 11.045 | H29: 10.713 | I29: 10.287 | J29: 9.776 | K29: 9.397 | L29: 8.919 | M29: 8.47 | N29: 8.059 | O29: 7.68 | P29: 7.25 | Q29: 6.871 | R29: 6.52 | S29: 6.263 | T29: 6.005 | U29: 5.79 | V29: 5.577 | W29: 5.396 | X29: 5.243 | Y29: 5.121 | Z29: 4.956 | AA29: 4.826 | AB29: 4.686 | AC29: 4.528 | AD29: 4.359
A30: Stock District heating (Million) | C30: 1.421 | D30: 1.565 | E30: 1.619 | F30: 1.868 | G30: 2.047 | H30: 2.375 | I30: 2.874 | J30: 3.521 | K30: 3.918 | L30: 4.489 | M30: 4.994 | N30: 5.419 | O30: 5.772 | P30: 6.064 | Q30: 6.255 | R30: 6.395 | S30: 6.484 | T30: 6.48 | U30: 6.506 | V30: 6.53 | W30: 6.554 | X30: 6.576 | Y30: 6.597 | Z30: 6.618 | AA30: 6.638 | AB30: 6.658 | AC30: 6.697 | AD30: 6.735

Sheet Gestes de rénovation
L1: 2023 | M1: 2024 | N1: 2025 | O1: 2026 | P1: 2027 | Q1: 2028 | R1: 2029 | S1: 2030 | T1: 2031 | U1: 2032 | V1: 2033 | W1: 2034 | X1: 2035 | Y1: 2036 | Z1: 2037 | AA1: 2038 | AB1: 2039 | AC1: 2040 | AD1: 2041 | AE1: 2042 | AF1: 2043 | AG1: 2044 | AH1: 2045 | AI1: 2046 | AJ1: 2047 | AK1: 2048 | AL1: 2049 | AM1: 2050
J2: Rénovations (isolation ou chauffage) par saut de classe
J3: Retrofit 6 EPC (Thousand households) | K3: 6 classes | L3: 0 | M3: 0.059 | N3: 0.042 | O3: 1.414 | P3: 1.343 | Q3: 1.142 | R3: 1.058 | S3: 0.817 | T3: 0.637 | U3: 0.494 | V3: 0.383 | W3: 0.297 | X3: 0.229 | Y3: 0.019 | Z3: 0.014 | AA3: 0.011 | AB3: 0.007 | AC3: 0.005 | AD3: 0.003 | AE3: 0.002 | AF3: 0.001 | AG3: 0 | AH3: 0 | AI3: 0 | AJ3: 0 | AK3: 0 | AL3: 0 | AM3: 0
J4: Retrofit 5 EPC (Thousand households) | K4: 5 classes | L4: 0 | M4: 0.773 | N4: 0.648 | O4: 4.173 | P4: 4.006 | Q4: 3.45 | R4: 3.264 | S4: 2.739 | T4: 2.255 | U4: 1.851 | V4: 1.531 | W4: 1.269 | X4: 1.053 | Y4: 0.659 | Z4: 0.55 | AA4: 0.494 | AB4: 0.381 | AC4: 0.309 | AD4: 0.214 | AE4: 0.167 | AF4: 0.127 | AG4: 0.037 | AH4: 0.027 | AI4: 0.016 | AJ4: 0.01 | AK4: 0.004 | AL4: 0.004 | AM4: 0.003
J5: Retrofit 4 EPC (Thousand households) | K5: 4 classes | L5: 0 | M5: 61.33 | N5: 51.213 | O5: 49.727 | P5: 44.856 | Q5: 34.177 | R5: 28.428 | S5: 21.995 | T5: 19.04 | U5: 14.397 | V5: 12.057 | W5: 10.236 | X5: 8.691 | Y5: 5.967 | Z5: 5.145 | AA5: 4.651 | AB5: 3.8 | AC5: 3.214 | AD5: 2.381 | AE5: 1.853 | AF5: 1.411 | AG5: 0.619 | AH5: 0.455 | AI5: 0.297 | AJ5: 0.185 | AK5: 0.081 | AL5: 0.069 | AM5: 0.067
J6: Retrofit 3 EPC (Thousand households) | K6: 3 classes | L6: 0 | M6: 251.615 | N6: 245.021 | O6: 361.174 | P6: 349.793 | Q6: 289.776 | R6: 264.264 | S6: 232.858 | T6: 216.754 | U6: 178.715 | V6: 158.511 | W6: 141.79 | X6: 130.237 | Y6: 94.262 | Z6: 89.474 | AA6: 85.396 | AB6: 77.283 | AC6: 77.977 | AD6: 63.784 | AE6: 57.743 | AF6: 51.652 | AG6: 20.056 | AH6: 17.924 | AI6: 14.259 | AJ6: 12.85 | AK6: 10.356 | AL6: 8.939 | AM6: 8.094
J7: Retrofit 2 EPC (Thousand households) | K7: 2 classes | L7: 0 | M7: 354.066 | N7: 379.101 | O7: 476.532 | P7: 497.146 | Q7: 476.988 | R7: 469.493 | S7: 462.88 | T7: 564.206 | U7: 511.107 | V7: 495.06 | W7: 481.824 | X7: 473.071 | Y7: 369.384 | Z7: 395.996 | AA7: 400.321 | AB7: 369.173 | AC7: 432.594 | AD7: 349.012 | AE7: 337.753 | AF7: 309.796 | AG7: 155.376 | AH7: 140.968 | AI7: 141.592 | AJ7: 128.275 | AK7: 122.222 | AL7: 116.864 | AM7: 114.938
J8: Retrofit 1 EPC (Thousand households) | K8: 1 classe | L8: 0 | M8: 385.953 | N8: 359.247 | O8: 476.103 | P8: 474.092 | Q8: 557.732 | R8: 642.438 | S8: 715.867 | T8: 729.308 | U8: 786.545 | V8: 738.802 | W8: 698.115 | X8: 649.705 | Y8: 559.65 | Z8: 634.52 | AA8: 572.959 | AB8: 485.811 | AC8: 531.081 | AD8: 428.273 | AE8: 404.355 | AF8: 353.826 | AG8: 322.807 | AH8: 296.758 | AI8: 292.689 | AJ8: 268.956 | AK8: 256.607 | AL8: 246.118 | AM8: 238.651
J9: Retrofit (Thousand households) | K9: tout | L9: 0 | M9: 2381.487 | N9: 2405.372 | O9: 2647.93 | P9: 2664.036 | Q9: 2638.071 | R9: 2640.715 | S9: 2622.072 | T9: 2794.75 | U9: 2688.616 | V9: 2631.566 | W9: 2618.23 | X9: 2576.913 | Y9: 2314.181 | Z9: 2673.462 | AA9: 2617.434 | AB9: 2413.115 | AC9: 2661.255 | AD9: 2371.68 | AE9: 2316.823 | AF9: 2124.618 | AG9: 2462.034 | AH9: 2272.589 | AI9: 2464.555 | AJ9: 2325.223 | AK9: 2382.273 | AL9: 2461.023 | AM9: 2534.16
K10: Nombre de logements qui rénovent (pas de double comptage)
J12: Retrofit at least 1 EPC (Thousand households) | K12: 1 ou plus | L12: 0 | M12: 1053.796 | N12: 1035.272 | O12: 1369.123 | P12: 1371.237 | Q12: 1363.265 | R12: 1408.945 | S12: 1437.157 | T12: 1532.199 | U12: 1493.108 | V12: 1406.345 | W12: 1333.531 | X12: 1262.987 | Y12: 1029.941 | Z12: 1125.698 | AA12: 1063.832 | AB12: 936.455 | AC12: 1045.18 | AD12: 843.667 | AE12: 801.875 | AF12: 716.815 | AG12: 498.896 | AH12: 456.133 | AI12: 448.853 | AJ12: 410.276 | AK12: 389.27 | AL12: 371.994 | AM12: 361.753
J13: Retrofit at least 2 EPC (Thousand households) | K13: 2 ou plus | L13: 0 | M13: 667.843 | N13: 676.025 | O13: 893.02 | P13: 897.145 | Q13: 805.533 | R13: 766.506 | S13: 721.289 | T13: 802.891 | U13: 706.564 | V13: 667.543 | W13: 635.416 | X13: 613.282 | Y13: 470.291 | Z13: 491.178 | AA13: 490.873 | AB13: 450.644 | AC13: 514.099 | AD13: 415.394 | AE13: 397.519 | AF13: 362.988 | AG13: 176.089 | AH13: 159.374 | AI13: 156.164 | AJ13: 141.32 | AK13: 132.663 | AL13: 125.876 | AM13: 123.102
J16: Nombre de ménages réalisant au moins un geste d'isolation
J17: Renovation (Thousand households) | K17: Total ménages gestes isolation (pas de double comptage) | L17: 0 | M17: 600.984 | N17: 633.017 | O17: 906.896 | P17: 930.626 | Q17: 910.702 | R17: 919.186 | S17: 904.087 | T17: 1080.782 | U17: 976.093 | V17: 923.369 | W17: 917.61 | X17: 878.916 | Y17: 847.975 | Z17: 1204.832 | AA17: 1151.39 | AB17: 1118.266 | AC17: 1312.817 | AD17: 1149.153 | AE17: 1093.078 | AF17: 975.247 | AG17: 971.543 | AH17: 920.872 | AI17: 876.263 | AJ17: 833.787 | AK17: 795.301 | AL17: 758.975 | AM17: 731.077
J18: Renovation Multi-family (Thousand households) | K18: LC - total gestes isolation | L18: 0 | M18: 157.845 | N18: 197.58 | O18: 301.471 | P18: 329.403 | Q18: 356.278 | R18: 363.095 | S18: 357.506 | T18: 546.638 | U18: 486.898 | V18: 464.279 | W18: 474.462 | X18: 461.422 | Y18: 442.759 | Z18: 690.482 | AA18: 659.476 | AB18: 656.718 | AC18: 708.467 | AD18: 616.103 | AE18: 592.481 | AF18: 539.399 | AG18: 551.485 | AH18: 517.396 | AI18: 487.795 | AJ18: 460.103 | AK18: 435.003 | AL18: 412.973 | AM18: 393.825
J19: Renovation Single-family (Thousand households) | K19: MI - total gestes isolation | L19: 0 | M19: 443.139 | N19: 435.437 | O19: 605.425 | P19: 601.224 | Q19: 554.424 | R19: 556.091 | S19: 546.582 | T19: 534.144 | U19: 489.195 | V19: 459.09 | W19: 443.147 | X19: 417.495 | Y19: 405.216 | Z19: 514.351 | AA19: 491.914 | AB19: 461.548 | AC19: 604.351 | AD19: 533.05 | AE19: 500.596 | AF19: 435.848 | AG19: 420.059 | AH19: 403.476 | AI19: 388.467 | AJ19: 373.683 | AK19: 360.298 | AL19: 346.001 | AM19: 337.252
J20: Renovation Multi-family - Owner-occupied (Thousand households) | K20: PO en copropriété - total gestes isolation | L20: 0 | M20: 66.859 | N20: 69.529 | O20: 68.545 | P20: 71.629 | Q20: 68.87 | R20: 72.832 | S20: 73.493 | T20: 70.084 | U20: 66.671 | V20: 63.5 | W20: 60.5 | X20: 57.697 | Y20: 85.98 | Z20: 80.192 | AA20: 78.143 | AB20: 72.691 | AC20: 142.856 | AD20: 88.089 | AE20: 81.699 | AF20: 75.69 | AG20: 70.771 | AH20: 66.355 | AI20: 62.029 | AJ20: 57.92 | AK20: 54.032 | AL20: 52.098 | AM20: 51.327
J21: Renovation Multi-family - Privately rented (Thousand households) | K21: PB en copropriété - total gestes isolation | L21: 0 | M21: 75.746 | N21: 66.232 | O21: 94.701 | P21: 79.853 | Q21: 67.77 | R21: 60.186 | S21: 52.586 | T21: 232.476 | U21: 187.343 | V21: 151.661 | W21: 123.423 | X21: 101.114 | Y21: 83.859 | Z21: 377.835 | AA21: 329.002 | AB21: 286.421 | AC21: 254.143 | AD21: 214.692 | AE21: 186.931 | AF21: 162.787 | AG21: 146.733 | AH21: 132.818 | AI21: 120.76 | AJ21: 110.053 | AK21: 100.691 | AL21: 91.919 | AM21: 84.404
J22: Renovation Multi-family - Social-housing (Thousand households) | K22: PB social en copropriété - total gestes isolation | L22: 0 | M22: 15.24 | N22: 61.818 | O22: 138.225 | P22: 177.92 | Q22: 219.637 | R22: 230.077 | S22: 231.426 | T22: 244.078 | U22: 232.884 | V22: 249.118 | W22: 290.54 | X22: 302.611 | Y22: 272.92 | Z22: 232.454 | AA22: 252.331 | AB22: 297.605 | AC22: 311.468 | AD22: 313.322 | AE22: 323.851 | AF22: 300.922 | AG22: 333.98 | AH22: 318.223 | AI22: 305.006 | AJ22: 292.131 | AK22: 280.28 | AL22: 268.957 | AM22: 258.094
J23: Renovation Single-family - Owner-occupied (Thousand households) | K23: PO en maison - total gestes isolation | L23: 0 | M23: 373.908 | N23: 360.023 | O23: 458.153 | P23: 465.931 | Q23: 435.469 | R23: 448.279 | S23: 445.771 | T23: 403.736 | U23: 368.386 | V23: 339.786 | W23: 316.142 | X23: 296.3 | Y23: 284.073 | Z23: 268.701 | AA23: 264.695 | AB23: 249.396 | AC23: 407.237 | AD23: 356.749 | AE23: 337.652 | AF23: 319.602 | AG23: 305.423 | AH23: 295.079 | AI23: 285.701 | AJ23: 276.219 | AK23: 267.637 | AL23: 258.41 | AM23: 254.311
J24: Renovation Single-family - Privately rented (Thousand households) | K24: PB en maison - total gestes isolation | L24: 0 | M24: 54.747 | N24: 45.586 | O24: 100.999 | P24: 79.919 | Q24: 63.455 | R24: 53.56 | S24: 43.134 | T24: 67.228 | U24: 52.519 | V24: 41.478 | W24: 33.203 | X24: 27.021 | Y24: 23.205 | Z24: 157.433 | AA24: 143.044 | AB24: 129.458 | AC24: 118.091 | AD24: 103.763 | AE24: 93.215 | AF24: 83.589 | AG24: 77.871 | AH24: 72.927 | AI24: 68.303 | AJ24: 64.082 | AK24: 60.218 | AL24: 56.081 | AM24: 52.365
J25: Renovation Single-family - Social-housing (Thousand households) | K25: PB social en maison - total gestes isolation | L25: 0 | M25: 14.484 | N25: 29.828 | O25: 46.274 | P25: 55.375 | Q25: 55.5 | R25: 54.251 | S25: 57.676 | T25: 63.179 | U25: 68.29 | V25: 77.826 | W25: 93.801 | X25: 94.174 | Y25: 97.938 | Z25: 88.217 | AA25: 84.174 | AB25: 82.694 | AC25: 79.022 | AD25: 72.538 | AE25: 69.73 | AF25: 32.657 | AG25: 36.765 | AH25: 35.471 | AI25: 34.463 | AJ25: 33.382 | AK25: 32.442 | AL25: 31.51 | AM25: 30.576
J27: dont maison | M27: 0.71325526 | N27: 0.6407553 | O27: 0.61655581 | P27: 0.58654067 | Q27: 0.54784551 | R27: 0.54596023 | S27: 0.54077207 | T27: 0.43576225 | U27: 0.43121403 | V27: 0.41290535 | W27: 0.38071185 | X27: 0.36786337 | Y27: 0.36236682 | Z27: 0.35368749 | AA27: 0.35412762 | AB27: 0.33878701 | AC27: 0.40015326 | AD27: 0.40074037 | AE27: 0.39417773 | AF27: 0.4134245 | AG27: 0.39452088 | AH27: 0.39962774 | AI27: 0.40399287 | AJ27: 0.40813901 | AK27: 0.41224015 | AL27: 0.41436279 | AM27: 0.41948523
J28: dont logements collectifs | M28: 0.23728585 | N28: 0.21446659 | O28: 0.1800052 | P28: 0.1627743 | Q28: 0.1500381 | R28: 0.14471282 | S28: 0.1394545 | T28: 0.27994545 | U28: 0.26023545 | V28: 0.23301735 | W28: 0.200437 | X28: 0.18068962 | Y28: 0.20028774 | Z28: 0.3801584 | AA28: 0.35361172 | AB28: 0.3211329 | AC28: 0.30240239 | AD28: 0.26348189 | AE28: 0.24575556 | AF28: 0.24452985 | AG28: 0.22387481 | AH28: 0.21628739 | AI28: 0.20860061 | AJ28: 0.20145793 | AK28: 0.19454647 | AL28: 0.18975197 | AM28: 0.18565897
J29: dont logements sociaux | M29: 0.049458887 | N29: 0.14477652 | O29: 0.20344009 | P29: 0.2506861 | Q29: 0.30211529 | R29: 0.30932586 | S29: 0.31977232 | T29: 0.28429137 | U29: 0.30855052 | V29: 0.3540773 | W29: 0.41885006 | X29: 0.45144815 | Y29: 0.43734544 | Z29: 0.26615412 | AA29: 0.29225979 | AB29: 0.34007919 | AC29: 0.29744435 | AD29: 0.33577774 | AE29: 0.36006671 | AF29: 0.34204566 | AG29: 0.38160431 | AH29: 0.38408595 | AI29: 0.38740538 | AJ29: 0.39040306 | AK29: 0.39321213 | AL29: 0.39588524 | AM29: 0.39485581
J32: Nombre de gestes
I33: Nombre de dossiers CEE | J33: Replacement total (Thousand) | K33: Nombre de remplacement (gestes d'isolation + chauffage) double comptage | L33: 0 | M33: 2719.872 | N33: 2757.853 | O33: 3357.189 | P33: 3377.297 | Q33: 3299.834 | R33: 3312.223 | S33: 3288.707 | T33: 3627.493 | U33: 3414.312 | V33: 3286.806 | W33: 3228.872 | X33: 3135.433 | Y33: 2841.74 | Z33: 3364.63 | AA33: 3287.39 | AB33: 3035.338 | AC33: 3511.532 | AD33: 2957.853 | AE33: 2865.808 | AF33: 2597.487 | AG33: 2923.978 | AH33: 2698.324 | AI33: 2875.414 | AJ33: 2706.085 | AK33: 2745.864 | AL33: 2811.21 | AM33: 2886.14
J34: Replacement total (Thousand renovating) | K34: Nombre de gestes d'isolation + nombre de changement de chauffage avec isolation (pas de double comptage) | L34: 0 | M34: 939.37 | N34: 985.497 | O34: 1616.155 | P34: 1643.888 | Q34: 1572.465 | R34: 1590.693 | S34: 1570.722 | T34: 1913.524 | U34: 1701.788 | V34: 1578.609 | W34: 1528.252 | X34: 1437.437 | Y34: 1375.534 | Z34: 1896.001 | AA34: 1821.345 | AB34: 1740.488 | AC34: 2163.095 | AD34: 1735.326 | AE34: 1642.062 | AF34: 1448.115 | AG34: 1433.488 | AH34: 1346.608 | AI34: 1287.121 | AJ34: 1214.649 | AK34: 1158.891 | AL34: 1109.161 | AM34: 1083.057
J36: Nombre de gestes d'isolation
J37: Replacement insulation (Thousand) | K37: Nombre de gestes d'isolation total | L37: 0 | M37: 912.091 | N37: 953.868 | O37: 1557.016 | P37: 1580.955 | Q37: 1507.333 | R37: 1523.565 | S37: 1503.885 | T37: 1845.485 | U37: 1634.01 | V37: 1508.477 | W37: 1452.813 | X37: 1360.918 | Y37: 1314.09 | Z37: 1838.174 | AA37: 1762.294 | AB37: 1687.201 | AC37: 2102.311 | AD37: 1685.932 | AE37: 1592.151 | AF37: 1409.225 | AG37: 1394.264 | AH37: 1315.369 | AI37: 1246.319 | AJ37: 1180.365 | AK37: 1120.867 | AL37: 1066.983 | AM37: 1036.934
J38: Replacement Floor (Thousand households) | L38: 0 | M38: 113.528 | N38: 120.634 | O38: 215.313 | P38: 220.844 | Q38: 211.424 | R38: 214.959 | S38: 213.465 | T38: 274.608 | U38: 240.607 | V38: 219.111 | W38: 207.061 | X38: 190.958 | Y38: 184.926 | Z38: 259.266 | AA38: 249.678 | AB38: 235.979 | AC38: 312.221 | AD38: 230.098 | AE38: 215.679 | AF38: 189.044 | AG38: 185.727 | AH38: 174.384 | AI38: 164.523 | AJ38: 155.019 | AK38: 146.496 | AL38: 139.023 | AM38: 136.701
J39: Replacement Roof (Thousand households) | L39: 0 | M39: 495.415 | N39: 522.797 | O39: 703.633 | P39: 720.733 | Q39: 713.912 | R39: 718.632 | S39: 707.48 | T39: 857.121 | U39: 777.683 | V39: 738.949 | W39: 737.054 | X39: 709.071 | Y39: 685 | Z39: 975.255 | AA39: 928.994 | AB39: 904.53 | AC39: 1045.701 | AD39: 933.217 | AE39: 888.905 | AF39: 796.204 | AG39: 794.211 | AH39: 753.212 | AI39: 717.151 | AJ39: 682.957 | AK39: 651.818 | AL39: 622.439 | AM39: 597.669
J40: Replacement Wall (Thousand households) | L40: 0 | M40: 189.634 | N40: 184.391 | O40: 428.92 | P40: 422.296 | Q40: 373.539 | R40: 378.14 | S40: 368.335 | T40: 435.018 | U40: 367.674 | V40: 320.241 | W40: 285.945 | X40: 252.084 | Y40: 241.506 | Z40: 311.952 | AA40: 303.283 | AB40: 279.564 | AC40: 398.866 | AD40: 255.591 | AE40: 236.244 | AF40: 202.802 | AG40: 196.114 | AH40: 182.204 | AI40: 170.082 | AJ40: 158.478 | AK40: 148.213 | AL40: 139.862 | AM40: 139.873
J41: Replacement Windows (Thousand households) | L41: 0 | M41: 113.514 | N41: 126.046 | O41: 209.149 | P41: 217.082 | Q41: 208.457 | R41: 211.834 | S41: 214.605 | T41: 278.738 | U41: 248.045 | V41: 230.176 | W41: 222.753 | X41: 208.806 | Y41: 202.658 | Z41: 291.7 | AA41: 280.338 | AB41: 267.127 | AC41: 345.522 | AD41: 267.025 | AE41: 251.323 | AF41: 221.175 | AG41: 218.212 | AH41: 205.569 | AI41: 194.562 | AJ41: 183.911 | AK41: 174.34 | AL41: 165.659 | AM41: 162.69
J44: Nombre de ménage réalisant au moins x gestes
J45: Retrofit measures 1 (Thousand households) | L45: 0 | M45: 2170.152 | N45: 2187.527 | O45: 2230.258 | P45: 2242.537 | Q45: 2245.625 | R45: 2242.027 | S45: 2230.303 | T45: 2319.859 | U45: 2272.393 | V45: 2252.499 | W45: 2259.523 | X45: 2245.242 | Y45: 2000.718 | Z45: 2264.309 | AA45: 2220.537 | AB45: 2041.588 | AC45: 2173.333 | AD45: 2017.367 | AE45: 1983.152 | AF45: 1836.934 | AG45: 2179.556 | AH45: 2012.287 | AI45: 2211.337 | AJ45: 2090.401 | AK45: 2156.655 | AL45: 2242.511 | AM45: 2314.919
J46: Retrofit measures 2 (Thousand households) | L46: 0 | M46: 117.774 | N46: 119.748 | O46: 213.155 | P46: 214.573 | Q46: 199.319 | R46: 202.571 | S46: 195.149 | T46: 222.278 | U46: 198.133 | V46: 184.435 | W46: 180.296 | X46: 170.639 | Y46: 159.416 | Z46: 204.084 | AA46: 198.724 | AB46: 188.056 | AC46: 230.784 | AD46: 182.344 | AE46: 173.625 | AF46: 149.302 | AG46: 148.15 | AH46: 135.874 | AI46: 135.166 | AJ46: 124.976 | AK46: 121.856 | AL46: 119.62 | AM46: 119.69
J47: Retrofit measures 3 (Thousand households) | L47: 0 | M47: 60.477 | N47: 62.279 | O47: 124.389 | P47: 129.485 | Q47: 124.395 | R47: 127.244 | S47: 125.991 | T47: 154.981 | U47: 134.107 | V47: 120.473 | W47: 112.275 | X47: 102.507 | Y47: 99.199 | Z47: 133.131 | AA47: 128.46 | AB47: 120.839 | AC47: 158.088 | AD47: 116.16 | AE47: 108.759 | AF47: 94.995 | AG47: 92.759 | AH47: 86.638 | AI47: 81.954 | AJ47: 76.84 | AK47: 72.708 | AL47: 69.251 | AM47: 69.62
J48: Retrofit measures 4 (Thousand households) | L48: 0 | M48: 32.676 | N48: 35.098 | O48: 73.184 | P48: 70.044 | Q48: 61.273 | R48: 61.047 | S48: 63.013 | T48: 90.024 | U48: 76.584 | V48: 66.779 | W48: 58.748 | X48: 51.23 | Y48: 49.65 | Z48: 66.929 | AA48: 64.543 | AB48: 58.043 | AC48: 92.882 | AD48: 51.731 | AE48: 47.311 | AF48: 39.971 | AG48: 37.998 | AH48: 34.574 | AI48: 32.608 | AJ48: 29.818 | AK48: 27.897 | AL48: 26.498 | AM48: 26.674
J49: Retrofit measures 5 (Thousand households) | L49: 0 | M49: 0.407 | N49: 0.72 | O49: 6.943 | P49: 7.396 | Q49: 7.459 | R49: 7.827 | S49: 7.616 | T49: 7.607 | U49: 7.399 | V49: 7.38 | W49: 7.389 | X49: 7.294 | Y49: 5.199 | Z49: 5.009 | AA49: 5.17 | AB49: 4.59 | AC49: 6.168 | AD49: 4.079 | AE49: 3.978 | AF49: 3.416 | AG49: 3.571 | AH49: 3.216 | AI49: 3.49 | AJ49: 3.188 | AK49: 3.157 | AL49: 3.143 | AM49: 3.257
...

Sheet Aides
L1: 2023 | M1: 2024 | N1: 2025 | O1: 2026 | P1: 2027 | Q1: 2028 | R1: 2029 | S1: 2030 | T1: 2031 | U1: 2032 | V1: 2033 | W1: 2034 | X1: 2035 | Y1: 2036 | Z1: 2037 | AA1: 2038 | AB1: 2039 | AC1: 2040 | AD1: 2041 | AE1: 2042 | AF1: 2043 | AG1: 2044 | AH1: 2045 | AI1: 2046 | AJ1: 2047 | AK1: 2048 | AL1: 2049 | AM1: 2050
J2: Investment heater (Billion euro) | L2: =VLOOKUP($J2,[1]output!$A$9:$AI$2200,L$1-$L$1+2) -> 0 | M2: =VLOOKUP($J2,[1]output!$A$9:$AI$2200,M$1-$L$1+2) -> 15.007 | N2: =VLOOKUP($J2,[1]output!$A$9:$AI$2200,N$1-$L$1+2) -> 15.67 | O2: =VLOOKUP($J2,[1]output!$A$9:$AI$2200,O$1-$L$1+2) -> 14.648 | P2: =VLOOKUP($J2,[1]output!$A$9:$AI$2200,P$1-$L$1+2) -> 15.055 | Q2: =VLOOKUP($J2,[1]output!$A$9:$AI$2200,Q$1-$L$1+2) -> 14.004 | R2: =VLOOKUP($J2,[1]output!$A$9:$AI$2200,R$1-$L$1+2) -> 12.863 | S2: =VLOOKUP($J2,[1]output!$A$9:$AI$2200,S$1-$L$1+2) -> 11.812 | ... AM2: =VLOOKUP($J2,[1]output!$A$9:$AI$2200,AM$1-$L$1+2) -> 12.367
J3: Investment insulation (Billion euro) | L3: =VLOOKUP($J3,[1]output!$A$9:$AI$2200,L$1-$L$1+3) -> 7.376 | M3: =VLOOKUP($J3,[1]output!$A$9:$AI$2200,M$1-$L$1+3) -> 7.208 | N3: =VLOOKUP($J3,[1]output!$A$9:$AI$2200,N$1-$L$1+3) -> 14.22 | O3: =VLOOKUP($J3,[1]output!$A$9:$AI$2200,O$1-$L$1+3) -> 14.29 | P3: =VLOOKUP($J3,[1]output!$A$9:$AI$2200,P$1-$L$1+3) -> 12.945 | Q3: =VLOOKUP($J3,[1]output!$A$9:$AI$2200,Q$1-$L$1+3) -> 13.21 | R3: =VLOOKUP($J3,[1]output!$A$9:$AI$2200,R$1-$L$1+3) -> 13.105 | S3: =VLOOKUP($J3,[1]output!$A$9:$AI$2200,S$1-$L$1+3) -> 13.597 | ... AM3: =VLOOKUP($J3,[1]output!$A$9:$AI$2200,AM$1-$L$1+3) -> 0
J5: Investment total (Billion euro) | K5: Investissement total (milliards) | L5: =VLOOKUP($J5,[1]output!$A$9:$AI$2200,L$1-$L$1+2) -> 0 | M5: =VLOOKUP($J5,[1]output!$A$9:$AI$2200,M$1-$L$1+2) -> 22.383 | N5: =VLOOKUP($J5,[1]output!$A$9:$AI$2200,N$1-$L$1+2) -> 22.878 | O5: =VLOOKUP($J5,[1]output!$A$9:$AI$2200,O$1-$L$1+2) -> 28.868 | P5: =VLOOKUP($J5,[1]output!$A$9:$AI$2200,P$1-$L$1+2) -> 29.345 | Q5: =VLOOKUP($J5,[1]output!$A$9:$AI$2200,Q$1-$L$1+2) -> 26.95 | R5: =VLOOKUP($J5,[1]output!$A$9:$AI$2200,R$1-$L$1+2) -> 26.073 | S5: =VLOOKUP($J5,[1]output!$A$9:$AI$2200,S$1-$L$1+2) -> 24.918 | ... AM5: =VLOOKUP($J5,[1]output!$A$9:$AI$2200,AM$1-$L$1+2) -> 18.51
J6: Financing total (Billion euro) | L6: =VLOOKUP($J6,[1]output!$A$9:$AI$2200,L$1-$L$1+2) -> 0 | M6: =VLOOKUP($J6,[1]output!$A$9:$AI$2200,M$1-$L$1+2) -> 5.188 | N6: =VLOOKUP($J6,[1]output!$A$9:$AI$2200,N$1-$L$1+2) -> 5.328 | O6: =VLOOKUP($J6,[1]output!$A$9:$AI$2200,O$1-$L$1+2) -> 4.705 | P6: =VLOOKUP($J6,[1]output!$A$9:$AI$2200,P$1-$L$1+2) -> 4.765 | Q6: =VLOOKUP($J6,[1]output!$A$9:$AI$2200,Q$1-$L$1+2) -> 4.315 | R6: =VLOOKUP($J6,[1]output!$A$9:$AI$2200,R$1-$L$1+2) -> 3.937 | S6: =VLOOKUP($J6,[1]output!$A$9:$AI$2200,S$1-$L$1+2) -> 3.577 | ... AM6: =VLOOKUP($J6,[1]output!$A$9:$AI$2200,AM$1-$L$1+2) -> 3.439
J7: Debt total (Billion euro) | L7: =VLOOKUP($J7,[1]output!$A$9:$AI$2200,L$1-$L$1+2) -> 0 | M7: =VLOOKUP($J7,[1]output!$A$9:$AI$2200,M$1-$L$1+2) -> 5.71 | N7: =VLOOKUP($J7,[1]output!$A$9:$AI$2200,N$1-$L$1+2) -> 5.622 | O7: =VLOOKUP($J7,[1]output!$A$9:$AI$2200,O$1-$L$1+2) -> 8.053 | P7: =VLOOKUP($J7,[1]output!$A$9:$AI$2200,P$1-$L$1+2) -> 7.933 | Q7: =VLOOKUP($J7,[1]output!$A$9:$AI$2200,Q$1-$L$1+2) -> 7.214 | R7: =VLOOKUP($J7,[1]output!$A$9:$AI$2200,R$1-$L$1+2) -> 7.219 | S7: =VLOOKUP($J7,[1]output!$A$9:$AI$2200,S$1-$L$1+2) -> 7.013 | ... AM7: =VLOOKUP($J7,[1]output!$A$9:$AI$2200,AM$1-$L$1+2) -> 4.529
J8: Soutien total (milliards) | K8: Soutien total (milliards) | L8: =SUM(L45:L48) -> 0 | M8: =SUM(M45:M48) -> 4.949 | N8: =SUM(N45:N48) -> 5.095 | O8: =SUM(O45:O50) -> 16.97825 | P8: =SUM(P45:P50) -> 17.58975 | Q8: =SUM(Q45:Q50) -> 16.39175 | R8: =SUM(R45:R50) -> 16.53925 | S8: =SUM(S45:S50) -> 16.724906 | T8: =SUM(T45:T50) -> 16.738833 | U8: =SUM(U45:U50) -> 14.952781 | V8: =SUM(V45:V50) -> 13.80401 | ... AM8: =SUM(AM45:AM50) -> 9.081196
K9: Part soutien | O9: =O8/O5 -> 0.58813392 | P9: =P8/P5 -> 0.59941217 | Q9: =Q8/Q5 -> 0.6082282 | R9: =R8/R5 -> 0.63434396 | S9: =S8/S5 -> 0.67119778 | T9: =T8/T5 -> 0.62509648 | U9: =U8/U5 -> 0.62584884 | V9: =V8/V5 -> 0.60124612 | ... AM9: =AM8/AM5 -> 0.49061027
K10: Part RAC | O10: =1-O9 -> 0.41186608 | P10: =1-P9 -> 0.40058783 | Q10: =1-Q9 -> 0.3917718 | R10: =1-R9 -> 0.36565604 | S10: =1-S9 -> 0.32880222 | T10: =1-T9 -> 0.37490352 | U10: =1-U9 -> 0.37415116 | V10: =1-V9 -> 0.39875388 | ... AM10: =1-AM9 -> 0.50938973
J12: Correction années historiques (I4CE) | K12: Investissement total (milliards) | O12: 15 | P12: 17 | Q12: 19 | R12: =R5 -> 26.073 | S12: =S5 -> 24.918 | T12: =T5 -> 26.778 | U12: =U5 -> 23.892 | V12: =V5 -> 22.959 | W12: =W5 -> 22.511 | X12: =X5 -> 21.945 | Y12: =Y5 -> 19.791 | ... AM12: =AM5 -> 18.51
K13: Soutien total (milliards) | O13: 4.8 | P13: 5.5 | Q13: 6 | R13: =R8 -> 16.53925 | S13: =S8 -> 16.724906 | T13: =T8 -> 16.738833 | U13: =U8 -> 14.952781 | V13: =V8 -> 13.80401 | W13: =W8 -> 12.9429 | X13: =X8 -> 12.194249 | Y13: =Y8 -> 10.804118 | ... AM13: =AM8 -> 9.081196
R14: =R13/R12 -> 0.63434396 | S14: =S13/S12 -> 0.67119778 | T14: =T13/T12 -> 0.62509648 | U14: =U13/U12 -> 0.62584884 | V14: =V13/V12 -> 0.60124612 | W14: =W13/W12 -> 0.57495891 | X14: =X13/X12 -> 0.55567324 | Y14: =Y13/Y12 -> 0.54591067 | ... AM14: =AM13/AM12 -> 0.49061027
J21: Montant des aides (au sens du modèle)
J23: Cee (Billion euro) | L23: =VLOOKUP($J23,[1]output!$A$9:$AI$2200,L$1-$L$1+2) -> 0 | M23: =VLOOKUP($J23,[1]output!$A$9:$AI$2200,M$1-$L$1+2) -> 3.097 | N23: =VLOOKUP($J23,[1]output!$A$9:$AI$2200,N$1-$L$1+2) -> 3.167 | O23: =VLOOKUP($J23,[1]output!$A$9:$AI$2200,O$1-$L$1+2) -> 3.092 | P23: =VLOOKUP($J23,[1]output!$A$9:$AI$2200,P$1-$L$1+2) -> 3.214 | Q23: =VLOOKUP($J23,[1]output!$A$9:$AI$2200,Q$1-$L$1+2) -> 3.123 | R23: =VLOOKUP($J23,[1]output!$A$9:$AI$2200,R$1-$L$1+2) -> 3.028 | S23: =VLOOKUP($J23,[1]output!$A$9:$AI$2200,S$1-$L$1+2) -> 2.919 | ... AM23: =VLOOKUP($J23,[1]output!$A$9:$AI$2200,AM$1-$L$1+2) -> 3.105
J24: Mpr (Billion euro) | L24: =VLOOKUP($J24,[1]output!$A$9:$AI$2200,L$1-$L$1+2) -> 0 | M24: =VLOOKUP($J24,[1]output!$A$9:$AI$2200,M$1-$L$1+2) -> 1.607 | N24: =VLOOKUP($J24,[1]output!$A$9:$AI$2200,N$1-$L$1+2) -> 1.589 | O24: =VLOOKUP($J24,[1]output!$A$9:$AI$2200,O$1-$L$1+2) -> 0 | P24: =VLOOKUP($J24,[1]output!$A$9:$AI$2200,P$1-$L$1+2) -> 0 | Q24: =VLOOKUP($J24,[1]output!$A$9:$AI$2200,Q$1-$L$1+2) -> 0 | R24: =VLOOKUP($J24,[1]output!$A$9:$AI$2200,R$1-$L$1+2) -> 0 | S24: =VLOOKUP($J24,[1]output!$A$9:$AI$2200,S$1-$L$1+2) -> 0 | ... AM24: =VLOOKUP($J24,[1]output!$A$9:$AI$2200,AM$1-$L$1+2) -> 0
J25: Mpr efficacite (Billion euro) | L25: =VLOOKUP($J25,[1]output!$A$9:$AI$2200,L$1-$L$1+2) -> 0 | M25: =VLOOKUP($J25,[1]output!$A$9:$AI$2200,M$1-$L$1+2) -> 0 | N25: =VLOOKUP($J25,[1]output!$A$9:$AI$2200,N$1-$L$1+2) -> 0 | O25: =VLOOKUP($J25,[1]output!$A$9:$AI$2200,O$1-$L$1+2) -> 1.634 | P25: =VLOOKUP($J25,[1]output!$A$9:$AI$2200,P$1-$L$1+2) -> 1.689 | Q25: =VLOOKUP($J25,[1]output!$A$9:$AI$2200,Q$1-$L$1+2) -> 1.664 | R25: =VLOOKUP($J25,[1]output!$A$9:$AI$2200,R$1-$L$1+2) -> 1.649 | S25: =VLOOKUP($J25,[1]output!$A$9:$AI$2200,S$1-$L$1+2) -> 1.624 | ... AM25: =VLOOKUP($J25,[1]output!$A$9:$AI$2200,AM$1-$L$1+2) -> 1.604
J26: Mpr multifamily (Billion euro) | L26: =VLOOKUP($J26,[1]output!$A$9:$AI$2200,L$1-$L$1+2) -> 0 | M26: =VLOOKUP($J26,[1]output!$A$9:$AI$2200,M$1-$L$1+2) -> 0.238 | N26: =VLOOKUP($J26,[1]output!$A$9:$AI$2200,N$1-$L$1+2) -> 0 | O26: =VLOOKUP($J26,[1]output!$A$9:$AI$2200,O$1-$L$1+2) -> 0 | P26: =VLOOKUP($J26,[1]output!$A$9:$AI$2200,P$1-$L$1+2) -> 0 | Q26: =VLOOKUP($J26,[1]output!$A$9:$AI$2200,Q$1-$L$1+2) -> 0
J27: Mpr multifamily updated (Billion euro) | L27: =VLOOKUP($J27,[1]output!$A$9:$AI$2200,L$1-$L$1+2) -> 0 | M27: =VLOOKUP($J27,[1]output!$A$9:$AI$2200,M$1-$L$1+2) -> 0 | N27: =VLOOKUP($J27,[1]output!$A$9:$AI$2200,N$1-$L$1+2) -> 0 | O27: =VLOOKUP($J27,[1]output!$A$9:$AI$2200,O$1-$L$1+2) -> 0 | P27: =VLOOKUP($J27,[1]output!$A$9:$AI$2200,P$1-$L$1+2) -> 0 | Q27: =VLOOKUP($J27,[1]output!$A$9:$AI$2200,Q$1-$L$1+2) -> 0 | R27: =VLOOKUP($J27,[1]output!$A$9:$AI$2200,R$1-$L$1+2) -> 0 | S27: =VLOOKUP($J27,[1]output!$A$9:$AI$2200,S$1-$L$1+2) -> 0 | ... AM27: =VLOOKUP($J27,[1]output!$A$9:$AI$2200,AM$1-$L$1+2) -> 0
J28: Mpr multifamily deep (Billion euro) | L28: =VLOOKUP($J28,[1]output!$A$9:$AI$2200,L$1-$L$1+2) -> 0 | M28: =VLOOKUP($J28,[1]output!$A$9:$AI$2200,M$1-$L$1+2) -> 0 | N28: =VLOOKUP($J28,[1]output!$A$9:$AI$2200,N$1-$L$1+2) -> 0.333 | O28: =VLOOKUP($J28,[1]output!$A$9:$AI$2200,O$1-$L$1+2) -> 0.439 | P28: =VLOOKUP($J28,[1]output!$A$9:$AI$2200,P$1-$L$1+2) -> 0.421 | Q28: =VLOOKUP($J28,[1]output!$A$9:$AI$2200,Q$1-$L$1+2) -> 0.375 | R28: =VLOOKUP($J28,[1]output!$A$9:$AI$2200,R$1-$L$1+2) -> 0.37 | S28: =VLOOKUP($J28,[1]output!$A$9:$AI$2200,S$1-$L$1+2) -> 0.358 | ... AM28: =VLOOKUP($J28,[1]output!$A$9:$AI$2200,AM$1-$L$1+2) -> 0.115
J29: Mpr multifamily all | L29: =SUM(L26:L28) -> 0 | M29: =SUM(M26:M28) -> 0.238 | N29: =SUM(N26:N28) -> 0.333 | O29: =SUM(O26:O28) -> 0.439 | P29: =SUM(P26:P28) -> 0.421 | Q29: =SUM(Q26:Q28) -> 0.375 | R29: =SUM(R26:R28) -> 0.37 | S29: =SUM(S26:S28) -> 0.358 | ... AM29: =SUM(AM26:AM28) -> 0.115
J30: Mpr performance (Billion euro) | L30: =VLOOKUP($J30,[1]output!$A$9:$AI$2200,L$1-$L$1+2) -> 0 | M30: =VLOOKUP($J30,[1]output!$A$9:$AI$2200,M$1-$L$1+2) -> 0 | N30: =VLOOKUP($J30,[1]output!$A$9:$AI$2200,N$1-$L$1+2) -> 0 | O30: =VLOOKUP($J30,[1]output!$A$9:$AI$2200,O$1-$L$1+2) -> 4.659 | P30: =VLOOKUP($J30,[1]output!$A$9:$AI$2200,P$1-$L$1+2) -> 4.909 | Q30: =VLOOKUP($J30,[1]output!$A$9:$AI$2200,Q$1-$L$1+2) -> 4.437 | R30: =VLOOKUP($J30,[1]output!$A$9:$AI$2200,R$1-$L$1+2) -> 4.591 | S30: =VLOOKUP($J30,[1]output!$A$9:$AI$2200,S$1-$L$1+2) -> 4.674 | ... AM30: =VLOOKUP($J30,[1]output!$A$9:$AI$2200,AM$1-$L$1+2) -> 0.854
J31: Mpr serenite (Billion euro) | L31: =VLOOKUP($J31,[1]output!$A$9:$AI$2200,L$1-$L$1+2) -> 0 | M31: =VLOOKUP($J31,[1]output!$A$9:$AI$2200,M$1-$L$1+2) -> 0.007 | N31: =VLOOKUP($J31,[1]output!$A$9:$AI$2200,N$1-$L$1+2) -> 0.006 | O31: =VLOOKUP($J31,[1]output!$A$9:$AI$2200,O$1-$L$1+2) -> 0 | P31: =VLOOKUP($J31,[1]output!$A$9:$AI$2200,P$1-$L$1+2) -> 0 | Q31: =VLOOKUP($J31,[1]output!$A$9:$AI$2200,Q$1-$L$1+2) -> 0 | R31: =VLOOKUP($J31,[1]output!$A$9:$AI$2200,R$1-$L$1+2) -> 0 | S31: =VLOOKUP($J31,[1]output!$A$9:$AI$2200,S$1-$L$1+2) -> 0 | ... AM31: =VLOOKUP($J31,[1]output!$A$9:$AI$2200,AM$1-$L$1+2) -> 0
J32: Over cap (Billion euro) | L32: =VLOOKUP($J32,[1]output!$A$9:$AI$2200,L$1-$L$1+2) -> 0 | M32: =VLOOKUP($J32,[1]output!$A$9:$AI$2200,M$1-$L$1+2) -> 0 | N32: =VLOOKUP($J32,[1]output!$A$9:$AI$2200,N$1-$L$1+2) -> 0.091 | O32: =VLOOKUP($J32,[1]output!$A$9:$AI$2200,O$1-$L$1+2) -> 0.199 | P32: =VLOOKUP($J32,[1]output!$A$9:$AI$2200,P$1-$L$1+2) -> 0.206 | Q32: =VLOOKUP($J32,[1]output!$A$9:$AI$2200,Q$1-$L$1+2) -> 0.207 | R32: =VLOOKUP($J32,[1]output!$A$9:$AI$2200,R$1-$L$1+2) -> 0.226 | S32: =VLOOKUP($J32,[1]output!$A$9:$AI$2200,S$1-$L$1+2) -> 0.229 | ... AM32: =VLOOKUP($J32,[1]output!$A$9:$AI$2200,AM$1-$L$1+2) -> 0.078
J33: Part CEE de MPR Performance | L33: =L30/4 -> 0 | M33: =M30/4 -> 0 | N33: =N30/4 -> 0 | O33: =O30/4 -> 1.16475 | P33: =P30/4 -> 1.22725 | Q33: =Q30/4 -> 1.10925 | R33: =R30/4 -> 1.14775 | S33: =S30/4 -> 1.1685 | ... AM33: =AM30/4 -> 0.2135
J34: Part système de MPR performance | K34: A vérifier | S34: =S62*S70*0.6/1000 -> 0.12920313 | T34: =T62*T70*0.6/1000 -> 0.12104174 | U34: =U62*U70*0.6/1000 -> 0.11651525 | V34: =V62*V70*0.6/1000 -> 0.10525487 | W34: =W62*W70*0.6/1000 -> 0.094450019 | X34: =X62*X70*0.6/1000 -> 0.089624635 | Y34: =Y62*Y70*0.6/1000 -> 0.084309054 | Z34: =Z62*Z70*0.6/1000 -> 0.093514021 | ... AM34: =AM62*AM70*0.6/1000 -> 0.074848023
J35: Part système de MPR copro | K35: A vérifier | S35: =S66*S70*0.6/1000 -> 0.064962161 | T35: =T66*T70*0.6/1000 -> 0.13481973 | U35: =U66*U70*0.6/1000 -> 0.12970265 | V35: =V66*V70*0.6/1000 -> 0.11516818 | W35: =W66*W70*0.6/1000 -> 0.10120302 | X35: =X66*X70*0.6/1000 -> 0.09740594 | Y35: =Y66*Y70*0.6/1000 -> 0.10200093 | Z35: =Z66*Z70*0.6/1000 -> 0.1603923 | ... AM35: =AM66*AM70*0.6/1000 -> 0.042976238
J37: Mpr heater (Billion euro) | L37: =VLOOKUP($J37,[1]output!$A$9:$AI$2200,L$1-$L$1+2) -> 0 | M37: =VLOOKUP($J37,[1]output!$A$9:$AI$2200,M$1-$L$1+2) -> 0.912 | N37: =VLOOKUP($J37,[1]output!$A$9:$AI$2200,N$1-$L$1+2) -> 0.95 | O37: =VLOOKUP($J37,[1]output!$A$9:$AI$2200,O$1-$L$1+2) -> 0 | P37: =VLOOKUP($J37,[1]output!$A$9:$AI$2200,P$1-$L$1+2) -> 0 | Q37: =VLOOKUP($J37,[1]output!$A$9:$AI$2200,Q$1-$L$1+2) -> 0 | R37: =VLOOKUP($J37,[1]output!$A$9:$AI$2200,R$1-$L$1+2) -> 0 | S37: =VLOOKUP($J37,[1]output!$A$9:$AI$2200,S$1-$L$1+2) -> 0 | ... AM37: =VLOOKUP($J37,[1]output!$A$9:$AI$2200,AM$1-$L$1+2) -> 0
J38: Mpr efficacite heater (Billion euro) | L38: =VLOOKUP($J38,[1]output!$A$9:$AI$2200,L$1-$L$1+2) -> 0 | M38: =VLOOKUP($J38,[1]output!$A$9:$AI$2200,M$1-$L$1+2) -> 0 | N38: =VLOOKUP($J38,[1]output!$A$9:$AI$2200,N$1-$L$1+2) -> 0 | O38: =VLOOKUP($J38,[1]output!$A$9:$AI$2200,O$1-$L$1+2) -> 1.425 | P38: =VLOOKUP($J38,[1]output!$A$9:$AI$2200,P$1-$L$1+2) -> 1.475 | Q38: =VLOOKUP($J38,[1]output!$A$9:$AI$2200,Q$1-$L$1+2) -> 1.453 | R38: =VLOOKUP($J38,[1]output!$A$9:$AI$2200,R$1-$L$1+2) -> 1.432 | S38: =VLOOKUP($J38,[1]output!$A$9:$AI$2200,S$1-$L$1+2) -> 1.412 | ... AM38: =VLOOKUP($J38,[1]output!$A$9:$AI$2200,AM$1-$L$1+2) -> 1.534
J39: Mpr efficacité chauffage (milliard) | L39: =L37+L38 -> 0 | M39: =M37+M38 -> 0.912 | N39: =N37+N38 -> 0.95 | O39: =O37+O38 -> 1.425 | P39: =P37+P38 -> 1.475 | Q39: =Q37+Q38 -> 1.453 | R39: =R37+R38 -> 1.432 | S39: =S37+S38 -> 1.412 | ... AM39: =AM37+AM38 -> 1.534
J44: Montant des aides (au sens réel) | K44: Milliards €
J45: CEE | L45: =L23+L33 -> 0 | M45: =M23+M33 -> 3.097 | N45: =N23+N33 -> 3.167 | O45: =O23+O33 -> 4.25675 | P45: =P23+P33 -> 4.44125 | Q45: =Q23+Q33 -> 4.23225 | R45: =R23+R33 -> 4.17575 | S45: =S23+S33 -> 4.0875 | ... AM45: =AM23+AM33 -> 3.3185
J46: MPR Efficacité | L46: =L24+L25 -> 0 | M46: =M24+M25 -> 1.607 | N46: =N24+N25 -> 1.589 | O46: =O24+O25 -> 1.634 | P46: =P24+P25 -> 1.689 | Q46: =Q24+Q25 -> 1.664 | R46: =R24+R25 -> 1.649 | S46: =S24+S25 -> 1.624 | ... AM46: =AM24+AM25 -> 1.604
J47: MPR Copro | L47: =L29 -> 0 | M47: =M29 -> 0.238 | N47: =N29 -> 0.333 | O47: =O29 -> 0.439 | P47: =P29 -> 0.421 | Q47: =Q29 -> 0.375 | R47: =R29 -> 0.37 | S47: =S29 -> 0.358 | ... AM47: =AM29 -> 0.115
J48: MPR Performance | K48: Inclut un peu de social | L48: =L30+L31-L33+L34 -> 0 | M48: =M30+M31-M33+M34 -> 0.007 | N48: =N30+N31-N33+N34 -> 0.006 | O48: =O30+O31-O33+O34 -> 3.49425 | P48: =P30+P31-P33+P34 -> 3.68175 | Q48: =Q30+Q31-Q33+Q34 -> 3.32775 | R48: =R30+R31-R33+R34 -> 3.44325 | S48: =S30+S31-S33+S34 -> 3.6347031 | ... AM48: =AM30+AM31-AM33+AM34 -> 0.71534802
J49: MPR Total | L49: =SUM(L46:L48) -> 0 | M49: =SUM(M46:M48) -> 1.852 | N49: =SUM(N46:N48) -> 1.928 | O49: =SUM(O46:O48) -> 5.56725 | P49: =SUM(P46:P48) -> 5.79175 | Q49: =SUM(Q46:Q48) -> 5.36675 | R49: =SUM(R46:R48) -> 5.46225 | S49: =SUM(S46:S48) -> 5.6167031 | ... AM49: =SUM(AM46:AM48) -> 2.434348
J50: Zero interest loan (Billion euro) | L50: =VLOOKUP($J50,[1]output!$A$9:$AI$2200,L$1-$L$1+2) -> 0 | M50: =VLOOKUP($J50,[1]output!$A$9:$AI$2200,M$1-$L$1+2) -> 0.98 | N50: =VLOOKUP($J50,[1]output!$A$9:$AI$2200,N$1-$L$1+2) -> 0.97 | O50: =VLOOKUP($J50,[1]output!$A$9:$AI$2200,O$1-$L$1+2) -> 1.587 | P50: =VLOOKUP($J50,[1]output!$A$9:$AI$2200,P$1-$L$1+2) -> 1.565 | Q50: =VLOOKUP($J50,[1]output!$A$9:$AI$2200,Q$1-$L$1+2) -> 1.426 | R50: =VLOOKUP($J50,[1]output!$A$9:$AI$2200,R$1-$L$1+2) -> 1.439 | S50: =VLOOKUP($J50,[1]output!$A$9:$AI$2200,S$1-$L$1+2) -> 1.404 | ... AM50: =VLOOKUP($J50,[1]output!$A$9:$AI$2200,AM$1-$L$1+2) -> 0.894
J51: Montant écrêté | L51: =L32 -> 0 | M51: =M32 -> 0 | N51: =N32 -> 0.091 | O51: =O32 -> 0.199 | P51: =P32 -> 0.206 | Q51: =Q32 -> 0.207 | R51: =R32 -> 0.226 | S51: =S32 -> 0.229 | ... AM51: =AM32 -> 0.078
J54: Nombre de ménages aidés (au sens du modèle)
J56: Cee (Thousand households) | K56: il y a un double comptage | L56: =VLOOKUP($J56,[1]output!$A$9:$AI$2200,L$1-$L$1+2) -> 0 | M56: =VLOOKUP($J56,[1]output!$A$9:$AI$2200,M$1-$L$1+2) -> 2408.639 | N56: =VLOOKUP($J56,[1]output!$A$9:$AI$2200,N$1-$L$1+2) -> 2437.002 | O56: =VLOOKUP($J56,[1]output!$A$9:$AI$2200,O$1-$L$1+2) -> 2707.07 | P56: =VLOOKUP($J56,[1]output!$A$9:$AI$2200,P$1-$L$1+2) -> 2726.968 | Q56: =VLOOKUP($J56,[1]output!$A$9:$AI$2200,Q$1-$L$1+2) -> 2703.204 | R56: =VLOOKUP($J56,[1]output!$A$9:$AI$2200,R$1-$L$1+2) -> 2707.844 | S56: =VLOOKUP($J56,[1]output!$A$9:$AI$2200,S$1-$L$1+2) -> 2688.909 | ... AM56: =VLOOKUP($J56,[1]output!$A$9:$AI$2200,AM$1-$L$1+2) -> 2580.284
J57: Mpr (Thousand households) | L57: =VLOOKUP($J57,[1]output!$A$9:$AI$2200,L$1-$L$1+2) -> 0 | M57: =VLOOKUP($J57,[1]output!$A$9:$AI$2200,M$1-$L$1+2) -> 1256.951 | N57: =VLOOKUP($J57,[1]output!$A$9:$AI$2200,N$1-$L$1+2) -> 1241.925 | O57: =VLOOKUP($J57,[1]output!$A$9:$AI$2200,O$1-$L$1+2) -> 0 | P57: =VLOOKUP($J57,[1]output!$A$9:$AI$2200,P$1-$L$1+2) -> 0 | Q57: =VLOOKUP($J57,[1]output!$A$9:$AI$2200,Q$1-$L$1+2) -> 0 | R57: =VLOOKUP($J57,[1]output!$A$9:$AI$2200,R$1-$L$1+2) -> 0 | S57: =VLOOKUP($J57,[1]output!$A$9:$AI$2200,S$1-$L$1+2) -> 0 | ... AM57: =VLOOKUP($J57,[1]output!$A$9:$AI$2200,AM$1-$L$1+2) -> 0
...

Sheet Feuil1
B1: 2023 | C1: 2024 | D1: 2025 | E1: 2026 | F1: 2027 | G1: 2028 | H1: 2029 | I1: 2030 | J1: 2031 | K1: 2032 | L1: 2033 | M1: 2034 | N1: 2035 | O1: 2036 | P1: 2037 | Q1: 2038 | R1: 2039 | S1: 2040 | T1: 2041 | U1: 2042 | V1: 2043 | W1: 2044 | X1: 2045 | Y1: 2046 | Z1: 2047 | AA1: 2048 | AB1: 2049 | AC1: 2050
A2: cible renov_val | B2: =Aides!L5 -> 0 | C2: =Aides!M5 -> 22.383 | D2: =Aides!N5 -> 22.878 | E2: =Aides!O5 -> 28.868 | F2: =Aides!P5 -> 29.345 | G2: =Aides!Q5 -> 26.95 | H2: =Aides!R5 -> 26.073 | I2: =Aides!S5 -> 24.918 | ... AC2: =Aides!AM5 -> 18.51
A3: soutien total | B3: =SUM(Aides!L46:L48) -> 0 | C3: =SUM(Aides!M46:M48) -> 1.852 | D3: =SUM(Aides!N46:N48) -> 1.928 | E3: =SUM(Aides!O46:O48) -> 5.56725 | F3: =SUM(Aides!P46:P48) -> 5.79175 | G3: =SUM(Aides!Q46:Q48) -> 5.36675 | H3: =SUM(Aides!R46:R48) -> 5.46225 | I3: =SUM(Aides!S46:S48) -> 5.6167031 | ... AC3: =SUM(Aides!AM46:AM48) -> 2.434348
A4: tx de subv | C4: =C3/C2 -> 0.082741366 | D4: =D3/D2 -> 0.084273101 | E4: =E3/E2 -> 0.19285195 | F4: =F3/F2 -> 0.19736752 | G4: =G3/G2 -> 0.19913729 | H4: =H3/H2 -> 0.20949833 | I4: =I3/I2 -> 0.22540746 | J4: =J3/J2 -> 0.20359219 | ... AC4: =AC3/AC2 -> 0.13151529
