Workbook
Name GES.élec: 'total biocarb'!$C$16
Name GES.fossile: 'total biocarb'!$C$15
Name NRJ.kWh: 'total biocarb'!$C$12

Sheet Bilan énergie
B1: Taux de bio (taux d'incorporation en énergie)
C2: 2018 | D2: 2019 | E2: 2020 | F2: 2021 | G2: 2022 | H2: 2023 | I2: 2025 | J2: 2030 | K2: 2035 | L2: 2040 | M2: 2045 | N2: 2050
B3: essence | C3: =FE_et_bio!B46 -> 0.073 | D3: =FE_et_bio!C46 -> 0.082039105 | E3: =FE_et_bio!D46 -> 0.076978498 | F3: =FE_et_bio!E46 -> 0.077583337 | G3: =FE_et_bio!F46 -> 0.080734559 | H3: =FE_et_bio!G46 -> 0.086852684 | I3: =FE_et_bio!H46 -> 0.105 | J3: =FE_et_bio!I46 -> 0.137 | ... N3: =FE_et_bio!M46 -> 1
B4: gazole | C4: =FE_et_bio!B47 -> 0.0697 | D4: =FE_et_bio!C47 -> 0.075808287 | E4: =FE_et_bio!D47 -> 0.075100974 | F4: =FE_et_bio!E47 -> 0.072170546 | G4: =FE_et_bio!F47 -> 0.073714163 | H4: =FE_et_bio!G47 -> 0.078624535 | I4: =FE_et_bio!H47 -> 0.094 | J4: =FE_et_bio!I47 -> 0.137 | ... N4: =FE_et_bio!M47 -> 1
B5: GNV | C5: =FE_et_bio!B48 -> 0.001 | D5: =FE_et_bio!C48 -> 0.074333333 | E5: =FE_et_bio!D48 -> 0.001 | F5: =FE_et_bio!E48 -> 0 | G5: =FE_et_bio!F48 -> 0 | H5: =FE_et_bio!G48 -> 0.01 | I5: =FE_et_bio!H48 -> 0.05 | J5: =FE_et_bio!I48 -> 0.15 | ... N5: =FE_et_bio!M48 -> 1
B7: FE avec taux de bio (taux d'incorporation en énergie) | I7: reprise de la feuille FE et bio
C8: 2018 | D8: 2019 | E8: 2020 | F8: 2021 | G8: 2022 | H8: 2023 | I8: 2025 | J8: 2030 | K8: 2035 | L8: 2040 | M8: 2045 | N8: 2050
B9: Taux d’incorporation des biocarburants dans l’essence (routier) | C9: =FE_et_bio!B67 -> 2.8407961 | D9: =FE_et_bio!C67 -> 2.8130958 | E9: =FE_et_bio!D67 -> 2.828604 | F9: =FE_et_bio!E67 -> 2.8267505 | G9: =FE_et_bio!F67 -> 2.8170935 | H9: =FE_et_bio!G67 -> 2.7983445 | I9: =FE_et_bio!H67 -> 2.742732 | J9: =FE_et_bio!I67 -> 2.6446678 | ... N9: =FE_et_bio!M67 -> 0
B10: Taux d’incorporation des biocarburants dans le diesel (routier) | C10: =FE_et_bio!B68 -> 2.9320544 | D10: =FE_et_bio!C68 -> 2.9128027 | E10: =FE_et_bio!D68 -> 2.915032 | F10: =FE_et_bio!E68 -> 2.9242679 | G10: =FE_et_bio!F68 -> 2.9194029 | H10: =FE_et_bio!G68 -> 2.9039267 | I10: =FE_et_bio!H68 -> 2.8554674 | J10: =FE_et_bio!I68 -> 2.719943 | ... N10: =FE_et_bio!M68 -> 0
B11: Taux d’incorporation du gaz renouvelable dans le gaz (GNV routier) | C11: =FE_et_bio!B69 -> 2.3606669 | D11: =FE_et_bio!C69 -> 2.187378 | E11: =FE_et_bio!D69 -> 2.3606669 | F11: =FE_et_bio!E69 -> 2.3630299 | G11: =FE_et_bio!F69 -> 2.3630299 | H11: =FE_et_bio!G69 -> 2.3393996 | I11: =FE_et_bio!H69 -> 2.2448784 | J11: =FE_et_bio!I69 -> 2.0085754 | ... N11: =FE_et_bio!M69 -> 0
B16: 4 - Demande d'énergie finale des transports | M16: Mtep | P16: 4 - Demande d'énergie finale des transports | AA16: TWh | AD16: 4 - GES | AO16: MtCO2e
C17: 2018 | D17: 2019 | E17: 2020 | F17: 2021 | G17: 2022 | H17: 2023 | I17: 2025 | J17: 2030 | K17: 2035 | L17: 2040 | M17: 2045 | N17: 2050 | Q17: 2018 | R17: 2019 | S17: 2020 | T17: 2021 | U17: 2022 | V17: 2023 | W17: 2025 | X17: 2030 | Y17: 2035 | Z17: 2040 | AA17: 2045 | AB17: 2050 | AE17: 2018 | AF17: 2019 | AG17: 2020 | AH17: 2021 | AI17: 2022 | AJ17: 2023 | AK17: 2025 | AL17: 2030 | AM17: 2035 | AN17: 2040 | AO17: 2045 | AP17: 2050
B19: 4.1 Trafics
C20: 2018 | D20: 2019 | E20: 2020 | F20: 2021 | G20: 2022 | H20: 2023 | I20: 2025 | J20: 2030 | K20: 2035 | L20: 2040 | M20: 2045 | N20: 2050
B21: Passagers (Gpkm)
B22: Voitures | C22: =Trafic!C34 -> 827.91488 | D22: =Trafic!D34 -> 834.04487 | E22: =Trafic!E34 -> 669.08139 | F22: =Trafic!F34 -> 725.93652 | G22: =Trafic!G34 -> 809.40368 | H22: =Trafic!H34 -> 796.49623 | I22: =Trafic!I34 -> 807.28652 | J22: =Trafic!J34 -> 803.06063 | ... N22: =Trafic!N34 -> 792.41584
B23: Bus et autocars | C23: =Trafic!C37 -> 59.355012 | D23: =Trafic!D37 -> 60.956931 | E23: =Trafic!E37 -> 37.910503 | F23: =Trafic!F37 -> 41.749797 | G23: =Trafic!G37 -> 47.908934 | H23: =Trafic!H37 -> 53.67602 | I23: =Trafic!I37 -> 53.413542 | J23: =Trafic!J37 -> 63 | ... N23: =Trafic!N37 -> 69.193386
B24: Ferroviaire | C24: =Trafic!C36 -> 107.87256 | D24: =Trafic!D36 -> 112.30932 | E24: =Trafic!E36 -> 64.816306 | F24: =Trafic!F36 -> 86.419111 | G24: =Trafic!G36 -> 117.85172 | H24: =Trafic!H36 -> 123.74975 | I24: =Trafic!I36 -> 130.56 | J24: =Trafic!J36 -> 152.67788 | ... N24: =Trafic!N36 -> 199.23288
B25: Aérien domestique | C25: =Aérien!C6 -> 16.012112 | D25: =Aérien!D6 -> 16.265166 | E25: =Aérien!E6 -> 7.2496757 | F25: =Aérien!F6 -> 10.086837 | G25: =Aérien!G6 -> 13.52361 | H25: =Aérien!H6 -> 13.233747 | I25: =Aérien!I6 -> 12.510166 | J25: =Aérien!J6 -> 12.344811 | ... N25: =Aérien!N6 -> 5.4891365
B28: Marchandises Gtkm)
B29: Poids lourds | C29: =Trafic!C69 -> 286.16291 | D29: =Trafic!D69 -> 296.78758 | E29: =Trafic!E69 -> 286.97453 | F29: =Trafic!F69 -> 296.16941 | G29: =Trafic!G69 -> 296.17082 | H29: =Trafic!H69 -> 289.12141 | I29: =Trafic!I69 -> 301.49401 | J29: =Trafic!J69 -> 276.66456 | ... N29: =Trafic!N69 -> 267.64517
B30: VUL | C30: =Trafic!C73 -> - | D30: =Trafic!D73 -> - | E30: =Trafic!E73 -> - | F30: =Trafic!F73 -> - | G30: =Trafic!G73 -> - | H30: =Trafic!H73 -> - | I30: =Trafic!I73 -> - | J30: =Trafic!J73 -> - | ... N30: =Trafic!N73 -> -
B31: Ferroviaire | C31: =Trafic!C70 -> 33.849726 | D31: =Trafic!D70 -> 33.90871 | E31: =Trafic!E70 -> 31.29656 | F31: =Trafic!F70 -> 35.769721 | G31: =Trafic!G70 -> 35.281856 | H31: =Trafic!H70 -> 29.398991 | I31: =Trafic!I70 -> 34.260683 | J31: =Trafic!J70 -> 63.037494 | ... N31: =Trafic!N70 -> 94.241257
B32: Fluvial | C32: =Trafic!C71 -> 7.255286 | D32: =Trafic!D71 -> 7.9964556 | E32: =Trafic!E71 -> 6.987717 | F32: =Trafic!F71 -> 7.2654698 | G32: =Trafic!G71 -> 6.5932717 | H32: =Trafic!H71 -> 5.9066986 | I32: =Trafic!I71 -> 6.8521366 | J32: =Trafic!J71 -> 10.506249 | ... N32: =Trafic!N71 -> 15.078601
B34: Voitures Gvkm | C34: =Trafic!C111 -> 501 | D34: =Trafic!D111 -> 504.5 | E34: =Trafic!E111 -> 406.6 | F34: =Trafic!F111 -> 441.1 | G34: =Trafic!G111 -> 489.7 | H34: =Trafic!H111 -> 481.8648 | I34: =Trafic!I111 -> 480.62862 | J34: =Trafic!J111 -> 465.73168 | ... N34: =Trafic!N111 -> 435.74481
K37: y compris vols vers DROM | Y37: y compris vols vers DROM | AN37: y compris vols vers DROM
B38: 4.2 Demande d'énergie finale par énergie | P38: 4.2 Demande d'énergie finale par énergie | AD38: 4.2 Demande de ges
B39: Mtep | C39: 2018 | D39: 2019 | E39: 2020 | F39: 2021 | G39: 2022 | H39: 2023 | I39: 2025 | J39: 2030 | K39: 2035 | L39: 2040 | M39: 2045 | N39: 2050 | P39: TWh | Q39: 2018 | R39: 2019 | S39: 2020 | T39: 2021 | U39: 2022 | V39: 2023 | W39: 2025 | X39: 2030 | Y39: 2035 | Z39: 2040 | AA39: 2045 | AB39: 2050 | AD39: Mt CO2eq | AE39: 2018 | AF39: 2019 | AG39: 2020 | AH39: 2021 | AI39: 2022 | AJ39: 2023 | AK39: 2025 | AL39: 2030 | AM39: 2035 | AN39: 2040 | AO39: 2045 | AP39: 2050
B40: Essence (yc carb subst) | C40: =C112+C143 -> 7.9780722 | D40: =D112+D143 -> 8.4834587 | E40: =E112+E143 -> 7.3040589 | F40: =F112+F143 -> 8.3465132 | G40: =G112+G143 -> 9.4562389 | H40: =H112+H143 -> 9.808148 | I40: =I112+I143 -> 10.28291 | J40: =J112+J143 -> 12.401463 | ... N40: =N112+N143 -> 0.24934978 | P40: Essence (yc carb subst) | Q40: =C40*11.63 -> 92.784979 | R40: =D40*11.63 -> 98.662625 | S40: =E40*11.63 -> 84.946205 | T40: =F40*11.63 -> 97.069949 | U40: =G40*11.63 -> 109.97606 | V40: =H40*11.63 -> 114.06876 | W40: =I40*11.63 -> 119.59024 | X40: =J40*11.63 -> 144.22902 | ... AB40: =N40*11.63 -> 2.899938 | AD40: Essence (yc carb subst) | AE40: =C40*C9 -> 22.664077 | AF40: =D40*D9 -> 23.864782 | AG40: =E40*E9 -> 20.66029 | AH40: =F40*F9 -> 23.59351 | AI40: =G40*G9 -> 26.63911 | AJ40: =H40*H9 -> 27.446577 | AK40: =I40*I9 -> 28.203265 | AL40: =J40*J9 -> 32.79775 | ... AP40: =N40*N9 -> 0
B41: dont essence fossile | C41: =C40*(1-FE_et_bio!B46) -> 7.3956729 | D41: =D40*(1-FE_et_bio!C46) -> 7.7874834 | E41: =E40*(1-FE_et_bio!D46) -> 6.7418034 | F41: =F40*(1-FE_et_bio!E46) -> 7.6989629 | G41: =G40*(1-FE_et_bio!F46) -> 8.6927936 | H41: =H40*(1-FE_et_bio!G46) -> 8.956284 | I41: =I40*(1-FE_et_bio!H46) -> 9.2032041 | J41: =J40*(1-FE_et_bio!I46) -> 10.702463 | ... N41: =N40*(1-FE_et_bio!M46) -> 0 | P41: dont essence fossile | Q41: =C41*11.63 -> 86.011676 | R41: =D41*11.63 -> 90.568432 | S41: =E41*11.63 -> 78.407174 | T41: =F41*11.63 -> 89.538938 | U41: =G41*11.63 -> 101.09719 | V41: =H41*11.63 -> 104.16158 | W41: =I41*11.63 -> 107.03326 | X41: =J41*11.63 -> 124.46964 | ... AB41: =N41*11.63 -> 0 | AD41: dont essence fossile | AE41: =C41*FE_et_bio!$B$17 -> 22.664077 | AF41: =D41*FE_et_bio!$B$17 -> 23.864782 | AG41: =E41*FE_et_bio!$B$17 -> 20.66029 | AH41: =F41*FE_et_bio!$B$17 -> 23.59351 | AI41: =G41*FE_et_bio!$B$17 -> 26.63911 | AJ41: =H41*FE_et_bio!$B$17 -> 27.446577 | AK41: =I41*FE_et_bio!$B$17 -> 28.203265 | AL41: =J41*FE_et_bio!$B$17 -> 32.79775 | ... AP41: =N41*FE_et_bio!$B$17 -> 0
B42: dont bio-essence | C42: =C40-C41 -> 0.58239927 | D42: =D40-D41 -> 0.69597536 | E42: =E40-E41 -> 0.56225548 | F42: =F40-F41 -> 0.64755035 | G42: =G40-G41 -> 0.76344528 | H42: =H40-H41 -> 0.85186397 | I42: =I40-I41 -> 1.0797055 | J42: =J40-J41 -> 1.6990004 | ... N42: =N40-N41 -> 0.24934978 | P42: dont bio-essence | Q42: =C42*11.63 -> 6.7733035 | R42: =D42*11.63 -> 8.0941934 | S42: =E42*11.63 -> 6.5390313 | T42: =F42*11.63 -> 7.5310106 | U42: =G42*11.63 -> 8.8788686 | V42: =H42*11.63 -> 9.907178 | W42: =I42*11.63 -> 12.556975 | X42: =J42*11.63 -> 19.759375 | ... AB42: =N42*11.63 -> 2.899938 | AD42: dont bio-essence | AE42: =0 -> 0 | AF42: =0 -> 0 | AG42: =0 -> 0 | AH42: =0 -> 0 | AI42: =0 -> 0 | AJ42: =0 -> 0 | AK42: =0 -> 0 | AL42: =0 -> 0 | ... AP42: =0 -> 0
B43: Gazole (yc carb subst) | C43: =C113+C124+C141 -> 35.903297 | D43: =D113+D124+D141 -> 35.889475 | E43: =E113+E124+E141 -> 29.655065 | F43: =F113+F124+F141 -> 31.610134 | G43: =G113+G124+G141 -> 32.89847 | H43: =H113+H124+H141 -> 31.401752 | I43: =I113+I124+I141 -> 28.988553 | J43: =J113+J124+J141 -> 18.298499 | ... N43: =N113+N124+N141 -> 1.3575248 | P43: Gazole (yc carb subst) | Q43: =C43*11.63 -> 417.55534 | R43: =D43*11.63 -> 417.3946 | S43: =E43*11.63 -> 344.8884 | T43: =F43*11.63 -> 367.62586 | U43: =G43*11.63 -> 382.60921 | V43: =H43*11.63 -> 365.20238 | W43: =I43*11.63 -> 337.13688 | X43: =J43*11.63 -> 212.81155 | ... AB43: =N43*11.63 -> 15.788013 | AD43: Gazole (yc carb subst) | AE43: =C43*C10 -> 105.27042 | AF43: =D43*D10 -> 104.53896 | AG43: =E43*E10 -> 86.445463 | AH43: =F43*F10 -> 92.436501 | AI43: =G43*G10 -> 96.043887 | AJ43: =H43*H10 -> 91.188387 | AK43: =I43*I10 -> 82.775869 | AL43: =J43*J10 -> 49.770875 | ... AP43: =N43*N10 -> 0
B44: dont gazole fossile | C44: =C43*(1-FE_et_bio!B47) -> 33.400837 | D44: =D43*(1-FE_et_bio!C47) -> 33.168756 | E44: =E43*(1-FE_et_bio!D47) -> 27.427941 | F44: =F43*(1-FE_et_bio!E47) -> 29.328813 | G44: =G43*(1-FE_et_bio!F47) -> 30.473387 | H44: =H43*(1-FE_et_bio!G47) -> 28.932804 | I44: =I43*(1-FE_et_bio!H47) -> 26.263629 | J44: =J43*(1-FE_et_bio!I47) -> 15.791605 | ... N44: =N43*(1-FE_et_bio!M47) -> 0 | P44: dont gazole fossile | Q44: =C44*11.63 -> 388.45174 | R44: =D44*11.63 -> 385.75263 | S44: =E44*11.63 -> 318.98695 | T44: =F44*11.63 -> 341.0941 | U44: =G44*11.63 -> 354.40549 | V44: =H44*11.63 -> 336.48851 | W44: =I44*11.63 -> 305.44601 | X44: =J44*11.63 -> 183.65636 | ... AB44: =N44*11.63 -> 0 | AD44: dont gazole fossile | AE44: =C44*FE_et_bio!$B$18 -> 105.27042 | AF44: =D44*FE_et_bio!$B$18 -> 104.53896 | AG44: =E44*FE_et_bio!$B$18 -> 86.445463 | AH44: =F44*FE_et_bio!$B$18 -> 92.436501 | AI44: =G44*FE_et_bio!$B$18 -> 96.043887 | AJ44: =H44*FE_et_bio!$B$18 -> 91.188387 | AK44: =I44*FE_et_bio!$B$18 -> 82.775869 | AL44: =J44*FE_et_bio!$B$18 -> 49.770875 | ... AP44: =N44*FE_et_bio!$B$18 -> 0
B45: dont bio-gazole | C45: =C43-C44 -> 2.5024598 | D45: =D43-D44 -> 2.7207196 | E45: =E43-E44 -> 2.2271242 | F45: =F43-F44 -> 2.2813207 | G45: =G43-G44 -> 2.4250832 | H45: =H43-H44 -> 2.4689482 | I45: =I43-I44 -> 2.724924 | J45: =J43-J44 -> 2.5068944 | ... N45: =N43-N44 -> 1.3575248 | P45: dont bio-gazole | Q45: =C45*11.63 -> 29.103607 | R45: =D45*11.63 -> 31.641969 | S45: =E45*11.63 -> 25.901455 | T45: =F45*11.63 -> 26.531759 | U45: =G45*11.63 -> 28.203717 | V45: =H45*11.63 -> 28.713867 | W45: =I45*11.63 -> 31.690866 | X45: =J45*11.63 -> 29.155182 | ... AB45: =N45*11.63 -> 15.788013 | AD45: dont bio-gazole | AE45: =0 -> 0 | AF45: =0 -> 0 | AG45: =0 -> 0 | AH45: =0 -> 0 | AI45: =0 -> 0 | AJ45: =0 -> 0 | AK45: =0 -> 0 | AL45: =0 -> 0 | ... AP45: =0 -> 0
B46: Carburéacteurs autres que H2 (yc vols vers DROM) | C46: =C128+C134-C131-C137 -> 1.6167023 | D46: =D128+D134-D131-D137 -> 1.6501915 | E46: =E128+E134-E131-E137 -> 1.0163051 | F46: =F128+F134-F131-F137 -> 1.2527221 | G46: =G128+G134-G131-G137 -> 1.5262755 | H46: =H128+H134-H131-H137 -> 1.4636046 | I46: =I128+I134-I131-I137 -> 1.4574536 | J46: =J128+J134-J131-J137 -> 1.4204002 | ... N46: =N128+N134-N131-N137 -> 0.86172722 | P46: Carburéacteurs autres que H2 (yc vols vers DROM) | Q46: =Q47+Q48+Q49 -> 18.802248 | R46: =R47+R48+R49 -> 19.191728 | S46: =S47+S48+S49 -> 11.819628 | T46: =T47+T48+T49 -> 14.569159 | U46: =U47+U48+U49 -> 17.750584 | V46: =V47+V48+V49 -> 17.021721 | W46: =W47+W48+W49 -> 16.950185 | X46: =X47+X48+X49 -> 16.519254 | ... AB46: =AB47+AB48+AB49 -> 10.021888 | AD46: Carburéacteurs autres que H2 | AE46: =AE47+AE48+AE49 -> 4.8942251 | AF46: =AF47+AF48+AF49 -> 4.9956067 | AG46: =AG47+AG48+AG49 -> 3.0766492 | AH46: =AH47+AH48+AH49 -> 3.7771826 | AI46: =AI47+AI48+AI49 -> 4.5835133 | AJ46: =AJ47+AJ48+AJ49 -> 4.377585 | AK46: =AK47+AK48+AK49 -> 4.3238905 | AL46: =AL47+AL48+AL49 -> 4.0600239 | ... AP46: =AP47+AP48+AP49 -> 1.6502231
B47: dont kérosène fossile | C47: =C132+C138 -> 1.6167023 | D47: =D132+D138 -> 1.6501915 | E47: =E132+E138 -> 1.0163051 | F47: =F132+F138 -> 1.2477113 | G47: =G132+G138 -> 1.5140653 | H47: =H132+H138 -> 1.4460413 | I47: =I132+I138 -> 1.4283045 | J47: =J132+J138 -> 1.3351762 | ... N47: =N132+N138 -> 0.1356906 | P47: dont kérosène fossile | Q47: =Q132+Q138 -> 18.802248 | R47: =R132+R138 -> 19.191728 | S47: =S132+S138 -> 11.819628 | T47: =T132+T138 -> 14.510882 | U47: =U132+U138 -> 17.60858 | V47: =V132+V138 -> 16.817461 | W47: =W132+W138 -> 16.611181 | X47: =X132+X138 -> 15.528099 | ... AB47: =AB132+AB138 -> 1.5780817 | AD47: dont kérosène fossile | AE47: =C47*FE_et_bio!$B$19 -> 4.8942251 | AF47: =D47*FE_et_bio!$B$19 -> 4.9956067 | AG47: =E47*FE_et_bio!$B$19 -> 3.0766492 | AH47: =F47*FE_et_bio!$B$19 -> 3.7771826 | AI47: =G47*FE_et_bio!$B$19 -> 4.5835133 | AJ47: =H47*FE_et_bio!$B$19 -> 4.377585 | AK47: =I47*FE_et_bio!$B$19 -> 4.3238905 | AL47: =J47*FE_et_bio!$B$19 -> 4.0419641 | ... AP47: =N47*FE_et_bio!$B$19 -> 0.41077467
B48: dont biocarburants durables pour l'aéronautique | C48: =C129+C135 -> 0 | D48: =D129+D135 -> 0 | E48: =E129+E135 -> 0 | F48: =F129+F135 -> 0.0050108886 | G48: =G129+G135 -> 0.012210204 | H48: =H129+H135 -> 0.017563255 | I48: =I129+I135 -> 0.029149072 | J48: =J129+J135 -> 0.079258329 | ... N48: =N129+N135 -> 0.31661141 | P48: dont biocarburants durables pour l'aéronautique | Q48: =Q129+Q135 -> 0 | R48: =R129+R135 -> 0 | S48: =S129+S135 -> 0 | T48: =T129+T135 -> 0.058276634 | U48: =U129+U135 -> 0.14200468 | V48: =V129+V135 -> 0.20426066 | W48: =W129+W135 -> 0.3390037 | X48: =X129+X135 -> 0.92177437 | ... AB48: =AB129+AB135 -> 3.6821907 | AD48: dont biocarburants durables pour l'aéronautique | AE48: =0 -> 0 | AF48: =0 -> 0 | AG48: =0 -> 0 | AH48: =0 -> 0 | AI48: =0 -> 0 | AJ48: =0 -> 0 | AK48: =0 -> 0 | AL48: =0 -> 0 | ... AP48: =0 -> 0
B49: dont PtL pour l'aéronautique | C49: =C130+C136 -> 0 | D49: =D130+D136 -> 0 | E49: =E130+E136 -> 0 | F49: =F130+F136 -> 0 | G49: =G130+G136 -> 0 | H49: =H130+H136 -> 0 | I49: =I130+I136 -> 0 | J49: =J130+J136 -> 0.0059656807 | ... N49: =N130+N136 -> 0.40942521 | P49: dont PtL pour l'aéronautique | Q49: =Q130+Q136 -> 0 | R49: =R130+R136 -> 0 | S49: =S130+S136 -> 0 | T49: =T130+T136 -> 0 | U49: =U130+U136 -> 0 | V49: =V130+V136 -> 0 | W49: =W130+W136 -> 0 | X49: =X130+X136 -> 0.069380867 | ... AB49: =AB130+AB136 -> 4.7616152 | AD49: dont PtL pour l'aéronautique | AE49: =C49*FE_et_bio!$B$19 -> 0 | AF49: =D49*FE_et_bio!$B$19 -> 0 | AG49: =E49*FE_et_bio!$B$19 -> 0 | AH49: =F49*FE_et_bio!$B$19 -> 0 | AI49: =G49*FE_et_bio!$B$19 -> 0 | AJ49: =H49*FE_et_bio!$B$19 -> 0 | AK49: =I49*FE_et_bio!$B$19 -> 0 | AL49: =J49*FE_et_bio!$B$19 -> 0.01805984 | ... AP49: =N49*FE_et_bio!$B$19 -> 1.2394484
B50: GPL | C50: =C114 -> 0 | D50: =D114 -> 0 | E50: =E114 -> 0 | F50: =F114 -> 0 | G50: =G114 -> 0 | H50: =H114 -> 0 | I50: =I114 -> 0 | J50: =J114 -> 0 | ... N50: =N114 -> 0 | P50: GPL | Q50: =C50*11.63 -> 0 | R50: =D50*11.63 -> 0 | S50: =E50*11.63 -> 0 | T50: =F50*11.63 -> 0 | U50: =G50*11.63 -> 0 | V50: =H50*11.63 -> 0 | W50: =I50*11.63 -> 0 | X50: =J50*11.63 -> 0 | ... AB50: =N50*11.63 -> 0 | AD50: GPL | AE50: =C50 -> 0 | AF50: =D50 -> 0 | AG50: =E50 -> 0 | AH50: =F50 -> 0 | AI50: =G50 -> 0 | AJ50: =H50 -> 0 | AK50: =I50 -> 0 | AL50: =J50 -> 0 | ... AP50: =N50 -> 0
B51: GNV (dont bio-GNV) | C51: =C115+C142 -> 0.091650184 | D51: =D115+D142 -> 0.11204792 | E51: =E115+E142 -> 0.13537863 | F51: =F115+F142 -> 0.20167722 | G51: =G115+G142 -> 0.25879115 | H51: =H115+H142 -> 0.26124573 | I51: =I115+I142 -> 0.35432371 | J51: =J115+J142 -> 0.4263092 | ... N51: =N115+N142 -> 0.044497549 | P51: GNV (dont bio-GNV) | Q51: =C51*11.63 -> 1.0658916 | R51: =D51*11.63 -> 1.3031174 | S51: =E51*11.63 -> 1.5744535 | T51: =F51*11.63 -> 2.3455061 | U51: =G51*11.63 -> 3.009741 | V51: =H51*11.63 -> 3.0382879 | W51: =I51*11.63 -> 4.1207847 | X51: =J51*11.63 -> 4.957976 | ... AB51: =N51*11.63 -> 0.51750649 | AD51: GNV (dont bio-GNV) | AE51: =C51*C11 -> 0.21635555 | AF51: =D51*D11 -> 0.24509117 | AG51: =E51*E11 -> 0.31958385 | AH51: =F51*F11 -> 0.4765693 | AI51: =G51*G11 -> 0.61153122 | AJ51: =H51*H11 -> 0.61115817 | AK51: =I51*I11 -> 0.79541364 | AL51: =J51*J11 -> 0.85627419 | ... AP51: =N51*N11 -> 0
...

Sheet FE_et_bio
A1: 1 tep | B1: 41.868 | C1: GJ | D1: =B1/3.6 -> 11.63 | E1: MWh
A3: 1/ Sur produits fossiles
B4: MJ/L | C4: MJ/kg | D4: kWh/L | E4: kgCO2/L | F4: kgCO2/kWh | G4: avec maj 1% | I4: 1kWh/L vaut 1TWh/m3
A5: H2 | C5: 120
A6: Gazole | B6: 36 | C6: 42.6 | D6: 10 | E6: 2.68272 | F6: 0.268272 | G6: 0.27095472
A7: Essence | B7: 32 | C7: 44 | D7: 8.8888889 | E7: 2.31936 | F7: 0.260928 | G7: 0.26353728
A8: carburéacteur | B8: 34 | C8: 44 | D8: 9.4444444 | E8: 2.43406 | F8: 0.257724 | G8: 0.26030124
C10: MJ/kg | D10: kWh/kg | E10: kgCO2/kg | F10: kgCO2/kWh | G10: avec maj 1%
A11: GNV/gaz | C11: =D11*3.6 -> 49.6 | D11: 13.777778 | E11: 2.799424 | F11: 0.203184 | G11: 0.20521584
A12: GPL | C12: =D12*3.6 -> 46 | D12: 12.777778 | E12: 2.9026 | F12: 0.22716 | G12: 0.2294316
A14: FE sur produits fossile
B15: FE (tCO2/tep) | C15: FE (kgCO2/kWh)
B16: 2015 | C16: 2015
A17: Essence | B17: =C17*11.63 -> 3.064505 | C17: 0.2635 | E17: 0.26096303 | F17: =C17/E17 -> 1.0097216
A18: Diesel | B18: =C18*11.63 -> 3.15173 | C18: 0.271 | E18: 0.27343078 | F18: =C18/E18 -> 0.99111006
A19: Kérosène | B19: =C19*11.63 -> 3.027289 | C19: 0.2603 | E19: 0.25984523 | F19: =C19/E19 -> 1.0017502
A20: GNV | B20: =C20*11.63 -> 2.3630299 | C20: =F11 -> 0.203184 | E20: 0.20309544 | F20: =C20/E20 -> 1.000436
A23: FE du fossile | B23: FE par udp (avec maj 1%) | D23: Energie par udp
A24: Essence | B24: =E7*1.01 -> 2.3425536 | C24: kgCO2/L | D24: =32/3.6 -> 8.8888889 | E24: kWh/L
A25: Gazole | B25: =E6*1.01 -> 2.7095472 | C25: kgCO2/L | D25: 10 | E25: kWh/L
A26: Kérosène | B26: =E8*1.01 -> 2.4584006 | C26: kgCO2/L | D26: =34/3.6 -> 9.4444444 | E26: kWh/L
A27: GNV | B27: =E11 -> 2.799424 | C27: kgCO2/kg | D27: =D11 -> 13.777778 | E27: kWh/kg
A29: 2/ Part de bio-énergies
C30: 2019 | D30: 2020 | E30: 2021 | F30: 2022 | G30: 2023 | H30: 2025
A31: tx observé fer | C31: 0.06756197 | D31: 0.066866998 | E31: 0.094685302 | F31: 0.095325097 | G31: 0.097510637
A32: Taux observés
A33: tx observé biocarb routier moy | C33: 0.077192913 | D33: 0.075518201 | E33: 0.073373389 | F33: 0.075274251 | G33: 0.080453012
A34: tx bio théorique | C34: =C39/4.5+3.5/4.5*C40 -> 0.074333333 | D34: =D39/4.5+3.5/4.5*D40 -> 0.080444444 | E34: =E39/4.5+3.5/4.5*E40 -> 0.081333333 | F34: =F39/4.5+3.5/4.5*F40 -> 0.085777778 | G34: =G39/4.5+3.5/4.5*G40 -> 0.088
A35: correctif | C35: =C33/C34 -> 1.0384697 | D35: =D33/D34 -> 0.93876217 | E35: =E33/E34 -> 0.90213183 | F35: =F33/F34 -> 0.87754956 | G35: =G33/G34 -> 0.91423878 | H35: 1
A37: Taux théoriques plafonds
B38: 2018 | C38: 2019 | D38: 2020 | E38: 2021 | F38: 2022 | G38: 2023 | H38: 2025
A39: Taux d’incorporation des biocarburants dans l’essence | B39: 0.073 | C39: 0.079 | D39: 0.082 | E39: 0.086 | F39: 0.092 | G39: 0.095 | H39: 0.105
A40: Taux d’incorporation des biocarburants dans le diesel | B40: 0.0697 | C40: 0.073 | D40: 0.08 | E40: 0.08 | F40: 0.084 | G40: 0.086 | H40: 0.094
A41: Taux d’incorporation du gaz renouvelable dans le gaz | B41: =0.1% -> 0.001 | C41: =0.1% -> 0.001 | D41: =0.1% -> 0.001 | E41: =D41 -> 0.001 | F41: =E41 -> 0.001 | G41: 0.01 | H41: =2% -> 0.02
A43: Taux appliqués
A44: Taux de bio dans les carburants terrestres (taux d'incorporation en énergie)
B45: 2018 | C45: 2019 | D45: 2020 | E45: 2021 | F45: 2022 | G45: 2023 | H45: 2025 | I45: 2030 | J45: 2035 | K45: 2040 | L45: 2045 | M45: 2050 | P45: 2022 | Q45: 2023 | R45: 2024 | S45: 2025
A46: Taux d’incorporation des biocarburants dans l’essence | B46: =B39 -> 0.073 | C46: =C39*C$35 -> 0.082039105 | D46: =D39*D$35 -> 0.076978498 | E46: =E39*E$35 -> 0.077583337 | F46: =F39*F$35 -> 0.080734559 | G46: =G39*G$35 -> 0.086852684 | H46: =H39*H$35 -> 0.105 | I46: 0.137 | J46: 0.19 | K46: 0.3 | L46: 0.6 | M46: 1 | O46: essence | Q46: 0.095 | R46: 0.099 | S46: 0.105
A47: Taux d’incorporation des biocarburants dans le diesel | B47: =B40 -> 0.0697 | C47: =C40*C$35 -> 0.075808287 | D47: =D40*D$35 -> 0.075100974 | E47: =E40*E$35 -> 0.072170546 | F47: =F40*F$35 -> 0.073714163 | G47: =G40*G$35 -> 0.078624535 | H47: =H40*H$35 -> 0.094 | I47: =I46 -> 0.137 | J47: 0.19 | K47: =K46 -> 0.3 | L47: =L46 -> 0.6 | M47: =M46 -> 1 | O47: gazole | Q47: 0.086 | R47: 0.092 | S47: 0.094
A48: Taux d’incorporation du gaz renouvelable dans le gaz | B48: =0.1% -> 0.001 | C48: =C34 -> 0.074333333 | D48: =0.1% -> 0.001 | G48: 0.01 | H48: 0.05 | I48: 0.15 | J48: 0.2 | K48: 0.4 | L48: 0.5 | M48: 1 | O48: carbu | Q48: 0.01 | R48: 0.015 | S48: 0.02
...

Sheet VP
B2: 1 tep | C2: 41.868 | D2: GJ | E2: =C2/3.6 -> 11.63 | K2: MWh
B4: FE du fossile sans intégration des parts de bio et avec contenu élec à 0 (pour calcul de l'évolution des émissions des véh neufs)
B5: FE du fossile | C5: FE par udp | E5: Energie par udp
B6: Essence | C6: 2.3422222 | D6: kgCO2/L | E6: 8.8888889 | F6: kWh/L | G6: =C6/E6 -> 0.2635
B7: Gazole | C7: 2.71 | D7: kgCO2/L | E7: 10 | F7: kWh/L | G7: =C7/E7 -> 0.271
B8: Kérosène | C8: 2.4583889 | D8: kgCO2/L | E8: 9.4444444 | F8: kWh/L | G8: =C8/E8 -> 0.2603
B9: GNV | C9: 2.8027171 | D9: kgCO2/kg | E9: 13.8 | F9: kWh/kg | G9: =C9/E9 -> 0.20309544
B10: Electricité | C10: 0
B12: FE des carburants avec intégration des parts de bio et avec facteur émissions de l'élec nul (pour calcul roulant)
B13: FE du fossile | C13: 2018 | D13: 2019 | E13: 2020 | F13: 2021 | G13: 2022 | H13: 2023 | I13: 2025 | J13: 2030 | K13: 2035 | L13: 2040 | M13: 2045 | N13: 2050
B14: Essence | C14: =FE_et_bio!B60 -> 2.1715472 | D14: =FE_et_bio!C60 -> 2.1503726 | E14: =FE_et_bio!D60 -> 2.1622273 | F14: =FE_et_bio!E60 -> 2.1608105 | G14: =FE_et_bio!F60 -> 2.1534286 | H14: =FE_et_bio!G60 -> 2.1390965 | I14: =FE_et_bio!H60 -> 2.0965855 | J14: =FE_et_bio!I60 -> 2.0216238 | ... N14: =FE_et_bio!M60 -> 0
B15: Gazole | C15: =FE_et_bio!B61 -> 2.5206918 | D15: =FE_et_bio!C61 -> 2.5041411 | E15: =FE_et_bio!D61 -> 2.5060576 | F15: =FE_et_bio!E61 -> 2.5139977 | G15: =FE_et_bio!F61 -> 2.5098152 | H15: =FE_et_bio!G61 -> 2.4965103 | I15: =FE_et_bio!H61 -> 2.4548498 | J15: =FE_et_bio!I61 -> 2.3383392 | ... N15: =FE_et_bio!M61 -> 0
B16: GNV | C16: =FE_et_bio!B62 -> 2.7966246 | D16: =FE_et_bio!C62 -> 2.5913335 | E16: =FE_et_bio!D62 -> 2.7966246 | F16: =FE_et_bio!E62 -> 2.799424 | G16: =FE_et_bio!F62 -> 2.799424 | H16: =FE_et_bio!G62 -> 2.7714298 | I16: =FE_et_bio!H62 -> 2.6594528 | J16: =FE_et_bio!I62 -> 2.3795104 | ... N16: =FE_et_bio!M62 -> 0
B17: Electricité | C17: 0 | D17: 0 | E17: =0 -> 0 | F17: =0 -> 0 | G17: =0 -> 0 | H17: =0 -> 0 | I17: =0 -> 0 | J17: =0 -> 0 | K17: =0 -> 0 | L17: =0 -> 0 | ... N17: =0 -> 0
B19: Pop
B20: en millions hab | C20: 2018 | D20: 2019 | E20: 2020 | I20: 2025 | J20: 2030 | K20: 2035 | L20: 2040 | M20: 2045 | N20: 2050
B21: France entière | C21: 66.992 | D21: 67.146 | E21: 67.3 | I21: 68 | J21: 68.6 | K21: 69 | L21: 69.2 | M21: 69.3 | N21: 69.2
B22: Métropole | C22: 64.880941 | D22: 65.031872 | E22: 65.182804 | I22: 65.867327 | J22: 66.45135 | K22: 66.835909 | L22: 67.022388 | M22: 67.109411 | N22: 66.999161
B23: évol pop métropole / 2019 | D23: =D22/$D22 -> 1 | E23: =E22/$D22 -> 1.0023209 | I23: =I22/$D22 -> 1.0128468 | J23: =J22/$D22 -> 1.0218274 | K23: =K22/$D22 -> 1.0277408 | L23: =L22/$D22 -> 1.0306083 | M23: =M22/$D22 -> 1.0319465 | N23: =N22/$D22 -> 1.0302511
B26: I) Hypothèses sur les parts des énergies et consos des véh neufs
B28: A) Parcs roulants et immatriculations des VP
B30: Parcs et immatriculations VP | C30: observé | D30: observé | E30: observé | F30: observé | G30: observé
B31: VP | C31: 2018 | D31: 2019 | E31: 2020 | F31: 2021 | G31: 2022 | H31: 2023 | I31: 2025 | J31: 2030 | K31: 2035 | L31: 2040 | M31: 2045 | N31: 2050
B32: Ensemble VP | C32: 37.988 | D32: 38.095 | E32: 38.046 | F32: 38.461 | G32: 38.682 | H32: 37.992 | I32: =I33/$G33*$G32 -> 36.837684 | J32: =J33/$G33*$G32 -> 35.315862 | K32: =K33/$G33*$G32 -> 33.842371 | L32: =L33/$G33*$G32 -> 32.36888 | M32: =M33/$G33*$G32 -> 30.895389 | N32: =N33/$G33*$G32 -> 29.421897
B33: Parc VP (*) | C33: 37.321089 | D33: 37.548734 | E33: 37.63588 | F33: =F32*$D$33/$D$32 -> 37.909486 | G33: =G32*$D$33/$D$32 -> 38.127317 | H33: =H32*$D$33/$D$32 -> 37.447211 | I33: 36.309448 | J33: 34.809448 | K33: =J33*0.75+0.25*N33 -> 33.357086 | L33: =0.5*J33+0.5*N33 -> 31.904724 | M33: =0.25*J33+0.75*N33 -> 30.452362 | N33: 29
B34: Immatriculations VP | C34: 2.223581 | D34: 2.258277 | E34: 1.69353 | F34: 1.708675 | G34: 1.57695 | H34: 1.817346 | I34: 1.9 | J34: 1.8 | K34: 1.8 | L34: 2 | M34: 2 | N34: 1.9
B35: ratio | C35: =C33/C34 -> 16.784227 | D35: =D33/D34 -> 16.62716 | E35: =E33/E34 -> 22.223332 | F35: =F33/F34 -> 22.186481 | G35: =G33/G34 -> 24.177886 | H35: =H33/H34 -> 20.605438 | I35: =I33/I34 -> 19.110236 | J35: =J33/J34 -> 19.338582 | ... N35: =N33/N34 -> 15.263158
B36: (*) parc effectif recalé
B38: Kilométrage moyen des véhicules immatriculés en France
C39: 2018 | D39: 2019 | E39: 2020 | F39: 2021 | G39: 2022
B40: Voitures pavillon français | C40: 12518 | D40: 12511 | E40: 10205 | F40: 10945 | G40: 11957 | H40: 11693.496
B41: Diesel (y compris hybrides) | C41: 14807 | D41: 14762 | E41: 11940 | F41: 12730 | G41: 13975 | H41: 13424.866
B42: Essence | C42: 8840 | D42: 9148 | E42: 7776 | F42: 8625 | G42: 9535 | H42: 9780.6297
B43: Electricité | C43: 10317 | D43: 10939 | E43: 9165 | F43: 10166 | G43: 11353 | H43: 12791.995
B45: B) Part de marché des énergies au sein des immatriculations
B47: Evolutions des parts de marché des énergies dans les immatriculations annuelles de véhicules particuliers
C48: observé | D48: observé | E48: observé | F48: observé | G48: observé | H48: observé | I48: projeté | J48: projeté | K48: projeté | L48: projeté | M48: projeté | N48: projeté
B49: % | C49: 2018 | D49: 2019 | E49: 2020 | F49: 2021 | G49: 2022 | H49: 2023 | I49: 2025 | J49: 2030 | K49: 2035 | L49: 2040 | M49: 2045 | N49: 2050 | P49: Part de marché des véhicules particuliers neufs (%)
B50: Thermiques | C50: =C51+C52 -> 0.97909858 | D50: =D51+D52 -> 0.97236123 | E50: =E51+E52 -> 0.88918354 | F50: =F51+F52 -> 0.82040528 | G50: =G51+G52 -> 0.78769143 | H50: 0.74318044 | I50: =1-I53-I54-I55 -> 0.69 | J50: =1-J53-J54-J55 -> 0.29 | K50: =1-K53-K54-K55 -> 0 | L50: =1-L53-L54-L55 -> 0 | M50: =1-M53-M54-M55 -> 0 | N50: =1-N53-N54-N55 -> 0 | P50: % | Q50: 2022 | R50: 2025 | S50: 2030 | T50: 2035 | U50: 2040 | V50: 2045 | W50: 2050
B51: dont Essence | C51: 0.59261525 | D51: 0.63022782 | E51: 0.57224437 | F51: 0.59102989 | G51: 0.61816798 | H51: 0.63596916 | I51: =I50-I52 -> 0.64 | J51: =J50-J52 -> 0.28 | K51: 0 | L51: 0 | M51: 0 | N51: 0 | P51: Essence | Q51: 0.63596916 | R51: 0.64 | S51: 0.28 | T51: 0 | U51: 0 | V51: 0 | W51: 0
...

Sheet VUL
B1: 1 tep | C1: 41.868 | F1: GJ | G1: =C1/3.6 -> 11.63 | I1: MWh
B3: FE du fossile sans intégration des parts de bio et avec contenu élec à 0 (pour calcul de l'évolution des émissions théoriques des véh neufs)
B4: FE du fossile | C4: FE par udp | E4: Energie par udp
B5: Essence | C5: 2.3422222 | D5: kgCO2/L | E5: 8.8888889 | F5: kWh/L
B6: Gazole | C6: 2.71 | D6: kgCO2/L | E6: 10 | F6: kWh/L
B7: Kérosène | C7: 2.4583889 | D7: kgCO2/L | E7: 9.4444444 | F7: kWh/L
B8: GNV | C8: 2.8027171 | D8: kgCO2/kg | E8: 13.8 | F8: kWh/kg
B9: Electricité | C9: 0
B11: FE des carburants avec intégration des parts de bio et avec facteur émissions de l'élec nul (pour calcul roulant)
B12: FE du fossile | C12: 2018 | D12: 2019 | E12: 2020 | F12: 2021 | G12: 2022 | H12: 2023 | I12: 2025 | J12: 2030 | K12: 2035 | L12: 2040 | M12: 2045 | N12: 2050
B13: Essence | C13: =FE_et_bio!B60 -> 2.1715472 | D13: =FE_et_bio!C60 -> 2.1503726 | E13: =FE_et_bio!D60 -> 2.1622273 | F13: =FE_et_bio!E60 -> 2.1608105 | G13: =FE_et_bio!F60 -> 2.1534286 | H13: =FE_et_bio!G60 -> 2.1390965 | I13: =FE_et_bio!H60 -> 2.0965855 | J13: =FE_et_bio!I60 -> 2.0216238 | ... N13: =FE_et_bio!M60 -> 0
B14: Gazole | C14: =FE_et_bio!B61 -> 2.5206918 | D14: =FE_et_bio!C61 -> 2.5041411 | E14: =FE_et_bio!D61 -> 2.5060576 | F14: =FE_et_bio!E61 -> 2.5139977 | G14: =FE_et_bio!F61 -> 2.5098152 | H14: =FE_et_bio!G61 -> 2.4965103 | I14: =FE_et_bio!H61 -> 2.4548498 | J14: =FE_et_bio!I61 -> 2.3383392 | ... N14: =FE_et_bio!M61 -> 0
B15: GNV | C15: =FE_et_bio!B62 -> 2.7966246 | D15: =FE_et_bio!C62 -> 2.5913335 | E15: =FE_et_bio!D62 -> 2.7966246 | F15: =FE_et_bio!E62 -> 2.799424 | G15: =FE_et_bio!F62 -> 2.799424 | H15: =FE_et_bio!G62 -> 2.7714298 | I15: =FE_et_bio!H62 -> 2.6594528 | J15: =FE_et_bio!I62 -> 2.3795104 | ... N15: =FE_et_bio!M62 -> 0
B16: Electricité | C16: 0 | D16: 0 | E16: 0 | F16: 1 | G16: 2 | H16: 3 | I16: 0 | J16: 0 | K16: 0 | L16: 0 | M16: 0 | N16: 0
B18: VUL-AME 2021
B20: I) Données sur les parts des énergies et consos des véh neufs
B22: A) Circulations, parcs roulants et immatriculations des VUL | P22: Immatriculations de véhicules (millions)
P23: Millions de véhicules | Q23: 2022 | R23: 2025 | S23: 2030 | T23: 2035 | U23: 2040 | V23: 2045 | W23: 2050
B24: Parc et immatriculations | P24: Véhicules particuliers | Q24: 1.58 | R24: 1.9 | S24: 1.8 | T24: 1.8 | U24: 2 | V24: 2 | W24: 1.9
P25: Véhicules utilitaires légers | Q25: 0.36 | R25: 0.36 | S25: 0.36 | T25: 0.36 | U25: 0.36 | V25: 0.36 | W25: 0.36
C26: 2018 | D26: 2019 | E26: 2020 | F26: 2021 | G26: 2022 | H26: 2023 | I26: 2025 | J26: 2030 | K26: 2035 | L26: 2040 | M26: 2045 | N26: 2050 | P26: Poids lourds | Q26: 0.05 | R26: 0.04 | S26: 0.04 | T26: 0.04 | U26: 0.04 | V26: 0.04 | W26: 0.04
B27: Parc VUL | C27: 6100.0734 | D27: 6091.1969 | E27: 6039.2158 | F27: 6161.463 | G27: 6222.0553 | H27: 6264.0927 | I27: 6200 | J27: 6138.2475 | K27: 6077.1101 | L27: 6016.5816 | M27: 5956.6559 | N27: 5897.3272 | P27: Bus et car | Q27: 0.01 | R27: 0.01 | S27: 0.01 | T27: 0.01 | U27: 0.01 | V27: 0.01 | W27: 0.01
B28: Immatriculations VUL | C28: 471.132 | D28: 490.256 | E28: 411.763 | F28: 444.99 | G28: 358.893 | H28: 390.471 | I28: 390 | J28: 410 | K28: 420 | L28: 420 | M28: 420 | N28: 420 | P28: Périmètre hexagone
C29: =C27/C28 -> 12.947695 | D29: =D27/D28 -> 12.424523 | E29: =E27/E28 -> 14.666728 | F29: =F27/F28 -> 13.846295 | G29: =G27/G28 -> 17.336798 | H29: =H27/H28 -> 16.042402 | I29: =I27/I28 -> 15.897436 | J29: =J27/J28 -> 14.971335 | ... N29: =N27/N28 -> 14.041255
P30: Parc de véhicules (millions)
B31: Kilométrage moyen des véhicules immatriculés en France | P31: Millions de véhicules | Q31: 2022 | R31: 2025 | S31: 2030 | T31: 2035 | U31: 2040 | V31: 2045 | W31: 2050
C32: 2018 | D32: 2019 | E32: 2020 | F32: 2021 | G32: 2022 | P32: Véhicules particuliers | Q32: 38.1 | R32: 36.3 | S32: 34.8 | T32: 33.4 | U32: 31.9 | V32: 30.5 | W32: 29
B33: Véhicules utilitaires légers pavillon français | C33: 13942 | D33: 14173 | E33: 12691 | F33: 13596 | G33: 13793 | P33: Véhicules utilitaires légers | Q33: 6.4 | R33: 6.4 | S33: 6.4 | T33: 6.4 | U33: 6.4 | V33: 6.4 | W33: 6.4
B34: Diesel (y compris hybrides) | C34: 14321 | D34: 14529 | E34: 12987 | F34: 13900 | G34: 14103 | P34: Poids lourds | Q34: 0.6 | R34: 0.6 | S34: 0.6 | T34: 0.6 | U34: 0.6 | V34: 0.6 | W34: 0.6
B35: Essence et autres énergies | C35: 7709 | D35: 7766 | E35: 6977 | F35: 7517 | G35: 7447 | P35: Bus et car | Q35: 0.1 | R35: 0.1 | S35: 0.1 | T35: 0.1 | U35: 0.1 | V35: 0.1 | W35: 0.1
P36: Périmètre hexagone
Q37: =Q32/Q24 -> 24.113924 | R37: =R32/R24 -> 19.105263 | S37: =S32/S24 -> 19.333333 | T37: =T32/T24 -> 18.555556 | U37: =U32/U24 -> 15.95 | V37: =V32/V24 -> 15.25 | W37: =W32/W24 -> 15.263158
B38: B) Parts de marchés des énergies | C38: véhicules neufs | Q38: =Q33/Q25 -> 17.777778 | R38: =R33/R25 -> 17.777778 | S38: =S33/S25 -> 17.777778 | T38: =T33/T25 -> 17.777778 | U38: =U33/U25 -> 17.777778 | V38: =V33/V25 -> 17.777778 | W38: =W33/W25 -> 17.777778
Q39: =Q34/Q26 -> 12 | R39: =R34/R26 -> 15 | S39: =S34/S26 -> 15 | T39: =T34/T26 -> 15 | U39: =U34/U26 -> 15 | V39: =V34/V26 -> 15 | W39: =W34/W26 -> 15
B40: Evolutions des parts de marché des énergies dans les immatriculations annuelles
C41: observé | D41: observé | E41: observé | P41: Part de marché des véhicules utilitaires légers neufs (%)
C42: 2018 | D42: 2019 | E42: 2020 | F42: 2021 | G42: 2022 | H42: 2023 | I42: 2025 | J42: 2030 | K42: 2035 | L42: 2040 | M42: 2045 | N42: 2050 | P42: % | Q42: 2023 | R42: 2025 | S42: 2030 | T42: 2035 | U42: 2040 | V42: 2045 | W42: 2050
B43: Thermique | C43: 0.98047005 | D43: 0.98069605 | E43: 0.97294705 | F43: 0.96439759 | G43: 0.94759254 | H43: 0.91697207 | I43: 0.83 | J43: 0.477 | K43: 0 | L43: 2.7755576e-17 | M43: 2.7755576e-17 | N43: 2.7755576e-17 | P43: Thermiques | Q43: 0.91697207 | R43: 0.83 | S43: 0.477 | T43: 0 | U43: 2.7755576e-17 | V43: 2.7755576e-17 | W43: 2.7755576e-17
B44: Gaz | C44: 0.0019873547 | D44: 0.0026571989 | E44: 0.0041453671 | F44: 0.0058292397 | G44: 0.0039996998 | H44: 0.0045304261 | I44: 0.003 | J44: 0.003 | K44: 0 | L44: 0 | M44: 0 | N44: 0 | P44: GNV | Q44: 0.0045304261 | R44: 0.003 | S44: 0.003 | T44: 0 | U44: 0 | V44: 0 | W44: 0
B45: Electrique | C45: 0.017542595 | D45: 0.01664675 | E45: 0.022907585 | F45: 0.029773168 | G45: 0.048407764 | H45: 0.078497507 | I45: 0.167 | J45: 0.51 | K45: 0.99 | L45: 0.99 | M45: 0.99 | N45: 0.99 | P45: Electrique | Q45: 0.078497507 | R45: 0.167 | S45: 0.51 | T45: =1-T46 -> 0.99 | U45: =1-U46 -> 0.99 | V45: =1-V46 -> 0.99 | W45: =1-W46 -> 0.99
...

Sheet PL
B1: 1 tep | C1: 41.868 | D1: GJ | E1: =C1/3.6 -> 11.63 | F1: MWh
B3: FE du fossile sans intégration des parts de bio et avec contenu élec à 0 (pour calcul de l'évolution des émissions théoriques des véh neufs)
B4: FE du fossile | C4: FE par udp | E4: Energie par udp
B5: Essence | C5: 2.3422222 | D5: kgCO2/L | E5: 8.8888889 | F5: kWh/L
B6: Gazole | C6: 2.71 | D6: kgCO2/L | E6: 10 | F6: kWh/L
B7: Kérosène | C7: 2.4583889 | D7: kgCO2/L | E7: 9.4444444 | F7: kWh/L
B8: GNV | C8: 2.8027171 | D8: kgCO2/kg | E8: 13.8 | F8: kWh/kg
B9: Electricité | C9: 0
B11: FE des carburants avec intégration des parts de bio et avec un contenu de l'élec nul
B12: FE du fossile | C12: 2018 | D12: 2019 | E12: 2020 | F12: 2021 | G12: 2022 | H12: 2023 | I12: 2025 | J12: 2030 | K12: 2035 | L12: 2040 | M12: 2045 | N12: 2050
B13: Essence | C13: =FE_et_bio!B60 -> 2.1715472 | D13: =FE_et_bio!C60 -> 2.1503726 | E13: =FE_et_bio!D60 -> 2.1622273 | F13: =FE_et_bio!E60 -> 2.1608105 | G13: =FE_et_bio!F60 -> 2.1534286 | H13: =FE_et_bio!G60 -> 2.1390965 | I13: =FE_et_bio!H60 -> 2.0965855 | J13: =FE_et_bio!I60 -> 2.0216238 | ... N13: =FE_et_bio!M60 -> 0
B14: Gazole | C14: =FE_et_bio!B61 -> 2.5206918 | D14: =FE_et_bio!C61 -> 2.5041411 | E14: =FE_et_bio!D61 -> 2.5060576 | F14: =FE_et_bio!E61 -> 2.5139977 | G14: =FE_et_bio!F61 -> 2.5098152 | H14: =FE_et_bio!G61 -> 2.4965103 | I14: =FE_et_bio!H61 -> 2.4548498 | J14: =FE_et_bio!I61 -> 2.3383392 | ... N14: =FE_et_bio!M61 -> 0
B15: GNV | C15: =FE_et_bio!B62 -> 2.7966246 | D15: =FE_et_bio!C62 -> 2.5913335 | E15: =FE_et_bio!D62 -> 2.7966246 | F15: =FE_et_bio!E62 -> 2.799424 | G15: =FE_et_bio!F62 -> 2.799424 | H15: =FE_et_bio!G62 -> 2.7714298 | I15: =FE_et_bio!H62 -> 2.6594528 | J15: =FE_et_bio!I62 -> 2.3795104 | ... N15: =FE_et_bio!M62 -> 0
B16: Electricité | C16: 0 | D16: 0 | E16: 0 | F16: 1 | G16: 2 | H16: 3 | I16: 0 | J16: 0 | K16: 0 | L16: 0 | M16: 0 | N16: 0
B19: PL | C19: AMS
B21: I) Données sur les parts des énergies et consos des véh neufs
B23: A) Circulations, parcs roulants et immatriculations des PL
P24: Immatriculations de véhicules (millions)
B25: Parc et immatriculation des PL immatriculés en France (camions + tracteurs routiers) | P25: Millions de véhicules | Q25: 2022 | R25: 2025 | S25: 2030 | T25: 2035 | U25: 2040 | V25: 2045 | W25: 2050
C26: 2018 | D26: 2019 | E26: 2020 | F26: 2021 | G26: 2022 | H26: 2023 | I26: 2025 | J26: 2030 | K26: 2035 | L26: 2040 | M26: 2045 | N26: 2050 | P26: Véhicules particuliers | Q26: 1.57695 | R26: 1.9 | S26: 1.8 | T26: 1.8 | U26: 2 | V26: 2 | W26: 1.9
B27: Parc de camions (milliers) | C27: 599 | D27: 606 | E27: 605 | F27: 612 | G27: 619 | H27: 611.55771 | I27: =E27 -> 605 | J27: =I27 -> 605 | K27: =J27 -> 605 | L27: =K27 -> 605 | M27: =L27 -> 605 | N27: =M27 -> 605 | P27: Véhicules utilitaires légers | Q27: 0.358893 | R27: 0.358893 | S27: 0.358893 | T27: 0.358893 | U27: 0.358893 | V27: 0.358893 | W27: 0.358893
B28: Immatriculations (milliers par an) | C28: 56.792 | D28: 57.278 | E28: 43.466 | F28: 45.944 | G28: 46.163 | H28: 50.48 | I28: =44.3 -> 44.3 | J28: =44.3 -> 44.3 | K28: =44.3 -> 44.3 | L28: =44.3 -> 44.3 | M28: =44.3 -> 44.3 | N28: =44.3 -> 44.3 | P28: Poids lourds | Q28: 0.046163 | R28: 0.0443 | S28: 0.0443 | T28: 0.0443 | U28: 0.0443 | V28: 0.0443 | W28: 0.0443
C29: =C27/C28 -> 10.54726 | D29: =D27/D28 -> 10.579978 | E29: =E27/E28 -> 13.918925 | F29: =F27/F28 -> 13.320564 | G29: =G27/G28 -> 13.409007 | H29: =H27/H28 -> 12.114852 | I29: =I27/I28 -> 13.656885 | J29: =J27/J28 -> 13.656885 | ... N29: =N27/N28 -> 13.656885 | P29: Bus et car | Q29: 0.006192 | R29: 0.0062 | S29: 0.0062 | T29: 0.0062 | U29: 0.0062 | V29: 0.0062 | W29: 0.0062
P30: Périmètre hexagone
B31: Kilométrage moyen des véhicules immatriculés en France
C32: 2018 | D32: 2019 | E32: 2020 | F32: 2021 | G32: 2022 | P32: Parc de véhicules (millions)
B33: Poids lourds pavillon français | C33: 44050 | D33: 44202 | E33: 41087 | F33: 43893 | G33: 44031 | P33: Millions de véhicules | Q33: 2022 | R33: 2025 | S33: 2030 | T33: 2035 | U33: 2040 | V33: 2045 | W33: 2050
B34: Diesel | C34: 44070 | D34: 44196 | E34: 41024 | F34: 43798 | G34: 43972 | P34: Véhicules particuliers | Q34: 38.127317 | R34: 36.309448 | S34: 34.809448 | T34: 33.357086 | U34: 31.904724 | V34: 30.452362 | W34: 29
B35: GNV | C35: 44677 | D35: 48206 | E35: 49942 | F35: 53137 | G35: 49770 | P35: Véhicules utilitaires légers | Q35: 6.356 | R35: 6.356 | S35: 6.356 | T35: 6.356 | U35: 6.356 | V35: 6.356 | W35: 6.356
B36: Electrique | C36: 11540 | D36: 15069 | E36: 16056 | F36: 18911 | G36: 16067 | P36: Poids lourds | Q36: 0.619 | R36: 0.605 | S36: 0.605 | T36: 0.605 | U36: 0.605 | V36: 0.605 | W36: 0.605
P37: Bus et car | Q37: 0.094 | R37: 0.094 | S37: 0.094 | T37: 0.094 | U37: 0.094 | V37: 0.094 | W37: 0.094
P38: Périmètre hexagone
B39: B) Part de marchés des énergies | E39: véhicules neufs
P40: Part de marché des poids lourds neufs (%)
C41: 2018 | D41: 2019 | E41: 2020 | F41: 2021 | G41: 2022 | H41: 2023 | I41: 2025 | J41: 2030 | K41: 2035 | L41: 2040 | M41: 2045 | N41: 2050 | P41: % | Q41: 2023 | R41: 2025 | S41: 2030 | T41: 2035 | U41: 2040 | V41: 2045 | W41: 2050
B42: Thermiques | C42: 0.97777856 | D42: 0.97045986 | E42: 0.96266047 | F42: 0.96077834 | G42: 0.93891212 | H42: 0.95186212 | I42: 0.89 | J42: 0.49 | K42: 0.33 | L42: 0.17 | M42: 0.11 | N42: 0.1 | P42: Thermiques | Q42: 0.93891212 | R42: 0.89 | S42: 0.49 | T42: 0.33 | U42: 0.17 | V42: 0.11 | W42: 0.1
B43: GNV | C43: 0.020566277 | D43: 0.026729285 | E43: 0.035360972 | F43: 0.036849208 | G43: 0.049563503 | H43: 0.035003962 | I43: 0.03 | J43: 0.01 | K43: 0 | L43: 0 | M43: 0 | N43: 0 | P43: GNV | Q43: 0.049563503 | R43: 0.03 | S43: 0.01 | T43: 0 | U43: 0 | V43: 0 | W43: 0
B44: Electrique | C44: 0.00015847302 | D44: 0.00094277035 | E44: 0.001035292 | F44: 0.001697719 | G44: 0.011199445 | H44: 0.013034865 | I44: 0.08 | J44: 0.496 | K44: 0.65 | L44: 0.8 | M44: 0.85 | N44: 0.85 | P44: Electrique | Q44: 0.011199445 | R44: 0.08 | S44: 0.496 | T44: 0.65 | U44: 0.8 | V44: 0.85 | W44: 0.85
B45: H2 | C45: 0.0014966897 | D45: 0.001868082 | E45: 0.000943266 | F45: 0.00067473446 | G45: 0.00032493555 | H45: 0 | I45: 0 | J45: 0.004 | K45: 0.02 | L45: 0.03 | M45: 0.04 | N45: 0.05 | P45: H2 | Q45: 0.00032493555 | R45: 0 | S45: 0.004 | T45: 0.02 | U45: 0.03 | V45: 0.04 | W45: 0.05
B46: baisse émissions parc à comparer avec règlement UE CO2 PL : | E46: =E103/$E103-1 -> 0 | F46: =F103/$E103-1 -> -0.0106042 | G46: =G103/$E103-1 -> -0.030089353 | H46: =H103/$E103-1 -> -0.041091971 | I46: =I103/$E103-1 -> -0.13126028 | J46: =J103/$E103-1 -> -0.55928379 | K46: =K103/$E103-1 -> -0.71990328 | L46: =L103/$E103-1 -> -0.8609916 | ... N46: =N103/$E103-1 -> -0.91823035
...

Sheet donnees parc
B3: Extrait du SDES 2019. Base : RSVERO (remontée des contrôles techniques).
B4: Traitement novembre 2022.
C6: inf à 7,5t | D6: ]7,5t-12t] | E6: ]12t-16t] | F6: ]16t-19t] | G6: ]19t-26t] | H6: sup à > 26t | J6: Tracteurs routiers
B7: Taille du parc | C7: moins de 7,5T | D7: 7.5 à moins de 12T | E7: 12 à moins de 16T | F7: 16 à moins de 19T | G7: 19 à moins de 26T | H7: 26T et plus | I7: Ensemble camions | J7: Tracteurs routiers | K7: Ensemble camion + tracteur
B8: Ensemble du parc | C8: 19700 | D8: 47300 | E8: 32900 | F8: 66400 | G8: 65100 | H8: 74000 | I8: 305600 | J8: 215600 | K8: 521200 | L8: =K8*K12/10^6 -> 25330.32
B9: 0 à 8 ans | C9: 9100 | D9: 19600 | E9: 13700 | F9: 25100 | G9: 30000 | H9: 50600 | I9: 148100 | J9: 181400 | K9: 329500 | L9: =K9*K13/10^6 -> 22175.35
B11: Parcours annuel moyen 2019 (km) | C11: moins de 7,5T | D11: 7.5 à moins de 12T | E11: 12 à moins de 16T | F11: 16 à moins de 19T | G11: 19 à moins de 26T | H11: 26T et plus | I11: Ensemble camions | J11: Tracteurs routiers | K11: Ensemble camion + tracteur
B12: Ensemble du parc | C12: 13800 | D12: 19400 | E12: 20000 | F12: 26300 | G12: 32900 | H12: 34700 | I12: 27200 | J12: 78900 | K12: 48600
B13: 0 à 8 ans | C13: 20400 | D13: 31100 | E13: 31400 | F13: 44300 | G13: 51300 | H13: 41000 | I13: 40200 | J13: 89500 | K13: 67300 | L13: camions | M13: tracteurs | N13: ensemble
A14: km | B14: Ensemble du parc | C14: =C8*C12/10^6 -> 271.86 | D14: =D8*D12/10^6 -> 917.62 | E14: =E8*E12/10^6 -> 658 | F14: =F8*F12/10^6 -> 1746.32 | G14: =G8*G12/10^6 -> 2141.79 | H14: =H8*H12/10^6 -> 2567.8 | I14: =I8*I12/10^6 -> 8312.32 | J14: =J8*J12/10^6 -> 17010.84 | K14: =K8*K12/10^6 -> 25330.32 | L14: =SUM(C14:H14) -> 8303.39 | M14: =J14 -> 17010.84 | N14: =L14+M14 -> 25314.23
A15: km | B15: 0-8 ans | C15: =C9*C13/10^6 -> 185.64 | D15: =D9*D13/10^6 -> 609.56 | E15: =E9*E13/10^6 -> 430.18 | F15: =F9*F13/10^6 -> 1111.93 | G15: =G9*G13/10^6 -> 1539 | H15: =H9*H13/10^6 -> 2074.6 | I15: =I9*I13/10^6 -> 5953.62 | J15: =J9*J13/10^6 -> 16235.3 | K15: =K9*K13/10^6 -> 22175.35 | L15: =SUM(C15:H15) -> 5950.91 | M15: =J15 -> 16235.3 | N15: =L15+M15 -> 22186.21
B16: % <8 ans | C16: =C15/C14 -> 0.68285147 | D16: =D15/D14 -> 0.66428369 | E16: =E15/E14 -> 0.653769 | F16: =F15/F14 -> 0.63672752 | G16: =G15/G14 -> 0.71855784 | H16: =H15/H14 -> 0.80792897 | I16: =I15/I14 -> 0.71624047 | J16: =J15/J14 -> 0.95440907 | K16: =K15/K14 -> 0.8754469
B17: % km tot | C17: =C14/$N14 -> 0.010739414 | D17: =D14/$N14 -> 0.036249177 | E17: =E14/$N14 -> 0.025993285 | F17: =F14/$N14 -> 0.068985705 | G17: =G14/$N14 -> 0.084608143 | H17: =H14/$N14 -> 0.10143702 | I17: =I14/$N14 -> 0.32836551 | J17: =J14/$N14 -> 0.67198726 | K17: =K14/$N14 -> 1.0006356
B19: Pour compte d'autrui | C19: Compte d’autrui : approche sectorielle des entreprises en considérant que les secteurs des transports (et location de camions) opérent essentiellement pour compte d'autrui.
B21: Taille du parc | C21: moins de 7,5T | D21: 7.5 à moins de 12T | E21: 12 à moins de 16T | F21: 16 à moins de 19T | G21: 19 à moins de 26T | H21: 26T et plus | I21: Ensemble camions | J21: Tracteurs routiers | K21: Ensemble camion + tracteur
B22: Tout âge | C22: 3200 | D22: 12800 | E22: 8000 | F22: 20000 | G22: 20600 | H22: 28500 | I22: 93100 | J22: 147400 | K22: 240500
B23: 0 à 8 ans | C23: 2200 | D23: 8500 | E23: 5000 | F23: 12000 | G23: 14500 | H23: 22700 | I23: 64900 | J23: 134100 | K23: 199000
B26: Ratio Pour Autrui / Ensemble | C26: moins de 7,5T | D26: 7.5 à moins de 12T | E26: 12 à moins de 16T | F26: 16 à moins de 19T | G26: 19 à moins de 26T | H26: 26T et plus | I26: Ensemble camions | J26: Tracteurs routiers | K26: Ensemble camion + tracteur
B27: Tout âge | C27: 0.16243655 | D27: 0.27061311 | E27: 0.24316109 | F27: 0.30120482 | G27: 0.31643625 | H27: 0.38513514 | I27: 0.3046466 | J27: 0.68367347 | K27: 0.46143515
B28: 0 à 8 ans | C28: 0.24175824 | D28: 0.43367347 | E28: 0.3649635 | F28: 0.47808765 | G28: 0.48333333 | H28: 0.4486166 | I28: 0.43821742 | J28: 0.73925028 | K28: 0.60394537
B30: Parcours annuel moyen 2019 (km) | C30: moins de 7,5T | D30: 7.5 à moins de 12T | E30: 12 à moins de 16T | F30: 16 à moins de 19T | G30: 19 à moins de 26T | H30: 26T et plus | I30: Ensemble camions | J30: Tracteurs routiers | K30: Ensemble camion + tracteur
B31: Tout âge | C31: 23100 | D31: 31200 | E31: 32900 | F31: 44700 | G31: 52900 | H31: 43000 | I31: 42400 | J31: 88900 | K31: 70900 | L31: =K22*K31/10^6 -> 17051.45
B32: 0 à 8 ans | C32: 27100 | D32: 36200 | E32: 38600 | F32: 56200 | G32: 64700 | H32: 47400 | I32: 50100 | J32: 94600 | K32: 80100 | L32: =K23*K32/10^6 -> 15939.9
B34: Ratio Pour Autrui / Ensemble | C34: moins de 7,5T | D34: 7.5 à moins de 12T | E34: 12 à moins de 16T | F34: 16 à moins de 19T | G34: 19 à moins de 26T | H34: 26T et plus | I34: Ensemble camions | J34: Tracteurs routiers | K34: Ensemble camion + tracteur
B35: Tout âge | C35: 1.673913 | D35: 1.6082474 | E35: 1.645 | F35: 1.6996198 | G35: 1.6079027 | H35: 1.2391931 | I35: 1.5588235 | J35: 1.1267427 | K35: 1.4588477
B36: 0 à 8 ans | C36: 1.3284314 | D36: 1.1639871 | E36: 1.2292994 | F36: 1.268623 | G36: 1.2612086 | H36: 1.1560976 | I36: 1.2462687 | J36: 1.0569832 | K36: 1.1901932

Sheet B&C
B3: Bus et cars
B5: I) Données sur les parts des énergies et consos des véh neufs
B7: A) Parcs roulants et immatriculations des autobus et autocars
B9: Evolution du parc et des immatriculations d’autobus et de cars
C11: 2018 | D11: 2019 | E11: 2020 | F11: 2021 | G11: 2022 | H11: 2023 | I11: 2025 | J11: 2030 | K11: 2035 | L11: 2040 | M11: 2045 | N11: 2050
B12: Parc (milliers) | C12: 90 | D12: 92 | E12: 92 | F12: 94 | G12: 94 | H12: =G12 -> 94 | I12: =94 -> 94 | J12: =94 -> 94 | K12: =94 -> 94 | L12: =94 -> 94 | M12: =94 -> 94 | N12: =94 -> 94
B13: Immatriculations (milliers) | C13: =C14+C15 -> 6.471 | D13: =D14+D15 -> 7.045 | E13: =E14+E15 -> 6.399 | F13: =F14+F15 -> 7.207 | G13: =G14+G15 -> 6.192 | H13: =H14+H15 -> 6.142 | I13: 6.2 | J13: 6.2 | K13: 6.2 | L13: 6.2 | M13: 6.2 | N13: 6.2
B14: dont autobus | C14: 1.691 | D14: 1.888 | E14: 1.849 | F14: 2.211 | G14: 1.911 | H14: 1.789 | I14: 1.9 | J14: 1.9 | K14: 1.9 | L14: 1.9 | M14: 1.9 | N14: 1.9
B15: dont autocars | C15: 4.78 | D15: 5.157 | E15: 4.55 | F15: 4.996 | G15: 4.281 | H15: 4.353 | I15: 4.3 | J15: 4.3 | K15: 4.3 | L15: 4.3 | M15: 4.3 | N15: 4.3
B17: durée de vie | C17: =C12/C13 -> 13.908206 | D17: =D12/D13 -> 13.058907 | E17: =E12/E13 -> 14.377246 | F17: =F12/F13 -> 13.042875 | G17: =G12/G13 -> 15.180879 | H17: =H12/H13 -> 15.304461 | I17: =I12/I13 -> 15.16129 | J17: =J12/J13 -> 15.16129 | ... N17: =N12/N13 -> 15.16129
B19: % bus dans les immat
B21: Evolution du kilométrage moyen
C22: 2018 | D22: 2019 | E22: 2020 | F22: 2021 | G22: 2022
B23: Autobus et autocars pavillon français | C23: 34109.517 | D23: 33528.401 | E23: 25856.157 | F23: 25856.157 | G23: 25856.157
B26: A1) Evolution des parts de marché des immatriculations
B28: dont autobus
B29: Parts de marché des énergies dans les immatriculations annuelles d'autobus
Q30: Part de marché des bus neufs (%)
B31: Bus | C31: 2018 | D31: 2019 | E31: 2020 | F31: 2021 | G31: 2022 | H31: 2023 | I31: 2025 | J31: 2030 | K31: 2035 | L31: 2040 | M31: 2045 | N31: 2050 | Q31: % | R31: 2023 | S31: 2025 | T31: 2030 | U31: 2035 | V31: 2040 | W31: 2045 | X31: 2050
B32: Gazole | C32: 0.80603193 | D32: 0.61493644 | E32: 0.53758789 | F32: 0.24242424 | G32: 0.12192569 | H32: 0.19333996 | I32: 0.2 | J32: 0.05 | K32: 0 | L32: 0 | M32: 0 | N32: 0 | Q32: Thermiques | R32: 0.19333996 | S32: 0.2 | T32: 0.05 | U32: 0 | V32: 0 | W32: 0 | X32: 0
B33: GNV | C33: 0.15198108 | D33: 0.24417373 | E33: 0.35911303 | F33: 0.48032564 | G33: 0.49659864 | H33: 0.43737575 | I33: 0.3 | J33: 0.05 | K33: 0 | L33: 0 | M33: 0 | N33: 0 | Q33: GNV | R33: 0.43737575 | S33: 0.3 | T33: 0.05 | U33: 0 | V33: 0 | W33: 0 | X33: 0
B34: Electrique | C34: 0.039621526 | D34: 0.13983051 | E34: 0.094645754 | F34: 0.27725011 | G34: 0.38147567 | H34: 0.36928429 | I34: 0.5 | J34: 0.89 | K34: 0.99 | L34: 0.99 | M34: 0.99 | N34: 0.99 | Q34: Electrique | R34: 0.36928429 | S34: 0.5 | T34: 0.89 | U34: 0.99 | V34: 0.99 | W34: 0.99 | X34: 0.99
B35: H2 | C35: 0.0023654642 | D35: 0.001059322 | E35: 0.0086533261 | F35: 0 | G35: 0 | H35: 0 | I35: 0 | J35: 0.01 | K35: 0.01 | L35: 0.01 | M35: 0.01 | N35: 0.01 | Q35: H2 | R35: 0 | S35: 0 | T35: 0.01 | U35: 0.01 | V35: 0.01 | W35: 0.01 | X35: 0.01
B36: check | C36: =SUM(C32:C35) -> 1 | D36: =SUM(D32:D35) -> 1 | E36: =SUM(E32:E35) -> 1 | F36: =SUM(F32:F35) -> 1 | G36: =SUM(G32:G35) -> 1 | H36: =SUM(H32:H35) -> 1 | I36: =SUM(I32:I35) -> 1 | J36: =SUM(J32:J35) -> 1 | ... N36: =SUM(N32:N35) -> 1
B39: Parts de marché des énergies dans les immatriculations annuelles d’autocars
Q40: Part de marché des autocars neufs (%)
B41: Cars | C41: 2018 | D41: 2019 | E41: 2020 | F41: 2021 | G41: 2022 | H41: 2023 | I41: 2025 | J41: 2030 | K41: 2035 | L41: 2040 | M41: 2045 | N41: 2050 | Q41: % | R41: 2023 | S41: 2025 | T41: 2030 | U41: 2035 | V41: 2040 | W41: 2045 | X41: 2050
B42: Gazole et cars B100 | C42: 0.98284519 | D42: 0.96800465 | E42: 0.91450549 | F42: 0.86289031 | G42: 0.83578603 | H42: =1-H43-H44-H45 -> 0.87680085 | I42: 0.9 | J42: 0.67 | K42: 0.48 | L42: 0.12 | M42: 0.11 | N42: 0.1 | Q42: Thermiques | R42: 0.87680085 | S42: 0.9 | T42: =1-T43-T44-T45 -> 0.67 | U42: =1-U43-U44-U45 -> 0.48 | V42: =1-V43-V44-V45 -> 0.12 | W42: =1-W43-W44-W45 -> 0.11 | X42: =1-X43-X44-X45 -> 0.1
B43: GNV | C43: 0.011924686 | D43: 0.025208455 | E43: 0.08 | F43: 0.13230584 | G43: 0.14552675 | H43: 0.11348495 | I43: 0.08 | J43: 0.03 | K43: 0 | L43: 0 | M43: 0 | N43: 0 | Q43: GNV | R43: 0.11348495 | S43: 0.08 | T43: 0.03 | U43: 0 | V43: 0 | W43: 0 | X43: 0
B44: Electrique | C44: 0.0052301255 | D44: 0.0032964902 | E44: 0.0010989011 | F44: 0.0018014412 | G44: 0.014716188 | H44: 0.0057431656 | I44: 0.02 | J44: 0.296 | K44: 0.5 | L44: 0.85 | M44: 0.85 | N44: 0.85 | Q44: Electrique | R44: 0.0057431656 | S44: 0.02 | T44: 0.296 | U44: 0.5 | V44: 0.85 | W44: 0.85 | X44: 0.85
B45: H2 | C45: 0 | D45: 0.0034904014 | E45: 0.0043956044 | F45: 0.0030024019 | G45: 0.0039710348 | H45: 0.0039710348 | I45: 0 | J45: 0.004 | K45: 0.02 | L45: 0.03 | M45: 0.04 | N45: 0.05 | Q45: H2 | R45: 0.0039710348 | S45: 0 | T45: 0.004 | U45: 0.02 | V45: 0.03 | W45: 0.04 | X45: 0.05
B46: dont gazole B100 | C46: 0 | D46: 0.0034904014 | E46: 0.0043956044 | F46: 0.0030024019 | G46: 0.0039710348 | H46: 0.08
B47: check | C47: =SUM(C42:C45) -> 1 | D47: =SUM(D42:D45) -> 1 | E47: =SUM(E42:E45) -> 1 | F47: =SUM(F42:F45) -> 1 | G47: =SUM(G42:G45) -> 1 | H47: =SUM(H42:H45) -> 1 | I47: =SUM(I42:I45) -> 1 | J47: =SUM(J42:J45) -> 1 | ... N47: =SUM(N42:N45) -> 1
B49: autobus et autocars
B50: Parts de marché des énergies dans les immatriculations annuelles d'autobus et d’autocars
B52: Bus et cars | C52: 2018 | D52: 2019 | E52: 2020 | F52: 2021 | G52: 2022 | H52: 2023 | I52: 2025 | J52: 2030 | K52: 2035 | L52: 2040 | M52: 2045 | N52: 2050
B53: Gazole | C53: =(C$14*C32+C$15*C42)/(C$13) -> 0.9366404 | D53: =(D$14*D32+D$15*D42)/(D$13) -> 0.87338538 | E53: =(E$14*E32+E$15*E42)/(E$13) -> 0.80559462 | F53: =(F$14*F32+F$15*F42)/(F$13) -> 0.67254059 | G53: =(G$14*G32+G$15*G42)/(G$13) -> 0.61547158 | H53: =(H$14*H32+H$15*H42)/(H$13) -> 0.67772701 | I53: =(I$14*I32+I$15*I42)/(I$13) -> 0.68548387 | J53: =(J$14*J32+J$15*J42)/(J$13) -> 0.48 | ... N53: =(N$14*N32+N$15*N42)/(N$13) -> 0.069354839 | O53: gazole
B54: GNV | C54: =(C$14*C33+C$15*C43)/(C$13) -> 0.048524185 | D54: =(D$14*D33+D$15*D43)/(D$13) -> 0.083889283 | E54: =(E$14*E33+E$15*E43)/(E$13) -> 0.1606501 | F54: =(F$14*F33+F$15*F43)/(F$13) -> 0.23907312 | G54: =(G$14*G33+G$15*G43)/(G$13) -> 0.25387597 | H54: =(H$14*H33+H$15*H43)/(H$13) -> 0.20782566 | I54: =(I$14*I33+I$15*I43)/(I$13) -> 0.14741935 | J54: =(J$14*J33+J$15*J43)/(J$13) -> 0.036129032 | ... N54: =(N$14*N33+N$15*N43)/(N$13) -> 0 | O54: gnv
B55: Electrique | C55: =(C$14*C34+C$15*C44)/(C$13) -> 0.014217277 | D55: =(D$14*D34+D$15*D44)/(D$13) -> 0.039886444 | E55: =(E$14*E34+E$15*E44)/(E$13) -> 0.028129395 | F55: =(F$14*F34+F$15*F44)/(F$13) -> 0.086304981 | G55: =(G$14*G34+G$15*G44)/(G$13) -> 0.12790698 | H55: =(H$14*H34+H$15*H44)/(H$13) -> 0.11163295 | I55: =(I$14*I34+I$15*I44)/(I$13) -> 0.16709677 | J55: =(J$14*J34+J$15*J44)/(J$13) -> 0.47803226 | ... N55: =(N$14*N34+N$15*N44)/(N$13) -> 0.89290323 | O55: élec
B56: H2 | C56: =(C$14*C35+C$15*C45)/(C$13) -> 0.00061814248 | D56: =(D$14*D35+D$15*D45)/(D$13) -> 0.0028388928 | E56: =(E$14*E35+E$15*E45)/(E$13) -> 0.005625879 | F56: =(F$14*F35+F$15*F45)/(F$13) -> 0.0020813098 | G56: =(G$14*G35+G$15*G45)/(G$13) -> 0.002745478 | H56: =(H$14*H35+H$15*H45)/(H$13) -> 0.0028143788 | I56: =(I$14*I35+I$15*I45)/(I$13) -> 0 | J56: =(J$14*J35+J$15*J45)/(J$13) -> 0.0058387097 | ... N56: =(N$14*N35+N$15*N45)/(N$13) -> 0.037741935 | O56: h2
...

Sheet 2RM
A2: 1) Deux roues motorisés
A5: Mix énergétique | B5: (moyennes motos, motocyclettes)
A6: % des immatriculations | B6: observé | C6: observé | D6: observé | E6: observé | F6: observé
B7: 2015 | C7: 2016 | D7: 2017 | E7: 2018 | F7: 2019 | G7: 2020 | H7: 2021 | I7: 2022 | J7: 2023 | K7: 2025 | L7: 2030 | M7: 2035 | N7: 2040 | O7: 2045 | P7: 2050
A8: % essence | B8: 0.98843692 | C8: 0.97516497 | D8: 0.9672865 | E8: 0.95262318 | F8: 0.94323566 | G8: 0.94141541 | H8: =1-H9 -> 0.85208187 | I8: =1-I9 -> 0.76004125 | J8: =I8 -> 0.76004125 | K8: 0.6707077 | L8: 0.4 | M8: 0.325 | N8: 0.25 | O8: 0.125 | P8: 0
A9: % électricité | B9: 0.011563079 | C9: 0.02483503 | D9: 0.032713502 | E9: 0.047376824 | F9: 0.05676434 | G9: 0.058584593 | H9: =0.67*G9+0.33*K9 -> 0.14791813 | I9: =0.33*G9+0.67*K9 -> 0.23995875 | J9: =I9 -> 0.23995875 | K9: 0.3292923 | L9: 0.6 | M9: 0.675 | N9: 0.75 | O9: 0.875 | P9: 1
A10: passage roulant - essence | G10: =1-G11 -> 0.98044326 | H10: =1-H11 -> 0.94910996 | I10: =1-I11 -> 0.91682716 | K10: =1-K11 -> 0.88549386 | L10: =1-L11 -> 0.6707077 | M10: =1-M11 -> 0.44892693 | N10: =1-N11 -> 0.325 | O10: =1-O11 -> 0.2375 | P10: =1-P11 -> 0.125
A11: passage roulant - élec | G11: =0.83*B9+0.17*G9 -> 0.019556737 | H11: =0.67*G11+0.33*K11 -> 0.05089004 | I11: =0.33*G11+0.67*K11 -> 0.083172837 | K11: =0.25*B9+0.5*G9+0.25*K9 -> 0.11450614 | L11: =0.25*G9+0.5*K9+0.25*L9 -> 0.3292923 | M11: =0.25*K9+0.5*L9+0.25*M9 -> 0.55107307 | N11: =0.25*L9+0.5*M9+0.25*N9 -> 0.675 | O11: =0.25*M9+0.5*N9+0.25*O9 -> 0.7625 | P11: =0.25*N9+0.5*O9+0.25*P9 -> 0.875
A13: % du parc roulant | B13: observé
B14: 2015 | C14: 2016 | D14: 2017 | E14: 2018 | F14: 2019 | G14: 2020 | H14: 2021 | I14: 2022 | J14: 2023 | K14: 2025 | L14: 2030 | M14: 2035 | N14: 2040 | O14: 2045 | P14: 2050
A15: % essence | B15: =1-B16 -> 1 | C15: =1-C16 -> 1 | D15: =1-D16 -> 0.99217731 | E15: =1-E16 -> 0.98826596 | F15: =1-F16 -> 0.98435461 | G15: =G10 -> 0.98044326 | H15: =H10 -> 0.94910996 | I15: =I10 -> 0.91682716 | J15: =I15 -> 0.91682716 | K15: =K10 -> 0.88549386 | L15: =L10 -> 0.6707077 | M15: =M10 -> 0.44892693 | N15: =N10 -> 0.325 | O15: =O10 -> 0.2375 | P15: =P10 -> 0.125
A16: % électricité | B16: =0% -> 0 | C16: =0.8*B16*0.2*G16 -> 0 | D16: =B16*0.6+G16*0.4 -> 0.0078226946 | E16: =0.4*B16+0.6*G16 -> 0.011734042 | F16: =B16*0.2+G16*0.8 -> 0.015645389 | G16: =G11 -> 0.019556737 | H16: =0.67*G16+0.33*K16 -> 0.05089004 | I16: =0.33*G16+0.67*K16 -> 0.083172837 | J16: =I16 -> 0.083172837 | K16: =K11 -> 0.11450614 | L16: =L11 -> 0.3292923 | M16: =M11 -> 0.55107307 | N16: =N11 -> 0.675 | O16: =O11 -> 0.7625 | P16: =P11 -> 0.875
A19: efficacité énergétique essence | E19: 1
A20: efficacité énergétique électricité | E20: 0.3
A22: Gains d'efficacité énergétique
B23: 2015 | C23: 2016 | D23: 2017 | E23: 2018 | F23: 2019 | G23: 2020 | H23: 2021 | I23: 2022 | J23: 2023 | K23: 2025 | L23: 2030 | M23: 2035 | N23: 2040 | O23: 2045 | P23: 2050
A24: Efficacité essence | B24: =0 -> 0 | C24: =0% -> 0 | D24: =0% -> 0 | E24: =0% -> 0 | F24: =E24 -> 0 | G24: =F24 -> 0 | H24: =G24 -> 0 | I24: =H24 -> 0 | J24: =I24 -> 0 | K24: 0.066666667 | L24: 0.1 | M24: 0.1375 | N24: 0.175 | O24: 0.2125 | P24: 0.25
A25: Efficacité électricité | B25: =0 -> 0 | C25: =0% -> 0 | D25: =0% -> 0 | E25: =0% -> 0 | F25: =E25 -> 0 | G25: =F25 -> 0 | H25: =G25 -> 0 | I25: =H25 -> 0 | J25: =I25 -> 0 | K25: 0.04 | L25: 0.06 | M25: 0.0825 | N25: 0.105 | O25: 0.1275 | P25: 0.15
B29: 2015 | C29: 2016 | D29: 2017 | E29: 2018 | F29: 2019 | G29: 2020 | H29: 2021 | I29: 2022 | J29: 2023 | K29: 2025 | L29: 2030 | M29: 2035 | N29: 2040 | O29: 2045 | P29: 2050
A30: Trafics 2RM | E30: =Trafic!C39 -> 11.340238 | F30: =Trafic!D39 -> 11.340238 | G30: =Trafic!E39 -> 9.5825009 | H30: =Trafic!F39 -> 9.8220635 | I30: =Trafic!G39 -> 11.069466 | J30: =I30 -> 11.069466 | K30: =Trafic!I39 -> 11.088283 | L30: =Trafic!J39 -> 11.1 | M30: =Trafic!K39 -> 11.10217 | N30: =Trafic!L39 -> 11.099269 | O30: =Trafic!M39 -> 11.091298 | P30: =Trafic!N39 -> 11.078257
A34: Mtep
A35: Mtep VP | B35: 2015 | C35: 2016 | D35: 2017 | E35: 2018 | F35: 2019 | G35: 2020 | H35: 2021 | I35: 2022 | J35: 2023 | K35: 2025 | L35: 2030 | M35: 2035 | N35: 2040 | O35: 2045 | P35: 2050
A36: Essence | B36: 0.43109493 | C36: 0.43407389 | D36: 0.43650341 | E36: 0.43910244 | F36: 0.43901604 | G36: 0.37096855 | H36: =$F36*(1-H24)*H15/$F15 -> 0.42329714 | I36: =$F36*(1-I24)*I15/$F15 -> 0.40889922 | J36: =$F36*(1-J24)*J15/$F15 -> 0.40889922 | K36: =$F36*(1-K24)*K15/$F15 -> 0.36859644 | L36: =$F36*(1-L24)*L15/$F15 -> 0.26921832 | M36: =$F36*(1-M24)*M15/$F15 -> 0.17268856 | N36: =$F36*(1-N24)*N15/$F15 -> 0.11958208 | O36: =$F36*(1-O24)*O15/$F15 -> 0.083414775 | P36: =$F36*(1-P24)*P15/$F15 -> 0.041811917
A37: Electricité | B37: =0 -> 0 | C37: =0 -> 0 | D37: =0 -> 0 | E37: =0 -> 0 | F37: =0 -> 0 | G37: =0 -> 0 | H37: =$F36*$E$20*(1-H25)*H16 -> 0.0067024631 | I37: =$F36*$E$20*(1-I25)*I16 -> 0.010954263 | J37: =$F36*$E$20*(1-J25)*J16 -> 0.010954263 | K37: =$F36*$E$20*(1-K25)*K16 -> 0.014477769 | L37: =$F36*$E$20*(1-L25)*L16 -> 0.040767217 | M37: =$F36*$E$20*(1-M25)*M16 -> 0.06659121 | N37: =$F36*$E$20*(1-N25)*N16 -> 0.079566169 | O37: =$F36*$E$20*(1-O25)*O16 -> 0.087620742 | P37: =$F36*$E$20*(1-P25)*P16 -> 0.097955454
