Workbook

Sheet T energie vecteurs
A1: Energie par vecteur énergétique | D1: c
A3: Energie primaire (Mtep)
A4: =Résultats!B1 -> SNBC3
E5: =Résultats!E1 -> 4 | F5: =E5+9 -> 13 | G5: =F5+3 -> 16 | H5: =G5+1 -> 17 | I5: =H5+1 -> 18 | J5: =I5+1 -> 19 | K5: =J5+1 -> 20 | L5: =K5+1 -> 21 | M5: =L5+1 -> 22 | N5: =M5+1 -> 23 | O5: =N5+1 -> 24 | ... S5: =R5+1 -> 28 | T5: =S5+5 -> 33 | U5: =T5+5 -> 38 | V5: =U5+5 -> 43 | W5: =V5+5 -> 48
E6: 2006 | F6: 2015 | G6: 2018 | H6: 2019 | I6: 2020 | J6: 2021 | K6: 2022 | L6: 2023 | M6: 2024 | N6: 2025 | O6: 2026 | P6: 2027 | Q6: 2028 | R6: 2029 | S6: 2030 | T6: 2035 | U6: 2040 | V6: 2045 | W6: 2050 | Z6: Cf. onglet "G énergie"
B7: Refined petroleum products | C7: Total | E7: =SUM(E8:E9) -> 85.507506 | F7: =SUM(F8:F9) -> 73.627917 | G7: =SUM(G8:G9) -> 67.118467 | H7: =SUM(H8:H9) -> 65.246975 | I7: =SUM(I8:I9) -> 63.540529 | J7: =SUM(J8:J9) -> 63.723147 | K7: =SUM(K8:K9) -> 63.749867 | L7: =SUM(L8:L9) -> 63.878995 | ... W7: =SUM(W8:W9) -> 53.061753 | AA7: 2020 | AB7: 2030 | AC7: 2050
C8: Oil | D8: Q_Mtep_ep_2201_2 | E8: =VLOOKUP($D8,Résultats!$B$2:$AX$476,E$5,FALSE) -> 84.840078 | F8: =VLOOKUP($D8,Résultats!$B$2:$AX$476,F$5,FALSE) -> 70.466412 | G8: =VLOOKUP($D8,Résultats!$B$2:$AX$476,G$5,FALSE) -> 64.067131 | H8: =VLOOKUP($D8,Résultats!$B$2:$AX$476,H$5,FALSE) -> 62.218773 | I8: =VLOOKUP($D8,Résultats!$B$2:$AX$476,I$5,FALSE) -> 60.527148 | J8: =VLOOKUP($D8,Résultats!$B$2:$AX$476,J$5,FALSE) -> 60.553253 | K8: =VLOOKUP($D8,Résultats!$B$2:$AX$476,K$5,FALSE) -> 60.43687 | L8: =VLOOKUP($D8,Résultats!$B$2:$AX$476,L$5,FALSE) -> 60.423066 | ... W8: =VLOOKUP($D8,Résultats!$B$2:$AX$476,W$5,FALSE) -> 50.191049 | X8: =W8-'[1]Cibles THREEME'!$H4 -> 39.790442 | Z8: Energie primaire | AA8: =I27 -> 227.83871 | AB8: =S27 -> 246.79317 | AC8: =W27 -> 247.56772
C9: Biofuels | D9: Q_Mtep_ep_2202_2 | E9: =VLOOKUP($D9,Résultats!$B$2:$AX$476,E$5,FALSE) -> 0.66742791 | F9: =VLOOKUP($D9,Résultats!$B$2:$AX$476,F$5,FALSE) -> 3.1615056 | G9: =VLOOKUP($D9,Résultats!$B$2:$AX$476,G$5,FALSE) -> 3.0513356 | H9: =VLOOKUP($D9,Résultats!$B$2:$AX$476,H$5,FALSE) -> 3.0282026 | I9: =VLOOKUP($D9,Résultats!$B$2:$AX$476,I$5,FALSE) -> 3.0133803 | J9: =VLOOKUP($D9,Résultats!$B$2:$AX$476,J$5,FALSE) -> 3.169894 | K9: =VLOOKUP($D9,Résultats!$B$2:$AX$476,K$5,FALSE) -> 3.3129965 | L9: =VLOOKUP($D9,Résultats!$B$2:$AX$476,L$5,FALSE) -> 3.4559291 | ... W9: =VLOOKUP($D9,Résultats!$B$2:$AX$476,W$5,FALSE) -> 2.8707035 | X9: =W9-'[1]Cibles THREEME'!$H5 -> -0.62613767
B10: Electric power generation, transmission and distribution | C10: Total | E10: =SUM(E11:E18) -> 135.21088 | F10: =SUM(F11:F18) -> 142.78155 | G10: =SUM(G11:G18) -> 132.04365 | H10: =SUM(H11:H18) -> 127.8628 | I10: =SUM(I11:I18) -> 123.23361 | J10: =SUM(J11:J18) -> 121.44619 | K10: =SUM(K11:K18) -> 119.91166 | L10: =SUM(L11:L18) -> 118.6704 | ... W10: =SUM(W11:W18) -> 148.67093
C11: Nuclear | D11: Q_Mtep_ep_2301_2 | E11: =VLOOKUP($D11,Résultats!$B$2:$AX$476,E$5,FALSE) -> 118.47205 | F11: =VLOOKUP($D11,Résultats!$B$2:$AX$476,F$5,FALSE) -> 123.93637 | G11: =VLOOKUP($D11,Résultats!$B$2:$AX$476,G$5,FALSE) -> 112.53772 | H11: =VLOOKUP($D11,Résultats!$B$2:$AX$476,H$5,FALSE) -> 108.19484 | I11: =VLOOKUP($D11,Résultats!$B$2:$AX$476,I$5,FALSE) -> 103.46436 | J11: =VLOOKUP($D11,Résultats!$B$2:$AX$476,J$5,FALSE) -> 101.41066 | K11: =VLOOKUP($D11,Résultats!$B$2:$AX$476,K$5,FALSE) -> 99.570109 | L11: =VLOOKUP($D11,Résultats!$B$2:$AX$476,L$5,FALSE) -> 97.972638 | ... W11: =VLOOKUP($D11,Résultats!$B$2:$AX$476,W$5,FALSE) -> 122.74066 | X11: =W11-'[1]Cibles THREEME'!$H10 -> 120.08296
C12: Fuel | D12: Q_Mtep_ep_2302_2 | E12: =VLOOKUP($D12,Résultats!$B$2:$AX$476,E$5,FALSE) -> 1.3210313 | F12: =VLOOKUP($D12,Résultats!$B$2:$AX$476,F$5,FALSE) -> 0.75271214 | G12: =VLOOKUP($D12,Résultats!$B$2:$AX$476,G$5,FALSE) -> 0.50197807 | H12: =VLOOKUP($D12,Résultats!$B$2:$AX$476,H$5,FALSE) -> 0.41556582 | I12: =VLOOKUP($D12,Résultats!$B$2:$AX$476,I$5,FALSE) -> 0.32808932 | J12: =VLOOKUP($D12,Résultats!$B$2:$AX$476,J$5,FALSE) -> 0.4331748 | K12: =VLOOKUP($D12,Résultats!$B$2:$AX$476,K$5,FALSE) -> 0.54108924 | L12: =VLOOKUP($D12,Résultats!$B$2:$AX$476,L$5,FALSE) -> 0.65272665 | ... W12: =VLOOKUP($D12,Résultats!$B$2:$AX$476,W$5,FALSE) -> 0.81773955 | X12: =W12-'[1]Cibles THREEME'!$H11 -> 0.81773955
C13: Combined gas | D13: Q_Mtep_ep_2303_2 | E13: =VLOOKUP($D13,Résultats!$B$2:$AX$476,E$5,FALSE) -> 3.5861625 | F13: =VLOOKUP($D13,Résultats!$B$2:$AX$476,F$5,FALSE) -> 4.092452 | G13: =VLOOKUP($D13,Résultats!$B$2:$AX$476,G$5,FALSE) -> 5.1256665 | H13: =VLOOKUP($D13,Résultats!$B$2:$AX$476,H$5,FALSE) -> 5.4541375 | I13: =VLOOKUP($D13,Résultats!$B$2:$AX$476,I$5,FALSE) -> 5.7625902 | J13: =VLOOKUP($D13,Résultats!$B$2:$AX$476,J$5,FALSE) -> 5.4711712 | K13: =VLOOKUP($D13,Résultats!$B$2:$AX$476,K$5,FALSE) -> 5.1912499 | L13: =VLOOKUP($D13,Résultats!$B$2:$AX$476,L$5,FALSE) -> 4.9232194 | ... W13: =VLOOKUP($D13,Résultats!$B$2:$AX$476,W$5,FALSE) -> 6.1678364 | X13: =W13-'[1]Cibles THREEME'!$H12 -> 3.8749158
C14: Coal | D14: Q_Mtep_ep_2304_2 | E14: =VLOOKUP($D14,Résultats!$B$2:$AX$476,E$5,FALSE) -> 5.2639567 | F14: =VLOOKUP($D14,Résultats!$B$2:$AX$476,F$5,FALSE) -> 3.2632691 | G14: =VLOOKUP($D14,Résultats!$B$2:$AX$476,G$5,FALSE) -> 1.8607648 | H14: =VLOOKUP($D14,Résultats!$B$2:$AX$476,H$5,FALSE) -> 1.3833052 | I14: =VLOOKUP($D14,Résultats!$B$2:$AX$476,I$5,FALSE) -> 0.90422959 | J14: =VLOOKUP($D14,Résultats!$B$2:$AX$476,J$5,FALSE) -> 0.85863077 | K14: =VLOOKUP($D14,Résultats!$B$2:$AX$476,K$5,FALSE) -> 0.81476638 | L14: =VLOOKUP($D14,Résultats!$B$2:$AX$476,L$5,FALSE) -> 0.77269918 | ... W14: =VLOOKUP($D14,Résultats!$B$2:$AX$476,W$5,FALSE) -> 0.9680418 | X14: =W14-'[1]Cibles THREEME'!$H13 -> 0.9680418
C15: Wind | D15: Q_Mtep_ep_2305_2 | E15: =VLOOKUP($D15,Résultats!$B$2:$AX$476,E$5,FALSE) -> 0.36837867 | F15: =VLOOKUP($D15,Résultats!$B$2:$AX$476,F$5,FALSE) -> 2.4987876 | G15: =VLOOKUP($D15,Résultats!$B$2:$AX$476,G$5,FALSE) -> 3.2232105 | H15: =VLOOKUP($D15,Résultats!$B$2:$AX$476,H$5,FALSE) -> 3.4581631 | I15: =VLOOKUP($D15,Résultats!$B$2:$AX$476,I$5,FALSE) -> 3.6819429 | J15: =VLOOKUP($D15,Résultats!$B$2:$AX$476,J$5,FALSE) -> 3.8347266 | K15: =VLOOKUP($D15,Résultats!$B$2:$AX$476,K$5,FALSE) -> 3.993968 | L15: =VLOOKUP($D15,Résultats!$B$2:$AX$476,L$5,FALSE) -> 4.1623613 | ... W15: =VLOOKUP($D15,Résultats!$B$2:$AX$476,W$5,FALSE) -> 5.2146293 | X15: =W15-'[1]Cibles THREEME'!$H14 -> -12.558372
C16: Solar | D16: Q_Mtep_ep_2306_2 | E16: =VLOOKUP($D16,Résultats!$B$2:$AX$476,E$5,FALSE) -> 0.0828852 | F16: =VLOOKUP($D16,Résultats!$B$2:$AX$476,F$5,FALSE) -> 1.1012285 | G16: =VLOOKUP($D16,Résultats!$B$2:$AX$476,G$5,FALSE) -> 1.4204854 | H16: =VLOOKUP($D16,Résultats!$B$2:$AX$476,H$5,FALSE) -> 1.5240302 | I16: =VLOOKUP($D16,Résultats!$B$2:$AX$476,I$5,FALSE) -> 1.6226511 | J16: =VLOOKUP($D16,Résultats!$B$2:$AX$476,J$5,FALSE) -> 1.6667567 | K16: =VLOOKUP($D16,Résultats!$B$2:$AX$476,K$5,FALSE) -> 1.7138292 | L16: =VLOOKUP($D16,Résultats!$B$2:$AX$476,L$5,FALSE) -> 1.7648884 | ... W16: =VLOOKUP($D16,Résultats!$B$2:$AX$476,W$5,FALSE) -> 2.2110619 | X16: =W16-'[1]Cibles THREEME'!$H17 -> -8.2790499
C17: Hydraulic | D17: Q_Mtep_ep_2307_2 | E17: =VLOOKUP($D17,Résultats!$B$2:$AX$476,E$5,FALSE) -> 4.6466944 | F17: =VLOOKUP($D17,Résultats!$B$2:$AX$476,F$5,FALSE) -> 3.2599772 | G17: =VLOOKUP($D17,Résultats!$B$2:$AX$476,G$5,FALSE) -> 4.2218789 | H17: =VLOOKUP($D17,Résultats!$B$2:$AX$476,H$5,FALSE) -> 4.5356061 | I17: =VLOOKUP($D17,Résultats!$B$2:$AX$476,I$5,FALSE) -> 4.8354557 | J17: =VLOOKUP($D17,Résultats!$B$2:$AX$476,J$5,FALSE) -> 5.0155576 | K17: =VLOOKUP($D17,Résultats!$B$2:$AX$476,K$5,FALSE) -> 5.204495 | L17: =VLOOKUP($D17,Résultats!$B$2:$AX$476,L$5,FALSE) -> 5.4056572 | ... W17: =VLOOKUP($D17,Résultats!$B$2:$AX$476,W$5,FALSE) -> 6.7722372 | X17: =W17-'[1]Cibles THREEME'!$H18 -> 1.31222
C18: Cogeneration (CHP) | D18: Q_Mtep_ep_2308_2 | E18: =VLOOKUP($D18,Résultats!$B$2:$AX$476,E$5,FALSE) -> 1.4697163 | F18: =VLOOKUP($D18,Résultats!$B$2:$AX$476,F$5,FALSE) -> 3.8767476 | G18: =VLOOKUP($D18,Résultats!$B$2:$AX$476,G$5,FALSE) -> 3.1519448 | H18: =VLOOKUP($D18,Résultats!$B$2:$AX$476,H$5,FALSE) -> 2.8971572 | I18: =VLOOKUP($D18,Résultats!$B$2:$AX$476,I$5,FALSE) -> 2.6342869 | J18: =VLOOKUP($D18,Résultats!$B$2:$AX$476,J$5,FALSE) -> 2.755514 | K18: =VLOOKUP($D18,Résultats!$B$2:$AX$476,K$5,FALSE) -> 2.8821506 | L18: =VLOOKUP($D18,Résultats!$B$2:$AX$476,L$5,FALSE) -> 3.0162084 | ... W18: =VLOOKUP($D18,Résultats!$B$2:$AX$476,W$5,FALSE) -> 3.7787225 | X18: =W18-'[1]Cibles THREEME'!$H19 -> 2.6165955
B19: Gas and heat | C19: Total | E19: =SUM(E20:E25) -> 38.496512 | F19: =SUM(F20:F25) -> 41.225038 | G19: =SUM(G20:G25) -> 40.660219 | H19: =SUM(H20:H25) -> 39.68536 | I19: =SUM(I20:I25) -> 38.963293 | J19: =SUM(J20:J25) -> 38.625633 | K19: =SUM(K20:K25) -> 38.546947 | L19: =SUM(L20:L25) -> 38.601183 | ... W19: =SUM(W20:W25) -> 43.665374
C20: Natural gas | D20: Q_Mtep_ep_2401_2 | E20: =VLOOKUP($D20,Résultats!$B$2:$AX$476,E$5,FALSE) -> 34.75186 | F20: =VLOOKUP($D20,Résultats!$B$2:$AX$476,F$5,FALSE) -> 28.425519 | G20: =VLOOKUP($D20,Résultats!$B$2:$AX$476,G$5,FALSE) -> 27.576233 | H20: =VLOOKUP($D20,Résultats!$B$2:$AX$476,H$5,FALSE) -> 26.788112 | I20: =VLOOKUP($D20,Résultats!$B$2:$AX$476,I$5,FALSE) -> 26.186954 | J20: =VLOOKUP($D20,Résultats!$B$2:$AX$476,J$5,FALSE) -> 24.924833 | K20: =VLOOKUP($D20,Résultats!$B$2:$AX$476,K$5,FALSE) -> 23.814808 | L20: =VLOOKUP($D20,Résultats!$B$2:$AX$476,L$5,FALSE) -> 22.760392 | ... W20: =VLOOKUP($D20,Résultats!$B$2:$AX$476,W$5,FALSE) -> 13.112728 | X20: =W20-'[1]Cibles THREEME'!$H28 -> 7.6739453
C21: Wood | D21: Q_Mtep_ep_2402_2 | E21: =VLOOKUP($D21,Résultats!$B$2:$AX$476,E$5,FALSE) -> 1.5809774 | F21: =VLOOKUP($D21,Résultats!$B$2:$AX$476,F$5,FALSE) -> 7.1876049 | G21: =VLOOKUP($D21,Résultats!$B$2:$AX$476,G$5,FALSE) -> 7.3596289 | H21: =VLOOKUP($D21,Résultats!$B$2:$AX$476,H$5,FALSE) -> 7.2772521 | I21: =VLOOKUP($D21,Résultats!$B$2:$AX$476,I$5,FALSE) -> 7.2403883 | J21: =VLOOKUP($D21,Résultats!$B$2:$AX$476,J$5,FALSE) -> 7.3763363 | K21: =VLOOKUP($D21,Résultats!$B$2:$AX$476,K$5,FALSE) -> 7.5646541 | L21: =VLOOKUP($D21,Résultats!$B$2:$AX$476,L$5,FALSE) -> 7.7841789 | ... W21: =VLOOKUP($D21,Résultats!$B$2:$AX$476,W$5,FALSE) -> 18.153332 | X21: =W21-'[1]Cibles THREEME'!$H29 -> 6.2421462
C22: Biogas | D22: Q_Mtep_ep_2403_2 | E22: =VLOOKUP($D22,Résultats!$B$2:$AX$476,E$5,FALSE) -> 0.47749075 | F22: =VLOOKUP($D22,Résultats!$B$2:$AX$476,F$5,FALSE) -> 0.50978685 | G22: =VLOOKUP($D22,Résultats!$B$2:$AX$476,G$5,FALSE) -> 0.68541131 | H22: =VLOOKUP($D22,Résultats!$B$2:$AX$476,H$5,FALSE) -> 0.72906017 | I22: =VLOOKUP($D22,Résultats!$B$2:$AX$476,I$5,FALSE) -> 0.77523603 | J22: =VLOOKUP($D22,Résultats!$B$2:$AX$476,J$5,FALSE) -> 0.99380942 | K22: =VLOOKUP($D22,Résultats!$B$2:$AX$476,K$5,FALSE) -> 1.2225233 | L22: =VLOOKUP($D22,Résultats!$B$2:$AX$476,L$5,FALSE) -> 1.4614409 | ... W22: =VLOOKUP($D22,Résultats!$B$2:$AX$476,W$5,FALSE) -> 3.0626379 | X22: =W22-'[1]Cibles THREEME'!$H30 -> -9.2629715
C23: Waste incineration | D23: Q_Mtep_ep_2404_2 | E23: =VLOOKUP($D23,Résultats!$B$2:$AX$476,E$5,FALSE) -> 0.73120206 | F23: =VLOOKUP($D23,Résultats!$B$2:$AX$476,F$5,FALSE) -> 0.68467885 | G23: =VLOOKUP($D23,Résultats!$B$2:$AX$476,G$5,FALSE) -> 1.3321764 | H23: =VLOOKUP($D23,Résultats!$B$2:$AX$476,H$5,FALSE) -> 1.4820374 | I23: =VLOOKUP($D23,Résultats!$B$2:$AX$476,I$5,FALSE) -> 1.6182104 | J23: =VLOOKUP($D23,Résultats!$B$2:$AX$476,J$5,FALSE) -> 1.6579565 | K23: =VLOOKUP($D23,Résultats!$B$2:$AX$476,K$5,FALSE) -> 1.7088684 | L23: =VLOOKUP($D23,Résultats!$B$2:$AX$476,L$5,FALSE) -> 1.76629 | ... W23: =VLOOKUP($D23,Résultats!$B$2:$AX$476,W$5,FALSE) -> 2.488775 | X23: =W23-'[1]Cibles THREEME'!$H31 -> 1.6972545
C24: Geothermal | D24: Q_Mtep_ep_2405_2 | E24: =VLOOKUP($D24,Résultats!$B$2:$AX$476,E$5,FALSE) -> 0.47749075 | F24: =VLOOKUP($D24,Résultats!$B$2:$AX$476,F$5,FALSE) -> 0.50978685 | G24: =VLOOKUP($D24,Résultats!$B$2:$AX$476,G$5,FALSE) -> 0.60121007 | H24: =VLOOKUP($D24,Résultats!$B$2:$AX$476,H$5,FALSE) -> 0.61935926 | I24: =VLOOKUP($D24,Résultats!$B$2:$AX$476,I$5,FALSE) -> 0.64039666 | J24: =VLOOKUP($D24,Résultats!$B$2:$AX$476,J$5,FALSE) -> 0.70223998 | K24: =VLOOKUP($D24,Résultats!$B$2:$AX$476,K$5,FALSE) -> 0.76982229 | L24: =VLOOKUP($D24,Résultats!$B$2:$AX$476,L$5,FALSE) -> 0.84184049 | ... W24: =VLOOKUP($D24,Résultats!$B$2:$AX$476,W$5,FALSE) -> 2.1241084 | X24: =W24-'[1]Cibles THREEME'!$H32 -> 1.8661548
C25: Cogeneration (CHP) | D25: Q_Mtep_ep_2406_2 | E25: =VLOOKUP($D25,Résultats!$B$2:$AX$476,E$5,FALSE) -> 0.47749075 | F25: =VLOOKUP($D25,Résultats!$B$2:$AX$476,F$5,FALSE) -> 3.9076614 | G25: =VLOOKUP($D25,Résultats!$B$2:$AX$476,G$5,FALSE) -> 3.1055586 | H25: =VLOOKUP($D25,Résultats!$B$2:$AX$476,H$5,FALSE) -> 2.7895398 | I25: =VLOOKUP($D25,Résultats!$B$2:$AX$476,I$5,FALSE) -> 2.5021069 | J25: =VLOOKUP($D25,Résultats!$B$2:$AX$476,J$5,FALSE) -> 2.9704586 | K25: =VLOOKUP($D25,Résultats!$B$2:$AX$476,K$5,FALSE) -> 3.4662708 | L25: =VLOOKUP($D25,Résultats!$B$2:$AX$476,L$5,FALSE) -> 3.9870406 | ... W25: =VLOOKUP($D25,Résultats!$B$2:$AX$476,W$5,FALSE) -> 4.7237929 | X25: =W25-'[1]Cibles THREEME'!$H33 -> -2.7573704
B26: Coal | D26: Q_Mtep_ep_21_2 | E26: =VLOOKUP($D26,Résultats!$B$2:$AX$476,E$5,FALSE) -> 5.7508898 | F26: =VLOOKUP($D26,Résultats!$B$2:$AX$476,F$5,FALSE) -> 4.3448538 | G26: =VLOOKUP($D26,Résultats!$B$2:$AX$476,G$5,FALSE) -> 2.5374132 | H26: =VLOOKUP($D26,Résultats!$B$2:$AX$476,H$5,FALSE) -> 2.310478 | I26: =VLOOKUP($D26,Résultats!$B$2:$AX$476,I$5,FALSE) -> 2.1012811 | J26: =VLOOKUP($D26,Résultats!$B$2:$AX$476,J$5,FALSE) -> 2.0606107 | K26: =VLOOKUP($D26,Résultats!$B$2:$AX$476,K$5,FALSE) -> 2.0365316 | L26: =VLOOKUP($D26,Résultats!$B$2:$AX$476,L$5,FALSE) -> 2.0297752 | ... W26: =VLOOKUP($D26,Résultats!$B$2:$AX$476,W$5,FALSE) -> 2.169658
B27: Total | E27: =E26+E19+E10+E7 -> 264.96579 | F27: =F26+F19+F10+F7 -> 261.97935 | G27: =G26+G19+G10+G7 -> 242.35974 | H27: =H26+H19+H10+H7 -> 235.10562 | I27: =I26+I19+I10+I7 -> 227.83871 | J27: =J26+J19+J10+J7 -> 225.85558 | K27: =K26+K19+K10+K7 -> 224.245 | L27: =L26+L19+L10+L7 -> 223.18035 | ... W27: =W26+W19+W10+W7 -> 247.56772
A30: Energie finale (Mtep)
A31: =Résultats!B1 -> SNBC3 | Z31: Cf. onglet "G mix elec" | AE31: Cf. onglet "G mix carb" | AJ31: Cf. onglet "G mix gaz"
E32: 2006 | F32: 2015 | G32: 2018 | H32: 2019 | I32: 2020 | J32: 2021 | K32: 2022 | L32: 2023 | M32: 2024 | N32: 2025 | O32: 2026 | P32: 2027 | Q32: 2028 | R32: 2029 | S32: 2030 | T32: 2035 | U32: 2040 | V32: 2045 | W32: 2050 | AA32: 2020 | AB32: 2030 | AC32: 2050 | AF32: 2020 | AG32: 2030 | AH32: 2050 | AK32: 2020 | AL32: 2030 | AM32: 2050
B33: Refined petroleum products | C33: Total | D33: ER_Oil_2 | E33: =SUM(E34:E35) -> 80.666675 | F33: =SUM(F34:F35) -> 71.337322 | G33: =SUM(G34:G35) -> 65.482836 | H33: =SUM(H34:H35) -> 63.804612 | I33: =SUM(I34:I35) -> 62.280175 | J33: =SUM(J34:J35) -> 62.233927 | K33: =SUM(K34:K35) -> 62.037374 | L33: =SUM(L34:L35) -> 61.942539 | ... W33: =SUM(W34:W35) -> 51.453215 | Z33: charbon | AA33: =(I38+I40)/I36 -> 0.0086413758 | AB33: =(S38+S40)/S36 -> 0.010597806 | AC33: =(W38+W40)/W36 -> 0.010597806 | AE33: carburants fossiles | AF33: =I34/I33 -> 0.95161574 | AG33: =S34/S33 -> 0.9442075 | AH33: =W34/W33 -> 0.9442075 | AJ33: gaz naturel | AK33: =I46/(I46+I48) -> 0.97055581 | AL33: =S46/(S46+S48) -> 0.91440265 | AM33: =W46/(W46+W48) -> 0.80715683
C34: Oil | D34: ER_oil_2201_2 | E34: =VLOOKUP($D34,Résultats!$B$2:$AX$476,E$5,FALSE) -> 79.999247 | F34: =VLOOKUP($D34,Résultats!$B$2:$AX$476,F$5,FALSE) -> 68.175816 | G34: =VLOOKUP($D34,Résultats!$B$2:$AX$476,G$5,FALSE) -> 62.4315 | H34: =VLOOKUP($D34,Résultats!$B$2:$AX$476,H$5,FALSE) -> 60.776409 | I34: =VLOOKUP($D34,Résultats!$B$2:$AX$476,I$5,FALSE) -> 59.266794 | J34: =VLOOKUP($D34,Résultats!$B$2:$AX$476,J$5,FALSE) -> 59.064033 | K34: =VLOOKUP($D34,Résultats!$B$2:$AX$476,K$5,FALSE) -> 58.724378 | L34: =VLOOKUP($D34,Résultats!$B$2:$AX$476,L$5,FALSE) -> 58.48661 | ... W34: =VLOOKUP($D34,Résultats!$B$2:$AX$476,W$5,FALSE) -> 48.582512 | X34: =W34-'[1]Cibles THREEME'!$AJ4 -> 38.900409 | Z34: nucléaire | AA34: =I37/I36 -> 0.69408091 | AB34: =S37/S36 -> 0.6681417 | AC34: =W37/W36 -> 0.6681417 | AE34: biocarburants | AF34: =I35/I33 -> 0.048384262 | AG34: =S35/S33 -> 0.055792501 | AH34: =W35/W33 -> 0.055792501 | AJ34: biogaz | AK34: =I48/(I46+I48) -> 0.029444189 | AL34: =S48/(S46+S48) -> 0.085597355 | AM34: =W48/(W46+W48) -> 0.19284317
C35: Biofuels | D35: ER_oil_2202_2 | E35: =VLOOKUP($D35,Résultats!$B$2:$AX$476,E$5,FALSE) -> 0.66742791 | F35: =VLOOKUP($D35,Résultats!$B$2:$AX$476,F$5,FALSE) -> 3.1615056 | G35: =VLOOKUP($D35,Résultats!$B$2:$AX$476,G$5,FALSE) -> 3.0513356 | H35: =VLOOKUP($D35,Résultats!$B$2:$AX$476,H$5,FALSE) -> 3.0282026 | I35: =VLOOKUP($D35,Résultats!$B$2:$AX$476,I$5,FALSE) -> 3.0133803 | J35: =VLOOKUP($D35,Résultats!$B$2:$AX$476,J$5,FALSE) -> 3.169894 | K35: =VLOOKUP($D35,Résultats!$B$2:$AX$476,K$5,FALSE) -> 3.3129965 | L35: =VLOOKUP($D35,Résultats!$B$2:$AX$476,L$5,FALSE) -> 3.4559291 | ... W35: =VLOOKUP($D35,Résultats!$B$2:$AX$476,W$5,FALSE) -> 2.8707035 | X35: =W35-'[1]Cibles THREEME'!$AJ5 -> -0.62613767 | Z35: hydraulique | AA35: =I43/I36 -> 0.10258601 | AB35: =S43/S36 -> 0.11650799 | AC35: =W43/W36 -> 0.11650799 | AE35: Total | AF35: =SUM(AF33:AF34) -> 1 | AG35: =SUM(AG33:AG34) -> 1 | AH35: =SUM(AH33:AH34) -> 1 | AJ35: Total | AK35: =SUM(AK33:AK34) -> 1 | AL35: =SUM(AL33:AL34) -> 1 | AM35: =SUM(AM33:AM34) -> 1
B36: Electric power generation, transmission and distribution | C36: Total | D36: ER_elec_2 | E36: =SUM(E37:E44) -> 37.199219 | F36: =SUM(F37:F44) -> 37.840835 | G36: =SUM(G37:G44) -> 37.343576 | H36: =SUM(H37:H44) -> 36.998343 | I36: =SUM(I37:I44) -> 36.508175 | J36: =SUM(J37:J44) -> 36.754998 | K36: =SUM(K37:K44) -> 37.083243 | L36: =SUM(L37:L44) -> 37.507887 | ... W36: =SUM(W37:W44) -> 48.49326 | Z36: solaire | AA36: =I42/I36 -> 0.036998234 | AB36: =S42/S36 -> 0.04095913 | AC36: =W42/W36 -> 0.04095913
C37: Nuclear | D37: ER_Elec_2301_2 | E37: =VLOOKUP($D37,Résultats!$B$2:$AX$476,E$5,FALSE) -> 29.720829 | F37: =VLOOKUP($D37,Résultats!$B$2:$AX$476,F$5,FALSE) -> 29.366185 | G37: =VLOOKUP($D37,Résultats!$B$2:$AX$476,G$5,FALSE) -> 27.211353 | H37: =VLOOKUP($D37,Résultats!$B$2:$AX$476,H$5,FALSE) -> 26.331809 | I37: =VLOOKUP($D37,Résultats!$B$2:$AX$476,I$5,FALSE) -> 25.339627 | J37: =VLOOKUP($D37,Résultats!$B$2:$AX$476,J$5,FALSE) -> 25.195318 | K37: =VLOOKUP($D37,Résultats!$B$2:$AX$476,K$5,FALSE) -> 25.099698 | L37: =VLOOKUP($D37,Résultats!$B$2:$AX$476,L$5,FALSE) -> 25.060583 | ... W37: =VLOOKUP($D37,Résultats!$B$2:$AX$476,W$5,FALSE) -> 32.400369 | X37: =W37-'[1]Cibles THREEME'!$AJ8 -> 31.77931 | Z37: éolien | AA37: =I41/I36 -> 0.083952357 | AB37: =S41/S36 -> 0.096599141 | AC37: =W41/W36 -> 0.096599141
C38: Fuel | D38: ER_elec_2302_2 | E38: =VLOOKUP($D38,Résultats!$B$2:$AX$476,E$5,FALSE) -> 0.38143142 | F38: =VLOOKUP($D38,Résultats!$B$2:$AX$476,F$5,FALSE) -> 0.23185648 | G38: =VLOOKUP($D38,Résultats!$B$2:$AX$476,G$5,FALSE) -> 0.1593467 | H38: =VLOOKUP($D38,Résultats!$B$2:$AX$476,H$5,FALSE) -> 0.13321387 | I38: =VLOOKUP($D38,Résultats!$B$2:$AX$476,I$5,FALSE) -> 0.10618667 | J38: =VLOOKUP($D38,Résultats!$B$2:$AX$476,J$5,FALSE) -> 0.14036934 | K38: =VLOOKUP($D38,Résultats!$B$2:$AX$476,K$5,FALSE) -> 0.17561825 | L38: =VLOOKUP($D38,Résultats!$B$2:$AX$476,L$5,FALSE) -> 0.21225064 | ... W38: =VLOOKUP($D38,Résultats!$B$2:$AX$476,W$5,FALSE) -> 0.27441497 | X38: =W38-'[1]Cibles THREEME'!$AJ9 -> 0.26441497 | Z38: autres renouvelables | AA38: =(I39+I44)/I36 -> 0.073741107 | AB38: =(S39+S44)/S36 -> 0.067194238 | AC38: =(W39+W44)/W36 -> 0.067194238
C39: Combined gas | D39: ER_Elec_2303_2 | E39: =VLOOKUP($D39,Résultats!$B$2:$AX$476,E$5,FALSE) -> 1.5232737 | F39: =VLOOKUP($D39,Résultats!$B$2:$AX$476,F$5,FALSE) -> 1.5249142 | G39: =VLOOKUP($D39,Résultats!$B$2:$AX$476,G$5,FALSE) -> 1.9634662 | H39: =VLOOKUP($D39,Résultats!$B$2:$AX$476,H$5,FALSE) -> 2.1081164 | I39: =VLOOKUP($D39,Résultats!$B$2:$AX$476,I$5,FALSE) -> 2.2469677 | J39: =VLOOKUP($D39,Résultats!$B$2:$AX$476,J$5,FALSE) -> 2.1597456 | K39: =VLOOKUP($D39,Résultats!$B$2:$AX$476,K$5,FALSE) -> 2.0749964 | L39: =VLOOKUP($D39,Résultats!$B$2:$AX$476,L$5,FALSE) -> 1.9928045 | ... W39: =VLOOKUP($D39,Résultats!$B$2:$AX$476,W$5,FALSE) -> 2.5764605 | X39: =W39-'[1]Cibles THREEME'!$AJ10 -> 1.4804738 | Z39: Total | AA39: =SUM(AA33:AA38) -> 1 | AB39: =SUM(AB33:AB38) -> 1 | AC39: =SUM(AC33:AC38) -> 1
C40: Coal | D40: ER_elec_2304_2 | E40: =VLOOKUP($D40,Résultats!$B$2:$AX$476,E$5,FALSE) -> 1.5199023 | F40: =VLOOKUP($D40,Résultats!$B$2:$AX$476,F$5,FALSE) -> 0.71481388 | G40: =VLOOKUP($D40,Résultats!$B$2:$AX$476,G$5,FALSE) -> 0.42146316 | H40: =VLOOKUP($D40,Résultats!$B$2:$AX$476,H$5,FALSE) -> 0.31676052 | I40: =VLOOKUP($D40,Résultats!$B$2:$AX$476,I$5,FALSE) -> 0.20929419 | J40: =VLOOKUP($D40,Résultats!$B$2:$AX$476,J$5,FALSE) -> 0.20105002 | K40: =VLOOKUP($D40,Résultats!$B$2:$AX$476,K$5,FALSE) -> 0.19303322 | L40: =VLOOKUP($D40,Résultats!$B$2:$AX$476,L$5,FALSE) -> 0.18525067 | ... W40: =VLOOKUP($D40,Résultats!$B$2:$AX$476,W$5,FALSE) -> 0.2395072 | X40: =W40-'[1]Cibles THREEME'!$AJ11 -> 0.2295072
C41: Wind | D41: ER_Elec_2305_2 | E41: =VLOOKUP($D41,Résultats!$B$2:$AX$476,E$5,FALSE) -> 0.30706825 | F41: =VLOOKUP($D41,Résultats!$B$2:$AX$476,F$5,FALSE) -> 2.0225632 | G41: =VLOOKUP($D41,Résultats!$B$2:$AX$476,G$5,FALSE) -> 2.6543005 | H41: =VLOOKUP($D41,Résultats!$B$2:$AX$476,H$5,FALSE) -> 2.8634673 | I41: =VLOOKUP($D41,Résultats!$B$2:$AX$476,I$5,FALSE) -> 3.0649473 | J41: =VLOOKUP($D41,Résultats!$B$2:$AX$476,J$5,FALSE) -> 3.2395533 | K41: =VLOOKUP($D41,Résultats!$B$2:$AX$476,K$5,FALSE) -> 3.4248087 | L41: =VLOOKUP($D41,Résultats!$B$2:$AX$476,L$5,FALSE) -> 3.6232296 | ... W41: =VLOOKUP($D41,Résultats!$B$2:$AX$476,W$5,FALSE) -> 4.6844073 | X41: =W41-'[1]Cibles THREEME'!$AJ12 -> -7.9011734
C42: Solar | D42: ER_elec_2306_2 | E42: =VLOOKUP($D42,Résultats!$B$2:$AX$476,E$5,FALSE) -> 0.069090357 | F42: =VLOOKUP($D42,Résultats!$B$2:$AX$476,F$5,FALSE) -> 0.89135396 | G42: =VLOOKUP($D42,Résultats!$B$2:$AX$476,G$5,FALSE) -> 1.1697638 | H42: =VLOOKUP($D42,Résultats!$B$2:$AX$476,H$5,FALSE) -> 1.2619447 | I42: =VLOOKUP($D42,Résultats!$B$2:$AX$476,I$5,FALSE) -> 1.350738 | J42: =VLOOKUP($D42,Résultats!$B$2:$AX$476,J$5,FALSE) -> 1.4080658 | K42: =VLOOKUP($D42,Résultats!$B$2:$AX$476,K$5,FALSE) -> 1.4696004 | L42: =VLOOKUP($D42,Résultats!$B$2:$AX$476,L$5,FALSE) -> 1.5362904 | ... W42: =VLOOKUP($D42,Résultats!$B$2:$AX$476,W$5,FALSE) -> 1.9862418 | X42: =W42-'[1]Cibles THREEME'!$AJ13 -> -5.4421126 | Z42: Cf. onglet "G mix energie"
C43: Hydraulic | D43: ER_Elec_2307_2 | E43: =VLOOKUP($D43,Résultats!$B$2:$AX$476,E$5,FALSE) -> 3.4538832 | F43: =VLOOKUP($D43,Résultats!$B$2:$AX$476,F$5,FALSE) -> 2.4714814 | G43: =VLOOKUP($D43,Résultats!$B$2:$AX$476,G$5,FALSE) -> 3.243436 | H43: =VLOOKUP($D43,Résultats!$B$2:$AX$476,H$5,FALSE) -> 3.4990285 | I43: =VLOOKUP($D43,Résultats!$B$2:$AX$476,I$5,FALSE) -> 3.7452281 | J43: =VLOOKUP($D43,Résultats!$B$2:$AX$476,J$5,FALSE) -> 3.9399496 | K43: =VLOOKUP($D43,Résultats!$B$2:$AX$476,K$5,FALSE) -> 4.1472224 | L43: =VLOOKUP($D43,Résultats!$B$2:$AX$476,L$5,FALSE) -> 4.3699683 | ... W43: =VLOOKUP($D43,Résultats!$B$2:$AX$476,W$5,FALSE) -> 5.6498521 | X43: =W43-'[1]Cibles THREEME'!$AJ14 -> 1.7834545 | AA43: 2020 | AB43: 2030 | AC43: 2050
...

Sheet T energie usages
A1: Energie par usage
A3: Energie finale (Mtep)
A4: =Résultats!B1 -> SNBC3
C7: Consos résultats de ThreeME | N7: Consos cibles d'Enerdata | U7: Consos résultats de ThreeME
C8: Hors bois domestique non marchand, avec consommation à double usage | N8: Hors bois domestique auto produit (8MTEP entre 2015 et 2030 4 Mtep en 2050) | U8: Hors bois domestique non marchand, avec consommation à double usage
C10: 2015 | H10: coal | I10: fuel and biofuel | J10: elec | K10: gas biogas biomass | L10: Total | N10: 2015 | O10: coal | P10: fuel and biofuel | Q10: elec | R10: gas biogas biomass | S10: Total | T10: Hors chal env PAC | U10: 2015 | Z10: coal | AA10: fuel and biofuel | AB10: elec | AC10: gas biogas biomass | AD10: Total
C11: Transport | H11: =SUM(H12:H13) -> 0 | I11: =SUM(I12:I13) -> 43.145689 | J11: =SUM(J12:J13) -> 1.2869702 | K11: =SUM(K12:K13) -> 0.24534333 | L11: =SUM(H11:K11) -> 44.678003 | N11: Transport | O11: ='[2]Bilan 2015'!$X$46 -> 0 | P11: =SUM('[2]Bilan 2015'!$X$41:$X$43) -> 42.748697 | Q11: ='[2]Bilan 2015'!$X$13 -> 0.94471195 | R11: =('[2]Bilan 2015'!$X$22+'[2]Bilan 2015'!$X$30+SUM('[2]Bilan 2015'!$X$36:$X$40)+SUM('[2]Bilan 2015'!$X$44:$X$45)+'[2]Bilan 2015'!$X$47) -> 0.072674067 | S11: =SUM(O11:R11) -> 43.766083 | T11: =S11 -> 43.766083 | U11: Transport | Z11: 0 | AA11: 43.15955 | AB11: 1.2867468 | AC11: 0.24934661 | AD11: 44.695644
C12: Personal vehicles | D12: ER_TRANS_PRIVATE_coal_2 | E12: ER_TRANS_PRIVATE_oil_2 | F12: ER_TRANS_PRIVATE_elec_2 | G12: ER_TRANS_PRIVATE_gas_2 | H12: =VLOOKUP(D12,Résultats!$B$2:$AX$476,'T energie vecteurs'!F5,FALSE) -> 0 | I12: =VLOOKUP(E12,Résultats!$B$2:$AX$476,'T energie vecteurs'!F5,FALSE) -> 24.200254 | J12: =VLOOKUP(F12,Résultats!$B$2:$AX$476,'T energie vecteurs'!F5,FALSE) -> 0.01816242 | K12: =VLOOKUP(G12,Résultats!$B$2:$AX$476,'T energie vecteurs'!F5,FALSE) -> 1.0589055e-05 | L12: =SUM(H12:K12) -> 24.218427 | N12: Personal vehicles | U12: Personal vehicles | V12: ER_TRANS_PRIVATE_coal_2 | W12: ER_TRANS_PRIVATE_oil_2 | X12: ER_TRANS_PRIVATE_elec_2 | Y12: ER_TRANS_PRIVATE_gas_2 | Z12: 0 | AA12: 24.198348 | AB12: 0.01818778 | AC12: 1.0630953e-05 | AD12: 24.216546
C13: Public and freight transport | D13: ER_TRANS_PUBLIC_coal_2 | E13: ER_TRANS_PUBLIC_oil_2 | F13: ER_TRANS_PUBLIC_elec_2 | G13: ER_TRANS_PUBLIC_gas_2 | H13: =VLOOKUP(D13,Résultats!$B$2:$AX$476,'T energie vecteurs'!F5,FALSE) -> 0 | I13: =VLOOKUP(E13,Résultats!$B$2:$AX$476,'T energie vecteurs'!F5,FALSE) -> 18.945435 | J13: =VLOOKUP(F13,Résultats!$B$2:$AX$476,'T energie vecteurs'!F5,FALSE) -> 1.2688078 | K13: =VLOOKUP(G13,Résultats!$B$2:$AX$476,'T energie vecteurs'!F5,FALSE) -> 0.24533274 | L13: =SUM(H13:K13) -> 20.459576 | N13: Public and freight transport | U13: Public and freight transport | V13: ER_TRANS_PUBLIC_coal_2 | W13: ER_TRANS_PUBLIC_oil_2 | X13: ER_TRANS_PUBLIC_elec_2 | Y13: ER_TRANS_PUBLIC_gas_2 | Z13: 0 | AA13: 18.961203 | AB13: 1.268559 | AC13: 0.24933598 | AD13: 20.479098
C14: Residential | D14: ER_RESIDENTIAL_coal_2 | E14: ER_RESIDENTIAL_oil_2 | F14: ER_RESIDENTIAL_elec_2 | G14: ER_RESIDENTIAL_gas_2 | H14: =VLOOKUP(D14,Résultats!$B$2:$AX$476,'T energie vecteurs'!F5,FALSE) -> 0.33122045 | I14: =VLOOKUP(E14,Résultats!$B$2:$AX$476,'T energie vecteurs'!F5,FALSE) -> 7.2440592 | J14: =VLOOKUP(F14,Résultats!$B$2:$AX$476,'T energie vecteurs'!F5,FALSE) -> 13.732729 | K14: =VLOOKUP(G14,Résultats!$B$2:$AX$476,'T energie vecteurs'!F5,FALSE)+2 -> 19.71798 | L14: =SUM(H14:K14) -> 41.025989 | N14: Residential | O14: ='[2]Bilan 2015'!$V$46 -> 0.036764197 | P14: =SUM('[2]Bilan 2015'!$V$41:$V$43) -> 6.6752954 | Q14: ='[2]Bilan 2015'!$V$13 -> 13.620367 | R14: =('[2]Bilan 2015'!$V$22+'[2]Bilan 2015'!$V$30+SUM('[2]Bilan 2015'!$V$36:$V$40)+SUM('[2]Bilan 2015'!$V$44:$V$45)+'[2]Bilan 2015'!$V$47) -> 21.832864 | S14: =SUM(O14:R14) -> 42.16529 | T14: =S14-'[2]Bilan 2015'!$V$40 -> 39.648469 | U14: Residential | V14: ER_RESIDENTIAL_coal_2 | W14: ER_RESIDENTIAL_oil_2 | X14: ER_RESIDENTIAL_elec_2 | Y14: ER_RESIDENTIAL_gas_2 | Z14: 0.33135186 | AA14: 7.2415499 | AB14: 13.750647 | AC14: 19.70225 | AD14: 41.025798
C15: Service | D15: ER_TERTIARY_coal_2 | E15: ER_TERTIARY_oil_2 | F15: ER_TERTIARY_elec_2 | G15: ER_TERTIARY_gas_2 | H15: =VLOOKUP(D15,Résultats!$B$2:$AX$476,'T energie vecteurs'!F5,FALSE) -> 0 | I15: =VLOOKUP(E15,Résultats!$B$2:$AX$476,'T energie vecteurs'!F5,FALSE) -> 3.7835587 | J15: =VLOOKUP(F15,Résultats!$B$2:$AX$476,'T energie vecteurs'!F5,FALSE) -> 11.548634 | K15: =VLOOKUP(G15,Résultats!$B$2:$AX$476,'T energie vecteurs'!F5,FALSE) -> 9.1338787 | L15: =SUM(H15:K15) -> 24.466072 | N15: Service | O15: ='[2]Bilan 2015'!$W$46 -> 0.043073392 | P15: =SUM('[2]Bilan 2015'!$W$41:$W$43) -> 3.0154656 | Q15: ='[2]Bilan 2015'!$W$13 -> 12.701365 | R15: =('[2]Bilan 2015'!$W$22+'[2]Bilan 2015'!$W$30+SUM('[2]Bilan 2015'!$W$36:$W$40)+SUM('[2]Bilan 2015'!$W$44:$W$45)+'[2]Bilan 2015'!$W$47) -> 8.7461122 | S15: =SUM(O15:R15) -> 24.506017 | T15: =S15-'[2]Bilan 2015'!$W$40 -> 24.06751 | U15: Service | V15: ER_TERTIARY_coal_2 | W15: ER_TERTIARY_oil_2 | X15: ER_TERTIARY_elec_2 | Y15: ER_TERTIARY_gas_2 | Z15: 0 | AA15: 3.7813464 | AB15: 11.575224 | AC15: 9.1357403 | AD15: 24.492311
C16: Industry | H16: =SUM(H17:H18) -> 5.0121731 | I16: =SUM(I17:I18) -> 16.5824 | J16: =SUM(J17:J18) -> 10.953796 | K16: =SUM(K17:K18) -> 14.31371 | L16: =SUM(H16:K16) -> 46.862079 | N16: Industry | O16: =O17+O18 -> 4.2636281 | P16: =P17+P18 -> 14.865721 | Q16: =Q17+Q18 -> 10.069552 | R16: =R17+R18 -> 13.7564 | S16: =SUM(O16:R16) -> 42.955301 | T16: =S16 -> 42.955301 | U16: Industry | Z16: 5.0051719 | AA16: 16.790367 | AB16: 10.963479 | AC16: 14.329332 | AD16: 47.08835
C17: Industry | D17: ER_INDUS_coal_2 | E17: ER_INDUS_oil_2 | F17: ER_INDUS_elec_2 | G17: ER_INDUS_gas_2 | H17: =VLOOKUP(D17,Résultats!$B$2:$AX$476,'T energie vecteurs'!F5,FALSE) -> 4.0136333 | I17: =VLOOKUP(E17,Résultats!$B$2:$AX$476,'T energie vecteurs'!F5,FALSE) -> 14.689397 | J17: =VLOOKUP(F17,Résultats!$B$2:$AX$476,'T energie vecteurs'!F5,FALSE) -> 10.953796 | K17: =VLOOKUP(G17,Résultats!$B$2:$AX$476,'T energie vecteurs'!F5,FALSE) -> 12.544766 | L17: =SUM(H17:K17) -> 42.201592 | N17: Industry energetic uses | O17: ='[2]Bilan 2015'!$U$46 -> 1.0493093 | P17: =SUM('[2]Bilan 2015'!$U$41:$U$43) -> 2.4127207 | Q17: ='[2]Bilan 2015'!$U$13 -> 10.069552 | R17: =('[2]Bilan 2015'!$U$22+'[2]Bilan 2015'!$U$30+SUM('[2]Bilan 2015'!$U$36:$U$40)+SUM('[2]Bilan 2015'!$U$44:$U$45)+'[2]Bilan 2015'!$U$47) -> 12.654814 | S17: =SUM(O17:R17) -> 26.186396 | U17: Industry | V17: ER_INDUS_coal_2 | W17: ER_INDUS_oil_2 | X17: ER_INDUS_elec_2 | Y17: ER_INDUS_gas_2 | Z17: 4.006287 | AA17: 14.897875 | AB17: 10.963479 | AC17: 12.561498 | AD17: 42.429138
C18: Industry non energetic uses | D18: Q_Mtep_indus_21_2 | E18: Q_Mtep_indus_22_2 | F18: Q_Mtep_indus_23_2 | G18: Q_Mtep_indus_24_2 | H18: =VLOOKUP(D18,Résultats!$B$2:$AX$476,'T energie vecteurs'!F5,FALSE) -> 0.99853977 | I18: =VLOOKUP(E18,Résultats!$B$2:$AX$476,'T energie vecteurs'!F5,FALSE) -> 1.8930036 | J18: =VLOOKUP(F18,Résultats!$B$2:$AX$476,'T energie vecteurs'!F5,FALSE) -> 0 | K18: =VLOOKUP(G18,Résultats!$B$2:$AX$476,'T energie vecteurs'!F5,FALSE) -> 1.7689436 | L18: =SUM(H18:K18) -> 4.660487 | N18: Industry non energetic uses | O18: ='[2]Bilan 2015'!$E$52 -> 3.2143188 | P18: =('[2]Bilan 2015'!$E$54+'[2]Bilan 2015'!$E$56) -> 12.453 | Q18: 0 | R18: =('[2]Bilan 2015'!$E$53+'[2]Bilan 2015'!$E$55+'[2]Bilan 2015'!$E$57) -> 1.1015862 | S18: =SUM(O18:R18) -> 16.768905 | U18: Industry non energetic uses | V18: Q_Mtep_indus_21_2 | W18: Q_Mtep_indus_22_2 | X18: Q_Mtep_indus_23_2 | Y18: Q_Mtep_indus_24_2 | Z18: 0.99888499 | AA18: 1.8924925 | AB18: 0 | AC18: 1.7678344 | AD18: 4.6592119
C19: Agriculture | D19: ER_AGRICULTURE_coal_2 | E19: ER_AGRICULTURE_oil_2 | F19: ER_AGRICULTURE_elec_2 | G19: ER_AGRICULTURE_gas_2 | H19: =VLOOKUP(D19,Résultats!$B$2:$AX$476,'T energie vecteurs'!F5,FALSE) -> 0 | I19: =VLOOKUP(E19,Résultats!$B$2:$AX$476,'T energie vecteurs'!F5,FALSE) -> 2.4746179 | J19: =VLOOKUP(F19,Résultats!$B$2:$AX$476,'T energie vecteurs'!F5,FALSE) -> 0.31870576 | K19: =VLOOKUP(G19,Résultats!$B$2:$AX$476,'T energie vecteurs'!F5,FALSE) -> 0.39369217 | L19: =SUM(H19:K19) -> 3.1870158 | N19: Agriculture | O19: ='[2]Bilan 2015'!$T$46 -> 0.0022137193 | P19: =SUM('[2]Bilan 2015'!$T$41:$T$43) -> 3.4936668 | Q19: ='[2]Bilan 2015'!$T$13 -> 0.74651763 | R19: =('[2]Bilan 2015'!$T$22+'[2]Bilan 2015'!$T$30+SUM('[2]Bilan 2015'!$T$36:$T$40)+SUM('[2]Bilan 2015'!$T$44:$T$45)+'[2]Bilan 2015'!$T$47) -> 0.24365267 | S19: =SUM(O19:R19) -> 4.4860508 | T19: =S19 -> 4.4860508 | U19: Agriculture | V19: ER_AGRICULTURE_coal_2 | W19: ER_AGRICULTURE_oil_2 | X19: ER_AGRICULTURE_elec_2 | Y19: ER_AGRICULTURE_gas_2 | Z19: 0 | AA19: 2.4785695 | AB19: 0.31965679 | AC19: 0.39436076 | AD19: 3.192587
C20: Total Final Mtep | H20: =SUM(H11,H14:H16,H19) -> 5.3433935 | I20: =SUM(I11,I14:I16,I19) -> 73.230325 | J20: =SUM(J11,J14:J16,J19) -> 37.840835 | K20: =SUM(K11,K14:K16,K19) -> 43.804604 | L20: =SUM(H20:K20) -> 160.21916 | N20: Total Final Mtep | O20: =O11+O14+O15+O16+O19 -> 4.3456794 | P20: =P11+P14+P15+P16+P19 -> 70.798845 | Q20: =Q11+Q14+Q15+Q16+Q19 -> 38.082514 | R20: =R11+R14+R15+R16+R19 -> 44.651703 | S20: =SUM(O20:R20) -> 157.87874 | T20: =SUM(T11:T19) -> 154.92341 | U20: Total Final Mtep | Z20: 5.3365238 | AA20: 73.451384 | AB20: 37.895753 | AC20: 43.81103 | AD20: 160.49469
L21: =L11+L14+L15+L16+L19 -> 160.21916 | AD21: 160.49469
C23: 2020 | H23: coal | I23: fuel and biofuel | J23: elec | K23: gas biogas biomass | L23: Total | N23: 2020 | O23: coal | P23: fuel and biofuel | Q23: elec | R23: gas biogas biomass | S23: Total | T23: Hors chal env PAC | U23: 2020 | Z23: coal | AA23: fuel and biofuel | AB23: elec | AC23: gas biogas biomass | AD23: Total
C24: Transport | H24: =SUM(H25:H26) -> 0 | I24: =SUM(I25:I26) -> 41.563023 | J24: =SUM(J25:J26) -> 1.5156367 | K24: =SUM(K25:K26) -> 0.27412866 | L24: =SUM(H24:K24) -> 43.352788 | N24: Transport | O24: ='[2]Bilan 2020'!$X$46/11.63 -> 0 | P24: =SUM('[2]Bilan 2020'!$X$41:$X$43)/11.63 -> 35.668036 | Q24: ='[2]Bilan 2020'!$X$13/11.63 -> 0.71687008 | R24: =('[2]Bilan 2020'!$X$22+'[2]Bilan 2020'!$X$30+SUM('[2]Bilan 2020'!$X$36:$X$40)+SUM('[2]Bilan 2020'!$X$44:$X$45)+'[2]Bilan 2020'!$X$47)/11.63 -> 0.19326866 | S24: =SUM(O24:R24) -> 36.578175 | T24: =S24 -> 36.578175 | U24: Transport | Z24: 0 | AA24: 41.602539 | AB24: 1.5063126 | AC24: 0.27860242 | AD24: 43.387454
C25: Personal vehicles | D25: ER_TRANS_PRIVATE_coal_2 | E25: ER_TRANS_PRIVATE_oil_2 | F25: ER_TRANS_PRIVATE_elec_2 | G25: ER_TRANS_PRIVATE_gas_2 | H25: =VLOOKUP(D25,Résultats!$B$2:$AX$476,'T energie vecteurs'!I5,FALSE) -> 0 | I25: =VLOOKUP(E25,Résultats!$B$2:$AX$476,'T energie vecteurs'!I5,FALSE) -> 23.247082 | J25: =VLOOKUP(F25,Résultats!$B$2:$AX$476,'T energie vecteurs'!I5,FALSE) -> 0.07237004 | K25: =VLOOKUP(G77,Résultats!$B$2:$AX$476,'T energie vecteurs'!I5,FALSE) -> 1.4664156e-05 | L25: =SUM(H25:K25) -> 23.319467 | N25: Personal vehicles | U25: Personal vehicles | V25: ER_TRANS_PRIVATE_coal_2 | W25: ER_TRANS_PRIVATE_oil_2 | X25: ER_TRANS_PRIVATE_elec_2 | Y25: ER_TRANS_PRIVATE_gas_2 | Z25: 0 | AA25: 23.244407 | AB25: 0.072506889 | AC25: 1.4761104e-05 | AD25: 23.316929
C26: Public and freight transport | D26: ER_TRANS_PUBLIC_coal_2 | E26: ER_TRANS_PUBLIC_oil_2 | F26: ER_TRANS_PUBLIC_elec_2 | G26: ER_TRANS_PUBLIC_gas_2 | H26: =VLOOKUP(D26,Résultats!$B$2:$AX$476,'T energie vecteurs'!I5,FALSE) -> 0 | I26: =VLOOKUP(E26,Résultats!$B$2:$AX$476,'T energie vecteurs'!I5,FALSE) -> 18.315941 | J26: =VLOOKUP(F26,Résultats!$B$2:$AX$476,'T energie vecteurs'!I5,FALSE) -> 1.4432666 | K26: =VLOOKUP(G26,Résultats!$B$2:$AX$476,'T energie vecteurs'!I5,FALSE) -> 0.27411399 | L26: =SUM(H26:K26) -> 20.033321 | N26: Public and freight transport | U26: Public and freight transport | V26: ER_TRANS_PUBLIC_coal_2 | W26: ER_TRANS_PUBLIC_oil_2 | X26: ER_TRANS_PUBLIC_elec_2 | Y26: ER_TRANS_PUBLIC_gas_2 | Z26: 0 | AA26: 18.358132 | AB26: 1.4338057 | AC26: 0.27858766 | AD26: 20.070525
C27: Residential | D27: ER_RESIDENTIAL_coal_2 | E27: ER_RESIDENTIAL_oil_2 | F27: ER_RESIDENTIAL_elec_2 | G27: ER_RESIDENTIAL_gas_2 | H27: =VLOOKUP(D27,Résultats!$B$2:$AX$476,'T energie vecteurs'!I5,FALSE) -> 0.31808457 | I27: =VLOOKUP(E27,Résultats!$B$2:$AX$476,'T energie vecteurs'!I5,FALSE) -> 6.4323583 | J27: =VLOOKUP(F27,Résultats!$B$2:$AX$476,'T energie vecteurs'!I5,FALSE) -> 14.456508 | K27: =VLOOKUP(G27,Résultats!$B$2:$AX$476,'T energie vecteurs'!I5,FALSE)+2 -> 19.097676 | L27: =SUM(H27:K27) -> 40.304627 | N27: Residential | O27: ='[2]Bilan 2020'!$V$46/11.63 -> 0.020700735 | P27: =SUM('[2]Bilan 2020'!$V$41:$V$43)/11.63 -> 4.2874728 | Q27: ='[2]Bilan 2020'!$V$13/11.63 -> 13.618732 | R27: =('[2]Bilan 2020'!$V$22+'[2]Bilan 2020'!$V$30+SUM('[2]Bilan 2020'!$V$36:$V$40)+SUM('[2]Bilan 2020'!$V$44:$V$45)+'[2]Bilan 2020'!$V$47)/11.63 -> 20.40841 | S27: =SUM(O27:R27) -> 38.335315 | T27: =S27-'[2]Bilan 2020'!$V$40/11.63 -> 35.977053 | U27: Residential | V27: ER_RESIDENTIAL_coal_2 | W27: ER_RESIDENTIAL_oil_2 | X27: ER_RESIDENTIAL_elec_2 | Y27: ER_RESIDENTIAL_gas_2 | Z27: 0.31862762 | AA27: 6.4568025 | AB27: 14.438674 | AC27: 19.172349 | AD27: 40.386453
C28: Service | D28: ER_TERTIARY_coal_2 | E28: ER_TERTIARY_oil_2 | F28: ER_TERTIARY_elec_2 | G28: ER_TERTIARY_gas_2 | H28: =VLOOKUP(D28,Résultats!$B$2:$AX$476,'T energie vecteurs'!I5,FALSE) -> 0 | I28: =VLOOKUP(E28,Résultats!$B$2:$AX$476,'T energie vecteurs'!I5,FALSE) -> 2.7287138 | J28: =VLOOKUP(F28,Résultats!$B$2:$AX$476,'T energie vecteurs'!I5,FALSE) -> 11.176971 | K28: =VLOOKUP(G28,Résultats!$B$2:$AX$476,'T energie vecteurs'!I5,FALSE) -> 7.8117768 | L28: =SUM(H28:K28) -> 21.717462 | N28: Service | O28: =('[2]Bilan 2020'!$W$46)/11.63 -> 0.030546421 | P28: =SUM('[2]Bilan 2020'!$W$41:$W$43)/11.63 -> 2.7068356 | Q28: =('[2]Bilan 2020'!$W$13)/11.63 -> 10.724851 | R28: =('[2]Bilan 2020'!$W$22+'[2]Bilan 2020'!$W$30+SUM('[2]Bilan 2020'!$W$36:$W$40)+SUM('[2]Bilan 2020'!$W$44:$W$45)+'[2]Bilan 2020'!$W$47)/11.63 -> 7.1906336 | S28: =SUM(O28:R28) -> 20.652866 | T28: =S28-'[2]Bilan 2020'!$W$40/11.63 -> 20.267161 | U28: Service | V28: ER_TERTIARY_coal_2 | W28: ER_TERTIARY_oil_2 | X28: ER_TERTIARY_elec_2 | Y28: ER_TERTIARY_gas_2 | Z28: 0 | AA28: 2.7306023 | AB28: 11.12796 | AC28: 7.8713222 | AD28: 21.729884
C29: Industry | H29: =SUM(H30:H31) -> 2.6467544 | I29: =SUM(I30:I31) -> 11.04789 | J29: =SUM(J30:J31) -> 9.0460201 | K29: =SUM(K30:K31) -> 14.700287 | L29: =SUM(H29:K29) -> 37.440951 | N29: Industry | O29: =O30+O31 -> 3.1626378 | P29: =P30+P31 -> 13.919974 | Q29: =Q30+Q31 -> 9.0413235 | R29: =R30+R31 -> 14.312071 | S29: =SUM(O29:R29) -> 40.436006 | T29: =S29 -> 40.436006 | U29: Industry | Z29: 2.6480606 | AA29: 11.228938 | AB29: 8.9819417 | AC29: 14.814342 | AD29: 37.673282
C30: Industry | D30: ER_INDUS_coal_2 | E30: ER_INDUS_oil_2 | F30: ER_INDUS_elec_2 | G30: ER_INDUS_gas_2 | H30: =VLOOKUP(D30,Résultats!$B$2:$AX$476,'T energie vecteurs'!I5,FALSE) -> 1.7831965 | I30: =VLOOKUP(E30,Résultats!$B$2:$AX$476,'T energie vecteurs'!I5,FALSE) -> 9.1710327 | J30: =VLOOKUP(F30,Résultats!$B$2:$AX$476,'T energie vecteurs'!I5,FALSE) -> 9.0460201 | K30: =VLOOKUP(G30,Résultats!$B$2:$AX$476,'T energie vecteurs'!I5,FALSE) -> 12.596217 | L30: =SUM(H30:K30) -> 32.596467 | N30: Industry energetic uses | O30: ='[2]Bilan 2020'!$U$46/11.63 -> 0.77267988 | P30: =SUM('[2]Bilan 2020'!$U$41:$U$43)/11.63 -> 2.7003588 | Q30: ='[2]Bilan 2020'!$U$13/11.63 -> 9.0413235 | R30: =('[2]Bilan 2020'!$U$22+'[2]Bilan 2020'!$U$30+SUM('[2]Bilan 2020'!$U$36:$U$40)+SUM('[2]Bilan 2020'!$U$44:$U$45)+'[2]Bilan 2020'!$U$47)/11.63 -> 13.277855 | S30: =SUM(O30:R30) -> 25.792217 | U30: Industry | V30: ER_INDUS_coal_2 | W30: ER_INDUS_oil_2 | X30: ER_INDUS_elec_2 | Y30: ER_INDUS_gas_2 | Z30: 1.7843253 | AA30: 9.352929 | AB30: 8.9819417 | AC30: 12.713318 | AD30: 32.832514
C31: Industry non energetic uses | D31: Q_Mtep_indus_21_2 | E31: Q_Mtep_indus_22_2 | F31: Q_Mtep_indus_23_2 | G31: Q_Mtep_indus_24_2 | H31: =VLOOKUP(D31,Résultats!$B$2:$AX$476,'T energie vecteurs'!I5,FALSE) -> 0.86355782 | I31: =VLOOKUP(E31,Résultats!$B$2:$AX$476,'T energie vecteurs'!I5,FALSE) -> 1.8768568 | J31: =VLOOKUP(F31,Résultats!$B$2:$AX$476,'T energie vecteurs'!I5,FALSE) -> 0 | K31: =VLOOKUP(G31,Résultats!$B$2:$AX$476,'T energie vecteurs'!I5,FALSE) -> 2.1040699 | L31: =SUM(H31:K31) -> 4.8444846 | N31: Industry non energetic uses | O31: ='[2]Bilan 2020'!$E$52/11.63 -> 2.3899579 | P31: =('[2]Bilan 2020'!$E$54+'[2]Bilan 2020'!$E$56)/11.63 -> 11.219615 | Q31: 0 | R31: =('[2]Bilan 2020'!$E$53+'[2]Bilan 2020'!$E$55+'[2]Bilan 2020'!$E$57)/11.63 -> 1.0342164 | S31: =SUM(O31:R31) -> 14.643789 | U31: Industry non energetic uses | V31: Q_Mtep_indus_21_2 | W31: Q_Mtep_indus_22_2 | X31: Q_Mtep_indus_23_2 | Y31: Q_Mtep_indus_24_2 | Z31: 0.86373539 | AA31: 1.8760089 | AB31: 0 | AC31: 2.1010242 | AD31: 4.8407685
C32: Agriculture | D32: ER_AGRICULTURE_coal_2 | E32: ER_AGRICULTURE_oil_2 | F32: ER_AGRICULTURE_elec_2 | G32: ER_AGRICULTURE_gas_2 | H32: =VLOOKUP(D32,Résultats!$B$2:$AX$476,'T energie vecteurs'!I5,FALSE) -> 0 | I32: =VLOOKUP(E32,Résultats!$B$2:$AX$476,'T energie vecteurs'!I5,FALSE) -> 2.3850467 | J32: =VLOOKUP(F32,Résultats!$B$2:$AX$476,'T energie vecteurs'!I5,FALSE) -> 0.31303899 | K32: =VLOOKUP(G32,Résultats!$B$2:$AX$476,'T energie vecteurs'!I5,FALSE) -> 0.36755918 | L32: =SUM(H32:K32) -> 3.0656449 | N32: Agriculture | O32: ='[2]Bilan 2020'!$T$46/11.63 -> 0.001321701 | P32: =SUM('[2]Bilan 2020'!$T$41:$T$43)/11.63 -> 3.3486885 | Q32: ='[2]Bilan 2020'!$T$13/11.63 -> 0.69143728 | R32: =('[2]Bilan 2020'!$T$22+'[2]Bilan 2020'!$T$30+SUM('[2]Bilan 2020'!$T$36:$T$40)+SUM('[2]Bilan 2020'!$T$44:$T$45)+'[2]Bilan 2020'!$T$47)/11.63 -> 0.41959097 | S32: =SUM(O32:R32) -> 4.4610384 | T32: =S32 -> 4.4610384 | U32: Agriculture | V32: ER_AGRICULTURE_coal_2 | W32: ER_AGRICULTURE_oil_2 | X32: ER_AGRICULTURE_elec_2 | Y32: ER_AGRICULTURE_gas_2 | Z32: 0 | AA32: 2.3952478 | AB32: 0.31132122 | AC32: 0.37010948 | AD32: 3.0766785
C33: Total Final Mtep | H33: =SUM(H24,H27:H29) -> 2.9648389 | I33: =SUM(I24,I27:I29) -> 61.771985 | J33: =SUM(J24,J27:J29) -> 36.195136 | K33: =SUM(K24,K27:K29) -> 41.883868 | L33: =SUM(H33:K33) -> 142.81583 | N33: Total Final Mtep | O33: =O24+O27+O28+O29+O32 -> 3.2152067 | P33: =P24+P27+P28+P29+P32 -> 59.931007 | Q33: =Q24+Q27+Q28+Q29+Q32 -> 34.793213 | R33: =R24+R27+R28+R29+R32 -> 42.523975 | S33: =SUM(O33:R33) -> 140.4634 | T33: =SUM(T24:T32) -> 137.71943 | U33: Total Final Mtep | Z33: 2.9666883 | AA33: 62.018882 | AB33: 36.054888 | AC33: 42.136615 | AD33: 143.17707
C36: 2022 | H36: coal | I36: fuel and biofuel | J36: elec | K36: gas biogas biomass | L36: Total | N36: 2022 | O36: coal | P36: fuel and biofuel | Q36: elec | R36: gas biogas biomass | S36: Total | T36: Hors chal env PAC | U36: 2022 | Z36: coal | AA36: fuel and biofuel | AB36: elec | AC36: gas biogas biomass | AD36: Total
C37: Transport | H37: =SUM(H38:H39) -> 0 | I37: =SUM(I38:I39) -> 41.556283 | J37: =SUM(J38:J39) -> 1.8293062 | K37: =SUM(K38:K39) -> 0.38453628 | L37: =SUM(H37:K37) -> 43.770126 | N37: Transport | O37: ='[2]Bilan 2022 réel'!$X$46/11.63 -> 0 | P37: =SUM('[2]Bilan 2022 réel'!$X$41:$X$43)/11.63 -> 43.395883 | Q37: ='[2]Bilan 2022 réel'!$X$13/11.63 -> 0.93062752 | R37: =('[2]Bilan 2022 réel'!$X$22+'[2]Bilan 2022 réel'!$X$30+SUM('[2]Bilan 2022 réel'!$X$36:$X$40)+SUM('[2]Bilan 2022 réel'!$X$44:$X$45)+'[2]Bilan 2022 réel'!$X$47)/11.63 -> 0.31885684 | S37: =SUM(O37:R37) -> 44.645367 | T37: =S37 -> 44.645367 | U37: Transport | Z37: 0 | AA37: 41.601708 | AB37: 1.8231851 | AC37: 0.3888431 | AD37: 43.813736
C38: Personal vehicles | D38: ER_TRANS_PRIVATE_coal_2 | E38: ER_TRANS_PRIVATE_oil_2 | F38: ER_TRANS_PRIVATE_elec_2 | G38: ER_TRANS_PRIVATE_gas_2 | H38: =VLOOKUP(D38,Résultats!$B$2:$AX$476,'T energie vecteurs'!K5,FALSE) -> 0 | I38: =VLOOKUP(E38,Résultats!$B$2:$AX$476,'T energie vecteurs'!K5,FALSE) -> 22.927345 | J38: =VLOOKUP(F38,Résultats!$B$2:$AX$476,'T energie vecteurs'!K5,FALSE) -> 0.11841651 | K38: =VLOOKUP(G51,Résultats!$B$2:$AX$476,'T energie vecteurs'!K5,FALSE) -> 1.8276192e-05 | L38: =SUM(H38:K38) -> 23.045779 | N38: Personal vehicles | U38: Personal vehicles | V38: ER_TRANS_PRIVATE_coal_2 | W38: ER_TRANS_PRIVATE_oil_2 | X38: ER_TRANS_PRIVATE_elec_2 | Y38: ER_TRANS_PRIVATE_gas_2 | Z38: 0 | AA38: 22.924827 | AB38: 0.1186245 | AC38: 1.8382908e-05 | AD38: 23.04347
C39: Public and freight transport | D39: ER_TRANS_PUBLIC_coal_2 | E39: ER_TRANS_PUBLIC_oil_2 | F39: ER_TRANS_PUBLIC_elec_2 | G39: ER_TRANS_PUBLIC_gas_2 | H39: =VLOOKUP(D39,Résultats!$B$2:$AX$476,'T energie vecteurs'!K5,FALSE) -> 0 | I39: =VLOOKUP(E39,Résultats!$B$2:$AX$476,'T energie vecteurs'!K5,FALSE) -> 18.628939 | J39: =VLOOKUP(F39,Résultats!$B$2:$AX$476,'T energie vecteurs'!K5,FALSE) -> 1.7108897 | K39: =VLOOKUP(G39,Résultats!$B$2:$AX$476,'T energie vecteurs'!K5,FALSE) -> 0.384518 | L39: =SUM(H39:K39) -> 20.724346 | N39: Public and freight transport | U39: Public and freight transport | V39: ER_TRANS_PUBLIC_coal_2 | W39: ER_TRANS_PUBLIC_oil_2 | X39: ER_TRANS_PUBLIC_elec_2 | Y39: ER_TRANS_PUBLIC_gas_2 | Z39: 0 | AA39: 18.676881 | AB39: 1.7045606 | AC39: 0.38882472 | AD39: 20.770266
C40: Residential | D40: ER_RESIDENTIAL_coal_2 | E40: ER_RESIDENTIAL_oil_2 | F40: ER_RESIDENTIAL_elec_2 | G40: ER_RESIDENTIAL_gas_2 | H40: =VLOOKUP(D40,Résultats!$B$2:$AX$476,'T energie vecteurs'!K5,FALSE) -> 0.30437398 | I40: =VLOOKUP(E40,Résultats!$B$2:$AX$476,'T energie vecteurs'!K5,FALSE) -> 6.2902516 | J40: =VLOOKUP(F40,Résultats!$B$2:$AX$476,'T energie vecteurs'!K5,FALSE) -> 14.518216 | K40: =VLOOKUP(G40,Résultats!$B$2:$AX$476,'T energie vecteurs'!K5,FALSE)+2 -> 18.573275 | L40: =SUM(H40:K40) -> 39.686116 | N40: Residential | O40: ='[2]Bilan 2022 réel'!$V$46/11.63 -> 0.026476317 | P40: =SUM('[2]Bilan 2022 réel'!$V$41:$V$43)/11.63 -> 3.5006052 | Q40: ='[2]Bilan 2022 réel'!$V$13/11.63 -> 13.359407 | R40: =('[2]Bilan 2022 réel'!$V$22+'[2]Bilan 2022 réel'!$V$30+SUM('[2]Bilan 2022 réel'!$V$36:$V$40)+SUM('[2]Bilan 2022 réel'!$V$44:$V$45)+'[2]Bilan 2022 réel'!$V$47)/11.63 -> 20.358937 | S40: =SUM(O40:R40) -> 37.245425 | T40: =S40-'[2]Bilan 2022 réel'!$V$40/11.63 -> 33.844962 | U40: Residential | V40: ER_RESIDENTIAL_coal_2 | W40: ER_RESIDENTIAL_oil_2 | X40: ER_RESIDENTIAL_elec_2 | Y40: ER_RESIDENTIAL_gas_2 | Z40: 0.30501769 | AA40: 6.3077542 | AB40: 14.50955 | AC40: 18.635776 | AD40: 39.758098
C41: Service | D41: ER_TERTIARY_coal_2 | E41: ER_TERTIARY_oil_2 | F41: ER_TERTIARY_elec_2 | G41: ER_TERTIARY_gas_2 | H41: =VLOOKUP(D41,Résultats!$B$2:$AX$476,'T energie vecteurs'!K5,FALSE) -> 0 | I41: =VLOOKUP(E41,Résultats!$B$2:$AX$476,'T energie vecteurs'!K5,FALSE) -> 2.7551192 | J41: =VLOOKUP(F41,Résultats!$B$2:$AX$476,'T energie vecteurs'!K5,FALSE) -> 11.113064 | K41: =VLOOKUP(G41,Résultats!$B$2:$AX$476,'T energie vecteurs'!K5,FALSE) -> 7.7104864 | L41: =SUM(H41:K41) -> 21.57867 | N41: Service | O41: =('[2]Bilan 2022 réel'!$W$46)/11.63 -> 0.032835728 | P41: =SUM('[2]Bilan 2022 réel'!$W$41:$W$43)/11.63 -> 2.081572 | Q41: =('[2]Bilan 2022 réel'!$W$13)/11.63 -> 11.43888 | R41: =('[2]Bilan 2022 réel'!$W$22+'[2]Bilan 2022 réel'!$W$30+SUM('[2]Bilan 2022 réel'!$W$36:$W$40)+SUM('[2]Bilan 2022 réel'!$W$44:$W$45)+'[2]Bilan 2022 réel'!$W$47)/11.63 -> 7.4016622 | S41: =SUM(O41:R41) -> 20.95495 | T41: =S41-'[2]Bilan 2022 réel'!$W$40/11.63 -> 20.53461 | U41: Service | V41: ER_TERTIARY_coal_2 | W41: ER_TERTIARY_oil_2 | X41: ER_TERTIARY_elec_2 | Y41: ER_TERTIARY_gas_2 | Z41: 0 | AA41: 2.755786 | AB41: 11.083352 | AC41: 7.7555464 | AD41: 21.594684
C42: Industry | H42: =SUM(H43:H44) -> 2.6037063 | I42: =SUM(I43:I44) -> 10.850887 | J42: =SUM(J43:J44) -> 9.3025763 | K42: =SUM(K43:K44) -> 14.924168 | L42: =SUM(H42:K42) -> 37.681337 | N42: Industry | O42: =O43+O44 -> 4.5030918 | P42: =P43+P44 -> 11.747675 | Q42: =Q43+Q44 -> 9.2559822 | R42: =R43+R44 -> 13.798624 | S42: =SUM(O42:R42) -> 39.305373 | T42: =S42 -> 39.305373 | U42: Industry | Z42: 2.6055347 | AA42: 11.081409 | AB42: 9.2421087 | AC42: 15.050753 | AD42: 37.979806
C43: Industry | D43: ER_INDUS_coal_2 | E43: ER_INDUS_oil_2 | F43: ER_INDUS_elec_2 | G43: ER_INDUS_gas_2 | H43: =VLOOKUP(D43,Résultats!$B$2:$AX$476,'T energie vecteurs'!K5,FALSE) -> 1.7321576 | I43: =VLOOKUP(E43,Résultats!$B$2:$AX$476,'T energie vecteurs'!K5,FALSE) -> 8.933332 | J43: =VLOOKUP(F43,Résultats!$B$2:$AX$476,'T energie vecteurs'!K5,FALSE) -> 9.3025763 | K43: =VLOOKUP(G43,Résultats!$B$2:$AX$476,'T energie vecteurs'!K5,FALSE) -> 12.783319 | L43: =SUM(H43:K43) -> 32.751384 | N43: Industry energetic uses | O43: ='[2]Bilan 2022 réel'!$U$46/11.63 -> 0.63402045 | P43: =SUM('[2]Bilan 2022 réel'!$U$41:$U$43)/11.63 -> 2.477583 | Q43: ='[2]Bilan 2022 réel'!$U$13/11.63 -> 9.2559822 | R43: =('[2]Bilan 2022 réel'!$U$22+'[2]Bilan 2022 réel'!$U$30+SUM('[2]Bilan 2022 réel'!$U$36:$U$40)+SUM('[2]Bilan 2022 réel'!$U$44:$U$45)+'[2]Bilan 2022 réel'!$U$47)/11.63 -> 12.926273 | S43: =SUM(O43:R43) -> 25.293858 | U43: Industry | V43: ER_INDUS_coal_2 | W43: ER_INDUS_oil_2 | X43: ER_INDUS_elec_2 | Y43: ER_INDUS_gas_2 | Z43: 1.7329112 | AA43: 9.1647792 | AB43: 9.2421087 | AC43: 12.91308 | AD43: 33.052879
C44: Industry non energetic uses | D44: Q_Mtep_indus_21_2 | E44: Q_Mtep_indus_22_2 | F44: Q_Mtep_indus_23_2 | G44: Q_Mtep_indus_24_2 | H44: =VLOOKUP(D44,Résultats!$B$2:$AX$476,'T energie vecteurs'!K5,FALSE) -> 0.87154876 | I44: =VLOOKUP(E44,Résultats!$B$2:$AX$476,'T energie vecteurs'!K5,FALSE) -> 1.9175551 | J44: =VLOOKUP(F44,Résultats!$B$2:$AX$476,'T energie vecteurs'!K5,FALSE) -> 0 | K44: =VLOOKUP(G44,Résultats!$B$2:$AX$476,'T energie vecteurs'!K5,FALSE) -> 2.1408492 | L44: =SUM(H44:K44) -> 4.9299531 | N44: Industry non energetic uses | O44: ='[2]Bilan 2022 réel'!$E$52/11.63 -> 3.8690713 | P44: =('[2]Bilan 2022 réel'!$E$54+'[2]Bilan 2022 réel'!$E$56)/11.63 -> 9.270092 | Q44: 0 | R44: =('[2]Bilan 2022 réel'!$E$53+'[2]Bilan 2022 réel'!$E$55+'[2]Bilan 2022 réel'!$E$57)/11.63 -> 0.87235178 | S44: =SUM(O44:R44) -> 14.011515 | U44: Industry non energetic uses | V44: Q_Mtep_indus_21_2 | W44: Q_Mtep_indus_22_2 | X44: Q_Mtep_indus_23_2 | Y44: Q_Mtep_indus_24_2 | Z44: 0.87262353 | AA44: 1.9166294 | AB44: 0 | AC44: 2.1376736 | AD44: 4.9269265
C45: Agriculture | D45: ER_AGRICULTURE_coal_2 | E45: ER_AGRICULTURE_oil_2 | F45: ER_AGRICULTURE_elec_2 | G45: ER_AGRICULTURE_gas_2 | H45: =VLOOKUP(D45,Résultats!$B$2:$AX$476,'T energie vecteurs'!K5,FALSE) -> 0 | I45: =VLOOKUP(E45,Résultats!$B$2:$AX$476,'T energie vecteurs'!K5,FALSE) -> 2.5023883 | J45: =VLOOKUP(F45,Résultats!$B$2:$AX$476,'T energie vecteurs'!K5,FALSE) -> 0.32008009 | K45: =VLOOKUP(G45,Résultats!$B$2:$AX$476,'T energie vecteurs'!K5,FALSE) -> 0.37919082 | L45: =SUM(H45:K45) -> 3.2016593 | N45: Agriculture | O45: ='[2]Bilan 2022 réel'!$T$46/11.63 -> 0.001651664 | P45: =SUM('[2]Bilan 2022 réel'!$T$41:$T$43)/11.63 -> 3.5697769 | Q45: ='[2]Bilan 2022 réel'!$T$13/11.63 -> 0.67291488 | R45: =('[2]Bilan 2022 réel'!$T$22+'[2]Bilan 2022 réel'!$T$30+SUM('[2]Bilan 2022 réel'!$T$36:$T$40)+SUM('[2]Bilan 2022 réel'!$T$44:$T$45)+'[2]Bilan 2022 réel'!$T$47)/11.63 -> 0.43996563 | S45: =SUM(O45:R45) -> 4.6843091 | T45: =S45 -> 4.6843091 | U45: Agriculture | V45: ER_AGRICULTURE_coal_2 | W45: ER_AGRICULTURE_oil_2 | X45: ER_AGRICULTURE_elec_2 | Y45: ER_AGRICULTURE_gas_2 | Z45: 0 | AA45: 2.5119302 | AB45: 0.31896459 | AC45: 0.38141049 | AD45: 3.2123052
C46: Total Final Mtep | H46: =SUM(H37,H40:H42) -> 2.9080803 | I46: =SUM(I37,I40:I42) -> 61.452541 | J46: =SUM(J37,J40:J42) -> 36.763163 | K46: =SUM(K37,K40:K42) -> 41.592465 | L46: =SUM(H46:K46) -> 142.71625 | N46: Total Final Mtep | O46: =O37+O40+O41+O42+O45 -> 4.5640555 | P46: =P37+P40+P41+P42+P45 -> 64.295512 | Q46: =Q37+Q40+Q41+Q42+Q45 -> 35.657811 | R46: =R37+R40+R41+R42+R45 -> 42.318046 | S46: =SUM(O46:R46) -> 146.83542 | T46: =SUM(T37:T45) -> 143.01462 | U46: Total Final Mtep | Z46: 2.9105524 | AA46: 61.746657 | AB46: 36.658196 | AC46: 41.830919 | AD46: 143.14632
C49: 2023 | H49: coal | I49: fuel and biofuel | J49: elec | K49: gas biogas biomass | L49: Total | N49: 2023 | O49: coal | P49: fuel and biofuel | Q49: elec | R49: gas biogas biomass | S49: Total | T49: Hors chal env PAC | U49: 2023 | Z49: coal | AA49: fuel and biofuel | AB49: elec | AC49: gas biogas biomass | AD49: Total
...

Sheet T transport
A1: =Résultats!B1 -> SNBC3 | B1: Transport (milliers de km voyageurs) | C1: 2006 | D1: 2007 | E1: 2008 | F1: 2009 | G1: 2010 | H1: 2011 | I1: 2012 | J1: 2013 | K1: 2014 | L1: 2015 | M1: 2016 | N1: 2017 | O1: 2018 | P1: 2019 | Q1: 2020 | R1: 2021 | S1: 2022 | T1: 2023 | U1: 2024 | V1: 2025 | W1: 2026 | X1: 2027 | Y1: 2028 | Z1: 2029 | AA1: 2030 | AB1: 2031 | AC1: 2032 | AD1: 2033 | AE1: 2034 | AF1: 2035 | AG1: 2036 | AH1: 2037 | AI1: 2038 | AJ1: 2039 | AK1: 2040 | AL1: 2041 | AM1: 2042 | AN1: 2043 | AO1: 2044 | AP1: 2045 | AQ1: 2046 | AR1: 2047 | AS1: 2048 | AT1: 2049 | AU1: 2050 | AW1: Part modale hors avion | AX1: 2020 | AY1: 2030 | AZ1: 2050
B2: Total | C2: =C3+C4+C7 -> 842942.38 | D2: =D3+D4+D7 -> 869933.51 | E2: =E3+E4+E7 -> 882159.87 | F2: =F3+F4+F7 -> 903546.03 | G2: =G3+G4+G7 -> 918679.93 | H2: =H3+H4+H7 -> 951417.16 | I2: =I3+I4+I7 -> 985661.34 | J2: =J3+J4+J7 -> 1026216.2 | ... AU2: =AU3+AU4+AU7 -> 1297378.6 | AW2: voiture CD | AX2: =Q8/Q7 -> 0.9168438 | AY2: =AA8/AA7 -> 0.92409629 | AZ2: =AU8/AU7 -> 0.92481319
B3: Avion (France + RDM) | C3: =Résultats!E286 -> 13442.055 | D3: =Résultats!F286 -> 13760.192 | E3: =Résultats!G286 -> 14220.486 | F3: =Résultats!H286 -> 13766.211 | G3: =Résultats!I286 -> 13331.85 | H3: =Résultats!J286 -> 13703.852 | I3: =Résultats!K286 -> 14002.183 | J3: =Résultats!L286 -> 13923.816 | ... AU3: =Résultats!AW286 -> 22841.493 | AW3: voiture LD | AX3: =Q5/Q4 -> 0.68207261 | AY3: =AA5/AA4 -> 0.49453788 | AZ3: =AU5/AU4 -> 0.55342551
B4: Longue Distance (LD) | C4: =Résultats!E292 -> 248850.1 | D4: =Résultats!F292 -> 262554.18 | E4: =Résultats!G292 -> 270560.58 | F4: =Résultats!H292 -> 280313.27 | G4: =Résultats!I292 -> 287655.77 | H4: =Résultats!J292 -> 303446.28 | I4: =Résultats!K292 -> 321817.05 | J4: =Résultats!L292 -> 344000.67 | ... P4: =Résultats!R292 -> 393699.81 | Q4: =SUM(Q5:Q6) -> 405500.04 | R4: =SUM(R5:R6) -> 344969.09 | S4: =SUM(S5:S6) -> 346990.44 | T4: =SUM(T5:T6) -> 342836.98 | U4: =SUM(U5:U6) -> 341047.99 | V4: =SUM(V5:V6) -> 307996.64 | W4: =SUM(W5:W6) -> 300090.7 | X4: =SUM(X5:X6) -> 298846.73 | ... AU4: =SUM(AU5:AU6) -> 477576.37 | AW4: voiture CD+LD | AX4: =Q10/(Q7+Q4) -> 0.83420584 | AY4: =AA10/(AA7+AA4) -> 0.7648331 | AZ4: =AU10/(AU7+AU4) -> 0.7856521
B5: voiture LD | C5: =Résultats!E287 -> 163461.3 | D5: =Résultats!F287 -> 171749.84 | E5: =Résultats!G287 -> 178981.26 | F5: =Résultats!H287 -> 186059.12 | G5: =Résultats!I287 -> 192587.05 | H5: =Résultats!J287 -> 202066.85 | I5: =Résultats!K287 -> 216540.19 | J5: =Résultats!L287 -> 232360.58 | ... AU5: =Résultats!AW287 -> 264302.94
B6: train | C6: =Résultats!E290 -> 47168.089 | D6: =Résultats!F290 -> 48086.325 | E6: =Résultats!G290 -> 47749.278 | F6: =Résultats!H290 -> 48731.582 | G6: =Résultats!I290 -> 49222.122 | H6: =Résultats!J290 -> 50609.36 | I6: =Résultats!K290 -> 51063.036 | J6: =Résultats!L290 -> 51928.424 | ... P6: =Résultats!R290 -> 62187.078 | Q6: =Résultats!S289 -> 128919.57 | R6: =Résultats!T290 -> 61653.162 | S6: =Résultats!U290 -> 61830.075 | T6: =Résultats!V290 -> 61772.232 | U6: =Résultats!W290 -> 60466.543 | V6: =Résultats!X290 -> 57825.955 | W6: =Résultats!Y290 -> 57853.826 | X6: =Résultats!Z290 -> 58366.938 | Y6: =Résultats!AA290 -> 58607.795 | Z6: =Résultats!AB290 -> 58753.451 | AA6: =Résultats!AC289 -> 226903.46 | AB6: =Résultats!AD290 -> 58669.009 | AC6: =Résultats!AE290 -> 58799.155 | AD6: =Résultats!AF290 -> 58940.135 | AE6: =Résultats!AG290 -> 59007.558 | AF6: =Résultats!AH290 -> 58266.344 | AG6: =Résultats!AI290 -> 58803.107 | AH6: =Résultats!AJ290 -> 59069.608 | AI6: =Résultats!AK290 -> 59211.018 | ... AT6: =Résultats!AV290 -> 59839.46 | AU6: =Résultats!AW289 -> 213273.42 | BB6: Cibles DGEC
B7: Courte Distance (CD) | C7: =Résultats!E291 -> 580650.23 | D7: =Résultats!F291 -> 593619.13 | E7: =Résultats!G291 -> 597378.81 | F7: =Résultats!H291 -> 609466.55 | G7: =Résultats!I291 -> 617692.32 | H7: =Résultats!J291 -> 634267.03 | I7: =Résultats!K291 -> 649842.1 | J7: =Résultats!L291 -> 668291.69 | ... P7: =Résultats!R291 -> 742928.77 | Q7: =SUM(Q8:Q9) -> 746509.65 | R7: =SUM(R8:R9) -> 822384.57 | S7: =SUM(S8:S9) -> 829017.83 | T7: =SUM(T8:T9) -> 839939.71 | U7: =SUM(U8:U9) -> 844313.34 | V7: =SUM(V8:V9) -> 901232.41 | W7: =SUM(W8:W9) -> 900012.88 | X7: =SUM(X8:X9) -> 897995.1 | ... AU7: =SUM(AU8:AU9) -> 796960.78 | AW7: Avion | AX7: =Q3/Q2 -> 0.013379844 | AY7: =AA3/AA2 -> 0.013048756 | AZ7: =AU3/AU2 -> 0.01760588 | BB7: =[3]Trafic!$H$27/([3]Trafic!$H$30-[3]Trafic!$H$29) -> 0.0096732537 | BC7: =[3]Trafic!$J$27/([3]Trafic!$J$30-[3]Trafic!$J$29) -> 0.014577968 | BD7: =[3]Trafic!$N$27/([3]Trafic!$N$30-[3]Trafic!$N$29) -> 0.0065864877
B8: voiture CD | C8: =Résultats!E288 -> 533482.14 | D8: =Résultats!F288 -> 545533.01 | E8: =Résultats!G288 -> 549634.41 | F8: =Résultats!H288 -> 560739.95 | G8: =Résultats!I288 -> 568475.55 | H8: =Résultats!J288 -> 583663.22 | I8: =Résultats!K288 -> 598791.34 | J8: =Résultats!L288 -> 616379.45 | ... AU8: =Résultats!AW288 -> 737039.84 | AW8: train | AX8: =+Q6/Q2 -> 0.11041109 | AY8: =+AA6/AA2 -> 0.18495986 | AZ8: =+AU6/AU2 -> 0.16438796 | BB8: =[3]Trafic!$H$25/[3]Trafic!$H$31 -> 0.086581999 | BC8: =[3]Trafic!$J$25/[3]Trafic!$J$31 -> 0.14233557 | BD8: =[3]Trafic!$N$25/[3]Trafic!$N$31 -> 0.18954037
B9: bus | C9: =Résultats!E289 -> 85388.794 | D9: =Résultats!F289 -> 90808.657 | E9: =Résultats!G289 -> 91615.781 | F9: =Résultats!H289 -> 94295.043 | G9: =Résultats!I289 -> 95131.742 | H9: =Résultats!J289 -> 101454.85 | I9: =Résultats!K289 -> 105391.4 | J9: =Résultats!L289 -> 111767.77 | ... P9: =Résultats!R289 -> 123060.71 | Q9: =Résultats!S290 -> 62076.907 | R9: =Résultats!T289 -> 136876.41 | S9: =Résultats!U289 -> 141254.74 | T9: =Résultats!V289 -> 149276.34 | U9: =Résultats!W289 -> 150836.99 | V9: =Résultats!X289 -> 200275.58 | W9: =Résultats!Y289 -> 199731.37 | X9: =Résultats!Z289 -> 197992.83 | Y9: =Résultats!AA289 -> 196400.27 | Z9: =Résultats!AB289 -> 194980.32 | AA9: =Résultats!AC290 -> 57828.042 | AB9: =Résultats!AD289 -> 223368.29 | AC9: =Résultats!AE289 -> 219849.46 | AD9: =Résultats!AF289 -> 216459.71 | AE9: =Résultats!AG289 -> 213337.35 | AF9: =Résultats!AH289 -> 226921.48 | AG9: =Résultats!AI289 -> 223806.12 | AH9: =Résultats!AJ289 -> 221157.91 | AI9: =Résultats!AK289 -> 218754.98 | ... AT9: =Résultats!AV289 -> 215111.34 | AU9: =Résultats!AW290 -> 59920.938 | AW9: bus | AX9: =Q9/Q2 -> 0.053164768 | AY9: =AA9/AA2 -> 0.047138402 | AZ9: =AU9/AU2 -> 0.046186161 | BB9: =[3]Trafic!$H$26/[3]Trafic!$H$31 -> 0.050587052 | BC9: =[3]Trafic!$J$26/[3]Trafic!$J$31 -> 0.076007848 | BD9: =[3]Trafic!$N$26/[3]Trafic!$N$31 -> 0.098293993
B10: Voiture CD+LD | C10: =C5+C8 -> 696943.45 | D10: =D5+D8 -> 717282.86 | E10: =E5+E8 -> 728615.67 | F10: =F5+F8 -> 746799.07 | G10: =G5+G8 -> 761062.6 | H10: =H5+H8 -> 785730.07 | I10: =I5+I8 -> 815331.53 | J10: =J5+J8 -> 848740.03 | ... AU10: =AU5+AU8 -> 1001342.8 | AW10: route | AX10: =1-SUM(AX7:AX9) -> 0.8230443 | AY10: =1-SUM(AY7:AY9) -> 0.75485298 | AZ10: =1-SUM(AZ7:AZ9) -> 0.77182 | BB10: =([3]Trafic!$H$23+[3]Trafic!$H$28)/[3]Trafic!$H$30 -> 0.84698145 | BC10: =([3]Trafic!$J$23+[3]Trafic!$J$28)/[3]Trafic!$J$30 -> 0.75252159 | BD10: =([3]Trafic!$N$23+[3]Trafic!$N$28)/[3]Trafic!$N$30 -> 0.68588807
A12: TEND | B12: Transport (milliers de km voyageurs) | C12: 2006 | D12: 2007 | E12: 2008 | F12: 2009 | G12: 2010 | H12: 2011 | I12: 2012 | J12: 2013 | K12: 2014 | L12: 2015 | M12: 2016 | N12: 2017 | O12: 2018 | P12: 2019 | Q12: 2020 | R12: 2021 | S12: 2022 | T12: 2023 | U12: 2024 | V12: 2025 | W12: 2026 | X12: 2027 | Y12: 2028 | Z12: 2029 | AA12: 2030 | AB12: 2031 | AC12: 2032 | AD12: 2033 | AE12: 2034 | AF12: 2035 | AG12: 2036 | AH12: 2037 | AI12: 2038 | AJ12: 2039 | AK12: 2040 | AL12: 2041 | AM12: 2042 | AN12: 2043 | AO12: 2044 | AP12: 2045 | AQ12: 2046 | AR12: 2047 | AS12: 2048 | AT12: 2049 | AU12: 2050 | AW12: Part modale hors avion | AX12: 2020 | AY12: 2030 | AZ12: 2050
B13: Total | C13: =C14+C15+C18 -> 842942.38 | D13: =D14+D15+D18 -> 869933.51 | E13: =E14+E15+E18 -> 882159.87 | F13: =F14+F15+F18 -> 903546.03 | G13: =G14+G15+G18 -> 918679.93 | H13: =H14+H15+H18 -> 951417.16 | I13: =I14+I15+I18 -> 985661.34 | J13: =J14+J15+J18 -> 1026216.2 | ... AU13: =AU14+AU15+AU18 -> 1288587.2 | AW13: voiture CD | AX13: =Q19/Q18 -> 0.91720921 | AY13: =AA19/AA18 -> 0.92278177 | AZ13: =AU19/AU18 -> 0.92335916
