Workbook

Sheet Résultats
A1: 1) Copier-coller sorties Eviews en B2 2) veillez à ce que les données commencent en 2004 3) modifier le scénario si besoin en B1 | B1: TEND | C1: 2 | D1: =C1+1 -> 3 | E1: =D1+1 -> 4 | F1: =E1+1 -> 5 | G1: =F1+1 -> 6 | H1: =G1+1 -> 7 | I1: =H1+1 -> 8 | J1: =I1+1 -> 9 | K1: =J1+1 -> 10 | ... AW1: =AV1+1 -> 48
C2: 2004 | D2: 2005 | E2: 2006 | F2: 2007 | G2: 2008 | H2: 2009 | I2: 2010 | J2: 2011 | K2: 2012 | L2: 2013 | M2: 2014 | N2: 2015 | O2: 2016 | P2: 2017 | Q2: 2018 | R2: 2019 | S2: 2020 | T2: 2021 | U2: 2022 | V2: 2023 | W2: 2024 | X2: 2025 | Y2: 2026 | Z2: 2027 | AA2: 2028 | AB2: 2029 | AC2: 2030 | AD2: 2031 | AE2: 2032 | AF2: 2033 | AG2: 2034 | AH2: 2035 | AI2: 2036 | AJ2: 2037 | AK2: 2038 | AL2: 2039 | AM2: 2040 | AN2: 2041 | AO2: 2042 | AP2: 2043 | AQ2: 2044 | AR2: 2045 | AS2: 2046 | AT2: 2047 | AU2: 2048 | AV2: 2049 | AW2: 2050
B3: ER_OIL_1 | C3: 78.155731 | D3: 79.410547 | E3: 80.666675 | F3: 82.035682 | G3: 78.482848 | H3: 76.415373 | I3: 75.517374 | J3: 73.768785 | K3: 71.715188 | L3: 70.391378 | M3: 70.512892 | N3: 71.337322 | O3: 70.080528 | P3: 68.213217 | Q3: 65.482836 | R3: 63.804612 | S3: 62.280175 | T3: 62.233927 | U3: 62.037374 | V3: 61.942539 | W3: 61.488789 | X3: 60.520864 | Y3: 59.888636 | Z3: 59.527087 | AA3: 59.164357 | AB3: 58.775049 | AC3: 58.23058 | AD3: 57.752251 | AE3: 57.347357 | AF3: 56.950989 | AG3: 56.553029 | AH3: 56.153917 | AI3: 55.834175 | AJ3: 55.532601 | AK3: 55.224904 | AL3: 54.925054 | AM3: 54.632669 | AN3: 54.302055 | AO3: 53.959506 | AP3: 53.594738 | AQ3: 53.224765 | AR3: 52.795129 | AS3: 52.536095 | AT3: 52.29053 | AU3: 52.044794 | AV3: 51.802559 | AW3: 51.584101
B4: ER_OIL_2201_1 | C4: 77.477679 | D4: 78.721608 | E4: 79.999247 | F4: 81.022954 | G4: 77.195781 | H4: 74.853667 | I4: 73.670354 | J4: 71.669115 | K4: 69.387955 | L4: 67.827521 | M4: 67.665694 | N4: 68.175816 | O4: 66.924745 | P4: 65.089784 | Q4: 62.4315 | R4: 60.776409 | S4: 59.266794 | T4: 59.064033 | U4: 58.724378 | V4: 58.48661 | W4: 58.058176 | X4: 57.144253 | Y4: 56.5473 | Z4: 56.205922 | AA4: 55.863429 | AB4: 55.495842 | AC4: 54.98175 | AD4: 54.530108 | AE4: 54.147805 | AF4: 53.773551 | AG4: 53.397794 | AH4: 53.020949 | AI4: 52.719046 | AJ4: 52.434299 | AK4: 52.143768 | AL4: 51.860648 | AM4: 51.584575 | AN4: 51.272407 | AO4: 50.948971 | AP4: 50.604554 | AQ4: 50.255222 | AR4: 49.849556 | AS4: 49.604975 | AT4: 49.373111 | AU4: 49.141084 | AV4: 48.912364 | AW4: 48.706095
B5: ER_OIL_2202_1 | C5: 0.67805251 | D5: 0.68893886 | E5: 0.66742791 | F5: 1.0127286 | G5: 1.2870671 | H5: 1.5617059 | I5: 1.8470199 | J5: 2.09967 | K5: 2.3272333 | L5: 2.5638568 | M5: 2.8471982 | N5: 3.1615056 | O5: 3.1557835 | P5: 3.1234328 | Q5: 3.0513356 | R5: 3.0282026 | S5: 3.0133803 | T5: 3.169894 | U5: 3.3129965 | V5: 3.4559291 | W5: 3.4306133 | X5: 3.3766103 | Y5: 3.3413368 | Z5: 3.321165 | AA5: 3.3009274 | AB5: 3.279207 | AC5: 3.2488297 | AD5: 3.2221425 | AE5: 3.1995525 | AF5: 3.1774381 | AG5: 3.1552349 | AH5: 3.1329674 | AI5: 3.1151282 | AJ5: 3.0983027 | AK5: 3.0811355 | AL5: 3.0644061 | AM5: 3.0480932 | AN5: 3.0296474 | AO5: 3.0105358 | AP5: 2.9901845 | AQ5: 2.9695427 | AR5: 2.9455722 | AS5: 2.9311201 | AT5: 2.9174195 | AU5: 2.9037092 | AV5: 2.8901943 | AW5: 2.878006
B6: ER_ELEC_2301_1 | C6: 28.634797 | D6: 29.094538 | E6: 29.720829 | F6: 30.395734 | G6: 30.84488 | H6: 28.382862 | I6: 29.33487 | J6: 30.227113 | K6: 30.510267 | L6: 30.317786 | M6: 30.078584 | N6: 29.366185 | O6: 27.729943 | P6: 27.282406 | Q6: 27.211353 | R6: 26.331809 | S6: 25.339627 | T6: 25.195318 | U6: 25.099698 | V6: 25.060583 | W6: 25.428937 | X6: 25.866638 | Y6: 26.379628 | Z6: 26.774546 | AA6: 27.149903 | AB6: 27.511001 | AC6: 27.92298 | AD6: 28.268945 | AE6: 28.602992 | AF6: 28.931656 | AG6: 29.242489 | AH6: 29.590121 | AI6: 29.896044 | AJ6: 30.190951 | AK6: 30.474748 | AL6: 30.75375 | AM6: 31.028873 | AN6: 31.22838 | AO6: 31.425242 | AP6: 31.617125 | AQ6: 31.800595 | AR6: 32.010407 | AS6: 32.163232 | AT6: 32.305167 | AU6: 32.441391 | AV6: 32.574578 | AW6: 32.716675
B7: ER_ELEC_2302_1 | C7: 0.3674935 | D7: 0.37339372 | E7: 0.38143142 | F7: 0.36959453 | G7: 0.35534756 | H7: 0.30980169 | I7: 0.30336755 | J7: 0.29616858 | K7: 0.28323418 | L7: 0.26665792 | M7: 0.25065233 | N7: 0.23185648 | O7: 0.20152333 | P7: 0.17977976 | Q7: 0.1593467 | R7: 0.13321387 | S7: 0.10618667 | T7: 0.14036934 | U7: 0.17561825 | V7: 0.21225064 | W7: 0.21537042 | X7: 0.21907752 | Y7: 0.22342229 | Z7: 0.22676705 | AA7: 0.22994613 | AB7: 0.23300446 | AC7: 0.23649371 | AD7: 0.23942386 | AE7: 0.24225308 | AF7: 0.2450367 | AG7: 0.2476693 | AH7: 0.25061357 | AI7: 0.25320458 | AJ7: 0.2557023 | AK7: 0.25810592 | AL7: 0.26046892 | AM7: 0.26279908 | AN7: 0.2644888 | AO7: 0.26615613 | AP7: 0.26778127 | AQ7: 0.26933518 | AR7: 0.27111218 | AS7: 0.27240653 | AT7: 0.27360865 | AU7: 0.2747624 | AV7: 0.27589043 | AW7: 0.27709392
B8: ER_ELEC_2303_1 | C8: 1.4676116 | D8: 1.4911746 | E8: 1.5232737 | F8: 1.5601303 | G8: 1.5854864 | H8: 1.4610559 | I8: 1.5122585 | J8: 1.5605214 | K8: 1.5774306 | L8: 1.5697589 | M8: 1.5596389 | N8: 1.5249142 | O8: 1.6126745 | P8: 1.7700533 | Q8: 1.9634662 | R8: 2.1081164 | S8: 2.2469677 | T8: 2.1597456 | U8: 2.0749964 | V8: 1.9928045 | W8: 2.0220958 | X8: 2.0569016 | Y8: 2.0976943 | Z8: 2.1290979 | AA8: 2.1589461 | AB8: 2.1876605 | AC8: 2.2204208 | AD8: 2.2479317 | AE8: 2.274495 | AF8: 2.3006302 | AG8: 2.3253475 | AH8: 2.352991 | AI8: 2.3773178 | AJ8: 2.4007687 | AK8: 2.4233361 | AL8: 2.4455221 | AM8: 2.4673998 | AN8: 2.4832644 | AO8: 2.4989188 | AP8: 2.5141772 | AQ8: 2.5287668 | AR8: 2.5454508 | AS8: 2.5576034 | AT8: 2.56889 | AU8: 2.5797225 | AV8: 2.5903134 | AW8: 2.6016129
B9: ER_ELEC_2304_1 | C9: 1.4643634 | D9: 1.4878742 | E9: 1.5199023 | F9: 1.4313444 | G9: 1.3374924 | H9: 1.1332903 | I9: 1.0785639 | J9: 1.0233758 | K9: 0.95117674 | L9: 0.87034099 | M9: 0.79510793 | N9: 0.71481388 | O9: 0.59939305 | P9: 0.50945316 | Q9: 0.42146316 | R9: 0.31676052 | S9: 0.20929419 | T9: 0.20105002 | U9: 0.19303322 | V9: 0.18525067 | W9: 0.18797358 | X9: 0.19120912 | Y9: 0.1950012 | Z9: 0.19792047 | AA9: 0.20069515 | AB9: 0.20336443 | AC9: 0.20640983 | AD9: 0.20896724 | AE9: 0.21143655 | AF9: 0.21386607 | AG9: 0.21616379 | AH9: 0.21873353 | AI9: 0.22099494 | AJ9: 0.22317493 | AK9: 0.22527279 | AL9: 0.2273352 | AM9: 0.22936894 | AN9: 0.23084371 | AO9: 0.23229894 | AP9: 0.23371736 | AQ9: 0.2350736 | AR9: 0.23662455 | AS9: 0.23775425 | AT9: 0.23880345 | AU9: 0.23981043 | AV9: 0.24079497 | AW9: 0.24184536
B10: ER_ELEC_2305_1 | C10: 0.29584764 | D10: 0.30059757 | E10: 0.30706825 | F10: 0.6519587 | G10: 0.97825412 | H10: 1.1655634 | I10: 1.4492602 | J10: 1.71064 | K10: 1.905129 | L10: 2.0219685 | M10: 2.0752167 | N10: 2.0225632 | O10: 2.154674 | P10: 2.3798406 | Q10: 2.6543005 | R10: 2.8634673 | S10: 3.0649473 | T10: 3.2395533 | U10: 3.4248087 | V10: 3.6232296 | W10: 3.6764858 | X10: 3.7397681 | Y10: 3.8139356 | Z10: 3.8710324 | AA10: 3.925301 | AB10: 3.9775082 | AC10: 4.0370716 | AD10: 4.0870908 | AE10: 4.1353869 | AF10: 4.1829048 | AG10: 4.2278447 | AH10: 4.2781049 | AI10: 4.3223348 | AJ10: 4.3649722 | AK10: 4.4060033 | AL10: 4.446341 | AM10: 4.4861179 | AN10: 4.5149624 | AO10: 4.5434245 | AP10: 4.5711667 | AQ10: 4.5976927 | AR10: 4.6280269 | AS10: 4.6501222 | AT10: 4.670643 | AU10: 4.6903381 | AV10: 4.7095942 | AW10: 4.7301383
B11: ER_ELEC_2306_1 | C11: 0.066565719 | D11: 0.067634453 | E11: 0.069090357 | F11: 0.09400524 | G11: 0.1269128 | H11: 0.15536794 | I11: 0.21363495 | J11: 0.29286517 | K11: 0.39327828 | L11: 0.51991738 | M11: 0.68624177 | N11: 0.89135396 | O11: 0.94957587 | P11: 1.048808 | Q11: 1.1697638 | R11: 1.2619447 | S11: 1.350738 | T11: 1.4080658 | U11: 1.4696004 | V11: 1.5362904 | W11: 1.5588717 | X11: 1.5857041 | Y11: 1.6171519 | Z11: 1.6413616 | AA11: 1.6643721 | AB11: 1.6865085 | AC11: 1.7117641 | AD11: 1.7329728 | AE11: 1.7534509 | AF11: 1.773599 | AG11: 1.792654 | AH11: 1.813965 | AI11: 1.8327189 | AJ11: 1.8507977 | AK11: 1.8681953 | AL11: 1.8852989 | AM11: 1.9021648 | AN11: 1.9143952 | AO11: 1.9264635 | AP11: 1.9382265 | AQ11: 1.9494738 | AR11: 1.9623359 | AS11: 1.9717045 | AT11: 1.9804056 | AU11: 1.9887565 | AV11: 1.9969213 | AW11: 2.0056322
B12: ER_ELEC_2307_1 | C12: 3.3276745 | D12: 3.3811014 | E12: 3.4538832 | F12: 3.4079138 | G12: 3.3364781 | H12: 2.9620379 | I12: 2.9535738 | J12: 2.9362266 | K12: 2.8593554 | L12: 2.7412512 | M12: 2.6238438 | N12: 2.4714814 | O12: 2.6329149 | P12: 2.9080584 | Q12: 3.243436 | R12: 3.4990285 | S12: 3.7452281 | T12: 3.9399496 | U12: 4.1472224 | V12: 4.3699683 | W12: 4.4342005 | X12: 4.5105251 | Y12: 4.5999783 | Z12: 4.6688426 | AA12: 4.7342958 | AB12: 4.7972628 | AC12: 4.8691021 | AD12: 4.9294301 | AE12: 4.98768 | AF12: 5.0449911 | AG12: 5.099193 | AH12: 5.1598118 | AI12: 5.2131573 | AJ12: 5.2645822 | AK12: 5.3140696 | AL12: 5.3627209 | AM12: 5.4106957 | AN12: 5.445485 | AO12: 5.4798131 | AP12: 5.5132728 | AQ12: 5.5452658 | AR12: 5.5818519 | AS12: 5.6085009 | AT12: 5.633251 | AU12: 5.6570052 | AV12: 5.6802299 | AW12: 5.7050081
B13: ER_ELEC_2308_1 | C13: 0.21556469 | D13: 0.21902565 | E13: 0.22374041 | F13: 0.25649359 | G13: 0.29176107 | H13: 0.30094062 | I13: 0.34864961 | J13: 0.4027004 | K13: 0.45562944 | L13: 0.50750885 | M13: 0.56439597 | N13: 0.61766704 | O13: 0.56696656 | P13: 0.54052438 | Q13: 0.52044672 | R13: 0.48400307 | S13: 0.44518555 | T13: 0.47094717 | U13: 0.49826553 | V13: 0.52750938 | W13: 0.535263 | X13: 0.54447633 | Y13: 0.55527445 | Z13: 0.56358721 | AA13: 0.57148823 | AB13: 0.57908913 | AC13: 0.58776102 | AD13: 0.59504336 | AE13: 0.60207484 | AF13: 0.60899301 | AG13: 0.61553585 | AH13: 0.62285329 | AI13: 0.62929276 | AJ13: 0.63550037 | AK13: 0.64147412 | AL13: 0.64734693 | AM13: 0.65313809 | AN13: 0.65733758 | AO13: 0.66148142 | AP13: 0.66552042 | AQ13: 0.66938237 | AR13: 0.67379876 | AS13: 0.67701564 | AT13: 0.68000328 | AU13: 0.6828707 | AV13: 0.68567421 | AW13: 0.68866525
B14: ER_ELEC_1 | C14: 35.839918 | D14: 36.41534 | E14: 37.199219 | F14: 38.167175 | G14: 38.856613 | H14: 35.870919 | I14: 37.194179 | J14: 38.449611 | K14: 38.935501 | L14: 38.81519 | M14: 38.633681 | N14: 37.840835 | O14: 36.447665 | P14: 36.618923 | Q14: 37.343576 | R14: 36.998343 | S14: 36.508175 | T14: 36.754998 | U14: 37.083243 | V14: 37.507887 | W14: 38.059198 | X14: 38.7143 | Y14: 39.482086 | Z14: 40.073155 | AA14: 40.634947 | AB14: 41.175399 | AC14: 41.792003 | AD14: 42.309805 | AE14: 42.809769 | AF14: 43.301677 | AG14: 43.766897 | AH14: 44.287195 | AI14: 44.745065 | AJ14: 45.186449 | AK14: 45.611205 | AL14: 46.028784 | AM14: 46.440557 | AN14: 46.739157 | AO14: 47.033799 | AP14: 47.320987 | AQ14: 47.595586 | AR14: 47.909608 | AS14: 48.13834 | AT14: 48.350772 | AU14: 48.554657 | AV14: 48.753996 | AW14: 48.966671
... B257: EMS_AUTO_24_H01_1 | C257: 2.3355384 | D257: 2.3730362 | E257: 2.3697171 | F257: 2.6984848 | G257: 4.699048 | H257: 6.8056363 | I257: 8.8675552 | J257: 11.410562 | K257: 13.542796 | L257: 15.26115 | M257: 16.765366 | N257: 17.356405 | O257: 18.204591 | P257: 18.505675 | Q257: 19.652648 | R257: 20.93412 | S257: 23.516443 | T257: 24.66199 | U257: 26.90948 | V257: 29.146283 | W257: 32.819296 | X257: 34.771363 | Y257: 37.66342 | Z257: 40.864148 | AA257: 44.131918 | AB257: 47.353872 | AC257: 49.236604 | AD257: 51.800962 | AE257: 54.666169 | AF257: 57.486683 | AG257: 60.213625 | AH257: 62.335584 | AI257: 64.548051 | AJ257: 66.90862 | AK257: 69.295447 | AL257: 71.663549 | AM257: 73.994166 | AN257: 76.18145 | AO257: 78.26872 | AP257: 80.307536 | AQ257: 82.324057 | AR257: 83.567784 | AS257: 85.182544 | AT257: 86.95091 | AU257: 88.799656 | AV257: 90.696722 | AW257: 92.62857

Sheet T energie vecteurs
A1: Energie par vecteur énergétique
A3: Energie primaire (Mtep)
A4: =Résultats!B1 -> TEND
E5: 4 | F5: =E5+9 -> 13 | G5: =F5+3 -> 16 | H5: =G5+1 -> 17 | I5: =H5+1 -> 18 | J5: =I5+1 -> 19 | K5: =J5+1 -> 20 | L5: =K5+1 -> 21 | M5: =L5+1 -> 22 | N5: =M5+1 -> 23 | O5: =N5+1 -> 24 | ... S5: =R5+1 -> 28 | T5: =S5+5 -> 33 | U5: =T5+5 -> 38 | V5: =U5+5 -> 43 | W5: =V5+5 -> 48
E6: 2006 | F6: 2015 | G6: 2018 | H6: 2019 | I6: 2020 | J6: 2021 | K6: 2022 | L6: 2023 | M6: 2024 | N6: 2025 | O6: 2026 | P6: 2027 | Q6: 2028 | R6: 2029 | S6: 2030 | T6: 2035 | U6: 2040 | V6: 2045 | W6: 2050 | Z6: Cf. onglet "G énergie"
B7: Refined petroleum products | C7: Total | E7: =SUM(E8:E9) -> #N/A | F7: =SUM(F8:F9) -> #N/A | G7: =SUM(G8:G9) -> #N/A | H7: =SUM(H8:H9) -> #N/A | I7: =SUM(I8:I9) -> #N/A | J7: =SUM(J8:J9) -> #N/A | K7: =SUM(K8:K9) -> #N/A | L7: =SUM(L8:L9) -> #N/A | ... W7: =SUM(W8:W9) -> #N/A | AA7: 2020 | AB7: 2030 | AC7: 2050
C8: Oil | D8: Q_Mtep_ep_2201_0 | E8: =VLOOKUP($D8,Résultats!$B$2:$AX$426,E$5,FALSE) -> #N/A | F8: =VLOOKUP($D8,Résultats!$B$2:$AX$426,F$5,FALSE) -> #N/A | G8: =VLOOKUP($D8,Résultats!$B$2:$AX$426,G$5,FALSE) -> #N/A | H8: =VLOOKUP($D8,Résultats!$B$2:$AX$426,H$5,FALSE) -> #N/A | I8: =VLOOKUP($D8,Résultats!$B$2:$AX$426,I$5,FALSE) -> #N/A | J8: =VLOOKUP($D8,Résultats!$B$2:$AX$426,J$5,FALSE) -> #N/A | K8: =VLOOKUP($D8,Résultats!$B$2:$AX$426,K$5,FALSE) -> #N/A | L8: =VLOOKUP($D8,Résultats!$B$2:$AX$426,L$5,FALSE) -> #N/A | ... W8: =VLOOKUP($D8,Résultats!$B$2:$AX$426,W$5,FALSE) -> #N/A | Z8: Energie primaire | AA8: =I27 -> #N/A | AB8: =S27 -> #N/A | AC8: =W27 -> #N/A
C9: Biofuels | D9: Q_Mtep_ep_2202_0 | E9: =VLOOKUP($D9,Résultats!$B$2:$AX$426,E$5,FALSE) -> #N/A | F9: =VLOOKUP($D9,Résultats!$B$2:$AX$426,F$5,FALSE) -> #N/A | G9: =VLOOKUP($D9,Résultats!$B$2:$AX$426,G$5,FALSE) -> #N/A | H9: =VLOOKUP($D9,Résultats!$B$2:$AX$426,H$5,FALSE) -> #N/A | I9: =VLOOKUP($D9,Résultats!$B$2:$AX$426,I$5,FALSE) -> #N/A | J9: =VLOOKUP($D9,Résultats!$B$2:$AX$426,J$5,FALSE) -> #N/A | K9: =VLOOKUP($D9,Résultats!$B$2:$AX$426,K$5,FALSE) -> #N/A | L9: =VLOOKUP($D9,Résultats!$B$2:$AX$426,L$5,FALSE) -> #N/A | ... W9: =VLOOKUP($D9,Résultats!$B$2:$AX$426,W$5,FALSE) -> #N/A
B10: Electric power generation, transmission and distribution | C10: Total | E10: =SUM(E11:E18) -> #N/A | F10: =SUM(F11:F18) -> #N/A | G10: =SUM(G11:G18) -> #N/A | H10: =SUM(H11:H18) -> #N/A | I10: =SUM(I11:I18) -> #N/A | J10: =SUM(J11:J18) -> #N/A | K10: =SUM(K11:K18) -> #N/A | L10: =SUM(L11:L18) -> #N/A | ... W10: =SUM(W11:W18) -> #N/A
C11: Nuclear | D11: Q_Mtep_ep_2301_0 | E11: =VLOOKUP($D11,Résultats!$B$2:$AX$426,E$5,FALSE) -> #N/A | F11: =VLOOKUP($D11,Résultats!$B$2:$AX$426,F$5,FALSE) -> #N/A | G11: =VLOOKUP($D11,Résultats!$B$2:$AX$426,G$5,FALSE) -> #N/A | H11: =VLOOKUP($D11,Résultats!$B$2:$AX$426,H$5,FALSE) -> #N/A | I11: =VLOOKUP($D11,Résultats!$B$2:$AX$426,I$5,FALSE) -> #N/A | J11: =VLOOKUP($D11,Résultats!$B$2:$AX$426,J$5,FALSE) -> #N/A | K11: =VLOOKUP($D11,Résultats!$B$2:$AX$426,K$5,FALSE) -> #N/A | L11: =VLOOKUP($D11,Résultats!$B$2:$AX$426,L$5,FALSE) -> #N/A | ... W11: =VLOOKUP($D11,Résultats!$B$2:$AX$426,W$5,FALSE) -> #N/A
C12: Fuel | D12: Q_Mtep_ep_2302_0 | E12: =VLOOKUP($D12,Résultats!$B$2:$AX$426,E$5,FALSE) -> #N/A | F12: =VLOOKUP($D12,Résultats!$B$2:$AX$426,F$5,FALSE) -> #N/A | G12: =VLOOKUP($D12,Résultats!$B$2:$AX$426,G$5,FALSE) -> #N/A | H12: =VLOOKUP($D12,Résultats!$B$2:$AX$426,H$5,FALSE) -> #N/A | I12: =VLOOKUP($D12,Résultats!$B$2:$AX$426,I$5,FALSE) -> #N/A | J12: =VLOOKUP($D12,Résultats!$B$2:$AX$426,J$5,FALSE) -> #N/A | K12: =VLOOKUP($D12,Résultats!$B$2:$AX$426,K$5,FALSE) -> #N/A | L12: =VLOOKUP($D12,Résultats!$B$2:$AX$426,L$5,FALSE) -> #N/A | ... W12: =VLOOKUP($D12,Résultats!$B$2:$AX$426,W$5,FALSE) -> #N/A
C13: Combined gas | D13: Q_Mtep_ep_2303_0 | E13: =VLOOKUP($D13,Résultats!$B$2:$AX$426,E$5,FALSE) -> #N/A | F13: =VLOOKUP($D13,Résultats!$B$2:$AX$426,F$5,FALSE) -> #N/A | G13: =VLOOKUP($D13,Résultats!$B$2:$AX$426,G$5,FALSE) -> #N/A | H13: =VLOOKUP($D13,Résultats!$B$2:$AX$426,H$5,FALSE) -> #N/A | I13: =VLOOKUP($D13,Résultats!$B$2:$AX$426,I$5,FALSE) -> #N/A | J13: =VLOOKUP($D13,Résultats!$B$2:$AX$426,J$5,FALSE) -> #N/A | K13: =VLOOKUP($D13,Résultats!$B$2:$AX$426,K$5,FALSE) -> #N/A | L13: =VLOOKUP($D13,Résultats!$B$2:$AX$426,L$5,FALSE) -> #N/A | ... W13: =VLOOKUP($D13,Résultats!$B$2:$AX$426,W$5,FALSE) -> #N/A
C14: Coal | D14: Q_Mtep_ep_2304_0 | E14: =VLOOKUP($D14,Résultats!$B$2:$AX$426,E$5,FALSE) -> #N/A | F14: =VLOOKUP($D14,Résultats!$B$2:$AX$426,F$5,FALSE) -> #N/A | G14: =VLOOKUP($D14,Résultats!$B$2:$AX$426,G$5,FALSE) -> #N/A | H14: =VLOOKUP($D14,Résultats!$B$2:$AX$426,H$5,FALSE) -> #N/A | I14: =VLOOKUP($D14,Résultats!$B$2:$AX$426,I$5,FALSE) -> #N/A | J14: =VLOOKUP($D14,Résultats!$B$2:$AX$426,J$5,FALSE) -> #N/A | K14: =VLOOKUP($D14,Résultats!$B$2:$AX$426,K$5,FALSE) -> #N/A | L14: =VLOOKUP($D14,Résultats!$B$2:$AX$426,L$5,FALSE) -> #N/A | ... W14: =VLOOKUP($D14,Résultats!$B$2:$AX$426,W$5,FALSE) -> #N/A
C15: Wind | D15: Q_Mtep_ep_2305_0 | E15: =VLOOKUP($D15,Résultats!$B$2:$AX$426,E$5,FALSE) -> #N/A | F15: =VLOOKUP($D15,Résultats!$B$2:$AX$426,F$5,FALSE) -> #N/A | G15: =VLOOKUP($D15,Résultats!$B$2:$AX$426,G$5,FALSE) -> #N/A | H15: =VLOOKUP($D15,Résultats!$B$2:$AX$426,H$5,FALSE) -> #N/A | I15: =VLOOKUP($D15,Résultats!$B$2:$AX$426,I$5,FALSE) -> #N/A | J15: =VLOOKUP($D15,Résultats!$B$2:$AX$426,J$5,FALSE) -> #N/A | K15: =VLOOKUP($D15,Résultats!$B$2:$AX$426,K$5,FALSE) -> #N/A | L15: =VLOOKUP($D15,Résultats!$B$2:$AX$426,L$5,FALSE) -> #N/A | ... W15: =VLOOKUP($D15,Résultats!$B$2:$AX$426,W$5,FALSE) -> #N/A
C16: Solar | D16: Q_Mtep_ep_2306_0 | E16: =VLOOKUP($D16,Résultats!$B$2:$AX$426,E$5,FALSE) -> #N/A | F16: =VLOOKUP($D16,Résultats!$B$2:$AX$426,F$5,FALSE) -> #N/A | G16: =VLOOKUP($D16,Résultats!$B$2:$AX$426,G$5,FALSE) -> #N/A | H16: =VLOOKUP($D16,Résultats!$B$2:$AX$426,H$5,FALSE) -> #N/A | I16: =VLOOKUP($D16,Résultats!$B$2:$AX$426,I$5,FALSE) -> #N/A | J16: =VLOOKUP($D16,Résultats!$B$2:$AX$426,J$5,FALSE) -> #N/A | K16: =VLOOKUP($D16,Résultats!$B$2:$AX$426,K$5,FALSE) -> #N/A | L16: =VLOOKUP($D16,Résultats!$B$2:$AX$426,L$5,FALSE) -> #N/A | ... W16: =VLOOKUP($D16,Résultats!$B$2:$AX$426,W$5,FALSE) -> #N/A
C17: Hydraulic | D17: Q_Mtep_ep_2307_0 | E17: =VLOOKUP($D17,Résultats!$B$2:$AX$426,E$5,FALSE) -> #N/A | F17: =VLOOKUP($D17,Résultats!$B$2:$AX$426,F$5,FALSE) -> #N/A | G17: =VLOOKUP($D17,Résultats!$B$2:$AX$426,G$5,FALSE) -> #N/A | H17: =VLOOKUP($D17,Résultats!$B$2:$AX$426,H$5,FALSE) -> #N/A | I17: =VLOOKUP($D17,Résultats!$B$2:$AX$426,I$5,FALSE) -> #N/A | J17: =VLOOKUP($D17,Résultats!$B$2:$AX$426,J$5,FALSE) -> #N/A | K17: =VLOOKUP($D17,Résultats!$B$2:$AX$426,K$5,FALSE) -> #N/A | L17: =VLOOKUP($D17,Résultats!$B$2:$AX$426,L$5,FALSE) -> #N/A | ... W17: =VLOOKUP($D17,Résultats!$B$2:$AX$426,W$5,FALSE) -> #N/A
C18: Cogeneration (CHP) | D18: Q_Mtep_ep_2308_0 | E18: =VLOOKUP($D18,Résultats!$B$2:$AX$426,E$5,FALSE) -> #N/A | F18: =VLOOKUP($D18,Résultats!$B$2:$AX$426,F$5,FALSE) -> #N/A | G18: =VLOOKUP($D18,Résultats!$B$2:$AX$426,G$5,FALSE) -> #N/A | H18: =VLOOKUP($D18,Résultats!$B$2:$AX$426,H$5,FALSE) -> #N/A | I18: =VLOOKUP($D18,Résultats!$B$2:$AX$426,I$5,FALSE) -> #N/A | J18: =VLOOKUP($D18,Résultats!$B$2:$AX$426,J$5,FALSE) -> #N/A | K18: =VLOOKUP($D18,Résultats!$B$2:$AX$426,K$5,FALSE) -> #N/A | L18: =VLOOKUP($D18,Résultats!$B$2:$AX$426,L$5,FALSE) -> #N/A | ... W18: =VLOOKUP($D18,Résultats!$B$2:$AX$426,W$5,FALSE) -> #N/A
B19: Gas and heat | C19: Total | E19: =SUM(E20:E25) -> #N/A | F19: =SUM(F20:F25) -> #N/A | G19: =SUM(G20:G25) -> #N/A | H19: =SUM(H20:H25) -> #N/A | I19: =SUM(I20:I25) -> #N/A | J19: =SUM(J20:J25) -> #N/A | K19: =SUM(K20:K25) -> #N/A | L19: =SUM(L20:L25) -> #N/A | ... W19: =SUM(W20:W25) -> #N/A
C20: Natural gas | D20: Q_Mtep_ep_2401_0 | E20: =VLOOKUP($D20,Résultats!$B$2:$AX$426,E$5,FALSE) -> #N/A | F20: =VLOOKUP($D20,Résultats!$B$2:$AX$426,F$5,FALSE) -> #N/A | G20: =VLOOKUP($D20,Résultats!$B$2:$AX$426,G$5,FALSE) -> #N/A | H20: =VLOOKUP($D20,Résultats!$B$2:$AX$426,H$5,FALSE) -> #N/A | I20: =VLOOKUP($D20,Résultats!$B$2:$AX$426,I$5,FALSE) -> #N/A | J20: =VLOOKUP($D20,Résultats!$B$2:$AX$426,J$5,FALSE) -> #N/A | K20: =VLOOKUP($D20,Résultats!$B$2:$AX$426,K$5,FALSE) -> #N/A | L20: =VLOOKUP($D20,Résultats!$B$2:$AX$426,L$5,FALSE) -> #N/A | ... W20: =VLOOKUP($D20,Résultats!$B$2:$AX$426,W$5,FALSE) -> #N/A
C21: Wood | D21: Q_Mtep_ep_2402_0 | E21: =VLOOKUP($D21,Résultats!$B$2:$AX$426,E$5,FALSE) -> #N/A | F21: =VLOOKUP($D21,Résultats!$B$2:$AX$426,F$5,FALSE) -> #N/A | G21: =VLOOKUP($D21,Résultats!$B$2:$AX$426,G$5,FALSE) -> #N/A | H21: =VLOOKUP($D21,Résultats!$B$2:$AX$426,H$5,FALSE) -> #N/A | I21: =VLOOKUP($D21,Résultats!$B$2:$AX$426,I$5,FALSE) -> #N/A | J21: =VLOOKUP($D21,Résultats!$B$2:$AX$426,J$5,FALSE) -> #N/A | K21: =VLOOKUP($D21,Résultats!$B$2:$AX$426,K$5,FALSE) -> #N/A | L21: =VLOOKUP($D21,Résultats!$B$2:$AX$426,L$5,FALSE) -> #N/A | ... W21: =VLOOKUP($D21,Résultats!$B$2:$AX$426,W$5,FALSE) -> #N/A
C22: Biogas | D22: Q_Mtep_ep_2403_0 | E22: =VLOOKUP($D22,Résultats!$B$2:$AX$426,E$5,FALSE) -> #N/A | F22: =VLOOKUP($D22,Résultats!$B$2:$AX$426,F$5,FALSE) -> #N/A | G22: =VLOOKUP($D22,Résultats!$B$2:$AX$426,G$5,FALSE) -> #N/A | H22: =VLOOKUP($D22,Résultats!$B$2:$AX$426,H$5,FALSE) -> #N/A | I22: =VLOOKUP($D22,Résultats!$B$2:$AX$426,I$5,FALSE) -> #N/A | J22: =VLOOKUP($D22,Résultats!$B$2:$AX$426,J$5,FALSE) -> #N/A | K22: =VLOOKUP($D22,Résultats!$B$2:$AX$426,K$5,FALSE) -> #N/A | L22: =VLOOKUP($D22,Résultats!$B$2:$AX$426,L$5,FALSE) -> #N/A | ... W22: =VLOOKUP($D22,Résultats!$B$2:$AX$426,W$5,FALSE) -> #N/A
C23: Waste incineration | D23: Q_Mtep_ep_2404_0 | E23: =VLOOKUP($D23,Résultats!$B$2:$AX$426,E$5,FALSE) -> #N/A | F23: =VLOOKUP($D23,Résultats!$B$2:$AX$426,F$5,FALSE) -> #N/A | G23: =VLOOKUP($D23,Résultats!$B$2:$AX$426,G$5,FALSE) -> #N/A | H23: =VLOOKUP($D23,Résultats!$B$2:$AX$426,H$5,FALSE) -> #N/A | I23: =VLOOKUP($D23,Résultats!$B$2:$AX$426,I$5,FALSE) -> #N/A | J23: =VLOOKUP($D23,Résultats!$B$2:$AX$426,J$5,FALSE) -> #N/A | K23: =VLOOKUP($D23,Résultats!$B$2:$AX$426,K$5,FALSE) -> #N/A | L23: =VLOOKUP($D23,Résultats!$B$2:$AX$426,L$5,FALSE) -> #N/A | ... W23: =VLOOKUP($D23,Résultats!$B$2:$AX$426,W$5,FALSE) -> #N/A
C24: Geothermal | D24: Q_Mtep_ep_2405_0 | E24: =VLOOKUP($D24,Résultats!$B$2:$AX$426,E$5,FALSE) -> #N/A | F24: =VLOOKUP($D24,Résultats!$B$2:$AX$426,F$5,FALSE) -> #N/A | G24: =VLOOKUP($D24,Résultats!$B$2:$AX$426,G$5,FALSE) -> #N/A | H24: =VLOOKUP($D24,Résultats!$B$2:$AX$426,H$5,FALSE) -> #N/A | I24: =VLOOKUP($D24,Résultats!$B$2:$AX$426,I$5,FALSE) -> #N/A | J24: =VLOOKUP($D24,Résultats!$B$2:$AX$426,J$5,FALSE) -> #N/A | K24: =VLOOKUP($D24,Résultats!$B$2:$AX$426,K$5,FALSE) -> #N/A | L24: =VLOOKUP($D24,Résultats!$B$2:$AX$426,L$5,FALSE) -> #N/A | ... W24: =VLOOKUP($D24,Résultats!$B$2:$AX$426,W$5,FALSE) -> #N/A
C25: Cogeneration (CHP) | D25: Q_Mtep_ep_2406_0 | E25: =VLOOKUP($D25,Résultats!$B$2:$AX$426,E$5,FALSE) -> #N/A | F25: =VLOOKUP($D25,Résultats!$B$2:$AX$426,F$5,FALSE) -> #N/A | G25: =VLOOKUP($D25,Résultats!$B$2:$AX$426,G$5,FALSE) -> #N/A | H25: =VLOOKUP($D25,Résultats!$B$2:$AX$426,H$5,FALSE) -> #N/A | I25: =VLOOKUP($D25,Résultats!$B$2:$AX$426,I$5,FALSE) -> #N/A | J25: =VLOOKUP($D25,Résultats!$B$2:$AX$426,J$5,FALSE) -> #N/A | K25: =VLOOKUP($D25,Résultats!$B$2:$AX$426,K$5,FALSE) -> #N/A | L25: =VLOOKUP($D25,Résultats!$B$2:$AX$426,L$5,FALSE) -> #N/A | ... W25: =VLOOKUP($D25,Résultats!$B$2:$AX$426,W$5,FALSE) -> #N/A
B26: Coal | D26: Q_Mtep_ep_21_0 | E26: =VLOOKUP($D26,Résultats!$B$2:$AX$426,E$5,FALSE) -> #N/A | F26: =VLOOKUP($D26,Résultats!$B$2:$AX$426,F$5,FALSE) -> #N/A | G26: =VLOOKUP($D26,Résultats!$B$2:$AX$426,G$5,FALSE) -> #N/A | H26: =VLOOKUP($D26,Résultats!$B$2:$AX$426,H$5,FALSE) -> #N/A | I26: =VLOOKUP($D26,Résultats!$B$2:$AX$426,I$5,FALSE) -> #N/A | J26: =VLOOKUP($D26,Résultats!$B$2:$AX$426,J$5,FALSE) -> #N/A | K26: =VLOOKUP($D26,Résultats!$B$2:$AX$426,K$5,FALSE) -> #N/A | L26: =VLOOKUP($D26,Résultats!$B$2:$AX$426,L$5,FALSE) -> #N/A | ... W26: =VLOOKUP($D26,Résultats!$B$2:$AX$426,W$5,FALSE) -> #N/A
B27: Total | E27: =E26+E19+E10+E7 -> #N/A | F27: =F26+F19+F10+F7 -> #N/A | G27: =G26+G19+G10+G7 -> #N/A | H27: =H26+H19+H10+H7 -> #N/A | I27: =I26+I19+I10+I7 -> #N/A | J27: =J26+J19+J10+J7 -> #N/A | K27: =K26+K19+K10+K7 -> #N/A | L27: =L26+L19+L10+L7 -> #N/A | ... W27: =W26+W19+W10+W7 -> #N/A
A30: Energie finale (Mtep)
A31: =Résultats!B1 -> TEND | Z31: Cf. onglet "G mix elec" | AE31: Cf. onglet "G mix carb" | AJ31: Cf. onglet "G mix gaz"
E32: 2006 | F32: 2015 | G32: 2018 | H32: 2019 | I32: 2020 | J32: 2021 | K32: 2022 | L32: 2023 | M32: 2024 | N32: 2025 | O32: 2026 | P32: 2027 | Q32: 2028 | R32: 2029 | S32: 2030 | T32: 2035 | U32: 2040 | V32: 2045 | W32: 2050 | AA32: 2020 | AB32: 2030 | AC32: 2050 | AF32: 2020 | AG32: 2030 | AH32: 2050 | AK32: 2020 | AL32: 2030 | AM32: 2050
B33: Refined petroleum products | C33: Total | D33: ER_Oil_0 | E33: =SUM(E34:E35) -> #N/A | F33: =SUM(F34:F35) -> #N/A | G33: =SUM(G34:G35) -> #N/A | H33: =SUM(H34:H35) -> #N/A | I33: =SUM(I34:I35) -> #N/A | J33: =SUM(J34:J35) -> #N/A | K33: =SUM(K34:K35) -> #N/A | L33: =SUM(L34:L35) -> #N/A | ... W33: =SUM(W34:W35) -> #N/A | Z33: charbon | AA33: =(I38+I40)/I36 -> #N/A | AB33: =(S38+S40)/S36 -> #N/A | AC33: =(W38+W40)/W36 -> #N/A | AE33: carburants fossiles | AF33: =I34/I33 -> #N/A | AG33: =S34/S33 -> #N/A | AH33: =W34/W33 -> #N/A | AJ33: gaz naturel | AK33: =I46/(I46+I48) -> #N/A | AL33: =S46/(S46+S48) -> #N/A | AM33: =W46/(W46+W48) -> #N/A
C34: Oil | D34: ER_oil_2201_0 | E34: =VLOOKUP($D34,Résultats!$B$2:$AX$426,E$5,FALSE) -> #N/A | F34: =VLOOKUP($D34,Résultats!$B$2:$AX$426,F$5,FALSE) -> #N/A | G34: =VLOOKUP($D34,Résultats!$B$2:$AX$426,G$5,FALSE) -> #N/A | H34: =VLOOKUP($D34,Résultats!$B$2:$AX$426,H$5,FALSE) -> #N/A | I34: =VLOOKUP($D34,Résultats!$B$2:$AX$426,I$5,FALSE) -> #N/A | J34: =VLOOKUP($D34,Résultats!$B$2:$AX$426,J$5,FALSE) -> #N/A | K34: =VLOOKUP($D34,Résultats!$B$2:$AX$426,K$5,FALSE) -> #N/A | L34: =VLOOKUP($D34,Résultats!$B$2:$AX$426,L$5,FALSE) -> #N/A | ... W34: =VLOOKUP($D34,Résultats!$B$2:$AX$426,W$5,FALSE) -> #N/A | Z34: nucléaire | AA34: =I37/I36 -> #N/A | AB34: =S37/S36 -> #N/A | AC34: =W37/W36 -> #N/A | AE34: biocarburants | AF34: =I35/I33 -> #N/A | AG34: =S35/S33 -> #N/A | AH34: =W35/W33 -> #N/A | AJ34: biogaz | AK34: =I48/(I46+I48) -> #N/A | AL34: =S48/(S46+S48) -> #N/A | AM34: =W48/(W46+W48) -> #N/A
C35: Biofuels | D35: ER_oil_2202_0 | E35: =VLOOKUP($D35,Résultats!$B$2:$AX$426,E$5,FALSE) -> #N/A | F35: =VLOOKUP($D35,Résultats!$B$2:$AX$426,F$5,FALSE) -> #N/A | G35: =VLOOKUP($D35,Résultats!$B$2:$AX$426,G$5,FALSE) -> #N/A | H35: =VLOOKUP($D35,Résultats!$B$2:$AX$426,H$5,FALSE) -> #N/A | I35: =VLOOKUP($D35,Résultats!$B$2:$AX$426,I$5,FALSE) -> #N/A | J35: =VLOOKUP($D35,Résultats!$B$2:$AX$426,J$5,FALSE) -> #N/A | K35: =VLOOKUP($D35,Résultats!$B$2:$AX$426,K$5,FALSE) -> #N/A | L35: =VLOOKUP($D35,Résultats!$B$2:$AX$426,L$5,FALSE) -> #N/A | ... W35: =VLOOKUP($D35,Résultats!$B$2:$AX$426,W$5,FALSE) -> #N/A | Z35: hydraulique | AA35: =I43/I36 -> #N/A | AB35: =S43/S36 -> #N/A | AC35: =W43/W36 -> #N/A | AE35: Total | AF35: =SUM(AF33:AF34) -> #N/A | AG35: =SUM(AG33:AG34) -> #N/A | AH35: =SUM(AH33:AH34) -> #N/A | AJ35: Total | AK35: =SUM(AK33:AK34) -> #N/A | AL35: =SUM(AL33:AL34) -> #N/A | AM35: =SUM(AM33:AM34) -> #N/A
B36: Electric power generation, transmission and distribution | C36: Total | D36: ER_elec_0 | E36: =SUM(E37:E44) -> #N/A | F36: =SUM(F37:F44) -> #N/A | G36: =SUM(G37:G44) -> #N/A | H36: =SUM(H37:H44) -> #N/A | I36: =SUM(I37:I44) -> #N/A | J36: =SUM(J37:J44) -> #N/A | K36: =SUM(K37:K44) -> #N/A | L36: =SUM(L37:L44) -> #N/A | ... W36: =SUM(W37:W44) -> #N/A | Z36: solaire | AA36: =I42/I36 -> #N/A | AB36: =S42/S36 -> #N/A | AC36: =W42/W36 -> #N/A
C37: Nuclear | D37: ER_Elec_2301_0 | E37: =VLOOKUP($D37,Résultats!$B$2:$AX$426,E$5,FALSE) -> #N/A | F37: =VLOOKUP($D37,Résultats!$B$2:$AX$426,F$5,FALSE) -> #N/A | G37: =VLOOKUP($D37,Résultats!$B$2:$AX$426,G$5,FALSE) -> #N/A | H37: =VLOOKUP($D37,Résultats!$B$2:$AX$426,H$5,FALSE) -> #N/A | I37: =VLOOKUP($D37,Résultats!$B$2:$AX$426,I$5,FALSE) -> #N/A | J37: =VLOOKUP($D37,Résultats!$B$2:$AX$426,J$5,FALSE) -> #N/A | K37: =VLOOKUP($D37,Résultats!$B$2:$AX$426,K$5,FALSE) -> #N/A | L37: =VLOOKUP($D37,Résultats!$B$2:$AX$426,L$5,FALSE) -> #N/A | ... W37: =VLOOKUP($D37,Résultats!$B$2:$AX$426,W$5,FALSE) -> #N/A | Z37: éolien | AA37: =I41/I36 -> #N/A | AB37: =S41/S36 -> #N/A | AC37: =W41/W36 -> #N/A
C38: Fuel | D38: ER_elec_2302_0 | E38: =VLOOKUP($D38,Résultats!$B$2:$AX$426,E$5,FALSE) -> #N/A | F38: =VLOOKUP($D38,Résultats!$B$2:$AX$426,F$5,FALSE) -> #N/A | G38: =VLOOKUP($D38,Résultats!$B$2:$AX$426,G$5,FALSE) -> #N/A | H38: =VLOOKUP($D38,Résultats!$B$2:$AX$426,H$5,FALSE) -> #N/A | I38: =VLOOKUP($D38,Résultats!$B$2:$AX$426,I$5,FALSE) -> #N/A | J38: =VLOOKUP($D38,Résultats!$B$2:$AX$426,J$5,FALSE) -> #N/A | K38: =VLOOKUP($D38,Résultats!$B$2:$AX$426,K$5,FALSE) -> #N/A | L38: =VLOOKUP($D38,Résultats!$B$2:$AX$426,L$5,FALSE) -> #N/A | ... W38: =VLOOKUP($D38,Résultats!$B$2:$AX$426,W$5,FALSE) -> #N/A | Z38: autres renouvelables | AA38: =(I39+I44)/I36 -> #N/A | AB38: =(S39+S44)/S36 -> #N/A | AC38: =(W39+W44)/W36 -> #N/A
C39: Combined gas | D39: ER_Elec_2303_0 | E39: =VLOOKUP($D39,Résultats!$B$2:$AX$426,E$5,FALSE) -> #N/A | F39: =VLOOKUP($D39,Résultats!$B$2:$AX$426,F$5,FALSE) -> #N/A | G39: =VLOOKUP($D39,Résultats!$B$2:$AX$426,G$5,FALSE) -> #N/A | H39: =VLOOKUP($D39,Résultats!$B$2:$AX$426,H$5,FALSE) -> #N/A | I39: =VLOOKUP($D39,Résultats!$B$2:$AX$426,I$5,FALSE) -> #N/A | J39: =VLOOKUP($D39,Résultats!$B$2:$AX$426,J$5,FALSE) -> #N/A | K39: =VLOOKUP($D39,Résultats!$B$2:$AX$426,K$5,FALSE) -> #N/A | L39: =VLOOKUP($D39,Résultats!$B$2:$AX$426,L$5,FALSE) -> #N/A | ... W39: =VLOOKUP($D39,Résultats!$B$2:$AX$426,W$5,FALSE) -> #N/A | Z39: Total | AA39: =SUM(AA33:AA38) -> #N/A | AB39: =SUM(AB33:AB38) -> #N/A | AC39: =SUM(AC33:AC38) -> #N/A
C40: Coal | D40: ER_elec_2304_0 | E40: =VLOOKUP($D40,Résultats!$B$2:$AX$426,E$5,FALSE) -> #N/A | F40: =VLOOKUP($D40,Résultats!$B$2:$AX$426,F$5,FALSE) -> #N/A | G40: =VLOOKUP($D40,Résultats!$B$2:$AX$426,G$5,FALSE) -> #N/A | H40: =VLOOKUP($D40,Résultats!$B$2:$AX$426,H$5,FALSE) -> #N/A | I40: =VLOOKUP($D40,Résultats!$B$2:$AX$426,I$5,FALSE) -> #N/A | J40: =VLOOKUP($D40,Résultats!$B$2:$AX$426,J$5,FALSE) -> #N/A | K40: =VLOOKUP($D40,Résultats!$B$2:$AX$426,K$5,FALSE) -> #N/A | L40: =VLOOKUP($D40,Résultats!$B$2:$AX$426,L$5,FALSE) -> #N/A | ... W40: =VLOOKUP($D40,Résultats!$B$2:$AX$426,W$5,FALSE) -> #N/A
C41: Wind | D41: ER_Elec_2305_0 | E41: =VLOOKUP($D41,Résultats!$B$2:$AX$426,E$5,FALSE) -> #N/A | F41: =VLOOKUP($D41,Résultats!$B$2:$AX$426,F$5,FALSE) -> #N/A | G41: =VLOOKUP($D41,Résultats!$B$2:$AX$426,G$5,FALSE) -> #N/A | H41: =VLOOKUP($D41,Résultats!$B$2:$AX$426,H$5,FALSE) -> #N/A | I41: =VLOOKUP($D41,Résultats!$B$2:$AX$426,I$5,FALSE) -> #N/A | J41: =VLOOKUP($D41,Résultats!$B$2:$AX$426,J$5,FALSE) -> #N/A | K41: =VLOOKUP($D41,Résultats!$B$2:$AX$426,K$5,FALSE) -> #N/A | L41: =VLOOKUP($D41,Résultats!$B$2:$AX$426,L$5,FALSE) -> #N/A | ... W41: =VLOOKUP($D41,Résultats!$B$2:$AX$426,W$5,FALSE) -> #N/A
C42: Solar | D42: ER_elec_2306_0 | E42: =VLOOKUP($D42,Résultats!$B$2:$AX$426,E$5,FALSE) -> #N/A | F42: =VLOOKUP($D42,Résultats!$B$2:$AX$426,F$5,FALSE) -> #N/A | G42: =VLOOKUP($D42,Résultats!$B$2:$AX$426,G$5,FALSE) -> #N/A | H42: =VLOOKUP($D42,Résultats!$B$2:$AX$426,H$5,FALSE) -> #N/A | I42: =VLOOKUP($D42,Résultats!$B$2:$AX$426,I$5,FALSE) -> #N/A | J42: =VLOOKUP($D42,Résultats!$B$2:$AX$426,J$5,FALSE) -> #N/A | K42: =VLOOKUP($D42,Résultats!$B$2:$AX$426,K$5,FALSE) -> #N/A | L42: =VLOOKUP($D42,Résultats!$B$2:$AX$426,L$5,FALSE) -> #N/A | ... W42: =VLOOKUP($D42,Résultats!$B$2:$AX$426,W$5,FALSE) -> #N/A
C43: Hydraulic | D43: ER_Elec_2307_0 | E43: =VLOOKUP($D43,Résultats!$B$2:$AX$426,E$5,FALSE) -> #N/A | F43: =VLOOKUP($D43,Résultats!$B$2:$AX$426,F$5,FALSE) -> #N/A | G43: =VLOOKUP($D43,Résultats!$B$2:$AX$426,G$5,FALSE) -> #N/A | H43: =VLOOKUP($D43,Résultats!$B$2:$AX$426,H$5,FALSE) -> #N/A | I43: =VLOOKUP($D43,Résultats!$B$2:$AX$426,I$5,FALSE) -> #N/A | J43: =VLOOKUP($D43,Résultats!$B$2:$AX$426,J$5,FALSE) -> #N/A | K43: =VLOOKUP($D43,Résultats!$B$2:$AX$426,K$5,FALSE) -> #N/A | L43: =VLOOKUP($D43,Résultats!$B$2:$AX$426,L$5,FALSE) -> #N/A | ... W43: =VLOOKUP($D43,Résultats!$B$2:$AX$426,W$5,FALSE) -> #N/A
...

Sheet T energie usages
A1: Energie par usage
A3: Energie finale (Mtep)
A4: =Résultats!B1 -> TEND
C7: Consos résultats de ThreeME | N7: Consos cibles d'Enerdata | U7: Consos résultats de ThreeME
C8: Hors bois domestique non marchand, avec consommation à double usage | N8: Hors bois domestique auto produit (8MTEP entre 2015 et 2030 4 Mtep en 2050) | U8: Hors bois domestique non marchand, avec consommation à double usage
C10: 2015 | H10: coal | I10: fuel and biofuel | J10: elec | K10: gas biogas biomass | L10: Total | N10: 2015 | O10: coal | P10: fuel and biofuel | Q10: elec | R10: gas biogas biomass | S10: Total | T10: Hors chal env PAC | U10: 2015 | Z10: coal | AA10: fuel and biofuel | AB10: elec | AC10: gas biogas biomass | AD10: Total
C11: Transport | H11: =SUM(H12:H13) -> 0 | I11: =SUM(I12:I13) -> 43.145689 | J11: =SUM(J12:J13) -> 1.2869702 | K11: =SUM(K12:K13) -> 0.24534333 | L11: =SUM(H11:K11) -> 44.678003 | N11: Transport | O11: ='[1]Bilan 2015'!$X$46 -> 0 | P11: =SUM('[1]Bilan 2015'!$X$41:$X$43) -> 42.748697 | Q11: ='[1]Bilan 2015'!$X$13 -> 0.94471195 | R11: =('[1]Bilan 2015'!$X$22+'[1]Bilan 2015'!$X$30+SUM('[1]Bilan 2015'!$X$36:$X$40)+SUM('[1]Bilan 2015'!$X$44:$X$45)+'[1]Bilan 2015'!$X$47) -> 0.072674067 | S11: =SUM(O11:R11) -> 43.766083 | T11: =S11 -> 43.766083 | U11: Transport | Z11: 0 | AA11: 43.15955 | AB11: 1.2867468 | AC11: 0.24934661 | AD11: 44.695644
C12: Personal vehicles | D12: ER_TRANS_PRIVATE_coal_1 | E12: ER_TRANS_PRIVATE_oil_1 | F12: ER_TRANS_PRIVATE_elec_1 | G12: ER_TRANS_PRIVATE_gas_1 | H12: =VLOOKUP(D12,Résultats!$B$2:$AX$426,'T energie vecteurs'!F5,FALSE) -> 0 | I12: =VLOOKUP(E12,Résultats!$B$2:$AX$426,'T energie vecteurs'!F5,FALSE) -> 24.200254 | J12: =VLOOKUP(F12,Résultats!$B$2:$AX$426,'T energie vecteurs'!F5,FALSE) -> 0.01816242 | K12: =VLOOKUP(G12,Résultats!$B$2:$AX$426,'T energie vecteurs'!F5,FALSE) -> 1.0589055e-05 | L12: =SUM(H12:K12) -> 24.218427 | N12: Personal vehicles | U12: Personal vehicles | V12: ER_TRANS_PRIVATE_coal_1 | W12: ER_TRANS_PRIVATE_oil_1 | X12: ER_TRANS_PRIVATE_elec_1 | Y12: ER_TRANS_PRIVATE_gas_1 | Z12: 0 | AA12: 24.198348 | AB12: 0.01818778 | AC12: 1.0630953e-05 | AD12: 24.216546
C13: Public and freight transport | D13: ER_TRANS_PUBLIC_coal_1 | E13: ER_TRANS_PUBLIC_oil_1 | F13: ER_TRANS_PUBLIC_elec_1 | G13: ER_TRANS_PUBLIC_gas_1 | H13: =VLOOKUP(D13,Résultats!$B$2:$AX$426,'T energie vecteurs'!F5,FALSE) -> 0 | I13: =VLOOKUP(E13,Résultats!$B$2:$AX$426,'T energie vecteurs'!F5,FALSE) -> 18.945435 | J13: =VLOOKUP(F13,Résultats!$B$2:$AX$426,'T energie vecteurs'!F5,FALSE) -> 1.2688078 | K13: =VLOOKUP(G13,Résultats!$B$2:$AX$426,'T energie vecteurs'!F5,FALSE) -> 0.24533274 | L13: =SUM(H13:K13) -> 20.459576 | N13: Public and freight transport | U13: Public and freight transport | V13: ER_TRANS_PUBLIC_coal_1 | W13: ER_TRANS_PUBLIC_oil_1 | X13: ER_TRANS_PUBLIC_elec_1 | Y13: ER_TRANS_PUBLIC_gas_1 | Z13: 0 | AA13: 18.961203 | AB13: 1.268559 | AC13: 0.24933598 | AD13: 20.479098
C14: Residential | D14: ER_RESIDENTIAL_coal_1 | E14: ER_RESIDENTIAL_oil_1 | F14: ER_RESIDENTIAL_elec_1 | G14: ER_RESIDENTIAL_gas_1 | H14: =VLOOKUP(D14,Résultats!$B$2:$AX$426,'T energie vecteurs'!F5,FALSE) -> 0.33122045 | I14: =VLOOKUP(E14,Résultats!$B$2:$AX$426,'T energie vecteurs'!F5,FALSE) -> 7.2440592 | J14: =VLOOKUP(F14,Résultats!$B$2:$AX$426,'T energie vecteurs'!F5,FALSE) -> 13.732729 | K14: =VLOOKUP(G14,Résultats!$B$2:$AX$426,'T energie vecteurs'!F5,FALSE)+2 -> 19.71798 | L14: =SUM(H14:K14) -> 41.025989 | N14: Residential | O14: ='[1]Bilan 2015'!$V$46 -> 0.036764197 | P14: =SUM('[1]Bilan 2015'!$V$41:$V$43) -> 6.6752954 | Q14: ='[1]Bilan 2015'!$V$13 -> 13.620367 | R14: =('[1]Bilan 2015'!$V$22+'[1]Bilan 2015'!$V$30+SUM('[1]Bilan 2015'!$V$36:$V$40)+SUM('[1]Bilan 2015'!$V$44:$V$45)+'[1]Bilan 2015'!$V$47) -> 21.832864 | S14: =SUM(O14:R14) -> 42.16529 | T14: =S14-'[1]Bilan 2015'!$V$40 -> 39.648469 | U14: Residential | V14: ER_RESIDENTIAL_coal_1 | W14: ER_RESIDENTIAL_oil_1 | X14: ER_RESIDENTIAL_elec_1 | Y14: ER_RESIDENTIAL_gas_1 | Z14: 0.33135186 | AA14: 7.2415499 | AB14: 13.750647 | AC14: 19.70225 | AD14: 41.025798
C15: Service | D15: ER_TERTIARY_coal_1 | E15: ER_TERTIARY_oil_1 | F15: ER_TERTIARY_elec_1 | G15: ER_TERTIARY_gas_1 | H15: =VLOOKUP(D15,Résultats!$B$2:$AX$426,'T energie vecteurs'!F5,FALSE) -> 0 | I15: =VLOOKUP(E15,Résultats!$B$2:$AX$426,'T energie vecteurs'!F5,FALSE) -> 3.7835587 | J15: =VLOOKUP(F15,Résultats!$B$2:$AX$426,'T energie vecteurs'!F5,FALSE) -> 11.548634 | K15: =VLOOKUP(G15,Résultats!$B$2:$AX$426,'T energie vecteurs'!F5,FALSE) -> 9.1338787 | L15: =SUM(H15:K15) -> 24.466072 | N15: Service | O15: ='[1]Bilan 2015'!$W$46 -> 0.043073392 | P15: =SUM('[1]Bilan 2015'!$W$41:$W$43) -> 3.0154656 | Q15: ='[1]Bilan 2015'!$W$13 -> 12.701365 | R15: =('[1]Bilan 2015'!$W$22+'[1]Bilan 2015'!$W$30+SUM('[1]Bilan 2015'!$W$36:$W$40)+SUM('[1]Bilan 2015'!$W$44:$W$45)+'[1]Bilan 2015'!$W$47) -> 8.7461122 | S15: =SUM(O15:R15) -> 24.506017 | T15: =S15-'[1]Bilan 2015'!$W$40 -> 24.06751 | U15: Service | V15: ER_TERTIARY_coal_1 | W15: ER_TERTIARY_oil_1 | X15: ER_TERTIARY_elec_1 | Y15: ER_TERTIARY_gas_1 | Z15: 0 | AA15: 3.7813464 | AB15: 11.575224 | AC15: 9.1357403 | AD15: 24.492311
C16: Industry and agriculture | H16: =SUM(H17:H19) -> 5.0121731 | I16: =SUM(I17:I19) -> 19.057018 | J16: =SUM(J17:J19) -> 11.272502 | K16: =SUM(K17:K19) -> 14.707402 | L16: =SUM(H16:K16) -> 50.049095 | N16: Industry | O16: =O17+O18 -> 4.2636281 | P16: =P17+P18 -> 14.865721 | Q16: =Q17+Q18 -> 10.069552 | R16: =R17+R18 -> 13.7564 | S16: =SUM(O16:R16) -> 42.955301 | T16: =S16 -> 42.955301 | U16: Industry and agriculture | Z16: 5.0051719 | AA16: 19.268937 | AB16: 11.283135 | AC16: 14.723693 | AD16: 50.280937
C17: Industry | D17: ER_INDUS_coal_1 | E17: ER_INDUS_oil_1 | F17: ER_INDUS_elec_1 | G17: ER_INDUS_gas_1 | H17: =VLOOKUP(D17,Résultats!$B$2:$AX$426,'T energie vecteurs'!F5,FALSE) -> 4.0136333 | I17: =VLOOKUP(E17,Résultats!$B$2:$AX$426,'T energie vecteurs'!F5,FALSE) -> 14.689397 | J17: =VLOOKUP(F17,Résultats!$B$2:$AX$426,'T energie vecteurs'!F5,FALSE) -> 10.953796 | K17: =VLOOKUP(G17,Résultats!$B$2:$AX$426,'T energie vecteurs'!F5,FALSE) -> 12.544766 | L17: =SUM(H17:K17) -> 42.201592 | N17: Industry energetic uses | O17: ='[1]Bilan 2015'!$U$46 -> 1.0493093 | P17: =SUM('[1]Bilan 2015'!$U$41:$U$43) -> 2.4127207 | Q17: ='[1]Bilan 2015'!$U$13 -> 10.069552 | R17: =('[1]Bilan 2015'!$U$22+'[1]Bilan 2015'!$U$30+SUM('[1]Bilan 2015'!$U$36:$U$40)+SUM('[1]Bilan 2015'!$U$44:$U$45)+'[1]Bilan 2015'!$U$47) -> 12.654814 | S17: =SUM(O17:R17) -> 26.186396 | U17: Industry | V17: ER_INDUS_coal_1 | W17: ER_INDUS_oil_1 | X17: ER_INDUS_elec_1 | Y17: ER_INDUS_gas_1 | Z17: 4.006287 | AA17: 14.897875 | AB17: 10.963479 | AC17: 12.561498 | AD17: 42.429138
C18: Industry non energetic uses | D18: Q_Mtep_indus_21_1 | E18: Q_Mtep_indus_22_1 | F18: Q_Mtep_indus_23_1 | G18: Q_Mtep_indus_24_1 | H18: =VLOOKUP(D18,Résultats!$B$2:$AX$426,'T energie vecteurs'!F5,FALSE) -> 0.99853977 | I18: =VLOOKUP(E18,Résultats!$B$2:$AX$426,'T energie vecteurs'!F5,FALSE) -> 1.8930036 | J18: =VLOOKUP(F18,Résultats!$B$2:$AX$426,'T energie vecteurs'!F5,FALSE) -> 0 | K18: =VLOOKUP(G18,Résultats!$B$2:$AX$426,'T energie vecteurs'!F5,FALSE) -> 1.7689436 | L18: =SUM(H18:K18) -> 4.660487 | N18: Industry non energetic uses | O18: ='[1]Bilan 2015'!$E$52 -> 3.2143188 | P18: =('[1]Bilan 2015'!$E$54+'[1]Bilan 2015'!$E$56) -> 12.453 | Q18: 0 | R18: =('[1]Bilan 2015'!$E$53+'[1]Bilan 2015'!$E$55+'[1]Bilan 2015'!$E$57) -> 1.1015862 | S18: =SUM(O18:R18) -> 16.768905 | U18: Industry non energetic uses | V18: Q_Mtep_indus_21_1 | W18: Q_Mtep_indus_22_1 | X18: Q_Mtep_indus_23_1 | Y18: Q_Mtep_indus_24_1 | Z18: 0.99888499 | AA18: 1.8924925 | AB18: 0 | AC18: 1.7678344 | AD18: 4.6592119
C19: Agriculture | D19: ER_AGRICULTURE_coal_1 | E19: ER_AGRICULTURE_oil_1 | F19: ER_AGRICULTURE_elec_1 | G19: ER_AGRICULTURE_gas_1 | H19: =VLOOKUP(D19,Résultats!$B$2:$AX$426,'T energie vecteurs'!F5,FALSE) -> 0 | I19: =VLOOKUP(E19,Résultats!$B$2:$AX$426,'T energie vecteurs'!F5,FALSE) -> 2.4746179 | J19: =VLOOKUP(F19,Résultats!$B$2:$AX$426,'T energie vecteurs'!F5,FALSE) -> 0.31870576 | K19: =VLOOKUP(G19,Résultats!$B$2:$AX$426,'T energie vecteurs'!F5,FALSE) -> 0.39369217 | L19: =SUM(H19:K19) -> 3.1870158 | N19: Agriculture | O19: ='[1]Bilan 2015'!$T$46 -> 0.0022137193 | P19: =SUM('[1]Bilan 2015'!$T$41:$T$43) -> 3.4936668 | Q19: ='[1]Bilan 2015'!$T$13 -> 0.74651763 | R19: =('[1]Bilan 2015'!$T$22+'[1]Bilan 2015'!$T$30+SUM('[1]Bilan 2015'!$T$36:$T$40)+SUM('[1]Bilan 2015'!$T$44:$T$45)+'[1]Bilan 2015'!$T$47) -> 0.24365267 | S19: =SUM(O19:R19) -> 4.4860508 | T19: =S19 -> 4.4860508 | U19: Agriculture | V19: ER_AGRICULTURE_coal_1 | W19: ER_AGRICULTURE_oil_1 | X19: ER_AGRICULTURE_elec_1 | Y19: ER_AGRICULTURE_gas_1 | Z19: 0 | AA19: 2.4785695 | AB19: 0.31965679 | AC19: 0.39436076 | AD19: 3.192587
C20: Total Final Mtep | H20: =SUM(H11,H14:H16) -> 5.3433935 | I20: =SUM(I11,I14:I16) -> 73.230325 | J20: =SUM(J11,J14:J16) -> 37.840835 | K20: =SUM(K11,K14:K16) -> 43.804604 | L20: =SUM(H20:K20) -> 160.21916 | N20: Total Final Mtep | O20: =O11+O14+O15+O16+O19 -> 4.3456794 | P20: =P11+P14+P15+P16+P19 -> 70.798845 | Q20: =Q11+Q14+Q15+Q16+Q19 -> 38.082514 | R20: =R11+R14+R15+R16+R19 -> 44.651703 | S20: =SUM(O20:R20) -> 157.87874 | T20: =SUM(T11:T19) -> 154.92341 | U20: Total Final Mtep | Z20: 5.3365238 | AA20: 73.451384 | AB20: 37.895753 | AC20: 43.81103 | AD20: 160.49469
S21: =S11+S14+S15+S16+S19 -> 157.87874
C23: 2020 | H23: coal | I23: fuel and biofuel | J23: elec | K23: gas biogas biomass | L23: Total | N23: 2020 | O23: coal | P23: fuel and biofuel | Q23: elec | R23: gas biogas biomass | S23: Total | T23: Hors chal env PAC | U23: 2020 | Z23: coal | AA23: fuel and biofuel | AB23: elec | AC23: gas biogas biomass | AD23: Total
C24: Transport | H24: =SUM(H25:H26) -> 0 | I24: =SUM(I25:I26) -> 41.563023 | J24: =SUM(J25:J26) -> 1.5156367 | K24: =SUM(K25:K26) -> 0.27412866 | L24: =SUM(H24:K24) -> 43.352788 | N24: Transport | O24: ='[1]Bilan 2020'!$X$46/11.63 -> 0 | P24: =SUM('[1]Bilan 2020'!$X$41:$X$43)/11.63 -> 35.668036 | Q24: ='[1]Bilan 2020'!$X$13/11.63 -> 0.71687008 | R24: =('[1]Bilan 2020'!$X$22+'[1]Bilan 2020'!$X$30+SUM('[1]Bilan 2020'!$X$36:$X$40)+SUM('[1]Bilan 2020'!$X$44:$X$45)+'[1]Bilan 2020'!$X$47)/11.63 -> 0.19326866 | S24: =SUM(O24:R24) -> 36.578175 | T24: =S24 -> 36.578175 | U24: Transport | Z24: 0 | AA24: 41.602539 | AB24: 1.5063126 | AC24: 0.27860242 | AD24: 43.387454
C25: Personal vehicles | D25: ER_TRANS_PRIVATE_coal_1 | E25: ER_TRANS_PRIVATE_oil_1 | F25: ER_TRANS_PRIVATE_elec_1 | G25: ER_TRANS_PRIVATE_gas_1 | H25: =VLOOKUP(D25,Résultats!$B$2:$AX$426,'T energie vecteurs'!I5,FALSE) -> 0 | I25: =VLOOKUP(E25,Résultats!$B$2:$AX$426,'T energie vecteurs'!I5,FALSE) -> 23.247082 | J25: =VLOOKUP(F25,Résultats!$B$2:$AX$426,'T energie vecteurs'!I5,FALSE) -> 0.07237004 | K25: =VLOOKUP(G77,Résultats!$B$2:$AX$426,'T energie vecteurs'!I5,FALSE) -> 1.4664156e-05 | L25: =SUM(H25:K25) -> 23.319467 | N25: Personal vehicles | U25: Personal vehicles | V25: ER_TRANS_PRIVATE_coal_1 | W25: ER_TRANS_PRIVATE_oil_1 | X25: ER_TRANS_PRIVATE_elec_1 | Y25: ER_TRANS_PRIVATE_gas_1 | Z25: 0 | AA25: 23.244407 | AB25: 0.072506889 | AC25: 1.4761104e-05 | AD25: 23.316929
C26: Public and freight transport | D26: ER_TRANS_PUBLIC_coal_1 | E26: ER_TRANS_PUBLIC_oil_1 | F26: ER_TRANS_PUBLIC_elec_1 | G26: ER_TRANS_PUBLIC_gas_1 | H26: =VLOOKUP(D26,Résultats!$B$2:$AX$426,'T energie vecteurs'!I5,FALSE) -> 0 | I26: =VLOOKUP(E26,Résultats!$B$2:$AX$426,'T energie vecteurs'!I5,FALSE) -> 18.315941 | J26: =VLOOKUP(F26,Résultats!$B$2:$AX$426,'T energie vecteurs'!I5,FALSE) -> 1.4432666 | K26: =VLOOKUP(G26,Résultats!$B$2:$AX$426,'T energie vecteurs'!I5,FALSE) -> 0.27411399 | L26: =SUM(H26:K26) -> 20.033321 | N26: Public and freight transport | U26: Public and freight transport | V26: ER_TRANS_PUBLIC_coal_1 | W26: ER_TRANS_PUBLIC_oil_1 | X26: ER_TRANS_PUBLIC_elec_1 | Y26: ER_TRANS_PUBLIC_gas_1 | Z26: 0 | AA26: 18.358132 | AB26: 1.4338057 | AC26: 0.27858766 | AD26: 20.070525
C27: Residential | D27: ER_RESIDENTIAL_coal_1 | E27: ER_RESIDENTIAL_oil_1 | F27: ER_RESIDENTIAL_elec_1 | G27: ER_RESIDENTIAL_gas_1 | H27: =VLOOKUP(D27,Résultats!$B$2:$AX$426,'T energie vecteurs'!I5,FALSE) -> 0.31808457 | I27: =VLOOKUP(E27,Résultats!$B$2:$AX$426,'T energie vecteurs'!I5,FALSE) -> 6.4323583 | J27: =VLOOKUP(F27,Résultats!$B$2:$AX$426,'T energie vecteurs'!I5,FALSE) -> 14.456508 | K27: =VLOOKUP(G27,Résultats!$B$2:$AX$426,'T energie vecteurs'!I5,FALSE)+2 -> 19.097676 | L27: =SUM(H27:K27) -> 40.304627 | N27: Residential | O27: ='[1]Bilan 2020'!$V$46/11.63 -> 0.020700735 | P27: =SUM('[1]Bilan 2020'!$V$41:$V$43)/11.63 -> 4.2874728 | Q27: ='[1]Bilan 2020'!$V$13/11.63 -> 13.618732 | R27: =('[1]Bilan 2020'!$V$22+'[1]Bilan 2020'!$V$30+SUM('[1]Bilan 2020'!$V$36:$V$40)+SUM('[1]Bilan 2020'!$V$44:$V$45)+'[1]Bilan 2020'!$V$47)/11.63 -> 20.40841 | S27: =SUM(O27:R27) -> 38.335315 | T27: =S27-'[1]Bilan 2020'!$V$40/11.63 -> 35.977053 | U27: Residential | V27: ER_RESIDENTIAL_coal_1 | W27: ER_RESIDENTIAL_oil_1 | X27: ER_RESIDENTIAL_elec_1 | Y27: ER_RESIDENTIAL_gas_1 | Z27: 0.31862762 | AA27: 6.4568025 | AB27: 14.438674 | AC27: 19.172349 | AD27: 40.386453
C28: Service | D28: ER_TERTIARY_coal_1 | E28: ER_TERTIARY_oil_1 | F28: ER_TERTIARY_elec_1 | G28: ER_TERTIARY_gas_1 | H28: =VLOOKUP(D28,Résultats!$B$2:$AX$426,'T energie vecteurs'!I5,FALSE) -> 0 | I28: =VLOOKUP(E28,Résultats!$B$2:$AX$426,'T energie vecteurs'!I5,FALSE) -> 2.7287138 | J28: =VLOOKUP(F28,Résultats!$B$2:$AX$426,'T energie vecteurs'!I5,FALSE) -> 11.176971 | K28: =VLOOKUP(G28,Résultats!$B$2:$AX$426,'T energie vecteurs'!I5,FALSE) -> 7.8117768 | L28: =SUM(H28:K28) -> 21.717462 | N28: Service | O28: =('[1]Bilan 2020'!$W$46)/11.63 -> 0.030546421 | P28: =SUM('[1]Bilan 2020'!$W$41:$W$43)/11.63 -> 2.7068356 | Q28: =('[1]Bilan 2020'!$W$13)/11.63 -> 10.724851 | R28: =('[1]Bilan 2020'!$W$22+'[1]Bilan 2020'!$W$30+SUM('[1]Bilan 2020'!$W$36:$W$40)+SUM('[1]Bilan 2020'!$W$44:$W$45)+'[1]Bilan 2020'!$W$47)/11.63 -> 7.1906336 | S28: =SUM(O28:R28) -> 20.652866 | T28: =S28-'[1]Bilan 2020'!$W$40/11.63 -> 20.267161 | U28: Service | V28: ER_TERTIARY_coal_1 | W28: ER_TERTIARY_oil_1 | X28: ER_TERTIARY_elec_1 | Y28: ER_TERTIARY_gas_1 | Z28: 0 | AA28: 2.7306023 | AB28: 11.12796 | AC28: 7.8713222 | AD28: 21.729884
C29: Industry and agriculture | H29: =SUM(H30:H32) -> 2.6467544 | I29: =SUM(I30:I32) -> 13.432936 | J29: =SUM(J30:J32) -> 9.3590591 | K29: =SUM(K30:K32) -> 15.067846 | L29: =SUM(H29:K29) -> 40.506596 | N29: Industry | O29: =O30+O31 -> 3.1626378 | P29: =P30+P31 -> 13.919974 | Q29: =Q30+Q31 -> 9.0413235 | R29: =R30+R31 -> 14.312071 | S29: =SUM(O29:R29) -> 40.436006 | T29: =S29 -> 40.436006 | U29: Industry and agriculture | Z29: 2.6480606 | AA29: 13.624186 | AB29: 9.2932629 | AC29: 15.184451 | AD29: 40.749961
C30: Industry | D30: ER_INDUS_coal_1 | E30: ER_INDUS_oil_1 | F30: ER_INDUS_elec_1 | G30: ER_INDUS_gas_1 | H30: =VLOOKUP(D30,Résultats!$B$2:$AX$426,'T energie vecteurs'!I5,FALSE) -> 1.7831965 | I30: =VLOOKUP(E30,Résultats!$B$2:$AX$426,'T energie vecteurs'!I5,FALSE) -> 9.1710327 | J30: =VLOOKUP(F30,Résultats!$B$2:$AX$426,'T energie vecteurs'!I5,FALSE) -> 9.0460201 | K30: =VLOOKUP(G30,Résultats!$B$2:$AX$426,'T energie vecteurs'!I5,FALSE) -> 12.596217 | L30: =SUM(H30:K30) -> 32.596467 | N30: Industry energetic uses | O30: ='[1]Bilan 2020'!$U$46/11.63 -> 0.77267988 | P30: =SUM('[1]Bilan 2020'!$U$41:$U$43)/11.63 -> 2.7003588 | Q30: ='[1]Bilan 2020'!$U$13/11.63 -> 9.0413235 | R30: =('[1]Bilan 2020'!$U$22+'[1]Bilan 2020'!$U$30+SUM('[1]Bilan 2020'!$U$36:$U$40)+SUM('[1]Bilan 2020'!$U$44:$U$45)+'[1]Bilan 2020'!$U$47)/11.63 -> 13.277855 | S30: =SUM(O30:R30) -> 25.792217 | U30: Industry | V30: ER_INDUS_coal_1 | W30: ER_INDUS_oil_1 | X30: ER_INDUS_elec_1 | Y30: ER_INDUS_gas_1 | Z30: 1.7843253 | AA30: 9.352929 | AB30: 8.9819417 | AC30: 12.713318 | AD30: 32.832514
C31: Industry non energetic uses | D31: Q_Mtep_indus_21_1 | E31: Q_Mtep_indus_22_1 | F31: Q_Mtep_indus_23_1 | G31: Q_Mtep_indus_24_1 | H31: =VLOOKUP(D31,Résultats!$B$2:$AX$426,'T energie vecteurs'!I5,FALSE) -> 0.86355782 | I31: =VLOOKUP(E31,Résultats!$B$2:$AX$426,'T energie vecteurs'!I5,FALSE) -> 1.8768568 | J31: =VLOOKUP(F31,Résultats!$B$2:$AX$426,'T energie vecteurs'!I5,FALSE) -> 0 | K31: =VLOOKUP(G31,Résultats!$B$2:$AX$426,'T energie vecteurs'!I5,FALSE) -> 2.1040699 | L31: =SUM(H31:K31) -> 4.8444846 | N31: Industry non energetic uses | O31: ='[1]Bilan 2020'!$E$52/11.63 -> 2.3899579 | P31: =('[1]Bilan 2020'!$E$54+'[1]Bilan 2020'!$E$56)/11.63 -> 11.219615 | Q31: 0 | R31: =('[1]Bilan 2020'!$E$53+'[1]Bilan 2020'!$E$55+'[1]Bilan 2020'!$E$57)/11.63 -> 1.0342164 | S31: =SUM(O31:R31) -> 14.643789 | U31: Industry non energetic uses | V31: Q_Mtep_indus_21_1 | W31: Q_Mtep_indus_22_1 | X31: Q_Mtep_indus_23_1 | Y31: Q_Mtep_indus_24_1 | Z31: 0.86373539 | AA31: 1.8760089 | AB31: 0 | AC31: 2.1010242 | AD31: 4.8407685
C32: Agriculture | D32: ER_AGRICULTURE_coal_1 | E32: ER_AGRICULTURE_oil_1 | F32: ER_AGRICULTURE_elec_1 | G32: ER_AGRICULTURE_gas_1 | H32: =VLOOKUP(D32,Résultats!$B$2:$AX$426,'T energie vecteurs'!I5,FALSE) -> 0 | I32: =VLOOKUP(E32,Résultats!$B$2:$AX$426,'T energie vecteurs'!I5,FALSE) -> 2.3850467 | J32: =VLOOKUP(F32,Résultats!$B$2:$AX$426,'T energie vecteurs'!I5,FALSE) -> 0.31303899 | K32: =VLOOKUP(G32,Résultats!$B$2:$AX$426,'T energie vecteurs'!I5,FALSE) -> 0.36755918 | L32: =SUM(H32:K32) -> 3.0656449 | N32: Agriculture | O32: ='[1]Bilan 2020'!$T$46/11.63 -> 0.001321701 | P32: =SUM('[1]Bilan 2020'!$T$41:$T$43)/11.63 -> 3.3486885 | Q32: ='[1]Bilan 2020'!$T$13/11.63 -> 0.69143728 | R32: =('[1]Bilan 2020'!$T$22+'[1]Bilan 2020'!$T$30+SUM('[1]Bilan 2020'!$T$36:$T$40)+SUM('[1]Bilan 2020'!$T$44:$T$45)+'[1]Bilan 2020'!$T$47)/11.63 -> 0.41959097 | S32: =SUM(O32:R32) -> 4.4610384 | T32: =S32 -> 4.4610384 | U32: Agriculture | V32: ER_AGRICULTURE_coal_1 | W32: ER_AGRICULTURE_oil_1 | X32: ER_AGRICULTURE_elec_1 | Y32: ER_AGRICULTURE_gas_1 | Z32: 0 | AA32: 2.3952478 | AB32: 0.31132122 | AC32: 0.37010948 | AD32: 3.0766785
C33: Total Final Mtep | H33: =SUM(H24,H27:H29) -> 2.9648389 | I33: =SUM(I24,I27:I29) -> 64.157032 | J33: =SUM(J24,J27:J29) -> 36.508175 | K33: =SUM(K24,K27:K29) -> 42.251428 | L33: =SUM(H33:K33) -> 145.88147 | N33: Total Final Mtep | O33: =O24+O27+O28+O29+O32 -> 3.2152067 | P33: =P24+P27+P28+P29+P32 -> 59.931007 | Q33: =Q24+Q27+Q28+Q29+Q32 -> 34.793213 | R33: =R24+R27+R28+R29+R32 -> 42.523975 | S33: =SUM(O33:R33) -> 140.4634 | T33: =SUM(T24:T32) -> 137.71943 | U33: Total Final Mtep | Z33: 2.9666883 | AA33: 64.41413 | AB33: 36.366209 | AC33: 42.506725 | AD33: 146.25375
C36: 2022 | H36: coal | I36: fuel and biofuel | J36: elec | K36: gas biogas biomass | L36: Total | N36: 2022 | O36: coal | P36: fuel and biofuel | Q36: elec | R36: gas biogas biomass | S36: Total | T36: Hors chal env PAC | U36: 2022 | Z36: coal | AA36: fuel and biofuel | AB36: elec | AC36: gas biogas biomass | AD36: Total
C37: Transport | H37: =SUM(H38:H39) -> 0 | I37: =SUM(I38:I39) -> 41.556283 | J37: =SUM(J38:J39) -> 1.8293062 | K37: =SUM(K38:K39) -> 0.38453628 | L37: =SUM(H37:K37) -> 43.770126 | N37: Transport | O37: ='[1]Bilan 2022 réel'!$X$46/11.63 -> 0 | P37: =SUM('[1]Bilan 2022 réel'!$X$41:$X$43)/11.63 -> 43.395883 | Q37: ='[1]Bilan 2022 réel'!$X$13/11.63 -> 0.93062752 | R37: =('[1]Bilan 2022 réel'!$X$22+'[1]Bilan 2022 réel'!$X$30+SUM('[1]Bilan 2022 réel'!$X$36:$X$40)+SUM('[1]Bilan 2022 réel'!$X$44:$X$45)+'[1]Bilan 2022 réel'!$X$47)/11.63 -> 0.31885684 | S37: =SUM(O37:R37) -> 44.645367 | T37: =S37 -> 44.645367 | U37: Transport | Z37: 0 | AA37: 41.601708 | AB37: 1.8231851 | AC37: 0.3888431 | AD37: 43.813736
C38: Personal vehicles | D38: ER_TRANS_PRIVATE_coal_1 | E38: ER_TRANS_PRIVATE_oil_1 | F38: ER_TRANS_PRIVATE_elec_1 | G38: ER_TRANS_PRIVATE_gas_1 | H38: =VLOOKUP(D38,Résultats!$B$2:$AX$426,'T energie vecteurs'!K5,FALSE) -> 0 | I38: =VLOOKUP(E38,Résultats!$B$2:$AX$426,'T energie vecteurs'!K5,FALSE) -> 22.927345 | J38: =VLOOKUP(F38,Résultats!$B$2:$AX$426,'T energie vecteurs'!K5,FALSE) -> 0.11841651 | K38: =VLOOKUP(G51,Résultats!$B$2:$AX$426,'T energie vecteurs'!K5,FALSE) -> 1.8276192e-05 | L38: =SUM(H38:K38) -> 23.045779 | N38: Personal vehicles | U38: Personal vehicles | V38: ER_TRANS_PRIVATE_coal_1 | W38: ER_TRANS_PRIVATE_oil_1 | X38: ER_TRANS_PRIVATE_elec_1 | Y38: ER_TRANS_PRIVATE_gas_1 | Z38: 0 | AA38: 22.924827 | AB38: 0.1186245 | AC38: 1.8382908e-05 | AD38: 23.04347
C39: Public and freight transport | D39: ER_TRANS_PUBLIC_coal_1 | E39: ER_TRANS_PUBLIC_oil_1 | F39: ER_TRANS_PUBLIC_elec_1 | G39: ER_TRANS_PUBLIC_gas_1 | H39: =VLOOKUP(D39,Résultats!$B$2:$AX$426,'T energie vecteurs'!K5,FALSE) -> 0 | I39: =VLOOKUP(E39,Résultats!$B$2:$AX$426,'T energie vecteurs'!K5,FALSE) -> 18.628939 | J39: =VLOOKUP(F39,Résultats!$B$2:$AX$426,'T energie vecteurs'!K5,FALSE) -> 1.7108897 | K39: =VLOOKUP(G39,Résultats!$B$2:$AX$426,'T energie vecteurs'!K5,FALSE) -> 0.384518 | L39: =SUM(H39:K39) -> 20.724346 | N39: Public and freight transport | U39: Public and freight transport | V39: ER_TRANS_PUBLIC_coal_1 | W39: ER_TRANS_PUBLIC_oil_1 | X39: ER_TRANS_PUBLIC_elec_1 | Y39: ER_TRANS_PUBLIC_gas_1 | Z39: 0 | AA39: 18.676881 | AB39: 1.7045606 | AC39: 0.38882472 | AD39: 20.770266
C40: Residential | D40: ER_RESIDENTIAL_coal_1 | E40: ER_RESIDENTIAL_oil_1 | F40: ER_RESIDENTIAL_elec_1 | G40: ER_RESIDENTIAL_gas_1 | H40: =VLOOKUP(D40,Résultats!$B$2:$AX$426,'T energie vecteurs'!K5,FALSE) -> 0.30437398 | I40: =VLOOKUP(E40,Résultats!$B$2:$AX$426,'T energie vecteurs'!K5,FALSE) -> 6.2902516 | J40: =VLOOKUP(F40,Résultats!$B$2:$AX$426,'T energie vecteurs'!K5,FALSE) -> 14.518216 | K40: =VLOOKUP(G40,Résultats!$B$2:$AX$426,'T energie vecteurs'!K5,FALSE)+2 -> 18.573275 | L40: =SUM(H40:K40) -> 39.686116 | N40: Residential | O40: ='[1]Bilan 2022 réel'!$V$46/11.63 -> 0.026476317 | P40: =SUM('[1]Bilan 2022 réel'!$V$41:$V$43)/11.63 -> 3.5006052 | Q40: ='[1]Bilan 2022 réel'!$V$13/11.63 -> 13.359407 | R40: =('[1]Bilan 2022 réel'!$V$22+'[1]Bilan 2022 réel'!$V$30+SUM('[1]Bilan 2022 réel'!$V$36:$V$40)+SUM('[1]Bilan 2022 réel'!$V$44:$V$45)+'[1]Bilan 2022 réel'!$V$47)/11.63 -> 20.358937 | S40: =SUM(O40:R40) -> 37.245425 | T40: =S40-'[1]Bilan 2022 réel'!$V$40/11.63 -> 33.844962 | U40: Residential | V40: ER_RESIDENTIAL_coal_1 | W40: ER_RESIDENTIAL_oil_1 | X40: ER_RESIDENTIAL_elec_1 | Y40: ER_RESIDENTIAL_gas_1 | Z40: 0.30501769 | AA40: 6.3077542 | AB40: 14.50955 | AC40: 18.635776 | AD40: 39.758098
C41: Service | D41: ER_TERTIARY_coal_1 | E41: ER_TERTIARY_oil_1 | F41: ER_TERTIARY_elec_1 | G41: ER_TERTIARY_gas_1 | H41: =VLOOKUP(D41,Résultats!$B$2:$AX$426,'T energie vecteurs'!K5,FALSE) -> 0 | I41: =VLOOKUP(E41,Résultats!$B$2:$AX$426,'T energie vecteurs'!K5,FALSE) -> 2.7551192 | J41: =VLOOKUP(F41,Résultats!$B$2:$AX$426,'T energie vecteurs'!K5,FALSE) -> 11.113064 | K41: =VLOOKUP(G41,Résultats!$B$2:$AX$426,'T energie vecteurs'!K5,FALSE) -> 7.7104864 | L41: =SUM(H41:K41) -> 21.57867 | N41: Service | O41: =('[1]Bilan 2022 réel'!$W$46)/11.63 -> 0.032835728 | P41: =SUM('[1]Bilan 2022 réel'!$W$41:$W$43)/11.63 -> 2.081572 | Q41: =('[1]Bilan 2022 réel'!$W$13)/11.63 -> 11.43888 | R41: =('[1]Bilan 2022 réel'!$W$22+'[1]Bilan 2022 réel'!$W$30+SUM('[1]Bilan 2022 réel'!$W$36:$W$40)+SUM('[1]Bilan 2022 réel'!$W$44:$W$45)+'[1]Bilan 2022 réel'!$W$47)/11.63 -> 7.4016622 | S41: =SUM(O41:R41) -> 20.95495 | T41: =S41-'[1]Bilan 2022 réel'!$W$40/11.63 -> 20.53461 | U41: Service | V41: ER_TERTIARY_coal_1 | W41: ER_TERTIARY_oil_1 | X41: ER_TERTIARY_elec_1 | Y41: ER_TERTIARY_gas_1 | Z41: 0 | AA41: 2.755786 | AB41: 11.083352 | AC41: 7.7555464 | AD41: 21.594684
C42: Industry and agriculture | H42: =SUM(H43:H45) -> 2.6037063 | I42: =SUM(I43:I45) -> 13.353275 | J42: =SUM(J43:J45) -> 9.6226564 | K42: =SUM(K43:K45) -> 15.303359 | L42: =SUM(H42:K42) -> 40.882997 | N42: Industry | O42: =O43+O44 -> 4.5030918 | P42: =P43+P44 -> 11.747675 | Q42: =Q43+Q44 -> 9.2559822 | R42: =R43+R44 -> 13.798624 | S42: =SUM(O42:R42) -> 39.305373 | T42: =S42 -> 39.305373 | U42: Industry and agriculture | Z42: 2.6055347 | AA42: 13.593339 | AB42: 9.5610733 | AC42: 15.432164 | AD42: 41.192111
C43: Industry | D43: ER_INDUS_coal_1 | E43: ER_INDUS_oil_1 | F43: ER_INDUS_elec_1 | G43: ER_INDUS_gas_1 | H43: =VLOOKUP(D43,Résultats!$B$2:$AX$426,'T energie vecteurs'!K5,FALSE) -> 1.7321576 | I43: =VLOOKUP(E43,Résultats!$B$2:$AX$426,'T energie vecteurs'!K5,FALSE) -> 8.933332 | J43: =VLOOKUP(F43,Résultats!$B$2:$AX$426,'T energie vecteurs'!K5,FALSE) -> 9.3025763 | K43: =VLOOKUP(G43,Résultats!$B$2:$AX$426,'T energie vecteurs'!K5,FALSE) -> 12.783319 | L43: =SUM(H43:K43) -> 32.751384 | N43: Industry energetic uses | O43: ='[1]Bilan 2022 réel'!$U$46/11.63 -> 0.63402045 | P43: =SUM('[1]Bilan 2022 réel'!$U$41:$U$43)/11.63 -> 2.477583 | Q43: ='[1]Bilan 2022 réel'!$U$13/11.63 -> 9.2559822 | R43: =('[1]Bilan 2022 réel'!$U$22+'[1]Bilan 2022 réel'!$U$30+SUM('[1]Bilan 2022 réel'!$U$36:$U$40)+SUM('[1]Bilan 2022 réel'!$U$44:$U$45)+'[1]Bilan 2022 réel'!$U$47)/11.63 -> 12.926273 | S43: =SUM(O43:R43) -> 25.293858 | U43: Industry | V43: ER_INDUS_coal_1 | W43: ER_INDUS_oil_1 | X43: ER_INDUS_elec_1 | Y43: ER_INDUS_gas_1 | Z43: 1.7329112 | AA43: 9.1647792 | AB43: 9.2421087 | AC43: 12.91308 | AD43: 33.052879
C44: Industry non energetic uses | D44: Q_Mtep_indus_21_1 | E44: Q_Mtep_indus_22_1 | F44: Q_Mtep_indus_23_1 | G44: Q_Mtep_indus_24_1 | H44: =VLOOKUP(D44,Résultats!$B$2:$AX$426,'T energie vecteurs'!K5,FALSE) -> 0.87154876 | I44: =VLOOKUP(E44,Résultats!$B$2:$AX$426,'T energie vecteurs'!K5,FALSE) -> 1.9175551 | J44: =VLOOKUP(F44,Résultats!$B$2:$AX$426,'T energie vecteurs'!K5,FALSE) -> 0 | K44: =VLOOKUP(G44,Résultats!$B$2:$AX$426,'T energie vecteurs'!K5,FALSE) -> 2.1408492 | L44: =SUM(H44:K44) -> 4.9299531 | N44: Industry non energetic uses | O44: ='[1]Bilan 2022 réel'!$E$52/11.63 -> 3.8690713 | P44: =('[1]Bilan 2022 réel'!$E$54+'[1]Bilan 2022 réel'!$E$56)/11.63 -> 9.270092 | Q44: 0 | R44: =('[1]Bilan 2022 réel'!$E$53+'[1]Bilan 2022 réel'!$E$55+'[1]Bilan 2022 réel'!$E$57)/11.63 -> 0.87235178 | S44: =SUM(O44:R44) -> 14.011515 | U44: Industry non energetic uses | V44: Q_Mtep_indus_21_1 | W44: Q_Mtep_indus_22_1 | X44: Q_Mtep_indus_23_1 | Y44: Q_Mtep_indus_24_1 | Z44: 0.87262353 | AA44: 1.9166294 | AB44: 0 | AC44: 2.1376736 | AD44: 4.9269265
C45: Agriculture | D45: ER_AGRICULTURE_coal_1 | E45: ER_AGRICULTURE_oil_1 | F45: ER_AGRICULTURE_elec_1 | G45: ER_AGRICULTURE_gas_1 | H45: =VLOOKUP(D45,Résultats!$B$2:$AX$426,'T energie vecteurs'!K5,FALSE) -> 0 | I45: =VLOOKUP(E45,Résultats!$B$2:$AX$426,'T energie vecteurs'!K5,FALSE) -> 2.5023883 | J45: =VLOOKUP(F45,Résultats!$B$2:$AX$426,'T energie vecteurs'!K5,FALSE) -> 0.32008009 | K45: =VLOOKUP(G45,Résultats!$B$2:$AX$426,'T energie vecteurs'!K5,FALSE) -> 0.37919082 | L45: =SUM(H45:K45) -> 3.2016593 | N45: Agriculture | O45: ='[1]Bilan 2022 réel'!$T$46/11.63 -> 0.001651664 | P45: =SUM('[1]Bilan 2022 réel'!$T$41:$T$43)/11.63 -> 3.5697769 | Q45: ='[1]Bilan 2022 réel'!$T$13/11.63 -> 0.67291488 | R45: =('[1]Bilan 2022 réel'!$T$22+'[1]Bilan 2022 réel'!$T$30+SUM('[1]Bilan 2022 réel'!$T$36:$T$40)+SUM('[1]Bilan 2022 réel'!$T$44:$T$45)+'[1]Bilan 2022 réel'!$T$47)/11.63 -> 0.43996563 | S45: =SUM(O45:R45) -> 4.6843091 | T45: =S45 -> 4.6843091 | U45: Agriculture | V45: ER_AGRICULTURE_coal_1 | W45: ER_AGRICULTURE_oil_1 | X45: ER_AGRICULTURE_elec_1 | Y45: ER_AGRICULTURE_gas_1 | Z45: 0 | AA45: 2.5119302 | AB45: 0.31896459 | AC45: 0.38141049 | AD45: 3.2123052
C46: Total Final Mtep | H46: =SUM(H37,H40:H42) -> 2.9080803 | I46: =SUM(I37,I40:I42) -> 63.95493 | J46: =SUM(J37,J40:J42) -> 37.083243 | K46: =SUM(K37,K40:K42) -> 41.971656 | L46: =SUM(H46:K46) -> 145.91791 | N46: Total Final Mtep | O46: =O37+O40+O41+O42+O45 -> 4.5640555 | P46: =P37+P40+P41+P42+P45 -> 64.295512 | Q46: =Q37+Q40+Q41+Q42+Q45 -> 35.657811 | R46: =R37+R40+R41+R42+R45 -> 42.318046 | S46: =SUM(O46:R46) -> 146.83542 | T46: =SUM(T37:T45) -> 143.01462 | U46: Total Final Mtep | Z46: 2.9105524 | AA46: 64.258587 | AB46: 36.977161 | AC46: 42.212329 | AD46: 146.35863
