Workbook

Sheet results
B1: 2004 | C1: 2005 | D1: 2006 | E1: 2007 | F1: 2008 | G1: 2009 | H1: 2010 | I1: 2011 | J1: 2012 | K1: 2013 | L1: 2014 | M1: 2015 | N1: 2016 | O1: 2017 | P1: 2018 | Q1: 2019 | R1: 2020 | S1: 2021 | T1: 2022 | U1: 2023 | V1: 2024 | W1: 2025 | X1: 2026 | Y1: 2027 | Z1: 2028 | AA1: 2029 | AB1: 2030 | AC1: 2031 | AD1: 2032 | AE1: 2033 | AF1: 2034 | AG1: 2035 | AH1: 2036 | AI1: 2037 | AJ1: 2038 | AK1: 2039 | AL1: 2040 | AM1: 2041 | AN1: 2042 | AO1: 2043 | AP1: 2044 | AQ1: 2045 | AR1: 2046 | AS1: 2047 | AT1: 2048 | AU1: 2049 | AV1: 2050
A2: PENER_01_1 | B2: 0.96116878 | C2: 0.98039216 | D2: 0.98481957 | E2: 0.9820174 | F2: 1.0577885 | G2: 0.94206518 | H2: 0.99334562 | I2: 1.0846404 | J2: 1.1631807 | K2: 1.1509188 | L2: 1.1107503 | M2: 1.0067624 | N2: 0.94502675 | O2: 1.0030323 | P2: 1.1340851 | Q2: 1.1426764 | R2: 1.171919 | S2: 1.2017553 | T2: 1.23319 | U2: 1.2652729 | V2: 1.3017171 | W2: 1.3398102 | X2: 1.3575654 | Y2: 1.3749817 | Z2: 1.3924237 | AA2: 1.4101569 | AB2: 1.4280661 | AC2: 1.4462895 | AD2: 1.46479 | AE2: 1.4839173 | AF2: 1.503216 | AG2: 1.5228513 | AH2: 1.5431862 | AI2: 1.563849 | AJ2: 1.5851442 | AK2: 1.607025 | AL2: 1.6293302 | AM2: 1.6564137 | AN2: 1.6841311 | AO2: 1.7125788 | AP2: 1.7416443 | AQ2: 1.7714371 | AR2: 1.8030675 | AS2: 1.8353691 | AT2: 1.8682037 | AU2: 1.9016742 | AV2: 1.9359231
A3: PENER_02_1 | B3: 0.96116878 | C3: 0.98039216 | D3: 0.97546158 | E3: 0.96753792 | F3: 1.01232 | G3: 0.95333827 | H3: 0.97141431 | I3: 1.0201514 | J3: 1.0683459 | K3: 1.0662165 | L3: 1.0577615 | M3: 1.0193992 | N3: 1.000848 | O3: 1.0507161 | P3: 1.1585113 | Q3: 1.1910507 | R3: 1.2161625 | S3: 1.238544 | T3: 1.2595526 | U3: 1.2791059 | V3: 1.31131 | W3: 1.3415766 | X3: 1.3624001 | Y3: 1.3837465 | Z3: 1.4047844 | AA3: 1.4257423 | AB3: 1.4466188 | AC3: 1.4671967 | AD3: 1.4887028 | AE3: 1.5113883 | AF3: 1.5333898 | AG3: 1.5557161 | AH3: 1.5793966 | AI3: 1.6032614 | AJ3: 1.6279846 | AK3: 1.6532823 | AL3: 1.6792223 | AM3: 1.7066082 | AN3: 1.7343866 | AO3: 1.7629924 | AP3: 1.7922853 | AQ3: 1.8222591 | AR3: 1.8532891 | AS3: 1.8850487 | AT3: 1.9172398 | AU3: 1.9500315 | AV3: 1.9835231
A4: PENER_03_1 | B4: 0.96116878 | C4: 0.98039216 | D4: 0.97839691 | E4: 0.97241638 | F4: 1.0242882 | G4: 0.95147162 | H4: 0.9797034 | I4: 1.0393625 | J4: 1.0938273 | K4: 1.0892693 | L4: 1.063243 | M4: 0.99735466 | N4: 0.95615294 | O4: 0.99795819 | P4: 1.0924947 | Q4: 1.1193781 | R4: 1.1485884 | S4: 1.1733641 | T4: 1.1989194 | U4: 1.2230707 | V4: 1.2563255 | W4: 1.2887532 | X4: 1.309126 | Y4: 1.3293655 | Z4: 1.3493803 | AA4: 1.3694857 | AB4: 1.3895411 | AC4: 1.4096023 | AD4: 1.4301396 | AE4: 1.4515949 | AF4: 1.4725951 | AG4: 1.4938865 | AH4: 1.5161295 | AI4: 1.538621 | AJ4: 1.5619242 | AK4: 1.5857961 | AL4: 1.610265 | AM4: 1.6373851 | AN4: 1.6649946 | AO4: 1.6934315 | AP4: 1.72254 | AQ4: 1.7523594 | AR4: 1.7835465 | AS4: 1.815487 | AT4: 1.8478674 | AU4: 1.8808557 | AV4: 1.9145582
A5: PENER_04_1 | B5: 0.96116878 | C5: 0.98039216 | D5: 0.97350205 | E5: 0.96406323 | F5: 1.0054403 | G5: 0.95375668 | H5: 1.0459923 | I5: 1.0828955 | J5: 1.1255274 | K5: 1.1259294 | L5: 1.1003692 | M5: 1.0516206 | N5: 1.0250977 | O5: 1.0595291 | P5: 1.1419885 | Q5: 1.2090155 | R5: 1.2615381 | S5: 1.3293096 | T5: 1.4030516 | U5: 1.4835761 | V5: 1.5987526 | W5: 1.7307014 | X5: 1.7546307 | Y5: 1.7838023 | Z5: 1.8135354 | AA5: 1.8432959 | AB5: 1.8729916 | AC5: 1.9051931 | AD5: 1.9383929 | AE5: 1.9732022 | AF5: 2.0071345 | AG5: 2.0414506 | AH5: 2.0798942 | AI5: 2.1186583 | AJ5: 2.1586828 | AK5: 2.1995585 | AL5: 2.2414678 | AM5: 2.327235 | AN5: 2.4148375 | AO5: 2.5068247 | AP5: 2.6036536 | AQ5: 2.705602 | AR5: 2.7788305 | AS5: 2.8567584 | AT5: 2.9372612 | AU5: 3.0202854 | AV5: 3.1060179
A6: PENER_05_1 | B6: 0.96116878 | C6: 0.98039216 | D6: 0.97849171 | E6: 0.9717304 | F6: 1.029391 | G6: 0.94848267 | H6: 1.0853383 | I6: 1.1442887 | J6: 1.202205 | K6: 1.198375 | L6: 1.1635383 | M6: 1.0894863 | N6: 1.0549041 | O6: 1.1054335 | P6: 1.2118422 | Q6: 1.2809385 | R6: 1.3462606 | S6: 1.4394275 | T6: 1.5473905 | U6: 1.6711293 | V6: 1.8348946 | W6: 2.0273718 | X6: 2.0571379 | Y6: 2.0926018 | Z6: 2.1288159 | AA6: 2.1650855 | AB6: 2.2012992 | AC6: 2.2412255 | AD6: 2.2822094 | AE6: 2.3250487 | AF6: 2.3674149 | AG6: 2.4102811 | AH6: 2.4579925 | AI6: 2.5063359 | AJ6: 2.55611 | AK6: 2.6070198 | AL6: 2.6591891 | AM6: 2.7862268 | AN6: 2.9173866 | AO6: 3.056047 | AP6: 3.2030081 | AQ6: 3.3588083 | AR6: 3.4660333 | AS6: 3.580454 | AT6: 3.6993018 | AU6: 3.8224002 | AV6: 3.9500125
A7: PENER_06_1 | B7: 0.96116878 | C7: 0.98039216 | D7: 0.97308567 | E7: 0.96419399 | F7: 1.0011798 | G7: 0.95854001 | H7: 1.0348182 | I7: 1.0668694 | J7: 1.1025327 | K7: 1.1033007 | L7: 1.0841803 | M7: 1.0466228 | N7: 1.025854 | O7: 1.0569216 | P7: 1.1281882 | Q7: 1.1872434 | R7: 1.2316257 | S7: 1.2876861 | T7: 1.3476598 | U7: 1.4111908 | V7: 1.499232 | W7: 1.5963786 | X7: 1.6193456 | Y7: 1.6470773 | Z7: 1.6753405 | AA7: 1.7037469 | AB7: 1.7320941 | AC7: 1.7620014 | AD7: 1.7927893 | AE7: 1.8250319 | AF7: 1.8563666 | AG7: 1.8880588 | AH7: 1.9226677 | AI7: 1.9575271 | AJ7: 1.9936296 | AK7: 2.0304988 | AL7: 2.0683463 | AM7: 2.1364865 | AN7: 2.2054082 | AO7: 2.2773224 | AP7: 2.3525472 | AQ7: 2.4312678 | AR7: 2.4907774 | AS7: 2.5541124 | AT7: 2.6192993 | AU7: 2.6863425 | AV7: 2.755378
A8: PENER_07_1 | B8: 0.96116878 | C8: 0.98039216 | D8: 0.97220384 | E8: 0.96111183 | F8: 1.0098942 | G8: 0.94972253 | H8: 1.015128 | I8: 1.0572021 | J8: 1.1038818 | K8: 1.0996044 | L8: 1.0671038 | M8: 1.0096677 | N8: 0.97374846 | O8: 1.0094517 | P8: 1.0964 | Q8: 1.1566677 | R8: 1.2100836 | S8: 1.2747058 | T8: 1.3452277 | U8: 1.4243318 | V8: 1.5421698 | W8: 1.6810454 | X8: 1.7061585 | Y8: 1.7338382 | Z8: 1.7614303 | AA8: 1.7887656 | AB8: 1.8159315 | AC8: 1.8456676 | AD8: 1.8765081 | AE8: 1.9089296 | AF8: 1.940576 | AG8: 1.9726195 | AH8: 2.0090816 | AI8: 2.0458795 | AJ8: 2.0838221 | AK8: 2.1225936 | AL8: 2.1623354 | AM8: 2.2483292 | AN8: 2.3383961 | AO8: 2.434194 | AP8: 2.5360995 | AQ8: 2.644463 | AR8: 2.7222419 | AS8: 2.8039966 | AT8: 2.8886276 | AU8: 2.9762388 | AV8: 3.0670963
A9: PENER_08_1 | B9: 0.96116878 | C9: 0.98039216 | D9: 0.98543311 | E9: 0.98214258 | F9: 1.0716623 | G9: 0.93165525 | H9: 0.99454834 | I9: 1.0986249 | J9: 1.1884443 | K9: 1.1691777 | L9: 1.107488 | M9: 0.97411789 | N9: 0.88997052 | O9: 0.94172355 | P9: 1.0646733 | Q9: 1.066462 | R9: 1.1004576 | S9: 1.1367462 | T9: 1.1745888 | U9: 1.2143664 | V9: 1.2580064 | W9: 1.3046192 | X9: 1.3209482 | Y9: 1.3371895 | Z9: 1.3531012 | AA9: 1.3689808 | AB9: 1.3848152 | AC9: 1.4024501 | AD9: 1.4204024 | AE9: 1.4389465 | AF9: 1.4576748 | AG9: 1.4767539 | AH9: 1.4966087 | AI9: 1.516803 | AJ9: 1.5374765 | AK9: 1.5586812 | AL9: 1.5802272 | AM9: 1.6091991 | AN9: 1.6388178 | AO9: 1.6693303 | AP9: 1.7006978 | AQ9: 1.7330524 | AR9: 1.7667092 | AS9: 1.8010398 | AT9: 1.8360769 | AU9: 1.8718924 | AV9: 1.9086635
A10: PENER_09_1 | B10: 0.96116878 | C10: 0.98039216 | D10: 0.975318 | E10: 0.96919327 | F10: 1.0032698 | G10: 0.96104558 | H10: 0.98563528 | I10: 1.0260384 | J10: 1.0633689 | K10: 1.0632836 | L10: 1.0461593 | M10: 1.0061736 | N10: 0.98285148 | O10: 1.0129375 | P10: 1.0756308 | Q10: 1.1099376 | R10: 1.1387633 | S10: 1.1678299 | T10: 1.1988274 | U10: 1.2294011 | V10: 1.2712355 | W10: 1.3143427 | X10: 1.336492 | Y10: 1.358595 | Z10: 1.3805849 | AA10: 1.4028876 | AB10: 1.4252002 | AC10: 1.4482692 | AD10: 1.4717547 | AE10: 1.4961024 | AF10: 1.5198704 | AG10: 1.5439578 | AH10: 1.5689708 | AI10: 1.5942504 | AJ10: 1.6206205 | AK10: 1.6475861 | AL10: 1.6753164 | AM10: 1.711993 | AN10: 1.7502771 | AO10: 1.7904704 | AP10: 1.8324877 | AQ10: 1.8764632 | AR10: 1.9161394 | AS10: 1.9572691 | AT10: 1.9992225 | AU10: 2.0422837 | AV10: 2.0865816
A11: PENER_10_1 | B11: 0.96116878 | C11: 0.98039216 | D11: 0.97440671 | E11: 0.96399465 | F11: 1.1055157 | G11: 1.0221528 | H11: 1.1323901 | I11: 1.2087364 | J11: 1.207557 | K11: 1.1410685 | L11: 1.1230813 | M11: 1.09739 | N11: 1.0997901 | O11: 1.1934759 | P11: 1.261086 | Q11: 1.24355 | R11: 1.2994865 | S11: 1.3772248 | T11: 1.4677499 | U11: 1.5715212 | V11: 1.7085364 | W11: 1.8672994 | X11: 1.8930513 | Y11: 1.9252886 | Z11: 1.9586115 | AA11: 1.9925261 | AB11: 2.0265932 | AC11: 2.0634372 | AD11: 2.1010213 | AE11: 2.1400618 | AF11: 2.1786118 | AG11: 2.2177023 | AH11: 2.2601441 | AI11: 2.3031411 | AJ11: 2.3477574 | AK11: 2.3934142 | AL11: 2.4403838 | AM11: 2.5490701 | AN11: 2.6634328 | AO11: 2.7854238 | AP11: 2.9155467 | AQ11: 3.0542659 | AR11: 3.1520279 | AS11: 3.255898 | AT11: 3.3637446 | AU11: 3.4757116 | AV11: 3.5921302
A12: PENER_11_1 | B12: 0.96116878 | C12: 0.98039216 | D12: 0.9705159 | E12: 0.96161514 | F12: 0.98144847 | G12: 0.96569284 | H12: 0.96756149 | I12: 0.98815355 | J12: 1.0120395 | K12: 1.0164759 | L12: 1.017541 | M12: 1.0112514 | N12: 1.0114024 | O12: 1.0437579 | P12: 1.1087744 | Q12: 1.1514658 | R12: 1.1763838 | S12: 1.1955231 | T12: 1.2134815 | U12: 1.2286639 | V12: 1.2577928 | W12: 1.2832173 | X12: 1.3051989 | Y12: 1.3276578 | Z12: 1.349891 | AA12: 1.3722852 | AB12: 1.3946097 | AC12: 1.416518 | AD12: 1.4392072 | AE12: 1.4630058 | AF12: 1.4858346 | AG12: 1.5089651 | AH12: 1.5331666 | AI12: 1.5575061 | AJ12: 1.5829562 | AK12: 1.6089541 | AL12: 1.6357451 | AM12: 1.6628757 | AN12: 1.6905701 | AO12: 1.7191872 | AP12: 1.7485436 | AQ12: 1.7786077 | AR12: 1.809418 | AS12: 1.8411572 | AT12: 1.873206 | AU12: 1.9058358 | AV12: 1.9391177
A13: PENER_12_1 | B13: 0.96116878 | C13: 0.98039216 | D13: 0.97824152 | E13: 0.97194 | F13: 1.0412561 | G13: 0.96473039 | H13: 0.99428994 | I13: 1.0592488 | J13: 1.1037462 | K13: 1.0848418 | L13: 1.0697701 | M13: 1.0206764 | N13: 0.99752417 | O13: 1.0568196 | P13: 1.1612181 | Q13: 1.1778098 | R13: 1.2058392 | S13: 1.2298729 | T13: 1.2540753 | U13: 1.2768671 | V13: 1.310535 | W13: 1.3428264 | X13: 1.3624445 | Y13: 1.3823609 | Z13: 1.4022158 | AA13: 1.4222409 | AB13: 1.4422757 | AC13: 1.4623459 | AD13: 1.4829313 | AE13: 1.5043933 | AF13: 1.5253967 | AG13: 1.54672 | AH13: 1.5689887 | AI13: 1.5915131 | AJ13: 1.6148973 | AK13: 1.6388362 | AL13: 1.6633878 | AM13: 1.690281 | AN13: 1.7177118 | AO13: 1.745966 | AP13: 1.7748891 | AQ13: 1.8045139 | AR13: 1.835294 | AS13: 1.8668584 | AT13: 1.8988281 | AU13: 1.931386 | AV13: 1.9646338
... A235: PVA_2406_2 | B235: 0.96116878 | C235: 0.98039216 | D235: 0.90324703 | E235: 0.94859048 | F235: 1.0446332 | G235: 1.1119483 | H235: 1.1225378 | I235: 1.1085572 | J235: 1.0858225 | K235: 1.0670405 | L235: 1.0575552 | M235: 1.0512942 | N235: 0.97217915 | O235: 0.8964476 | P235: 0.87974845 | Q235: 0.90854867 | R235: 0.96747347 | S235: 1.0048232 | T235: 1.0227665 | U235: 1.0133051 | V235: 1.0168008 | W235: 1.0256613 | X235: 1.0393187 | Y235: 1.0530977 | Z235: 1.0705386 | AA235: 1.0895802 | AB235: 1.1072584 | AC235: 1.1267728 | AD235: 1.1503073 | AE235: 1.1735009 | AF235: 1.196805 | AG235: 1.219628 | AH235: 1.2436573 | AI235: 1.2689407 | AJ235: 1.2948151 | AK235: 1.3196889 | AL235: 1.3407483 | AM235: 1.3647827 | AN235: 1.3946809 | AO235: 1.4244273 | AP235: 1.4538884 | AQ235: 1.483634 | AR235: 1.5114008 | AS235: 1.5339499 | AT235: 1.5584789 | AU235: 1.5845555 | AV235: 1.6112527

Sheet facture énergétique secteurs
C1: =results!B1 -> 2004 | D1: =results!C1 -> 2005 | E1: =results!D1 -> 2006 | F1: =results!E1 -> 2007 | G1: =results!F1 -> 2008 | H1: =results!G1 -> 2009 | I1: =results!H1 -> 2010 | J1: =results!I1 -> 2011 | ... AW1: =results!AV1 -> 2050
A2: AME | B2: facture énergétique du secteur 1 | C2: =results!B2*results!B22 -> 4552.75 | D2: =results!C2*results!C22 -> 4718.3628 | E2: =results!D2*results!D22 -> 4836.3213 | F2: =results!E2*results!E22 -> 4983.3976 | G2: =results!F2*results!F22 -> 5177.2329 | H2: =results!G2*results!G22 -> 4801.3313 | I2: =results!H2*results!H22 -> 5242.2105 | J2: =results!I2*results!I22 -> 5485.6179 | ... AW2: =results!AV2*results!AV22 -> 15680.271
A3: € courants | B3: facture énergétique du secteur 2 | C3: =results!B3*results!B23 -> 3122.6838 | D3: =results!C3*results!C23 -> 3236.2758 | E3: =results!D3*results!D23 -> 3245.8472 | F3: =results!E3*results!E23 -> 3318.5918 | G3: =results!F3*results!F23 -> 3381.9412 | H3: =results!G3*results!G23 -> 3184.9763 | I3: =results!H3*results!H23 -> 3266.6753 | J3: =results!I3*results!I23 -> 3450.3564 | ... AW3: =results!AV3*results!AV23 -> 7890.9032
B4: facture énergétique du secteur 3 | C4: =results!B4*results!B24 -> 984.3809 | D4: =results!C4*results!C24 -> 1020.1892 | E4: =results!D4*results!D24 -> 1045.547 | F4: =results!E4*results!E24 -> 1039.4783 | G4: =results!F4*results!F24 -> 1049.9948 | H4: =results!G4*results!G24 -> 895.15185 | I4: =results!H4*results!H24 -> 992.32129 | J4: =results!I4*results!I24 -> 1035.4307 | ... AW4: =results!AV4*results!AV24 -> 1825.4668
B5: facture énergétique du secteur 4 | C5: =results!B5*results!B25 -> 440.37848 | D5: =results!C5*results!C25 -> 456.39787 | E5: =results!D5*results!D25 -> 460.59521 | F5: =results!E5*results!E25 -> 464.62663 | G5: =results!F5*results!F25 -> 454.09345 | H5: =results!G5*results!G25 -> 373.26076 | I5: =results!H5*results!H25 -> 413.66834 | J5: =results!I5*results!I25 -> 477.33066 | ... AW5: =results!AV5*results!AV25 -> 2813.1422
B6: facture énergétique du secteur 5 | C6: =results!B6*results!B26 -> 1069.7566 | D6: =results!C6*results!C26 -> 1108.6705 | E6: =results!D6*results!D26 -> 1126.9479 | F6: =results!E6*results!E26 -> 1139.0953 | G6: =results!F6*results!F26 -> 1128.4674 | H6: =results!G6*results!G26 -> 904.10998 | I6: =results!H6*results!H26 -> 1035.4623 | J6: =results!I6*results!I26 -> 1216.4103 | ... AW6: =results!AV6*results!AV26 -> 3724.6874
B7: facture énergétique du secteur 6 | C7: =results!B7*results!B27 -> 1215.9287 | D7: =results!C7*results!C27 -> 1260.1599 | E7: =results!D7*results!D27 -> 1270.9712 | F7: =results!E7*results!E27 -> 1272.4369 | G7: =results!F7*results!F27 -> 1268.9167 | H7: =results!G7*results!G27 -> 1085.8485 | I7: =results!H7*results!H27 -> 1220.2114 | J7: =results!I7*results!I27 -> 1215.3277 | ... AW7: =results!AV7*results!AV27 -> 5308.0511
B8: facture énergétique du secteur 7 | C8: =results!B8*results!B28 -> 1003.6533 | D8: =results!C8*results!C28 -> 1040.1626 | E8: =results!D8*results!D28 -> 1049.942 | F8: =results!E8*results!E28 -> 1051.0059 | G8: =results!F8*results!F28 -> 1115.7559 | H8: =results!G8*results!G28 -> 976.72559 | I8: =results!H8*results!H28 -> 1083.1815 | J8: =results!I8*results!I28 -> 1145.8554 | ... AW8: =results!AV8*results!AV28 -> 5416.2217
B9: facture énergétique du secteur 8 | C9: =results!B9*results!B29 -> 7627.9511 | D9: =results!C9*results!C29 -> 7905.4287 | E9: =results!D9*results!D29 -> 8078.9207 | F9: =results!E9*results!E29 -> 8156.1336 | G9: =results!F9*results!F29 -> 8995.428 | H9: =results!G9*results!G29 -> 7346.2067 | I9: =results!H9*results!H29 -> 8204.0984 | J9: =results!I9*results!I29 -> 9241.6781 | ... AW9: =results!AV9*results!AV29 -> 26171.508
B10: facture énergétique du secteur 9 | C10: =results!B10*results!B30 -> 602.37817 | D10: =results!C10*results!C30 -> 624.29054 | E10: =results!D10*results!D30 -> 633.17115 | F10: =results!E10*results!E30 -> 655.24504 | G10: =results!F10*results!F30 -> 661.00464 | H10: =results!G10*results!G30 -> 546.93805 | I10: =results!H10*results!H30 -> 591.90584 | J10: =results!I10*results!I30 -> 634.22669 | ... AW10: =results!AV10*results!AV30 -> 1401.7733
B11: facture énergétique du secteur 10 | C11: =results!B11*results!B31 -> 1143.3082 | D11: =results!C11*results!C31 -> 1184.8977 | E11: =results!D11*results!D31 -> 1199.5201 | F11: =results!E11*results!E31 -> 1193.1139 | G11: =results!F11*results!F31 -> 1264.3227 | H11: =results!G11*results!G31 -> 948.34362 | I11: =results!H11*results!H31 -> 1145.205 | J11: =results!I11*results!I31 -> 1251.7891 | ... AW11: =results!AV11*results!AV31 -> 3751.5254
B12: facture énergétique du secteur 11 | C12: =results!B12*results!B32 -> 336.10281 | D12: =results!C12*results!C32 -> 348.32903 | E12: =results!D12*results!D32 -> 353.6351 | F12: =results!E12*results!E32 -> 352.74039 | G12: =results!F12*results!F32 -> 340.92711 | H12: =results!G12*results!G32 -> 282.85074 | I12: =results!H12*results!H32 -> 310.3991 | J12: =results!I12*results!I32 -> 320.73645 | ... AW12: =results!AV12*results!AV32 -> 759.14035
B13: facture énergétique du secteur 12 | C13: =results!B13*results!B33 -> 7056.0177 | D13: =results!C13*results!C33 -> 7312.6904 | E13: =results!D13*results!D33 -> 7407.9679 | F13: =results!E13*results!E33 -> 7583.523 | G13: =results!F13*results!F33 -> 7916.3576 | H13: =results!G13*results!G33 -> 6727.3179 | I13: =results!H13*results!H33 -> 7082.7213 | J13: =results!I13*results!I33 -> 7574.3743 | ... AW13: =results!AV13*results!AV33 -> 17612.331
B14: facture énergétique du secteur 13 | C14: =results!B14*results!B34 -> 4089.0957 | D14: =results!C14*results!C34 -> 4237.8424 | E14: =results!D14*results!D34 -> 4341.4944 | F14: =results!E14*results!E34 -> 4613.7952 | G14: =results!F14*results!F34 -> 4944.3785 | H14: =results!G14*results!G34 -> 4050.9178 | I14: =results!H14*results!H34 -> 4264.5286 | J14: =results!I14*results!I34 -> 4739.5128 | ... AW14: =results!AV14*results!AV34 -> 10761.994
B15: facture énergétique du secteur 14 | C15: =results!B15*results!B35 -> 512.84006 | D15: =results!C15*results!C35 -> 531.49535 | E15: =results!D15*results!D35 -> 538.47617 | F15: =results!E15*results!E35 -> 550.11292 | G15: =results!F15*results!F35 -> 555.48403 | H15: =results!G15*results!G35 -> 499.79657 | I15: =results!H15*results!H35 -> 525.91936 | J15: =results!I15*results!I35 -> 549.60228 | ... AW15: =results!AV15*results!AV35 -> 1424.3806
... B21: facture énergétique du secteur 20 | C21: =results!B21*results!B41 -> 5997.7128 | D21: =results!C21*results!C41 -> 6215.8882 | E21: =results!D21*results!D41 -> 6312.9995 | F21: =results!E21*results!E41 -> 6403.2992 | G21: =results!F21*results!F41 -> 6713.0132 | H21: =results!G21*results!G41 -> 6519.5329 | I21: =results!H21*results!H41 -> 6664.5476 | J21: =results!I21*results!I41 -> 6960.6933 | ... AW21: =results!AV21*results!AV41 -> 8762.1877
A22: AME | B22: facture énergétique en % de la VA du secteur 1 | C22: =results!B2*results!B22/(results!B85*results!B123) -> 0.14702787 | D22: =results!C2*results!C22/(results!C85*results!C123) -> 0.14702787 | E22: =results!D2*results!D22/(results!D85*results!D123) -> 0.15070351 | F22: =results!E2*results!E22/(results!E85*results!E123) -> 0.15299053 | G22: =results!F2*results!F22/(results!F85*results!F123) -> 0.16070267 | H22: =results!G2*results!G22/(results!G85*results!G123) -> 0.14323965 | I22: =results!H2*results!H22/(results!H85*results!H123) -> 0.15191197 | J22: =results!I2*results!I22/(results!I85*results!I123) -> 0.16393643 | ... AW22: =results!AV2*results!AV22/(results!AV85*results!AV123) -> 0.16172476
B23: facture énergétique en % de la VA du secteur 2 | C23: =results!B3*results!B23/(results!B86*results!B124) -> 0.1168967 | D23: =results!C3*results!C23/(results!C86*results!C124) -> 0.1168967 | E23: =results!D3*results!D23/(results!D86*results!D124) -> 0.11687301 | F23: =results!E3*results!E23/(results!E86*results!E124) -> 0.11424762 | G23: =results!F3*results!F23/(results!F86*results!F124) -> 0.11965606 | H23: =results!G3*results!G23/(results!G86*results!G124) -> 0.10664108 | I23: =results!H3*results!H23/(results!H86*results!H124) -> 0.11127787 | J23: =results!I3*results!I23/(results!I86*results!I124) -> 0.11656624 | ... AW23: =results!AV3*results!AV23/(results!AV86*results!AV124) -> 0.092741295
B24: facture énergétique en % de la VA du secteur 3 | C24: =results!B4*results!B24/(results!B87*results!B125) -> 0.079096595 | D24: =results!C4*results!C24/(results!C87*results!C125) -> 0.079096595 | E24: =results!D4*results!D24/(results!D87*results!D125) -> 0.08033847 | F24: =results!E4*results!E24/(results!E87*results!E125) -> 0.083123723 | G24: =results!F4*results!F24/(results!F87*results!F125) -> 0.083989012 | H24: =results!G4*results!G24/(results!G87*results!G125) -> 0.075416134 | I24: =results!H4*results!H24/(results!H87*results!H125) -> 0.070313454 | J24: =results!I4*results!I24/(results!I87*results!I125) -> 0.08132281 | ... AW24: =results!AV4*results!AV24/(results!AV87*results!AV125) -> 0.13161308
B25: facture énergétique en % de la VA du secteur 4 | C25: =results!B5*results!B25/(results!B88*results!B126) -> 0.19204222 | D25: =results!C5*results!C25/(results!C88*results!C126) -> 0.19204222 | E25: =results!D5*results!D25/(results!D88*results!D126) -> 0.19047189 | F25: =results!E5*results!E25/(results!E88*results!E126) -> 0.1891268 | G25: =results!F5*results!F25/(results!F88*results!F126) -> 0.1972425 | H25: =results!G5*results!G25/(results!G88*results!G126) -> 0.18381942 | I25: =results!H5*results!H25/(results!H88*results!H126) -> 0.18720609 | J25: =results!I5*results!I25/(results!I88*results!I126) -> 0.1873613 | ... AW25: =results!AV5*results!AV25/(results!AV88*results!AV126) -> 0.21785927
B26: facture énergétique en % de la VA du secteur 5 | C26: =results!B6*results!B26/(results!B89*results!B127) -> 0.17847158 | D26: =results!C6*results!C26/(results!C89*results!C127) -> 0.17847158 | E26: =results!D6*results!D26/(results!D89*results!D127) -> 0.17840883 | F26: =results!E6*results!E26/(results!E89*results!E127) -> 0.17869893 | G26: =results!F6*results!F26/(results!F89*results!F127) -> 0.18887663 | H26: =results!G6*results!G26/(results!G89*results!G127) -> 0.1702972 | I26: =results!H6*results!H26/(results!H89*results!H127) -> 0.17632892 | J26: =results!I6*results!I26/(results!I89*results!I127) -> 0.17813 | ... AW26: =results!AV6*results!AV26/(results!AV89*results!AV127) -> 0.28701273
B27: facture énergétique en % de la VA du secteur 6 | C27: =results!B7*results!B27/(results!B90*results!B128) -> 0.28671789 | D27: =results!C7*results!C27/(results!C90*results!C128) -> 0.28671789 | E27: =results!D7*results!D27/(results!D90*results!D128) -> 0.28512037 | F27: =results!E7*results!E27/(results!E90*results!E128) -> 0.28161352 | G27: =results!F7*results!F27/(results!F90*results!F128) -> 0.2918392 | H27: =results!G7*results!G27/(results!G90*results!G128) -> 0.2715731 | I27: =results!H7*results!H27/(results!H90*results!H128) -> 0.26335734 | J27: =results!I7*results!I27/(results!I90*results!I128) -> 0.28066312 | ... AW27: =results!AV7*results!AV27/(results!AV90*results!AV128) -> -2.539664
B28: facture énergétique en % de la VA du secteur 7 | C28: =results!B8*results!B28/(results!B91*results!B129) -> 1.3066667 | D28: =results!C8*results!C28/(results!C91*results!C129) -> 1.3066667 | E28: =results!D8*results!D28/(results!D91*results!D129) -> 1.2749812 | F28: =results!E8*results!E28/(results!E91*results!E129) -> 1.2955396 | G28: =results!F8*results!F28/(results!F91*results!F129) -> 1.3099688 | H28: =results!G8*results!G28/(results!G91*results!G129) -> 1.1390024 | I28: =results!H8*results!H28/(results!H91*results!H129) -> 1.312331 | J28: =results!I8*results!I28/(results!I91*results!I129) -> 1.3857666 | ... AW28: =results!AV8*results!AV28/(results!AV91*results!AV129) -> 4.6259135
B29: facture énergétique en % de la VA du secteur 8 | C29: =results!B9*results!B29/(results!B92*results!B130) -> 2.126947 | D29: =results!C9*results!C29/(results!C92*results!C130) -> 2.126947 | E29: =results!D9*results!D29/(results!D92*results!D130) -> 2.1377878 | F29: =results!E9*results!E29/(results!E92*results!E130) -> 2.1643215 | G29: =results!F9*results!F29/(results!F92*results!F130) -> 2.4097089 | H29: =results!G9*results!G29/(results!G92*results!G130) -> 1.8021848 | I29: =results!H9*results!H29/(results!H92*results!H130) -> 2.2131663 | J29: =results!I9*results!I29/(results!I92*results!I130) -> 2.5363125 | ... AW29: =results!AV9*results!AV29/(results!AV92*results!AV130) -> 1.7418239
B30: facture énergétique en % de la VA du secteur 9 | C30: =results!B10*results!B30/(results!B93*results!B131) -> 0.086174747 | D30: =results!C10*results!C30/(results!C93*results!C131) -> 0.086174747 | E30: =results!D10*results!D30/(results!D93*results!D131) -> 0.085809104 | F30: =results!E10*results!E30/(results!E93*results!E131) -> 0.084053837 | G30: =results!F10*results!F30/(results!F93*results!F131) -> 0.086841833 | H30: =results!G10*results!G30/(results!G93*results!G131) -> 0.084005722 | I30: =results!H10*results!H30/(results!H93*results!H131) -> 0.079681964 | J30: =results!I10*results!I30/(results!I93*results!I131) -> 0.081429504 | ... AW30: =results!AV10*results!AV30/(results!AV93*results!AV131) -> 0.066744963
B31: facture énergétique en % de la VA du secteur 10 | C31: =results!B11*results!B31/(results!B94*results!B132) -> 0.26402924 | D31: =results!C11*results!C31/(results!C94*results!C132) -> 0.26402924 | E31: =results!D11*results!D31/(results!D94*results!D132) -> 0.26283356 | F31: =results!E11*results!E31/(results!E94*results!E132) -> 0.26907162 | G31: =results!F11*results!F31/(results!F94*results!F132) -> 0.30295467 | H31: =results!G11*results!G31/(results!G94*results!G132) -> 0.27811916 | I31: =results!H11*results!H31/(results!H94*results!H132) -> 0.24704271 | J31: =results!I11*results!I31/(results!I94*results!I132) -> 0.26990697 | ... AW31: =results!AV11*results!AV31/(results!AV94*results!AV132) -> 0.42517548
B32: facture énergétique en % de la VA du secteur 11 | C32: =results!B12*results!B32/(results!B95*results!B133) -> 0.17933433 | D32: =results!C12*results!C32/(results!C95*results!C133) -> 0.17933433 | E32: =results!D12*results!D32/(results!D95*results!D133) -> 0.17959003 | F32: =results!E12*results!E32/(results!E95*results!E133) -> 0.18863615 | G32: =results!F12*results!F32/(results!F95*results!F133) -> 0.18036196 | H32: =results!G12*results!G32/(results!G95*results!G133) -> 0.17801275 | I32: =results!H12*results!H32/(results!H95*results!H133) -> 0.15768631 | J32: =results!I12*results!I32/(results!I95*results!I133) -> 0.17072572 | ... AW32: =results!AV12*results!AV32/(results!AV95*results!AV133) -> 0.25774332
B33: facture énergétique en % de la VA du secteur 12 | C33: =results!B13*results!B33/(results!B96*results!B134) -> 0.057027814 | D33: =results!C13*results!C33/(results!C96*results!C134) -> 0.057027814 | E33: =results!D13*results!D33/(results!D96*results!D134) -> 0.056756971 | F33: =results!E13*results!E33/(results!E96*results!E134) -> 0.055499393 | G33: =results!F13*results!F33/(results!F96*results!F134) -> 0.058457414 | H33: =results!G13*results!G33/(results!G96*results!G134) -> 0.053538597 | I33: =results!H13*results!H33/(results!H96*results!H134) -> 0.054480368 | J33: =results!I13*results!I33/(results!I96*results!I134) -> 0.056584077 | ... AW33: =results!AV13*results!AV33/(results!AV96*results!AV134) -> 0.042746308
B34: facture énergétique en % de la VA du secteur 13 | C34: =results!B14*results!B34/(results!B97*results!B135) -> 0.044110558 | D34: =results!C14*results!C34/(results!C97*results!C135) -> 0.044110558 | E34: =results!D14*results!D34/(results!D97*results!D135) -> 0.043814708 | F34: =results!E14*results!E34/(results!E97*results!E135) -> 0.043052903 | G34: =results!F14*results!F34/(results!F97*results!F135) -> 0.045953545 | H34: =results!G14*results!G34/(results!G97*results!G135) -> 0.042359497 | I34: =results!H14*results!H34/(results!H97*results!H135) -> 0.044243836 | J34: =results!I14*results!I34/(results!I97*results!I135) -> 0.046194175 | ... AW34: =results!AV14*results!AV34/(results!AV97*results!AV135) -> 0.041200331
... B41: facture énergétique en % de la VA du secteur 20 | C41: =results!B21*results!B41/(results!B104*results!B142) -> 0.022587975 | D41: =results!C21*results!C41/(results!C104*results!C142) -> 0.022587975 | E41: =results!D21*results!D41/(results!D104*results!D142) -> 0.022707658 | F41: =results!E21*results!E41/(results!E104*results!E142) -> 0.022590155 | G41: =results!F21*results!F41/(results!F104*results!F142) -> 0.023144639 | H41: =results!G21*results!G41/(results!G104*results!G142) -> 0.021666106 | I41: =results!H21*results!H41/(results!H104*results!H142) -> 0.022047867 | J41: =results!I21*results!I41/(results!I104*results!I142) -> 0.02284451 | ... AW41: =results!AV21*results!AV41/(results!AV104*results!AV142) -> 0.00898333
A42: AMS | B42: facture énergétique du secteur 1 | C42: =results!B43*results!B63 -> 4552.75 | D42: =results!C43*results!C63 -> 4718.3628 | E42: =results!D43*results!D63 -> 4836.3213 | F42: =results!E43*results!E63 -> 4983.3976 | G42: =results!F43*results!F63 -> 5177.2329 | H42: =results!G43*results!G63 -> 4801.3313 | I42: =results!H43*results!H63 -> 5242.2105 | J42: =results!I43*results!I63 -> 5485.6179 | ... AW42: =results!AV43*results!AV63 -> 16379.113
B43: facture énergétique du secteur 2 | C43: =results!B44*results!B64 -> 3122.6838 | D43: =results!C44*results!C64 -> 3236.2758 | E43: =results!D44*results!D64 -> 3245.8472 | F43: =results!E44*results!E64 -> 3318.5918 | G43: =results!F44*results!F64 -> 3381.9412 | H43: =results!G44*results!G64 -> 3184.9763 | I43: =results!H44*results!H64 -> 3266.6753 | J43: =results!I44*results!I64 -> 3450.3564 | ... AW43: =results!AV44*results!AV64 -> 6187.1625
B44: facture énergétique du secteur 3 | C44: =results!B45*results!B65 -> 984.3809 | D44: =results!C45*results!C65 -> 1020.1892 | E44: =results!D45*results!D65 -> 1045.547 | F44: =results!E45*results!E65 -> 1039.4783 | G44: =results!F45*results!F65 -> 1049.9948 | H44: =results!G45*results!G65 -> 895.15185 | I44: =results!H45*results!H65 -> 992.32129 | J44: =results!I45*results!I65 -> 1035.4307 | ... AW44: =results!AV45*results!AV65 -> 1052.9626
B45: facture énergétique du secteur 4 | C45: =results!B46*results!B66 -> 440.37848 | D45: =results!C46*results!C66 -> 456.39787 | E45: =results!D46*results!D66 -> 460.59521 | F45: =results!E46*results!E66 -> 464.62663 | G45: =results!F46*results!F66 -> 454.09345 | H45: =results!G46*results!G66 -> 373.26076 | I45: =results!H46*results!H66 -> 413.66834 | J45: =results!I46*results!I66 -> 477.33066 | ... AW45: =results!AV46*results!AV66 -> 1736.1808
B46: facture énergétique du secteur 5 | C46: =results!B47*results!B67 -> 1069.7566 | D46: =results!C47*results!C67 -> 1108.6705 | E46: =results!D47*results!D67 -> 1126.9479 | F46: =results!E47*results!E67 -> 1139.0953 | G46: =results!F47*results!F67 -> 1128.4674 | H46: =results!G47*results!G67 -> 904.10998 | I46: =results!H47*results!H67 -> 1035.4623 | J46: =results!I47*results!I67 -> 1216.4103 | ... AW46: =results!AV47*results!AV67 -> 2129.6801
B47: facture énergétique du secteur 6 | C47: =results!B48*results!B68 -> 1215.9287 | D47: =results!C48*results!C68 -> 1260.1599 | E47: =results!D48*results!D68 -> 1270.9712 | F47: =results!E48*results!E68 -> 1272.4369 | G47: =results!F48*results!F68 -> 1268.9167 | H47: =results!G48*results!G68 -> 1085.8485 | I47: =results!H48*results!H68 -> 1220.2114 | J47: =results!I48*results!I68 -> 1215.3277 | ... AW47: =results!AV48*results!AV68 -> 4183.205
B48: facture énergétique du secteur 7 | C48: =results!B49*results!B69 -> 1003.6533 | D48: =results!C49*results!C69 -> 1040.1626 | E48: =results!D49*results!D69 -> 1049.942 | F48: =results!E49*results!E69 -> 1051.0059 | G48: =results!F49*results!F69 -> 1115.7559 | H48: =results!G49*results!G69 -> 976.72559 | I48: =results!H49*results!H69 -> 1083.1815 | J48: =results!I49*results!I69 -> 1145.8554 | ... AW48: =results!AV49*results!AV69 -> 3625.7268
B49: facture énergétique du secteur 8 | C49: =results!B50*results!B70 -> 7627.9511 | D49: =results!C50*results!C70 -> 7905.4287 | E49: =results!D50*results!D70 -> 8078.9207 | F49: =results!E50*results!E70 -> 8156.1336 | G49: =results!F50*results!F70 -> 8995.428 | H49: =results!G50*results!G70 -> 7346.2067 | I49: =results!H50*results!H70 -> 8204.0984 | J49: =results!I50*results!I70 -> 9241.6781 | ... AW49: =results!AV50*results!AV70 -> 25446.642
B50: facture énergétique du secteur 9 | C50: =results!B51*results!B71 -> 602.37817 | D50: =results!C51*results!C71 -> 624.29054 | E50: =results!D51*results!D71 -> 633.17115 | F50: =results!E51*results!E71 -> 655.24504 | G50: =results!F51*results!F71 -> 661.00464 | H50: =results!G51*results!G71 -> 546.93805 | I50: =results!H51*results!H71 -> 591.90584 | J50: =results!I51*results!I71 -> 634.22669 | ... AW50: =results!AV51*results!AV71 -> 918.98041
B51: facture énergétique du secteur 10 | C51: =results!B52*results!B72 -> 1143.3082 | D51: =results!C52*results!C72 -> 1184.8977 | E51: =results!D52*results!D72 -> 1199.5201 | F51: =results!E52*results!E72 -> 1193.1139 | G51: =results!F52*results!F72 -> 1264.3227 | H51: =results!G52*results!G72 -> 948.34362 | I51: =results!H52*results!H72 -> 1145.205 | J51: =results!I52*results!I72 -> 1251.7891 | ... AW51: =results!AV52*results!AV72 -> 2996.3505
...
