Workbook

Sheet Produits et secteurs 3ME

Sheet Sorties des modèles
A2: En valeur
A4: Ménages
A5: 1 | B5: Consommation TTC des ménages totale
A6: 2 | B6: Investissements des ménages
A8: 3 | B8: Revenu des ménages
A9: 4 | B9: RDB des ménages
A11: 5 | B11: Flux nets d'endettement des ménages hors 'co-financeurs'
A12: 6 | B12: Flux nets d'endettement des ménages y compris auprès des 'co-financeurs'
A14: 7 | B14: Flux de remboursement des ménages (hors remboursement aux 'co-financeurs')
A15: 8 | B15: Flux de remboursement des ménages (yc remboursement aux 'co-financeurs')
A18: Entreprises
A19: 9 | B19: Valeur ajoutée
A21: 10 | B21: Masse salariale
A23: 11 | B23: Investissement des entreprises
A25: 12 | B25: Flux net (des remboursements) d'endettement des entreprises
A28: Etat
A29: 13 | B29: recettes
A30: 14 | B30: dont | C30: toutes taxes sur l'énergie
A31: 15 | C31: taxe carbone
A32: 16 | C32: (taux de la taxe carbone)
A33: 17 | B33: dépenses
A34: 18 | B34: dont | C34: investisements
A35: 19 | B35: déficit public courant
A37: 20 | B37: Dette publique
A40: Extérieur
A41: 21 | B41: Exportations
A42: 22 | B42: Importations
A43: 23 | B43: dont | C43: importations d'énergie | E43: (ventilées pr secteur ?)
A44: 24 | B44: Solde du compte courant
A46: Déclinaison sectorielles (en valeur)
B48: Consommation TTC des ménages
A49: 1 | B49: en | C49: biens manufacturés
A50: 2 | C50: services de transports
A51: 3 | C51: services (hors service de transports)
A52: 4 | C52: énergie
A53: 5 | C53: autre
B55: Valeur ajoutée
A56: 6 | B56: secteur | C56: énergie
A57: 7 | C57: manuf
A58: 8 | C58: bâtiment
...

Sheet résultats
C1: 2004 | D1: 2005 | E1: 2006 | F1: 2007 | G1: 2008 | H1: 2009 | I1: 2010 | J1: 2011 | K1: 2012 | L1: 2013 | M1: 2014 | N1: 2015 | O1: 2016 | P1: 2017 | Q1: 2018 | R1: 2019 | S1: 2020 | T1: 2021 | U1: 2022 | V1: 2023 | W1: 2024 | X1: 2025 | Y1: 2026 | Z1: 2027 | AA1: 2028 | AB1: 2029 | AC1: 2030 | AD1: 2031 | AE1: 2032 | AF1: 2033 | AG1: 2034 | AH1: 2035 | AI1: 2036 | AJ1: 2037 | AK1: 2038 | AL1: 2039 | AM1: 2040 | AN1: 2041 | AO1: 2042 | AP1: 2043 | AQ1: 2044 | AR1: 2045 | AS1: 2046 | AT1: 2047 | AU1: 2048 | AV1: 2049 | AW1: 2050
A2: Rénovation (M€ courants) | B2: REHAB_VAL_1 | C2: 4655.932 | D2: 4825.2982 | E2: 4958.9472 | F2: 4601.6258 | G2: 5944.0779 | H2: 6462.5149 | I2: 5653.6409 | J2: 5784.6682 | K2: 7209.2996 | L2: 8182.7283 | M2: 8166.9262 | N2: 7060.4379 | O2: 6430.2519 | P2: 5813.7251 | Q2: 7353.7641 | R2: 9159.3655 | S2: 11855.356 | T2: 11651.666 | U2: 13714.466 | V2: 14527.82 | W2: 16838.812 | X2: 16165.677 | Y2: 18324.099 | Z2: 16897.383 | AA2: 16509.013 | AB2: 16393.135 | AC2: 16443.474 | AD2: 16582.41 | AE2: 16767.135 | AF2: 17001.913 | AG2: 17272.97 | AH2: 17556.6 | AI2: 17867.131 | AJ2: 18200.34 | AK2: 18555.372 | AL2: 18940.04 | AM2: 19348.699 | AN2: 19809.074 | AO2: 20384.705 | AP2: 21016.29 | AQ2: 21676.068 | AR2: 22355.738 | AS2: 23048.951 | AT2: 23772.974 | AU2: 24515.987 | AV2: 25254.508 | AW2: 25982.98
A3: Taux de financement des rénovations par emprunt | B3: R_LOAN_REHAB_H01_CG_1 | C3: 0.3 | D3: 0.3 | E3: 0.3 | F3: 0.3 | G3: 0.3 | H3: 0.3 | I3: 0.3 | J3: 0.3 | K3: 0.3 | L3: 0.3 | M3: 0.3 | N3: 0.3 | O3: 0.3 | P3: 0.3 | Q3: 0.3 | R3: 0.3 | S3: 0.3 | T3: 0.3 | U3: 0.3 | V3: 0.3 | W3: 0.3 | X3: 0.3 | Y3: 0.3 | Z3: 0.3 | AA3: 0.3 | AB3: 0.3 | AC3: 0.3 | AD3: 0.3 | AE3: 0.3 | AF3: 0.3 | AG3: 0.3 | AH3: 0.3 | AI3: 0.3 | AJ3: 0.3 | AK3: 0.3 | AL3: 0.3 | AM3: 0.3 | AN3: 0.3 | AO3: 0.3 | AP3: 0.3 | AQ3: 0.3 | AR3: 0.3 | AS3: 0.3 | AT3: 0.3 | AU3: 0.3 | AV3: 0.3 | AW3: 0.3
A4: Taux d'intérêt | B4: R_1 | C4: 0.02637643 | D4: 0.02637643 | E4: 0.013276695 | F4: 0.0096219735 | G4: 0.020462196 | H4: 0.0078342748 | I4: 0.015112648 | J4: 0.014958585 | K4: 0.01552575 | L4: 0.013503432 | M4: 0.016129302 | N4: 0.013312163 | O4: 0.013202983 | P4: 0.020584777 | Q4: 0.026723349 | R4: 0.024559854 | S4: 0.026213344 | T4: 0.026268186 | U4: 0.026752761 | V4: 0.026908462 | W4: 0.026980911 | X4: 0.026954565 | Y4: 0.026389747 | Z4: 0.026029573 | AA4: 0.025826511 | AB4: 0.025647215 | AC4: 0.025510008 | AD4: 0.025473788 | AE4: 0.025202476 | AF4: 0.025395825 | AG4: 0.025497706 | AH4: 0.025355401 | AI4: 0.025799573 | AJ4: 0.025775958 | AK4: 0.025785726 | AL4: 0.02577651 | AM4: 0.025769324 | AN4: 0.025822692 | AO4: 0.02581647 | AP4: 0.025807983 | AQ4: 0.025798682 | AR4: 0.025778892 | AS4: 0.025783489 | AT4: 0.025798547 | AU4: 0.025788078 | AV4: 0.025783999 | AW4: 0.025899267
A5: Durée de vie (an) | B5: LD_REHAB_H01_CG | C5: 25 | D5: 25 | E5: 25 | F5: 25 | G5: 25 | H5: 25 | I5: 25 | J5: 25 | K5: 25 | L5: 25 | M5: 25 | N5: 25 | O5: 25 | P5: 25 | Q5: 25 | R5: 25 | S5: 25 | T5: 25 | U5: 25 | V5: 10 | W5: 10 | X5: 10 | Y5: 10 | Z5: 10 | AA5: 10 | AB5: 10 | AC5: 10 | AD5: 10 | AE5: 10 | AF5: 10 | AG5: 10 | AH5: 10 | AI5: 10 | AJ5: 10 | AK5: 10 | AL5: 10 | AM5: 10 | AN5: 10 | AO5: 10 | AP5: 10 | AQ5: 10 | AR5: 10 | AS5: 10 | AT5: 10 | AU5: 10 | AV5: 10 | AW5: 10
A6: Revenu (M€ courants) | B6: DISPINC_AI_VAL_1 | C6: 1226094.8 | D6: 1270695.8 | E6: 1304023.8 | F6: 1328960 | G6: 1369991.9 | H6: 1353956.9 | I6: 1347772.3 | J6: 1381927.6 | K6: 1413118.6 | L6: 1426218.4 | M6: 1446051.5 | N6: 1472687 | O6: 1500976.7 | P6: 1546623.6 | Q6: 1605310.6 | R6: 1662475.8 | S6: 1730997.1 | T6: 1778158.3 | U6: 1847853.8 | V6: 1909512.6 | W6: 1969195.8 | X6: 2021255.6 | Y6: 2074851 | Z6: 2124425 | AA6: 2182092.3 | AB6: 2243899 | AC6: 2307698 | AD6: 2375217.5 | AE6: 2443514.9 | AF6: 2517975.1 | AG6: 2597145.4 | AH6: 2681060.4 | AI6: 2772204.3 | AJ6: 2868949.7 | AK6: 2969073.5 | AL6: 3074302.9 | AM6: 3183629.9 | AN6: 3296919 | AO6: 3412780 | AP6: 3532910.1 | AQ6: 3656420 | AR6: 3783615.1 | AS6: 3914023.4 | AT6: 4049042.9 | AU6: 4188199.6 | AV6: 4331599 | AW6: 4480933.7
A7: Rénovation (M€ courants) | B7: REHAB_VAL_2 | C7: 4655.932 | D7: 4825.2982 | E7: 4958.9472 | F7: 4601.6258 | G7: 5944.0779 | H7: 6462.5149 | I7: 5653.6409 | J7: 5784.6682 | K7: 7209.2996 | L7: 8182.7283 | M7: 8166.9262 | N7: 7060.4379 | O7: 6430.2519 | P7: 5813.7251 | Q7: 7353.7641 | R7: 9159.3655 | S7: 11855.356 | T7: 11651.666 | U7: 13714.466 | V7: 14461.436 | W7: 14900.55 | X7: 14360.468 | Y7: 16540.241 | Z7: 17963.955 | AA7: 18402.456 | AB7: 19020.008 | AC7: 19298.321 | AD7: 19272.862 | AE7: 19827.051 | AF7: 19846.019 | AG7: 19653.632 | AH7: 19757.599 | AI7: 19668.47 | AJ7: 19358.769 | AK7: 19293.234 | AL7: 19276.444 | AM7: 19157.138 | AN7: 19752.526 | AO7: 19907.195 | AP7: 19953.81 | AQ7: 19932.211 | AR7: 19877.753 | AS7: 19899.083 | AT7: 20228.442 | AU7: 20637.406 | AV7: 21054.949 | AW7: 21454.89
A8: Taux de financement des rénovations par emprunt | B8: R_LOAN_REHAB_H01_CG_2 | C8: 0.3 | D8: 0.3 | E8: 0.3 | F8: 0.3 | G8: 0.3 | H8: 0.3 | I8: 0.3 | J8: 0.3 | K8: 0.3 | L8: 0.3 | M8: 0.3 | N8: 0.3 | O8: 0.3 | P8: 0.3 | Q8: 0.3 | R8: 0.3 | S8: 0.3 | T8: 0.3 | U8: 0.3 | V8: 0.3 | W8: 0.3 | X8: 0.3 | Y8: 0.3 | Z8: 0.3 | AA8: 0.3 | AB8: 0.3 | AC8: 0.3 | AD8: 0.3 | AE8: 0.3 | AF8: 0.3 | AG8: 0.3 | AH8: 0.3 | AI8: 0.3 | AJ8: 0.3 | AK8: 0.3 | AL8: 0.3 | AM8: 0.3 | AN8: 0.3 | AO8: 0.3 | AP8: 0.3 | AQ8: 0.3 | AR8: 0.3 | AS8: 0.3 | AT8: 0.3 | AU8: 0.3 | AV8: 0.3 | AW8: 0.3
A9: Taux d'intérêt | B9: R_2 | C9: 0.02637643 | D9: 0.02637643 | E9: 0.013276695 | F9: 0.0096219735 | G9: 0.020462196 | H9: 0.0078342748 | I9: 0.015112648 | J9: 0.014958585 | K9: 0.01552575 | L9: 0.013503432 | M9: 0.016129302 | N9: 0.013312163 | O9: 0.013202983 | P9: 0.020584777 | Q9: 0.026723349 | R9: 0.024559854 | S9: 0.026213344 | T9: 0.026268186 | U9: 0.026752761 | V9: 0.026713653 | W9: 0.027659423 | X9: 0.027662767 | Y9: 0.026055448 | Z9: 0.02602458 | AA9: 0.026311389 | AB9: 0.027418035 | AC9: 0.027664483 | AD9: 0.027130643 | AE9: 0.026762764 | AF9: 0.0267073 | AG9: 0.026804054 | AH9: 0.026672382 | AI9: 0.026643006 | AJ9: 0.026652602 | AK9: 0.026921291 | AL9: 0.026874944 | AM9: 0.027136271 | AN9: 0.02701082 | AO9: 0.027155187 | AP9: 0.027251786 | AQ9: 0.027215843 | AR9: 0.027219554 | AS9: 0.027309751 | AT9: 0.027270024 | AU9: 0.027184411 | AV9: 0.027097897 | AW9: 0.027128778
A10: Durée de vie (an) | B10: LD_REHAB_H01_CG | C10: 25 | D10: 25 | E10: 25 | F10: 25 | G10: 25 | H10: 25 | I10: 25 | J10: 25 | K10: 25 | L10: 25 | M10: 25 | N10: 25 | O10: 25 | P10: 25 | Q10: 25 | R10: 25 | S10: 25 | T10: 25 | U10: 25 | V10: 10 | W10: 10 | X10: 10 | Y10: 10 | Z10: 10 | AA10: 10 | AB10: 10 | AC10: 10 | AD10: 10 | AE10: 10 | AF10: 10 | AG10: 10 | AH10: 10 | AI10: 10 | AJ10: 10 | AK10: 10 | AL10: 10 | AM10: 10 | AN10: 10 | AO10: 10 | AP10: 10 | AQ10: 10 | AR10: 10 | AS10: 10 | AT10: 10 | AU10: 10 | AV10: 10 | AW10: 10
A11: Revenu (M€ courants) | B11: DISPINC_AI_VAL_2 | C11: 1226094.8 | D11: 1270695.8 | E11: 1304023.8 | F11: 1328960 | G11: 1369991.9 | H11: 1353956.9 | I11: 1347772.3 | J11: 1381927.6 | K11: 1413118.6 | L11: 1426218.4 | M11: 1446051.5 | N11: 1472687 | O11: 1500976.7 | P11: 1546623.6 | Q11: 1605310.6 | R11: 1662475.8 | S11: 1730997.1 | T11: 1778158.3 | U11: 1847853.8 | V11: 1910081.8 | W11: 1972574.8 | X11: 2026244.5 | Y11: 2083491.2 | Z11: 2144130.6 | AA11: 2211944.2 | AB11: 2282059 | AC11: 2349925.2 | AD11: 2422079.2 | AE11: 2500526.2 | AF11: 2582089.8 | AG11: 2666812.1 | AH11: 2753800.6 | AI11: 2847335.5 | AJ11: 2950395.3 | AK11: 3055102.5 | AL11: 3168320.2 | AM11: 3281520.8 | AN11: 3404298 | AO11: 3530623.6 | AP11: 3662069.7 | AQ11: 3797312.3 | AR11: 3936247 | AS11: 4075436.7 | AT11: 4217175 | AU11: 4365692.1 | AV11: 4520122 | AW11: 4680122.5
A12: Prix d'achat des automobiles net de subvention | B12: PNEWAUTO_H01_1*NEWAUTO_H01_1*(1-R_SUB_AUTO_H01_1) | C12: 49901.347 | D12: 51716.58 | E12: 53220.249 | F12: 55902.555 | G12: 55392.29 | H12: 62075.577 | I12: 61001.942 | J12: 59921.041 | K12: 52167.917 | L12: 49897.42 | M12: 51255.567 | N12: 50283.355 | O12: 53942.513 | P12: 58730.11 | Q12: 61674.524 | R12: 63471.097 | S12: 56843.074 | T12: 49792.871 | U12: 51465.625 | V12: 53671.433 | W12: 54592.047 | X12: 55058.827 | Y12: 63123.964 | Z12: 67558.932 | AA12: 71218.997 | AB12: 74185.567 | AC12: 76676.994 | AD12: 79047.075 | AE12: 77395.468 | AF12: 77753.893 | AG12: 78851.369 | AH12: 76538.484 | AI12: 80196.787 | AJ12: 82872.33 | AK12: 85054.069 | AL12: 87049.468 | AM12: 88881.345 | AN12: 89956.757 | AO12: 91450.319 | AP12: 93249.35 | AQ12: 95150.687 | AR12: 97122.094 | AS12: 98657.737 | AT12: 100494.94 | AU12: 102463.37 | AV12: 104521.48 | AW12: 106712.05
A13: Taux de financement des auto par emprunt | B13: R_LOAN_AUTO_H01_CA | C13: 0.2 | D13: 0.2 | E13: 0.2 | F13: 0.2 | G13: 0.2 | H13: 0.2 | I13: 0.2 | J13: 0.2 | K13: 0.2 | L13: 0.2 | M13: 0.2 | N13: 0.2 | O13: 0.2 | P13: 0.2 | Q13: 0.2 | R13: 0.2 | S13: 0.2 | T13: 0.2 | U13: 0.2 | V13: 0.2 | W13: 0.2 | X13: 0.2 | Y13: 0.2 | Z13: 0.2 | AA13: 0.2 | AB13: 0.2 | AC13: 0.2 | AD13: 0.2 | AE13: 0.2 | AF13: 0.2 | AG13: 0.2 | AH13: 0.2 | AI13: 0.2 | AJ13: 0.2 | AK13: 0.2 | AL13: 0.2 | AM13: 0.2 | AN13: 0.2 | AO13: 0.2 | AP13: 0.2 | AQ13: 0.2 | AR13: 0.2 | AS13: 0.2 | AT13: 0.2 | AU13: 0.2 | AV13: 0.2 | AW13: 0.2
... A233: Réhabilitation | B233: REHAB_VAL_2 | C233: 4655.932 | D233: 4825.2982 | E233: 4958.9472 | F233: 4601.6258 | G233: 5944.0779 | H233: 6462.5149 | I233: 5653.6409 | J233: 5784.6682 | K233: 7209.2996 | L233: 8182.7283 | M233: 8166.9262 | N233: 7060.4379 | O233: 6430.2519 | P233: 5813.7251 | Q233: 7353.7641 | R233: 9159.3655 | S233: 11855.356 | T233: 11651.666 | U233: 13714.466 | V233: 14461.436 | W233: 14900.55 | X233: 14360.468 | Y233: 16540.241 | Z233: 17963.955 | AA233: 18402.456 | AB233: 19020.008 | AC233: 19298.321 | AD233: 19272.862 | AE233: 19827.051 | AF233: 19846.019 | AG233: 19653.632 | AH233: 19757.599 | AI233: 19668.47 | AJ233: 19358.769 | AK233: 19293.234 | AL233: 19276.444 | AM233: 19157.138 | AN233: 19752.526 | AO233: 19907.195 | AP233: 19953.81 | AQ233: 19932.211 | AR233: 19877.753 | AS233: 19899.083 | AT233: 20228.442 | AU233: 20637.406 | AV233: 21054.949 | AW233: 21454.89
A234: Coût unitaire du capital CB | B234: UC_K_REHAB_H01_CB_1 | D234: 8.3580815e-06 | E234: 8.4538508e-06 | F234: 6.5740456e-06 | G234: 6.46202e-06 | H234: 6.9722041e-06 | I234: 6.9108297e-06 | J234: 7.0538631e-06 | K234: 7.5241695e-06 | L234: 7.4850678e-06 | M234: 7.2609709e-06 | N234: 7.0409358e-06 | O234: 7.102457e-06 | P234: 6.4998734e-06 | Q234: 7.1133829e-06 | R234: 6.4998605e-06 | S234: 7.2709093e-06 | T234: 6.5084439e-06 | U234: 7.3231407e-06 | V234: 6.8913137e-06 | W234: 8.3357107e-06 | X234: 8.4174628e-06 | Y234: 1.0376323e-05 | Z234: 1.057335e-05 | AA234: 1.077744e-05 | AB234: 1.0987707e-05 | AC234: 1.1201823e-05 | AD234: 1.14212e-05 | AE234: 1.1646025e-05 | AF234: 1.1869862e-05 | AG234: 1.2107457e-05 | AH234: 1.2347951e-05 | AI234: 1.2587989e-05 | AJ234: 1.2845751e-05 | AK234: 1.3098475e-05 | AL234: 1.3356985e-05 | AM234: 1.3620172e-05 | AN234: 1.3887095e-05 | AO234: 1.4161603e-05 | AP234: 1.4440334e-05 | AQ234: 1.472422e-05 | AR234: 1.5013246e-05 | AS234: 1.5307433e-05 | AT234: 1.5607828e-05 | AU234: 1.5914172e-05 | AV234: 1.6225567e-05 | AW234: 1.6545947e-05
A235: Coût unitaire du capital CC | B235: UC_K_REHAB_H01_CC_1 | D235: 5.8631016e-06 | E235: 5.9302827e-06 | F235: 4.6116202e-06 | G235: 4.5330355e-06 | H235: 4.890924e-06 | I235: 4.8478706e-06 | J235: 4.9482069e-06 | K235: 5.2781216e-06 | L235: 5.2506922e-06 | M235: 5.0934907e-06 | N235: 4.9391385e-06 | O235: 4.9822949e-06 | P235: 4.5595892e-06 | Q235: 4.9899593e-06 | R235: 4.5595802e-06 | S235: 5.1004624e-06 | T235: 4.5656013e-06 | U235: 5.1371021e-06 | V235: 4.8341803e-06 | W235: 5.8474088e-06 | X235: 5.9047569e-06 | Y235: 7.2788753e-06 | Z235: 7.417088e-06 | AA235: 7.5602551e-06 | AB235: 7.7077547e-06 | AC235: 7.857955e-06 | AD235: 8.0118451e-06 | AE235: 8.1695577e-06 | AF235: 8.3265765e-06 | AG235: 8.4932469e-06 | AH235: 8.6619512e-06 | AI235: 8.8303346e-06 | AJ235: 9.0111518e-06 | AK235: 9.1884352e-06 | AL235: 9.3697772e-06 | AM235: 9.5544001e-06 | AN235: 9.7416435e-06 | AO235: 9.9342079e-06 | AP235: 1.0129734e-05 | AQ235: 1.0328877e-05 | AR235: 1.0531626e-05 | AS235: 1.0737995e-05 | AT235: 1.0948719e-05 | AU235: 1.1163616e-05 | AV235: 1.1382056e-05 | AW235: 1.1606798e-05
A236: Coût unitaire du capital CD | B236: UC_K_REHAB_H01_CD_1 | D236: 3.4620548e-06 | E236: 3.501724e-06 | F236: 2.7230778e-06 | G236: 2.676675e-06 | H236: 2.8880016e-06 | I236: 2.8625793e-06 | J236: 2.9218261e-06 | K236: 3.1166347e-06 | L236: 3.1004382e-06 | M236: 3.0076136e-06 | N236: 2.9164714e-06 | O236: 2.9419545e-06 | P236: 2.6923544e-06 | Q236: 2.9464802e-06 | R236: 2.6923491e-06 | S236: 3.0117302e-06 | T236: 2.6959045e-06 | U236: 3.0333653e-06 | V236: 2.8544955e-06 | W236: 3.4527885e-06 | X236: 3.4866515e-06 | Y236: 4.2980434e-06 | Z236: 4.3796555e-06 | AA236: 4.4641931e-06 | AB236: 4.5512889e-06 | AC236: 4.6399794e-06 | AD236: 4.7308487e-06 | AE236: 4.8239751e-06 | AF236: 4.9166919e-06 | AG236: 5.0151078e-06 | AH236: 5.1147245e-06 | AI236: 5.2141519e-06 | AJ236: 5.3209212e-06 | AK236: 5.4256037e-06 | AL236: 5.5326829e-06 | AM236: 5.6416994e-06 | AN236: 5.7522632e-06 | AO236: 5.865969e-06 | AP236: 5.9814237e-06 | AQ236: 6.099014e-06 | AR236: 6.2187335e-06 | AS236: 6.3405906e-06 | AT236: 6.4650192e-06 | AU236: 6.5919119e-06 | AV236: 6.7208969e-06 | AW236: 6.8536032e-06
A237: Coût unitaire du capital CE | B237: UC_K_REHAB_H01_CE_1 | D237: 7.3182617e-06 | E237: 7.4021164e-06 | F237: 5.7561758e-06 | G237: 5.6580872e-06 | H237: 6.1047998e-06 | I237: 6.051061e-06 | J237: 6.1762997e-06 | K237: 6.5880958e-06 | L237: 6.5538588e-06 | M237: 6.3576415e-06 | N237: 6.1649807e-06 | O237: 6.2188481e-06 | P237: 5.6912312e-06 | Q237: 6.2284147e-06 | R237: 5.69122e-06 | S237: 6.3663435e-06 | T237: 5.6987355e-06 | U237: 6.4120768e-06 | V237: 6.0339729e-06 | W237: 7.2986741e-06 | X237: 7.3702554e-06 | Y237: 9.0854156e-06 | Z237: 9.2579312e-06 | AA237: 9.4366309e-06 | AB237: 9.6207383e-06 | AC237: 9.8082167e-06 | AD237: 1.0000301e-05 | AE237: 1.0197156e-05 | AF237: 1.0393145e-05 | AG237: 1.0601181e-05 | AH237: 1.0811756e-05 | AI237: 1.1021931e-05 | AJ237: 1.1247625e-05 | AK237: 1.1468908e-05 | AL237: 1.1695257e-05 | AM237: 1.1925702e-05 | AN237: 1.2159417e-05 | AO237: 1.2399774e-05 | AP237: 1.2643828e-05 | AQ237: 1.2892396e-05 | AR237: 1.3145465e-05 | AS237: 1.3403052e-05 | AT237: 1.3666076e-05 | AU237: 1.3934308e-05 | AV237: 1.4206962e-05 | AW237: 1.4487483e-05
A238: Coût unitaire du capital CF | B238: UC_K_REHAB_H01_CF_1 | D238: 1.1158829e-05 | E238: 1.128669e-05 | F238: 8.7769727e-06 | G238: 8.6274079e-06 | H238: 9.308552e-06 | I238: 9.2266114e-06 | J238: 9.4175744e-06 | K238: 1.0045478e-05 | L238: 9.9932736e-06 | M238: 9.6940829e-06 | N238: 9.4003152e-06 | O238: 9.4824519e-06 | P238: 8.6779458e-06 | Q238: 9.497039e-06 | R238: 8.6779285e-06 | S238: 9.7073517e-06 | T238: 8.6893882e-06 | U238: 9.7770855e-06 | V238: 9.2005557e-06 | W238: 1.1128962e-05 | X238: 1.1238109e-05 | Y238: 1.3853372e-05 | Z238: 1.4116422e-05 | AA238: 1.4388902e-05 | AB238: 1.4669628e-05 | AC238: 1.4955494e-05 | AD238: 1.5248382e-05 | AE238: 1.5548545e-05 | AF238: 1.5847388e-05 | AG238: 1.61646e-05 | AH238: 1.6485683e-05 | AI238: 1.6806155e-05 | AJ238: 1.7150292e-05 | AK238: 1.7487703e-05 | AL238: 1.7832838e-05 | AM238: 1.8184218e-05 | AN238: 1.8540586e-05 | AO238: 1.890708e-05 | AP238: 1.9279211e-05 | AQ238: 1.9658226e-05 | AR238: 2.0044104e-05 | AS238: 2.0436871e-05 | AT238: 2.0837927e-05 | AU238: 2.1246925e-05 | AV238: 2.1662667e-05 | AW238: 2.2090404e-05
A239: Coût unitaire du capital CG | B239: UC_K_REHAB_H01_CG_1 | D239: 1.1136217e-05 | E239: 1.1263819e-05 | F239: 8.7591871e-06 | G239: 8.6099253e-06 | H239: 9.2896891e-06 | I239: 9.2079146e-06 | J239: 9.3984906e-06 | K239: 1.0025122e-05 | L239: 9.9730232e-06 | M239: 9.6744388e-06 | N239: 9.3812664e-06 | O239: 9.4632366e-06 | P239: 8.6603608e-06 | Q239: 9.4777942e-06 | R239: 8.6603436e-06 | S239: 9.6876807e-06 | T239: 8.67178e-06 | U239: 9.7572732e-06 | V239: 9.1819116e-06 | W239: 1.110641e-05 | X239: 1.1215336e-05 | Y239: 1.3825299e-05 | Z239: 1.4087817e-05 | AA239: 1.4359745e-05 | AB239: 1.4639901e-05 | AC239: 1.4925188e-05 | AD239: 1.5217482e-05 | AE239: 1.5517037e-05 | AF239: 1.5815275e-05 | AG239: 1.6131844e-05 | AH239: 1.6452277e-05 | AI239: 1.6772099e-05 | AJ239: 1.7115539e-05 | AK239: 1.7452266e-05 | AL239: 1.7796702e-05 | AM239: 1.814737e-05 | AN239: 1.8503015e-05 | AO239: 1.8868766e-05 | AP239: 1.9240144e-05 | AQ239: 1.961839e-05 | AR239: 2.0003486e-05 | AS239: 2.0395458e-05 | AT239: 2.0795701e-05 | AU239: 2.120387e-05 | AV239: 2.161877e-05 | AW239: 2.204564e-05
A240: Coût unitaire du capital CB (choc) | B240: UC_K_REHAB_H01_CB_2 | D240: 8.3580815e-06 | E240: 8.4538508e-06 | F240: 6.5740456e-06 | G240: 6.46202e-06 | H240: 6.9722041e-06 | I240: 6.9108297e-06 | J240: 7.0538631e-06 | K240: 7.5241695e-06 | L240: 7.4850678e-06 | M240: 7.2609709e-06 | N240: 7.0409358e-06 | O240: 7.102457e-06 | P240: 6.4998734e-06 | Q240: 7.1133829e-06 | R240: 6.4998605e-06 | S240: 7.2709093e-06 | T240: 6.5084439e-06 | U240: 7.3231407e-06 | V240: 6.8858641e-06 | W240: 6.8670117e-06 | X240: 5.9492137e-06 | Y240: 6.1434672e-06 | Z240: 6.4763982e-06 | AA240: 6.6788078e-06 | AB240: 7.0377393e-06 | AC240: 7.2243134e-06 | AD240: 7.1513819e-06 | AE240: 7.3867808e-06 | AF240: 7.5828682e-06 | AG240: 7.6973588e-06 | AH240: 7.9226484e-06 | AI240: 8.1291361e-06 | AJ240: 8.2496314e-06 | AK240: 8.4596477e-06 | AL240: 8.6860886e-06 | AM240: 8.6810352e-06 | AN240: 8.9755841e-06 | AO240: 9.2315944e-06 | AP240: 9.4862078e-06 | AQ240: 9.7380879e-06 | AR240: 9.9872097e-06 | AS240: 1.0244214e-05 | AT240: 1.0527386e-05 | AU240: 1.0814348e-05 | AV240: 1.1101841e-05 | AW240: 1.1391777e-05
A241: Coût unitaire du capital CC | B241: UC_K_REHAB_H01_CC_2 | D241: 5.8631016e-06 | E241: 5.9302827e-06 | F241: 4.6116202e-06 | G241: 4.5330355e-06 | H241: 4.890924e-06 | I241: 4.8478706e-06 | J241: 4.9482069e-06 | K241: 5.2781216e-06 | L241: 5.2506922e-06 | M241: 5.0934907e-06 | N241: 4.9391385e-06 | O241: 4.9822949e-06 | P241: 4.5595892e-06 | Q241: 4.9899593e-06 | R241: 4.5595802e-06 | S241: 5.1004624e-06 | T241: 4.5656013e-06 | U241: 5.1371021e-06 | V241: 4.8303574e-06 | W241: 4.8171327e-06 | X241: 4.1733075e-06 | Y241: 4.3095742e-06 | Z241: 4.5431216e-06 | AA241: 4.6851097e-06 | AB241: 4.9368962e-06 | AC241: 5.0677759e-06 | AD241: 5.0166152e-06 | AE241: 5.1817449e-06 | AF241: 5.3192981e-06 | AG241: 5.399612e-06 | AH241: 5.5576502e-06 | AI241: 5.702499e-06 | AJ241: 5.7870251e-06 | AK241: 5.9343492e-06 | AL241: 6.093195e-06 | AM241: 6.0896501e-06 | AN241: 6.2962729e-06 | AO241: 6.4758613e-06 | AP241: 6.6544697e-06 | AQ241: 6.8311608e-06 | AR241: 7.0059171e-06 | AS241: 7.186203e-06 | AT241: 7.3848444e-06 | AU241: 7.5861454e-06 | AV241: 7.7878187e-06 | AW241: 7.9912053e-06
A242: Coût unitaire du capital CD | B242: UC_K_REHAB_H01_CD_2 | D242: 3.4620548e-06 | E242: 3.501724e-06 | F242: 2.7230778e-06 | G242: 2.676675e-06 | H242: 2.8880016e-06 | I242: 2.8625793e-06 | J242: 2.9218261e-06 | K242: 3.1166347e-06 | L242: 3.1004382e-06 | M242: 3.0076136e-06 | N242: 2.9164714e-06 | O242: 2.9419545e-06 | P242: 2.6923544e-06 | Q242: 2.9464802e-06 | R242: 2.6923491e-06 | S242: 3.0117302e-06 | T242: 2.6959045e-06 | U242: 3.0333653e-06 | V242: 2.8522382e-06 | W242: 2.8444292e-06 | X242: 2.4642622e-06 | Y242: 2.5447252e-06 | Z242: 2.6826306e-06 | AA242: 2.766472e-06 | AB242: 2.9151474e-06 | AC242: 2.9924294e-06 | AD242: 2.96222e-06 | AE242: 3.0597261e-06 | AF242: 3.1409487e-06 | AG242: 3.1883726e-06 | AH242: 3.2816913e-06 | AI242: 3.3672219e-06 | AJ242: 3.417133e-06 | AK242: 3.5041252e-06 | AL242: 3.5979207e-06 | AM242: 3.5958276e-06 | AN242: 3.7178346e-06 | AO242: 3.8238782e-06 | AP242: 3.9293433e-06 | AQ242: 4.0336762e-06 | AR242: 4.1368665e-06 | AS242: 4.2433221e-06 | AT242: 4.3606162e-06 | AU242: 4.4794808e-06 | AV242: 4.5985652e-06 | AW242: 4.7186613e-06
A243: Coût unitaire du capital CE | B243: UC_K_REHAB_H01_CE_2 | D243: 7.3182617e-06 | E243: 7.4021164e-06 | F243: 5.7561758e-06 | G243: 5.6580872e-06 | H243: 6.1047998e-06 | I243: 6.051061e-06 | J243: 6.1762997e-06 | K243: 6.5880958e-06 | L243: 6.5538588e-06 | M243: 6.3576415e-06 | N243: 6.1649807e-06 | O243: 6.2188481e-06 | P243: 5.6912312e-06 | Q243: 6.2284147e-06 | R243: 5.69122e-06 | S243: 6.3663435e-06 | T243: 5.6987355e-06 | U243: 6.4120768e-06 | V243: 6.0292013e-06 | W243: 6.0126943e-06 | X243: 5.2090785e-06 | Y243: 5.3791652e-06 | Z243: 5.6706766e-06 | AA243: 5.8479046e-06 | AB243: 6.1621819e-06 | AC243: 6.3255445e-06 | AD243: 6.2616863e-06 | AE243: 6.4677995e-06 | AF243: 6.6394919e-06 | AG243: 6.7397388e-06 | AH243: 6.9370004e-06 | AI243: 7.1177992e-06 | AJ243: 7.2233038e-06 | AK243: 7.4071922e-06 | AL243: 7.6054618e-06 | AM243: 7.6010371e-06 | AN243: 7.8589415e-06 | AO243: 8.0831019e-06 | AP243: 8.306039e-06 | AQ243: 8.526583e-06 | AR243: 8.7447119e-06 | AS243: 8.9697429e-06 | AT243: 9.217685e-06 | AU243: 9.4689468e-06 | AV243: 9.7206733e-06 | AW243: 9.9745384e-06
A244: Coût unitaire du capital CF | B244: UC_K_REHAB_H01_CF_2 | D244: 1.1158829e-05 | E244: 1.128669e-05 | F244: 8.7769727e-06 | G244: 8.6274079e-06 | H244: 9.308552e-06 | I244: 9.2266114e-06 | J244: 9.4175744e-06 | K244: 1.0045478e-05 | L244: 9.9932736e-06 | M244: 9.6940829e-06 | N244: 9.4003152e-06 | O244: 9.4824519e-06 | P244: 8.6779458e-06 | Q244: 9.497039e-06 | R244: 8.6779285e-06 | S244: 9.7073517e-06 | T244: 8.6893882e-06 | U244: 9.7770855e-06 | V244: 9.1932799e-06 | W244: 9.1681102e-06 | X244: 7.942763e-06 | Y244: 8.2021098e-06 | Z244: 8.6466042e-06 | AA244: 8.9168401e-06 | AB244: 9.3960476e-06 | AC244: 9.6451417e-06 | AD244: 9.5477713e-06 | AE244: 9.8620511e-06 | AF244: 1.0123846e-05 | AG244: 1.0276702e-05 | AH244: 1.0577485e-05 | AI244: 1.0853166e-05 | AJ244: 1.1014038e-05 | AK244: 1.129443e-05 | AL244: 1.159675e-05 | AM244: 1.1590003e-05 | AN244: 1.1983254e-05 | AO244: 1.2325052e-05 | AP244: 1.2664985e-05 | AQ244: 1.3001268e-05 | AR244: 1.333387e-05 | AS244: 1.3676995e-05 | AT244: 1.4055055e-05 | AU244: 1.4438178e-05 | AV244: 1.4822008e-05 | AW244: 1.52091e-05
A245: Coût unitaire du capital CG | B245: UC_K_REHAB_H01_CG_2 | D245: 1.1136217e-05 | E245: 1.1263819e-05 | F245: 8.7591871e-06 | G245: 8.6099253e-06 | H245: 9.2896891e-06 | I245: 9.2079146e-06 | J245: 9.3984906e-06 | K245: 1.0025122e-05 | L245: 9.9730232e-06 | M245: 9.6744388e-06 | N245: 9.3812664e-06 | O245: 9.4632366e-06 | P245: 8.6603608e-06 | Q245: 9.4777942e-06 | R245: 8.6603436e-06 | S245: 9.6876807e-06 | T245: 8.67178e-06 | U245: 9.7572732e-06 | V245: 9.1746506e-06 | W245: 9.1495319e-06 | X245: 7.9266678e-06 | Y245: 8.1854891e-06 | Z245: 8.6290827e-06 | AA245: 8.898771e-06 | AB245: 9.3770075e-06 | AC245: 9.6255968e-06 | AD245: 9.5284237e-06 | AE245: 9.8420666e-06 | AF245: 1.0103331e-05 | AG245: 1.0255877e-05 | AH245: 1.0556051e-05 | AI245: 1.0831173e-05 | AJ245: 1.0991719e-05 | AK245: 1.1271543e-05 | AL245: 1.157325e-05 | AM245: 1.1566517e-05 | AN245: 1.1958971e-05 | AO245: 1.2300076e-05 | AP245: 1.263932e-05 | AQ245: 1.2974923e-05 | AR245: 1.330685e-05 | AS245: 1.364928e-05 | AT245: 1.4026574e-05 | AU245: 1.440892e-05 | AV245: 1.4791973e-05 | AW245: 1.517828e-05
A246: Subvention à la rénovation CA (M€ constants) | B246: SUB_REHAB_VAL_H01_CA_1 | C246: 0 | D246: 0 | E246: 0 | F246: 0 | G246: 0 | H246: 0 | I246: 0 | J246: 0 | K246: 0 | L246: 0 | M246: 0 | N246: 0 | O246: 0 | P246: 0 | Q246: 0 | R246: 0 | S246: 0 | T246: 0 | U246: 0 | V246: 0 | W246: 0 | X246: 0 | Y246: 0 | Z246: 0 | AA246: 0 | AB246: 0 | AC246: 0 | AD246: 0 | AE246: 0 | AF246: 0 | AG246: 0 | AH246: 0 | AI246: 0 | AJ246: 0 | AK246: 0 | AL246: 0 | AM246: 0 | AN246: 0 | AO246: 0 | AP246: 0 | AQ246: 0 | AR246: 0 | AS246: 0 | AT246: 0 | AU246: 0 | AV246: 0 | AW246: 0
A247: Subvention à la rénovation CB (M€ constants) | B247: SUB_REHAB_VAL_H01_CB_1 | C247: 0 | D247: 0 | E247: 0 | F247: 0.00013503238 | G247: 152.98778 | H247: 216.03471 | I247: 218.29437 | J247: 259.75154 | K247: 190.8707 | L247: 228.87427 | M247: 320.55608 | N247: 481.00491 | O247: 514.52687 | P247: 735.28336 | Q247: 698.84213 | R247: 1039.8408 | S247: 973.97649 | T247: 1508.9163 | U247: 1402.1665 | V247: 1510.6607 | W247: 910.41561 | X247: 1002.8794 | Y247: 0 | Z247: 0 | AA247: 0 | AB247: 0 | AC247: 0 | AD247: 0 | AE247: 0 | AF247: 0 | AG247: 0 | AH247: 0 | AI247: 0 | AJ247: 0 | AK247: 0 | AL247: 0 | AM247: 0 | AN247: 0 | AO247: 0 | AP247: 0 | AQ247: 0 | AR247: 0 | AS247: 0 | AT247: 0 | AU247: 0 | AV247: 0 | AW247: 0
A248: Subvention à la rénovation CC (M€ constants) | B248: SUB_REHAB_VAL_H01_CC_1 | C248: 0 | D248: 0 | E248: 0 | F248: 0.00067244915 | G248: 16.859833 | H248: 36.506958 | I248: 61.94118 | J248: 114.5842 | K248: 108.41514 | L248: 146.45529 | M248: 209.66858 | N248: 302.19969 | O248: 294.32749 | P248: 428.48347 | Q248: 412.70738 | R248: 683.5767 | S248: 600.60743 | T248: 902.80566 | U248: 779.90457 | V248: 839.94526 | W248: 459.56035 | X248: 492.85905 | Y248: 0 | Z248: 0 | AA248: 0 | AB248: 0 | AC248: 0 | AD248: 0 | AE248: 0 | AF248: 0 | AG248: 0 | AH248: 0 | AI248: 0 | AJ248: 0 | AK248: 0 | AL248: 0 | AM248: 0 | AN248: 0 | AO248: 0 | AP248: 0 | AQ248: 0 | AR248: 0 | AS248: 0 | AT248: 0 | AU248: 0 | AV248: 0 | AW248: 0
A249: Subvention à la rénovation CD (M€ constants) | B249: SUB_REHAB_VAL_H01_CD_1 | C249: 0 | D249: 0 | E249: 0 | F249: 78.288711 | G249: 90.988067 | H249: 78.762245 | I249: 56.112706 | J249: 72.456152 | K249: 65.097583 | L249: 90.953034 | M249: 133.21418 | N249: 188.35731 | O249: 158.3237 | P249: 228.7214 | Q249: 254.17437 | R249: 530.68777 | S249: 526.00171 | T249: 821.68192 | U249: 751.16489 | V249: 782.10284 | W249: 409.88359 | X249: 390.14522 | Y249: 0 | Z249: 0 | AA249: 0 | AB249: 0 | AC249: 0 | AD249: 0 | AE249: 0 | AF249: 0 | AG249: 0 | AH249: 0 | AI249: 0 | AJ249: 0 | AK249: 0 | AL249: 0 | AM249: 0 | AN249: 0 | AO249: 0 | AP249: 0 | AQ249: 0 | AR249: 0 | AS249: 0 | AT249: 0 | AU249: 0 | AV249: 0 | AW249: 0
A250: Subvention à la rénovation CE (M€ constants) | B250: SUB_REHAB_VAL_H01_CE_1 | C250: 0 | D250: 0 | E250: 0 | F250: 297.15475 | G250: 331.79758 | H250: 290.38186 | I250: 166.69439 | J250: 189.0671 | K250: 174.70294 | L250: 247.09012 | M250: 317.01085 | N250: 335.84459 | O250: 283.34712 | P250: 348.51186 | Q250: 438.51122 | R250: 1035.816 | S250: 981.23654 | T250: 1492.993 | U250: 1274.314 | V250: 1282.8503 | W250: 660.73376 | X250: 647.44927 | Y250: 0 | Z250: 0 | AA250: 0 | AB250: 0 | AC250: 0 | AD250: 0 | AE250: 0 | AF250: 0 | AG250: 0 | AH250: 0 | AI250: 0 | AJ250: 0 | AK250: 0 | AL250: 0 | AM250: 0 | AN250: 0 | AO250: 0 | AP250: 0 | AQ250: 0 | AR250: 0 | AS250: 0 | AT250: 0 | AU250: 0 | AV250: 0 | AW250: 0
A251: Subvention à la rénovation CF (M€ constants) | B251: SUB_REHAB_VAL_H01_CF_1 | C251: 0 | D251: 0 | E251: 0 | F251: 268.22371 | G251: 312.32736 | H251: 289.01243 | I251: 179.08071 | J251: 212.17465 | K251: 194.93855 | L251: 271.23808 | M251: 347.84121 | N251: 381.54141 | O251: 329.40342 | P251: 402.52954 | Q251: 460.54204 | R251: 997.72536 | S251: 914.5752 | T251: 1386.5086 | U251: 1168.9478 | V251: 1185.7883 | W251: 620.22038 | X251: 607.74827 | Y251: 0 | Z251: 0 | AA251: 0 | AB251: 0 | AC251: 0 | AD251: 0 | AE251: 0 | AF251: 0 | AG251: 0 | AH251: 0 | AI251: 0 | AJ251: 0 | AK251: 0 | AL251: 0 | AM251: 0 | AN251: 0 | AO251: 0 | AP251: 0 | AQ251: 0 | AR251: 0 | AS251: 0 | AT251: 0 | AU251: 0 | AV251: 0 | AW251: 0
A252: Subvention à la rénovation CG (M€ constants) | B252: SUB_REHAB_VAL_H01_CG_1 | C252: 0 | D252: 0 | E252: 0 | F252: 336.56001 | G252: 361.23348 | H252: 320.25701 | I252: 238.23679 | J252: 258.71242 | K252: 194.54666 | L252: 228.30981 | M252: 283.63452 | N252: 342.37766 | O252: 264.27333 | P252: 289.29728 | Q252: 271.05429 | R252: 469.44721 | S252: 421.48574 | T252: 590.36133 | U252: 499.00247 | V252: 477.74723 | W252: 245.49103 | X252: 231.34957 | Y252: 0 | Z252: 0 | AA252: 0 | AB252: 0 | AC252: 0 | AD252: 0 | AE252: 0 | AF252: 0 | AG252: 0 | AH252: 0 | AI252: 0 | AJ252: 0 | AK252: 0 | AL252: 0 | AM252: 0 | AN252: 0 | AO252: 0 | AP252: 0 | AQ252: 0 | AR252: 0 | AS252: 0 | AT252: 0 | AU252: 0 | AV252: 0 | AW252: 0
A253: Subvention à la rénovation CA (M€ constants) choc | B253: SUB_REHAB_VAL_H01_CA_2 | C253: 0 | D253: 0 | E253: 0 | F253: 0 | G253: 0 | H253: 0 | I253: 0 | J253: 0 | K253: 0 | L253: 0 | M253: 0 | N253: 0 | O253: 0 | P253: 0 | Q253: 0 | R253: 0 | S253: 0 | T253: 0 | U253: 0 | V253: 0 | W253: 0 | X253: 0 | Y253: 0 | Z253: 0 | AA253: 0 | AB253: 0 | AC253: 0 | AD253: 0 | AE253: 0 | AF253: 0 | AG253: 0 | AH253: 0 | AI253: 0 | AJ253: 0 | AK253: 0 | AL253: 0 | AM253: 0 | AN253: 0 | AO253: 0 | AP253: 0 | AQ253: 0 | AR253: 0 | AS253: 0 | AT253: 0 | AU253: 0 | AV253: 0 | AW253: 0
A254: Subvention à la rénovation CB (M€ constants) | B254: SUB_REHAB_VAL_H01_CB_2 | C254: 0 | D254: 0 | E254: 0 | F254: 0.00013503238 | G254: 152.98778 | H254: 216.03471 | I254: 218.29437 | J254: 259.75154 | K254: 190.8707 | L254: 228.87427 | M254: 320.55608 | N254: 481.00491 | O254: 514.52687 | P254: 735.28336 | Q254: 698.84213 | R254: 1039.8408 | S254: 973.97649 | T254: 1508.9163 | U254: 1402.1665 | V254: 1513.3814 | W254: 1744.5877 | X254: 2583.4226 | Y254: 2908.9114 | Z254: 3149.0737 | AA254: 3440.0106 | AB254: 3517.5056 | AC254: 3688.4624 | AD254: 4088.0479 | AE254: 4200.6743 | AF254: 4329.1027 | AG254: 4523.4725 | AH254: 4598.391 | AI254: 4675.3336 | AJ254: 4823.4376 | AK254: 4871.1233 | AL254: 4904.0546 | AM254: 5184.5207 | AN254: 5199.9082 | AO254: 5251.26 | AP254: 5296.1899 | AQ254: 5328.4593 | AR254: 5350.547 | AS254: 5357.2737 | AT254: 5346.962 | AU254: 5345.7876 | AV254: 5356.0865 | AW254: 5376.1027
A255: Subvention à la rénovation CC (M€ constants) | B255: SUB_REHAB_VAL_H01_CC_2 | C255: 0 | D255: 0 | E255: 0 | F255: 0.00067244915 | G255: 16.859833 | H255: 36.506958 | I255: 61.94118 | J255: 114.5842 | K255: 108.41514 | L255: 146.45529 | M255: 209.66858 | N255: 302.19969 | O255: 294.32749 | P255: 428.48347 | Q255: 412.70738 | R255: 683.5767 | S255: 600.60743 | T255: 902.80566 | U255: 779.90457 | V255: 839.58911 | W255: 983.59525 | X255: 1629.0263 | Y255: 1932.14 | Z255: 2010.6501 | AA255: 2084.2714 | AB255: 2048.9128 | AC255: 2117.9787 | AD255: 2385.3209 | AE255: 2447.0878 | AF255: 2476.6594 | AG255: 2564.4335 | AH255: 2588.2818 | AI255: 2587.5929 | AJ255: 2637.7091 | AK255: 2649.1643 | AL255: 2651.6207 | AM255: 2837.9746 | AN255: 2863.5044 | AO255: 2835.2522 | AP255: 2799.9463 | AQ255: 2763.4282 | AR255: 2726.9108 | AS255: 2707.5708 | AT255: 2720.5605 | AU255: 2737.6491 | AV255: 2757.7768 | AW255: 2778.1704
A256: Subvention à la rénovation CD (M€ constants) | B256: SUB_REHAB_VAL_H01_CD_2 | C256: 0 | D256: 0 | E256: 0 | F256: 78.288711 | G256: 90.988067 | H256: 78.762245 | I256: 56.112706 | J256: 72.456152 | K256: 65.097583 | L256: 90.953034 | M256: 133.21418 | N256: 188.35731 | O256: 158.3237 | P256: 228.7214 | Q256: 254.17437 | R256: 530.68777 | S256: 526.00171 | T256: 821.68192 | U256: 751.16489 | V256: 781.02711 | W256: 895.76914 | X256: 1485.8399 | Y256: 1839.0477 | Z256: 1852.1284 | AA256: 1812.9359 | AB256: 1674.2122 | AC256: 1614.3209 | AD256: 1720.3057 | AE256: 1687.475 | AF256: 1605.9963 | AG256: 1572.1938 | AH256: 1511.3394 | AI256: 1434.1142 | AJ256: 1391.5568 | AK256: 1338.7482 | AL256: 1282.2719 | AM256: 1327.07 | AN256: 1311.1782 | AO256: 1249.0987 | AP256: 1187.686 | AQ256: 1132.2423 | AR256: 1090.336 | AS256: 1053.6552 | AT256: 1032.5302 | AU256: 1015.0735 | AV256: 999.13124 | AW256: 983.17381
A257: Subvention à la rénovation CE (M€ constants) | B257: SUB_REHAB_VAL_H01_CE_2 | C257: 0 | D257: 0 | E257: 0 | F257: 297.15475 | G257: 331.79758 | H257: 290.38186 | I257: 166.69439 | J257: 189.0671 | K257: 174.70294 | L257: 247.09012 | M257: 317.01085 | N257: 335.84459 | O257: 283.34712 | P257: 348.51186 | Q257: 438.51122 | R257: 1035.816 | S257: 981.23654 | T257: 1492.993 | U257: 1274.314 | V257: 1277.2082 | W257: 1360.7707 | X257: 2016.3721 | Y257: 2156.003 | Z257: 1978.1596 | AA257: 1807.3402 | AB257: 1584.4254 | AC257: 1522.7135 | AD257: 1609.3769 | AE257: 1515.1364 | AF257: 1391.9361 | AG257: 1305.3704 | AH257: 1200.4554 | AI257: 1103.3317 | AJ257: 1033.3757 | AK257: 950.0233 | AL257: 884.12163 | AM257: 924.64158 | AN257: 909.89965 | AO257: 862.77345 | AP257: 812.04866 | AQ257: 760.24701 | AR257: 707.94853 | AS257: 671.79831 | AT257: 682.01945 | AU257: 703.58663 | AV257: 723.04758 | AW257: 736.84006
... A469: Taux d'intérêt directeur | B469: R_DIR_2 | C469: 0.02637643 | D469: 0.02637643 | E469: 0.013276695 | F469: 0.0096219735 | G469: 0.020462196 | H469: 0.0078342748 | I469: 0.015112648 | J469: 0.014958585 | K469: 0.01552575 | L469: 0.013503432 | M469: 0.016129302 | N469: 0.013312163 | O469: 0.013202983 | P469: 0.020584777 | Q469: 0.026723349 | R469: 0.024559854 | S469: 0.026213344 | T469: 0.026268186 | U469: 0.026752761 | V469: 0.026713653 | W469: 0.027659423 | X469: 0.027662767 | Y469: 0.026055448 | Z469: 0.02602458 | AA469: 0.026311389 | AB469: 0.027418035 | AC469: 0.027664483 | AD469: 0.027130643 | AE469: 0.026762764 | AF469: 0.0267073 | AG469: 0.026804054 | AH469: 0.026672382 | AI469: 0.026643006 | AJ469: 0.026652602 | AK469: 0.026921291 | AL469: 0.026874944 | AM469: 0.027136271 | AN469: 0.02701082 | AO469: 0.027155187 | AP469: 0.027251786 | AQ469: 0.027215843 | AR469: 0.027219554 | AS469: 0.027309751 | AT469: 0.027270024 | AU469: 0.027184411 | AV469: 0.027097897 | AW469: 0.027128778
B470: TS_2 | C470: 0.043327542 | D470: 0.043327542 | E470: 0.059872177 | F470: 0.071907338 | G470: 0.080391001 | H470: 0.061875943 | I470: 0.034763886 | J470: 0.039273311 | K470: 0.051220228 | L470: 0.044855211 | M470: 0.039804271 | N470: 0.043244748 | O470: 0.041207826 | P470: 0.037947118 | Q470: 0.040783076 | R470: 0.041889179 | S470: 0.055257917 | T470: 0.060711416 | U470: 0.06692993 | V470: 0.062430978 | W470: 0.059547477 | X470: 0.061772863 | Y470: 0.066182449 | Z470: 0.067406879 | AA470: 0.069921674 | AB470: 0.073316566 | AC470: 0.076456752 | AD470: 0.077955901 | AE470: 0.078594258 | AF470: 0.080116707 | AG470: 0.082108762 | AH470: 0.083887697 | AI470: 0.085907874 | AJ470: 0.088796714 | AK470: 0.091233513 | AL470: 0.094347995 | AM470: 0.097158824 | AN470: 0.099261099 | AO470: 0.10086867 | AP470: 0.10280785 | AQ470: 0.10447431 | AR470: 0.10595161 | AS470: 0.10748534 | AT470: 0.10890689 | AU470: 0.11037683 | AV470: 0.11183009 | AW470: 0.11299548
...

Sheet taux de profit des secteurs
D1: =résultats!C1 -> 2004 | E1: =résultats!D1 -> 2005 | F1: =résultats!E1 -> 2006 | G1: =résultats!F1 -> 2007 | H1: =résultats!G1 -> 2008 | I1: =résultats!H1 -> 2009 | J1: =résultats!I1 -> 2010 | K1: =résultats!J1 -> 2011 | ... AX1: =résultats!AW1 -> 2050
A2: AME | B2: taux de profit du secteur 01 | D2: =résultats!C593*résultats!C631/(résultats!C745*résultats!C783) -> 0 | E2: =résultats!D593*résultats!D631/(résultats!D745*résultats!D783) -> 0 | F2: =résultats!E593*résultats!E631/(résultats!E745*résultats!E783) -> 0.3153017 | G2: =résultats!F593*résultats!F631/(résultats!F745*résultats!F783) -> 0.28794528 | H2: =résultats!G593*résultats!G631/(résultats!G745*résultats!G783) -> 0.28150983 | I2: =résultats!H593*résultats!H631/(résultats!H745*résultats!H783) -> 0.24702375 | J2: =résultats!I593*résultats!I631/(résultats!I745*résultats!I783) -> 0.26356396 | K2: =résultats!J593*résultats!J631/(résultats!J745*résultats!J783) -> 0.29120181 | ... AX2: =résultats!AW593*résultats!AW631/(résultats!AW745*résultats!AW783) -> 0.28808806
B3: taux de profit du secteur 02 | D3: =résultats!C594*résultats!C632/(résultats!C746*résultats!C784) -> 0 | E3: =résultats!D594*résultats!D632/(résultats!D746*résultats!D784) -> 0 | F3: =résultats!E594*résultats!E632/(résultats!E746*résultats!E784) -> 0.21442462 | G3: =résultats!F594*résultats!F632/(résultats!F746*résultats!F784) -> 0.19065248 | H3: =résultats!G594*résultats!G632/(résultats!G746*résultats!G784) -> 0.21115328 | I3: =résultats!H594*résultats!H632/(résultats!H746*résultats!H784) -> 0.16457804 | J3: =résultats!I594*résultats!I632/(résultats!I746*résultats!I784) -> 0.21094316 | K3: =résultats!J594*résultats!J632/(résultats!J746*résultats!J784) -> 0.19579752 | ... AX3: =résultats!AW594*résultats!AW632/(résultats!AW746*résultats!AW784) -> 0.14826013
B4: taux de profit du secteur 03 | D4: =résultats!C595*résultats!C633/(résultats!C747*résultats!C785) -> 0 | E4: =résultats!D595*résultats!D633/(résultats!D747*résultats!D785) -> 0 | F4: =résultats!E595*résultats!E633/(résultats!E747*résultats!E785) -> -0.081916677 | G4: =résultats!F595*résultats!F633/(résultats!F747*résultats!F785) -> -0.11514296 | H4: =résultats!G595*résultats!G633/(résultats!G747*résultats!G785) -> -0.18285581 | I4: =résultats!H595*résultats!H633/(résultats!H747*résultats!H785) -> -0.20427668 | J4: =résultats!I595*résultats!I633/(résultats!I747*résultats!I785) -> -0.16152618 | K4: =résultats!J595*résultats!J633/(résultats!J747*résultats!J785) -> -0.0061792214 | ... AX4: =résultats!AW595*résultats!AW633/(résultats!AW747*résultats!AW785) -> -2.3746086
B5: taux de profit du secteur 04 | D5: =résultats!C596*résultats!C634/(résultats!C748*résultats!C786) -> 0 | E5: =résultats!D596*résultats!D634/(résultats!D748*résultats!D786) -> 0 | F5: =résultats!E596*résultats!E634/(résultats!E748*résultats!E786) -> -0.14995298 | G5: =résultats!F596*résultats!F634/(résultats!F748*résultats!F786) -> -0.16699672 | H5: =résultats!G596*résultats!G634/(résultats!G748*résultats!G786) -> -0.19740779 | I5: =résultats!H596*résultats!H634/(résultats!H748*résultats!H786) -> -0.27798697 | J5: =résultats!I596*résultats!I634/(résultats!I748*résultats!I786) -> -0.25834634 | K5: =résultats!J596*résultats!J634/(résultats!J748*résultats!J786) -> -0.11385242 | ... AX5: =résultats!AW596*résultats!AW634/(résultats!AW748*résultats!AW786) -> 0.32536918
B6: taux de profit du secteur 05 | D6: =résultats!C597*résultats!C635/(résultats!C749*résultats!C787) -> 0 | E6: =résultats!D597*résultats!D635/(résultats!D749*résultats!D787) -> 0 | F6: =résultats!E597*résultats!E635/(résultats!E749*résultats!E787) -> 0.10198844 | G6: =résultats!F597*résultats!F635/(résultats!F749*résultats!F787) -> 0.090015104 | H6: =résultats!G597*résultats!G635/(résultats!G749*résultats!G787) -> 0.079883284 | I6: =résultats!H597*résultats!H635/(résultats!H749*résultats!H787) -> 0.035800349 | J6: =résultats!I597*résultats!I635/(résultats!I749*résultats!I787) -> 0.0083265154 | K6: =résultats!J597*résultats!J635/(résultats!J749*résultats!J787) -> 0.10021936 | ... AX6: =résultats!AW597*résultats!AW635/(résultats!AW749*résultats!AW787) -> -0.0319538
B7: taux de profit du secteur 06 | D7: =résultats!C598*résultats!C636/(résultats!C750*résultats!C788) -> 0 | E7: =résultats!D598*résultats!D636/(résultats!D750*résultats!D788) -> 0 | F7: =résultats!E598*résultats!E636/(résultats!E750*résultats!E788) -> -0.10362457 | G7: =résultats!F598*résultats!F636/(résultats!F750*résultats!F788) -> -0.12389702 | H7: =résultats!G598*résultats!G636/(résultats!G750*résultats!G788) -> -0.15058704 | I7: =résultats!H598*résultats!H636/(résultats!H750*résultats!H788) -> -0.2138281 | J7: =résultats!I598*résultats!I636/(résultats!I750*résultats!I788) -> -0.19849119 | K7: =résultats!J598*résultats!J636/(résultats!J750*résultats!J788) -> -0.059264449 | ... AX7: =résultats!AW598*résultats!AW636/(résultats!AW750*résultats!AW788) -> 7.0093775
B8: taux de profit du secteur 07 | D8: =résultats!C599*résultats!C637/(résultats!C751*résultats!C789) -> 0 | E8: =résultats!D599*résultats!D637/(résultats!D751*résultats!D789) -> 0 | F8: =résultats!E599*résultats!E637/(résultats!E751*résultats!E789) -> -1.4048059 | G8: =résultats!F599*résultats!F637/(résultats!F751*résultats!F789) -> -1.4753344 | H8: =résultats!G599*résultats!G637/(résultats!G751*résultats!G789) -> -1.4857453 | I8: =résultats!H599*résultats!H637/(résultats!H751*résultats!H789) -> -1.4956492 | J8: =résultats!I599*résultats!I637/(résultats!I751*résultats!I789) -> -1.4663933 | K8: =résultats!J599*résultats!J637/(résultats!J751*résultats!J789) -> -1.4975985 | ... AX8: =résultats!AW599*résultats!AW637/(résultats!AW751*résultats!AW789) -> -3.0431729
B9: taux de profit du secteur 08 | D9: =résultats!C600*résultats!C638/(résultats!C752*résultats!C790) -> 0 | E9: =résultats!D600*résultats!D638/(résultats!D752*résultats!D790) -> 0 | F9: =résultats!E600*résultats!E638/(résultats!E752*résultats!E790) -> 0.064171195 | G9: =résultats!F600*résultats!F638/(résultats!F752*résultats!F790) -> 0.051653249 | H9: =résultats!G600*résultats!G638/(résultats!G752*résultats!G790) -> 0.025443432 | I9: =résultats!H600*résultats!H638/(résultats!H752*résultats!H790) -> -0.010540966 | J9: =résultats!I600*résultats!I638/(résultats!I752*résultats!I790) -> 0.091809914 | K9: =résultats!J600*résultats!J638/(résultats!J752*résultats!J790) -> -0.00067427171 | ... AX9: =résultats!AW600*résultats!AW638/(résultats!AW752*résultats!AW790) -> 0.11788208
B10: taux de profit du secteur 09 | D10: =résultats!C601*résultats!C639/(résultats!C753*résultats!C791) -> 0 | E10: =résultats!D601*résultats!D639/(résultats!D753*résultats!D791) -> 0 | F10: =résultats!E601*résultats!E639/(résultats!E753*résultats!E791) -> -0.010110392 | G10: =résultats!F601*résultats!F639/(résultats!F753*résultats!F791) -> -0.023743679 | H10: =résultats!G601*résultats!G639/(résultats!G753*résultats!G791) -> -0.01557274 | I10: =résultats!H601*résultats!H639/(résultats!H753*résultats!H791) -> -0.071286632 | J10: =résultats!I601*résultats!I639/(résultats!I753*résultats!I791) -> -0.12586034 | K10: =résultats!J601*résultats!J639/(résultats!J753*résultats!J791) -> 0.015003135 | ... AX10: =résultats!AW601*résultats!AW639/(résultats!AW753*résultats!AW791) -> -0.03069986
B11: taux de profit du secteur 10 | D11: =résultats!C602*résultats!C640/(résultats!C754*résultats!C792) -> 0 | E11: =résultats!D602*résultats!D640/(résultats!D754*résultats!D792) -> 0 | F11: =résultats!E602*résultats!E640/(résultats!E754*résultats!E792) -> 0.12768421 | G11: =résultats!F602*résultats!F640/(résultats!F754*résultats!F792) -> 0.12026196 | H11: =résultats!G602*résultats!G640/(résultats!G754*résultats!G792) -> 0.079612809 | I11: =résultats!H602*résultats!H640/(résultats!H754*résultats!H792) -> 0.045782567 | J11: =résultats!I602*résultats!I640/(résultats!I754*résultats!I792) -> -0.032459835 | K11: =résultats!J602*résultats!J640/(résultats!J754*résultats!J792) -> 0.21172632 | ... AX11: =résultats!AW602*résultats!AW640/(résultats!AW754*résultats!AW792) -> 0.06683275
B12: taux de profit du secteur 11 | D12: =résultats!C603*résultats!C641/(résultats!C755*résultats!C793) -> 0 | E12: =résultats!D603*résultats!D641/(résultats!D755*résultats!D793) -> 0 | F12: =résultats!E603*résultats!E641/(résultats!E755*résultats!E793) -> -0.021298662 | G12: =résultats!F603*résultats!F641/(résultats!F755*résultats!F793) -> -0.045168717 | H12: =résultats!G603*résultats!G641/(résultats!G755*résultats!G793) -> -0.12078134 | I12: =résultats!H603*résultats!H641/(résultats!H755*résultats!H793) -> -0.11387767 | J12: =résultats!I603*résultats!I641/(résultats!I755*résultats!I793) -> -0.14367054 | K12: =résultats!J603*résultats!J641/(résultats!J755*résultats!J793) -> 0.069157491 | ... AX12: =résultats!AW603*résultats!AW641/(résultats!AW755*résultats!AW793) -> -0.91476189
B13: taux de profit du secteur 12 | D13: =résultats!C604*résultats!C642/(résultats!C756*résultats!C794) -> 0 | E13: =résultats!D604*résultats!D642/(résultats!D756*résultats!D794) -> 0 | F13: =résultats!E604*résultats!E642/(résultats!E756*résultats!E794) -> 0.14022959 | G13: =résultats!F604*résultats!F642/(résultats!F756*résultats!F794) -> 0.12651204 | H13: =résultats!G604*résultats!G642/(résultats!G756*résultats!G794) -> 0.13835781 | I13: =résultats!H604*résultats!H642/(résultats!H756*résultats!H794) -> 0.1236868 | J13: =résultats!I604*résultats!I642/(résultats!I756*résultats!I794) -> 0.089280171 | K13: =résultats!J604*résultats!J642/(résultats!J756*résultats!J794) -> 0.13037538 | ... AX13: =résultats!AW604*résultats!AW642/(résultats!AW756*résultats!AW794) -> 0.12976674
B14: taux de profit du secteur 13 | D14: =résultats!C605*résultats!C643/(résultats!C757*résultats!C795) -> 0 | E14: =résultats!D605*résultats!D643/(résultats!D757*résultats!D795) -> 0 | F14: =résultats!E605*résultats!E643/(résultats!E757*résultats!E795) -> 0.26684707 | G14: =résultats!F605*résultats!F643/(résultats!F757*résultats!F795) -> 0.25223664 | H14: =résultats!G605*résultats!G643/(résultats!G757*résultats!G795) -> 0.27715862 | I14: =résultats!H605*résultats!H643/(résultats!H757*résultats!H795) -> 0.29416068 | J14: =résultats!I605*résultats!I643/(résultats!I757*résultats!I795) -> 0.23413574 | K14: =résultats!J605*résultats!J643/(résultats!J757*résultats!J795) -> 0.24100925 | ... AX14: =résultats!AW605*résultats!AW643/(résultats!AW757*résultats!AW795) -> 0.17800244
... B21: taux de profit du secteur 20 | D21: =résultats!C612*résultats!C650/(résultats!C764*résultats!C802) -> 0 | E21: =résultats!D612*résultats!D650/(résultats!D764*résultats!D802) -> 0 | F21: =résultats!E612*résultats!E650/(résultats!E764*résultats!E802) -> -0.02847956 | G21: =résultats!F612*résultats!F650/(résultats!F764*résultats!F802) -> -0.053414286 | H21: =résultats!G612*résultats!G650/(résultats!G764*résultats!G802) -> -0.066716291 | I21: =résultats!H612*résultats!H650/(résultats!H764*résultats!H802) -> -0.069259825 | J21: =résultats!I612*résultats!I650/(résultats!I764*résultats!I802) -> -0.056551516 | K21: =résultats!J612*résultats!J650/(résultats!J764*résultats!J802) -> -0.058119802 | ... AX21: =résultats!AW612*résultats!AW650/(résultats!AW764*résultats!AW802) -> -0.020858651
A22: AMS | B22: taux de profit du secteur 01 | D22: =résultats!C669*résultats!C707/(résultats!C745*résultats!C783) -> 0 | E22: =résultats!D669*résultats!D707/(résultats!D745*résultats!D783) -> 0 | F22: =résultats!E669*résultats!E707/(résultats!E745*résultats!E783) -> 0.3153017 | G22: =résultats!F669*résultats!F707/(résultats!F745*résultats!F783) -> 0.28794528 | H22: =résultats!G669*résultats!G707/(résultats!G745*résultats!G783) -> 0.28150983 | I22: =résultats!H669*résultats!H707/(résultats!H745*résultats!H783) -> 0.24702375 | J22: =résultats!I669*résultats!I707/(résultats!I745*résultats!I783) -> 0.26356396 | K22: =résultats!J669*résultats!J707/(résultats!J745*résultats!J783) -> 0.29120181 | ... AX22: =résultats!AW669*résultats!AW707/(résultats!AW745*résultats!AW783) -> 0.37220832
B23: taux de profit du secteur 02 | D23: =résultats!C670*résultats!C708/(résultats!C746*résultats!C784) -> 0 | E23: =résultats!D670*résultats!D708/(résultats!D746*résultats!D784) -> 0 | F23: =résultats!E670*résultats!E708/(résultats!E746*résultats!E784) -> 0.21442462 | G23: =résultats!F670*résultats!F708/(résultats!F746*résultats!F784) -> 0.19065248 | H23: =résultats!G670*résultats!G708/(résultats!G746*résultats!G784) -> 0.21115328 | I23: =résultats!H670*résultats!H708/(résultats!H746*résultats!H784) -> 0.16457804 | J23: =résultats!I670*résultats!I708/(résultats!I746*résultats!I784) -> 0.21094316 | K23: =résultats!J670*résultats!J708/(résultats!J746*résultats!J784) -> 0.19579752 | ... AX23: =résultats!AW670*résultats!AW708/(résultats!AW746*résultats!AW784) -> 0.11009019
B24: taux de profit du secteur 03 | D24: =résultats!C671*résultats!C709/(résultats!C747*résultats!C785) -> 0 | E24: =résultats!D671*résultats!D709/(résultats!D747*résultats!D785) -> 0 | F24: =résultats!E671*résultats!E709/(résultats!E747*résultats!E785) -> -0.081916677 | G24: =résultats!F671*résultats!F709/(résultats!F747*résultats!F785) -> -0.11514296 | H24: =résultats!G671*résultats!G709/(résultats!G747*résultats!G785) -> -0.18285581 | I24: =résultats!H671*résultats!H709/(résultats!H747*résultats!H785) -> -0.20427668 | J24: =résultats!I671*résultats!I709/(résultats!I747*résultats!I785) -> -0.16152618 | K24: =résultats!J671*résultats!J709/(résultats!J747*résultats!J785) -> -0.0061792214 | ... AX24: =résultats!AW671*résultats!AW709/(résultats!AW747*résultats!AW785) -> -1.7621845
B25: taux de profit du secteur 04 | D25: =résultats!C672*résultats!C710/(résultats!C748*résultats!C786) -> 0 | E25: =résultats!D672*résultats!D710/(résultats!D748*résultats!D786) -> 0 | F25: =résultats!E672*résultats!E710/(résultats!E748*résultats!E786) -> -0.14995298 | G25: =résultats!F672*résultats!F710/(résultats!F748*résultats!F786) -> -0.16699672 | H25: =résultats!G672*résultats!G710/(résultats!G748*résultats!G786) -> -0.19740779 | I25: =résultats!H672*résultats!H710/(résultats!H748*résultats!H786) -> -0.27798697 | J25: =résultats!I672*résultats!I710/(résultats!I748*résultats!I786) -> -0.25834634 | K25: =résultats!J672*résultats!J710/(résultats!J748*résultats!J786) -> -0.11385242 | ... AX25: =résultats!AW672*résultats!AW710/(résultats!AW748*résultats!AW786) -> 0.26838219
B26: taux de profit du secteur 05 | D26: =résultats!C673*résultats!C711/(résultats!C749*résultats!C787) -> 0 | E26: =résultats!D673*résultats!D711/(résultats!D749*résultats!D787) -> 0 | F26: =résultats!E673*résultats!E711/(résultats!E749*résultats!E787) -> 0.10198844 | G26: =résultats!F673*résultats!F711/(résultats!F749*résultats!F787) -> 0.090015104 | H26: =résultats!G673*résultats!G711/(résultats!G749*résultats!G787) -> 0.079883284 | I26: =résultats!H673*résultats!H711/(résultats!H749*résultats!H787) -> 0.035800349 | J26: =résultats!I673*résultats!I711/(résultats!I749*résultats!I787) -> 0.0083265154 | K26: =résultats!J673*résultats!J711/(résultats!J749*résultats!J787) -> 0.10021936 | ... AX26: =résultats!AW673*résultats!AW711/(résultats!AW749*résultats!AW787) -> -0.16095784
B27: taux de profit du secteur 06 | D27: =résultats!C674*résultats!C712/(résultats!C750*résultats!C788) -> 0 | E27: =résultats!D674*résultats!D712/(résultats!D750*résultats!D788) -> 0 | F27: =résultats!E674*résultats!E712/(résultats!E750*résultats!E788) -> -0.10362457 | G27: =résultats!F674*résultats!F712/(résultats!F750*résultats!F788) -> -0.12389702 | H27: =résultats!G674*résultats!G712/(résultats!G750*résultats!G788) -> -0.15058704 | I27: =résultats!H674*résultats!H712/(résultats!H750*résultats!H788) -> -0.2138281 | J27: =résultats!I674*résultats!I712/(résultats!I750*résultats!I788) -> -0.19849119 | K27: =résultats!J674*résultats!J712/(résultats!J750*résultats!J788) -> -0.059264449 | ... AX27: =résultats!AW674*résultats!AW712/(résultats!AW750*résultats!AW788) -> 10.326529
B28: taux de profit du secteur 07 | D28: =résultats!C675*résultats!C713/(résultats!C751*résultats!C789) -> 0 | E28: =résultats!D675*résultats!D713/(résultats!D751*résultats!D789) -> 0 | F28: =résultats!E675*résultats!E713/(résultats!E751*résultats!E789) -> -1.4048059 | G28: =résultats!F675*résultats!F713/(résultats!F751*résultats!F789) -> -1.4753344 | H28: =résultats!G675*résultats!G713/(résultats!G751*résultats!G789) -> -1.4857453 | I28: =résultats!H675*résultats!H713/(résultats!H751*résultats!H789) -> -1.4956492 | J28: =résultats!I675*résultats!I713/(résultats!I751*résultats!I789) -> -1.4663933 | K28: =résultats!J675*résultats!J713/(résultats!J751*résultats!J789) -> -1.4975985 | ... AX28: =résultats!AW675*résultats!AW713/(résultats!AW751*résultats!AW789) -> -4.0018815
B29: taux de profit du secteur 08 | D29: =résultats!C676*résultats!C714/(résultats!C752*résultats!C790) -> 0 | E29: =résultats!D676*résultats!D714/(résultats!D752*résultats!D790) -> 0 | F29: =résultats!E676*résultats!E714/(résultats!E752*résultats!E790) -> 0.064171195 | G29: =résultats!F676*résultats!F714/(résultats!F752*résultats!F790) -> 0.051653249 | H29: =résultats!G676*résultats!G714/(résultats!G752*résultats!G790) -> 0.025443432 | I29: =résultats!H676*résultats!H714/(résultats!H752*résultats!H790) -> -0.010540966 | J29: =résultats!I676*résultats!I714/(résultats!I752*résultats!I790) -> 0.091809914 | K29: =résultats!J676*résultats!J714/(résultats!J752*résultats!J790) -> -0.00067427171 | ... AX29: =résultats!AW676*résultats!AW714/(résultats!AW752*résultats!AW790) -> 0.10958392
B30: taux de profit du secteur 09 | D30: =résultats!C677*résultats!C715/(résultats!C753*résultats!C791) -> 0 | E30: =résultats!D677*résultats!D715/(résultats!D753*résultats!D791) -> 0 | F30: =résultats!E677*résultats!E715/(résultats!E753*résultats!E791) -> -0.010110392 | G30: =résultats!F677*résultats!F715/(résultats!F753*résultats!F791) -> -0.023743679 | H30: =résultats!G677*résultats!G715/(résultats!G753*résultats!G791) -> -0.01557274 | I30: =résultats!H677*résultats!H715/(résultats!H753*résultats!H791) -> -0.071286632 | J30: =résultats!I677*résultats!I715/(résultats!I753*résultats!I791) -> -0.12586034 | K30: =résultats!J677*résultats!J715/(résultats!J753*résultats!J791) -> 0.015003135 | ... AX30: =résultats!AW677*résultats!AW715/(résultats!AW753*résultats!AW791) -> -0.079175424
B31: taux de profit du secteur 10 | D31: =résultats!C678*résultats!C716/(résultats!C754*résultats!C792) -> 0 | E31: =résultats!D678*résultats!D716/(résultats!D754*résultats!D792) -> 0 | F31: =résultats!E678*résultats!E716/(résultats!E754*résultats!E792) -> 0.12768421 | G31: =résultats!F678*résultats!F716/(résultats!F754*résultats!F792) -> 0.12026196 | H31: =résultats!G678*résultats!G716/(résultats!G754*résultats!G792) -> 0.079612809 | I31: =résultats!H678*résultats!H716/(résultats!H754*résultats!H792) -> 0.045782567 | J31: =résultats!I678*résultats!I716/(résultats!I754*résultats!I792) -> -0.032459835 | K31: =résultats!J678*résultats!J716/(résultats!J754*résultats!J792) -> 0.21172632 | ... AX31: =résultats!AW678*résultats!AW716/(résultats!AW754*résultats!AW792) -> -0.076762043
B32: taux de profit du secteur 11 | D32: =résultats!C679*résultats!C717/(résultats!C755*résultats!C793) -> 0 | E32: =résultats!D679*résultats!D717/(résultats!D755*résultats!D793) -> 0 | F32: =résultats!E679*résultats!E717/(résultats!E755*résultats!E793) -> -0.021298662 | G32: =résultats!F679*résultats!F717/(résultats!F755*résultats!F793) -> -0.045168717 | H32: =résultats!G679*résultats!G717/(résultats!G755*résultats!G793) -> -0.12078134 | I32: =résultats!H679*résultats!H717/(résultats!H755*résultats!H793) -> -0.11387767 | J32: =résultats!I679*résultats!I717/(résultats!I755*résultats!I793) -> -0.14367054 | K32: =résultats!J679*résultats!J717/(résultats!J755*résultats!J793) -> 0.069157491 | ... AX32: =résultats!AW679*résultats!AW717/(résultats!AW755*résultats!AW793) -> -1.1507501
B33: taux de profit du secteur 12 | D33: =résultats!C680*résultats!C718/(résultats!C756*résultats!C794) -> 0 | E33: =résultats!D680*résultats!D718/(résultats!D756*résultats!D794) -> 0 | F33: =résultats!E680*résultats!E718/(résultats!E756*résultats!E794) -> 0.14022959 | G33: =résultats!F680*résultats!F718/(résultats!F756*résultats!F794) -> 0.12651204 | H33: =résultats!G680*résultats!G718/(résultats!G756*résultats!G794) -> 0.13835781 | I33: =résultats!H680*résultats!H718/(résultats!H756*résultats!H794) -> 0.1236868 | J33: =résultats!I680*résultats!I718/(résultats!I756*résultats!I794) -> 0.089280171 | K33: =résultats!J680*résultats!J718/(résultats!J756*résultats!J794) -> 0.13037538 | ... AX33: =résultats!AW680*résultats!AW718/(résultats!AW756*résultats!AW794) -> 0.1082689
B34: taux de profit du secteur 13 | D34: =résultats!C681*résultats!C719/(résultats!C757*résultats!C795) -> 0 | E34: =résultats!D681*résultats!D719/(résultats!D757*résultats!D795) -> 0 | F34: =résultats!E681*résultats!E719/(résultats!E757*résultats!E795) -> 0.26684707 | G34: =résultats!F681*résultats!F719/(résultats!F757*résultats!F795) -> 0.25223664 | H34: =résultats!G681*résultats!G719/(résultats!G757*résultats!G795) -> 0.27715862 | I34: =résultats!H681*résultats!H719/(résultats!H757*résultats!H795) -> 0.29416068 | J34: =résultats!I681*résultats!I719/(résultats!I757*résultats!I795) -> 0.23413574 | K34: =résultats!J681*résultats!J719/(résultats!J757*résultats!J795) -> 0.24100925 | ... AX34: =résultats!AW681*résultats!AW719/(résultats!AW757*résultats!AW795) -> 0.15326636
... B41: taux de profit du secteur 20 | D41: =résultats!C688*résultats!C726/(résultats!C764*résultats!C802) -> 0 | E41: =résultats!D688*résultats!D726/(résultats!D764*résultats!D802) -> 0 | F41: =résultats!E688*résultats!E726/(résultats!E764*résultats!E802) -> -0.02847956 | G41: =résultats!F688*résultats!F726/(résultats!F764*résultats!F802) -> -0.053414286 | H41: =résultats!G688*résultats!G726/(résultats!G764*résultats!G802) -> -0.066716291 | I41: =résultats!H688*résultats!H726/(résultats!H764*résultats!H802) -> -0.069259825 | J41: =résultats!I688*résultats!I726/(résultats!I764*résultats!I802) -> -0.056551516 | K41: =résultats!J688*résultats!J726/(résultats!J764*résultats!J802) -> -0.058119802 | ... AX41: =résultats!AW688*résultats!AW726/(résultats!AW764*résultats!AW802) -> -0.039025664

Sheet Parts VE
B1: 2004 | C1: 2005 | D1: 2006 | E1: 2007 | F1: 2008 | G1: 2009 | H1: 2010 | I1: 2011 | J1: 2012 | K1: 2013 | L1: 2014 | M1: 2015 | N1: 2016 | O1: 2017 | P1: 2018 | Q1: 2019 | R1: 2020 | S1: 2021 | T1: 2022 | U1: 2023 | V1: 2024 | W1: 2025 | X1: 2026 | Y1: 2027 | Z1: 2028 | AA1: 2029 | AB1: 2030 | AC1: 2031 | AD1: 2032 | AE1: 2033 | AF1: 2034 | AG1: 2035 | AH1: 2036 | AI1: 2037 | AJ1: 2038 | AK1: 2039 | AL1: 2040 | AM1: 2041 | AN1: 2042 | AO1: 2043 | AP1: 2044 | AQ1: 2045 | AR1: 2046 | AS1: 2047 | AT1: 2048 | AU1: 2049 | AV1: 2050
A2: =résultats!B584 -> NEWAUTO_ELEC_H01_2 | B2: =résultats!C584 -> 1.149299 | C2: =résultats!D584 -> 1.1677514 | D2: =résultats!E584 -> 2.1795284 | E2: =résultats!F584 -> 3.54705 | F2: =résultats!G584 -> 5.7124314 | G2: =résultats!H584 -> 9.1534476 | H2: =résultats!I584 -> 12.615368 | ... AV2: =résultats!AW584 -> 1464.903
A3: =résultats!B585 -> NEWAUTO_2 | B3: =résultats!C585 -> 2298.598 | C3: =résultats!D585 -> 2335.5027 | D3: =résultats!E585 -> 2373 | E3: =résultats!F585 -> 2446.6776 | F3: =résultats!G585 -> 2424.2766 | G3: =résultats!H585 -> 2660.3639 | H3: =résultats!I585 -> 2598.849 | ... AV3: =résultats!AW585 -> 1464.904
A4: =résultats!B586 -> AUTO_ELEC_2 | B4: =résultats!C586 -> 2.3360541 | C4: =résultats!D586 -> 2.3735602 | D4: =résultats!E586 -> 2.4116685 | E4: =résultats!F586 -> 5.8260767 | F4: =résultats!G586 -> 11.218074 | G4: =résultats!H586 -> 19.754527 | H4: =résultats!I586 -> 31.283396 | ... AV4: =résultats!AW586 -> 18313.318
