Workbook

Sheet Feuil4
B1: TAX_0 | C1: TAX_01_0 | D1: TAX_02_0 | E1: TAX_03_0 | F1: TAX_04_0 | G1: TAX_05_0 | H1: TAX_06_0 | I1: TAX_07_0 | J1: TAX_08_0 | K1: TAX_09_0 | L1: TAX_10_0 | M1: TAX_11_0 | N1: TAX_12_0 | O1: TAX_13_0 | P1: TAX_14_0 | Q1: TAX_15_0 | R1: TAX_16_0 | S1: TAX_17_0 | T1: TAX_18_0 | U1: TAX_19_0 | V1: TAX_21_0 | W1: TAX_22_0 | X1: TAX_23_0 | Y1: TAX_24_0 | Z1: TAX_CR_19_0
A2: 2004 | B2: 198321.64 | C2: 1826.8672 | D2: 23732.807 | E2: 10811.354 | F2: 318.68468 | G2: 249.91078 | H2: 834.97324 | I2: 52.306908 | J2: 120.11216 | K2: 803.97655 | L2: 7.7491716 | M2: 11.623757 | N2: 31876.895 | O2: 21060.311 | P2: 282.13879 | Q2: 743.92047 | R2: 235.78891 | S2: 12.873246 | T2: 525.99233 | U2: 63127.657 | V2: 32.933979 | W2: 33245.165 | X2: 6431.8124 | Y2: 1975.7881 | Z2: 0
A3: 2005 | B3: 201505.76 | C3: 1856.1981 | D3: 24113.844 | E3: 10984.933 | F3: 323.80127 | G3: 253.92318 | H3: 848.379 | I3: 53.146712 | J3: 122.0406 | K3: 816.88465 | L3: 7.873587 | M3: 11.810381 | N3: 32388.689 | O3: 21398.441 | P3: 286.66862 | Q3: 755.86435 | R3: 239.57458 | S3: 13.07993 | T3: 534.4373 | U3: 64141.192 | V3: 33.462745 | W3: 33778.927 | X3: 6535.0772 | Y3: 2007.5101 | Z3: 0
A4: 2006 | B4: 204740.96 | C4: 1886 | D4: 24501 | E4: 11161.3 | F4: 329 | G4: 258 | H4: 862 | I4: 54 | J4: 124 | K4: 830 | L4: 8 | M4: 12 | N4: 32908.699 | O4: 21741.995 | P4: 291.27117 | Q4: 768 | R4: 243.42103 | S4: 13.289932 | T4: 543.01787 | U4: 65171 | V4: 33.999985 | W4: 34321.219 | X4: 6640.0087 | Y4: 2039.7396 | Z4: 0
A5: 2007 | B5: 209991.48 | C5: 1905.3784 | D5: 25023.326 | E5: 11567.724 | F5: 338.8825 | G5: 265.75246 | H5: 882.3168 | I5: 56.439168 | J5: 128.57922 | K5: 863.56227 | L5: 8.206801 | M5: 12.266661 | N5: 34428.957 | O5: 22680.404 | P5: 297.65121 | Q5: 784.87869 | R5: 250.27937 | S5: 13.746692 | T5: 570.48784 | U5: 66788.126 | V5: 33.509741 | W5: 34363.047 | X5: 6704.8705 | Y5: 2023.0879 | Z5: 0
A6: 2008 | B6: 209240.76 | C6: 1896.549 | D6: 24894.248 | E6: 11196.434 | F6: 331.8491 | G6: 260.37759 | H6: 863.61728 | I6: 57.082176 | J6: 128.94595 | K6: 856.90965 | L6: 7.5151293 | M6: 11.236936 | N6: 34437.717 | O6: 22926.553 | P6: 313.61209 | Q6: 821.52287 | R6: 250.80888 | S6: 13.822104 | T6: 578.00804 | U6: 67101.751 | V6: 30.068643 | W6: 33456.791 | X6: 6844.7814 | Y6: 1960.5571 | Z6: 0
A7: 2009 | B7: 204626.3 | C7: 1947.3629 | D7: 24730.051 | E7: 11129.926 | F7: 305.08907 | G7: 239.18113 | H7: 838.55167 | I7: 54.581015 | J7: 119.55474 | K7: 847.062 | L7: 6.0322074 | M7: 8.5210077 | N7: 33709.029 | O7: 21800.771 | P7: 312.4621 | Q7: 814.74771 | R7: 240.58612 | S7: 13.671677 | T7: 507.46659 | U7: 65807.79 | V7: 27.572189 | W7: 32730.937 | X7: 6499.3414 | Y7: 1936.0172 | Z7: 0
A8: 2010 | B8: 207310.26 | C8: 1951.0907 | D8: 25085.223 | E8: 11057.388 | F8: 308.93554 | G8: 242.73377 | H8: 844.34921 | I8: 58.083519 | J8: 127.76504 | K8: 892.9076 | L8: 6.5552107 | M8: 9.6328423 | N8: 34473.266 | O8: 22074.181 | P8: 319.45385 | Q8: 833.39603 | R8: 252.27214 | S8: 14.176641 | T8: 535.11449 | U8: 67121.995 | V8: 27.171899 | W8: 32504.314 | X8: 6639.6542 | Y8: 1930.6015 | Z8: 0
A9: 2011 | B9: 209299.36 | C9: 1932.5557 | D9: 25689.117 | E9: 11180.927 | F9: 316.98661 | G9: 248.96462 | H9: 842.9682 | I9: 60.323065 | J9: 131.71102 | K9: 916.06177 | L9: 6.6628278 | M9: 10.189248 | N9: 35058.739 | O9: 22342.25 | P9: 323.89321 | Q9: 844.07264 | R9: 255.7418 | S9: 13.960516 | T9: 571.38808 | U9: 67990.382 | V9: 25.836487 | W9: 31824.112 | X9: 6829.5699 | Y9: 1882.943 | Z9: 0
A10: 2012 | B10: 207603.31 | C10: 1935.2784 | D10: 25530.945 | E10: 10384.846 | F10: 311.92784 | G10: 244.72036 | H10: 837.21273 | I10: 60.999181 | J10: 131.36426 | K10: 899.37692 | L10: 6.3662693 | M10: 9.5946222 | N10: 34855.862 | O10: 22242.91 | P10: 325.51307 | Q10: 846.95563 | R10: 253.85742 | S10: 13.64376 | T10: 574.6161 | U10: 68506.187 | V10: 24.980025 | W10: 30852.697 | X10: 6948.9828 | Y10: 1804.4711 | Z10: 0
A11: 2013 | B11: 207229.4 | C11: 1969.8312 | D11: 25554.739 | E11: 9974.3644 | F11: 307.53944 | G11: 241.4469 | H11: 833.40556 | I11: 60.827276 | J11: 128.80102 | K11: 884.60346 | L11: 6.3358361 | M11: 9.7084025 | N11: 35011.17 | O11: 22079.734 | P11: 324.94148 | Q11: 845.9058 | R11: 255.20131 | S11: 14.042138 | T11: 575.97145 | U11: 69243.975 | V11: 25.086553 | W11: 30190.983 | X11: 6928.1032 | Y11: 1762.6834 | Z11: 0
A12: 2014 | B12: 209134.95 | C12: 2040.6589 | D12: 25862.833 | E12: 9941.7861 | F12: 306.48311 | G12: 240.81379 | H12: 837.12414 | I12: 62.771682 | J12: 131.52531 | K12: 901.38293 | L12: 6.364072 | M12: 9.7492743 | N12: 35883.383 | O12: 22005.91 | P12: 322.3745 | Q12: 839.73136 | R12: 255.81424 | S12: 14.510243 | T12: 581.1474 | U12: 70352.641 | V12: 24.938725 | W12: 29881.596 | X12: 6892.6535 | Y12: 1738.7546 | Z12: 0
A13: 2015 | B13: 212002.04 | C13: 2031.8 | D13: 26297.76 | E13: 10415.97 | F13: 303.26803 | G13: 238.39571 | H13: 840.76786 | I13: 64.551057 | J13: 135.09932 | K13: 907.42527 | L13: 6.1862031 | M13: 9.8302362 | N13: 36853.612 | O13: 22000.406 | P13: 320.64201 | Q13: 831.31365 | R13: 249.80779 | S13: 14.932055 | T13: 580.20501 | U13: 71533.502 | V13: 24.415355 | W13: 29853.086 | X13: 6763.2855 | Y13: 1725.7792 | Z13: 0
... A48: 2050 | B48: 295197.15 | C48: 2028.0217 | D48: 34402.122 | E48: 27423.6 | F48: 735.11041 | G48: 590.12363 | H48: 1649.007 | I48: 60.182294 | J48: 139.91303 | K48: 1880.3915 | L48: 6.4014144 | M48: 13.225613 | N48: 26529.842 | O48: 26170.295 | P48: 357.00295 | Q48: 912.78049 | R48: 447.31213 | S48: 36.035839 | T48: 930.14481 | U48: 146926.03 | V48: 7.6950037 | W48: 13675.934 | X48: 9363.4383 | Y48: 912.54259 | Z48: 34.343913
B49: =(B48/B18)^(1/30)-1 -> 0.0080421095 | C49: =(C48/C18)^(1/30)-1 -> 0.00023422648 | D49: =(D48/D18)^(1/30)-1 -> 0.0048957139 | E49: =(E48/E18)^(1/30)-1 -> 0.025664407 | F49: =(F48/F18)^(1/30)-1 -> 0.023337781 | G49: =(G48/G18)^(1/30)-1 -> 0.023585564 | H49: =(H48/H18)^(1/30)-1 -> 0.018861881 | I49: =(I48/I18)^(1/30)-1 -> -0.0042132468 | ... Z49: =(Z48/Z18)^(1/30)-1 -> #DIV/0!

Sheet résultats
D1: 2004 | E1: 2005 | F1: 2006 | G1: 2007 | H1: 2008 | I1: 2009 | J1: 2010 | K1: 2011 | L1: 2012 | M1: 2013 | N1: 2014 | O1: 2015 | P1: 2016 | Q1: 2017 | R1: 2018 | S1: 2019 | T1: 2020 | U1: 2021 | V1: 2022 | W1: 2023 | X1: 2024 | Y1: 2025 | Z1: 2026 | AA1: 2027 | AB1: 2028 | AC1: 2029 | AD1: 2030 | AE1: 2031 | AF1: 2032 | AG1: 2033 | AH1: 2034 | AI1: 2035 | AJ1: 2036 | AK1: 2037 | AL1: 2038 | AM1: 2039 | AN1: 2040 | AO1: 2041 | AP1: 2042 | AQ1: 2043 | AR1: 2044 | AS1: 2045 | AT1: 2046 | AU1: 2047 | AV1: 2048 | AW1: 2049 | AX1: 2050
B2: Déficit public Tend | C2: DEP_VAL_1-REC_VAL_1 | F2: 46046.848 | G2: 41515.083 | H2: 39594.513 | I2: 69718.51 | J2: 87488.349 | K2: 77038.755 | L2: 81118.732 | M2: 92939.121 | N2: 101137.91 | O2: 107539.25 | P2: 112002.03 | Q2: 106420.95 | R2: 102279.62 | S2: 108345.1 | T2: 123607.72 | U2: 139142.73 | V2: 148016.42 | W2: 160126.87 | X2: 168814.27 | Y2: 180400.69 | Z2: 194747.04 | AA2: 210868.31 | AB2: 225696.61 | AC2: 240632.17 | AD2: 254458.85 | AE2: 269491.64 | AF2: 285171.44 | AG2: 300672.08 | AH2: 317224.11 | AI2: 335142.05 | AJ2: 353508.56 | AK2: 374408.8 | AL2: 396617.8 | AM2: 419707.55 | AN2: 444154.1 | AO2: 470379.62 | AP2: 498706.87 | AQ2: 528110.03 | AR2: 558501.84 | AS2: 590076.11 | AT2: 623118.38 | AU2: 657464.49 | AV2: 693614.92 | AW2: 731588.92 | AX2: 769566.07
A3: TEND | B3: Déficit public en % PIB | C3: (DEP_VAL_1-REC_VAL_1)/(PGDP_1*GDP_1) | F3: 0.026124716 | G3: 0.02274442 | H3: 0.021522202 | I3: 0.038636076 | J3: 0.047502793 | K3: 0.041135131 | L3: 0.043197439 | M3: 0.049103405 | N3: 0.05244689 | O3: 0.054724876 | P3: 0.055834333 | Q3: 0.051298635 | R3: 0.047620238 | S3: 0.048286177 | T3: 0.053494859 | U3: 0.058288537 | V3: 0.060211743 | W3: 0.062828808 | X3: 0.064223792 | Y3: 0.066833525 | Z3: 0.070364834 | AA3: 0.074166454 | AB3: 0.07721077 | AC3: 0.080065451 | AD3: 0.08232817 | AE3: 0.084731084 | AF3: 0.087058824 | AG3: 0.089077886 | AH3: 0.091156791 | AI3: 0.09330227 | AJ3: 0.095276489 | AK3: 0.097641455 | AL3: 0.10002783 | AM3: 0.10233191 | AN3: 0.10468288 | AO3: 0.1072081 | AP3: 0.10987339 | AQ3: 0.11249255 | AR3: 0.11501937 | AS3: 0.11753069 | AT3: 0.1200381 | AU3: 0.12251456 | AV3: 0.12503402 | AW3: 0.12758576 | AX3: 0.12974965
B4: Dépenses publiques | C4: DEP_VAL_1 | E4: 912128.34 | F4: 937425.07 | G4: 961862 | H4: 986659.9 | I4: 1008523.5 | J4: 1032902.3 | K4: 1047851.8 | L4: 1070612.1 | M4: 1095908.2 | N4: 1121771.6 | O4: 1148883 | P4: 1175814.4 | Q4: 1206902.8 | R4: 1245996.2 | S4: 1296419.4 | T4: 1350708.4 | U4: 1402975.7 | V4: 1451638.6 | W4: 1509929.7 | X4: 1562894.7 | Y4: 1614378 | Z4: 1666703.6 | AA4: 1720982.7 | AB4: 1777230.8 | AC4: 1834921.4 | AD4: 1894585.3 | AE4: 1956462 | AF4: 2020712.3 | AG4: 2087899.9 | AH4: 2158999.1 | AI4: 2234346.9 | AJ4: 2314702.1 | AK4: 2400777.3 | AL4: 2490977.1 | AM4: 2585434.4 | AN4: 2683857.6 | AO4: 2787150.9 | AP4: 2895092.8 | AQ4: 3006721 | AR4: 3121990.2 | AS4: 3240852.9 | AT4: 3363392.3 | AU4: 3490293 | AV4: 3621928 | AW4: 3758278.4 | AX4: 3899770.5
B5: Cotisations sociales | C5: CL_S_20_1*L_S_20_1*PROG_L_20_1 | D5: 225891.81 | E5: 234108.95 | F5: 242473.94 | G5: 250402.08 | H5: 256846.06 | I5: 262566.58 | J5: 263167.14 | K5: 263676.15 | L5: 266631.64 | M5: 271219.5 | N5: 274530.54 | O5: 277636.51 | P5: 281316.62 | Q5: 286630.63 | R5: 294477.82 | S5: 304804.23 | T5: 315357.14 | U5: 325800.82 | V5: 336494.3 | W5: 349298.7 | X5: 361057.5 | Y5: 371493.17 | Z5: 382345.68 | AA5: 393507.52 | AB5: 404975.84 | AC5: 416650.51 | AD5: 428687.48 | AE5: 441273.82 | AF5: 454423.9 | AG5: 468306.16 | AH5: 483094.09 | AI5: 498892.45 | AJ5: 515802.52 | AK5: 533927.48 | AL5: 552830.23 | AM5: 572566.72 | AN5: 593050.89 | AO5: 614387.83 | AP5: 636528.74 | AQ5: 659213.31 | AR5: 682440.05 | AS5: 706213.51 | AT5: 730634.24 | AU5: 755794.01 | AV5: 781789.86 | AW5: 808601.89 | AX5: 836360.22
B6: Intérêts de la dette | C6: R_G_1(-1)*DEBT_G_VAL_1(-1) | E6: 41668.561 | F6: 43184.314 | G6: 43187.915 | H6: 42585.465 | I6: 43691.245 | J6: 43903.569 | K6: 45997.25 | L6: 47736.632 | M6: 49746.374 | N6: 51750.62 | O6: 54600.366 | P6: 57036.086 | Q6: 59608.47 | R6: 63917.696 | S6: 69712.845 | T6: 75012.737 | U6: 81112.827 | V6: 87706.558 | W6: 94734.86 | X6: 102253.86 | Y6: 110015.36 | Z6: 118114.17 | AA6: 126559.44 | AB6: 135469.42 | AC6: 144844.8 | AD6: 154706.49 | AE6: 165029.94 | AF6: 175911.67 | AG6: 187245.57 | AH6: 199257.16 | AI6: 211998.08 | AJ6: 225322.65 | AK6: 239682.38 | AL6: 254834.68 | AM6: 270844.39 | AN6: 287736.18 | AO6: 305568.31 | AP6: 324501.1 | AQ6: 344518.61 | AR6: 365670.45 | AS6: 387995.51 | AT6: 411526.55 | AU6: 436361.98 | AV6: 462557.85 | AW6: 490171.08 | AX6: 519229.76
B7: Facture énergétique | C7: PE_20_1*E_20_1 | D7: 5997.7128 | E7: 6215.8882 | F7: 6313.0449 | G7: 6408.2141 | H7: 6729.4513 | I7: 6554.4748 | J7: 6722.3094 | K7: 7044.4625 | L7: 7352.392 | M7: 7418.0233 | N7: 7378.7942 | O7: 7231.5171 | P7: 6831.6071 | Q7: 6866.0636 | R7: 7125.6747 | S7: 7046.934 | T7: 6890.9903 | U7: 7036.1768 | V7: 7189.8606 | W7: 7336.3779 | X7: 7446.8042 | Y7: 7522.2589 | Z7: 7589.8646 | AA7: 7659.7754 | AB7: 7730.1456 | AC7: 7801.9572 | AD7: 7873.2494 | AE7: 7942.2767 | AF7: 8011.5302 | AG7: 8074.5251 | AH7: 8143.0708 | AI7: 8206.4834 | AJ7: 8272.9158 | AK7: 8340.7582 | AL7: 8409.995 | AM7: 8479.8915 | AN7: 8551.2528 | AO7: 8625.0632 | AP7: 8699.6065 | AQ7: 8776.0369 | AR7: 8853.3439 | AS7: 8931.4201 | AT7: 9012.6121 | AU7: 9095.167 | AV7: 9181.8398 | AW7: 9264.0289 | AX7: 9346.0282
B8: Consommations intermédiaires | C8: PMAT_20_1*MAT_20_1 | D8: 79234.609 | E8: 82116.881 | F8: 84010.915 | G8: 86823.459 | H8: 87308.063 | I8: 81976.69 | J8: 85097.05 | K8: 86655.463 | L8: 86623.655 | M8: 87570.65 | N8: 89540.406 | O8: 92873.071 | P8: 94878.687 | Q8: 99511.806 | R8: 103270.42 | S8: 108144.72 | T8: 111864.5 | U8: 115659.22 | V8: 119505.11 | W8: 123828.11 | X8: 128117.41 | Y8: 132149.39 | Z8: 136112.48 | AA8: 140161.46 | AB8: 144340.62 | AC8: 148639.92 | AD8: 153085.93 | AE8: 157629.17 | AF8: 162375.38 | AG8: 167332.19 | AH8: 172539.58 | AI8: 178063.66 | AJ8: 183907.28 | AK8: 190122.88 | AL8: 196667.26 | AM8: 203529.43 | AN8: 210686.97 | AO8: 218143.41 | AP8: 225911.21 | AQ8: 233937 | AR8: 242204.91 | AS8: 250699.34 | AT8: 259435.99 | AU8: 268429.47 | AV8: 277708.56 | AW8: 287278.94 | AX8: 297181.5
B9: Taxe à la production | C9: PIY_20_1*IY_20_1 | D9: 7105.6417 | E9: 7364.1196 | F9: 7461.7212 | G9: 7630.9433 | H9: 7780.8693 | I9: 7889.7548 | J9: 7984.8462 | K9: 8073.1776 | L9: 8165.7128 | M9: 8284.1869 | N9: 8396.2133 | O9: 8558.7543 | P9: 8722.3275 | Q9: 8949.8236 | R9: 9200.5088 | S9: 9520.9596 | T9: 9847.0824 | U9: 10181.936 | V9: 10520.846 | W9: 10900.939 | X9: 11277.729 | Y9: 11632.571 | Z9: 11981.497 | AA9: 12338.106 | AB9: 12705.916 | AC9: 13083.907 | AD9: 13474.151 | AE9: 13876.57 | AF9: 14295.903 | AG9: 14733.023 | AH9: 15191.22 | AI9: 15676.152 | AJ9: 16188.91 | AK9: 16734.184 | AL9: 17308.494 | AM9: 17910.952 | AN9: 18539.625 | AO9: 19195.57 | AP9: 19879.596 | AQ9: 20586.832 | AR9: 21315.739 | AS9: 22064.798 | AT9: 22835.249 | AU9: 23628.229 | AV9: 24446.08 | AW9: 25289.462 | AX9: 26160.313
B10: Investissements | C10: PIA_20_1*IA_20_1 | D10: 56421.514 | E10: 58473.927 | F10: 60071.544 | G10: 61013.011 | H10: 60073.363 | I10: 62700.448 | J10: 63450.005 | K10: 60935.431 | L10: 63272.986 | M10: 62819.218 | N10: 61054.072 | O10: 60796.705 | P10: 62812.171 | Q10: 62624.632 | R10: 65020.912 | S10: 71426.599 | T10: 73890.333 | U10: 76328.741 | V10: 78845.266 | W10: 81858.997 | X10: 84617.555 | Y10: 87074.422 | Z10: 89603.334 | AA10: 92225.244 | AB10: 94957.072 | AC10: 97759.157 | AD10: 100661.3 | AE10: 103706.65 | AF10: 106891.85 | AG10: 110226.9 | AH10: 113746.5 | AI10: 117503.55 | AJ10: 121482.67 | AK10: 125733.94 | AL10: 130174.36 | AM10: 134814.48 | AN10: 139636.21 | AO10: 144656.39 | AP10: 149879.63 | AQ10: 155246.28 | AR10: 160754.08 | AS10: 166399.79 | AT10: 172204.94 | AU10: 178189.24 | AV10: 184372.63 | AW10: 190750.39 | AX10: 197376.14
B11: Consommation finale | C11: PG_1*G_1-PG_20_1*G_20_1 | D11: 107619 | E11: 111533.8 | F11: 113942.67 | G11: 117442.67 | H11: 123159.05 | I11: 127288.16 | J11: 132353 | K11: 134411.74 | L11: 138386.77 | M11: 143777.02 | N11: 148459.89 | O11: 153311.54 | P11: 158002.3 | Q11: 162015.26 | R11: 164253.74 | S11: 169990.65 | T11: 175872.75 | U11: 181812.26 | V11: 187877.36 | W11: 194596.61 | X11: 201343.37 | Y11: 207721.1 | Z11: 214027.09 | AA11: 220408.29 | AB11: 226947.75 | AC11: 233645.1 | AD11: 240538.92 | AE11: 247695.01 | AF11: 255140.26 | AG11: 262913.14 | AH11: 271084.11 | AI11: 279726.78 | AJ11: 288892.31 | AK11: 298654.92 | AL11: 308942.59 | AM11: 319733.36 | AN11: 330995.35 | AO11: 342738.18 | AP11: 354964.91 | AQ11: 367608.05 | AR11: 380632.29 | AS11: 394016.81 | AT11: 407774.1 | AU11: 421934.41 | AV11: 436539.05 | AW11: 451599.39 | AX11: 467162.18
B12: Subventions | C12: 0-(PSUB_1*SUB_1-PSUB_01_1*SUB_01_1) | D12: 8435.1565 | E12: 8741.9973 | F12: 9052.0676 | G12: 9514.5739 | H12: 9579.7848 | I12: 9185.7675 | J12: 9668.5068 | K12: 9958.4654 | L12: 10138.964 | M12: 10380.176 | N12: 10657.159 | O12: 10910.06 | P12: 11189.514 | Q12: 11835.116 | R12: 12147.105 | S12: 12663.046 | T12: 12921.232 | U12: 13199.942 | V12: 13543.215 | W12: 13963.058 | X12: 14418.093 | Y12: 14859.872 | Z12: 15285.356 | AA12: 15712.974 | AB12: 16159 | AC12: 16613.691 | AD12: 17083.717 | AE12: 17529.075 | AF12: 17968.217 | AG12: 18436.308 | AH12: 18926.688 | AI12: 19417.465 | AJ12: 19972.814 | AK12: 20543.634 | AL12: 21133.195 | AM12: 21743.865 | AN12: 22372.435 | AO12: 23015.883 | AP12: 23685.677 | AQ12: 24374.318 | AR12: 25083.314 | AS12: 25809.649 | AT12: 26565.526 | AU12: 27343.676 | AV12: 28145.897 | AW12: 28970.224 | AX12: 29826.427
B13: Subventions à la production | C13: 0-(PSY_1*SY_1-PSY_01_1*SY_01_1) | D13: 14588.352 | E13: 15119.024 | F13: 15344.916 | G13: 15983.264 | H13: 16301.289 | I13: 15772.841 | J13: 16234.242 | K13: 16522.807 | L13: 16716.689 | M13: 16911.088 | N13: 17281.824 | O13: 17695.966 | P13: 18040.865 | Q13: 18786.288 | R13: 19467.161 | S13: 20347.074 | T13: 20953.956 | U13: 21678.036 | V13: 22367.955 | W13: 23211.139 | X13: 23986.274 | Y13: 24694.152 | Z13: 25348.433 | AA13: 26064.881 | AB13: 26824.271 | AC13: 27614.382 | AD13: 28442.663 | AE13: 29254.24 | AF13: 30113.901 | AG13: 31016.293 | AH13: 31962.766 | AI13: 32973.91 | AJ13: 34043.808 | AK13: 35169.082 | AL13: 36349.705 | AM13: 37583.41 | AN13: 38864.022 | AO13: 40182.702 | AP13: 41562.588 | AQ13: 42981.666 | AR13: 44445.954 | AS13: 45946.449 | AT13: 47496.024 | AU13: 49089.058 | AV13: 50733.476 | AW13: 52430.076 | AX13: 54203.878
B14: Prestations sociales | C14: PRESOC_VAL_1 | D14: 334613.16 | E14: 346785.19 | F14: 355569.94 | G14: 362474.15 | H14: 375166.89 | I14: 389779.76 | J14: 402784.48 | K14: 413040.95 | L14: 424174.08 | M14: 435846.94 | N14: 448624.69 | O14: 460339.77 | P14: 470567.91 | Q14: 482243.94 | R14: 497227.39 | S14: 511861.13 | T14: 538863.16 | U14: 556795.2 | V14: 575163.65 | W14: 596984.81 | X14: 617015.79 | Y14: 634827.7 | Z14: 653737.58 | AA14: 673445 | AB14: 693811.23 | AC14: 714508.93 | AD14: 735794.43 | AE14: 757932.65 | AF14: 780689.81 | AG14: 804428.23 | AH14: 829568.36 | AI14: 856185.29 | AJ14: 884744.01 | AK14: 915443.48 | AL14: 947558.99 | AM14: 981117.9 | AN14: 1015976 | AO14: 1052363.7 | AP14: 1090311.4 | AQ14: 1129341.4 | AR14: 1169398.3 | AS14: 1210442.2 | AT14: 1252620.9 | AU14: 1296081 | AV14: 1340968.7 | AW14: 1387225.8 | AX14: 1434916.2
B15: Subventions à la rénovation énergétique | C15: SUB_RENOV_VAL_1 | D15: 0 | E15: 0 | F15: 0 | G15: 981.71741 | H15: 1275.7646 | I15: 1256.1846 | J15: 962.83367 | K15: 907.83579 | L15: 730.04444 | M15: 1046.0339 | N15: 1478.0556 | O15: 2067.9391 | P15: 1560.2962 | Q15: 1611.5249 | R15: 1227.2902 | S15: 1845.6156 | T15: 1829.233 | U15: 3502.7992 | V15: 2632.5168 | W15: 2779.9116 | X15: 0 | Y15: 0 | Z15: 0 | AA15: 0 | AB15: 0 | AC15: 0 | AD15: 0 | AE15: 0 | AF15: 0 | AG15: 0 | AH15: 0 | AI15: 0 | AJ15: 0 | AK15: 0 | AL15: 0 | AM15: 0 | AN15: 0 | AO15: 0 | AP15: 0 | AQ15: 0 | AR15: 0 | AS15: 0 | AT15: 0 | AU15: 0 | AV15: 0 | AW15: 0 | AX15: 0
B16: Subventions aux automobiles | C16: SUB_AUTO_VAL_1 | D16: 0 | E16: 0 | F16: 0 | G16: 0 | H16: -146.15689 | I16: -138.40401 | J16: -122.17213 | K16: -60.537774 | L16: 30.851943 | M16: 248.66455 | N16: 291.27213 | O16: -1159.0664 | P16: -1100.1117 | Q16: -1744.0667 | R16: -2367.1233 | S16: -1949.7674 | T16: -3557.2983 | U16: -1245.6668 | V16: -1567.8608 | W16: -1318.5097 | X16: -1088.306 | Y16: -832.82382 | Z16: -651.75153 | AA16: -384.02915 | AB16: -86.374331 | AC16: 220.77697 | AD16: 523.75277 | AE16: 816.18698 | AF16: 1044.671 | AG16: 1266.8012 | AH16: 1479.0389 | AI16: 1600.2116 | AJ16: 1826.6695 | AK16: 2022.7327 | AL16: 2195.0392 | AM16: 2351.0038 | AN16: 2491.7308 | AO16: 2609.1341 | AP16: 2728.5225 | AQ16: 2846.2287 | AR16: 2959.1383 | AS16: 3066.5467 | AT16: 3154.3593 | AU16: 3244.5288 | AV16: 3332.8367 | AW16: 3416.9084 | AX16: 3500.0569
B17: Redistribution des recettes de taxe carbone aux ménages | C17: REDIS_VAL_TCO_H_1 | D17: 0 | E17: 0 | F17: 0 | G17: 0 | H17: 0 | I17: 0 | J17: 0 | K17: 0 | L17: 0 | M17: 0 | N17: 882.28486 | O17: 1736.9373 | P17: 2713.0584 | Q17: 3719.5187 | R17: 5332.1552 | S17: 5271.6672 | T17: 5175.6218 | U17: 5019.5414 | V17: 4854.2733 | W17: 4679.7854 | X17: 4603.5513 | Y17: 4523.5657 | Z17: 4426.1807 | AA17: 4336.4638 | AB17: 4250.8516 | AC17: 4167.1391 | AD17: 4084.0852 | AE17: 4002.8592 | AF17: 3918.1668 | AG17: 3832.3533 | AH17: 3745.957 | AI17: 3657.2084 | AJ17: 3575.9356 | AK17: 3497.2599 | AL17: 3420.5984 | AM17: 3345.7049 | AN17: 3272.7044 | AO17: 3195.9268 | AP17: 3119.8798 | AQ17: 3044.4722 | AR17: 2969.7843 | AS17: 2895.8531 | AT17: 2821.7121 | AU17: 2748.4372 | AV17: 2675.3321 | AW17: 2603.4753 | AX17: 2533.0899
B18: Redistribution des recettes de l'ETS aux secteurs | C18: REDIS_VAL_SEC_TCO_1 | D18: 0 | E18: 0 | F18: 0 | G18: 0 | H18: 0 | I18: 0 | J18: 0 | K18: 0 | L18: 0 | M18: 0 | N18: 804.87323 | O18: 1636.4205 | P18: 2517.5888 | Q18: 3417.9982 | R18: 4753.4041 | S18: 4618.4269 | T18: 4516.8533 | U18: 4481.9143 | V18: 4453.284 | W18: 4449.0536 | X18: 4524.5909 | Y18: 4574.287 | Z18: 4565.3748 | AA18: 4566.5347 | AB18: 4571.7816 | AC18: 4578.5093 | AD18: 4588.2624 | AE18: 4579.8662 | AF18: 4574.083 | AG18: 4570.3513 | AH18: 4566.7284 | AI18: 4566.477 | AJ18: 4582.2889 | AK18: 4600.5013 | AL18: 4620.2469 | AM18: 4641.3396 | AN18: 4663.0128 | AO18: 4695.203 | AP18: 4730.587 | AQ18: 4765.6237 | AR18: 4801.0399 | AS18: 4835.9385 | AT18: 4880.9187 | AU18: 4926.0795 | AV18: 4971.1071 | AW18: 5017.2263 | AX18: 5065.3508
... B21: Redistribution des recettes de l'ETS aux secteurs | C21: REDIS_VAL_SEC_ETS2_1 | D21: 0 | E21: 0 | F21: 0 | G21: 0 | H21: 0 | I21: 0 | J21: 0 | K21: 0 | L21: 0 | M21: 0 | N21: 0 | O21: 0 | P21: 0 | Q21: 0 | R21: 0 | S21: 0 | T21: 0 | U21: 0 | V21: 0 | W21: 0 | X21: 0 | Y21: 0 | Z21: 0 | AA21: 0 | AB21: 0 | AC21: 0 | AD21: 0 | AE21: 0 | AF21: 0 | AG21: 0 | AH21: 0 | AI21: 0 | AJ21: 0 | AK21: 0 | AL21: 0 | AM21: 0 | AN21: 0 | AO21: 0 | AP21: 0 | AQ21: 0 | AR21: 0 | AS21: 0 | AT21: 0 | AU21: 0 | AV21: 0 | AW21: 0 | AX21: 0
B22: Recettes publiques | C22: REC_VAL_1 | F22: 891378.22 | G22: 920346.92 | H22: 947065.38 | I22: 938804.99 | J22: 945413.99 | K22: 970813.09 | L22: 989493.32 | M22: 1002969.1 | N22: 1020633.7 | O22: 1041343.8 | P22: 1063812.4 | Q22: 1100481.8 | R22: 1143716.6 | S22: 1188074.3 | T22: 1227100.7 | U22: 1263833 | V22: 1303622.2 | W22: 1349802.8 | X22: 1394080.5 | Y22: 1433977.3 | Z22: 1471956.5 | AA22: 1510114.4 | AB22: 1551534.1 | AC22: 1594289.2 | AD22: 1640126.4 | AE22: 1686970.3 | AF22: 1735540.8 | AG22: 1787227.8 | AH22: 1841775 | AI22: 1899204.8 | AJ22: 1961193.5 | AK22: 2026368.5 | AL22: 2094359.3 | AM22: 2165726.9 | AN22: 2239703.5 | AO22: 2316771.3 | AP22: 2396386 | AQ22: 2478610.9 | AR22: 2563488.4 | AS22: 2650776.8 | AT22: 2740273.9 | AU22: 2832828.5 | AV22: 2928313.1 | AW22: 3026689.5 | AX22: 3130204.5
B23: Dividendes | C23: DIV_GOV_VAL_1 | D23: 6736.0217 | E23: 6981.0542 | F23: 7184.2108 | G23: 6897.7147 | H23: 6995.8402 | I23: 6577.538 | J23: 6110.018 | K23: 6724.3593 | L23: 7115.3042 | M23: 7000.438 | N23: 6942.4202 | O23: 7144.7234 | P23: 7346.8706 | Q23: 7554.5856 | R23: 7841.8697 | S23: 8018.0041 | T23: 8358.3008 | U23: 8434.0763 | V23: 8682.2554 | W23: 8877.5713 | X23: 9099.16 | Y23: 9277.953 | Z23: 9377.266 | AA23: 9415.522 | AB23: 9589.7261 | AC23: 9837.5845 | AD23: 10083.097 | AE23: 10344.902 | AF23: 10646.632 | AG23: 10995.089 | AH23: 11350.762 | AI23: 11714.508 | AJ23: 12117.548 | AK23: 12529.16 | AL23: 12936.479 | AM23: 13376.175 | AN23: 13834.35 | AO23: 14306.499 | AP23: 14760.816 | AQ23: 15248.234 | AR23: 15757.142 | AS23: 16292.795 | AT23: 16839.839 | AU23: 17412.563 | AV23: 17999.446 | AW23: 18602.692 | AX23: 19220.508
B24: Impôts sur les revenus et le patrimoine | C24: IR_VAL_1 | D24: 130354.82 | E24: 135096.67 | F24: 138640.55 | G24: 147517.58 | H24: 157566.63 | I24: 161161.36 | J24: 165854.42 | K24: 175705.73 | L24: 185407.9 | M24: 192921.2 | N24: 195697.58 | O24: 199466.42 | P24: 203516.6 | Q24: 209936.36 | R24: 218159.57 | S24: 226261.65 | T24: 235671.71 | U24: 242524.46 | V24: 250415.56 | W24: 259367.27 | X24: 267742.4 | Y24: 275093.45 | Z24: 282301.99 | AA24: 289415.28 | AB24: 297377.86 | AC24: 305840.31 | AD24: 314549.97 | AE24: 323724.82 | AF24: 333418.18 | AG24: 343829.33 | AH24: 354819.97 | AI24: 366425.28 | AJ24: 378974.5 | AK24: 392235.73 | AL24: 405973.11 | AM24: 420388.96 | AN24: 435376.92 | AO24: 450956.27 | AP24: 466947.53 | AQ24: 483452.09 | AR24: 500424.44 | AS24: 517887.79 | AT24: 535838.68 | AU24: 554394.3 | AV24: 573555.55 | AW24: 593313.15 | AX24: 613882.41
B25: Taxes sur les revenus financiers | C25: AIC_VAL_1 | D25: 16317.279 | E25: 16910.844 | F25: 17354.453 | G25: 17686.606 | H25: 18234.342 | I25: 18023.439 | J25: 17945.089 | K25: 18412.209 | L25: 18835.65 | M25: 19018.22 | N25: 19291.916 | O25: 19663.45 | P25: 20062.718 | Q25: 20695.579 | R25: 21506.225 | S25: 22304.93 | T25: 23232.577 | U25: 23908.122 | V25: 24686.029 | W25: 25568.491 | X25: 26394.112 | Y25: 27118.781 | Z25: 27829.401 | AA25: 28530.63 | AB25: 29315.584 | AC25: 30149.814 | AD25: 31008.415 | AE25: 31912.874 | AF25: 32868.447 | AG25: 33894.781 | AH25: 34978.242 | AI25: 36122.295 | AJ25: 37359.401 | AK25: 38666.697 | AL25: 40020.931 | AM25: 41442.049 | AN25: 42919.565 | AO25: 44455.381 | AP25: 46031.805 | AQ25: 47658.828 | AR25: 49331.966 | AS25: 51053.508 | AT25: 52823.111 | AU25: 54652.329 | AV25: 56541.25 | AW25: 58488.959 | AX25: 60516.682
B26: Versement européens | C26: INC_GOV_OTH_NET | D26: 13404.851 | E26: 13892.471 | F26: 14397.83 | G26: 14944.719 | H26: 15512.381 | I26: 16101.606 | J26: 16713.211 | K26: 17348.048 | L26: 18006.999 | M26: 18690.979 | N26: 19400.94 | O26: 20137.868 | P26: 20846.405 | Q26: 21579.871 | R26: 22339.144 | S26: 23111.678 | T26: 23907.252 | U26: 24697.605 | V26: 25509.093 | W26: 26478.863 | X26: 27368.02 | Y26: 28157.266 | Z26: 28980.126 | AA26: 29835.301 | AB26: 30727.385 | AC26: 31643.97 | AD26: 32594.03 | AE26: 33587.271 | AF26: 34619.5 | AG26: 35699.35 | AH26: 36837.936 | AI26: 38045.151 | AJ26: 39329.348 | AK26: 40701.058 | AL26: 42133.61 | AM26: 43631.043 | AN26: 45187.199 | AO26: 46813.04 | AP26: 48507.035 | AQ26: 50249.529 | AR26: 52040.109 | AS26: 53877.777 | AT26: 55768.666 | AU26: 57719.138 | AV26: 59735.578 | AW26: 61816.323 | AX26: 63964.189
B27: Taxes à la consommation | C27: PTAX_1*TAX_1 | D27: 190620.57 | E27: 197554.67 | F27: 201147.45 | G27: 206937.78 | H27: 209327.17 | I27: 205566.88 | J27: 210304.23 | K27: 214070.8 | L27: 214158.71 | M27: 215210.81 | N27: 221745.64 | O27: 225341.83 | P27: 228654.9 | Q27: 236281.66 | R27: 243367.73 | S27: 251221.58 | T27: 256087.16 | U27: 262341.11 | V27: 269169.91 | W27: 278849.91 | X27: 286714.01 | Y27: 293569.3 | Z27: 300400.64 | AA27: 307295.61 | AB27: 314686.83 | AC27: 322299.68 | AD27: 330207.75 | AE27: 338463.05 | AF27: 346663.58 | AG27: 355563.6 | AH27: 364970.75 | AI27: 374655.37 | AJ27: 385637.78 | AK27: 396940.88 | AL27: 408791.54 | AM27: 421112.69 | AN27: 433823.27 | AO27: 446797.1 | AP27: 460299.8 | AQ27: 474185.32 | AR27: 488647.39 | AS27: 503408.9 | AT27: 518614.92 | AU27: 534392.16 | AV27: 550649.67 | AW27: 567404.96 | AX27: 585574.01
B28: Taxes à la production | C28: PIY_1*IY_1 | D28: 70157.971 | E28: 72710.067 | F28: 73838.983 | G28: 76385.248 | H28: 77177.742 | I28: 73793.167 | J28: 76150.993 | K28: 77725.644 | L28: 78078.96 | M28: 78660.372 | N28: 80171.835 | O28: 82000.075 | P28: 83462.603 | Q28: 87053.346 | R28: 90348.384 | S28: 94366.063 | T28: 97076.558 | U28: 100479.77 | V28: 103649.76 | W28: 107579.43 | X28: 111271.61 | Y28: 114639.81 | Z28: 117668.47 | AA28: 121063 | AB28: 124700.71 | AC28: 128510.98 | AD28: 132539.43 | AE28: 136297.45 | AF28: 140310.18 | AG28: 144509.55 | AH28: 148910.79 | AI28: 153641.1 | AJ28: 158606.57 | AK28: 163826.06 | AL28: 169305.97 | AM28: 175029.8 | AN28: 180966.35 | AO28: 187059.96 | AP28: 193437.87 | AQ28: 199989.16 | AR28: 206755.11 | AS28: 213684.59 | AT28: 220861.8 | AU28: 228239.84 | AV28: 235855.63 | AW28: 243709.41 | AX28: 251945
B29: Impôts sur les bénéfices | C29: PIS_1*IS_1 | F29: 41720 | G29: 39457.604 | H29: 40747.154 | I29: 37985.352 | J29: 35239.253 | K29: 39462.881 | L29: 41536.949 | M29: 40347.046 | N29: 40273.369 | O29: 41738.573 | P29: 42656.482 | Q29: 43783.153 | R29: 45752.284 | S29: 46287.534 | T29: 48729.568 | U29: 49719.348 | V29: 51548.731 | W29: 51967.247 | X29: 53691.619 | Y29: 55095.203 | Z29: 56197.89 | AA29: 56866.112 | AB29: 58321.593 | AC29: 59445.246 | AD29: 62057.103 | AE29: 64165.635 | AF29: 66016.768 | AG29: 68051.159 | AH29: 70321.819 | AI29: 72540.278 | AJ29: 75096.344 | AK29: 77685.893 | AL29: 80271.597 | AM29: 83194.414 | AN29: 86033.258 | AO29: 89059.829 | AP29: 91929.397 | AQ29: 95062.383 | AR29: 98299.989 | AS29: 101731.56 | AT29: 105123.35 | AU29: 108721.56 | AV29: 112353.96 | AW29: 115945.19 | AX29: 119794.69
B30: Cotisations sociales | C30: PCSE_TOT_1*CSE_TOT_1+PCSS_TOT_1*CSS_TOT_1 | D30: 344617.11 | E30: 357153.05 | F30: 369017.92 | G30: 385094.53 | H30: 396077.86 | I30: 389117.47 | J30: 385211.89 | K30: 387603.98 | L30: 391386.7 | M30: 396035.84 | N30: 400161.67 | O30: 405640.99 | P30: 412494.56 | Q30: 425797.97 | R30: 443279.15 | S30: 465026.74 | T30: 480948.52 | U30: 496677.55 | V30: 512965.64 | W30: 532615.3 | X30: 550542.5 | Y30: 566378.02 | Z30: 582572.16 | AA30: 599024.02 | AB30: 615963 | AC30: 633332.61 | AD30: 651363.4 | AE30: 670424.17 | AF30: 690563.72 | AG30: 711936.96 | AH30: 734654.86 | AI30: 758967.49 | AJ30: 784857.36 | AK30: 812449.14 | AL30: 841162.16 | AM30: 871132.98 | AN30: 902254.23 | AO30: 934450.46 | AP30: 967725.19 | AQ30: 1001749.9 | AR30: 1036594.8 | AS30: 1072287.1 | AT30: 1108962.8 | AU30: 1146769.9 | AV30: 1185853.8 | AW30: 1226187.3 | AX30: 1268483.4
B31: Revenus des services publics | C31: PY_20_1*Y_20_1-(PE_20_1*E_20_1+PMAT_20_1*MAT_20_1+PIY_20_1*IY_20_1) | D31: 258421.17 | E31: 267821.61 | F31: 270550.76 | G31: 275827.22 | H31: 282272.32 | I31: 293044.75 | J31: 294355.51 | K31: 296746.96 | L31: 300946.15 | M31: 305663.35 | N31: 309150.81 | O31: 313826.46 | P31: 320131.73 | Q31: 326466.65 | R31: 334572.43 | S31: 345274.99 | T31: 357483.58 | U31: 369738.33 | V31: 382129.66 | W31: 396042.74 | X31: 409865.87 | Y31: 422919.86 | Z31: 435764.44 | AA31: 448892.4 | AB31: 462431.44 | AC31: 476341.27 | AD31: 490697.51 | AE31: 505547.61 | AF31: 521012.55 | AG31: 537133.39 | AH31: 554017.44 | AI31: 571882.97 | AJ31: 590771.68 | AK31: 610859.54 | AL31: 632021.58 | AM31: 654226.46 | AN31: 677402.36 | AO31: 701595.89 | AP31: 726835.43 | AQ31: 752937.57 | AR31: 779844.85 | AS31: 807499.43 | AT31: 835943.26 | AU31: 865218.47 | AV31: 895406.85 | AW31: 926543.16 | AX31: 958675.95
B32: moins les cotisations salariales des salariés du public | C32: (-1)*CL_S_20_1*L_S_20_1*PROG_L_20_1 | D32: -225891.81 | E32: -234108.95 | F32: -242473.94 | G32: -250402.08 | H32: -256846.06 | I32: -262566.58 | J32: -263167.14 | K32: -263676.15 | L32: -266631.64 | M32: -271219.5 | N32: -274530.54 | O32: -277636.51 | P32: -281316.62 | Q32: -286630.63 | R32: -294477.82 | S32: -304804.23 | T32: -315357.14 | U32: -325800.82 | V32: -336494.3 | W32: -349298.7 | X32: -361057.5 | Y32: -371493.17 | Z32: -382345.68 | AA32: -393507.52 | AB32: -404975.84 | AC32: -416650.51 | AD32: -428687.48 | AE32: -441273.82 | AF32: -454423.9 | AG32: -468306.16 | AH32: -483094.09 | AI32: -498892.45 | AJ32: -515802.52 | AK32: -533927.48 | AL32: -552830.23 | AM32: -572566.72 | AN32: -593050.89 | AO32: -614387.83 | AP32: -636528.74 | AQ32: -659213.31 | AR32: -682440.05 | AS32: -706213.51 | AT32: -730634.24 | AU32: -755794.01 | AV32: -781789.86 | AW32: -808601.89 | AX32: -836360.22
B33: recettes de l'ETS aux secteurs | C33: REC_VAL_SEC_ETS_1 | D33: 0 | E33: 0 | F33: 0 | G33: 0 | H33: 0 | I33: 0 | J33: 696.51547 | K33: 688.64066 | L33: 651.64154 | M33: 640.32182 | N33: 640.94018 | O33: 646.54145 | P33: 725.47396 | Q33: 825.77768 | R33: 942.08791 | S33: 1115.2353 | T33: 1270.1604 | U33: 1611.9912 | V33: 2052.2536 | W33: 2625.8302 | X33: 3320.5108 | Y33: 4122.9858 | Z33: 4218.283 | AA33: 4381.0472 | AB33: 4573.2224 | AC33: 4792.5871 | AD33: 5040.8345 | AE33: 5193.6462 | AF33: 5352.9102 | AG33: 5518.0531 | AH33: 5693.791 | AI33: 5879.1492 | AJ33: 6087.3201 | AK33: 6304.056 | AL33: 6531.6808 | AM33: 6771.9781 | AN33: 7021.1339 | AO33: 7773.5589 | AP33: 8589.3526 | AQ33: 9481.12 | AR33: 10461.881 | AS33: 11535.065 | AT33: 12429.099 | AU33: 13427.672 | AV33: 14504.834 | AW33: 15659.5 | AX33: 16909.441
B34: recettes de l'ETS aux secteurs | C34: REC_VAL_SEC_ETS2_1 | D34: 0 | E34: 0 | F34: 0 | G34: 0 | H34: 0 | I34: 0 | J34: 0 | K34: 0 | L34: 0 | M34: 0 | N34: 0 | O34: 0 | P34: 0 | Q34: 0 | R34: 0 | S34: 0 | T34: 0 | U34: 0 | V34: 0 | W34: 0 | X34: 0 | Y34: 0 | Z34: 0 | AA34: 0 | AB34: 0 | AC34: 0 | AD34: 0 | AE34: 0 | AF34: 0 | AG34: 0 | AH34: 0 | AI34: 0 | AJ34: 0 | AK34: 0 | AL34: 0 | AM34: 0 | AN34: 0 | AO34: 0 | AP34: 0 | AQ34: 0 | AR34: 0 | AS34: 0 | AT34: 0 | AU34: 0 | AV34: 0 | AW34: 0 | AX34: 0
B35: recettes de l'ETS aux ménages | C35: REC_VAL_ETS2_HH_1 | D35: 0 | E35: 0 | F35: 0 | G35: 0 | H35: 0 | I35: 0 | J35: 0 | K35: 0 | L35: 0 | M35: 0 | N35: 0 | O35: 0 | P35: 0 | Q35: 0 | R35: 0 | S35: 0 | T35: 0 | U35: 0 | V35: 0 | W35: 0 | X35: 0 | Y35: 0 | Z35: 0 | AA35: 0 | AB35: 0 | AC35: 0 | AD35: 0 | AE35: 0 | AF35: 0 | AG35: 0 | AH35: 0 | AI35: 0 | AJ35: 0 | AK35: 0 | AL35: 0 | AM35: 0 | AN35: 0 | AO35: 0 | AP35: 0 | AQ35: 0 | AR35: 0 | AS35: 0 | AT35: 0 | AU35: 0 | AV35: 0 | AW35: 0 | AX35: 0
B36: recettes de taxe carbone aux ménages | C36: REC_VAL_TCO_HH_1 | D36: 0 | E36: 0 | F36: 0 | G36: 0 | H36: 0 | I36: 0 | J36: 0 | K36: 0 | L36: 0 | M36: 0 | N36: 882.28486 | O36: 1736.9373 | P36: 2713.0584 | Q36: 3719.5187 | R36: 5332.1552 | S36: 5271.6672 | T36: 5175.6218 | U36: 5019.5414 | V36: 4854.2733 | W36: 4679.7854 | X36: 4603.5513 | Y36: 4523.5657 | Z36: 4426.1807 | AA36: 4336.4638 | AB36: 4250.8516 | AC36: 4167.1391 | AD36: 4084.0852 | AE36: 4002.8592 | AF36: 3918.1668 | AG36: 3832.3533 | AH36: 3745.957 | AI36: 3657.2084 | AJ36: 3575.9356 | AK36: 3497.2599 | AL36: 3420.5984 | AM36: 3345.7049 | AN36: 3272.7044 | AO36: 3195.9268 | AP36: 3119.8798 | AQ36: 3044.4722 | AR36: 2969.7843 | AS36: 2895.8531 | AT36: 2821.7121 | AU36: 2748.4372 | AV36: 2675.3321 | AW36: 2603.4753 | AX36: 2533.0899
B37: recettes de taxe carbone aux secteurs | C37: REC_VAL_SEC_TCO_1 | D37: 0 | E37: 0 | F37: 0 | G37: 0 | H37: 0 | I37: 0 | J37: 0 | K37: 0 | L37: 0 | M37: 0 | N37: 804.87323 | O37: 1636.4205 | P37: 2517.5888 | Q37: 3417.9982 | R37: 4753.4041 | S37: 4618.4269 | T37: 4516.8533 | U37: 4481.9143 | V37: 4453.284 | W37: 4449.0536 | X37: 4524.5909 | Y37: 4574.287 | Z37: 4565.3748 | AA37: 4566.5347 | AB37: 4571.7816 | AC37: 4578.5093 | AD37: 4588.2624 | AE37: 4579.8662 | AF37: 4574.083 | AG37: 4570.3513 | AH37: 4566.7284 | AI37: 4566.477 | AJ37: 4582.2889 | AK37: 4600.5013 | AL37: 4620.2469 | AM37: 4641.3396 | AN37: 4663.0128 | AO37: 4695.203 | AP37: 4730.587 | AQ37: 4765.6237 | AR37: 4801.0399 | AS37: 4835.9385 | AT37: 4880.9187 | AU37: 4926.0795 | AV37: 4971.1071 | AW37: 5017.2263 | AX37: 5065.3508
B38: Déficit public choc | C38: DEP_VAL_2-REC_VAL_2 | F38: 46046.848 | G38: 41515.083 | H38: 39594.513 | I38: 69718.51 | J38: 87488.349 | K38: 77038.755 | L38: 81118.732 | M38: 92939.121 | N38: 101137.91 | O38: 107539.25 | P38: 112002.03 | Q38: 106420.95 | R38: 102279.62 | S38: 108345.1 | T38: 123607.72 | U38: 139142.73 | V38: 148016.42 | W38: 160126.87 | X38: 169040.22 | Y38: 180349.64 | Z38: 194109.44 | AA38: 209638.35 | AB38: 224034.74 | AC38: 238668.32 | AD38: 252209.17 | AE38: 266381.91 | AF38: 282234.76 | AG38: 298025 | AH38: 314918.26 | AI38: 333068.07 | AJ38: 351738.04 | AK38: 372926.84 | AL38: 395367.14 | AM38: 418698.03 | AN38: 443370.68 | AO38: 469817.95 | AP38: 498305.43 | AQ38: 527843.59 | AR38: 558361.53 | AS38: 590045.18 | AT38: 623173.87 | AU38: 657605.48 | AV38: 693820.2 | AW38: 731741.26 | AX38: 769923.52
B39: Déficit public en % PIB | C39: (DEP_VAL_2-REC_VAL_2)/(PGDP_2*GDP_2) | F39: 0.026124716 | G39: 0.02274442 | H39: 0.021522202 | I39: 0.038636076 | J39: 0.047502793 | K39: 0.041135131 | L39: 0.043197439 | M39: 0.049103405 | N39: 0.05244689 | O39: 0.054724876 | P39: 0.055834333 | Q39: 0.051298635 | R39: 0.047620238 | S39: 0.048286177 | T39: 0.053494859 | U39: 0.058288537 | V39: 0.060211743 | W39: 0.062828808 | X39: 0.064302091 | Y39: 0.066781026 | Z39: 0.070064054 | AA39: 0.073621488 | AB39: 0.076485172 | AC39: 0.079207143 | AD39: 0.081346987 | AE39: 0.083453501 | AF39: 0.085825794 | AG39: 0.087923864 | AH39: 0.090093614 | AI39: 0.092296793 | AJ39: 0.094347299 | AK39: 0.096778738 | AL39: 0.099214242 | AM39: 0.10156782 | AN39: 0.10396142 | AO39: 0.10652453 | AP39: 0.1092103 | AQ39: 0.11184305 | AR39: 0.11438128 | AS39: 0.11689909 | AT39: 0.11940568 | AU39: 0.12187955 | AV39: 0.12439091 | AW39: 0.12691387 | AX39: 0.12909372 | AY39: =AX39-AX3 -> -0.00065593353
B40: Dépenses publiques | C40: DEP_VAL_2 | E40: 912128.34 | F40: 937425.07 | G40: 961862 | H40: 986659.9 | I40: 1008523.5 | J40: 1032902.3 | K40: 1047851.8 | L40: 1070612.1 | M40: 1095908.2 | N40: 1121771.6 | O40: 1148883 | P40: 1175814.4 | Q40: 1206902.8 | R40: 1245996.2 | S40: 1296419.4 | T40: 1350708.4 | U40: 1402975.7 | V40: 1451638.6 | W40: 1509929.7 | X40: 1562504.7 | Y40: 1613383.2 | Z40: 1665297.1 | AA40: 1719346.4 | AB40: 1775567.5 | AC40: 1833395.2 | AD40: 1893323.5 | AE40: 1955899.8 | AF40: 2021046.4 | AG40: 2089099.4 | AH40: 2161002.8 | AI40: 2237105.5 | AJ40: 2318176.5 | AK40: 2404909 | AL40: 2495727.7 | AM40: 2590785.2 | AN40: 2689784.3 | AO40: 2793482.5 | AP40: 2901786.6 | AQ40: 3013748.4 | AR40: 3129322.3 | AS40: 3248464.5 | AT40: 3371392 | AU40: 3498694.6 | AV40: 3630730.5 | AW40: 3767498.9 | AX40: 3909429.1
B41: Cotisations sociales | C41: CL_S_20_2*L_S_20_2*PROG_L_20_2 | D41: 225891.81 | E41: 234108.95 | F41: 242473.94 | G41: 250402.08 | H41: 256846.06 | I41: 262566.58 | J41: 263167.14 | K41: 263676.15 | L41: 266631.64 | M41: 271219.5 | N41: 274530.54 | O41: 277636.51 | P41: 281316.62 | Q41: 286630.63 | R41: 294477.82 | S41: 304804.23 | T41: 315357.14 | U41: 325800.82 | V41: 336494.3 | W41: 349298.7 | X41: 361045.38 | Y41: 371489.97 | Z41: 382419.34 | AA41: 393734.59 | AB41: 405428.38 | AC41: 417383.43 | AD41: 429740.74 | AE41: 442689.58 | AF41: 456216.82 | AG41: 470447.92 | AH41: 485554.74 | AI41: 501638.98 | AJ41: 518806.15 | AK41: 537162.07 | AL41: 556274.12 | AM41: 576201.73 | AN41: 596859.65 | AO41: 618353.07 | AP41: 640638.93 | AQ41: 663460.04 | AR41: 686817.27 | AS41: 710717.43 | AT41: 735266.54 | AU41: 760558.02 | AV41: 786689.63 | AW41: 813644.51 | AX41: 841552.82
A42: choc | B42: Intérêts de la dette | C42: R_G_2(-1)*DEBT_G_VAL_2(-1) | E42: 41668.561 | F42: 43184.314 | G42: 43187.915 | H42: 42585.465 | I42: 43691.245 | J42: 43903.569 | K42: 45997.25 | L42: 47736.632 | M42: 49746.374 | N42: 51750.62 | O42: 54600.366 | P42: 57036.086 | Q42: 59608.47 | R42: 63917.696 | S42: 69712.845 | T42: 75012.737 | U42: 81112.827 | V42: 87706.558 | W42: 94734.86 | X42: 102253.86 | Y42: 109977.53 | Z42: 118027.46 | AA42: 126421.96 | AB42: 135296.84 | AC42: 144651.94 | AD42: 154507.21 | AE42: 164837.07 | AF42: 175802.14 | AG42: 187201.93 | AH42: 199276.28 | AI42: 212064.45 | AJ42: 225445.01 | AK42: 239844.99 | AL42: 255027.83 | AM42: 271071.26 | AN42: 287995.5 | AO42: 305858.14 | AP42: 324801.81 | AQ42: 344825.45 | AR42: 365979.92 | AS42: 388302.85 | AT42: 411828.13 | AU42: 436674.65 | AV42: 462881.7 | AW42: 490504.24 | AX42: 519590.95
...

Sheet T graph
B1: en écart au Tend | C1: 2020 | D1: 2021 | E1: 2022 | F1: 2023 | G1: 2024 | H1: 2025 | I1: 2026 | J1: 2027 | K1: 2028 | L1: 2029 | M1: 2030 | N1: 2031 | O1: 2032 | P1: 2033 | Q1: 2034 | R1: 2035 | S1: 2036 | T1: 2037 | U1: 2038 | V1: 2039 | W1: 2040 | X1: 2041 | Y1: 2042 | Z1: 2043 | AA1: 2044 | AB1: 2045 | AC1: 2046 | AD1: 2047 | AE1: 2048 | AF1: 2049 | AG1: 2050
B2: Solde public | C2: =-(résultats!T58-résultats!T40)+(résultats!T22-résultats!T4) -> 0 | D2: =-(résultats!U58-résultats!U40)+(résultats!U22-résultats!U4) -> 0 | E2: =+(résultats!V58-résultats!V40)-(résultats!V22-résultats!V4) -> 0 | F2: =+(résultats!W58-résultats!W40)-(résultats!W22-résultats!W4) -> 0 | G2: =+(résultats!X58-résultats!X40)-(résultats!X22-résultats!X4) -> -225.945 | H2: =+(résultats!Y58-résultats!Y40)-(résultats!Y22-résultats!Y4) -> 51.045 | I2: =+(résultats!Z58-résultats!Z40)-(résultats!Z22-résultats!Z4) -> 637.593 | J2: =+(résultats!AA58-résultats!AA40)-(résultats!AA22-résultats!AA4) -> 1229.961 | K2: =+(résultats!AB58-résultats!AB40)-(résultats!AB22-résultats!AB4) -> 1661.868 | L2: =+(résultats!AC58-résultats!AC40)-(résultats!AC22-résultats!AC4) -> 1963.849 | ... AG2: =+(résultats!AX58-résultats!AX40)-(résultats!AX22-résultats!AX4) -> -357.449 | AH2: =E4+E14-E2 -> 0 | AI2: =AG2+(résultats!AX237-résultats!AX236) -> 0.00049999997
B3: Déficit public en % PIB | C3: =résultats!T39-résultats!T3 -> 0 | D3: =résultats!U39-résultats!U3 -> 0 | E3: =résultats!V39-résultats!V3 -> 0 | F3: =(résultats!W39-résultats!W3) -> 0 | G3: =(résultats!X39-résultats!X3) -> 7.8299091e-05 | H3: =(résultats!Y39-résultats!Y3) -> -5.2499338e-05 | I3: =(résultats!Z39-résultats!Z3) -> -0.00030078031 | J3: =(résultats!AA39-résultats!AA3) -> -0.00054496604 | K3: =(résultats!AB39-résultats!AB3) -> -0.00072559803 | L3: =(résultats!AC39-résultats!AC3) -> -0.00085830747 | M3: =(résultats!AD39-résultats!AD3) -> -0.00098118281 | ... AG3: =(résultats!AX39-résultats!AX3) -> -0.00065593353
B4: Dépenses publiques (-) en M€ courants | C4: =-(résultats!T40-résultats!T4) -> 0 | D4: =-(résultats!U40-résultats!U4) -> 0 | E4: =-(résultats!V40-résultats!V4) -> 0 | F4: =-(résultats!W40-résultats!W4) -> 0 | G4: =-(résultats!X40-résultats!X4) -> 390.016 | H4: =-(résultats!Y40-résultats!Y4) -> 994.833 | I4: =-(résultats!Z40-résultats!Z4) -> 1406.427 | J4: =-(résultats!AA40-résultats!AA4) -> 1636.272 | ... AG4: =-(résultats!AX40-résultats!AX4) -> -9658.523 | AH4: =SUM(E5:E13)-E4 -> 0
B5: Intérêts de la dette | C5: =-(résultats!T42-résultats!T6) -> 0 | D5: =-(résultats!U42-résultats!U6) -> 0 | E5: =-(résultats!V42-résultats!V6) -> 0 | F5: =-(résultats!W42-résultats!W6) -> 0 | G5: =-(résultats!X42-résultats!X6) -> 0 | H5: =-(résultats!Y42-résultats!Y6) -> 37.83308 | I5: =-(résultats!Z42-résultats!Z6) -> 86.710528 | J5: =-(résultats!AA42-résultats!AA6) -> 137.48254 | ... AG5: =-(résultats!AX42-résultats!AX6) -> -361.19708
B6: Facture énergétique | C6: =-(résultats!T43-résultats!T7) -> 0 | D6: =-(résultats!U43-résultats!U7) -> 0 | E6: =-(résultats!V43-résultats!V7) -> 0 | F6: =-(résultats!W43-résultats!W7) -> 0 | G6: =-(résultats!X43-résultats!X7) -> -1.3262088 | H6: =-(résultats!Y43-résultats!Y7) -> -4.0723924 | I6: =-(résultats!Z43-résultats!Z7) -> 2.2920361 | J6: =-(résultats!AA43-résultats!AA7) -> 3.1497813 | ... AG6: =-(résultats!AX43-résultats!AX7) -> -23.984572
B7: Charges courantes | C7: =-(résultats!T44-résultats!T8+(résultats!T41-résultats!T5)+(résultats!T45-résultats!T9)+(résultats!T47-résultats!T11)) -> 0 | D7: =-(résultats!U44-résultats!U8+(résultats!U41-résultats!U5)+(résultats!U45-résultats!U9)+(résultats!U47-résultats!U11)) -> 0 | E7: =-(résultats!V44-résultats!V8+(résultats!V41-résultats!V5)+(résultats!V45-résultats!V9)+(résultats!V47-résultats!V11)) -> 0 | F7: =-(résultats!W44-résultats!W8+(résultats!W41-résultats!W5)+(résultats!W45-résultats!W9)+(résultats!W47-résultats!W11)) -> 0 | G7: =-(résultats!X44-résultats!X8+(résultats!X41-résultats!X5)+(résultats!X45-résultats!X9)+(résultats!X47-résultats!X11)) -> 34.414416 | H7: =-(résultats!Y44-résultats!Y8+(résultats!Y41-résultats!Y5)+(résultats!Y45-résultats!Y9)+(résultats!Y47-résultats!Y11)) -> 42.151774 | I7: =-(résultats!Z44-résultats!Z8+(résultats!Z41-résultats!Z5)+(résultats!Z45-résultats!Z9)+(résultats!Z47-résultats!Z11)) -> -43.051542 | J7: =-(résultats!AA44-résultats!AA8+(résultats!AA41-résultats!AA5)+(résultats!AA45-résultats!AA9)+(résultats!AA47-résultats!AA11)) -> -228.37756 | ... AG7: =-(résultats!AX44-résultats!AX8+(résultats!AX41-résultats!AX5)+(résultats!AX45-résultats!AX9)+(résultats!AX47-résultats!AX11)) -> -8150.466
B8: Investissements | C8: =-(résultats!T46-résultats!T10) -> 0 | D8: =-(résultats!U46-résultats!U10) -> 0 | E8: =-(résultats!V46-résultats!V10) -> 0 | F8: =-(résultats!W46-résultats!W10) -> 0 | G8: =-(résultats!X46-résultats!X10) -> 1.7984423 | H8: =-(résultats!Y46-résultats!Y10) -> -2.5573333 | I8: =-(résultats!Z46-résultats!Z10) -> -16.315256 | J8: =-(résultats!AA46-résultats!AA10) -> -36.38554 | ... AG8: =-(résultats!AX46-résultats!AX10) -> -809.05966
B9: Prestations sociales | C9: =-(résultats!T50-résultats!T14) -> 0 | D9: =-(résultats!U50-résultats!U14) -> 0 | E9: =-(résultats!V50-résultats!V14) -> 0 | F9: =-(résultats!W50-résultats!W14) -> 0 | G9: =-(résultats!X50-résultats!X14) -> 41.554 | H9: =-(résultats!Y50-résultats!Y14) -> 147.7702 | I9: =-(résultats!Z50-résultats!Z14) -> 282.6237 | J9: =-(résultats!AA50-résultats!AA14) -> 382.8192 | ... AG9: =-(résultats!AX50-résultats!AX14) -> -4921.805
B10: Subventions | C10: =-((résultats!T49-résultats!T13)+(résultats!T48-résultats!T12)) -> 0 | D10: =-((résultats!U49-résultats!U13)+(résultats!U48-résultats!U12)) -> 0 | E10: =-((résultats!V49-résultats!V13)+(résultats!V48-résultats!V12)) -> 0 | F10: =-((résultats!W49-résultats!W13)+(résultats!W48-résultats!W12)) -> 0 | G10: =-((résultats!X49-résultats!X13)+(résultats!X48-résultats!X12)) -> -43.044196 | H10: =-((résultats!Y49-résultats!Y13)+(résultats!Y48-résultats!Y12)) -> -89.096296 | I10: =-((résultats!Z49-résultats!Z13)+(résultats!Z48-résultats!Z12)) -> -132.41675 | J10: =-((résultats!AA49-résultats!AA13)+(résultats!AA48-résultats!AA12)) -> -170.61828 | ... AG10: =-((résultats!AX49-résultats!AX13)+(résultats!AX48-résultats!AX12)) -> -482.5337
B11: Subventions à la rénovation énergétique | C11: =-(résultats!T51-résultats!T15) -> 0 | D11: =-(résultats!U51-résultats!U15) -> 0 | E11: =-(résultats!V51-résultats!V15) -> 0 | F11: =-(résultats!W51-résultats!W15) -> 0 | G11: =-(résultats!X51-résultats!X15) -> 0 | H11: =-(résultats!Y51-résultats!Y15) -> 0 | I11: =-(résultats!Z51-résultats!Z15) -> 0 | J11: =-(résultats!AA51-résultats!AA15) -> 0 | ... AG11: =-(résultats!AX51-résultats!AX15) -> 0
B12: Solde bonus malus automobile | C12: =-(résultats!T52-résultats!T16) -> 0 | D12: =-(résultats!U52-résultats!U16) -> 0 | E12: =-(résultats!V52-résultats!V16) -> 0 | F12: =-(résultats!W52-résultats!W16) -> 0 | G12: =-(résultats!X52-résultats!X16) -> 0.790545 | H12: =-(résultats!Y52-résultats!Y16) -> 2.1524958 | I12: =-(résultats!Z52-résultats!Z16) -> 2.357425 | J12: =-(résultats!AA52-résultats!AA16) -> 1.7808381 | ... AG12: =-(résultats!AX52-résultats!AX16) -> 2.020689
B13: Redistribution aux agents | C13: =SUM(résultats!T53:T57)-SUM(résultats!T17:T21) -> 0 | D13: =SUM(résultats!U53:U57)-SUM(résultats!U17:U21) -> 0 | E13: =SUM(résultats!V53:V57)-SUM(résultats!V17:V21) -> 0 | F13: =-(SUM(résultats!W53:W57)-SUM(résultats!W17:W21)) -> 0 | G13: =-(SUM(résultats!X53:X57)-SUM(résultats!X17:X21)) -> 355.82958 | H13: =-(SUM(résultats!Y53:Y57)-SUM(résultats!Y17:Y21)) -> 860.65254 | I13: =-(SUM(résultats!Z53:Z57)-SUM(résultats!Z17:Z21)) -> 1224.2261 | J13: =-(SUM(résultats!AA53:AA57)-SUM(résultats!AA17:AA21)) -> 1546.4214 | K13: =-(SUM(résultats!AB53:AB57)-SUM(résultats!AB17:AB21)) -> 1842.4871 | L13: =-(SUM(résultats!AC53:AC57)-SUM(résultats!AC17:AC21)) -> 2124.7109 | M13: =-(SUM(résultats!AD53:AD57)-SUM(résultats!AD17:AD21)) -> 2405.9872 | ... AG13: =-(SUM(résultats!AX53:AX57)-SUM(résultats!AX17:AX21)) -> 5088.5008
B14: Recettes publiques en M€ courants | C14: =(résultats!T58-résultats!T22) -> 0 | D14: =(résultats!U58-résultats!U22) -> 0 | E14: =(résultats!V58-résultats!V22) -> 0 | F14: =(résultats!W58-résultats!W22) -> 0 | G14: =(résultats!X58-résultats!X22) -> -615.961 | H14: =(résultats!Y58-résultats!Y22) -> -943.788 | I14: =(résultats!Z58-résultats!Z22) -> -768.834 | J14: =(résultats!AA58-résultats!AA22) -> -406.311 | ... AG14: =(résultats!AX58-résultats!AX22) -> 9301.074
B15: Impôts sur les revenus et le patrimoine | C15: =(résultats!T59-résultats!T23+(résultats!T60-résultats!T24)+(résultats!T61-résultats!T25)) -> 0 | D15: =(résultats!U59-résultats!U23+(résultats!U60-résultats!U24)+(résultats!U61-résultats!U25)) -> 0 | E15: =(résultats!V59-résultats!V23+(résultats!V60-résultats!V24)+(résultats!V61-résultats!V25)) -> 0 | F15: =(résultats!W59-résultats!W23+(résultats!W60-résultats!W24)+(résultats!W61-résultats!W25)) -> 0 | G15: =(résultats!X59-résultats!X23+(résultats!X60-résultats!X24)+(résultats!X61-résultats!X25)) -> 10.375427 | H15: =(résultats!Y59-résultats!Y23+(résultats!Y60-résultats!Y24)+(résultats!Y61-résultats!Y25)) -> 105.54581 | I15: =(résultats!Z59-résultats!Z23+(résultats!Z60-résultats!Z24)+(résultats!Z61-résultats!Z25)) -> 286.7507 | J15: =(résultats!AA59-résultats!AA23+(résultats!AA60-résultats!AA24)+(résultats!AA61-résultats!AA25)) -> 481.40512 | ... AG15: =(résultats!AX59-résultats!AX23+(résultats!AX60-résultats!AX24)+(résultats!AX61-résultats!AX25)) -> 2745.7343
B16: Taxes à la consommation | C16: =(résultats!T63-résultats!T27) -> 0 | D16: =(résultats!U63-résultats!U27) -> 0 | E16: =(résultats!V63-résultats!V27) -> 0 | F16: =(résultats!W63-résultats!W27) -> 0 | G16: =(résultats!X63-résultats!X27) -> -83.161 | H16: =(résultats!Y63-résultats!Y27) -> -126.12893 | I16: =(résultats!Z63-résultats!Z27) -> -115.9511 | J16: =(résultats!AA63-résultats!AA27) -> -87.714401 | ... AG16: =(résultats!AX63-résultats!AX27) -> 1312.2078
B17: Taxes énergétiques | C17: =SUM(résultats!T69:T73)-SUM(résultats!T33:T37) -> 0 | D17: =SUM(résultats!U69:U73)-SUM(résultats!U33:U37) -> 0 | E17: =SUM(résultats!V69:V73)-SUM(résultats!V33:V37) -> 0 | F17: =SUM(résultats!W69:W73)-SUM(résultats!W33:W37) -> 0 | G17: =SUM(résultats!X69:X73)-SUM(résultats!X33:X37) -> -355.82958 | H17: =SUM(résultats!Y69:Y73)-SUM(résultats!Y33:Y37) -> -860.65254 | I17: =SUM(résultats!Z69:Z73)-SUM(résultats!Z33:Z37) -> -1224.2261 | J17: =SUM(résultats!AA69:AA73)-SUM(résultats!AA33:AA37) -> -1546.4214 | ... AG17: =SUM(résultats!AX69:AX73)-SUM(résultats!AX33:AX37) -> -5088.5008
B18: Taxes à la production | C18: =(résultats!T64-résultats!T28) -> 0 | D18: =(résultats!U64-résultats!U28) -> 0 | E18: =(résultats!V64-résultats!V28) -> 0 | F18: =(résultats!W64-résultats!W28) -> 0 | G18: =(résultats!X64-résultats!X28) -> 30.948442 | H18: =(résultats!Y64-résultats!Y28) -> 86.606698 | I18: =(résultats!Z64-résultats!Z28) -> 151.73404 | J18: =(résultats!AA64-résultats!AA28) -> 218.55817 | ... AG18: =(résultats!AX64-résultats!AX28) -> 1169.859
B19: Impôts sur les bénéfices | C19: =(résultats!T65-résultats!T29) -> 0 | D19: =(résultats!U65-résultats!U29) -> 0 | E19: =(résultats!V65-résultats!V29) -> 0 | F19: =(résultats!W65-résultats!W29) -> 0 | G19: =(résultats!X65-résultats!X29) -> -244.85271 | H19: =(résultats!Y65-résultats!Y29) -> -369.08619 | I19: =(résultats!Z65-résultats!Z29) -> -444.58739 | J19: =(résultats!AA65-résultats!AA29) -> -466.50743 | ... AG19: =(résultats!AX65-résultats!AX29) -> 116.53325
B20: Cotisations sociales | C20: =(résultats!T66-résultats!T30) -> 0 | D20: =(résultats!U66-résultats!U30) -> 0 | E20: =(résultats!V66-résultats!V30) -> 0 | F20: =(résultats!W66-résultats!W30) -> 0 | G20: =(résultats!X66-résultats!X30) -> 3.430913 | H20: =(résultats!Y66-résultats!Y30) -> 179.35576 | I20: =(résultats!Z66-résultats!Z30) -> 567.93861 | J20: =(résultats!AA66-résultats!AA30) -> 1087.373 | ... AG20: =(résultats!AX66-résultats!AX30) -> 9815.476
B21: Revenus des services publics | C21: =(résultats!T67-résultats!T31+(résultats!T68-résultats!T32)) -> 0 | D21: =(résultats!U67-résultats!U31+(résultats!U68-résultats!U32)) -> 0 | E21: =(résultats!V67-résultats!V31+(résultats!V68-résultats!V32)) -> 0 | F21: =(résultats!W67-résultats!W31+(résultats!W68-résultats!W32)) -> 0 | G21: =(résultats!X67-résultats!X31+(résultats!X68-résultats!X32)) -> 23.126647 | H21: =(résultats!Y67-résultats!Y31+(résultats!Y68-résultats!Y32)) -> 40.571841 | I21: =(résultats!Z67-résultats!Z31+(résultats!Z68-résultats!Z32)) -> 9.506593 | J21: =(résultats!AA67-résultats!AA31+(résultats!AA68-résultats!AA32)) -> -93.004129 | ... AG21: =(résultats!AX67-résultats!AX31+(résultats!AX68-résultats!AX32)) -> -770.23556
E22: =SUM(E15:E21,E5:E12) -> 0 | F22: =SUM(F15:F21,F5:F13)-F2 -> 0 | G22: =SUM(G15:G21,G5:G13)-G2 -> -0.00028227786 | H22: =SUM(H15:H21,H5:H13)-H2 -> 0.0015186248 | I22: =SUM(I15:I21,I5:I13)-I2 -> -0.0014006859 | J22: =SUM(J15:J21,J5:J13)-J2 -> 0.00028350736 | K22: =SUM(K15:K21,K5:K13)-K2 -> -0.00045556735 | L22: =SUM(L15:L21,L5:L13)-L2 -> -0.0010033515 | M22: =SUM(M15:M21,M5:M13)-M2 -> -0.0011196327 | ... AG22: =SUM(AG15:AG21,AG5:AG13)-AG2 -> -0.0015740375
E25: =E2+E4+E14 -> 0 | F25: =SUM(F15:F21)-F14 -> 0 | G25: =SUM(G15:G21)-G14 -> -0.00086438217 | H25: =SUM(H15:H21)-H14 -> 0.00045414684 | I25: =SUM(I15:I21)-I14 -> -0.00066624862 | J25: =SUM(J15:J21)-J14 -> -9.3744935e-05 | K25: =SUM(K15:K21)-K14 -> -0.00034063562 | L25: =SUM(L15:L21)-L14 -> -0.00027033425 | M25: =SUM(M15:M21)-M14 -> -0.0008759891 | ... AG25: =SUM(AG15:AG21)-AG14 -> -7.1769067e-05
F26: =SUM(F5:F13)-F4 -> 0 | G26: =SUM(G5:G13)-G4 -> 0.00058210431 | H26: =SUM(H5:H13)-H4 -> 0.0010644779 | I26: =SUM(I5:I13)-I4 -> -0.00073443733 | J26: =SUM(J5:J13)-J4 -> 0.00037725229 | K26: =SUM(K5:K13)-K4 -> -0.00011493173 | L26: =SUM(L5:L13)-L4 -> -0.00073301726 | M26: =SUM(M5:M13)-M4 -> -0.00024364362 | ... AG26: =SUM(AG5:AG13)-AG4 -> -0.0015022684
