Workbook

Sheet output
A1: Annuities heater (Billion euro/year) | C1: 1.027 | D1: 0.959 | E1: 0.884 | F1: 0.912 | G1: 0.854 | H1: 0.789 | I1: 0.728 | J1: 0.815 | K1: 0.75 | L1: 0.77 | M1: 0.795 | N1: 0.816 | O1: 0.708 | P1: 0.744 | Q1: 0.762 | R1: 0.693 | S1: 0.787 | T1: 0.709 | U1: 0.704 | V1: 0.653 | W1: 0.846 | X1: 0.727 | Y1: 0.771 | Z1: 0.75 | AA1: 0.748 | AB1: 0.747 | AC1: 0.745
A2: Annuities heater households (Billion euro/year) | C2: 1.561 | D2: 1.814 | E2: 1.673 | F2: 1.726 | G2: 1.615 | H2: 1.492 | I2: 1.378 | J2: 1.542 | K2: 1.418 | L2: 1.456 | M2: 1.503 | N2: 1.544 | O2: 1.34 | P2: 1.408 | Q2: 1.441 | R2: 1.311 | S2: 1.489 | T2: 1.341 | U2: 1.331 | V2: 1.234 | W2: 1.6 | X2: 1.375 | Y2: 1.458 | Z2: 1.418 | AA2: 1.415 | AB2: 1.414 | AC2: 1.409
A3: Annuities insulation (Billion euro/year) | C3: 0.386 | D3: 0.216 | E3: 0.329 | F3: 0.357 | G3: 0.333 | H3: 0.304 | I3: 0.379 | J3: 0.448 | K3: 0.43 | L3: 0.401 | M3: 0.384 | N3: 0.352 | O3: 0.355 | P3: 0.473 | Q3: 0.443 | R3: 0.424 | S3: 0.632 | T3: 0.461 | U3: 0.438 | V3: 0.386 | W3: 0.382 | X3: 0.366 | Y3: 0.349 | Z3: 0.334 | AA3: 0.32 | AB3: 0.307 | AC3: 0.296
A4: Annuities insulation households (Billion euro/year) | C4: 0.554 | D4: 0.425 | E4: 0.648 | F4: 0.708 | G4: 0.658 | H4: 0.598 | I4: 0.756 | J4: 0.886 | K4: 0.851 | L4: 0.791 | M4: 0.756 | N4: 0.69 | O4: 0.698 | P4: 0.922 | Q4: 0.863 | R4: 0.825 | S4: 1.238 | T4: 0.895 | U4: 0.849 | V4: 0.749 | W4: 0.742 | X4: 0.709 | Y4: 0.677 | Z4: 0.648 | AA4: 0.621 | AB4: 0.595 | AC4: 0.573
A5: Annuities insulation Owner-occupied - C1 (euro/year,household) | C5: 315.146 | D5: 192.269 | E5: 657.039 | F5: 1150.535 | G5: 1102.32 | H5: 1054.903 | I5: 1738.001 | J5: 1686.557 | K5: 1629.919 | L5: 1575.449 | M5: 1519.245 | N5: 1461.274 | O5: 1319 | P5: 1280.992 | Q5: 1244.559 | R5: 1208.35 | S5: 1011.993 | T5: 980.385 | U5: 958.416 | V5: 937.116 | W5: 922.093 | X5: 905.902 | Y5: 890.526 | Z5: 875.098 | AA5: 860.133 | AB5: 845.543 | AC5: 829.331
A6: Annuities insulation Owner-occupied - C2 (euro/year,household) | C6: 439.593 | D6: 706.915 | E6: 706.811 | F6: 1102.271 | G6: 1056.133 | H6: 1011.344 | I6: 1578.806 | J6: 1520.42 | K6: 1455.072 | L6: 1395.478 | M6: 1335.212 | N6: 1274.442 | O6: 1204.806 | P6: 1169.087 | Q6: 1133.628 | R6: 1099.919 | S6: 1001.562 | T6: 961.781 | U6: 945.26 | V6: 929.852 | W6: 920.051 | X6: 909.516 | Y6: 899.24 | Z6: 889.377 | AA6: 879.858 | AB6: 870.6 | AC6: 882.95
A7: Annuities insulation Owner-occupied - C3 (euro/year,household) | C7: 964.912 | D7: 888.48 | E7: 890.1 | F7: 1105.174 | G7: 1077.536 | H7: 1051.473 | I7: 1423.073 | J7: 1374.62 | K7: 1344.66 | L7: 1297.103 | M7: 1248.914 | N7: 1200.15 | O7: 1170.102 | P7: 1145.097 | Q7: 1120.354 | R7: 1097.945 | S7: 1292.586 | T7: 991.758 | U7: 984.566 | V7: 978.578 | W7: 976.919 | X7: 974.955 | Y7: 972.262 | Z7: 970.391 | AA7: 969.15 | AB7: 967.728 | AC7: 965.998
A8: Annuities insulation Owner-occupied - C4 (euro/year,household) | C8: 931 | D8: 933.078 | E8: 932.872 | F8: 1119.797 | G8: 1094.433 | H8: 1070.88 | I8: 1418.202 | J8: 1373.147 | K8: 1363.822 | L8: 1316.266 | M8: 1267.938 | N8: 1219.583 | O8: 1174.862 | P8: 1151.841 | Q8: 1131.279 | R8: 1110.723 | S8: 1329.547 | T8: 989.588 | U8: 983.478 | V8: 978.53 | W8: 981.982 | X8: 980.712 | Y8: 978.553 | Z8: 977.336 | AA8: 976.397 | AB8: 975.657 | AC8: 974.592
A9: Annuities insulation Owner-occupied - C5 (euro/year,household) | C9: 1179.05 | D9: 1140.559 | E9: 1116.542 | F9: 1248.897 | G9: 1211.632 | H9: 1180.796 | I9: 1391.221 | J9: 1350.955 | K9: 1430.168 | L9: 1369.132 | M9: 1310.163 | N9: 1253.901 | O9: 1186.868 | P9: 1155.482 | Q9: 1120.878 | R9: 1088.413 | S9: 1332.839 | T9: 1010.196 | U9: 1009.614 | V9: 1010.536 | W9: 1014.769 | X9: 1019.405 | Y9: 1021.857 | Z9: 1025.829 | AA9: 1029.726 | AB9: 1033.435 | AC9: 1036.771
A10: Annuities insulation Privately rented - C1 (euro/year,household) | C10: 815.738 | D10: 1540.522 | E10: 1820.005 | F10: 1779.634 | G10: 1732.705 | H10: 1678.654 | I10: 1616.611 | J10: 961.85 | K10: 939.018 | L10: 910.057 | M10: 877.935 | N10: 842.874 | O10: 822.215 | P10: 570.492 | Q10: 567.466 | R10: 564.842 | S10: 575.248 | T10: 561.309 | U10: 560.833 | V10: 560.657 | W10: 560.926 | X10: 561.184 | Y10: 562.071 | Z10: 562.825 | AA10: 563.89 | AB10: 565.177 | AC10: 566.335
A11: Annuities insulation Privately rented - C2 (euro/year,household) | C11: 947.655 | D11: 1587.525 | E11: 1867.167 | F11: 1814.372 | G11: 1753.16 | H11: 1682.841 | I11: 1603.139 | J11: 1023.619 | K11: 995.438 | L11: 957.412 | M11: 915.236 | N11: 869.395 | O11: 843.469 | P11: 619.28 | Q11: 618.165 | R11: 617.787 | S11: 645.994 | T11: 617.607 | U11: 618.131 | V11: 619.23 | W11: 621.444 | X11: 623.45 | Y11: 625.451 | Z11: 627.489 | AA11: 629.622 | AB11: 631.735 | AC11: 636.623
A12: Annuities insulation Privately rented - C3 (euro/year,household) | C12: 1133.728 | D12: 1524.941 | E12: 1871.543 | F12: 1803.428 | G12: 1725.665 | H12: 1638.016 | I12: 1541.514 | J12: 1084.447 | K12: 1051.917 | L12: 1002.633 | M12: 949.051 | N12: 892.083 | O12: 862.034 | P12: 648.797 | Q12: 651.566 | R12: 654.725 | S12: 720.745 | T12: 659.554 | U12: 663.077 | V12: 667.135 | W12: 671.616 | X12: 676.901 | Y12: 680.63 | Z12: 684.69 | AA12: 688.473 | AB12: 691.822 | AC12: 694.605
... A55: Annuities Single-family - Social-housing - C5 (euro) | C55: 1194125.7 | D55: 2496026.2 | E55: 3943721 | F55: 5503217.3 | G55: 7126046.8 | H55: 8730383.6 | I55: 10415463 | J55: 12226319 | K55: 14215771 | L55: 16439221 | M55: 17745981 | N55: 18811107 | O55: 19786449 | P55: 20512757 | Q55: 21111120 | R55: 21588875 | S55: 22250017 | T55: 22357010 | U55: 22229142 | V55: 21155042 | W55: 20002628 | X55: 18870165 | Y55: 17714210 | Z55: 16655009 | AA55: 15635982 | AB55: 14731175 | AC55: 13534095
A56: Average cost Cee (euro) | C56: 8806.903
A57: Average cost Cee heater (euro) | C57: 7868.634
A58: Average cost Cee insulation (euro) | C58: 11629.844
A59: Average cost Mpr (euro) | C59: 9620.599
A60: Average cost Mpr heater (euro) | C60: 8732.055
A61: Average cost Mpr insulation (euro) | C61: 12349.084
A62: Average cost Mpr multifamily (euro) | C62: 7499.803
A63: Average cost Mpr multifamily insulation (euro) | C63: 7499.803
A64: Average cost Mpr serenite (euro) | C64: 9775.139
A65: Average cost Mpr serenite insulation (euro) | C65: 9775.139
A66: Average cost Over cap (euro) | C66: 4618.255
A67: Average cost Over cap heater (euro) | C67: 0
A68: Average cost Over cap insulation (euro) | C68: 4618.255
A69: Average cost Reduced vat (euro) | C69: 8806.903 | D69: 7677.401 | E69: 7506.398 | F69: 7735.568 | G69: 7205.668 | H69: 6694.883 | I69: 6794.113 | J69: 7138.466 | K69: 6825.823 | L69: 6807.68 | M69: 6793.601 | N69: 6779.028 | O69: 6895.299 | P69: 6794.657 | Q69: 6842.101 | R69: 6872.593 | S69: 7662.126 | T69: 6957.697 | U69: 6931.202 | V69: 6921.447 | W69: 7045.471 | X69: 7157.463 | Y69: 6730.661 | Z69: 6919.962 | AA69: 6601.565 | AB69: 6261.544 | AC69: 5975.502
A70: Average cost Reduced vat heater (euro) | C70: 7868.634 | D70: 7358.448 | E70: 6801.633 | F70: 7031.051 | G70: 6593.528 | H70: 6103.443 | I70: 5649.509 | J70: 6334.08 | K70: 5830.9 | L70: 5993.882 | M70: 6195.346 | N70: 6367.262 | O70: 6419.697 | P70: 6750.127 | Q70: 6912.978 | R70: 7113.349 | S70: 7248.111 | T70: 7163.348 | U70: 7158.301 | V70: 7183.832 | W70: 7389.336 | X70: 7613.66 | Y70: 6826.861 | Z70: 7125.224 | AA70: 6595.948 | AB70: 6081.444 | AC70: 5673.832
A71: Average cost Reduced vat insulation (euro) | C71: 11629.844 | D71: 8999.472 | E71: 9538.858 | F71: 9615.634 | G71: 8806.393 | H71: 8287.986 | I71: 9669.751 | J71: 8672.34 | K71: 8837.077 | L71: 8504.921 | M71: 8019.404 | N71: 7658.191 | O71: 7772.706 | P71: 6849.041 | Q71: 6751.034 | R71: 6593.741 | S71: 8103.268 | T71: 6730.629 | U71: 6671.021 | V71: 6609.428 | W71: 6531.355 | X71: 6560.069 | Y71: 6574.339 | Z71: 6594.194 | AA71: 6611.622 | AB71: 6627.05 | AC71: 6657.512
A72: Average cost Zero interest loan (euro) | C72: 11629.844 | D72: 8999.472 | E72: 9538.858 | F72: 9615.634 | G72: 8806.393 | H72: 8287.986 | I72: 9669.751 | J72: 8672.34 | K72: 8837.077 | L72: 8504.921 | M72: 8019.404 | N72: 7658.191 | O72: 7772.706 | P72: 6849.041 | Q72: 6751.034 | R72: 6593.741 | S72: 8103.268 | T72: 6730.629 | U72: 6671.021 | V72: 6609.428 | W72: 6531.355 | X72: 6560.069 | Y72: 6574.339 | Z72: 6594.194 | AA72: 6611.622 | AB72: 6627.05 | AC72: 6657.512
A73: Average cost Zero interest loan insulation (euro) | C73: 11629.844 | D73: 8999.472 | E73: 9538.858 | F73: 9615.634 | G73: 8806.393 | H73: 8287.986 | I73: 9669.751 | J73: 8672.34 | K73: 8837.077 | L73: 8504.921 | M73: 8019.404 | N73: 7658.191 | O73: 7772.706 | P73: 6849.041 | Q73: 6751.034 | R73: 6593.741 | S73: 8103.268 | T73: 6730.629 | U73: 6671.021 | V73: 6609.428 | W73: 6531.355 | X73: 6560.069 | Y73: 6574.339 | Z73: 6594.194 | AA73: 6611.622 | AB73: 6627.05 | AC73: 6657.512
A74: Average energy std saved Cee insulation (MWh) | C74: 5.689
A75: Average energy std saved Mpr insulation (MWh) | C75: 5.304
A76: Average energy std saved Mpr multifamily insulation (MWh) | C76: 4.772
A77: Average energy std saved Mpr serenite insulation (MWh) | C77: 4.4
A78: Average energy std saved Over cap insulation (MWh) | C78: 0.615
A79: Average energy std saved Reduced vat insulation (MWh) | C79: 5.689 | D79: 4.149 | E79: 4.104 | F79: 4.399 | G79: 3.789 | H79: 3.354 | I79: 3.999 | J79: 3.8 | K79: 3.834 | L79: 3.457 | M79: 2.944 | N79: 2.627 | O79: 2.691 | P79: 2.088 | Q79: 1.953 | R79: 1.803 | S79: 2.563 | T79: 1.454 | U79: 1.383 | V79: 1.313 | W79: 1.237 | X79: 1.196 | Y79: 1.15 | Z79: 1.109 | AA79: 1.068 | AB79: 1.027 | AC79: 0.985
A80: Average energy std saved Zero interest loan insulation (MWh) | C80: 5.689 | D80: 4.149 | E80: 4.104 | F80: 4.399 | G80: 3.789 | H80: 3.354 | I80: 3.999 | J80: 3.8 | K80: 3.834 | L80: 3.457 | M80: 2.944 | N80: 2.627 | O80: 2.691 | P80: 2.088 | Q80: 1.953 | R80: 1.803 | S80: 2.563 | T80: 1.454 | U80: 1.383 | V80: 1.313 | W80: 1.237 | X80: 1.196 | Y80: 1.15 | Z80: 1.109 | AA80: 1.068 | AB80: 1.027 | AC80: 0.985
A81: Balance Owner-occupied - C1 (euro/year,household) | C81: -232.115 | D81: -79.296 | E81: -575.989 | F81: -809.676 | G81: -780.899 | H81: -753.656 | I81: -1243.452 | J81: -1204.973 | K81: -1164.351 | L81: -1127.672 | M81: -1091.724 | N81: -1056.254 | O81: -933.243 | P81: -908.18 | Q81: -884.772 | R81: -861.367 | S81: -746.186 | T81: -780.75 | U81: -769.903 | V81: -759.466 | W81: -753.159 | X81: -746.201 | Y81: -740.691 | Z81: -735.091 | AA81: -730.099 | AB81: -725.65 | AC81: -720.999
A82: Balance Owner-occupied - C2 (euro/year,household) | C82: -333.051 | D82: -607.225 | E82: -607.09 | F82: -764.576 | G82: -741.157 | H82: -719.5 | I82: -1100.351 | J82: -1062.369 | K82: -1020.165 | L82: -985.993 | M82: -953.594 | N82: -922.703 | O82: -849.726 | P82: -829.087 | Q82: -809.631 | R82: -790.737 | S82: -734.203 | T82: -773.655 | U82: -766.935 | V82: -760.693 | W82: -757.842 | X82: -754.515 | Y82: -752.197 | Z82: -749.893 | AA82: -748 | AB82: -746.449 | AC82: -765.55
...

Sheet figures 2030
J1: 2018 | K1: 2019 | L1: 2020 | M1: 2021 | N1: 2022 | O1: 2023 | P1: 2024 | Q1: 2025 | R1: 2026 | S1: 2027 | T1: 2028 | U1: 2029 | V1: 2030
H3: Emission Natural gas (MtCO2) | I3: Emissions du gaz (MtCO2) | J3: =VLOOKUP($H3,output!$A$10:$N$2201,J$1-$J$1+2) -> 20.02 | K3: =VLOOKUP($H3,output!$A$10:$N$2201,K$1-$J$1+2) -> 19.601 | L3: =VLOOKUP($H3,output!$A$10:$N$2201,L$1-$J$1+2) -> 19.575 | M3: =VLOOKUP($H3,output!$A$10:$N$2201,M$1-$J$1+2) -> 19.088 | N3: =VLOOKUP($H3,output!$A$10:$N$2201,N$1-$J$1+2) -> 18.257 | O3: =VLOOKUP($H3,output!$A$10:$N$2201,O$1-$J$1+2) -> 17.594 | P3: =VLOOKUP($H3,output!$A$10:$N$2201,P$1-$J$1+2) -> 16.811 | Q3: =VLOOKUP($H3,output!$A$10:$N$2201,Q$1-$J$1+2) -> 15.886 | ... V3: =VLOOKUP($H3,output!$A$10:$N$2201,V$1-$J$1+2) -> 11.457
H4: Emission Oil fuel (MtCO2) | I4: Emissions du fioul (MtCO2) | J4: =VLOOKUP($H4,output!$A$10:$N$2201,J$1-$J$1+2) -> 10.044 | K4: =VLOOKUP($H4,output!$A$10:$N$2201,K$1-$J$1+2) -> 9.04 | L4: =VLOOKUP($H4,output!$A$10:$N$2201,L$1-$J$1+2) -> 8.182 | M4: =VLOOKUP($H4,output!$A$10:$N$2201,M$1-$J$1+2) -> 7.23 | N4: =VLOOKUP($H4,output!$A$10:$N$2201,N$1-$J$1+2) -> 6.14 | O4: =VLOOKUP($H4,output!$A$10:$N$2201,O$1-$J$1+2) -> 5.237 | P4: =VLOOKUP($H4,output!$A$10:$N$2201,P$1-$J$1+2) -> 4.379 | Q4: =VLOOKUP($H4,output!$A$10:$N$2201,Q$1-$J$1+2) -> 3.559 | ... V4: =VLOOKUP($H4,output!$A$10:$N$2201,V$1-$J$1+2) -> 0
H5: Emission Electricity (MtCO2) | I5: Emissions de l'électricité (MtCO2) | J5: =VLOOKUP($H5,output!$A$10:$N$2201,J$1-$J$1+2) -> 4.021 | K5: =VLOOKUP($H5,output!$A$10:$N$2201,K$1-$J$1+2) -> 3.938 | L5: =VLOOKUP($H5,output!$A$10:$N$2201,L$1-$J$1+2) -> 3.923 | M5: =VLOOKUP($H5,output!$A$10:$N$2201,M$1-$J$1+2) -> 3.908 | N5: =VLOOKUP($H5,output!$A$10:$N$2201,N$1-$J$1+2) -> 3.915 | O5: =VLOOKUP($H5,output!$A$10:$N$2201,O$1-$J$1+2) -> 3.917 | P5: =VLOOKUP($H5,output!$A$10:$N$2201,P$1-$J$1+2) -> 3.915 | Q5: =VLOOKUP($H5,output!$A$10:$N$2201,Q$1-$J$1+2) -> 3.889 | ... V5: =VLOOKUP($H5,output!$A$10:$N$2201,V$1-$J$1+2) -> 3.901
I7: Directes | J7: =J3+J4 -> 30.064 | K7: =K3+K4 -> 28.641 | L7: =L3+L4 -> 27.757 | M7: =M3+M4 -> 26.318 | N7: =N3+N4 -> 24.397 | O7: =O3+O4 -> 22.831 | P7: =P3+P4 -> 21.19 | Q7: =Q3+Q4 -> 19.445 | ... V7: =V3+V4 -> 11.457 | W7: =V7/L7-1 -> -0.58723925
I8: Gain annuel | K8: =J7-K7 -> 1.423 | L8: =K7-L7 -> 0.884 | M8: =L7-M7 -> 1.439 | N8: =M7-N7 -> 1.921 | O8: =N7-O7 -> 1.566 | P8: =O7-P7 -> 1.641 | Q8: =P7-Q7 -> 1.745 | R8: =Q7-R7 -> 1.682 | ... V8: =U7-V7 -> 1.425
H13: Stock A (Million) | I13: A | J13: =VLOOKUP($H13,output!$A$10:$N$2201,J$1-$J$1+2) -> 0.397 | K13: =VLOOKUP($H13,output!$A$10:$N$2201,K$1-$J$1+2) -> 0.545 | L13: =VLOOKUP($H13,output!$A$10:$N$2201,L$1-$J$1+2) -> 0.757 | M13: =VLOOKUP($H13,output!$A$10:$N$2201,M$1-$J$1+2) -> 0.969 | N13: =VLOOKUP($H13,output!$A$10:$N$2201,N$1-$J$1+2) -> 1.182 | O13: =VLOOKUP($H13,output!$A$10:$N$2201,O$1-$J$1+2) -> 1.395 | P13: =VLOOKUP($H13,output!$A$10:$N$2201,P$1-$J$1+2) -> 1.606 | Q13: =VLOOKUP($H13,output!$A$10:$N$2201,Q$1-$J$1+2) -> 1.757 | ... V13: =VLOOKUP($H13,output!$A$10:$N$2201,V$1-$J$1+2) -> 2.549
H14: Stock B (Million) | I14: B | J14: =VLOOKUP($H14,output!$A$10:$N$2201,J$1-$J$1+2) -> 2.156 | K14: =VLOOKUP($H14,output!$A$10:$N$2201,K$1-$J$1+2) -> 2.435 | L14: =VLOOKUP($H14,output!$A$10:$N$2201,L$1-$J$1+2) -> 2.686 | M14: =VLOOKUP($H14,output!$A$10:$N$2201,M$1-$J$1+2) -> 2.947 | N14: =VLOOKUP($H14,output!$A$10:$N$2201,N$1-$J$1+2) -> 3.224 | O14: =VLOOKUP($H14,output!$A$10:$N$2201,O$1-$J$1+2) -> 3.519 | P14: =VLOOKUP($H14,output!$A$10:$N$2201,P$1-$J$1+2) -> 3.834 | Q14: =VLOOKUP($H14,output!$A$10:$N$2201,Q$1-$J$1+2) -> 4.141 | ... V14: =VLOOKUP($H14,output!$A$10:$N$2201,V$1-$J$1+2) -> 6.018
H15: Stock C (Million) | I15: C | J15: =VLOOKUP($H15,output!$A$10:$N$2201,J$1-$J$1+2) -> 5.55 | K15: =VLOOKUP($H15,output!$A$10:$N$2201,K$1-$J$1+2) -> 6.018 | L15: =VLOOKUP($H15,output!$A$10:$N$2201,L$1-$J$1+2) -> 6.359 | M15: =VLOOKUP($H15,output!$A$10:$N$2201,M$1-$J$1+2) -> 6.835 | N15: =VLOOKUP($H15,output!$A$10:$N$2201,N$1-$J$1+2) -> 7.326 | O15: =VLOOKUP($H15,output!$A$10:$N$2201,O$1-$J$1+2) -> 7.843 | P15: =VLOOKUP($H15,output!$A$10:$N$2201,P$1-$J$1+2) -> 8.377 | Q15: =VLOOKUP($H15,output!$A$10:$N$2201,Q$1-$J$1+2) -> 8.945 | ... V15: =VLOOKUP($H15,output!$A$10:$N$2201,V$1-$J$1+2) -> 11.615
H16: Stock D (Million) | I16: D | J16: =VLOOKUP($H16,output!$A$10:$N$2201,J$1-$J$1+2) -> 12.774 | K16: =VLOOKUP($H16,output!$A$10:$N$2201,K$1-$J$1+2) -> 12.688 | L16: =VLOOKUP($H16,output!$A$10:$N$2201,L$1-$J$1+2) -> 12.639 | M16: =VLOOKUP($H16,output!$A$10:$N$2201,M$1-$J$1+2) -> 12.527 | N16: =VLOOKUP($H16,output!$A$10:$N$2201,N$1-$J$1+2) -> 12.387 | O16: =VLOOKUP($H16,output!$A$10:$N$2201,O$1-$J$1+2) -> 12.168 | P16: =VLOOKUP($H16,output!$A$10:$N$2201,P$1-$J$1+2) -> 11.876 | Q16: =VLOOKUP($H16,output!$A$10:$N$2201,Q$1-$J$1+2) -> 11.562 | ... V16: =VLOOKUP($H16,output!$A$10:$N$2201,V$1-$J$1+2) -> 10.039
H17: Stock E (Million) | I17: E | J17: =VLOOKUP($H17,output!$A$10:$N$2201,J$1-$J$1+2) -> 5.024 | K17: =VLOOKUP($H17,output!$A$10:$N$2201,K$1-$J$1+2) -> 4.841 | L17: =VLOOKUP($H17,output!$A$10:$N$2201,L$1-$J$1+2) -> 4.647 | M17: =VLOOKUP($H17,output!$A$10:$N$2201,M$1-$J$1+2) -> 4.446 | N17: =VLOOKUP($H17,output!$A$10:$N$2201,N$1-$J$1+2) -> 4.229 | O17: =VLOOKUP($H17,output!$A$10:$N$2201,O$1-$J$1+2) -> 4.001 | P17: =VLOOKUP($H17,output!$A$10:$N$2201,P$1-$J$1+2) -> 3.77 | Q17: =VLOOKUP($H17,output!$A$10:$N$2201,Q$1-$J$1+2) -> 3.54 | ... V17: =VLOOKUP($H17,output!$A$10:$N$2201,V$1-$J$1+2) -> 1.723
H18: Stock F (Million) | I18: F | J18: =VLOOKUP($H18,output!$A$10:$N$2201,J$1-$J$1+2) -> 2.927 | K18: =VLOOKUP($H18,output!$A$10:$N$2201,K$1-$J$1+2) -> 2.755 | L18: =VLOOKUP($H18,output!$A$10:$N$2201,L$1-$J$1+2) -> 2.62 | M18: =VLOOKUP($H18,output!$A$10:$N$2201,M$1-$J$1+2) -> 2.385 | N18: =VLOOKUP($H18,output!$A$10:$N$2201,N$1-$J$1+2) -> 2.17 | O18: =VLOOKUP($H18,output!$A$10:$N$2201,O$1-$J$1+2) -> 1.984 | P18: =VLOOKUP($H18,output!$A$10:$N$2201,P$1-$J$1+2) -> 1.823 | Q18: =VLOOKUP($H18,output!$A$10:$N$2201,Q$1-$J$1+2) -> 1.613 | ... V18: =VLOOKUP($H18,output!$A$10:$N$2201,V$1-$J$1+2) -> 0.816
H19: Stock G (Million) | I19: G | J19: =VLOOKUP($H19,output!$A$10:$N$2201,J$1-$J$1+2) -> 1.398 | K19: =VLOOKUP($H19,output!$A$10:$N$2201,K$1-$J$1+2) -> 1.162 | L19: =VLOOKUP($H19,output!$A$10:$N$2201,L$1-$J$1+2) -> 1.006 | M19: =VLOOKUP($H19,output!$A$10:$N$2201,M$1-$J$1+2) -> 0.872 | N19: =VLOOKUP($H19,output!$A$10:$N$2201,N$1-$J$1+2) -> 0.729 | O19: =VLOOKUP($H19,output!$A$10:$N$2201,O$1-$J$1+2) -> 0.605 | P19: =VLOOKUP($H19,output!$A$10:$N$2201,P$1-$J$1+2) -> 0.497 | Q19: =VLOOKUP($H19,output!$A$10:$N$2201,Q$1-$J$1+2) -> 0.403 | ... V19: =VLOOKUP($H19,output!$A$10:$N$2201,V$1-$J$1+2) -> 0.089
I21: Passoires | J21: =J18+J19 -> 4.325 | K21: =K18+K19 -> 3.917 | L21: =L18+L19 -> 3.626 | M21: =M18+M19 -> 3.257 | N21: =N18+N19 -> 2.899 | O21: =O18+O19 -> 2.589 | P21: =P18+P19 -> 2.32 | Q21: =Q18+Q19 -> 2.016 | ... V21: =V18+V19 -> 0.905 | W21: =V21/N21-1 -> -0.68782339
H26: Consumption Heating (TWh) | I26: Chauffage urbain | J26: =VLOOKUP($H26,output!$A$10:$N$2201,J$1-$J$1+2) -> 11.458 | K26: =VLOOKUP($H26,output!$A$10:$N$2201,K$1-$J$1+2) -> 12.433 | L26: =VLOOKUP($H26,output!$A$10:$N$2201,L$1-$J$1+2) -> 12.517 | M26: =VLOOKUP($H26,output!$A$10:$N$2201,M$1-$J$1+2) -> 14.035 | N26: =VLOOKUP($H26,output!$A$10:$N$2201,N$1-$J$1+2) -> 15.012 | O26: =VLOOKUP($H26,output!$A$10:$N$2201,O$1-$J$1+2) -> 17.038 | P26: =VLOOKUP($H26,output!$A$10:$N$2201,P$1-$J$1+2) -> 20.233 | Q26: =VLOOKUP($H26,output!$A$10:$N$2201,Q$1-$J$1+2) -> 24.458 | ... V26: =VLOOKUP($H26,output!$A$10:$N$2201,V$1-$J$1+2) -> 37.128
H27: Consumption Natural gas (TWh) | I27: Gaz naturel | J27: =VLOOKUP($H27,output!$A$10:$N$2201,J$1-$J$1+2) -> 91 | K27: =VLOOKUP($H27,output!$A$10:$N$2201,K$1-$J$1+2) -> 89.097 | L27: =VLOOKUP($H27,output!$A$10:$N$2201,L$1-$J$1+2) -> 88.979 | M27: =VLOOKUP($H27,output!$A$10:$N$2201,M$1-$J$1+2) -> 86.764 | N27: =VLOOKUP($H27,output!$A$10:$N$2201,N$1-$J$1+2) -> 82.988 | O27: =VLOOKUP($H27,output!$A$10:$N$2201,O$1-$J$1+2) -> 79.972 | P27: =VLOOKUP($H27,output!$A$10:$N$2201,P$1-$J$1+2) -> 76.412 | Q27: =VLOOKUP($H27,output!$A$10:$N$2201,Q$1-$J$1+2) -> 72.209 | ... V27: =VLOOKUP($H27,output!$A$10:$N$2201,V$1-$J$1+2) -> 52.078
H28: Consumption Oil fuel (TWh) | I28: Fioul | J28: =VLOOKUP($H28,output!$A$10:$N$2201,J$1-$J$1+2) -> 31 | K28: =VLOOKUP($H28,output!$A$10:$N$2201,K$1-$J$1+2) -> 27.903 | L28: =VLOOKUP($H28,output!$A$10:$N$2201,L$1-$J$1+2) -> 25.252 | M28: =VLOOKUP($H28,output!$A$10:$N$2201,M$1-$J$1+2) -> 22.315 | N28: =VLOOKUP($H28,output!$A$10:$N$2201,N$1-$J$1+2) -> 18.951 | O28: =VLOOKUP($H28,output!$A$10:$N$2201,O$1-$J$1+2) -> 16.163 | P28: =VLOOKUP($H28,output!$A$10:$N$2201,P$1-$J$1+2) -> 13.514 | Q28: =VLOOKUP($H28,output!$A$10:$N$2201,Q$1-$J$1+2) -> 10.984 | ... V28: =VLOOKUP($H28,output!$A$10:$N$2201,V$1-$J$1+2) -> 0
H29: Consumption Wood fuel (TWh) | I29: Bois | J29: =VLOOKUP($H29,output!$A$10:$N$2201,J$1-$J$1+2) -> 76.103 | K29: =VLOOKUP($H29,output!$A$10:$N$2201,K$1-$J$1+2) -> 74.564 | L29: =VLOOKUP($H29,output!$A$10:$N$2201,L$1-$J$1+2) -> 73.541 | M29: =VLOOKUP($H29,output!$A$10:$N$2201,M$1-$J$1+2) -> 71.848 | N29: =VLOOKUP($H29,output!$A$10:$N$2201,N$1-$J$1+2) -> 69.645 | O29: =VLOOKUP($H29,output!$A$10:$N$2201,O$1-$J$1+2) -> 67.831 | P29: =VLOOKUP($H29,output!$A$10:$N$2201,P$1-$J$1+2) -> 65.93 | Q29: =VLOOKUP($H29,output!$A$10:$N$2201,Q$1-$J$1+2) -> 63.778 | ... V29: =VLOOKUP($H29,output!$A$10:$N$2201,V$1-$J$1+2) -> 53.952
H30: Consumption Heat pump (TWh) | I30: Electricité (pompe à chaleur) | J30: =VLOOKUP($H30,output!$A$10:$N$2201,J$1-$J$1+2) -> 6.984 | K30: =VLOOKUP($H30,output!$A$10:$N$2201,K$1-$J$1+2) -> 9.027 | L30: =VLOOKUP($H30,output!$A$10:$N$2201,L$1-$J$1+2) -> 10.851 | M30: =VLOOKUP($H30,output!$A$10:$N$2201,M$1-$J$1+2) -> 12.635 | N30: =VLOOKUP($H30,output!$A$10:$N$2201,N$1-$J$1+2) -> 14.589 | O30: =VLOOKUP($H30,output!$A$10:$N$2201,O$1-$J$1+2) -> 16.461 | P30: =VLOOKUP($H30,output!$A$10:$N$2201,P$1-$J$1+2) -> 18.247 | Q30: =VLOOKUP($H30,output!$A$10:$N$2201,Q$1-$J$1+2) -> 19.873 | ... V30: =VLOOKUP($H30,output!$A$10:$N$2201,V$1-$J$1+2) -> 28.732
H31: Consumption Direct electric (TWh) | I31: Electricité (joule) | J31: =VLOOKUP($H31,output!$A$10:$N$2201,J$1-$J$1+2) -> 43.913 | K31: =VLOOKUP($H31,output!$A$10:$N$2201,K$1-$J$1+2) -> 40.822 | L31: =VLOOKUP($H31,output!$A$10:$N$2201,L$1-$J$1+2) -> 38.813 | M31: =VLOOKUP($H31,output!$A$10:$N$2201,M$1-$J$1+2) -> 36.839 | N31: =VLOOKUP($H31,output!$A$10:$N$2201,N$1-$J$1+2) -> 34.963 | O31: =VLOOKUP($H31,output!$A$10:$N$2201,O$1-$J$1+2) -> 33.127 | P31: =VLOOKUP($H31,output!$A$10:$N$2201,P$1-$J$1+2) -> 31.307 | Q31: =VLOOKUP($H31,output!$A$10:$N$2201,Q$1-$J$1+2) -> 29.36 | ... V31: =VLOOKUP($H31,output!$A$10:$N$2201,V$1-$J$1+2) -> 20.646
I33: total | J33: =SUM(J26:J31) -> 260.458 | K33: =SUM(K26:K31) -> 253.846 | L33: =SUM(L26:L31) -> 249.953 | M33: =SUM(M26:M31) -> 244.436 | N33: =SUM(N26:N31) -> 236.148 | O33: =SUM(O26:O31) -> 230.592 | P33: =SUM(P26:P31) -> 225.643 | Q33: =SUM(Q26:Q31) -> 220.662 | ... V33: =SUM(V26:V31) -> 192.536
H37: Stock Direct electric (Million) | I37: Electricité (joule) | J37: =VLOOKUP($H37,output!$A$10:$N$2201,J$1-$J$1+2) -> 8.317 | K37: =VLOOKUP($H37,output!$A$10:$N$2201,K$1-$J$1+2) -> 8.012 | L37: =VLOOKUP($H37,output!$A$10:$N$2201,L$1-$J$1+2) -> 7.768 | M37: =VLOOKUP($H37,output!$A$10:$N$2201,M$1-$J$1+2) -> 7.499 | N37: =VLOOKUP($H37,output!$A$10:$N$2201,N$1-$J$1+2) -> 7.241 | O37: =VLOOKUP($H37,output!$A$10:$N$2201,O$1-$J$1+2) -> 6.964 | P37: =VLOOKUP($H37,output!$A$10:$N$2201,P$1-$J$1+2) -> 6.666 | Q37: =VLOOKUP($H37,output!$A$10:$N$2201,Q$1-$J$1+2) -> 6.332 | ... V37: =VLOOKUP($H37,output!$A$10:$N$2201,V$1-$J$1+2) -> 4.795
H38: Stock Heat pump (Million) | I38: Electricité (pompe à chaleur) | J38: =VLOOKUP($H38,output!$A$10:$N$2201,J$1-$J$1+2) -> 2.896 | K38: =VLOOKUP($H38,output!$A$10:$N$2201,K$1-$J$1+2) -> 3.642 | L38: =VLOOKUP($H38,output!$A$10:$N$2201,L$1-$J$1+2) -> 4.368 | M38: =VLOOKUP($H38,output!$A$10:$N$2201,M$1-$J$1+2) -> 5.054 | N38: =VLOOKUP($H38,output!$A$10:$N$2201,N$1-$J$1+2) -> 5.799 | O38: =VLOOKUP($H38,output!$A$10:$N$2201,O$1-$J$1+2) -> 6.511 | P38: =VLOOKUP($H38,output!$A$10:$N$2201,P$1-$J$1+2) -> 7.184 | Q38: =VLOOKUP($H38,output!$A$10:$N$2201,Q$1-$J$1+2) -> 7.756 | ... V38: =VLOOKUP($H38,output!$A$10:$N$2201,V$1-$J$1+2) -> 11.107
H39: Stock Oil fuel (Million) | I39: Fioul | J39: =VLOOKUP($H39,output!$A$10:$N$2201,J$1-$J$1+2) -> 3.049 | K39: =VLOOKUP($H39,output!$A$10:$N$2201,K$1-$J$1+2) -> 2.788 | L39: =VLOOKUP($H39,output!$A$10:$N$2201,L$1-$J$1+2) -> 2.528 | M39: =VLOOKUP($H39,output!$A$10:$N$2201,M$1-$J$1+2) -> 2.27 | N39: =VLOOKUP($H39,output!$A$10:$N$2201,N$1-$J$1+2) -> 2.013 | O39: =VLOOKUP($H39,output!$A$10:$N$2201,O$1-$J$1+2) -> 1.758 | P39: =VLOOKUP($H39,output!$A$10:$N$2201,P$1-$J$1+2) -> 1.504 | Q39: =VLOOKUP($H39,output!$A$10:$N$2201,Q$1-$J$1+2) -> 1.251 | ... V39: =VLOOKUP($H39,output!$A$10:$N$2201,V$1-$J$1+2) -> 0
H40: Stock Wood fuel (Million) | I40: Bois | J40: =VLOOKUP($H40,output!$A$10:$N$2201,J$1-$J$1+2) -> 2.733 | K40: =VLOOKUP($H40,output!$A$10:$N$2201,K$1-$J$1+2) -> 2.763 | L40: =VLOOKUP($H40,output!$A$10:$N$2201,L$1-$J$1+2) -> 2.782 | M40: =VLOOKUP($H40,output!$A$10:$N$2201,M$1-$J$1+2) -> 2.8 | N40: =VLOOKUP($H40,output!$A$10:$N$2201,N$1-$J$1+2) -> 2.82 | O40: =VLOOKUP($H40,output!$A$10:$N$2201,O$1-$J$1+2) -> 2.84 | P40: =VLOOKUP($H40,output!$A$10:$N$2201,P$1-$J$1+2) -> 2.86 | Q40: =VLOOKUP($H40,output!$A$10:$N$2201,Q$1-$J$1+2) -> 2.876 | ... V40: =VLOOKUP($H40,output!$A$10:$N$2201,V$1-$J$1+2) -> 2.962
H41: Stock Natural gas (Million) | I41: Gaz naturel | J41: =VLOOKUP($H41,output!$A$10:$N$2201,J$1-$J$1+2) -> 11.809 | K41: =VLOOKUP($H41,output!$A$10:$N$2201,K$1-$J$1+2) -> 11.674 | L41: =VLOOKUP($H41,output!$A$10:$N$2201,L$1-$J$1+2) -> 11.648 | M41: =VLOOKUP($H41,output!$A$10:$N$2201,M$1-$J$1+2) -> 11.49 | N41: =VLOOKUP($H41,output!$A$10:$N$2201,N$1-$J$1+2) -> 11.328 | O41: =VLOOKUP($H41,output!$A$10:$N$2201,O$1-$J$1+2) -> 11.067 | P41: =VLOOKUP($H41,output!$A$10:$N$2201,P$1-$J$1+2) -> 10.695 | Q41: =VLOOKUP($H41,output!$A$10:$N$2201,Q$1-$J$1+2) -> 10.223 | ... V41: =VLOOKUP($H41,output!$A$10:$N$2201,V$1-$J$1+2) -> 8.208
H42: Stock District heating (Million) | I42: Chauffage urbain | J42: =VLOOKUP($H42,output!$A$10:$N$2201,J$1-$J$1+2) -> 1.421 | K42: =VLOOKUP($H42,output!$A$10:$N$2201,K$1-$J$1+2) -> 1.565 | L42: =VLOOKUP($H42,output!$A$10:$N$2201,L$1-$J$1+2) -> 1.619 | M42: =VLOOKUP($H42,output!$A$10:$N$2201,M$1-$J$1+2) -> 1.868 | N42: =VLOOKUP($H42,output!$A$10:$N$2201,N$1-$J$1+2) -> 2.047 | O42: =VLOOKUP($H42,output!$A$10:$N$2201,O$1-$J$1+2) -> 2.375 | P42: =VLOOKUP($H42,output!$A$10:$N$2201,P$1-$J$1+2) -> 2.874 | Q42: =VLOOKUP($H42,output!$A$10:$N$2201,Q$1-$J$1+2) -> 3.522 | ... V42: =VLOOKUP($H42,output!$A$10:$N$2201,V$1-$J$1+2) -> 5.777
H48: Retrofit 6 EPC (Thousand households) | I48: 6 classes | J48: =VLOOKUP($H48,output!$A$10:$N$2201,J$1-$J$1+2) -> 0 | K48: =VLOOKUP($H48,output!$A$10:$N$2201,K$1-$J$1+2) -> 0.059 | L48: =VLOOKUP($H48,output!$A$10:$N$2201,L$1-$J$1+2) -> 0.014 | M48: =VLOOKUP($H48,output!$A$10:$N$2201,M$1-$J$1+2) -> 0.006 | N48: =VLOOKUP($H48,output!$A$10:$N$2201,N$1-$J$1+2) -> 0.003 | O48: =VLOOKUP($H48,output!$A$10:$N$2201,O$1-$J$1+2) -> 0.002 | P48: =VLOOKUP($H48,output!$A$10:$N$2201,P$1-$J$1+2) -> 0.002 | Q48: =VLOOKUP($H48,output!$A$10:$N$2201,Q$1-$J$1+2) -> 0.001 | ... V48: =VLOOKUP($H48,output!$A$10:$N$2201,V$1-$J$1+2) -> 0.001
H49: Retrofit 5 EPC (Thousand households) | I49: 5 classes | J49: =VLOOKUP($H49,output!$A$10:$N$2201,J$1-$J$1+2) -> 0 | K49: =VLOOKUP($H49,output!$A$10:$N$2201,K$1-$J$1+2) -> 0.773 | L49: =VLOOKUP($H49,output!$A$10:$N$2201,L$1-$J$1+2) -> 0.31 | M49: =VLOOKUP($H49,output!$A$10:$N$2201,M$1-$J$1+2) -> 0.241 | N49: =VLOOKUP($H49,output!$A$10:$N$2201,N$1-$J$1+2) -> 0.279 | O49: =VLOOKUP($H49,output!$A$10:$N$2201,O$1-$J$1+2) -> 0.23 | P49: =VLOOKUP($H49,output!$A$10:$N$2201,P$1-$J$1+2) -> 0.182 | Q49: =VLOOKUP($H49,output!$A$10:$N$2201,Q$1-$J$1+2) -> 0.16 | ... V49: =VLOOKUP($H49,output!$A$10:$N$2201,V$1-$J$1+2) -> 0.097
H50: Retrofit 4 EPC (Thousand households) | I50: 4 classes | J50: =VLOOKUP($H50,output!$A$10:$N$2201,J$1-$J$1+2) -> 0 | K50: =VLOOKUP($H50,output!$A$10:$N$2201,K$1-$J$1+2) -> 61.33 | L50: =VLOOKUP($H50,output!$A$10:$N$2201,L$1-$J$1+2) -> 40.121 | M50: =VLOOKUP($H50,output!$A$10:$N$2201,M$1-$J$1+2) -> 29.405 | N50: =VLOOKUP($H50,output!$A$10:$N$2201,N$1-$J$1+2) -> 29.237 | O50: =VLOOKUP($H50,output!$A$10:$N$2201,O$1-$J$1+2) -> 22.59 | P50: =VLOOKUP($H50,output!$A$10:$N$2201,P$1-$J$1+2) -> 17.083 | Q50: =VLOOKUP($H50,output!$A$10:$N$2201,Q$1-$J$1+2) -> 13.109 | ... V50: =VLOOKUP($H50,output!$A$10:$N$2201,V$1-$J$1+2) -> 6.189
H51: Retrofit 3 EPC (Thousand households) | I51: 3 classes | J51: =VLOOKUP($H51,output!$A$10:$N$2201,J$1-$J$1+2) -> 0 | K51: =VLOOKUP($H51,output!$A$10:$N$2201,K$1-$J$1+2) -> 251.615 | L51: =VLOOKUP($H51,output!$A$10:$N$2201,L$1-$J$1+2) -> 184.159 | M51: =VLOOKUP($H51,output!$A$10:$N$2201,M$1-$J$1+2) -> 210.072 | N51: =VLOOKUP($H51,output!$A$10:$N$2201,N$1-$J$1+2) -> 221.142 | O51: =VLOOKUP($H51,output!$A$10:$N$2201,O$1-$J$1+2) -> 192.734 | P51: =VLOOKUP($H51,output!$A$10:$N$2201,P$1-$J$1+2) -> 166.147 | Q51: =VLOOKUP($H51,output!$A$10:$N$2201,Q$1-$J$1+2) -> 168.647 | ... V51: =VLOOKUP($H51,output!$A$10:$N$2201,V$1-$J$1+2) -> 122.339
H52: Retrofit 2 EPC (Thousand households) | I52: 2 classes | J52: =VLOOKUP($H52,output!$A$10:$N$2201,J$1-$J$1+2) -> 0 | K52: =VLOOKUP($H52,output!$A$10:$N$2201,K$1-$J$1+2) -> 354.066 | L52: =VLOOKUP($H52,output!$A$10:$N$2201,L$1-$J$1+2) -> 275.016 | M52: =VLOOKUP($H52,output!$A$10:$N$2201,M$1-$J$1+2) -> 332.511 | N52: =VLOOKUP($H52,output!$A$10:$N$2201,N$1-$J$1+2) -> 348.665 | O52: =VLOOKUP($H52,output!$A$10:$N$2201,O$1-$J$1+2) -> 341.088 | P52: =VLOOKUP($H52,output!$A$10:$N$2201,P$1-$J$1+2) -> 331.271 | Q52: =VLOOKUP($H52,output!$A$10:$N$2201,Q$1-$J$1+2) -> 362.798 | ... V52: =VLOOKUP($H52,output!$A$10:$N$2201,V$1-$J$1+2) -> 408.51
H53: Retrofit 1 EPC (Thousand households) | I53: 1 classe | J53: =VLOOKUP($H53,output!$A$10:$N$2201,J$1-$J$1+2) -> 0 | K53: =VLOOKUP($H53,output!$A$10:$N$2201,K$1-$J$1+2) -> 385.953 | L53: =VLOOKUP($H53,output!$A$10:$N$2201,L$1-$J$1+2) -> 333.736 | M53: =VLOOKUP($H53,output!$A$10:$N$2201,M$1-$J$1+2) -> 470.83 | N53: =VLOOKUP($H53,output!$A$10:$N$2201,N$1-$J$1+2) -> 468.452 | O53: =VLOOKUP($H53,output!$A$10:$N$2201,O$1-$J$1+2) -> 549.61 | P53: =VLOOKUP($H53,output!$A$10:$N$2201,P$1-$J$1+2) -> 624.923 | Q53: =VLOOKUP($H53,output!$A$10:$N$2201,Q$1-$J$1+2) -> 694.254 | ... V53: =VLOOKUP($H53,output!$A$10:$N$2201,V$1-$J$1+2) -> 668.203
I55: Part réno 2+ | K55: =SUM(K48:K52)/SUM(K48:K53) -> 0.6337498 | L55: =SUM(L48:L52)/SUM(L48:L53) -> 0.59952769 | M55: =SUM(M48:M52)/SUM(M48:M53) -> 0.54860915 | N55: =SUM(N48:N52)/SUM(N48:N53) -> 0.56128334 | O55: =SUM(O48:O52)/SUM(O48:O53) -> 0.5031792 | P55: =SUM(P48:P52)/SUM(P48:P53) -> 0.45163337 | Q55: =SUM(Q48:Q52)/SUM(Q48:Q53) -> 0.43965184 | R55: =SUM(R48:R52)/SUM(R48:R53) -> 0.45119005 | ... V55: =SUM(V48:V52)/SUM(V48:V53) -> 0.44563065
I56: Part réno 3+ | K56: =SUM(K48:K51)/SUM(K48:K53) -> 0.29775877 | L56: =SUM(L48:L51)/SUM(L48:L53) -> 0.26951747 | M56: =SUM(M48:M51)/SUM(M48:M53) -> 0.22982652 | N56: =SUM(N48:N51)/SUM(N48:N53) -> 0.23475011 | O56: =SUM(O48:O51)/SUM(O48:O53) -> 0.19485218 | P56: =SUM(P48:P51)/SUM(P48:P53) -> 0.16094482 | Q56: =SUM(Q48:Q51)/SUM(Q48:Q53) -> 0.14682934 | R56: =SUM(R48:R51)/SUM(R48:R53) -> 0.13158012 | ... V56: =SUM(V48:V51)/SUM(V48:V53) -> 0.10671355
H60: Renovation Multi-family - Owner-occupied (Thousand households) | I60: PO en copropriété | J60: =VLOOKUP($H60,output!$A$10:$N$2201,J$1-$J$1+2) -> 0 | K60: =VLOOKUP($H60,output!$A$10:$N$2201,K$1-$J$1+2) -> 66.859 | L60: =VLOOKUP($H60,output!$A$10:$N$2201,L$1-$J$1+2) -> 51 | M60: =VLOOKUP($H60,output!$A$10:$N$2201,M$1-$J$1+2) -> 50.872 | N60: =VLOOKUP($H60,output!$A$10:$N$2201,N$1-$J$1+2) -> 55.295 | O60: =VLOOKUP($H60,output!$A$10:$N$2201,O$1-$J$1+2) -> 54.615 | P60: =VLOOKUP($H60,output!$A$10:$N$2201,P$1-$J$1+2) -> 53.884 | Q60: =VLOOKUP($H60,output!$A$10:$N$2201,Q$1-$J$1+2) -> 57.446 | ... V60: =VLOOKUP($H60,output!$A$10:$N$2201,V$1-$J$1+2) -> 54.485
H61: Renovation Multi-family - Privately rented (Thousand households) | I61: PB en copropriété | J61: =VLOOKUP($H61,output!$A$10:$N$2201,J$1-$J$1+2) -> 0 | K61: =VLOOKUP($H61,output!$A$10:$N$2201,K$1-$J$1+2) -> 75.746 | L61: =VLOOKUP($H61,output!$A$10:$N$2201,L$1-$J$1+2) -> 60.488 | M61: =VLOOKUP($H61,output!$A$10:$N$2201,M$1-$J$1+2) -> 89.875 | N61: =VLOOKUP($H61,output!$A$10:$N$2201,N$1-$J$1+2) -> 75.798 | O61: =VLOOKUP($H61,output!$A$10:$N$2201,O$1-$J$1+2) -> 64.472 | P61: =VLOOKUP($H61,output!$A$10:$N$2201,P$1-$J$1+2) -> 55.584 | Q61: =VLOOKUP($H61,output!$A$10:$N$2201,Q$1-$J$1+2) -> 48.606 | ... V61: =VLOOKUP($H61,output!$A$10:$N$2201,V$1-$J$1+2) -> 104.876
H62: Renovation Multi-family - Social-housing (Thousand households) | I62: PB social en copropriété | J62: =VLOOKUP($H62,output!$A$10:$N$2201,J$1-$J$1+2) -> 0 | K62: =VLOOKUP($H62,output!$A$10:$N$2201,K$1-$J$1+2) -> 15.24 | L62: =VLOOKUP($H62,output!$A$10:$N$2201,L$1-$J$1+2) -> 61.818 | M62: =VLOOKUP($H62,output!$A$10:$N$2201,M$1-$J$1+2) -> 139.633 | N62: =VLOOKUP($H62,output!$A$10:$N$2201,N$1-$J$1+2) -> 181.31 | O62: =VLOOKUP($H62,output!$A$10:$N$2201,O$1-$J$1+2) -> 224.567 | P62: =VLOOKUP($H62,output!$A$10:$N$2201,P$1-$J$1+2) -> 234.966 | Q62: =VLOOKUP($H62,output!$A$10:$N$2201,Q$1-$J$1+2) -> 238.434 | ... V62: =VLOOKUP($H62,output!$A$10:$N$2201,V$1-$J$1+2) -> 325.795
H63: Renovation Single-family - Owner-occupied (Thousand households) | I63: PO en maison | J63: =VLOOKUP($H63,output!$A$10:$N$2201,J$1-$J$1+2) -> 0 | K63: =VLOOKUP($H63,output!$A$10:$N$2201,K$1-$J$1+2) -> 373.908 | L63: =VLOOKUP($H63,output!$A$10:$N$2201,L$1-$J$1+2) -> 194.506 | M63: =VLOOKUP($H63,output!$A$10:$N$2201,M$1-$J$1+2) -> 207.952 | N63: =VLOOKUP($H63,output!$A$10:$N$2201,N$1-$J$1+2) -> 230.087 | O63: =VLOOKUP($H63,output!$A$10:$N$2201,O$1-$J$1+2) -> 222.751 | P63: =VLOOKUP($H63,output!$A$10:$N$2201,P$1-$J$1+2) -> 216.001 | Q63: =VLOOKUP($H63,output!$A$10:$N$2201,Q$1-$J$1+2) -> 266.178 | ... V63: =VLOOKUP($H63,output!$A$10:$N$2201,V$1-$J$1+2) -> 218.739
H64: Renovation Single-family - Privately rented (Thousand households) | I64: PB en maison | J64: =VLOOKUP($H64,output!$A$10:$N$2201,J$1-$J$1+2) -> 0 | K64: =VLOOKUP($H64,output!$A$10:$N$2201,K$1-$J$1+2) -> 54.747 | L64: =VLOOKUP($H64,output!$A$10:$N$2201,L$1-$J$1+2) -> 37.575 | M64: =VLOOKUP($H64,output!$A$10:$N$2201,M$1-$J$1+2) -> 88.86 | N64: =VLOOKUP($H64,output!$A$10:$N$2201,N$1-$J$1+2) -> 71.556 | O64: =VLOOKUP($H64,output!$A$10:$N$2201,O$1-$J$1+2) -> 57.828 | P64: =VLOOKUP($H64,output!$A$10:$N$2201,P$1-$J$1+2) -> 47.111 | Q64: =VLOOKUP($H64,output!$A$10:$N$2201,Q$1-$J$1+2) -> 38.75 | ... V64: =VLOOKUP($H64,output!$A$10:$N$2201,V$1-$J$1+2) -> 26.642
...

Sheet figures 2050
J1: 2018 | K1: 2019 | L1: 2020 | M1: 2021 | N1: 2022 | O1: 2023 | P1: 2024 | Q1: 2025 | R1: 2026 | S1: 2027 | T1: 2028 | U1: 2029 | V1: 2030 | W1: 2031 | X1: 2032 | Y1: 2033 | Z1: 2034 | AA1: 2035 | AB1: 2036 | AC1: 2037 | AD1: 2038 | AE1: 2039 | AF1: 2040 | AG1: 2041 | AH1: 2042 | AI1: 2043 | AJ1: 2044 | AK1: 2045 | AL1: 2046 | AM1: 2047 | AN1: 2048 | AO1: 2049 | AP1: 2050
H2: Emissions (calculées par le modèle)
H3: Emission Natural gas (MtCO2) | I3: Emissions du gaz (MtCO2) | J3: =VLOOKUP($H3,output!$A$10:$AH$2201,J$1-$J$1+2) -> 20.02 | K3: =VLOOKUP($H3,output!$A$10:$AH$2201,K$1-$J$1+2) -> 19.601 | L3: =VLOOKUP($H3,output!$A$10:$AH$2201,L$1-$J$1+2) -> 19.575 | M3: =VLOOKUP($H3,output!$A$10:$AH$2201,M$1-$J$1+2) -> 19.088 | N3: =VLOOKUP($H3,output!$A$10:$AH$2201,N$1-$J$1+2) -> 18.257 | O3: =VLOOKUP($H3,output!$A$10:$AH$2201,O$1-$J$1+2) -> 17.594 | P3: =VLOOKUP($H3,output!$A$10:$AH$2201,P$1-$J$1+2) -> 16.811 | Q3: =VLOOKUP($H3,output!$A$10:$AH$2201,Q$1-$J$1+2) -> 15.886 | ... AP3: =VLOOKUP($H3,output!$A$10:$AH$2201,AP$1-$J$1+2) -> 0
H4: Emission Oil fuel (MtCO2) | I4: Emissions du fioul (MtCO2) | J4: =VLOOKUP($H4,output!$A$10:$AH$2201,J$1-$J$1+2) -> 10.044 | K4: =VLOOKUP($H4,output!$A$10:$AH$2201,K$1-$J$1+2) -> 9.04 | L4: =VLOOKUP($H4,output!$A$10:$AH$2201,L$1-$J$1+2) -> 8.182 | M4: =VLOOKUP($H4,output!$A$10:$AH$2201,M$1-$J$1+2) -> 7.23 | N4: =VLOOKUP($H4,output!$A$10:$AH$2201,N$1-$J$1+2) -> 6.14 | O4: =VLOOKUP($H4,output!$A$10:$AH$2201,O$1-$J$1+2) -> 5.237 | P4: =VLOOKUP($H4,output!$A$10:$AH$2201,P$1-$J$1+2) -> 4.379 | Q4: =VLOOKUP($H4,output!$A$10:$AH$2201,Q$1-$J$1+2) -> 3.559 | ... AP4: =VLOOKUP($H4,output!$A$10:$AH$2201,AP$1-$J$1+2) -> 0
H5: Emission Electricity (MtCO2) | I5: Emissions de l'électricité (MtCO2) | J5: =VLOOKUP($H5,output!$A$10:$AH$2201,J$1-$J$1+2) -> 4.021 | K5: =VLOOKUP($H5,output!$A$10:$AH$2201,K$1-$J$1+2) -> 3.938 | L5: =VLOOKUP($H5,output!$A$10:$AH$2201,L$1-$J$1+2) -> 3.923 | M5: =VLOOKUP($H5,output!$A$10:$AH$2201,M$1-$J$1+2) -> 3.908 | N5: =VLOOKUP($H5,output!$A$10:$AH$2201,N$1-$J$1+2) -> 3.915 | O5: =VLOOKUP($H5,output!$A$10:$AH$2201,O$1-$J$1+2) -> 3.917 | P5: =VLOOKUP($H5,output!$A$10:$AH$2201,P$1-$J$1+2) -> 3.915 | Q5: =VLOOKUP($H5,output!$A$10:$AH$2201,Q$1-$J$1+2) -> 3.889 | ... AP5: =VLOOKUP($H5,output!$A$10:$AH$2201,AP$1-$J$1+2) -> 0
I7: Directes | J7: =J3+J4 -> 30.064 | K7: =K3+K4 -> 28.641 | L7: =L3+L4 -> 27.757 | M7: =M3+M4 -> 26.318 | N7: =N3+N4 -> 24.397 | O7: =O3+O4 -> 22.831 | P7: =P3+P4 -> 21.19 | Q7: =Q3+Q4 -> 19.445 | ... AP7: =AP3+AP4 -> 0
I8: Gain annuel | K8: =J7-K7 -> 1.423 | L8: =K7-L7 -> 0.884 | M8: =L7-M7 -> 1.439 | N8: =M7-N7 -> 1.921 | O8: =N7-O7 -> 1.566 | P8: =O7-P7 -> 1.641 | Q8: =P7-Q7 -> 1.745 | R8: =Q7-R7 -> 1.682 | ... AP8: =AO7-AP7 -> 0
H10: Hypothèse de sobriété (baisse température de consigne & individualisation frais en collectif) | J10: 1 | K10: 1 | L10: 1 | M10: 1 | N10: 1 | O10: 1 | P10: 0.99 | Q10: 0.98 | R10: 0.97 | S10: 0.96 | T10: 0.95 | U10: 0.94 | V10: 0.93 | W10: =$V10-0.03*(W1-$V1)/20 -> 0.9285 | X10: =$V10-0.03*(X1-$V1)/20 -> 0.927 | Y10: =$V10-0.03*(Y1-$V1)/20 -> 0.9255 | Z10: =$V10-0.03*(Z1-$V1)/20 -> 0.924 | AA10: =$V10-0.03*(AA1-$V1)/20 -> 0.9225 | AB10: =$V10-0.03*(AB1-$V1)/20 -> 0.921 | AC10: =$V10-0.03*(AC1-$V1)/20 -> 0.9195 | AD10: =$V10-0.03*(AD1-$V1)/20 -> 0.918 | ... AO10: =$V10-0.03*(AO1-$V1)/20 -> 0.9015 | AP10: 0.9
H11: Impact du changement climatique (RCP2.6) | J11: 1 | K11: 1 | L11: 1 | M11: 0.99 | N11: 0.98 | O11: 0.97 | P11: 0.96 | Q11: 0.95 | R11: 0.94 | S11: 0.93 | T11: 0.92 | U11: 0.915 | V11: 0.91 | W11: 0.9 | X11: 0.9 | Y11: 0.89 | Z11: 0.89 | AA11: 0.88 | AB11: 0.88 | AC11: 0.88 | AD11: 0.87 | AE11: 0.87 | AF11: 0.87 | AG11: 0.87 | AH11: 0.87 | AI11: 0.87 | AJ11: 0.865 | AK11: 0.865 | AL11: 0.865 | AM11: 0.865 | AN11: 0.86 | AO11: 0.86 | AP11: 0.86
H12: Variation de la demande induite | J12: =J10*J11 -> 1 | K12: =K10*K11 -> 1 | L12: =L10*L11 -> 1 | M12: =M10*M11 -> 0.99 | N12: =N10*N11 -> 0.98 | O12: =O10*O11 -> 0.97 | P12: =P10*P11 -> 0.9504 | Q12: =Q10*Q11 -> 0.931 | ... AP12: =AP10*AP11 -> 0.774
H14: Emissions (incluant sobriété et CC)
H15: Emissions du gaz (MtCO2) | J15: =J3*J$12 -> 20.02 | K15: =K3*K$12 -> 19.601 | L15: =L3*L$12 -> 19.575 | M15: =M3*M$12 -> 18.89712 | N15: =N3*N$12 -> 17.89186 | O15: =O3*O$12 -> 17.06618 | P15: =P3*P$12 -> 15.977174 | Q15: =Q3*Q$12 -> 14.789866 | ... AP15: =AP3*AP$12 -> 0
H16: Emissions du fioul (MtCO2) | J16: =J4*J$12 -> 10.044 | K16: =K4*K$12 -> 9.04 | L16: =L4*L$12 -> 8.182 | M16: =M4*M$12 -> 7.1577 | N16: =N4*N$12 -> 6.0172 | O16: =O4*O$12 -> 5.07989 | P16: =P4*P$12 -> 4.1618016 | Q16: =Q4*Q$12 -> 3.313429 | ... AP16: =AP4*AP$12 -> 0
H17: Emissions de l'électricité (MtCO2) | J17: =J5*J$12 -> 4.021 | K17: =K5*K$12 -> 3.938 | L17: =L5*L$12 -> 3.923 | M17: =M5*M$12 -> 3.86892 | N17: =N5*N$12 -> 3.8367 | O17: =O5*O$12 -> 3.79949 | P17: =P5*P$12 -> 3.720816 | Q17: =Q5*Q$12 -> 3.620659 | ... AP17: =AP5*AP$12 -> 0
I19: Directes | J19: =SUM(J15:J16) -> 30.064 | K19: =SUM(K15:K16) -> 28.641 | L19: =SUM(L15:L16) -> 27.757 | M19: =SUM(M15:M16) -> 26.05482 | N19: =SUM(N15:N16) -> 23.90906 | O19: =SUM(O15:O16) -> 22.14607 | P19: =SUM(P15:P16) -> 20.138976 | Q19: =SUM(Q15:Q16) -> 18.103295 | ... AP19: =SUM(AP15:AP16) -> 0
I20: Gain annuel | K20: =K19-J19 -> -1.423 | L20: =L19-K19 -> -0.884 | M20: =M19-L19 -> -1.70218 | N20: =N19-M19 -> -2.14576 | O20: =O19-N19 -> -1.76299 | P20: =P19-O19 -> -2.007094 | Q20: =Q19-P19 -> -2.035681 | R20: =R19-Q19 -> -1.9069916 | ... AP20: =AP19-AO19 -> 0
I21: Réduction vs 2019 | L21: =L19/$K19-1 -> -0.030864844 | M21: =M19/$K19-1 -> -0.090296428 | N21: =N19/$K19-1 -> -0.1652156 | O21: =O19/$K19-1 -> -0.22677036 | P21: =P19/$K19-1 -> -0.29684802 | Q21: =Q19/$K19-1 -> -0.36792378 | R21: =R19/$K19-1 -> -0.43450636 | S21: =S19/$K19-1 -> -0.50052951 | ... AP21: =AP19/$K19-1 -> -1
H23: Stock A (Million) | I23: A | J23: =VLOOKUP($H23,output!$A$10:$AH$2201,J$1-$J$1+2) -> 0.397 | K23: =VLOOKUP($H23,output!$A$10:$AH$2201,K$1-$J$1+2) -> 0.545 | L23: =VLOOKUP($H23,output!$A$10:$AH$2201,L$1-$J$1+2) -> 0.757 | M23: =VLOOKUP($H23,output!$A$10:$AH$2201,M$1-$J$1+2) -> 0.969 | N23: =VLOOKUP($H23,output!$A$10:$AH$2201,N$1-$J$1+2) -> 1.182 | O23: =VLOOKUP($H23,output!$A$10:$AH$2201,O$1-$J$1+2) -> 1.395 | P23: =VLOOKUP($H23,output!$A$10:$AH$2201,P$1-$J$1+2) -> 1.606 | Q23: =VLOOKUP($H23,output!$A$10:$AH$2201,Q$1-$J$1+2) -> 1.757 | ... AP23: =VLOOKUP($H23,output!$A$10:$AH$2201,AP$1-$J$1+2) -> 0
H24: Stock B (Million) | I24: B | J24: =VLOOKUP($H24,output!$A$10:$AH$2201,J$1-$J$1+2) -> 2.156 | K24: =VLOOKUP($H24,output!$A$10:$AH$2201,K$1-$J$1+2) -> 2.435 | L24: =VLOOKUP($H24,output!$A$10:$AH$2201,L$1-$J$1+2) -> 2.686 | M24: =VLOOKUP($H24,output!$A$10:$AH$2201,M$1-$J$1+2) -> 2.947 | N24: =VLOOKUP($H24,output!$A$10:$AH$2201,N$1-$J$1+2) -> 3.224 | O24: =VLOOKUP($H24,output!$A$10:$AH$2201,O$1-$J$1+2) -> 3.519 | P24: =VLOOKUP($H24,output!$A$10:$AH$2201,P$1-$J$1+2) -> 3.834 | Q24: =VLOOKUP($H24,output!$A$10:$AH$2201,Q$1-$J$1+2) -> 4.141 | ... AP24: =VLOOKUP($H24,output!$A$10:$AH$2201,AP$1-$J$1+2) -> 0
H25: Stock C (Million) | I25: C | J25: =VLOOKUP($H25,output!$A$10:$AH$2201,J$1-$J$1+2) -> 5.55 | K25: =VLOOKUP($H25,output!$A$10:$AH$2201,K$1-$J$1+2) -> 6.018 | L25: =VLOOKUP($H25,output!$A$10:$AH$2201,L$1-$J$1+2) -> 6.359 | M25: =VLOOKUP($H25,output!$A$10:$AH$2201,M$1-$J$1+2) -> 6.835 | N25: =VLOOKUP($H25,output!$A$10:$AH$2201,N$1-$J$1+2) -> 7.326 | O25: =VLOOKUP($H25,output!$A$10:$AH$2201,O$1-$J$1+2) -> 7.843 | P25: =VLOOKUP($H25,output!$A$10:$AH$2201,P$1-$J$1+2) -> 8.377 | Q25: =VLOOKUP($H25,output!$A$10:$AH$2201,Q$1-$J$1+2) -> 8.945 | ... AP25: =VLOOKUP($H25,output!$A$10:$AH$2201,AP$1-$J$1+2) -> 0
H26: Stock D (Million) | I26: D | J26: =VLOOKUP($H26,output!$A$10:$AH$2201,J$1-$J$1+2) -> 12.774 | K26: =VLOOKUP($H26,output!$A$10:$AH$2201,K$1-$J$1+2) -> 12.688 | L26: =VLOOKUP($H26,output!$A$10:$AH$2201,L$1-$J$1+2) -> 12.639 | M26: =VLOOKUP($H26,output!$A$10:$AH$2201,M$1-$J$1+2) -> 12.527 | N26: =VLOOKUP($H26,output!$A$10:$AH$2201,N$1-$J$1+2) -> 12.387 | O26: =VLOOKUP($H26,output!$A$10:$AH$2201,O$1-$J$1+2) -> 12.168 | P26: =VLOOKUP($H26,output!$A$10:$AH$2201,P$1-$J$1+2) -> 11.876 | Q26: =VLOOKUP($H26,output!$A$10:$AH$2201,Q$1-$J$1+2) -> 11.562 | ... AP26: =VLOOKUP($H26,output!$A$10:$AH$2201,AP$1-$J$1+2) -> 0
H27: Stock E (Million) | I27: E | J27: =VLOOKUP($H27,output!$A$10:$AH$2201,J$1-$J$1+2) -> 5.024 | K27: =VLOOKUP($H27,output!$A$10:$AH$2201,K$1-$J$1+2) -> 4.841 | L27: =VLOOKUP($H27,output!$A$10:$AH$2201,L$1-$J$1+2) -> 4.647 | M27: =VLOOKUP($H27,output!$A$10:$AH$2201,M$1-$J$1+2) -> 4.446 | N27: =VLOOKUP($H27,output!$A$10:$AH$2201,N$1-$J$1+2) -> 4.229 | O27: =VLOOKUP($H27,output!$A$10:$AH$2201,O$1-$J$1+2) -> 4.001 | P27: =VLOOKUP($H27,output!$A$10:$AH$2201,P$1-$J$1+2) -> 3.77 | Q27: =VLOOKUP($H27,output!$A$10:$AH$2201,Q$1-$J$1+2) -> 3.54 | ... AP27: =VLOOKUP($H27,output!$A$10:$AH$2201,AP$1-$J$1+2) -> 0
H28: Stock F (Million) | I28: F | J28: =VLOOKUP($H28,output!$A$10:$AH$2201,J$1-$J$1+2) -> 2.927 | K28: =VLOOKUP($H28,output!$A$10:$AH$2201,K$1-$J$1+2) -> 2.755 | L28: =VLOOKUP($H28,output!$A$10:$AH$2201,L$1-$J$1+2) -> 2.62 | M28: =VLOOKUP($H28,output!$A$10:$AH$2201,M$1-$J$1+2) -> 2.385 | N28: =VLOOKUP($H28,output!$A$10:$AH$2201,N$1-$J$1+2) -> 2.17 | O28: =VLOOKUP($H28,output!$A$10:$AH$2201,O$1-$J$1+2) -> 1.984 | P28: =VLOOKUP($H28,output!$A$10:$AH$2201,P$1-$J$1+2) -> 1.823 | Q28: =VLOOKUP($H28,output!$A$10:$AH$2201,Q$1-$J$1+2) -> 1.613 | ... AP28: =VLOOKUP($H28,output!$A$10:$AH$2201,AP$1-$J$1+2) -> 0
H29: Stock G (Million) | I29: G | J29: =VLOOKUP($H29,output!$A$10:$AH$2201,J$1-$J$1+2) -> 1.398 | K29: =VLOOKUP($H29,output!$A$10:$AH$2201,K$1-$J$1+2) -> 1.162 | L29: =VLOOKUP($H29,output!$A$10:$AH$2201,L$1-$J$1+2) -> 1.006 | M29: =VLOOKUP($H29,output!$A$10:$AH$2201,M$1-$J$1+2) -> 0.872 | N29: =VLOOKUP($H29,output!$A$10:$AH$2201,N$1-$J$1+2) -> 0.729 | O29: =VLOOKUP($H29,output!$A$10:$AH$2201,O$1-$J$1+2) -> 0.605 | P29: =VLOOKUP($H29,output!$A$10:$AH$2201,P$1-$J$1+2) -> 0.497 | Q29: =VLOOKUP($H29,output!$A$10:$AH$2201,Q$1-$J$1+2) -> 0.403 | ... AP29: =VLOOKUP($H29,output!$A$10:$AH$2201,AP$1-$J$1+2) -> 0
I31: Passoires | J31: =J28+J29 -> 4.325 | K31: =K28+K29 -> 3.917 | L31: =L28+L29 -> 3.626 | M31: =M28+M29 -> 3.257 | N31: =N28+N29 -> 2.899 | O31: =O28+O29 -> 2.589 | P31: =P28+P29 -> 2.32 | Q31: =Q28+Q29 -> 2.016 | ... V31: =V28+V29 -> 0.905 | W31: =V31/K31-1 -> -0.76895583
AA34: Fioul pour correction | AC34: =AC38*AC$12 -> 0 | AD34: =AD38*AD$12 -> 0 | AE34: =AE38*AE$12 -> 0 | AF34: =AF38*AF$12 -> 0 | AG34: =AG38*AG$12 -> 0 | AH34: =AH38*AH$12 -> 0 | AI34: =AI38*AI$12 -> 0 | AJ34: =AJ38*AJ$12 -> 0 | ... AP34: =AP38*AP$12 -> 0
H35: Consommation (calculée par le modèle)
H36: Consumption Heating (TWh) | I36: Chauffage urbain | J36: =VLOOKUP($H36,output!$A$10:$AH$2201,J$1-$J$1+2) -> 11.458 | K36: =VLOOKUP($H36,output!$A$10:$AH$2201,K$1-$J$1+2) -> 12.433 | L36: =VLOOKUP($H36,output!$A$10:$AH$2201,L$1-$J$1+2) -> 12.517 | M36: =VLOOKUP($H36,output!$A$10:$AH$2201,M$1-$J$1+2) -> 14.035 | N36: =VLOOKUP($H36,output!$A$10:$AH$2201,N$1-$J$1+2) -> 15.012 | O36: =VLOOKUP($H36,output!$A$10:$AH$2201,O$1-$J$1+2) -> 17.038 | P36: =VLOOKUP($H36,output!$A$10:$AH$2201,P$1-$J$1+2) -> 20.233 | Q36: =VLOOKUP($H36,output!$A$10:$AH$2201,Q$1-$J$1+2) -> 24.458 | ... AP36: =VLOOKUP($H36,output!$A$10:$AH$2201,AP$1-$J$1+2) -> 0 | AQ36: Chauffage urbain
H37: Consumption Natural gas (TWh) | I37: Gaz | J37: =VLOOKUP($H37,output!$A$10:$AH$2201,J$1-$J$1+2) -> 91 | K37: =VLOOKUP($H37,output!$A$10:$AH$2201,K$1-$J$1+2) -> 89.097 | L37: =VLOOKUP($H37,output!$A$10:$AH$2201,L$1-$J$1+2) -> 88.979 | M37: =VLOOKUP($H37,output!$A$10:$AH$2201,M$1-$J$1+2) -> 86.764 | N37: =VLOOKUP($H37,output!$A$10:$AH$2201,N$1-$J$1+2) -> 82.988 | O37: =VLOOKUP($H37,output!$A$10:$AH$2201,O$1-$J$1+2) -> 79.972 | P37: =VLOOKUP($H37,output!$A$10:$AH$2201,P$1-$J$1+2) -> 76.412 | Q37: =VLOOKUP($H37,output!$A$10:$AH$2201,Q$1-$J$1+2) -> 72.209 | ... AP37: =VLOOKUP($H37,output!$A$10:$AH$2201,AP$1-$J$1+2) -> 0 | AQ37: Gaz
H38: Consumption Oil fuel (TWh) | I38: Fioul | J38: =VLOOKUP($H38,output!$A$10:$AH$2201,J$1-$J$1+2) -> 31 | K38: =VLOOKUP($H38,output!$A$10:$AH$2201,K$1-$J$1+2) -> 27.903 | L38: =VLOOKUP($H38,output!$A$10:$AH$2201,L$1-$J$1+2) -> 25.252 | M38: =VLOOKUP($H38,output!$A$10:$AH$2201,M$1-$J$1+2) -> 22.315 | N38: =VLOOKUP($H38,output!$A$10:$AH$2201,N$1-$J$1+2) -> 18.951 | O38: =VLOOKUP($H38,output!$A$10:$AH$2201,O$1-$J$1+2) -> 16.163 | P38: =VLOOKUP($H38,output!$A$10:$AH$2201,P$1-$J$1+2) -> 13.514 | Q38: =VLOOKUP($H38,output!$A$10:$AH$2201,Q$1-$J$1+2) -> 10.984 | ... AP38: =VLOOKUP($H38,output!$A$10:$AH$2201,AP$1-$J$1+2) -> 0 | AQ38: Fioul
H39: Consumption Wood fuel (TWh) | I39: Bois | J39: =VLOOKUP($H39,output!$A$10:$AH$2201,J$1-$J$1+2) -> 76.103 | K39: =VLOOKUP($H39,output!$A$10:$AH$2201,K$1-$J$1+2) -> 74.564 | L39: =VLOOKUP($H39,output!$A$10:$AH$2201,L$1-$J$1+2) -> 73.541 | M39: =VLOOKUP($H39,output!$A$10:$AH$2201,M$1-$J$1+2) -> 71.848 | N39: =VLOOKUP($H39,output!$A$10:$AH$2201,N$1-$J$1+2) -> 69.645 | O39: =VLOOKUP($H39,output!$A$10:$AH$2201,O$1-$J$1+2) -> 67.831 | P39: =VLOOKUP($H39,output!$A$10:$AH$2201,P$1-$J$1+2) -> 65.93 | Q39: =VLOOKUP($H39,output!$A$10:$AH$2201,Q$1-$J$1+2) -> 63.778 | ... AP39: =VLOOKUP($H39,output!$A$10:$AH$2201,AP$1-$J$1+2) -> 0 | AQ39: Bois
H40: Consumption Heat pump (TWh) | I40: Electricité (pompe à chaleur) | J40: =VLOOKUP($H40,output!$A$10:$AH$2201,J$1-$J$1+2) -> 6.984 | K40: =VLOOKUP($H40,output!$A$10:$AH$2201,K$1-$J$1+2) -> 9.027 | L40: =VLOOKUP($H40,output!$A$10:$AH$2201,L$1-$J$1+2) -> 10.851 | M40: =VLOOKUP($H40,output!$A$10:$AH$2201,M$1-$J$1+2) -> 12.635 | N40: =VLOOKUP($H40,output!$A$10:$AH$2201,N$1-$J$1+2) -> 14.589 | O40: =VLOOKUP($H40,output!$A$10:$AH$2201,O$1-$J$1+2) -> 16.461 | P40: =VLOOKUP($H40,output!$A$10:$AH$2201,P$1-$J$1+2) -> 18.247 | Q40: =VLOOKUP($H40,output!$A$10:$AH$2201,Q$1-$J$1+2) -> 19.873 | ... AP40: =VLOOKUP($H40,output!$A$10:$AH$2201,AP$1-$J$1+2) -> 0 | AQ40: Electricité (pompe à chaleur)
H41: Consumption Direct electric (TWh) | I41: Electricité (joule) | J41: =VLOOKUP($H41,output!$A$10:$AH$2201,J$1-$J$1+2) -> 43.913 | K41: =VLOOKUP($H41,output!$A$10:$AH$2201,K$1-$J$1+2) -> 40.822 | L41: =VLOOKUP($H41,output!$A$10:$AH$2201,L$1-$J$1+2) -> 38.813 | M41: =VLOOKUP($H41,output!$A$10:$AH$2201,M$1-$J$1+2) -> 36.839 | N41: =VLOOKUP($H41,output!$A$10:$AH$2201,N$1-$J$1+2) -> 34.963 | O41: =VLOOKUP($H41,output!$A$10:$AH$2201,O$1-$J$1+2) -> 33.127 | P41: =VLOOKUP($H41,output!$A$10:$AH$2201,P$1-$J$1+2) -> 31.307 | Q41: =VLOOKUP($H41,output!$A$10:$AH$2201,Q$1-$J$1+2) -> 29.36 | ... AP41: =VLOOKUP($H41,output!$A$10:$AH$2201,AP$1-$J$1+2) -> 0 | AQ41: Electricité (joule)
I43: total | J43: =SUM(J36:J41) -> 260.458 | K43: =SUM(K36:K41) -> 253.846 | L43: =SUM(L36:L41) -> 249.953 | M43: =SUM(M36:M41) -> 244.436 | N43: =SUM(N36:N41) -> 236.148 | O43: =SUM(O36:O41) -> 230.592 | P43: =SUM(P36:P41) -> 225.643 | Q43: =SUM(Q36:Q41) -> 220.662 | ... AP43: =SUM(AP36:AP41) -> 0
H44: Consommation (incluant sobriété et CC)
H45: Chauffage urbain | J45: =J36*J$12 -> 11.458 | K45: =K36*K$12 -> 12.433 | L45: =L36*L$12 -> 12.517 | M45: =M36*M$12 -> 13.89465 | N45: =N36*N$12 -> 14.71176 | O45: =O36*O$12 -> 16.52686 | P45: =P36*P$12 -> 19.229443 | Q45: =Q36*Q$12 -> 22.770398 | ... AP45: =AP36*AP$12 -> 0 | AQ45: Chauffage urbain
H46: Gaz | J46: =J37*J$12 -> 91 | K46: =K37*K$12 -> 89.097 | L46: =L37*L$12 -> 88.979 | M46: =M37*M$12 -> 85.89636 | N46: =N37*N$12 -> 81.32824 | O46: =O37*O$12 -> 77.57284 | P46: =P37*P$12 -> 72.621965 | Q46: =Q37*Q$12 -> 67.226579 | ... AP46: =AP37*AP$12 -> 0 | AQ46: Gaz
H47: Fioul | J47: =J38*J$12 -> 31 | K47: =K38*K$12 -> 27.903 | L47: =L38*L$12 -> 25.252 | M47: =M38*M$12 -> 22.09185 | N47: =N38*N$12 -> 18.57198 | O47: =O38*O$12 -> 15.67811 | P47: =P38*P$12 -> 12.843706 | Q47: =Q38*Q$12 -> 10.226104 | ... AC47: =AC38*AC$12 -> 0 | AD47: 1 | AE47: 0.5 | AF47: 0 | AG47: 0 | AH47: 0 | AI47: 0 | AJ47: 0 | AK47: 0 | AL47: 0 | AM47: 0 | AN47: 0 | AO47: 0 | AP47: 0 | AQ47: Fioul
H48: Bois | J48: =J39*J$12 -> 76.103 | K48: =K39*K$12 -> 74.564 | L48: =L39*L$12 -> 73.541 | M48: =M39*M$12 -> 71.12952 | N48: =N39*N$12 -> 68.2521 | O48: =O39*O$12 -> 65.79607 | P48: =P39*P$12 -> 62.659872 | Q48: =Q39*Q$12 -> 59.377318 | ... AP48: =AP39*AP$12 -> 0 | AQ48: Bois
H49: Electricité (pompe à chaleur) | J49: =J40*J$12 -> 6.984 | K49: =K40*K$12 -> 9.027 | L49: =L40*L$12 -> 10.851 | M49: =M40*M$12 -> 12.50865 | N49: =N40*N$12 -> 14.29722 | O49: =O40*O$12 -> 15.96717 | P49: =P40*P$12 -> 17.341949 | Q49: =Q40*Q$12 -> 18.501763 | ... AC49: =AC40*AC$12 -> 30.235073 | AD49: =AD40*AD$12+(AD34-AD47)/3 -> 30.214613 | AE49: =AE40*AE$12+(AE34-AE47)/3 -> 30.660672 | AF49: =AF40*AF$12+(AF34-AF47)/3 -> 31.073812 | AG49: =AG40*AG$12+(AG34-AG47)/3 -> 31.378917 | AH49: =AH40*AH$12+(AH34-AH47)/3 -> 31.606682 | AI49: =AI40*AI$12+(AI34-AI47)/3 -> 31.827984 | AJ49: =AJ40*AJ$12+(AJ34-AJ47)/3 -> 31.862627 | AK49: =AK40*AK$12+(AK34-AK47)/3 -> 32.065954 | ... AP49: =AP40*AP$12+(AP34-AP47)/3 -> 0 | AQ49: Electricité (pompe à chaleur)
...

Sheet Post traitement FE
A1: Taux de biogaz
B3: 2023 | C3: 2024 | D3: 2025 | E3: 2026 | F3: 2027 | G3: 2028 | H3: 2029 | I3: 2030 | J3: 2031 | K3: 2032 | L3: 2033 | M3: 2034 | N3: 2035 | O3: 2036 | P3: 2037 | Q3: 2038 | R3: 2039 | S3: 2040 | T3: 2041 | U3: 2042 | V3: 2043 | W3: 2044 | X3: 2045 | Y3: 2046 | Z3: 2047 | AA3: 2048 | AB3: 2049 | AC3: 2050 | AD3: 2045 | AE3: 2046 | AF3: 2047 | AG3: 2048 | AH3: 2049 | AI3: 2050
A4: Emission content Natural gas (gCO2/kWh) | B4: =VLOOKUP($A4,output!$A$9:$AI$2200,B$3-$B$3+2) -> 220 | C4: =VLOOKUP($A4,output!$A$9:$AI$2200,C$3-$B$3+2) -> 220 | D4: =VLOOKUP($A4,output!$A$9:$AI$2200,D$3-$B$3+2) -> 220 | E4: =VLOOKUP($A4,output!$A$9:$AI$2200,E$3-$B$3+2) -> 220 | F4: =VLOOKUP($A4,output!$A$9:$AI$2200,F$3-$B$3+2) -> 220 | G4: =VLOOKUP($A4,output!$A$9:$AI$2200,G$3-$B$3+2) -> 220 | H4: =VLOOKUP($A4,output!$A$9:$AI$2200,H$3-$B$3+2) -> 220 | I4: =VLOOKUP($A4,output!$A$9:$AI$2200,I$3-$B$3+2) -> 220 | ... AI4: =VLOOKUP($A4,output!$A$9:$AI$2200,AI$3-$B$3+2) -> 220
A5: Consumption Natural gas (TWh) | B5: =VLOOKUP($A5,output!$A$9:$AI$2200,B$3-$B$3+2) -> 91 | C5: =VLOOKUP($A5,output!$A$9:$AI$2200,C$3-$B$3+2) -> 89.097 | D5: =VLOOKUP($A5,output!$A$9:$AI$2200,D$3-$B$3+2) -> 88.979 | E5: =VLOOKUP($A5,output!$A$9:$AI$2200,E$3-$B$3+2) -> 86.764 | F5: =VLOOKUP($A5,output!$A$9:$AI$2200,F$3-$B$3+2) -> 82.988 | G5: =VLOOKUP($A5,output!$A$9:$AI$2200,G$3-$B$3+2) -> 79.972 | H5: =VLOOKUP($A5,output!$A$9:$AI$2200,H$3-$B$3+2) -> 76.412 | I5: =VLOOKUP($A5,output!$A$9:$AI$2200,I$3-$B$3+2) -> 72.209 | ... AI5: =VLOOKUP($A5,output!$A$9:$AI$2200,AI$3-$B$3+2) -> 18.159
A7: Recalcul FE Gaz | B7: 220.0992 | C7: 217.8746 | D7: 215.65 | E7: 211.11 | F7: 206.57 | G7: 202.03 | H7: 197.49 | I7: 192.95 | J7: 187.502 | K7: 182.054 | L7: 176.606 | M7: 171.158 | N7: 165.71 | O7: 157.538 | P7: 149.366 | Q7: 141.194 | R7: 133.022 | S7: 124.85 | T7: 117.586 | U7: 110.322 | V7: 103.058 | W7: 95.794 | X7: 88.53 | Y7: 70.824 | Z7: 53.118 | AA7: 35.412 | AB7: 17.706 | AC7: 0 | AD7: 88.53 | AE7: 70.824 | AF7: 53.118 | AG7: 35.412 | AH7: 17.706 | AI7: 0
A9: Emissions Gaz | B9: =B5*B7/1000 -> 20.029027 | C9: =C5*C7/1000 -> 19.411973 | D9: =D5*D7/1000 -> 19.188321 | E9: =E5*E7/1000 -> 18.316748 | F9: =F5*F7/1000 -> 17.142831 | G9: =G5*G7/1000 -> 16.156743 | H9: =H5*H7/1000 -> 15.090606 | I9: =I5*I7/1000 -> 13.932727 | ... AI9: =AI5*AI7/1000 -> 0

Sheet Parc et émission
J1: 2023 | K1: 2024 | L1: 2025 | M1: 2026 | N1: 2027 | O1: 2028 | P1: 2029 | Q1: 2030 | R1: 2031 | S1: 2032 | T1: 2033 | U1: 2034 | V1: 2035 | W1: 2036 | X1: 2037 | Y1: 2038 | Z1: 2039 | AA1: 2040 | AB1: 2041 | AC1: 2042 | AD1: 2043 | AE1: 2044 | AF1: 2045 | AG1: 2046 | AH1: 2047 | AI1: 2048 | AJ1: 2049 | AK1: 2050
H2: Emissions (calculées par le modèle)
H3: Emission Natural gas (MtCO2) | I3: Emissions du gaz (MtCO2) | J3: ='Post traitement FE'!B9 -> 20.029027 | K3: ='Post traitement FE'!C9 -> 19.411973 | L3: ='Post traitement FE'!D9 -> 19.188321 | M3: ='Post traitement FE'!E9 -> 18.316748 | N3: ='Post traitement FE'!F9 -> 17.142831 | O3: ='Post traitement FE'!G9 -> 16.156743 | P3: ='Post traitement FE'!H9 -> 15.090606 | Q3: ='Post traitement FE'!I9 -> 13.932727 | ... AK3: ='Post traitement FE'!AC9 -> 0
H4: Emission Oil fuel (MtCO2) | I4: Emissions du fioul (MtCO2) | J4: =VLOOKUP($H4,output!$A$9:$AI$2200,J$1-$J$1+2) -> 10.044 | K4: =VLOOKUP($H4,output!$A$9:$AI$2200,K$1-$J$1+2) -> 9.04 | L4: =VLOOKUP($H4,output!$A$9:$AI$2200,L$1-$J$1+2) -> 8.182 | M4: =VLOOKUP($H4,output!$A$9:$AI$2200,M$1-$J$1+2) -> 7.23 | N4: =VLOOKUP($H4,output!$A$9:$AI$2200,N$1-$J$1+2) -> 6.14 | O4: =VLOOKUP($H4,output!$A$9:$AI$2200,O$1-$J$1+2) -> 5.237 | P4: =VLOOKUP($H4,output!$A$9:$AI$2200,P$1-$J$1+2) -> 4.379 | Q4: =VLOOKUP($H4,output!$A$9:$AI$2200,Q$1-$J$1+2) -> 3.559 | ... AK4: =VLOOKUP($H4,output!$A$9:$AI$2200,AK$1-$J$1+2) -> 0
H5: Emission Electricity (MtCO2) | I5: Emissions de l'électricité (MtCO2) | J5: =VLOOKUP($H5,output!$A$9:$AI$2200,J$1-$J$1+2) -> 4.021 | K5: =VLOOKUP($H5,output!$A$9:$AI$2200,K$1-$J$1+2) -> 3.938 | L5: =VLOOKUP($H5,output!$A$9:$AI$2200,L$1-$J$1+2) -> 3.923 | M5: =VLOOKUP($H5,output!$A$9:$AI$2200,M$1-$J$1+2) -> 3.908 | N5: =VLOOKUP($H5,output!$A$9:$AI$2200,N$1-$J$1+2) -> 3.915 | O5: =VLOOKUP($H5,output!$A$9:$AI$2200,O$1-$J$1+2) -> 3.917 | P5: =VLOOKUP($H5,output!$A$9:$AI$2200,P$1-$J$1+2) -> 3.915 | Q5: =VLOOKUP($H5,output!$A$9:$AI$2200,Q$1-$J$1+2) -> 3.889 | ... AK5: =VLOOKUP($H5,output!$A$9:$AI$2200,AK$1-$J$1+2) -> 3.74
I7: Directes | J7: =J3+J4 -> 30.073027 | K7: =K3+K4 -> 28.451973 | L7: =L3+L4 -> 27.370321 | M7: =M3+M4 -> 25.546748 | N7: =N3+N4 -> 23.282831 | O7: =O3+O4 -> 21.393743 | P7: =P3+P4 -> 19.469606 | Q7: =Q3+Q4 -> 17.491727 | ... AK7: =AK3+AK4 -> 0
I8: Gain annuel | K8: =K7-L7 -> 1.0816519 | L8: =L7-M7 -> 1.8235733 | M8: =M7-N7 -> 2.2639169 | N8: =N7-O7 -> 1.889088 | O8: =O7-P7 -> 1.9241373 | P8: =P7-Q7 -> 1.9778793 | Q8: =Q7-R7 -> 1.9455901 | R8: =R7-S7 -> 1.9423734 | ... AJ8: =AJ7-AK7 -> 0.34462958 | AK8: =AK7-#REF! -> #REF!
H10: Année historique de sobriété : on estime que 2/3 du chemin est fait entre 2020 et 2023
H11: Hyp sobriété | I11: Economie d'énergie (2030/2020) | L11: 0.07
I12: Economie d'énergie (2050/2030) | L12: 0.03
I13: Chemin parcouru en 2023 | L13: =2/3 -> 0.66666667 | P13: Par rapport à 2023
H14: Hypothèse de sobriété (baisse température de consigne & individualisation frais en collectif) | J14: 1 | K14: =J14-(1-$L$13)*$L$11*1/7 -> 0.99666667 | L14: =K14-(1-$L$13)*$L$11*1/7 -> 0.99333333 | M14: =L14-(1-$L$13)*$L$11*1/7 -> 0.99 | N14: =M14-(1-$L$13)*$L$11*1/7 -> 0.98666667 | O14: =N14-(1-$L$13)*$L$11*1/7 -> 0.98333333 | P14: =O14-(1-$L$13)*$L$11*1/7 -> 0.98 | Q14: =P14-(1-$L$13)*$L$11*1/7 -> 0.97666667 | R14: =Q14+($AK$14-$Q$14)/20 -> 0.97516667 | S14: =R14+($AK$14-$Q$14)/20 -> 0.97366667 | T14: =S14+($AK$14-$Q$14)/20 -> 0.97216667 | U14: =T14+($AK$14-$Q$14)/20 -> 0.97066667 | V14: =U14+($AK$14-$Q$14)/20 -> 0.96916667 | W14: =V14+($AK$14-$Q$14)/20 -> 0.96766667 | X14: =W14+($AK$14-$Q$14)/20 -> 0.96616667 | Y14: =X14+($AK$14-$Q$14)/20 -> 0.96466667 | ... AJ14: =AI14+($AK$14-$Q$14)/20 -> 0.94816667 | AK14: =Q14-L12 -> 0.94666667
H15: Impact du changement climatique (RCP2.6) | J15: 0.97 | K15: 0.96 | L15: 0.95 | M15: 0.94 | N15: 0.93 | O15: 0.92 | P15: 0.91 | Q15: =100%-10% -> 0.9 | R15: =Q15+($AK$15-$Q$15)/20 -> 0.8975 | S15: =R15+($AK$15-$Q$15)/20 -> 0.895 | T15: =S15+($AK$15-$Q$15)/20 -> 0.8925 | U15: =T15+($AK$15-$Q$15)/20 -> 0.89 | V15: =U15+($AK$15-$Q$15)/20 -> 0.8875 | W15: =V15+($AK$15-$Q$15)/20 -> 0.885 | X15: =W15+($AK$15-$Q$15)/20 -> 0.8825 | Y15: =X15+($AK$15-$Q$15)/20 -> 0.88 | ... AJ15: =AI15+($AK$15-$Q$15)/20 -> 0.8525 | AK15: =100%-15% -> 0.85
H16: Variation de la demande induite | J16: =J14*J15 -> 0.97 | K16: =K14*K15 -> 0.9568 | L16: =L14*L15 -> 0.94366667 | M16: =M14*M15 -> 0.9306 | N16: =N14*N15 -> 0.9176 | O16: =O14*O15 -> 0.90466667 | P16: =P14*P15 -> 0.8918 | Q16: =Q14*Q15 -> 0.879 | ... AK16: =AK14*AK15 -> 0.80466667
H18: Emissions (incluant CC)
H19: Emissions du gaz (MtCO2) | J19: =J3*J$16 -> 19.428156 | K19: =K3*K$16 -> 18.573376 | L19: =L3*L$16 -> 18.107379 | M19: =M3*M$16 -> 17.045566 | N19: =N3*N$16 -> 15.730262 | O19: =O3*O$16 -> 14.616467 | P19: =P3*P$16 -> 13.457802 | Q19: =Q3*Q$16 -> 12.246867 | ... AK19: =AK3*AK$16 -> 0
H20: Emissions du fioul (MtCO2) | J20: =J4*J$16 -> 9.74268 | K20: =K4*K$16 -> 8.649472 | L20: =L4*L$16 -> 7.7210807 | M20: =M4*M$16 -> 6.728238 | N20: =N4*N$16 -> 5.634064 | O20: =O4*O$16 -> 4.7377393 | P20: =P4*P$16 -> 3.9051922 | Q20: =Q4*Q$16 -> 3.128361 | ... AK20: =AK4*AK$16 -> 0
H21: Emissions de l'électricité (MtCO2) | J21: =J5*J$16 -> 3.90037 | K21: =K5*K$16 -> 3.7678784 | L21: =L5*L$16 -> 3.7020043 | M21: =M5*M$16 -> 3.6367848 | N21: =N5*N$16 -> 3.592404 | O21: =O5*O$16 -> 3.5435793 | P21: =P5*P$16 -> 3.491397 | Q21: =Q5*Q$16 -> 3.418431 | ... AK21: =AK5*AK$16 -> 3.0094533
H23: Directes | J23: =SUM(J19:J20) -> 29.170836 | K23: =SUM(K19:K20) -> 27.222848 | L23: =SUM(L19:L20) -> 25.82846 | M23: =SUM(M19:M20) -> 23.773804 | N23: =SUM(N19:N20) -> 21.364326 | O23: =SUM(O19:O20) -> 19.354206 | P23: =SUM(P19:P20) -> 17.362995 | Q23: =SUM(Q19:Q20) -> 15.375228 | ... AK23: =SUM(AK19:AK20) -> 0
H24: Gain annuel | K24: =K23-J23 -> -1.9479884 | L24: =L23-K23 -> -1.3943881 | M24: =M23-L23 -> -2.0546562 | N24: =N23-M23 -> -2.4094779 | O24: =O23-N23 -> -2.0101196 | P24: =P23-O23 -> -1.9912118 | Q24: =Q23-P23 -> -1.9877669 | R24: =R23-Q23 -> -1.7690612 | ... AK24: =AK23-AJ23 -> -0.27856826
H25: Réduction vs 2019 | L25: =L23/$K23-1 -> -0.051221242 | M25: =M23/$K23-1 -> -0.12669667 | N25: =N23/$K23-1 -> -0.21520607 | O25: =O23/$K23-1 -> -0.2890455 | P25: =P23/$K23-1 -> -0.36219037 | Q25: =Q23/$K23-1 -> -0.4352087 | R25: =R23/$K23-1 -> -0.50019313 | S25: =S23/$K23-1 -> -0.5645294 | ... AK25: =AK23/$K23-1 -> -1
H27: Parc DPE
