Workbook

Sheet Feuil1
A1: Interdiction de gaz en 2027, avec compensation RCU et PAC mais pas à 50/50 en 2040 car trop de RCU
A2: Le reste sur du joule

Sheet Tableau de bord
B2: 1. Conformité au décret tertiaire
E4: Bureaux | F4: Café Hôtels Restaurants | G4: Commerce | H4: Enseignement | I4: Habitat communautaire | J4: Santé social | K4: Sport Loisir Culture | L4: Transport | M4: Total | O4: Commentaire (AME 24)
C6: Surface du parc (milliers de m²) | E6: 261321 | F6: 76051 | G6: 247482 | H6: 224459 | I6: 72135 | J6: 138496 | K6: 73203 | L6: 31290 | M6: =SUM(E6:L6) -> 1124437 | O6: Màj à partir de l'étude d'impact DHUP (2023) pour l'AME 24
C8: Part Etat | E8: 0.1 | F8: 0 | G8: 0 | H8: 0.07 | I8: 0 | J8: 0.6 | K8: 0.06 | L8: 0.5 | M8: =SUMPRODUCT(E$6:L$6,E8:L8)/M$6 -> 0.12893476 | O8: Etude d'impact DHUP (avant 2023) utilisée pour l'AMS run 2 (voir onglet source)
C9: Part collectivités | E9: 0.1 | F9: 0 | G9: 0 | H9: 0.72 | I9: 0.1 | J9: 0.08 | K9: 0.85 | L9: 0 | M9: =SUMPRODUCT(E$6:L$6,E9:L9)/M$6 -> 0.23857122
C10: Part Privé | E10: 0.8 | F10: 1 | G10: 1 | H10: 0.21 | I10: 0.9 | J10: 0.32 | K10: 0.09 | L10: 0.5 | M10: =SUMPRODUCT(E$6:L$6,E10:L10)/M$6 -> 0.63249402 | Q10: Proportion du parc qui applique la trajectoire décret tertiaire
C12: Surfaces > 1000m² | E12: 0.76 | F12: 0.61 | G12: 0.74 | H12: 0.92 | I12: 0.85 | J12: 0.83 | K12: 0.77 | L12: 0.86 | M12: =SUMPRODUCT(E$6:L$6,E12:L12)/M$6 -> 0.79522123 | O12: Màj à partir de l'étude d'impact DHUP (2023) pour l'AME 24 (voir onglet source) | Q12: Ademe | R12: S2 | S12: S3 | T12: S4
C13: Surfaces > 500m² | E13: =MIN(100%, E12+0.175) -> 0.935 | F13: =MIN(100%, F12+0.175) -> 0.785 | G13: =MIN(100%, G12+0.175) -> 0.915 | H13: =MIN(100%, H12+0.175) -> 1 | I13: 0.9 | J13: =MIN(100%, J12+0.175) -> 1 | K13: =MIN(100%, K12+0.175) -> 0.945 | L13: =MIN(100%, L12+0.175) -> 1 | M13: =SUMPRODUCT(E$6:L$6,E13:L13)/M$6 -> 0.94164861 | O13: Hyp AMS run 2 : +17,5% pour les surfaces > 500m²
Q14: Bureaux | R14: 0.65 | S14: 0.65 | T14: 0.55
B15: AME | C15: Part de la surface assujettie qui applique les objectifs du décret tertiaire | D15: Etat | E15: 0.6 | F15: 0.6 | G15: 0.6 | H15: 0.6 | I15: 0.6 | J15: 0.6 | K15: 0.6 | L15: 0.6 | M15: =SUMPRODUCT(E$6:L$6,E15:L15)/M$6 -> 0.6 | O15: L'Analyse du taux de complétion d'Operat au 04/01/2024 de la DHUP estime un taux de complétion de 53% pour les branches. Si on considère qu'en AME, ce taux peut monter à 60% (sans relance de la DHUP pour inciter les inscriptions sur Operat), que 10% utilisent des dérogations type bâtiments historiques, on tombe à 50%. Sachant qu'une part des bâtiments hors Operat pourrait respecter la trajectoire DEET (proportion probablement faible) et qu'une part inscrite sur Operat ne respectera pas le DEET en AME. | Q15: Cafés-hôtels-restaurants | R15: 0.66 | S15: 0.66 | T15: 0.55
D16: Collectivités | E16: 0.5 | F16: 0.5 | G16: 0.5 | H16: 0.5 | I16: 0.5 | J16: 0.5 | K16: 0.5 | L16: 0.5 | M16: =SUMPRODUCT(E$6:L$6,E16:L16)/M$6 -> 0.5 | Q16: Commerce | R16: 0.52 | S16: 0.52 | T16: 0.42
D17: Privé | E17: 0.45 | F17: 0.45 | G17: 0.45 | H17: 0.45 | I17: 0.45 | J17: 0.45 | K17: 0.45 | L17: 0.45 | M17: =SUMPRODUCT(E$6:L$6,E17:L17)/M$6 -> 0.45 | Q17: Enseignement-recherche | R17: 0.85 | S17: 0.85 | T17: 0.75
Q18: Habitat communautaire | R18: 0.78 | S18: 0.78 | T18: 0.68
B19: AMS | C19: Part de la surface assujettie qui applique les objectifs du décret tertiaire | D19: Etat | E19: 1 | F19: 1 | G19: 1 | H19: 1 | I19: 1 | J19: 1 | K19: 1 | L19: 1 | M19: =SUMPRODUCT(E$6:L$6,E19:L19)/M$6 -> 1 | Q19: Santé | R19: 0.99 | S19: 0.99 | T19: 0.89
D20: Collectivités | E20: 0.95 | F20: 0.95 | G20: 0.95 | H20: 0.95 | I20: 0.95 | J20: 0.95 | K20: 0.95 | L20: 0.95 | M20: =SUMPRODUCT(E$6:L$6,E20:L20)/M$6 -> 0.95 | Q20: Sport, Loisirs, Culture | R20: 0.59 | S20: 0.59 | T20: 0.49
D21: Privé | E21: 0.9 | F21: 0.9 | G21: 0.9 | H21: 0.9 | I21: 0.9 | J21: 0.9 | K21: 0.9 | L21: 0.9 | M21: =SUMPRODUCT(E$6:L$6,E21:L21)/M$6 -> 0.9 | Q21: Transport | R21: 0.78 | S21: 0.58 | T21: 0.58
Q22: TOTAL | R22: 0.7085533 | S22: 0.71522963 | T22: 0.61947514
B24: AME | C24: Proportion du parc assujetti qui applique la trajectoire décret tertiaire | D24: Total | E24: =E8*E15+E9*E16+E10*E17 -> 0.47 | F24: =F8*F15+F9*F16+F10*F17 -> 0.45 | G24: =G8*G15+G9*G16+G10*G17 -> 0.45 | H24: =H8*H15+H9*H16+H10*H17 -> 0.4965 | I24: =I8*I15+I9*I16+I10*I17 -> 0.455 | J24: =J8*J15+J9*J16+J10*J17 -> 0.544 | K24: =K8*K15+K9*K16+K10*K17 -> 0.5015 | L24: =L8*L15+L9*L16+L10*L17 -> 0.525 | M24: =SUMPRODUCT(E$6:L$6,E24:L24)/M$6 -> 0.48126877
B25: AMS | D25: Total | E25: =E8*E19+E9*E20+E10*E21 -> 0.915 | F25: =F8*F19+F9*F20+F10*F21 -> 0.9 | G25: =G8*G19+G9*G20+G10*G21 -> 0.9 | H25: =H8*H19+H9*H20+H10*H21 -> 0.943 | I25: =I8*I19+I9*I20+I10*I21 -> 0.905 | J25: =J8*J19+J9*J20+J10*J21 -> 0.964 | K25: =K8*K19+K9*K20+K10*K21 -> 0.9485 | L25: =L8*L19+L9*L20+L10*L21 -> 0.95 | M25: =SUMPRODUCT(E$6:L$6,E25:L25)/M$6 -> 0.92482204
B27: AME | C27: Proportion du parc qui applique la trajectoire décret tertiaire | D27: Total | E27: =E12*E24 -> 0.3572 | F27: =F12*F24 -> 0.2745 | G27: =G12*G24 -> 0.333 | H27: =H12*H24 -> 0.45678 | I27: =I12*I24 -> 0.38675 | J27: =J12*J24 -> 0.45152 | K27: =K12*K24 -> 0.386155 | L27: =L12*L24 -> 0.4515 | M27: =SUMPRODUCT(E$6:L$6,E27:L27)/M$6 -> 0.38418054
B28: AMS | D28: Total | E28: =E13*E25 -> 0.855525 | F28: =F13*F25 -> 0.7065 | G28: =G13*G25 -> 0.8235 | H28: =H13*H25 -> 0.943 | I28: =I13*I25 -> 0.8145 | J28: =J13*J25 -> 0.964 | K28: =K13*K25 -> 0.8963325 | L28: =L13*L25 -> 0.95 | M28: =SUMPRODUCT(E$6:L$6,E28:L28)/M$6 -> 0.87187346
B31: 2. Gain énergétique en 2030 pour le parc qui respecte le décret tertiaire
A32: 2030 | P32: 2040 | AE32: 2050
B33: AMS run 3 | E33: Part du parc | F33: Gain en terme de consommation énergétique par m² en 2030 | G33: Commentaire | P33: 0.5 | AE33: 0.6
A34: BUREAUX | B34: Parc assujetti atteignant les valeurs absolues aujourd'hui | E34: 0.5 | F34: 0.2 | G34: Basé sur les VA publiées, au vu des données déclarées sur OPERAT. La diminution de conso vient de la tendance observée 2010-2020 au vu des données CEREN et OPERAT ; on suppose qu'ils ne font plus rien ensuite car ils ont déjà atteint les objectifs
B35: Parc visant la valeur absolue | E35: 0.25 | F35: 0.33 | G35: Basé sur les VA publiées, au vu des données déclarées sur OPERAT. On suppose qu'ils ont déjà fait 20% entre 2010 et 2020, et refont 10% sur la décennie suivante. Ceux-là choisissent la VA car au global c'est plus facile que la VR (40%)
B36: Parc visant la valeur relative | E36: 0.25 | F36: 0.45 | G36: Le reste
B37: Total | E37: =SUM(E34:E36) -> 1 | F37: {=MMULT(TRANSPOSE(E34:E36),F34:F36)} -> 0.295 | G37: Gain énergétique de plus en 2030 par rapport à 2010 pour les bureaux
A38: AUTRES BRANCHES | B38: Parc assujetti atteignant les valeurs absolues aujourd'hui | E38: 0.25 | F38: 0.2 | G38: Basé sur les VA publiées, au vu des données déclarées sur OPERAT. La diminution de conso vient de la tendance observée 2010-2020 au vu des données CEREN et OPERAT ; on suppose qu'ils ne font plus rien ensuite car ils ont déjà atteint les objectifs
B39: Parc visant la valeur absolue | E39: 0.25 | F39: 0.33 | G39: Basé sur les VA publiées, au vu des données déclarées sur OPERAT. On suppose qu'ils ont déjà fait 20% entre 2010 et 2020, et refont 10% sur la décennie suivante. Ceux-là choisissent la VA car au global c'est plus facile que la VR (40%)
B40: Parc visant la valeur relative | E40: 0.5 | F40: 0.45 | G40: Le reste
B41: Total | E41: =SUM(E38:E40) -> 1 | F41: {=MMULT(TRANSPOSE(E38:E40),F38:F40)} -> 0.3575 | G41: Gain énergétique de plus en 2030 par rapport à 2010 pour les autres branches
B44: Remarque 1 : L'année de référence est à choisir après 2010 pour respecter le décret tertiaire. La baisse relative affichée s'entend ici par rapport à 2020. On considère donc qu'une partie du parc a déjà fait les travaux (ligne "parc assujetti atteignant les valeurs absolues aujourd'hui")
B45: Remarque 2 : Pour 2040 et 2050, on applique directement les valeurs relatives de -50% en -60% en prévision de valeurs absolues ambitieuses et en absence de données pertinentes.
A47: 2030 | P47: 2040 | AE47: 2050
B48: AME 24 | E48: Part du parc | F48: Gain en termes de consommation énergétique par m² en 2030/2010 | G48: Commentaire | Q48: AME 24 | T48: Part du parc | U48: Gain en termes de consommation énergétique par m² en 2040/2010 | V48: Commentaire | AF48: AME 24 | AI48: Part du parc | AJ48: Gain en termes de consommation énergétique par m² en 2050/2010 | AK48: Commentaire
A49: BUREAUX | B49: Parc assujetti atteignant les valeurs absolues aujourd'hui | E49: 0.5 | F49: 0.2 | G49: Basé sur les VA publiées, au vu des données déclarées sur OPERAT. La diminution de conso vient de la tendance observée 2010-2020 au vu des données CEREN et OPERAT ; on suppose qu'ils ne font plus rien ensuite car ils ont déjà atteint les objectifs | P49: BUREAUX | Q49: Parc assujetti atteignant les valeurs absolues aujourd'hui | T49: 0.25 | U49: 0.3 | V49: On suppose que les VA sont réhaussées pour être ajustées sur les 25% les plus performants. Les valeurs devraient diminuer de l'ordre de 10% supplémentaire | AE49: BUREAUX | AF49: Parc assujetti atteignant les valeurs absolues aujourd'hui | AI49: 0.25 | AJ49: 0.4 | AK49: On suppose que les VA sont réhaussées pour être ajustées sur les 25% les plus performants. Les valeurs devraient diminuer de l'ordre de 10% supplémentaire
B50: Parc visant la valeur absolue | E50: 0.25 | F50: 0.3 | G50: Basé sur les VA publiées, au vu des données déclarées sur OPERAT. On suppose qu'ils ont déjà fait 20% entre 2010 et 2020, et refont 10% sur la décennie suivante. Ceux-là choisissent la VA car au global c'est plus facile que la VR (40%) | Q50: Parc visant la valeur absolue | T50: 0.25 | U50: 0.4 | AF50: Parc visant la valeur absolue | AI50: 0.25 | AJ50: 0.5
B51: Parc visant la valeur relative | E51: 0.25 | F51: 0.4 | G51: Le reste | Q51: Parc visant la valeur relative | T51: 0.5 | U51: 0.5 | AF51: Parc visant la valeur relative | AI51: 0.5 | AJ51: 0.6
B52: Total | E52: =SUM(E49:E51) -> 1 | F52: {=MMULT(TRANSPOSE(E49:E51),F49:F51)} -> 0.275 | G52: Gain énergétique de plus en 2030 par rapport à 2010 pour les bureaux | Q52: Total | T52: =SUM(T49:T51) -> 1 | U52: {=MMULT(TRANSPOSE(T49:T51),U49:U51)} -> 0.425 | V52: Gain énergétique de plus en 2040 par rapport à 2010 pour les bureaux | AF52: Total | AI52: =SUM(AI49:AI51) -> 1 | AJ52: {=MMULT(TRANSPOSE(AI49:AI51),AJ49:AJ51)} -> 0.525 | AK52: Gain énergétique de plus en 2050 par rapport à 2010 pour les bureaux
...

Sheet Résultats
A1: Scénario AME | P1: Scénario AMS
A3: Consommation totale | P3: Consommation totale
B7: Surface chauffée - Scénario AME [thousand sq m] | Y7: Surface chauffée - Scénario AMS [thousand sq m]
A8: Catégorie | C8: 2020 | D8: 2030 | E8: 2040 | F8: 2050 | X8: Catégorie | Z8: 2020 | AA8: 2030 | AB8: 2040 | AC8: 2050
A9: Bureaux | B9: Neuf post 2020 | C9: ='Bureaux - AME'!H8 -> 0 | D9: ='Bureaux - AME'!I8 -> 6206.4099 | E9: ='Bureaux - AME'!J8 -> 6411.8445 | F9: ='Bureaux - AME'!K8 -> 5961.6497 | X9: Bureaux | Y9: Neuf post 2020 | Z9: ='Bureaux - AMS'!H8 -> 0 | AA9: ='Bureaux - AMS'!I8 -> 6206.4099 | AB9: ='Bureaux - AMS'!J8 -> 5920.8739 | AC9: ='Bureaux - AMS'!K8 -> 5623.8459
B10: Existant 2020 | C10: ='Bureaux - AME'!H9 -> 287333.79 | D10: ='Bureaux - AME'!I9 -> 269335.76 | E10: ='Bureaux - AME'!J9 -> 269590.46 | F10: ='Bureaux - AME'!K9 -> 263785.02 | Y10: Existant 2020 | Z10: ='Bureaux - AMS'!H9 -> 287333.79 | AA10: ='Bureaux - AMS'!I9 -> 267908.12 | AB10: ='Bureaux - AMS'!J9 -> 254442.36 | AC10: ='Bureaux - AMS'!K9 -> 233249.46
A11: Café Hôtels Restaurants | B11: Neuf post 2020 | C11: ='CaHoREs - AME'!H8 -> 0 | D11: ='CaHoREs - AME'!I8 -> 4554.2951 | E11: ='CaHoREs - AME'!J8 -> 3048.0727 | F11: ='CaHoREs - AME'!K8 -> 2041.8509 | X11: Café Hôtels Restaurants | Y11: Neuf post 2020 | Z11: ='CaHoREs - AMS'!H8 -> 0 | AA11: ='CaHoREs - AMS'!I8 -> 4192.3289 | AB11: ='CaHoREs - AMS'!J8 -> 2902.3742 | AC11: ='CaHoREs - AMS'!K8 -> 2027.5304
B12: Existant 2020 | C12: ='CaHoREs - AME'!H9 -> 67243.869 | D12: ='CaHoREs - AME'!I9 -> 65307.246 | E12: ='CaHoREs - AME'!J9 -> 67849.529 | F12: ='CaHoREs - AME'!K9 -> 68171.331 | Y12: Existant 2020 | Z12: ='CaHoREs - AMS'!H9 -> 67243.869 | AA12: ='CaHoREs - AMS'!I9 -> 65307.246 | AB12: ='CaHoREs - AMS'!J9 -> 67497.987 | AC12: ='CaHoREs - AMS'!K9 -> 66866.719
A13: Commerce | B13: Neuf post 2020 | C13: ='Commerce - AME'!H8 -> 0 | D13: ='Commerce - AME'!I8 -> 13164.331 | E13: ='Commerce - AME'!J8 -> 8969.5375 | F13: ='Commerce - AME'!K8 -> 8772.0507 | X13: Commerce | Y13: Neuf post 2020 | Z13: ='Commerce - AMS'!H8 -> 0 | AA13: ='Commerce - AMS'!I8 -> 12185.885 | AB13: ='Commerce - AMS'!J8 -> 8717.0415 | AC13: ='Commerce - AMS'!K8 -> 8710.528
B14: Existant 2020 | C14: ='Commerce - AME'!H9 -> 184229.65 | D14: ='Commerce - AME'!I9 -> 175681.39 | E14: ='Commerce - AME'!J9 -> 180083.28 | F14: ='Commerce - AME'!K9 -> 175887.23 | Y14: Existant 2020 | Z14: ='Commerce - AMS'!H9 -> 184229.65 | AA14: ='Commerce - AMS'!I9 -> 175681.39 | AB14: ='Commerce - AMS'!J9 -> 179009.85 | AC14: ='Commerce - AMS'!K9 -> 172479.99
A15: Enseignement | B15: Neuf post 2020 | C15: ='Enseignement - AME'!H8 -> 0 | D15: ='Enseignement - AME'!I8 -> 5840.7077 | E15: ='Enseignement - AME'!J8 -> 3412.3997 | F15: ='Enseignement - AME'!K8 -> 3380.7737 | X15: Enseignement | Y15: Neuf post 2020 | Z15: ='Enseignement - AMS'!H8 -> 0 | AA15: ='Enseignement - AMS'!I8 -> 4962.0556 | AB15: ='Enseignement - AMS'!J8 -> 3394.7194 | AC15: ='Enseignement - AMS'!K8 -> 3357.0627
B16: Existant 2020 | C16: ='Enseignement - AME'!H9 -> 167106.71 | D16: ='Enseignement - AME'!I9 -> 163744.18 | E16: ='Enseignement - AME'!J9 -> 164600.78 | F16: ='Enseignement - AME'!K9 -> 158963.24 | Y16: Existant 2020 | Z16: ='Enseignement - AMS'!H9 -> 167106.71 | AA16: ='Enseignement - AMS'!I9 -> 163744.18 | AB16: ='Enseignement - AMS'!J9 -> 163440.1 | AC16: ='Enseignement - AMS'!K9 -> 155937.37
A17: Santé social | B17: Neuf post 2020 | C17: ='Santé social - AME'!H8 -> 0 | D17: ='Santé social - AME'!I8 -> 22460.451 | E17: ='Santé social - AME'!J8 -> 19028.378 | F17: ='Santé social - AME'!K8 -> 14323.903 | X17: Santé social | Y17: Neuf post 2020 | Z17: ='Santé social - AMS'!H8 -> 0 | AA17: ='Santé social - AMS'!I8 -> 21439.618 | AB17: ='Santé social - AMS'!J8 -> 18543.246 | AC17: ='Santé social - AMS'!K8 -> 11635.794
B18: Existant 2020 | C18: ='Santé social - AME'!H9 -> 179200 | D18: ='Santé social - AME'!I9 -> 174566.15 | E18: ='Santé social - AME'!J9 -> 191931.78 | F18: ='Santé social - AME'!K9 -> 205505.03 | Y18: Existant 2020 | Z18: ='Santé social - AMS'!H9 -> 179200 | AA18: ='Santé social - AMS'!I9 -> 174566.15 | AB18: ='Santé social - AMS'!J9 -> 190937.34 | AC18: ='Santé social - AMS'!K9 -> 204063.73
A19: Sport Loisir Culture | B19: Neuf post 2020 | C19: ='Sport Loisir Culture - AME'!H8 -> 0 | D19: ='Sport Loisir Culture - AME'!I8 -> 3336.8292 | E19: ='Sport Loisir Culture - AME'!J8 -> 2051.9847 | F19: ='Sport Loisir Culture - AME'!K8 -> 1198.8501 | X19: Sport Loisir Culture | Y19: Neuf post 2020 | Z19: ='Sport Loisir Culture - AMS'!H8 -> 0 | AA19: ='Sport Loisir Culture - AMS'!I8 -> 3032.6507 | AB19: ='Sport Loisir Culture - AMS'!J8 -> 1932.1865 | AC19: ='Sport Loisir Culture - AMS'!K8 -> 1190.4419
B20: Existant 2020 | C20: ='Sport Loisir Culture - AME'!H9 -> 56508.434 | D20: ='Sport Loisir Culture - AME'!I9 -> 55371.367 | E20: ='Sport Loisir Culture - AME'!J9 -> 57526.866 | F20: ='Sport Loisir Culture - AME'!K9 -> 57804.848 | Y20: Existant 2020 | Z20: ='Sport Loisir Culture - AMS'!H9 -> 56508.434 | AA20: ='Sport Loisir Culture - AMS'!I9 -> 55371.367 | AB20: ='Sport Loisir Culture - AMS'!J9 -> 57228.808 | AC20: ='Sport Loisir Culture - AMS'!K9 -> 56704.89
A21: Transport | B21: Neuf post 2020 | C21: ='Transport - AME'!H8 -> 0 | D21: ='Transport - AME'!I8 -> 2714.9401 | E21: ='Transport - AME'!J8 -> 1773.7602 | F21: ='Transport - AME'!K8 -> 1146.2522 | X21: Transport | Y21: Neuf post 2020 | Z21: ='Transport - AMS'!H8 -> 0 | AA21: ='Transport - AMS'!I8 -> 2489.8568 | AB21: ='Transport - AMS'!J8 -> 1683.79 | AC21: ='Transport - AMS'!K8 -> 1138.213
B22: Existant 2020 | C22: ='Transport - AME'!H9 -> 41814.604 | D22: ='Transport - AME'!I9 -> 40727.425 | E22: ='Transport - AME'!J9 -> 42312.863 | F22: ='Transport - AME'!K9 -> 42514.775 | Y22: Existant 2020 | Z22: ='Transport - AMS'!H9 -> 41814.604 | AA22: ='Transport - AMS'!I9 -> 40727.425 | AB22: ='Transport - AMS'!J9 -> 42093.632 | AC22: ='Transport - AMS'!K9 -> 41702.656
A23: Total | B23: Neuf post 2020 | C23: =C9+C11+C13+C15+C17+C19+C21 -> 0 | D23: =D9+D11+D13+D15+D17+D19+D21 -> 58277.964 | E23: =E9+E11+E13+E15+E17+E19+E21 -> 44695.977 | F23: =F9+F11+F13+F15+F17+F19+F21 -> 36825.33 | X23: Total | Y23: Neuf post 2020 | Z23: =Z9+Z11+Z13+Z15+Z17+Z19+Z21 -> 0 | AA23: =AA9+AA11+AA13+AA15+AA17+AA19+AA21 -> 54508.805 | AB23: =AB9+AB11+AB13+AB15+AB17+AB19+AB21 -> 43094.231 | AC23: =AC9+AC11+AC13+AC15+AC17+AC19+AC21 -> 33683.416
B24: Existant 2020 | C24: =C10+C12+C14+C16+C18+C20+C22 -> 983437.06 | D24: =D10+D12+D14+D16+D18+D20+D22 -> 944733.51 | E24: =E10+E12+E14+E16+E18+E20+E22 -> 973895.55 | F24: =F10+F12+F14+F16+F18+F20+F22 -> 972631.48 | Y24: Existant 2020 | Z24: =Z10+Z12+Z14+Z16+Z18+Z20+Z22 -> 983437.06 | AA24: =AA10+AA12+AA14+AA16+AA18+AA20+AA22 -> 943305.87 | AB24: =AB10+AB12+AB14+AB16+AB18+AB20+AB22 -> 954650.08 | AC24: =AC10+AC12+AC14+AC16+AC18+AC20+AC22 -> 931004.81
AA25: =AA24*0.4/7 -> 53903.193 | AC25: =AC24*0.3/10 -> 27930.144
A27: Consommation totale en GWh AME | X27: Consommation totale en GWh AMS
A28: Usage | B28: 2020 | C28: 2030 | D28: 2040 | E28: 2050 | X28: Usage | Y28: 2020 | Z28: 2030 | AA28: 2040 | AB28: 2050
A29: Chauffage | B29: =B64 -> 100997.67 | C29: =C64 -> 82779.177 | D29: =D64 -> 75656.355 | E29: =E64 -> 66876.448 | X29: Chauffage | Y29: =Y64 -> 100997.67 | Z29: =Z64 -> 81335.173 | AA29: =AA64 -> 62532.978 | AB29: =AB64 -> 48822.166
A30: Hors chauffage | B30: =B120 -> 158828.24 | C30: =C120 -> 163798.85 | D30: =D120 -> 185016.6 | E30: =E120 -> 213980.17 | X30: Hors chauffage | Y30: =Y120 -> 151855.24 | Z30: =Z120 -> 130305.87 | AA30: =AA120 -> 123681.67 | AB30: =AB120 -> 120626.2
A31: Total | B31: =SUM(B29:B30) -> 259825.91 | C31: =SUM(C29:C30) -> 246578.03 | D31: =SUM(D29:D30) -> 260672.96 | E31: =SUM(E29:E30) -> 280856.62 | X31: Total | Y31: =SUM(Y29:Y30) -> 252852.91 | Z31: =SUM(Z29:Z30) -> 211641.04 | AA31: =SUM(AA29:AA30) -> 186214.65 | AB31: =SUM(AB29:AB30) -> 169448.37
A33: Consommation totale en GWh AME | X33: Consommation totale en GWh AMS
A34: Energie | B34: 2020 | C34: 2030 | D34: 2040 | E34: 2050 | X34: Energie | Y34: 2020 | Z34: 2030 | AA34: 2040 | AB34: 2050
A35: Fuel domestique | B35: =B57+B116 -> 22595.211 | C35: =C57+C116 -> 16467.226 | D35: =D57+D116 -> 13527.856 | E35: =E57+E116 -> 10756.59 | X35: Fuel domestique | Y35: =Y57+Y116 -> 22595.211 | Z35: =Z57+Z116 -> 1657.2553 | AA35: =AA57+AA116 -> 0 | AB35: =AB57+AB116 -> 0 | AC35: =Z35/Y35-1 -> -0.92665458 | AD35: J'aimerais bien que le tertiaire fasse plus d'effort que le résidentiel sur le gaz mais en comparent l'évolution du nombre de chaudière (res) à l'évolution du nombre de m², ce n'est pas équivalent
A36: Gaz naturel | B36: =B58+B115 -> 72724.002 | C36: =C58+C115 -> 59107.144 | D36: =D58+D115 -> 54381.501 | E36: =E58+E115 -> 48964.706 | X36: Gaz naturel | Y36: =Y58+Y115 -> 72856.921 | Z36: =Z58+Z115 -> 50935.799 | AA36: =AA58+AA115 -> 21647.97 | AB36: =AB58+AB115 -> 2830.2408 | AC36: =Z36/Y36-1 -> -0.30087906 | AD36: Le gaz est plus haut en 2030 malgré l'interdiction des chaudières à gaz du fait de la baisse des objectifs DEET dans les bureaux notamment et changement du parc
A37: Réseau de chaleur | B37: =B59+B118 -> 8956.0755 | C37: =C59+C118 -> 8753.9663 | D37: =D59+D118 -> 8305.5385 | E37: =E59+E118 -> 7473.4208 | X37: Réseau de chaleur | Y37: =Y59+Y118 -> 8956.0755 | Z37: =Z59+Z118 -> 18541.841 | AA37: =AA59+AA118 -> 20367.21 | AB37: =AB59+AB118 -> 19367.231 | AC37: =Z37/Y37-1 -> 1.0703087 | AD37: Ne pas faire une extrapolation linéaire entre 2030 et 2040 mais un pic en 2035 et une stabilisation
A38: GPL | B38: =B60 -> 1272.5787 | C38: =C60 -> 1096.1877 | D38: =D60 -> 1044.2803 | E38: =E60 -> 969.07551 | X38: GPL | Y38: =Y60 -> 1272.5787 | Z38: =Z60 -> 767.39292 | AA38: =AA60 -> 433.51045 | AB38: =AB60 -> 44.699236 | AC38: =Z38/Y38-1 -> -0.39697802
A39: ENR | B39: =B61+B117+B119 -> 1509.289 | C39: =C61+C117+C119 -> 1539.1785 | D39: =D61+D117+D119 -> 1625.3271 | E39: =E61+E117+E119 -> 1663.1942 | X39: ENR | Y39: =Y61+Y117+Y119 -> 1509.289 | Z39: =Z61+Z117+Z119 -> 2468.9607 | AA39: =AA61+AA117+AA119 -> 2907.1975 | AB39: =AB61+AB117+AB119 -> 3632.0252 | AC39: =Z39/Y39-1 -> 0.63584357
A40: Electricité (PAC incluses) | B40: =B62+B63+B114 -> 152768.75 | C40: =C62+C63+C114 -> 159614.33 | D40: =D62+D63+D114 -> 181788.45 | E40: =E62+E63+E114 -> 211029.63 | X40: Electricité (PAC incluses) | Y40: =Y62+Y63+Y114 -> 145662.83 | Z40: =Z62+Z63+Z114 -> 137167.52 | AA40: =AA62+AA63+AA114 -> 140681.46 | AB40: =AB62+AB63+AB114 -> 143344.62 | AC40: =Z40/Y40-1 -> -0.058321743
A41: Total | B41: =SUM(B35:B40) -> 259825.91 | C41: =SUM(C35:C40) -> 246578.03 | D41: =SUM(D35:D40) -> 260672.96 | E41: =SUM(E35:E40) -> 280856.62 | X41: Total | Y41: =Y64+Y120 -> 252852.91 | Z41: =Z64+Z120 -> 211641.04 | AA41: =AA64+AA120 -> 186214.65 | AB41: =AB64+AB120 -> 169448.37
A42: Gain énergétique | B42: =B41/$B41-1 -> 0 | C42: =C41/$B41-1 -> -0.050987518 | D42: =D41/$B41-1 -> 0.0032600586 | E42: =E41/$B41-1 -> 0.080941534 | X42: Gain énergétique | Y42: =Y41/$Y41-1 -> 0 | Z42: =Z41/$Y41-1 -> -0.16298752 | AA42: =AA41/$Y41-1 -> -0.26354555 | AB42: =AB41/$Y41-1 -> -0.32985399
B44: =SUM(B35:B40) -> 259825.91 | C44: =SUM(C35:C40) -> 246578.03 | D44: =SUM(D35:D40) -> 260672.96 | E44: =SUM(E35:E40) -> 280856.62
A49: Chauffage | P49: Chauffage
A55: Consommation totale de chauffage en GWh AME (hors chaleur environnement des PAC) | X55: Consommation totale de chauffage en GWh AMS (hors chaleur environnement des PAC)
A56: Energie | B56: 2020 | C56: 2030 | D56: 2040 | E56: 2050 | X56: Energie | Y56: 2020 | Z56: 2030 | AA56: 2040 | AB56: 2050
...

Sheet Résultats - post traitement
A1: Scénario AME | P1: Scénario AMS
A3: Consommation totale | P3: Consommation totale
B7: Surface chauffée - Scénario AME [thousand sq m] | Y7: Surface chauffée - Scénario AMS [thousand sq m]
A8: Catégorie | C8: 2020 | D8: 2030 | E8: 2040 | F8: 2050 | X8: Catégorie | Z8: 2020 | AA8: 2030 | AB8: 2040 | AC8: 2050
A9: Bureaux | B9: Neuf post 2020 | C9: ='Bureaux - AME'!H8 -> 0 | D9: ='Bureaux - AME'!I8 -> 6206.4099 | E9: ='Bureaux - AME'!J8 -> 6411.8445 | F9: ='Bureaux - AME'!K8 -> 5961.6497 | X9: Bureaux | Y9: Neuf post 2020 | Z9: ='Bureaux - AMS'!H8 -> 0 | AA9: ='Bureaux - AMS'!I8 -> 6206.4099 | AB9: ='Bureaux - AMS'!J8 -> 5920.8739 | AC9: ='Bureaux - AMS'!K8 -> 5623.8459
B10: Existant 2020 | C10: ='Bureaux - AME'!H9 -> 287333.79 | D10: ='Bureaux - AME'!I9 -> 269335.76 | E10: ='Bureaux - AME'!J9 -> 269590.46 | F10: ='Bureaux - AME'!K9 -> 263785.02 | Y10: Existant 2020 | Z10: ='Bureaux - AMS'!H9 -> 287333.79 | AA10: ='Bureaux - AMS'!I9 -> 267908.12 | AB10: ='Bureaux - AMS'!J9 -> 254442.36 | AC10: ='Bureaux - AMS'!K9 -> 233249.46
A11: Café Hôtels Restaurants | B11: Neuf post 2020 | C11: ='CaHoREs - AME'!H8 -> 0 | D11: ='CaHoREs - AME'!I8 -> 4554.2951 | E11: ='CaHoREs - AME'!J8 -> 3048.0727 | F11: ='CaHoREs - AME'!K8 -> 2041.8509 | X11: Café Hôtels Restaurants | Y11: Neuf post 2020 | Z11: ='CaHoREs - AMS'!H8 -> 0 | AA11: ='CaHoREs - AMS'!I8 -> 4192.3289 | AB11: ='CaHoREs - AMS'!J8 -> 2902.3742 | AC11: ='CaHoREs - AMS'!K8 -> 2027.5304
B12: Existant 2020 | C12: ='CaHoREs - AME'!H9 -> 67243.869 | D12: ='CaHoREs - AME'!I9 -> 65307.246 | E12: ='CaHoREs - AME'!J9 -> 67849.529 | F12: ='CaHoREs - AME'!K9 -> 68171.331 | Y12: Existant 2020 | Z12: ='CaHoREs - AMS'!H9 -> 67243.869 | AA12: ='CaHoREs - AMS'!I9 -> 65307.246 | AB12: ='CaHoREs - AMS'!J9 -> 67497.987 | AC12: ='CaHoREs - AMS'!K9 -> 66866.719
A13: Commerce | B13: Neuf post 2020 | C13: ='Commerce - AME'!H8 -> 0 | D13: ='Commerce - AME'!I8 -> 13164.331 | E13: ='Commerce - AME'!J8 -> 8969.5375 | F13: ='Commerce - AME'!K8 -> 8772.0507 | X13: Commerce | Y13: Neuf post 2020 | Z13: ='Commerce - AMS'!H8 -> 0 | AA13: ='Commerce - AMS'!I8 -> 12185.885 | AB13: ='Commerce - AMS'!J8 -> 8717.0415 | AC13: ='Commerce - AMS'!K8 -> 8710.528
B14: Existant 2020 | C14: ='Commerce - AME'!H9 -> 184229.65 | D14: ='Commerce - AME'!I9 -> 175681.39 | E14: ='Commerce - AME'!J9 -> 180083.28 | F14: ='Commerce - AME'!K9 -> 175887.23 | Y14: Existant 2020 | Z14: ='Commerce - AMS'!H9 -> 184229.65 | AA14: ='Commerce - AMS'!I9 -> 175681.39 | AB14: ='Commerce - AMS'!J9 -> 179009.85 | AC14: ='Commerce - AMS'!K9 -> 172479.99
A15: Enseignement | B15: Neuf post 2020 | C15: ='Enseignement - AME'!H8 -> 0 | D15: ='Enseignement - AME'!I8 -> 5840.7077 | E15: ='Enseignement - AME'!J8 -> 3412.3997 | F15: ='Enseignement - AME'!K8 -> 3380.7737 | X15: Enseignement | Y15: Neuf post 2020 | Z15: ='Enseignement - AMS'!H8 -> 0 | AA15: ='Enseignement - AMS'!I8 -> 4962.0556 | AB15: ='Enseignement - AMS'!J8 -> 3394.7194 | AC15: ='Enseignement - AMS'!K8 -> 3357.0627
B16: Existant 2020 | C16: ='Enseignement - AME'!H9 -> 167106.71 | D16: ='Enseignement - AME'!I9 -> 163744.18 | E16: ='Enseignement - AME'!J9 -> 164600.78 | F16: ='Enseignement - AME'!K9 -> 158963.24 | Y16: Existant 2020 | Z16: ='Enseignement - AMS'!H9 -> 167106.71 | AA16: ='Enseignement - AMS'!I9 -> 163744.18 | AB16: ='Enseignement - AMS'!J9 -> 163440.1 | AC16: ='Enseignement - AMS'!K9 -> 155937.37
A17: Santé social | B17: Neuf post 2020 | C17: ='Santé social - AME'!H8 -> 0 | D17: ='Santé social - AME'!I8 -> 22460.451 | E17: ='Santé social - AME'!J8 -> 19028.378 | F17: ='Santé social - AME'!K8 -> 14323.903 | X17: Santé social | Y17: Neuf post 2020 | Z17: ='Santé social - AMS'!H8 -> 0 | AA17: ='Santé social - AMS'!I8 -> 21439.618 | AB17: ='Santé social - AMS'!J8 -> 18543.246 | AC17: ='Santé social - AMS'!K8 -> 11635.794
B18: Existant 2020 | C18: ='Santé social - AME'!H9 -> 179200 | D18: ='Santé social - AME'!I9 -> 174566.15 | E18: ='Santé social - AME'!J9 -> 191931.78 | F18: ='Santé social - AME'!K9 -> 205505.03 | Y18: Existant 2020 | Z18: ='Santé social - AMS'!H9 -> 179200 | AA18: ='Santé social - AMS'!I9 -> 174566.15 | AB18: ='Santé social - AMS'!J9 -> 190937.34 | AC18: ='Santé social - AMS'!K9 -> 204063.73
A19: Sport Loisir Culture | B19: Neuf post 2020 | C19: ='Sport Loisir Culture - AME'!H8 -> 0 | D19: ='Sport Loisir Culture - AME'!I8 -> 3336.8292 | E19: ='Sport Loisir Culture - AME'!J8 -> 2051.9847 | F19: ='Sport Loisir Culture - AME'!K8 -> 1198.8501 | X19: Sport Loisir Culture | Y19: Neuf post 2020 | Z19: ='Sport Loisir Culture - AMS'!H8 -> 0 | AA19: ='Sport Loisir Culture - AMS'!I8 -> 3032.6507 | AB19: ='Sport Loisir Culture - AMS'!J8 -> 1932.1865 | AC19: ='Sport Loisir Culture - AMS'!K8 -> 1190.4419
B20: Existant 2020 | C20: ='Sport Loisir Culture - AME'!H9 -> 56508.434 | D20: ='Sport Loisir Culture - AME'!I9 -> 55371.367 | E20: ='Sport Loisir Culture - AME'!J9 -> 57526.866 | F20: ='Sport Loisir Culture - AME'!K9 -> 57804.848 | Y20: Existant 2020 | Z20: ='Sport Loisir Culture - AMS'!H9 -> 56508.434 | AA20: ='Sport Loisir Culture - AMS'!I9 -> 55371.367 | AB20: ='Sport Loisir Culture - AMS'!J9 -> 57228.808 | AC20: ='Sport Loisir Culture - AMS'!K9 -> 56704.89
A21: Transport | B21: Neuf post 2020 | C21: ='Transport - AME'!H8 -> 0 | D21: ='Transport - AME'!I8 -> 2714.9401 | E21: ='Transport - AME'!J8 -> 1773.7602 | F21: ='Transport - AME'!K8 -> 1146.2522 | X21: Transport | Y21: Neuf post 2020 | Z21: ='Transport - AMS'!H8 -> 0 | AA21: ='Transport - AMS'!I8 -> 2489.8568 | AB21: ='Transport - AMS'!J8 -> 1683.79 | AC21: ='Transport - AMS'!K8 -> 1138.213
B22: Existant 2020 | C22: ='Transport - AME'!H9 -> 41814.604 | D22: ='Transport - AME'!I9 -> 40727.425 | E22: ='Transport - AME'!J9 -> 42312.863 | F22: ='Transport - AME'!K9 -> 42514.775 | Y22: Existant 2020 | Z22: ='Transport - AMS'!H9 -> 41814.604 | AA22: ='Transport - AMS'!I9 -> 40727.425 | AB22: ='Transport - AMS'!J9 -> 42093.632 | AC22: ='Transport - AMS'!K9 -> 41702.656
A23: Total | B23: Neuf post 2020 | C23: =C9+C11+C13+C15+C17+C19+C21 -> 0 | D23: =D9+D11+D13+D15+D17+D19+D21 -> 58277.964 | E23: =E9+E11+E13+E15+E17+E19+E21 -> 44695.977 | F23: =F9+F11+F13+F15+F17+F19+F21 -> 36825.33 | X23: Total | Y23: Neuf post 2020 | Z23: =Z9+Z11+Z13+Z15+Z17+Z19+Z21 -> 0 | AA23: =AA9+AA11+AA13+AA15+AA17+AA19+AA21 -> 54508.805 | AB23: =AB9+AB11+AB13+AB15+AB17+AB19+AB21 -> 43094.231 | AC23: =AC9+AC11+AC13+AC15+AC17+AC19+AC21 -> 33683.416
B24: Existant 2020 | C24: =C10+C12+C14+C16+C18+C20+C22 -> 983437.06 | D24: =D10+D12+D14+D16+D18+D20+D22 -> 944733.51 | E24: =E10+E12+E14+E16+E18+E20+E22 -> 973895.55 | F24: =F10+F12+F14+F16+F18+F20+F22 -> 972631.48 | Y24: Existant 2020 | Z24: =Z10+Z12+Z14+Z16+Z18+Z20+Z22 -> 983437.06 | AA24: =AA10+AA12+AA14+AA16+AA18+AA20+AA22 -> 943305.87 | AB24: =AB10+AB12+AB14+AB16+AB18+AB20+AB22 -> 954650.08 | AC24: =AC10+AC12+AC14+AC16+AC18+AC20+AC22 -> 931004.81
AA25: =AA24*0.4/7 -> 53903.193 | AC25: =AC24*0.3/10 -> 27930.144
A27: Consommation totale en GWh AME | X27: Consommation totale en GWh AMS
A28: Usage | B28: 2020 | C28: 2030 | D28: 2040 | E28: 2050 | X28: Usage | Y28: 2020 | Z28: 2030 | AA28: 2040 | AB28: 2050
A29: Chauffage | B29: =B64 -> 100997.67 | C29: =C64 -> 82779.177 | D29: =D64 -> 75656.355 | E29: =E64 -> 66876.448 | X29: Chauffage | Y29: =Y69 -> 100997.67 | Z29: =Z69 -> 81145.038 | AA29: =AA69 -> 62549.422 | AB29: =AB69 -> 48997.735
A30: Hors chauffage | B30: =B120 -> 158828.24 | C30: =C120 -> 163798.85 | D30: =D120 -> 185016.6 | E30: =E120 -> 213980.17 | X30: Hors chauffage | Y30: =Y120 -> 151855.24 | Z30: =Z120 -> 130305.87 | AA30: =AA120 -> 123681.67 | AB30: =AB120 -> 120626.2
A31: Total | B31: =SUM(B29:B30) -> 259825.91 | C31: =SUM(C29:C30) -> 246578.03 | D31: =SUM(D29:D30) -> 260672.96 | E31: =SUM(E29:E30) -> 280856.62 | X31: Total | Y31: =SUM(Y29:Y30) -> 252852.91 | Z31: =SUM(Z29:Z30) -> 211450.9 | AA31: =SUM(AA29:AA30) -> 186231.09 | AB31: =SUM(AB29:AB30) -> 169623.94
A33: Consommation totale en GWh AME | X33: Consommation totale en GWh AMS
A34: Energie | B34: 2020 | C34: 2030 | D34: 2040 | E34: 2050 | X34: Energie | Y34: 2020 | Z34: 2030 | AA34: 2040 | AB34: 2050
A35: Fuel domestique | B35: =B57+B116 -> 22595.211 | C35: =C57+C116 -> 16467.226 | D35: =D57+D116 -> 13527.856 | E35: =E57+E116 -> 10756.59 | X35: Fuel domestique | Y35: =Y57+Y116 -> 22595.211 | Z35: =Z57+Z116 -> 1657.2553 | AA35: =AA57+AA116 -> 0 | AB35: =AB57+AB116 -> 0 | AC35: =Z35/Y35-1 -> -0.92665458 | AD35: J'aimerais bien que le tertiaire fasse plus d'effort que le résidentiel sur le gaz mais en comparent l'évolution du nombre de chaudière (res) à l'évolution du nombre de m², ce n'est pas équivalent
A36: Gaz naturel | B36: =B58+B115 -> 72724.002 | C36: =C58+C115 -> 59107.144 | D36: =D58+D115 -> 54381.501 | E36: =E58+E115 -> 48964.706 | X36: Gaz naturel | Y36: =Y58+Y115 -> 72856.921 | Z36: =Z58+Z115 -> 51040.534 | AA36: =AA58+AA115 -> 22537.321 | AB36: =AB58+AB115 -> 4455.6684 | AC36: =Z36/Y36-1 -> -0.29944152 | AD36: Le gaz est plus haut en 2030 malgré l'interdiction des chaudières à gaz du fait de la baisse des objectifs DEET dans les bureaux notamment et changement du parc
A37: Réseau de chaleur | B37: =B59+B118 -> 8956.0755 | C37: =C59+C118 -> 8753.9663 | D37: =D59+D118 -> 8305.5385 | E37: =E59+E118 -> 7473.4208 | X37: Réseau de chaleur | Y37: =Y61+Y118 -> 8956.0755 | Z37: =Z61+Z118 -> 18541.841 | AA37: =AA61+AA118 -> 20367.21 | AB37: =AB61+AB118 -> 19367.231 | AC37: =Z37/Y37-1 -> 1.0703087 | AD37: Ne pas faire une extrapolation linéaire entre 2030 et 2040 mais un pic en 2035 et une stabilisation
A38: GPL | B38: =B60 -> 1272.5787 | C38: =C60 -> 1096.1877 | D38: =D60 -> 1044.2803 | E38: =E60 -> 969.07551 | X38: GPL | Y38: =Y62 -> 1272.5787 | Z38: =Z62 -> 767.39292 | AA38: =AA62 -> 433.51045 | AB38: =AB62 -> 44.699236 | AC38: =Z38/Y38-1 -> -0.39697802
A39: ENR | B39: =B61+B117+B119 -> 1509.289 | C39: =C61+C117+C119 -> 1539.1785 | D39: =D61+D117+D119 -> 1625.3271 | E39: =E61+E117+E119 -> 1663.1942 | X39: ENR | Y39: =Y63+Y117+Y119 -> 1509.289 | Z39: =Z63+Z117+Z119 -> 2468.9607 | AA39: =AA63+AA117+AA119 -> 2907.1975 | AB39: =AB63+AB117+AB119 -> 3632.0252 | AC39: =Z39/Y39-1 -> 0.63584357
A40: Electricité (PAC incluses) | B40: =B62+B63+B114 -> 152768.75 | C40: =C62+C63+C114 -> 159614.33 | D40: =D62+D63+D114 -> 181788.45 | E40: =E62+E63+E114 -> 211029.63 | X40: Electricité (PAC incluses) | Y40: =Y64+Y65+Y114 -> 145662.83 | Z40: =Z64+Z65+Z114 -> 136872.65 | AA40: =AA64+AA65+AA114 -> 139808.55 | AB40: =AB64+AB65+AB114 -> 141894.76 | AC40: =Z40/Y40-1 -> -0.060346068
A41: Total | B41: =SUM(B35:B40) -> 259825.91 | C41: =SUM(C35:C40) -> 246578.03 | D41: =SUM(D35:D40) -> 260672.96 | E41: =SUM(E35:E40) -> 280856.62 | X41: Total | Y41: =Y69+Y120 -> 252852.91 | Z41: =Z69+Z120 -> 211450.9 | AA41: =AA69+AA120 -> 186231.09 | AB41: =AB69+AB120 -> 169623.94
A42: Gain énergétique | B42: =B41/$B41-1 -> 0 | C42: =C41/$B41-1 -> -0.050987518 | D42: =D41/$B41-1 -> 0.0032600586 | E42: =E41/$B41-1 -> 0.080941534 | X42: Gain énergétique | Y42: =Y41/$Y41-1 -> 0 | Z42: =Z41/$Y41-1 -> -0.16373947 | AA42: =AA41/$Y41-1 -> -0.26348052 | AB42: =AB41/$Y41-1 -> -0.32915964
B44: =SUM(B35:B40) -> 259825.91 | C44: =SUM(C35:C40) -> 246578.03 | D44: =SUM(D35:D40) -> 260672.96 | E44: =SUM(E35:E40) -> 280856.62
A49: Chauffage | P49: Chauffage
AE52: Trajectoire de PAC hybride (même proposition par rapport aux PAC que dans le résidentiel)
A55: Consommation totale de chauffage en GWh AME (hors chaleur environnement des PAC) | X55: Consommation totale de chauffage en GWh AMS (hors chaleur environnement des PAC) | AF55: 0 | AG55: 0.01 | AH55: 0.05 | AI55: 0.08
...

Sheet Init. parc
B2: Projection surface tertiaire AME 24 | H2: Renouvellement du parc (destruction reconstruction) | M2: Parc post-2020 (besoins suppl. + destruction/reconstruction)
C3: Etat initial (2020) | D3: 2030 | E3: 2040 | F3: 2050 | I3: 2020-2030 | J3: 2030-2040 | K3: 2040-2050 | M3: Etat initial (2020) | N3: 2030 | O3: 2040 | P3: 2050
B4: Bureaux Administration | C4: 287333.79 | D4: 275542.17 | E4: 276002.3 | F4: 269746.67 | H4: Bureaux Administration | I4: 0.00216 | J4: 0.00216 | K4: 0.00216 | M4: Bureaux Administration | N4: =IF(D4>C4,D4-C4,0)+C4*I4*10 -> 6206.4099 | O4: =IF(E4>D4,E4-D4,0)+D4*J4*10 -> 6411.8445 | P4: =IF(F4>E4,F4-E4,0)+E4*K4*10 -> 5961.6497
B5: Café Hôtel Restaurant | C5: 67243.869 | D5: 69861.541 | E5: 70897.601 | F5: 70213.182 | H5: Café Hôtel Restaurant | I5: 0.00288 | J5: 0.00288 | K5: 0.00288 | M5: Café Hôtel Restaurant | N5: =IF(D5>C5,D5-C5,0)+C5*I5*10 -> 4554.2951 | O5: =IF(E5>D5,E5-D5,0)+D5*J5*10 -> 3048.0727 | P5: =IF(F5>E5,F5-E5,0)+E5*K5*10 -> 2041.8509
B6: Commerce | C6: 184229.65 | D6: 188845.72 | E6: 189052.82 | F6: 184659.28 | H6: Commerce | I6: 0.00464 | J6: 0.00464 | K6: 0.00464 | M6: Commerce | N6: =IF(D6>C6,D6-C6,0)+C6*I6*10 -> 13164.331 | O6: =IF(E6>D6,E6-D6,0)+D6*J6*10 -> 8969.5375 | P6: =IF(F6>E6,F6-E6,0)+E6*K6*10 -> 8772.0507
B7: Enseignement Recherche | C7: 167106.71 | D7: 169584.88 | E7: 168013.18 | F7: 162344.01 | H7: Enseignement Recherche | I7: 0.0020122075 | J7: 0.0020122075 | K7: 0.0020122075 | M7: Enseignement Recherche | N7: =IF(D7>C7,D7-C7,0)+C7*I7*10 -> 5840.7077 | O7: =IF(E7>D7,E7-D7,0)+D7*J7*10 -> 3412.3997 | P7: =IF(F7>E7,F7-E7,0)+E7*K7*10 -> 3380.7737
C8: 0 | D8: 0 | E8: 0 | F8: 0 | I8: 0.002 | J8: 0.002 | K8: 0.002 | M8: Habitat communautaire | N8: =IF(D8>C8,D8-C8,0)+C8*I8*10 -> 0 | O8: =IF(E8>D8,E8-D8,0)+D8*J8*10 -> 0 | P8: =IF(F8>E8,F8-E8,0)+E8*K8*10 -> 0
B9: Santé Action Sociale | C9: 179200 | D9: 197026.6 | E9: 210960.16 | F9: 219828.94 | H9: Santé Action Sociale | I9: 0.0025858545 | J9: 0.0025858545 | K9: 0.0025858545 | M9: Santé Action Sociale | N9: =IF(D9>C9,D9-C9,0)+C9*I9*10 -> 22460.451 | O9: =IF(E9>D9,E9-D9,0)+D9*J9*10 -> 19028.378 | P9: =IF(F9>E9,F9-E9,0)+E9*K9*10 -> 14323.903
B10: Sport Loisir Culture | C10: 56508.434 | D10: 58708.196 | E10: 59578.85 | F10: 59003.698 | H10: Sport Loisir Culture | I10: 0.0020122075 | J10: 0.0020122075 | K10: 0.0020122075 | M10: Sport Loisir Culture | N10: =IF(D10>C10,D10-C10,0)+C10*I10*10 -> 3336.8292 | O10: =IF(E10>D10,E10-D10,0)+D10*J10*10 -> 2051.9847 | P10: =IF(F10>E10,F10-E10,0)+E10*K10*10 -> 1198.8501
B11: Transport | C11: 41814.604 | D11: 43442.365 | E11: 44086.623 | F11: 43661.027 | H11: Transport | I11: 0.0026 | J11: 0.0026 | K11: 0.0026 | M11: Transport | N11: =IF(D11>C11,D11-C11,0)+C11*I11*10 -> 2714.9401 | O11: =IF(E11>D11,E11-D11,0)+D11*J11*10 -> 1773.7602 | P11: =IF(F11>E11,F11-E11,0)+E11*K11*10 -> 1146.2522
B12: total | C12: =SUM(C4:C11) -> 983437.06 | D12: =SUM(D4:D11) -> 1003011.5 | E12: =SUM(E4:E11) -> 1018591.5 | F12: =SUM(F4:F11) -> 1009456.8 | H12: Flux de renouvellement annuel | I12: =SUMPRODUCT(C4:C11,I4:I11) -> 2691.192 | J12: =SUMPRODUCT(D4:D11,J4:J11) -> 2754.4218 | K12: =SUMPRODUCT(E4:E11,K4:K11) -> 2795.655 | M12: total | N12: =SUM(N4:N11) -> 58277.964 | O12: =SUM(O4:O11) -> 44695.977 | P12: =SUM(P4:P11) -> 36825.33
D13: =(D12-C12)/10 -> 1957.4421 | E13: =(E12-D12)/10 -> 1558.0054 | F13: =(F12-E12)/10 -> -913.47178 | M13: par an | N13: =N12/10 -> 5827.7964 | O13: =O12/10 -> 4469.5977 | P13: =P12/10 -> 3682.533
N14: =N13/D12 -> 0.0058102988 | O14: =O13/E12 -> 0.0043880178 | P14: =P13/F12 -> 0.0036480342
B17: milliers de m²
B18: Projection surface tertiaire nette AMS run 3 | H18: Renouvellement du parc (destruction reconstruction) | M18: Parc post-2020
C19: Etat initial (2020) | D19: 2030 | E19: 2040 | F19: 2050 | I19: 2020-2030 | J19: 2030-2040 | K19: 2040-2050 | M19: Etat initial (2020) | N19: 2030 | O19: 2040 | P19: 2050
B20: Bureaux Administration | C20: 287333.79 | D20: 274114.53 | E20: 260363.23 | F20: 238873.31 | H20: Bureaux Administration | I20: 0.00216 | J20: 0.00216 | K20: 0.00216 | M20: Bureaux Administration | N20: =IF(D20>C20,D20-C20,0)+C20*I20*10 -> 6206.4099 | O20: =IF(E20>D20,E20-D20,0)+D20*J20*10 -> 5920.8739 | P20: =IF(F20>E20,F20-E20,0)+E20*K20*10 -> 5623.8459
B21: Café Hôtel Restaurant | C21: 67243.869 | D21: 69499.575 | E21: 70400.361 | F21: 68894.25 | H21: Café Hôtel Restaurant | I21: 0.00288 | J21: 0.00288 | K21: 0.00288 | M21: Café Hôtel Restaurant | N21: =IF(D21>C21,D21-C21,0)+C21*I21*10 -> 4192.3289 | O21: =IF(E21>D21,E21-D21,0)+D21*J21*10 -> 2902.3742 | P21: =IF(F21>E21,F21-E21,0)+E21*K21*10 -> 2027.5304
B22: Commerce | C22: 184229.65 | D22: 187867.27 | E22: 187726.9 | F22: 181190.52 | H22: Commerce | I22: 0.00464 | J22: 0.00464 | K22: 0.00464 | M22: Commerce | N22: =IF(D22>C22,D22-C22,0)+C22*I22*10 -> 12185.885 | O22: =IF(E22>D22,E22-D22,0)+D22*J22*10 -> 8717.0415 | P22: =IF(F22>E22,F22-E22,0)+E22*K22*10 -> 8710.528
B23: Enseignement Recherche | C23: 167106.71 | D23: 168706.23 | E23: 166834.82 | F23: 159294.43 | H23: Enseignement Recherche | I23: 0.0020122075 | J23: 0.0020122075 | K23: 0.0020122075 | M23: Enseignement Recherche | N23: =IF(D23>C23,D23-C23,0)+C23*I23*10 -> 4962.0556 | O23: =IF(E23>D23,E23-D23,0)+D23*J23*10 -> 3394.7194 | P23: =IF(F23>E23,F23-E23,0)+E23*K23*10 -> 3357.0627
C24: 0 | D24: 0 | E24: 0 | F24: 0 | I24: 0.002 | J24: 0.002 | K24: 0.002 | M24: Habitat communautaire | N24: =IF(D24>C24,D24-C24,0)+C24*I24*10 -> 0 | O24: =IF(E24>D24,E24-D24,0)+D24*J24*10 -> 0 | P24: =IF(F24>E24,F24-E24,0)+E24*K24*10 -> 0
B25: Santé Action Sociale | C25: 179200 | D25: 196005.77 | E25: 209480.59 | F25: 215699.52 | H25: Santé Action Sociale | I25: 0.0025858545 | J25: 0.0025858545 | K25: 0.0025858545 | M25: Santé Action Sociale | N25: =IF(D25>C25,D25-C25,0)+C25*I25*10 -> 21439.618 | O25: =IF(E25>D25,E25-D25,0)+D25*J25*10 -> 18543.246 | P25: =IF(F25>E25,F25-E25,0)+E25*K25*10 -> 11635.794
B26: Sport Loisir Culture | C26: 56508.434 | D26: 58404.018 | E26: 59160.994 | F26: 57895.332 | H26: Sport Loisir Culture | I26: 0.0020122075 | J26: 0.0020122075 | K26: 0.0020122075 | M26: Sport Loisir Culture | N26: =IF(D26>C26,D26-C26,0)+C26*I26*10 -> 3032.6507 | O26: =IF(E26>D26,E26-D26,0)+D26*J26*10 -> 1932.1865 | P26: =IF(F26>E26,F26-E26,0)+E26*K26*10 -> 1190.4419
B27: Transport | C27: 41814.604 | D27: 43217.281 | E27: 43777.422 | F27: 42840.869 | H27: Transport | I27: 0.0026 | J27: 0.0026 | K27: 0.0026 | M27: Transport | N27: =IF(D27>C27,D27-C27,0)+C27*I27*10 -> 2489.8568 | O27: =IF(E27>D27,E27-D27,0)+D27*J27*10 -> 1683.79 | P27: =IF(F27>E27,F27-E27,0)+E27*K27*10 -> 1138.213
B28: total | C28: 983437.06 | D28: 997814.68 | E28: 997744.31 | F28: 964688.23 | H28: Flux de renouvellement annuel | I28: 2691.192 | J28: 2754.4218 | K28: 2795.655 | M28: total | N28: =SUM(N20:N27) -> 54508.805 | O28: =SUM(O20:O27) -> 43094.231 | P28: =SUM(P20:P27) -> 33683.416
M29: par an | N29: =N28/10 -> 5450.8805 | O29: =O28/10 -> 4309.4231 | P29: =P28/10 -> 3368.3416
N30: =N29/D28 -> 0.0054628185 | O30: =O29/E28 -> 0.0043191658 | P30: =P29/F28 -> 0.0034916375
B34: https://www.ecologie.gouv.fr/sites/default/files/CGDD_scenarios_renovation_batiments_tertiaires_publication_20201203.pdf
B35: p. 54
B41: Parc Ademe | C41: 2020
B42: Bureaux Administration | C42: 239113.67
B43: Café Hôtel Restaurant | C43: 67389.902
B44: Commerce | C44: 215959
B45: Enseignement Recherche | C45: 190850
B46: Hab com | C46: 72592
B47: Santé Action Sociale | C47: 118445.14
B48: Sport Loisir Culture | C48: 74481
B49: Transport | C49: 25839.303
C50: =SUM(C42:C49) -> 1004670

Sheet Bureaux - AME
C1: Bureaux - Scénario AME
C3: Résultats - Scénario AME
F5: Surface chauffée - Scénario AME [thousand sq m]
E6: Catégorie | G6: 2010 | H6: 2020 | I6: 2030 | J6: 2040 | K6: 2050
E7: Tous bureaux | H7: =H34 -> 287333.79 | I7: =I34 -> 275542.17 | J7: =J34 -> 276002.3 | K7: =K34 -> 269746.67
E8: Dont surfaces construites après 2015 | H8: =H35 -> 0 | I8: =I35 -> 6206.4099 | J8: =J35 -> 6411.8445 | K8: =K35 -> 5961.6497
E9: Dont surfaces existantes en 2015 | H9: =H36 -> 287333.79 | I9: =I36 -> 269335.76 | J9: =J36 -> 269590.46 | K9: =K36 -> 263785.02
F11: Consommation par source énergie - Scénario AME [GWh LHV]
E12: Energie | G12: 2010 | H12: 2020 | I12: 2030 | J12: 2040 | K12: 2050
E13: Fuel domestique | H13: =H133+H167 -> 3705.1685 | I13: =I133+I167 -> 2535.2489 | J13: =J133+J167 -> 1849.638 | K13: =K133+K167 -> 1270.1721
E14: Gaz naturel | H14: =H134+H168 -> 17519.297 | I14: =I134+I168 -> 14064.469 | J14: =J134+J168 -> 12178.541 | K14: =K134+K168 -> 10558.977
E15: Réseau de chaleur | H15: =H135+H169 -> 2766.1151 | I15: =I135+I169 -> 2535.3244 | J15: =J135+J169 -> 2323.5714 | K15: =K135+K169 -> 2055.4152
E16: GPL | H16: =H136+H170 -> 394.01187 | I16: =I136+I170 -> 302.77798 | J16: =J136+J170 -> 255.44488 | K16: =K136+K170 -> 212.4528
E17: ENR | H17: =H137+H171 -> 411.65001 | I17: =I137+I171 -> 427.87867 | J17: =J137+J171 -> 464.91367 | K17: =K137+K171 -> 489.59612
E18: Electricité Joule | H18: =H138+H172 -> 6418.4622 | I18: =I138+I172 -> 4703.0268 | J18: =J138+J172 -> 3735.1157 | K18: =K138+K172 -> 2905.3549
E19: Electricité PAC | H19: =H139+H173 -> 1152.0826 | I19: =I139+I173 -> 1595.5655 | J19: =J139+J173 -> 2205.5392 | K19: =K139+K173 -> 2444.3127
E20: Total | H20: =SUM(H13:H19) -> 32366.788 | I20: =SUM(I13:I19) -> 26164.291 | J20: =SUM(J13:J19) -> 23012.764 | K20: =SUM(K13:K19) -> 19936.28
F22: Réalisation des objectifs
E23: Baisse de la consommation du parc suivant le décret | I23: =I118/$G118-1 -> -0.3204126 | J23: =J118/$G118-1 -> -0.46050719 | K23: =K118/$G118-1 -> -0.56392917
E24: Baisse de la consommation du parc hors décret | I24: =I129/$G129-1 -> -0.15599987 | J24: =J129/$G129-1 -> -0.22698864 | K24: =K129/$G129-1 -> -0.31365817
C27: Calculs - Scénario AME
D29: SURFACES CHAUFFEES
F32: Surfaces chauffées - Scénario AME [thousand sq m]
E33: Surface | G33: 2010 | H33: 2020 | I33: 2030 | J33: 2040 | K33: 2050
E34: Surface [thousand sq m] | G34: =H34 -> 287333.79 | H34: ='Init. parc'!C4 -> 287333.79 | I34: ='Init. parc'!D4 -> 275542.17 | J34: ='Init. parc'!E4 -> 276002.3 | K34: ='Init. parc'!F4 -> 269746.67
E35: Dont surfaces construites après 2020 | H35: 0 | I35: ='Init. parc'!N4 -> 6206.4099 | J35: ='Init. parc'!O4 -> 6411.8445 | K35: ='Init. parc'!P4 -> 5961.6497
E36: Dont surfaces existantes en 2020 | G36: =G34-G35 -> 287333.79 | H36: =H34-H35 -> 287333.79 | I36: =I34-I35 -> 269335.76 | J36: =J34-J35 -> 269590.46 | K36: =K34-K35 -> 263785.02
D39: CHAUFFAGE
E41: Parc existant en 2020
F43: Parc existant en 2015 - Répartition des surfaces chauffées par type d'énergie de chauffage - Scénario Tendanciel - surfaces suivant la traj décret
E44: Energie | G44: 2010 | H44: 2020 | I44: 2030 | J44: 2040 | K44: 2050 | M44: Justification hypothèses
E45: Fuel domestique | G45: =H45 -> 0.09 | H45: ='Init. énergie'!B3 -> 0.09 | I45: =H45+((K45-H45)/3) -> 0.073333333 | J45: =H45+((K45-H45)/3*2) -> 0.056666667 | K45: 0.04 | M45: Bâtiments qui suivent le décret : baisse du gaz et du joule au profit de RCU et surtout PAC qui sont favorisés dans le DEET. Pour le gaz : baisse supplémentaire liée au cadrage macro-éco. Pic RCU en 2030/2040 car plus de fonds chaleur et juste coup de pouce CEE + classement des fonds chaleur mais après ça s'arrête
E46: Gaz naturel | G46: =H46 -> 0.425 | H46: ='Init. énergie'!B4 -> 0.425 | I46: =H46+((K46-H46)/3) -> 0.39666667 | J46: =H46+((K46-H46)/3*2) -> 0.36833333 | K46: 0.34
E47: Réseaux de chaleur | G47: =H47 -> 0.08 | H47: ='Init. énergie'!B5 -> 0.08 | I47: 0.1 | J47: 0.1 | K47: 0.09
E48: GPL | G48: =H48 -> 0.013 | H48: ='Init. énergie'!B6 -> 0.013 | I48: =H48+((K48-H48)/3) -> 0.012 | J48: =H48+((K48-H48)/3*2) -> 0.011 | K48: 0.01
E49: ENR | G49: =H49 -> 0.012 | H49: ='Init. énergie'!B7 -> 0.012 | I49: =H49+((K49-H49)/3) -> 0.014666667 | J49: =H49+((K49-H49)/3*2) -> 0.017333333 | K49: 0.02
E50: Joule | G50: =H50 -> 0.306 | H50: ='Init. énergie'!B8 -> 0.306 | I50: =H50+((K50-H50)/3) -> 0.27733333 | J50: =H50+((K50-H50)/3*2) -> 0.24866667 | K50: =1-K45-K46-K47-K48-K49-K51 -> 0.22
E51: PAC | G51: =H51 -> 0.073 | H51: ='Init. énergie'!B9 -> 0.073 | I51: 0.13 | J51: 0.2 | K51: 0.28
E52: Total | G52: =SUM(G45:G51) -> 0.999 | H52: =SUM(H45:H51) -> 0.999 | I52: =SUM(I45:I51) -> 1.004 | J52: =SUM(J45:J51) -> 1.002 | K52: =SUM(K45:K51) -> 1
F54: Baisses de consommation induites par les changements de système de chauffage
...

Sheet CaHoREs - AME
C1: Bureaux - Scénario AME
C3: Résultats - Scénario AME
F5: Surface chauffée - Scénario AME [thousand sq m]
E6: Catégorie | G6: 2010 | H6: 2020 | I6: 2030 | J6: 2040 | K6: 2050
E7: Tous bureaux | H7: =H34 -> 67243.869 | I7: =I34 -> 69861.541 | J7: =J34 -> 70897.601 | K7: =K34 -> 70213.182
E8: Dont surfaces construites après 2015 | H8: =H35 -> 0 | I8: =I35 -> 4554.2951 | J8: =J35 -> 3048.0727 | K8: =K35 -> 2041.8509
E9: Dont surfaces existantes en 2015 | H9: =H36 -> 67243.869 | I9: =I36 -> 65307.246 | J9: =J36 -> 67849.529 | K9: =K36 -> 68171.331
F11: Consommation par source énergie - Scénario AME [GWh LHV]
E12: Energie | G12: 2010 | H12: 2020 | I12: 2030 | J12: 2040 | K12: 2050
E13: Fuel domestique | H13: =H133+H167 -> 1146.8356 | I13: =I133+I167 -> 835.17619 | J13: =J133+J167 -> 675.50311 | K13: =K133+K167 -> 510.20016
E14: Gaz naturel | H14: =H134+H168 -> 3676.1473 | I14: =I134+I168 -> 3015.5264 | J14: =J134+J168 -> 2811.9835 | K14: =K134+K168 -> 2529.5397
E15: Réseau de chaleur | H15: =H135+H169 -> 623.71893 | I15: =I135+I169 -> 712.056 | J15: =J135+J169 -> 753.20931 | K15: =K135+K169 -> 632.38683
E16: GPL | H16: =H136+H170 -> 125.59756 | I16: =I136+I170 -> 98.056256 | J16: =J136+J170 -> 86.136962 | K16: =K136+K170 -> 72.03639
E17: ENR | H17: =H137+H171 -> 213.99844 | I17: =I137+I171 -> 288.40871 | J17: =J137+J171 -> 378.06855 | K17: =K137+K171 -> 452.31176
E18: Electricité Joule | H18: =H138+H172 -> 1168.4295 | I18: =I138+I172 -> 836.424 | J18: =J138+J172 -> 682.92741 | K18: =K138+K172 -> 544.06695
E19: Electricité PAC | H19: =H139+H173 -> 330.97384 | I19: =I139+I173 -> 472.41985 | J19: =J139+J173 -> 531.33973 | K19: =K139+K173 -> 567.53441
E20: Total | H20: =SUM(H13:H19) -> 7285.7012 | I20: =SUM(I13:I19) -> 6258.0674 | J20: =SUM(J13:J19) -> 5919.1686 | K20: =SUM(K13:K19) -> 5308.0762
F22: Réalisation des objectifs
E23: Baisse de la consommation du parc suivant le décret | I23: =I118/$G118-1 -> -0.34444 | J23: =J118/$G118-1 -> -0.41982103 | K23: =K118/$G118-1 -> -0.51844856
E24: Baisse de la consommation du parc hors décret | I24: =I129/$G129-1 -> -0.11265686 | J24: =J129/$G129-1 -> -0.13867983 | K24: =K129/$G129-1 -> -0.20913738
C27: Calculs - Scénario AME
D29: SURFACES CHAUFFEES
F32: Surfaces chauffées - Scénario AME [thousand sq m]
E33: Surface | G33: 2010 | H33: 2020 | I33: 2030 | J33: 2040 | K33: 2050
E34: Surface [thousand sq m] | G34: =H34 -> 67243.869 | H34: ='Init. parc'!C5 -> 67243.869 | I34: ='Init. parc'!D5 -> 69861.541 | J34: ='Init. parc'!E5 -> 70897.601 | K34: ='Init. parc'!F5 -> 70213.182
E35: Dont surfaces construites après 2015 | H35: 0 | I35: ='Init. parc'!N5 -> 4554.2951 | J35: ='Init. parc'!O5 -> 3048.0727 | K35: ='Init. parc'!P5 -> 2041.8509
E36: Dont surfaces existantes en 2015 | G36: =G34-G35 -> 67243.869 | H36: =H34-H35 -> 67243.869 | I36: =I34-I35 -> 65307.246 | J36: =J34-J35 -> 67849.529 | K36: =K34-K35 -> 68171.331
D39: CHAUFFAGE
E41: Parc existant en 2020
F43: Parc existant en 2015 - Répartition des surfaces chauffées par type d'énergie de chauffage - Scénario Tendanciel - surfaces suivant la traj décret
E44: Energie | G44: 2010 | H44: 2020 | I44: 2030 | J44: 2040 | K44: 2050 | M44: Justification hypothèses
E45: Fuel domestique | G45: =H45 -> 0.08 | H45: ='Init. énergie'!B12 -> 0.08 | I45: =H45+((K45-H45)/3) -> 0.066666667 | J45: =H45+((K45-H45)/3*2) -> 0.053333333 | K45: 0.04 | M45: Bâtiments qui suivent le décret : baisse du gaz et du joule au profit de RCU et surtout PAC qui sont favorisés dans le DEET. Pour le gaz : baisse supplémentaire liée au cadrage macro-éco. Pic RCU en 2030/2040 car plus de fonds chaleur et juste coup de pouce CEE + classement des fonds chaleur mais après ça s'arrête
E46: Gaz naturel | G46: =H46 -> 0.345 | H46: ='Init. énergie'!B13 -> 0.345 | I46: =H46+((K46-H46)/3) -> 0.32333333 | J46: =H46+((K46-H46)/3*2) -> 0.30166667 | K46: 0.28
E47: Réseaux de chaleur | G47: =H47 -> 0.066 | H47: ='Init. énergie'!B14 -> 0.066 | I47: 0.1 | J47: 0.1 | K47: 0.09
E48: GPL | G48: =H48 -> 0.014 | H48: ='Init. énergie'!B15 -> 0.014 | I48: =H48+((K48-H48)/3) -> 0.012666667 | J48: =H48+((K48-H48)/3*2) -> 0.011333333 | K48: 0.01
E49: ENR | G49: =H49 -> 0.027 | H49: ='Init. énergie'!B16 -> 0.027 | I49: =H49+((K49-H49)/3) -> 0.028 | J49: =H49+((K49-H49)/3*2) -> 0.029 | K49: 0.03
E50: Joule | G50: =H50 -> 0.362 | H50: ='Init. énergie'!B17 -> 0.362 | I50: 0.31 | J50: 0.27 | K50: =1-K45-K46-K47-K48-K49-K51 -> 0.23
E51: PAC | G51: =H51 -> 0.107 | H51: ='Init. énergie'!B18 -> 0.107 | I51: 0.16 | J51: 0.24 | K51: 0.32
E52: Total | G52: =SUM(G45:G51) -> 1.001 | H52: =SUM(H45:H51) -> 1.001 | I52: =SUM(I45:I51) -> 1.0006667 | J52: =SUM(J45:J51) -> 1.0053333 | K52: =SUM(K45:K51) -> 1
F54: Baisses de consommation induites par les changements de système de chauffage
...

Sheet Commerce - AME
C1: Bureaux - Scénario AME
C3: Résultats - Scénario AME
F5: Surface chauffée - Scénario AME [thousand sq m]
E6: Catégorie | G6: 2010 | H6: 2020 | I6: 2030 | J6: 2040 | K6: 2050
E7: Tous bureaux | H7: =H34 -> 184229.65 | I7: =I34 -> 188845.72 | J7: =J34 -> 189052.82 | K7: =K34 -> 184659.28
E8: Dont surfaces construites après 2015 | H8: =H35 -> 0 | I8: =I35 -> 13164.331 | J8: =J35 -> 8969.5375 | K8: =K35 -> 8772.0507
E9: Dont surfaces existantes en 2015 | H9: =H36 -> 184229.65 | I9: =I36 -> 175681.39 | J9: =J36 -> 180083.28 | K9: =K36 -> 175887.23
F11: Consommation par source énergie - Scénario AME [GWh LHV]
E12: Energie | G12: 2010 | H12: 2020 | I12: 2030 | J12: 2040 | K12: 2050
E13: Fuel domestique | H13: =H133+H167 -> 3430.6718 | I13: =I133+I167 -> 2428.7885 | J13: =J133+J167 -> 1974.2603 | K13: =K133+K167 -> 1465.9959
E14: Gaz naturel | H14: =H134+H168 -> 7861.9618 | I14: =I134+I168 -> 6281.2396 | J14: =J134+J168 -> 5758.9276 | K14: =K134+K168 -> 5009.7399
E15: Réseau de chaleur | H15: =H135+H169 -> 392.69537 | I15: =I135+I169 -> 337.41146 | J15: =J135+J169 -> 296.77485 | K15: =K135+K169 -> 232.21019
E16: GPL | H16: =H136+H170 -> 159.09604 | I16: =I136+I170 -> 138.28346 | J16: =J136+J170 -> 137.83284 | K16: =K136+K170 -> 130.22436
E17: ENR | H17: =H137+H171 -> 142.21439 | I17: =I137+I171 -> 112.40533 | J17: =J137+J171 -> 95.9689 | K17: =K137+K171 -> 77.872305
E18: Electricité Joule | H18: =H138+H172 -> 2654.7492 | I18: =I138+I172 -> 1911.1201 | J18: =J138+J172 -> 1385.0424 | K18: =K138+K172 -> 921.23625
E19: Electricité PAC | H19: =H139+H173 -> 822.29267 | I19: =I139+I173 -> 1507.7136 | J19: =J139+J173 -> 1917.8681 | K19: =K139+K173 -> 2211.6673
E20: Total | H20: =SUM(H13:H19) -> 15463.681 | I20: =SUM(I13:I19) -> 12716.962 | J20: =SUM(J13:J19) -> 11566.675 | K20: =SUM(K13:K19) -> 10048.946
F22: Réalisation des objectifs
E23: Baisse de la consommation du parc suivant le décret | I23: =I118/$G118-1 -> -0.35632 | J23: =J118/$G118-1 -> -0.43794124 | K23: =K118/$G118-1 -> -0.54650927
E24: Baisse de la consommation du parc hors décret | I24: =I129/$G129-1 -> -0.14836324 | J24: =J129/$G129-1 -> -0.20572739 | K24: =K129/$G129-1 -> -0.29522114
C27: Calculs - Scénario AME
D29: SURFACES CHAUFFEES
F32: Surfaces chauffées - Scénario AME [thousand sq m]
E33: Surface | G33: 2010 | H33: 2020 | I33: 2030 | J33: 2040 | K33: 2050
E34: Surface [thousand sq m] | G34: =H34 -> 184229.65 | H34: ='Init. parc'!C6 -> 184229.65 | I34: ='Init. parc'!D6 -> 188845.72 | J34: ='Init. parc'!E6 -> 189052.82 | K34: ='Init. parc'!F6 -> 184659.28
E35: Dont surfaces construites après 2015 | H35: 0 | I35: ='Init. parc'!N6 -> 13164.331 | J35: ='Init. parc'!O6 -> 8969.5375 | K35: ='Init. parc'!P6 -> 8772.0507
E36: Dont surfaces existantes en 2015 | G36: =G34-G35 -> 184229.65 | H36: =H34-H35 -> 184229.65 | I36: =I34-I35 -> 175681.39 | J36: =J34-J35 -> 180083.28 | K36: =K34-K35 -> 175887.23
D39: CHAUFFAGE
E41: Parc existant en 2020
F43: Parc existant en 2015 - Répartition des surfaces chauffées par type d'énergie de chauffage - Scénario Tendanciel - surfaces suivant la traj décret
E44: Energie | G44: 2010 | H44: 2020 | I44: 2030 | J44: 2040 | K44: 2050 | M44: Justification hypothèses
E45: Fuel domestique | G45: =H45 -> 0.184 | H45: ='Init. énergie'!B21 -> 0.184 | I45: 0.15 | J45: =H45+((K45-H45)/3*2) -> 0.128 | K45: 0.1 | M45: Bâtiments qui suivent le décret : baisse du gaz et du joule au profit de RCU et surtout PAC qui sont favorisés dans le DEET. Pour le gaz : baisse supplémentaire liée au cadrage macro-éco. Pic RCU en 2030/2040 car plus de fonds chaleur et juste coup de pouce CEE + classement des fonds chaleur mais après ça s'arrête
E46: Gaz naturel | G46: =H46 -> 0.393 | H46: ='Init. énergie'!B22 -> 0.393 | I46: =H46+((K46-H46)/3) -> 0.36866667 | J46: =H46+((K46-H46)/3*2) -> 0.34433333 | K46: 0.32
E47: Réseaux de chaleur | G47: =H47 -> 0.042 | H47: ='Init. énergie'!B23 -> 0.042 | I47: 0.05 | J47: 0.05 | K47: 0.04
E48: GPL | G48: =H48 -> 0.018 | H48: ='Init. énergie'!B24 -> 0.018 | I48: =H48+((K48-H48)/3) -> 0.018666667 | J48: =H48+((K48-H48)/3*2) -> 0.019333333 | K48: 0.02
E49: ENR | G49: =H49 -> 0.014 | H49: ='Init. énergie'!B25 -> 0.014 | I49: =H49+((K49-H49)/3) -> 0.012666667 | J49: =H49+((K49-H49)/3*2) -> 0.011333333 | K49: 0.01
E50: Joule | G50: =H50 -> 0.262 | H50: ='Init. énergie'!B26 -> 0.262 | I50: =H50+((K50-H50)/3) -> 0.21133333 | J50: =H50+((K50-H50)/3*2) -> 0.16066667 | K50: =1-K45-K46-K47-K48-K49-K51 -> 0.11
E51: PAC | G51: =H51 -> 0.088 | H51: ='Init. énergie'!B27 -> 0.088 | I51: =H51+((K51-H51)/3) -> 0.192 | J51: 0.29 | K51: 0.4
E52: Total | G52: =SUM(G45:G51) -> 1.001 | H52: =SUM(H45:H51) -> 1.001 | I52: =SUM(I45:I51) -> 1.0033333 | J52: =SUM(J45:J51) -> 1.0036667 | K52: =SUM(K45:K51) -> 1
F54: Baisses de consommation induites par les changements de système de chauffage
...

Sheet Enseignement - AME
C1: Bureaux - Scénario AME
C3: Résultats - Scénario AME
F5: Surface chauffée - Scénario AME [thousand sq m]
E6: Catégorie | G6: 2010 | H6: 2020 | I6: 2030 | J6: 2040 | K6: 2050
E7: Tous bureaux | H7: =H34 -> 167106.71 | I7: =I34 -> 169584.88 | J7: =J34 -> 168013.18 | K7: =K34 -> 162344.01
E8: Dont surfaces construites après 2015 | H8: =H35 -> 0 | I8: =I35 -> 5840.7077 | J8: =J35 -> 3412.3997 | K8: =K35 -> 3380.7737
E9: Dont surfaces existantes en 2015 | H9: =H36 -> 167106.71 | I9: =I36 -> 163744.18 | J9: =J36 -> 164600.78 | K9: =K36 -> 158963.24
F11: Consommation par source énergie - Scénario AME [GWh LHV]
E12: Energie | G12: 2010 | H12: 2020 | I12: 2030 | J12: 2040 | K12: 2050
E13: Fuel domestique | H13: =H133+H167 -> 3584.895 | I13: =I133+I167 -> 2621.0025 | J13: =J133+J167 -> 2142.0011 | K13: =K133+K167 -> 1647.061
E14: Gaz naturel | H14: =H134+H168 -> 8977.6736 | I14: =I134+I168 -> 7154.85 | J14: =J134+J168 -> 6440.7193 | K14: =K134+K168 -> 5525.384
E15: Réseau de chaleur | H15: =H135+H169 -> 1357.2567 | I15: =I135+I169 -> 1185.3944 | J15: =J135+J169 -> 1130.7378 | K15: =K135+K169 -> 1028.2412
E16: GPL | H16: =H136+H170 -> 214.36381 | I16: =I136+I170 -> 162.61007 | J16: =J136+J170 -> 138.4419 | K16: =K136+K170 -> 111.46831
E17: ENR | H17: =H137+H171 -> 141.7556 | I17: =I137+I171 -> 123.32236 | J17: =J137+J171 -> 117.6789 | K17: =K137+K171 -> 107.92926
E18: Electricité Joule | H18: =H138+H172 -> 751.9802 | I18: =I138+I172 -> 499.37701 | J18: =J138+J172 -> 357.77721 | K18: =K138+K172 -> 232.4827
E19: Electricité PAC | H19: =H139+H173 -> 116.24971 | I19: =I139+I173 -> 522.61095 | J19: =J139+J173 -> 682.65368 | K19: =K139+K173 -> 809.31798
E20: Total | H20: =SUM(H13:H19) -> 15144.175 | I20: =SUM(I13:I19) -> 12269.167 | J20: =SUM(J13:J19) -> 11010.01 | K20: =SUM(K13:K19) -> 9461.8845
F22: Réalisation des objectifs
E23: Baisse de la consommation du parc suivant le décret | I23: =I118/$G118-1 -> -0.3385824 | J23: =J118/$G118-1 -> -0.4336227 | K23: =K118/$G118-1 -> -0.54814778
E24: Baisse de la consommation du parc hors décret | I24: =I129/$G129-1 -> -0.1143849 | J24: =J129/$G129-1 -> -0.17615584 | K24: =K129/$G129-1 -> -0.2642009
C27: Calculs - Scénario AME
D29: SURFACES CHAUFFEES
F32: Surfaces chauffées - Scénario AME [thousand sq m]
E33: Surface | G33: 2010 | H33: 2020 | I33: 2030 | J33: 2040 | K33: 2050
E34: Surface [thousand sq m] | G34: =H34 -> 167106.71 | H34: ='Init. parc'!C7 -> 167106.71 | I34: ='Init. parc'!D7 -> 169584.88 | J34: ='Init. parc'!E7 -> 168013.18 | K34: ='Init. parc'!F7 -> 162344.01
E35: Dont surfaces construites après 2015 | H35: 0 | I35: ='Init. parc'!N7 -> 5840.7077 | J35: ='Init. parc'!O7 -> 3412.3997 | K35: ='Init. parc'!P7 -> 3380.7737
E36: Dont surfaces existantes en 2015 | G36: =G34-G35 -> 167106.71 | H36: =H34-H35 -> 167106.71 | I36: =I34-I35 -> 163744.18 | J36: =J34-J35 -> 164600.78 | K36: =K34-K35 -> 158963.24
D39: CHAUFFAGE
E41: Parc existant en 2020
F43: Parc existant en 2015 - Répartition des surfaces chauffées par type d'énergie de chauffage - Scénario Tendanciel - surfaces suivant la traj décret
E44: Energie | G44: 2010 | H44: 2020 | I44: 2030 | J44: 2040 | K44: 2050 | M44: Justification hypothèses
E45: Fuel domestique | G45: =H45 -> 0.202 | H45: ='Init. énergie'!B30 -> 0.202 | I45: =H45+((K45-H45)/3) -> 0.18133333 | J45: =H45+((K45-H45)/3*2) -> 0.16066667 | K45: 0.14 | M45: Bâtiments qui suivent le décret : baisse du gaz et du joule au profit de RCU et surtout PAC qui sont favorisés dans le DEET. Pour le gaz : baisse supplémentaire liée au cadrage macro-éco. Pic RCU en 2030/2040 car plus de fonds chaleur et juste coup de pouce CEE + classement des fonds chaleur mais après ça s'arrête
E46: Gaz naturel | G46: =H46 -> 0.588 | H46: ='Init. énergie'!B31 -> 0.588 | I46: =H46+((K46-H46)/3) -> 0.572 | J46: =H46+((K46-H46)/3*2) -> 0.556 | K46: 0.54
E47: Réseaux de chaleur | G47: =H47 -> 0.084 | H47: ='Init. énergie'!B32 -> 0.084 | I47: 0.1 | J47: 0.11 | K47: 0.12
