Workbook

Sheet Récap run 1bis
B1: Mesures | C1: Cibles | D1: Modélisation | E1: Résultat
A2: Tertiaire
B3: Obligation de rénovation | C3: 9Mtep/2020 | D3: Choc exogène d'investissement et de consommation énergétique (cf. I4CE) | E3: Cible atteinte
B4: Réduction du nombre de m2 par employé/tend | C4: Xm²vs Xm²/employé an 2050 | D4: Choc exogène d'investissement immobilier | E4: Cible atteinte
A5: Energie
B6: Modification de la part des combustibles fossiles dans les vecteurs carburant, chaleur et vapeur et électricité | C6: Cibles Enerdata : 60% de biocarb, Electricité totalement décarbonée 27% de nucléaire; 0.6% de gaz naturel dans le vecteur chaleur et vapeur. | D6: Modification exogène | E6: Cible atteinte
A7: Résidentiel
B8: Hausse des taux moyens pondérés de ma prime rénov de 11.5% à 16.6% en 2025 puis 20% en 2040, quel que soit le saut de classe énergie. | C8: Réduction de la consommation énergétique des ménages de 42Mtep en 2015 à 29 Mtep en 2050 | D8: Hausse des crédits d'impôts à l'efficacité énergétique | E8: Cible atteinte
B9: Réduction de la construction neuve | C9: nombre de m² par tête de 44m² dans AME à 42m² dans AMS | D9: Modification exogene du nombre de m² par tête | E9: Cible atteinte
B10: Doublement du budget CEE alloué au résidentiel en 2024 jusqu’en 2050. | D10: Modification exogene du nombre CEE | E10: Cible atteinte
A11: Transport de voyageur
B12: Interdiction de la vente des Vth à partir de 2035 (pas d’interdiction dans AME) | C12: Baisse des émissions du parc de 37% en 2030 | D12: Modification exogene des coefficients du modèle de Bass; baisse des taux d'aide à l'achat de VE; aide à l'installation de bornes électriques | E12: Cible atteinte
B13: Développement du covoiturage et du télétravail | C13: Nombre de Km parcourus; nombre de véhicule en circulation | D13: Choc exogene sur le nombre de KM courte distance parcourus; choc sur le nombre de passagers/véhicule | E13: cible atteinte
A14: Transport de marchandises
B15: Report modal du transport de marchandises | C15: Part du fret ferroviaire passe de 10 à 18% en 2030 ; Part du fluvial de 2 à 3% en 2030; La part du routier de 88 à 79% en 2030 | D15: Modification exogene des coefficients techniques | E15: Cible atteinte
B16: Evolution exogène de la consommation de transport aérien | C16: Limitation à 22% de la hausse du trafic d'ici 2050 | D16: Choc exogene sur la demande finale | E16: Cible atteinte
B17: Aide à l'électrification des poids lourds | C17: Le parc passe de 97% gazole 3% élec en 2019 à 78% gazole 16% élec 6% gaz en 2050. | D17: Introduction d'un crédit d'impôt à l'électrification (Hausse du crédit d’impôt de 0 en 2023 à 270M€ en 2030 puis à 860M€ en 2050 (13Mds€ sur toute la période). | E17: Cible atteinte
B18: Electrification des bus | D18: non réalisé
B19: Amélioration des rendements des moteurs | C19: (1.5%/An versus 0.3%/an) | D19: non réalisé
B20: Augmentation du taux de chargement | C20: baisse du trafic de 16% en veh.km (ce qui correspond à l’augmentation de 20% du taux de chargement) | D20: Choc négatif sur le ratio énergie/production | E20: Cible atteinte
A21: Industrie | B21: Crédit d'impôt à l'EE | C21: 12mds€ pour une baisse de 35MtCO2 | D21: Introduction d'un crédit d'impôt à l'efficacité énergéttique | E21: Cible atteinte
B22: Introduction des CEE | D22: non réalisé
B23: Réduction de la consommation de produits manufacturés | C23: Sucre (-31% dans AMS en 2050 ; Papier (baisse de 30% dans l’AME en 2050 et seulement 15% dans l’AMS); Textile (baisse de la consommation finale de 15% en 2050 dans AME et 30% dans l’AMS en 2050 | D23: Choc de demande négatif sur le sucre, le textile, le plastique. Insertion d’un choc sur la demande finale de l’agroalimentaire au prorata de la part du sucre dans la consommation qui est de 2,4%; Insertion d’un choc négatif sur la consommation finale du secteur autre industrie au prorata de la part de la consommation du textile 19,4% | E23: Cible atteinte
B24: Réduction de la demande de consommation intermédiaire de plastique | C24: La part de marché des menuiseries PVC passe de 61 à 48 et 27% dans l’AME et l’AMS en 2050. En revanche la part des tuyaux reste à 100%. Il est prévu que la part de marché du PVC dans les menuiseries soit réduite. Il est prévu que les films plastiques disparaissent dans l’AMS en 2050 ; que le nombre de bouteilles chute de 80% par rapport à 2014, que les emballages chutent de 60% etc… | D24: Faute d’avoir les quantités concernées par ses sous-produits, nous avons appliqué aux ratios CI/prod de plastiques consommés par les divers secteurs de production hors automobile et construction, le taux de croissance anticipé de la production de dichlore et d’éthylène consommé par le secteur de la fabrication de plastique entre aujourd’hui et 2050 | E24: Cible atteinte
B25: Réduction de la demanded'engrais azotés | C25: Il est prévu de réduire la consommation d’engrais de respectivement 29% et 59% en 2050 dans l’AME et l’AMS et de réduire la consommation de produits phytosanitaires de 31% et 44%. | D25: Modification des coefficients techniques | E25: Cible atteinte
B26: Augmentation de la construction bois | C26: La part des MI en bois passe de 10% aujourd’hui à 38% dans l’AMS en 2050, la part des LC passe de 3% à 38% ; respectivement 25 et 15% dans l’AME. | D26: On introduit un choc moyen pondéré (avec 44% de MI et 66% de LC) sur le ratio consommations intermédiaires/production de bois dans le bâtiment de la même ampleur. un choc inverse de même ampleur est appliqué à au ratio de consommations intermédiaires/production d’acier et de ciment par le BTP. | E26: Cible atteinte
B27: Modifiaction des taux d'import et d'export | C27: Cible de VA/PIB | D27: Non réalisé

Sheet Récap run 2
B1: Mesures | C1: Cibles | D1: Modélisation | E1: Résultat
A2: Tertiaire
B3: Obligation de rénovation
B4: Réduction du nombre de m2 par employé/tend
A5: Energie
B6: Modification de la part des combustibles fossiles dans les vecteurs carburant, chaleur et vapeur et électricité
A7: Résidentiel
B8: Hausse des taux moyens pondérés de ma prime rénov de 11.5% à 16.6% en 2025 puis 20% en 2040, quel que soit le saut de classe énergie.
B9: Réduction de la construction neuve
B10: Doublement du budget CEE alloué au résidentiel en 2024 jusqu’en 2050.
A11: Transport de voyageurs
B12: Interdiction de la vente des Vth à partir de 2035 (pas d’interdiction dans AME)
B13: Développement du covoiturage et du télétravail
A14: Transport de marchandises
B15: Report modal du transport de marchandises
B16: Evolution exogène de la consommation de transport aérien
B17: Aide à l'électrification des poids lourds
B18: Electrification des bus
B19: Amélioration des rendements des moteurs
B20: Augmentation du taux de chargement
A21: Industrie | B21: Crédit d'impôt à l'EE
B22: Introduction des CEE
B23: Réduction de la consommation de produits manufacturés
B24: Réduction de la demande de consommation intermédiaire de plastique
B25: Réduction de la demanded'engrais azotés
B26: Augmentation de la construction bois
B27: Modification des taux d'import et d'export | C27: Cible de VA/PIB | D27: Non réalisé

Sheet Variables AME
B1: 2004 | C1: 2005 | D1: 2006 | E1: 2007 | F1: 2008 | G1: 2009 | H1: 2010 | I1: 2011 | J1: 2012 | K1: 2013 | L1: 2014 | M1: 2015 | N1: 2016 | O1: 2017 | P1: 2018 | Q1: 2019 | R1: 2020 | S1: 2021 | T1: 2022 | U1: 2023 | V1: 2024 | W1: 2025 | X1: 2026 | Y1: 2027 | Z1: 2028 | AA1: 2029 | AB1: 2030 | AC1: 2031 | AD1: 2032 | AE1: 2033 | AF1: 2034 | AG1: 2035 | AH1: 2036 | AI1: 2037 | AJ1: 2038 | AK1: 2039 | AL1: 2040 | AM1: 2041 | AN1: 2042 | AO1: 2043 | AP1: 2044 | AQ1: 2045 | AR1: 2046 | AS1: 2047 | AT1: 2048 | AU1: 2049 | AV1: 2050
A2: NEWAUTO_ELEC_H01_1 | B2: 1.149299 | C2: 1.1677514 | D2: 2.1795284 | E2: 3.547016 | F2: 5.7123385 | G2: 9.1532957 | H2: 12.615338 | I2: 17.14676 | J2: 20.465819 | K2: 26.068457 | L2: 34.520713 | M2: 42.053287 | N2: 57.293884 | O2: 77.334793 | P2: 101.82701 | Q2: 131.38201 | R2: 142.42415 | S2: 157.17609 | T2: 197.20989 | U2: 245.22433 | V2: 291.13823 | W2: 336.90526 | X2: 436.40521 | Y2: 519.20602 | Z2: 600.30871 | AA2: 677.02292 | AB2: 748.55698 | AC2: 816.71218 | AD2: 838.45699 | AE2: 876.08867 | AF2: 917.71998 | AG2: 914.71055 | AH2: 979.21172 | AI2: 1029.4205 | AJ2: 1070.873 | AK2: 1107.4311 | AL2: 1139.4612 | AM2: 1160.2497 | AN2: 1184.2959 | AO2: 1210.3841 | AP2: 1236.0266 | AQ2: 1260.9109 | AR2: 1278.5939 | AS2: 1298.7024 | AT2: 1319.1199 | AU2: 1339.36 | AV2: 1360.017
A3: NEWAUTO_TH_H01_1 | B3: 2297.4487 | C3: 2334.335 | D3: 2370.8205 | E3: 2443.1306 | F3: 2418.5642 | G3: 2651.2106 | H3: 2586.2336 | I3: 2525.6757 | J3: 2173.6021 | K3: 2047.7565 | L3: 2044.8223 | M3: 1898.3337 | N3: 1985.0221 | O3: 2064.2932 | P3: 2101.915 | Q3: 2108.92 | R3: 1789.3354 | S3: 1557.3268 | T3: 1553.4291 | U3: 1549.745 | V3: 1491.1436 | W3: 1414.0827 | X3: 1519.1815 | Y3: 1517.8806 | Z3: 1492.6078 | AA3: 1449.66 | AB3: 1396.9915 | AC3: 1343.5623 | AD3: 1228.6922 | AE3: 1154.6411 | AF3: 1097.2699 | AG3: 999.95777 | AH3: 985.60912 | AI3: 959.98205 | AJ3: 930.40967 | AK3: 900.91807 | AL3: 871.84588 | AM3: 838.30036 | AN3: 810.91855 | AO3: 787.98095 | AP3: 767.30334 | AQ3: 748.38023 | AR3: 727.30298 | AS3: 709.56242 | AT3: 693.64079 | AU3: 679.07121 | AV3: 665.98317
A4: NEWAUTO_H01_1 | B4: 2298.598 | C4: 2335.5027 | D4: 2373 | E4: 2446.6776 | F4: 2424.2766 | G4: 2660.3639 | H4: 2598.849 | I4: 2542.8224 | J4: 2194.0679 | K4: 2073.825 | L4: 2079.343 | M4: 1940.387 | N4: 2042.316 | O4: 2141.628 | P4: 2203.742 | Q4: 2240.302 | R4: 1931.7595 | S4: 1714.5029 | T4: 1750.639 | U4: 1794.9694 | V4: 1782.2818 | W4: 1750.988 | X4: 1955.5868 | Y4: 2037.0867 | Z4: 2092.9165 | AA4: 2126.6829 | AB4: 2145.5485 | AC4: 2160.2745 | AD4: 2067.1492 | AE4: 2030.7298 | AF4: 2014.9898 | AG4: 1914.6683 | AH4: 1964.8208 | AI4: 1989.4025 | AJ4: 2001.2827 | AK4: 2008.3491 | AL4: 2011.3071 | AM4: 1998.55 | AN4: 1995.2145 | AO4: 1998.365 | AP4: 2003.33 | AQ4: 2009.2911 | AR4: 2005.8969 | AS4: 2008.2648 | AT4: 2012.7607 | AU4: 2018.4312 | AV4: 2026.0001
A5: PAUTO_ELEC_H01_1 | B5: 32.360331 | C5: 33.007538 | D5: 33.488809 | E5: 33.839494 | F5: 34.293416 | G5: 34.811247 | H5: 34.91417 | I5: 35.171003 | J5: 35.488543 | K5: 35.912137 | L5: 36.504035 | M5: 37.069763 | N5: 37.545288 | O5: 38.395762 | P5: 38.888451 | Q5: 39.418662 | R5: 40.067961 | S5: 40.604049 | T5: 40.697631 | U5: 41.005045 | V5: 41.561604 | W5: 42.127885 | X5: 42.702397 | Y5: 43.285092 | Z5: 43.876042 | AA5: 44.47524 | AB5: 45.083172 | AC5: 45.701113 | AD5: 46.329811 | AE5: 46.97022 | AF5: 47.623412 | AG5: 48.289918 | AH5: 48.969914 | AI5: 49.66366 | AJ5: 50.370978 | AK5: 51.091802 | AL5: 51.826328 | AM5: 52.544713 | AN5: 53.275889 | AO5: 54.019879 | AP5: 54.776991 | AQ5: 55.54754 | AR5: 56.332024 | AS5: 57.130734 | AT5: 57.943953 | AU5: 58.771982 | AV5: 59.616281
A6: PNEWAUTO_TH_H01_1 | B6: 21.704143 | C6: 22.138226 | D6: 22.417243 | E6: 22.83235 | F6: 22.906497 | G6: 23.386835 | H6: 23.514262 | I6: 23.605102 | J6: 23.817102 | K6: 24.147671 | L6: 24.706833 | M6: 25.200848 | N6: 25.668231 | O6: 26.364201 | P6: 26.547282 | Q6: 26.917385 | R6: 26.979834 | S6: 27.33753 | T6: 27.257914 | U6: 27.546627 | V6: 28.017065 | W6: 28.494237 | X6: 28.993492 | Y6: 29.503083 | Z6: 30.0186 | AA6: 30.540507 | AB6: 31.070022 | AC6: 31.608256 | AD6: 32.155336 | AE6: 32.714171 | AF6: 33.281408 | AG6: 33.860904 | AH6: 34.453812 | AI6: 35.0552 | AJ6: 35.671621 | AK6: 36.29989 | AL6: 36.940618 | AM6: 37.564976 | AN6: 38.199753 | AO6: 38.845735 | AP6: 39.502689 | AQ6: 40.170735 | AR6: 40.848734 | AS6: 41.538336 | AT6: 42.239856 | AU6: 42.953787 | AV6: 43.681095
A7: PNEWAUTO_H01_1 | B7: 21.709471 | C7: 22.143661 | D7: 22.427412 | E7: 22.848307 | F7: 22.933329 | G7: 23.426142 | H7: 23.5696 | I7: 23.683093 | J7: 23.92597 | K7: 24.295553 | L7: 24.902687 | M7: 25.458078 | N7: 26.001423 | O7: 26.798664 | P7: 27.117523 | Q7: 27.65052 | R7: 27.944791 | S7: 28.553731 | T7: 28.771901 | U7: 29.385283 | V7: 30.229585 | W7: 31.117469 | X7: 32.052747 | Y7: 33.015797 | Z7: 33.993313 | AA7: 34.976586 | AB7: 35.959047 | AC7: 36.936194 | AD7: 37.904649 | AE7: 38.864454 | AF7: 39.813423 | AG7: 40.754198 | AH7: 41.688231 | AI7: 42.614378 | AJ7: 43.537149 | AK7: 44.456352 | AL7: 45.373785 | AM7: 46.261398 | AN7: 47.148468 | AO7: 48.036519 | AP7: 48.92672 | AQ7: 49.820298 | AR7: 50.718055 | AS7: 51.62161 | AT7: 52.531982 | AU7: 53.450185 | AV7: 54.378095
A8: PCH_1 | B8: 0.96116878 | C8: 0.98039216 | D8: 0.98715712 | E8: 0.99036346 | F8: 1.0043122 | G8: 1.0057988 | H8: 1.0145862 | I8: 1.0232782 | J8: 1.032617 | K8: 1.0399768 | L8: 1.0501176 | M8: 1.0574685 | N8: 1.064722 | O8: 1.0798249 | P8: 1.1017374 | Q8: 1.1217746 | R8: 1.1440126 | S8: 1.1667712 | T8: 1.1905363 | U8: 1.2149769 | V8: 1.2399797 | W8: 1.2654671 | X8: 1.2907267 | Y8: 1.3160357 | Z8: 1.3415843 | AA8: 1.3673916 | AB8: 1.3935086 | AC8: 1.4200773 | AD8: 1.4467659 | AE8: 1.4742381 | AF8: 1.5023842 | AG8: 1.5308525 | AH8: 1.5605419 | AI8: 1.5907691 | AJ8: 1.6215977 | AK8: 1.6530092 | AL8: 1.6850182 | AM8: 1.7177333 | AN8: 1.7510721 | AO8: 1.78504 | AP8: 1.819655 | AQ8: 1.8549028 | AR8: 1.8908421 | AS8: 1.9275086 | AT8: 1.9648686 | AU8: 2.0029474 | AV8: 2.0420028
A9: AUTO_ELEC_H01_1 | B9: 2.3360541 | C9: 2.3735602 | D9: 2.4116685 | E9: 5.8260427 | F9: 11.217949 | G9: 19.754257 | H9: 31.283111 | I9: 46.7093 | J9: 64.606108 | K9: 87.121228 | L9: 116.85027 | M9: 152.4768 | N9: 201.38446 | O9: 268.65003 | P9: 357.04453 | Q9: 470.57431 | R9: 589.46975 | S9: 717.17235 | T9: 874.53933 | U9: 1068.3202 | V9: 1296.616 | W9: 1557.2498 | X9: 1902.052 | Y9: 2309.3727 | Z9: 2773.8359 | AA9: 3287.692 | AB9: 3842.8553 | AC9: 4433.5172 | AD9: 5011.1791 | AE9: 5592.4925 | AF9: 6181.2423 | AG9: 6732.3504 | AH9: 7315.5415 | AI9: 7914.636 | AJ9: 8519.9422 | AK9: 9126.2002 | AL9: 9728.8261 | AM9: 10313.406 | AN9: 10883.808 | AO9: 11442.467 | AP9: 11989.189 | AQ9: 12523.482 | AR9: 13038.449 | AS9: 13537.247 | AT9: 14020.734 | AU9: 14489.241 | AV9: 14943.68
A10: AUTO_TH_H01_1 | B10: 30996.094 | C10: 31493.746 | D10: 31999.389 | E10: 32682.553 | F10: 33303.577 | G10: 34123.091 | H10: 34832.554 | I10: 35442.44 | J10: 35666.707 | K10: 35752.795 | L10: 35831.214 | M10: 35758.831 | N10: 35777.117 | O10: 36052.554 | P10: 36351.842 | Q10: 36643.17 | R10: 36600.346 | S10: 36327.656 | T10: 35862.882 | U10: 35303.046 | V10: 34717.54 | W10: 34089.414 | X10: 33603.336 | Y10: 33144.55 | Z10: 32687.478 | AA10: 32214.345 | AB10: 31716.375 | AC10: 31194.269 | AD10: 30588.004 | AE10: 29943.351 | AF10: 29279.247 | AG10: 28556.896 | AH10: 27862.688 | AI10: 27183.688 | AJ10: 26515.057 | AK10: 25856.266 | AL10: 25207.155 | AM10: 24553.908 | AN10: 23903.284 | AO10: 23259.931 | AP10: 22626.034 | AQ10: 22003.139 | AR10: 21388.787 | AS10: 20786.154 | AT10: 20196.699 | AU10: 19621.317 | AV10: 19060.968
A11: AUTO_1 | B11: 30998.43 | C11: 31496.12 | D11: 32001.8 | E11: 32688.379 | F11: 33314.795 | G11: 34142.845 | H11: 34863.837 | I11: 35489.149 | J11: 35731.314 | K11: 35839.916 | L11: 35948.064 | M11: 35911.307 | N11: 35978.501 | O11: 36321.204 | P11: 36708.886 | Q11: 37113.744 | R11: 37189.816 | S11: 37044.828 | T11: 36737.421 | U11: 36371.366 | V11: 36014.156 | W11: 35646.664 | X11: 35505.388 | Y11: 35453.922 | Z11: 35461.314 | AA11: 35502.037 | AB11: 35559.231 | AC11: 35627.786 | AD11: 35599.183 | AE11: 35535.843 | AF11: 35460.489 | AG11: 35289.246 | AH11: 35178.229 | AI11: 35098.324 | AJ11: 35035 | AK11: 34982.466 | AL11: 34935.981 | AM11: 34867.313 | AN11: 34787.093 | AO11: 34702.398 | AP11: 34615.222 | AQ11: 34526.621 | AR11: 34427.236 | AS11: 34323.401 | AT11: 34217.433 | AU11: 34110.558 | AV11: 34004.648
A12: PENER_AUTOELEC_H01_CA_1 | B12: 0.25383749 | C12: 0.25891424 | D12: 0.25652822 | E12: 0.2632583 | F12: 0.26012564 | G12: 0.26053308 | H12: 0.26147498 | I12: 0.26226138 | J12: 0.26370216 | K12: 0.26522646 | L12: 0.26828614 | M12: 0.27155537 | N12: 0.27593021 | O12: 0.27923703 | P12: 0.28294175 | Q12: 0.28964151 | R12: 0.29904186 | S12: 0.3078615 | T12: 0.31713878 | U12: 0.32555112 | V12: 0.33650908 | W12: 0.34642302 | X12: 0.35276036 | Y12: 0.35910501 | Z12: 0.36546514 | AA12: 0.37201866 | AB12: 0.37859118 | AC12: 0.38504973 | AD12: 0.39391643 | AE12: 0.40306621 | AF12: 0.41202883 | AG12: 0.42361783 | AH12: 0.43285079 | AI12: 0.44221355 | AJ12: 0.45205593 | AK12: 0.46213309 | AL12: 0.47256152 | AM12: 0.48366692 | AN12: 0.49516768 | AO12: 0.50707924 | AP12: 0.51933954 | AQ12: 0.53195164 | AR12: 0.54516618 | AS12: 0.55887674 | AT12: 0.57277642 | AU12: 0.5869885 | AV12: 0.60153417
A13: PEXP_AUTO_H01_1 | B13: 0.96116878 | C13: 0.98039216 | D13: 0.98801884 | E13: 0.98669645 | F13: 1.0865767 | G13: 0.92641605 | H13: 1.006402 | I13: 1.1281116 | J13: 1.2272799 | K13: 1.2038813 | L13: 1.1516351 | M13: 1.0086765 | N13: 0.93008066 | O13: 1.0053342 | P13: 1.1682937 | Q13: 1.161239 | R13: 1.198542 | S13: 1.2390652 | T13: 1.2836593 | U13: 1.3335803 | V13: 1.3895946 | W13: 1.4519692 | X13: 1.4718601 | Y13: 1.4918798 | Z13: 1.5117038 | AA13: 1.531271 | AB13: 1.5505712 | AC13: 1.5692313 | AD13: 1.5876968 | AE13: 1.6059559 | AF13: 1.6239264 | AG13: 1.6416184 | AH13: 1.6590211 | AI13: 1.6759291 | AJ13: 1.6923399 | AK13: 1.7081466 | AL13: 1.723219 | AM13: 1.7530704 | AN13: 1.7834491 | AO13: 1.814317 | AP13: 1.8459358 | AQ13: 1.8784981 | AR13: 1.91551 | AS13: 1.9533956 | AT13: 1.9919377 | AU13: 2.0312262 | AV13: 2.0714168
... A44: BUIL_H01_CG_1 | B44: 1.8297097e+08 | C44: 1.8590863e+08 | D44: 188893454 | E44: 1.800399e+08 | F44: 1.7103185e+08 | G44: 1.6228071e+08 | H44: 154931207 | I44: 1.4786681e+08 | J44: 1.4048552e+08 | K44: 1.3272979e+08 | L44: 1.2536576e+08 | M44: 1.1900069e+08 | N44: 1.1407377e+08 | O44: 1.0969824e+08 | P44: 1.0510932e+08 | Q44: 99294803 | R44: 93330572 | S44: 87081895 | T44: 81129942 | U44: 75286529 | V44: 69986650 | W44: 64995939 | X44: 60709057 | Y44: 56928129 | Z44: 53527734 | AA44: 50429906 | AB44: 47582872 | AC44: 44950407 | AD44: 42505895 | AE44: 40223692 | AF44: 38084214 | AG44: 36074224 | AH44: 34181038 | AI44: 32393063 | AJ44: 30701659 | AK44: 29100207 | AL44: 27583327 | AM44: 26142497 | AN44: 24762422 | AO44: 23436976 | AP44: 22163575 | AQ44: 20941083 | AR44: 19768131 | AS44: 18642018 | AT44: 17561544 | AU44: 16526273 | AV44: 15536004
A45: BUIL_H01_DES_1 | C45: 2182612 | D45: 2217654.6 | E45: 2253259.7 | F45: 2197348 | G45: 2135517.6 | H45: 2073850.5 | I45: 2025887.2 | J45: 1978454.7 | K45: 1924316.5 | L45: 1863141.2 | M45: 1803611.1 | N45: 1753745.6 | O45: 1720550.5 | P45: 1692851.5 | Q45: 1659938.1 | R45: 1607861.2 | S45: 1600180.9 | T45: 1582221.9 | U45: 1561512.8 | V45: 1535440.8 | W45: 1511719.1 | X45: 1487546.1 | Y45: 1470747 | Z45: 1460304.2 | AA45: 1452832 | AB45: 1447319.2 | AC45: 1443131 | AD45: 1439867.2 | AE45: 1437276.5 | AF45: 1435067.5 | AG45: 1433032.4 | AH45: 1431077 | AI45: 1429083.9 | AJ45: 1426942.5 | AK45: 1424577.2 | AL45: 1421944.4 | AM45: 1419028.9 | AN45: 1415663.3 | AO45: 1411326.4 | AP45: 1405812 | AQ45: 1399061.6 | AR45: 1391084.8 | AS45: 1381880.2 | AT45: 1371366.7 | AU45: 1359546.5 | AV45: 1346479.4
A46: REHAB_H01_1 | B46: 27240235 | C46: 27677586 | D46: 28121958 | E46: 39354810 | F46: 45364406 | G46: 45516119 | H46: 35070344 | I46: 35012114 | J46: 39899401 | K46: 46533664 | L46: 46964548 | M46: 41281813 | N46: 28952518 | O46: 30282525 | P46: 37773608 | Q46: 62400636 | R46: 69799680 | S46: 83652349 | T46: 84518164 | U46: 92015110 | V46: 86066225 | W46: 86536359 | X46: 71165919 | Y46: 62420843 | Z46: 57576384 | AA46: 54921959 | AB46: 53550860 | AC46: 52854576 | AD46: 52471596 | AE46: 52426343 | AF46: 52572922 | AG46: 52697743 | AH46: 52897932 | AI46: 53137577 | AJ46: 53468504 | AK46: 53944496 | AL46: 54514948 | AM46: 55318467 | AN46: 56624760 | AO46: 58166785 | AP46: 59820487 | AQ46: 61506465 | AR46: 63217691 | AS46: 65025231 | AT46: 66858082 | AU46: 68601149 | AV46: 70221997
A47: PREHAB_H01_1 | B47: 0.00017092114 | C47: 0.00017433956 | D47: 0.00017633719 | E47: 0.00014003564 | F47: 0.00014683287 | G47: 0.00015141592 | H47: 0.00015511363 | I47: 0.00015050677 | J47: 0.00016363455 | K47: 0.00015928559 | L47: 0.00015397907 | M47: 0.00014433845 | N47: 0.00013845886 | O47: 0.00011055861 | P47: 0.00012352136 | Q47: 0.00011079756 | R47: 0.00013276872 | S47: 0.00011200677 | T47: 0.00013078063 | U47: 0.0001291518 | V47: 0.00015380977 | W47: 0.00014424135 | X47: 0.00018738453 | Y47: 0.00017601744 | Z47: 0.00017751826 | AA47: 0.00017875099 | AB47: 0.00017993094 | AC47: 0.00018126419 | AD47: 0.00018280753 | AE47: 0.00018462048 | AF47: 0.00018671268 | AG47: 0.00018906178 | AH47: 0.00019164298 | AI47: 0.00019446954 | AJ47: 0.00019749818 | AK47: 0.00020069703 | AL47: 0.00020406877 | AM47: 0.00020766518 | AN47: 0.00021169769 | AO47: 0.00021599659 | AP47: 0.00022047744 | AQ47: 0.00022511854 | AR47: 0.0002299376 | AS47: 0.00023497223 | AT47: 0.00024019504 | AU47: 0.00024559014 | AV47: 0.00025119817
A48: RENOV_VAL_1 | B48: 4655.932 | C48: 4825.2982 | D48: 4958.9473 | E48: 6685.0332 | F48: 8079.8942 | G48: 8204.6011 | H48: 6325.4515 | I48: 6303.711 | J48: 7395.6572 | K48: 8536.6752 | L48: 8693.9841 | M48: 7712.534 | N48: 5313.4787 | O48: 5170.6902 | P48: 6806.4049 | Q48: 11316.814 | R48: 13348.567 | S48: 15518.483 | T48: 16503.877 | U48: 17540.8 | V48: 16544.131 | W48: 15854.552 | X48: 13335.392 | Y48: 10987.157 | Z48: 10220.86 | AA48: 9817.3545 | AB48: 9635.4569 | AC48: 9580.6417 | AD48: 9592.2028 | AE48: 9678.9763 | AF48: 9816.0312 | AG48: 9963.1292 | AH48: 10137.517 | AI48: 10333.64 | AJ48: 10559.932 | AK48: 10826.5 | AL48: 11124.798 | AM48: 11487.719 | AN48: 11987.331 | AO48: 12563.827 | AP48: 13189.068 | AQ48: 13846.246 | AR48: 14536.124 | AS48: 15279.124 | AT48: 16058.979 | AU48: 16847.766 | AV48: 17639.637
A49: SUB_RENOV_VAL_1 | B49: 0 | C49: 0 | D49: 0 | E49: 1173.9571 | F49: 1418.9082 | G49: 1312.7362 | H49: 885.56321 | I49: 778.65691 | J49: 616.14297 | K49: 878.41651 | L49: 1198.0624 | M49: 1550.8859 | N49: 968.05518 | O49: 1025.6624 | P49: 872.60071 | Q49: 1541.5524 | R49: 1535.9671 | S49: 3033.2484 | T49: 2272.6217 | U49: 2415.4084 | V49: 0 | W49: 0 | X49: 0 | Y49: 0 | Z49: 0 | AA49: 0 | AB49: 0 | AC49: 0 | AD49: 0 | AE49: 0 | AF49: 0 | AG49: 0 | AH49: 0 | AI49: 0 | AJ49: 0 | AK49: 0 | AL49: 0 | AM49: 0 | AN49: 0 | AO49: 0 | AP49: 0 | AQ49: 0 | AR49: 0 | AS49: 0 | AT49: 0 | AU49: 0 | AV49: 0
A50: R_SUB_CEE_H01_CF_CA_1 | B50: 0 | C50: 0 | D50: 0 | E50: 0 | F50: 0 | G50: 0 | H50: 0 | I50: 0.040530719 | J50: 0.033883896 | K50: 0.028830481 | L50: 0.03040774 | M50: 0.02633315 | N50: 0.06336543 | O50: 0.15414461 | P50: 0.18628877 | Q50: 0.25284707 | R50: 0.19068605 | S50: 0.20076736 | T50: 0.19255578 | U50: 0.18479631 | V50: 0.19984759 | W50: 0.21271057 | X50: 0 | Y50: 0 | Z50: 0 | AA50: 0 | AB50: 0 | AC50: 0 | AD50: 0 | AE50: 0 | AF50: 0 | AG50: 0 | AH50: 0 | AI50: 0 | AJ50: 0 | AK50: 0 | AL50: 0 | AM50: 0 | AN50: 0 | AO50: 0 | AP50: 0 | AQ50: 0 | AR50: 0 | AS50: 0 | AT50: 0 | AU50: 0 | AV50: 0
A51: ER_TERTIARY_1 | B51: 21.072807 | C51: 21.411137 | D51: 21.7549 | E51: 23.111168 | F51: 23.885852 | G51: 23.444481 | H51: 24.603056 | I51: 25.441776 | J51: 25.783656 | K51: 26.232663 | L51: 27.090239 | M51: 28.31981 | N51: 27.949439 | O51: 27.547144 | P51: 26.801156 | Q51: 25.826825 | R51: 25.021981 | S51: 25.034436 | T51: 25.010957 | U51: 24.998994 | V51: 25.182672 | W51: 25.408836 | X51: 25.569184 | Y51: 25.682776 | Z51: 25.764489 | AA51: 25.819159 | AB51: 25.850019 | AC51: 25.861495 | AD51: 25.848674 | AE51: 25.8123 | AF51: 25.764021 | AG51: 25.701683 | AH51: 25.621796 | AI51: 25.529929 | AJ51: 25.42513 | AK51: 25.309382 | AL51: 25.183195 | AM51: 24.912207 | AN51: 24.615317 | AO51: 24.313775 | AP51: 24.0125 | AQ51: 23.712359 | AR51: 23.414926 | AS51: 23.119103 | AT51: 22.825638 | AU51: 22.534187 | AV51: 22.244617
A52: ER_TERTIARY_COAL_1 | B52: 0 | C52: 0 | D52: 0 | E52: 0 | F52: 0 | G52: 0 | H52: 0 | I52: 0 | J52: 0 | K52: 0 | L52: 0 | M52: 0 | N52: 0 | O52: 0 | P52: 0 | Q52: 0 | R52: 0 | S52: 0 | T52: 0 | U52: 0 | V52: 0 | W52: 0 | X52: 0 | Y52: 0 | Z52: 0 | AA52: 0 | AB52: 0 | AC52: 0 | AD52: 0 | AE52: 0 | AF52: 0 | AG52: 0 | AH52: 0 | AI52: 0 | AJ52: 0 | AK52: 0 | AL52: 0 | AM52: 0 | AN52: 0 | AO52: 0 | AP52: 0 | AQ52: 0 | AR52: 0 | AS52: 0 | AT52: 0 | AU52: 0 | AV52: 0
A53: ER_TERTIARY_OIL_1 | B53: 4.6065844 | C53: 4.6805446 | D53: 4.7556923 | E53: 4.8584285 | F53: 4.6740887 | G53: 4.613069 | H53: 4.5416749 | I53: 4.34262 | J53: 4.1268973 | K53: 4.0489182 | L53: 4.0627365 | M53: 4.1781675 | N53: 3.9170705 | O53: 3.6404446 | P53: 3.4042399 | Q53: 3.2198847 | R53: 3.0142307 | S53: 3.0092941 | T53: 3.0128964 | U53: 3.0144777 | V53: 2.9186239 | W53: 2.8147547 | X53: 2.7241297 | Y53: 2.6426243 | Z53: 2.5674745 | AA53: 2.4977719 | AB53: 2.4327476 | AC53: 2.3715018 | AD53: 2.3146738 | AE53: 2.2621251 | AF53: 2.2119048 | AG53: 2.1643703 | AH53: 2.1199207 | AI53: 2.0777417 | AJ53: 2.0380682 | AK53: 2.000482 | AL53: 1.9649022 | AM53: 1.9562959 | AN53: 1.9526402 | AO53: 1.9499118 | AP53: 1.9471789 | AQ53: 1.944281 | AR53: 1.9408812 | AS53: 1.9372527 | AT53: 1.9332059 | AU53: 1.9288109 | AV53: 1.9240909
A54: ER_TERTIARY_ELEC_1 | B54: 10.826676 | C54: 11.000502 | D54: 11.177119 | E54: 11.887835 | F54: 12.504639 | G54: 11.787154 | H54: 12.310258 | I54: 12.871045 | J54: 13.217653 | K54: 13.280641 | L54: 13.295465 | M54: 13.068313 | N54: 12.451329 | O54: 12.503449 | P54: 12.948172 | Q54: 12.810045 | R54: 12.634897 | S54: 12.736727 | T54: 12.766863 | U54: 12.803145 | V54: 13.078122 | W54: 13.396181 | X54: 13.614864 | Y54: 13.793156 | Z54: 13.941159 | AA54: 14.060246 | AB54: 14.15687 | AC54: 14.236272 | AD54: 14.302971 | AE54: 14.356875 | AF54: 14.400023 | AG54: 14.431494 | AH54: 14.456883 | AI54: 14.472666 | AJ54: 14.475275 | AK54: 14.468025 | AL54: 14.45054 | AM54: 14.31593 | AN54: 14.155715 | AO54: 13.989369 | AP54: 13.821598 | AQ54: 13.653065 | AR54: 13.486661 | AS54: 13.319006 | AT54: 13.152783 | AU54: 12.987435 | AV54: 12.822939
A55: ER_TERTIARY_GAS_1 | B55: 5.6395461 | C55: 5.7300908 | D55: 5.8220893 | E55: 6.3649049 | F55: 6.7071242 | G55: 7.0442581 | H55: 7.7511234 | I55: 8.2281112 | J55: 8.4391064 | K55: 8.9031038 | L55: 9.7320375 | M55: 11.07333 | N55: 11.581039 | O55: 11.403251 | P55: 10.448744 | Q55: 9.7968949 | R55: 9.3728535 | S55: 9.2884151 | T55: 9.2311979 | U55: 9.1813715 | V55: 9.1859254 | W55: 9.1979005 | X55: 9.23019 | Y55: 9.2469959 | Z55: 9.2558549 | AA55: 9.2611403 | AB55: 9.2604014 | AC55: 9.2537216 | AD55: 9.2310294 | AE55: 9.1932992 | AF55: 9.1520934 | AG55: 9.1058186 | AH55: 9.0449923 | AI55: 8.9795209 | AJ55: 8.9117866 | AK55: 8.8408747 | AL55: 8.7677531 | AM55: 8.6399813 | AN55: 8.5069617 | AO55: 8.3744945 | AP55: 8.243723 | AQ55: 8.1150126 | AR55: 7.9873832 | AS55: 7.8628446 | AT55: 7.7396486 | AU55: 7.6179417 | AV55: 7.4975879
A56: EMS_SEC_TOT_19_1 | B56: 20640521 | C56: 20971911 | D56: 21313933 | E56: 22206970 | F56: 21946561 | G56: 21680617 | H56: 22244065 | I56: 22089159 | J56: 21448171 | K56: 21467673 | L56: 22211890 | M56: 23793446 | N56: 23724535 | O56: 22820726 | P56: 21088588 | Q56: 19827775 | R56: 18787404 | S56: 18229321 | T56: 17715657 | U56: 17201328 | V56: 17463053 | W56: 17696752 | X56: 17435693 | Y56: 17173619 | Z56: 16913993 | AA56: 16657440 | AB56: 16402893 | AC56: 16164193 | AD56: 15917633 | AE56: 15664513 | AF56: 15411216 | AG56: 15159308 | AH56: 14950461 | AI56: 14742103 | AJ56: 14537324 | AK56: 14333466 | AL56: 14132316 | AM56: 13921122 | AN56: 13716845 | AO56: 13516877 | AP56: 13320356 | AQ56: 13127259 | AR56: 12934343 | AS56: 12745479 | AT56: 12558478 | AU56: 12373612 | AV56: 12190772
A57: EMS_SEC_TOT_20_1 | B57: 5733144.5 | C57: 5825191.9 | D57: 5919233.7 | E57: 6053525.2 | F57: 6003086.6 | G57: 6290808 | H57: 6414227.9 | I57: 6373952.7 | J57: 6246017.5 | K57: 6309819 | L57: 6515336.1 | M57: 6967670.1 | N57: 7036455.2 | O57: 6747901.3 | P57: 6121807.8 | Q57: 5688631.4 | R57: 5357163.9 | S57: 5121868.2 | T57: 4905286.8 | U57: 4687526.9 | V57: 4833942.8 | W57: 4962523.7 | X57: 4864708.3 | Y57: 4768675.8 | Z57: 4675395.5 | AA57: 4584687.6 | AB57: 4495960.4 | AC57: 4414549.3 | AD57: 4331124.2 | AE57: 4246093.9 | AF57: 4161693.2 | AG57: 4078459.1 | AH57: 4013103.9 | AI57: 3948242.1 | AJ57: 3884900.2 | AK57: 3822058.2 | AL57: 3760357.9 | AM57: 3694346.8 | AN57: 3630528.4 | AO57: 3568076 | AP57: 3506723.1 | AQ57: 3446479.2 | AR57: 3386205.8 | AS57: 3327271.8 | AT57: 3268927.7 | AU57: 3211270.8 | AV57: 3154268.5
... A562: I_MDE_14_1 | B562: 528.06275 | C562: 536.54097 | D562: 509.09232 | E562: 725.67716 | F562: 692.31355 | G562: 505.49928 | H562: 764.92789 | I562: 921.48445 | J562: 889.35546 | K562: 842.51177 | L562: 822.04169 | M562: 863.35214 | N562: 479.51703 | O562: 841.13881 | P562: 899.10766 | Q562: 753.75232 | R562: 852.06465 | S562: 6504.2346 | T562: 5016.7551 | U562: 5365.7591 | V562: 4493.54 | W562: 3994.514 | X562: 4689.3872 | Y562: 4755.3001 | Z562: 4826.4177 | AA562: 4782.2808 | AB562: 4830.0905 | AC562: 4829.267 | AD562: 4751.7322 | AE562: 4833.641 | AF562: 4916.221 | AG562: 4917.6575 | AH562: 5111.2441 | AI562: 5173.9206 | AJ562: 5125.9716 | AK562: 5153.3403 | AL562: 5157.9294 | AM562: 5196.7662 | AN562: 5247.5903 | AO562: 5224.3293 | AP562: 5239.3607 | AQ562: 5250.4846 | AR562: 5278.8864 | AS562: 5319.2347 | AT562: 5362.2643 | AU562: 5383.0866 | AV562: 5421.9021
A563: I_MDE_15_1 | C563: 25.563692 | D563: 27.174516 | E563: 59.014301 | F563: 62.266563 | G563: 66.091101 | H563: 70.100616 | I563: 75.499498 | J563: 75.503546 | K563: 76.823477 | L563: 85.080937 | M563: 75.917302 | N563: 53.370951 | O563: 87.446867 | P563: 94.174744 | Q563: 232.53303 | R563: 297.98834 | S563: 401.08835 | T563: 353.0158 | U563: 304.43347 | V563: 270.61017 | W563: 742.62923 | X563: 680.48022 | Y563: 697.19692 | Z563: 722.97782 | AA563: 747.34089 | AB563: 771.66041 | AC563: 826.85488 | AD563: 834.65145 | AE563: 871.7986 | AF563: 905.1375 | AG563: 914.57744 | AH563: 803.99839 | AI563: 824.32767 | AJ563: 846.44997 | AK563: 870.55733 | AL563: 893.6645 | AM563: 699.92397 | AN563: 714.94252 | AO563: 728.334 | AP563: 740.6741 | AQ563: 751.75805 | AR563: 611.47624 | AS563: 614.95113 | AT563: 617.72457 | AU563: 620.31598 | AV563: 624.90315
A564: I_MDE_16_1 | C564: 32.611451 | D564: 37.137185 | E564: 37.560493 | F564: 59.347566 | G564: 80.304664 | H564: 101.93379 | I564: 120.87487 | J564: 153.7942 | K564: 186.91817 | L564: 217.76751 | M564: 263.26599 | N564: 260.33005 | O564: 337.82378 | P564: 334.0845 | Q564: 416.89997 | R564: 452.97004 | S564: 1333.6678 | T564: 1193.0527 | U564: 1131.8637 | V564: 997.63448 | W564: 2781.0417 | X564: 3554.4028 | Y564: 3794.0071 | Z564: 4026.8878 | AA564: 4267.5324 | AB564: 4524.7079 | AC564: 5723.7094 | AD564: 6034.1034 | AE564: 6369.2728 | AF564: 6708.0625 | AG564: 7065.57 | AH564: 6684.5884 | AI564: 7021.4955 | AJ564: 7379.8842 | AK564: 7738.4065 | AL564: 8090.0374 | AM564: 6315.886 | AN564: 6573.007 | AO564: 6760.6486 | AP564: 6973.225 | AQ564: 7154.8571 | AR564: 5882.0359 | AS564: 5934.6851 | AT564: 6010.1736 | AU564: 6084.3229 | AV564: 6189.2132
A565: I_MDE_17_1 | B565: 534.35075 | C565: 542.92993 | D565: 546.81091 | E565: 569.83881 | F565: 606.47755 | G565: 368.21115 | H565: 525.58189 | I565: 605.3048 | J565: 589.55305 | K565: 581.06324 | L565: 586.84064 | M565: 640.91957 | N565: 605.51066 | O565: 716.90508 | P565: 776.56361 | Q565: 732.32542 | R565: 712.94488 | S565: 687.30827 | T565: 692.54602 | U565: 708.23915 | V565: 716.52052 | W565: 722.53176 | X565: 722.63608 | Y565: 729.38726 | Z565: 738.3557 | AA565: 747.77576 | AB565: 758.23405 | AC565: 766.70001 | AD565: 776.04097 | AE565: 786.47305 | AF565: 798.07382 | AG565: 811.04756 | AH565: 825.8568 | AI565: 842.1083 | AJ565: 858.86135 | AK565: 876.51073 | AL565: 894.3283 | AM565: 913.94677 | AN565: 933.79361 | AO565: 953.3311 | AP565: 972.94737 | AQ565: 992.51623 | AR565: 1012.8738 | AS565: 1033.1152 | AT565: 1053.8184 | AU565: 1074.8286 | AV565: 1096.5855
A566: I_MDE_18_1 | B566: 970.42802 | C566: 986.00856 | D566: 991.19398 | E566: 1069.1726 | F566: 1193.4499 | G566: 752.11733 | H566: 1072.1105 | I566: 1256.8962 | J566: 1230.0432 | K566: 1187.1796 | L566: 1113.3729 | M566: 1149.7972 | N566: 1051.2057 | O566: 1345.4529 | P566: 1484.6629 | Q566: 1386.3185 | R566: 1345.9331 | S566: 1313.5488 | T566: 1307.8935 | U566: 1312.1658 | V566: 1329.1598 | W566: 1341.4787 | X566: 1296.8359 | Y566: 1287.9037 | Z566: 1292.9133 | AA566: 1299.6553 | AB566: 1306.6876 | AC566: 1309.9035 | AD566: 1311.1313 | AE566: 1314.8671 | AF566: 1320.2512 | AG566: 1327.222 | AH566: 1337.537 | AI566: 1349.2907 | AJ566: 1359.5044 | AK566: 1370.5454 | AL566: 1380.5823 | AM566: 1405.1601 | AN566: 1419.0006 | AO566: 1430.2082 | AP566: 1441.1104 | AQ566: 1451.1328 | AR566: 1452.7581 | AS566: 1459.2587 | AT566: 1466.4956 | AU566: 1473.4788 | AV566: 1480.8595
A567: ER_COAL_1 | B567: 5.570579 | C567: 5.6600164 | D567: 5.7508898 | E567: 5.7929036 | F567: 4.8242806 | G567: 4.2185211 | H567: 4.084085 | I567: 3.8991141 | J567: 3.7615492 | K567: 4.0026494 | L567: 4.0988615 | M567: 4.1630921 | N567: 3.2553048 | O567: 2.7334405 | P567: 2.3991506 | Q567: 2.1834951 | R567: 1.9973772 | S567: 2.0030384 | T567: 1.9618528 | U567: 1.9451373 | V567: 1.91255 | W567: 1.8640023 | X567: 1.8554258 | Y567: 1.8721113 | Z567: 1.8944213 | AA567: 1.9199594 | AB567: 1.9494204 | AC567: 1.9504081 | AD567: 1.9567921 | AE567: 1.9647827 | AF567: 1.9740917 | AG567: 1.986342 | AH567: 2.0001071 | AI567: 2.0145604 | AJ567: 2.03095 | AK567: 2.0482868 | AL567: 2.065978 | AM567: 2.0579387 | AN567: 2.046346 | AO567: 2.0317768 | AP567: 2.0159639 | AQ567: 1.9975455 | AR567: 1.9951071 | AS567: 1.994435 | AT567: 1.993777 | AU567: 1.9927857 | AV567: 1.9924393
A568: ER_OIL_2201_1 | B568: 77.477679 | C568: 78.721608 | D568: 80.00373 | E568: 80.189475 | F568: 76.950267 | G568: 74.603074 | H568: 73.063966 | I568: 71.285518 | J568: 69.186514 | K568: 67.614613 | L568: 67.318829 | M568: 67.648774 | N568: 66.103925 | O568: 64.464309 | P568: 62.191245 | Q568: 60.914616 | R568: 59.282102 | S568: 58.819585 | T568: 57.857999 | U568: 57.140669 | V568: 56.29937 | W568: 55.173092 | X568: 54.512926 | Y568: 54.128834 | Z568: 53.856553 | AA568: 53.650891 | AB568: 53.520664 | AC568: 52.960715 | AD568: 52.421773 | AE568: 51.903042 | AF568: 51.398656 | AG568: 50.908673 | AH568: 50.535956 | AI568: 50.189798 | AJ568: 49.874339 | AK568: 49.581325 | AL568: 49.301862 | AM568: 49.002877 | AN568: 48.708631 | AO568: 48.40791 | AP568: 48.115104 | AQ568: 47.81666 | AR568: 47.695796 | AS568: 47.592621 | AT568: 47.501982 | AU568: 47.421731 | AV568: 47.369434
A569: ER_OIL_2202_1 | B569: 0.67805251 | C569: 0.68893886 | D569: 0.66746531 | E569: 1.0023107 | F569: 1.2829737 | G569: 1.5564776 | H569: 1.8318169 | I569: 2.0884318 | J569: 2.3204771 | K569: 2.555809 | L569: 2.832603 | M569: 3.1370651 | N569: 3.1170784 | O569: 3.0934185 | P569: 3.0395931 | Q569: 3.0350888 | R569: 3.0141586 | S569: 3.1567748 | T569: 3.2641188 | U569: 3.3763985 | V569: 3.4835503 | W569: 3.5749335 | X569: 3.53197 | Y569: 3.5068862 | Z569: 3.4890369 | AA569: 3.4766189 | AB569: 3.4691425 | AC569: 3.4297875 | AD569: 3.3916918 | AE569: 3.3547916 | AF569: 3.3191882 | AG569: 3.2843966 | AH569: 3.2618467 | AI569: 3.2410665 | AJ569: 3.2223303 | AK569: 3.2045297 | AL569: 3.1876547 | AM569: 3.1804792 | AN569: 3.1739363 | AO569: 3.1673155 | AP569: 3.1615781 | AQ569: 3.155859 | AR569: 3.1642321 | AS569: 3.1740729 | AT569: 3.1850647 | AU569: 3.1970877 | AV569: 3.2113558
A570: ER_ELEC_2301_1 | B570: 28.634797 | C570: 29.094538 | D570: 29.720948 | E570: 30.52551 | F570: 31.195934 | G570: 29.010321 | H570: 30.081874 | I570: 31.084929 | J570: 31.401742 | K570: 31.225922 | L570: 31.043343 | M570: 30.417636 | N570: 28.689727 | O570: 28.16767 | P570: 28.076537 | Q570: 27.095231 | R570: 26.128889 | S570: 26.107046 | T570: 25.987033 | U570: 25.997111 | V570: 26.913215 | W570: 27.877809 | X570: 27.952276 | Y570: 28.069737 | Z570: 28.203491 | AA570: 28.418866 | AB570: 28.658586 | AC570: 28.348215 | AD570: 28.057527 | AE570: 27.770024 | AF570: 27.456182 | AG570: 27.149444 | AH570: 26.764746 | AI570: 26.379998 | AJ570: 25.989665 | AK570: 25.565523 | AL570: 25.132998 | AM570: 24.670229 | AN570: 24.203396 | AO570: 23.728973 | AP570: 23.253397 | AQ570: 22.772367 | AR570: 22.171953 | AS570: 21.561739 | AT570: 20.949909 | AU570: 20.33612 | AV570: 19.727952
A571: ER_ELEC_2302_1 | B571: 0.3674935 | C571: 0.37339372 | D571: 0.38143295 | E571: 0.37117253 | F571: 0.35939186 | G571: 0.31665047 | H571: 0.31109271 | I571: 0.30457354 | J571: 0.29150996 | K571: 0.27464537 | L571: 0.25869191 | M571: 0.24015806 | N571: 0.20849842 | O571: 0.18561328 | P571: 0.16441312 | Q571: 0.13707606 | R571: 0.1094941 | S571: 0.14544881 | T571: 0.18182678 | U571: 0.22018257 | V571: 0.23134827 | W571: 0.2427947 | X571: 0.24194868 | Y571: 0.24145254 | Z571: 0.24107083 | AA571: 0.2413657 | AB571: 0.24183777 | AC571: 0.24700557 | AD571: 0.25232996 | AE571: 0.25767409 | AF571: 0.26319354 | AG571: 0.26877911 | AH571: 0.26840178 | AI571: 0.26803281 | AJ571: 0.26761562 | AK571: 0.26702013 | AL571: 0.26634458 | AM571: 0.27117357 | AN571: 0.27597204 | AO571: 0.28069402 | AP571: 0.28540923 | AQ571: 0.29006176 | AR571: 0.29179369 | AS571: 0.2933964 | AT571: 0.29497158 | AU571: 0.29651137 | AV571: 0.29812658
A572: ER_ELEC_2303_1 | B572: 1.4676116 | C572: 1.4911746 | D572: 1.5232798 | E572: 1.5667914 | F572: 1.6035313 | G572: 1.4933554 | H572: 1.5507677 | I572: 1.6048075 | J572: 1.6235214 | K572: 1.6167793 | L572: 1.6096637 | M572: 1.5795135 | N572: 1.6684922 | O572: 1.8274882 | P572: 2.0258946 | Q572: 2.1692357 | R572: 2.3169547 | S572: 2.2378991 | T572: 2.1483525 | U572: 2.0672767 | V572: 1.3717159 | W572: 0.70932612 | X572: 0.71216301 | Y572: 0.71610931 | Z572: 0.72048751 | AA572: 0.7269392 | AB572: 0.7340318 | AC572: 0.74108576 | AD572: 0.74862553 | AE572: 0.75623314 | AF572: 0.76393767 | AG572: 0.77183605 | AH572: 0.77970675 | AI572: 0.78762463 | AJ572: 0.79542249 | AK572: 0.80311017 | AL572: 0.81057558 | AM572: 0.81637412 | AN572: 0.82206829 | AO572: 0.82752611 | AP572: 0.83295831 | AQ572: 0.83820422 | AR572: 1.1515195 | AS572: 1.4643167 | AT572: 1.7768059 | AU572: 2.0888496 | AV572: 2.4012366
A573: ER_ELEC_2304_1 | B573: 1.4643634 | C573: 1.4878742 | D573: 1.5199084 | E573: 1.4374556 | F573: 1.3527148 | G573: 1.1583439 | H573: 1.1060293 | I573: 1.0524182 | J573: 0.97896903 | K573: 0.89641111 | L573: 0.82061072 | M573: 0.74040767 | N573: 0.62013914 | O573: 0.52598398 | P573: 0.43486356 | Q573: 0.32594416 | R573: 0.21581314 | S573: 0.2083253 | T573: 0.19985741 | U573: 0.19217359 | V573: 0.12628916 | W573: 0.063535037 | X573: 0.06376655 | Y573: 0.064097062 | Z573: 0.064465845 | AA573: 0.065019861 | AB573: 0.065630757 | AC573: 0.066244766 | AD573: 0.066902231 | AE573: 0.067565777 | AF573: 0.068236798 | AG573: 0.068925139 | AH573: 0.06962487 | AI573: 0.070328805 | AJ573: 0.071022017 | AK573: 0.071705229 | AL573: 0.072368589 | AM573: 0.072883283 | AN573: 0.073388656 | AO573: 0.073872926 | AP573: 0.074354907 | AQ573: 0.074820258 | AR573: 0.075005586 | AS573: 0.075157705 | AT573: 0.075302916 | AU573: 0.075439288 | AV573: 0.075595007
A574: ER_ELEC_2305_1 | B574: 0.29584764 | C574: 0.30059757 | D574: 0.30706949 | E574: 0.65474226 | F574: 0.98938789 | G574: 1.1913305 | H574: 1.4861652 | I574: 1.7591862 | J574: 1.9607947 | K574: 2.0825344 | L574: 2.1417785 | M574: 2.0949807 | N574: 2.2292512 | O574: 2.4570621 | P574: 2.7386938 | Q574: 2.946486 | R574: 3.1604122 | S574: 3.3567812 | T574: 3.5458839 | U574: 3.7586318 | V574: 4.1643559 | W574: 4.5666652 | X574: 4.9020657 | Y574: 5.249818 | Z574: 5.6061819 | AA574: 5.8748008 | AB574: 6.1527722 | AC574: 6.5163186 | AD574: 6.8835649 | AE574: 7.2511015 | AF574: 7.6348685 | AG574: 8.0205018 | AH574: 8.4223877 | AI574: 8.8255907 | AJ574: 9.2282065 | AK574: 9.6440123 | AL574: 10.057781 | AM574: 10.467129 | AN574: 10.875616 | AO574: 11.281307 | AP574: 11.686869 | AQ574: 12.089951 | AR574: 12.463137 | AS574: 12.830797 | AT574: 13.197085 | AU574: 13.561564 | AV574: 13.929308
...

Sheet Variables AMS
B1: 2004 | C1: 2005 | D1: 2006 | E1: 2007 | F1: 2008 | G1: 2009 | H1: 2010 | I1: 2011 | J1: 2012 | K1: 2013 | L1: 2014 | M1: 2015 | N1: 2016 | O1: 2017 | P1: 2018 | Q1: 2019 | R1: 2020 | S1: 2021 | T1: 2022 | U1: 2023 | V1: 2024 | W1: 2025 | X1: 2026 | Y1: 2027 | Z1: 2028 | AA1: 2029 | AB1: 2030 | AC1: 2031 | AD1: 2032 | AE1: 2033 | AF1: 2034 | AG1: 2035 | AH1: 2036 | AI1: 2037 | AJ1: 2038 | AK1: 2039 | AL1: 2040 | AM1: 2041 | AN1: 2042 | AO1: 2043 | AP1: 2044 | AQ1: 2045 | AR1: 2046 | AS1: 2047 | AT1: 2048 | AU1: 2049 | AV1: 2050
A2: NEWAUTO_ELEC_H01_2 | B2: 1.149299 | C2: 1.1677514 | D2: 2.1795284 | E2: 3.547016 | F2: 5.7123385 | G2: 9.1532957 | H2: 12.615338 | I2: 17.14676 | J2: 20.465819 | K2: 26.068457 | L2: 34.520713 | M2: 42.053287 | N2: 57.293884 | O2: 77.334793 | P2: 101.82701 | Q2: 131.38201 | R2: 142.42415 | S2: 157.17609 | T2: 197.20989 | U2: 245.53125 | V2: 369.10544 | W2: 467.08336 | X2: 484.44787 | Y2: 574.74716 | Z2: 729.25581 | AA2: 895.88404 | AB2: 1062.3645 | AC2: 1208.5317 | AD2: 1327.0612 | AE2: 1404.8546 | AF2: 1450.4285 | AG2: 1472.5615 | AH2: 1519.8902 | AI2: 1546.967 | AJ2: 1553.6848 | AK2: 1555.8917 | AL2: 1547.8555 | AM2: 1537.3043 | AN2: 1523.7276 | AO2: 1509.0834 | AP2: 1492.8133 | AQ2: 1522.8212 | AR2: 1523.8903 | AS2: 1517.1944 | AT2: 1508.3881 | AU2: 1495.812 | AV2: 1465.3582
A3: NEWAUTO_TH_H01_2 | B3: 2297.4487 | C3: 2334.335 | D3: 2370.8205 | E3: 2443.1306 | F3: 2418.5642 | G3: 2651.2106 | H3: 2586.2336 | I3: 2525.6757 | J3: 2173.6021 | K3: 2047.7565 | L3: 2044.8223 | M3: 1898.3337 | N3: 1985.0221 | O3: 2064.2932 | P3: 2101.915 | Q3: 2108.92 | R3: 1789.3354 | S3: 1557.3268 | T3: 1553.4291 | U3: 1551.6869 | V3: 1890.3118 | W3: 1960.3045 | X3: 1562.3305 | Y3: 1283.6743 | Z3: 1022.2938 | AA3: 769.07151 | AB3: 541.09297 | AC3: 351.9231 | AD3: 212.63415 | AE3: 119.7256 | AF3: 64.089205 | AG3: 33.18118 | AH3: 17.296614 | AI3: 8.8445897 | AJ3: 4.4505744 | AK3: 2.2298789 | AL3: 1.1091145 | AM3: 0.55054305 | AN3: 0.27267399 | AO3: 0.13493126 | AP3: 0.066687716 | AQ3: 0.033988446 | AR3: 0.016992987 | AS3: 0.0084524746 | AT3: 0.0041983458 | AU3: 0.0020799867 | AV3: 0.0010179867
A4: NEWAUTO_H01_2 | B4: 2298.598 | C4: 2335.5027 | D4: 2373 | E4: 2446.6776 | F4: 2424.2766 | G4: 2660.3639 | H4: 2598.849 | I4: 2542.8224 | J4: 2194.0679 | K4: 2073.825 | L4: 2079.343 | M4: 1940.387 | N4: 2042.316 | O4: 2141.628 | P4: 2203.742 | Q4: 2240.302 | R4: 1931.7595 | S4: 1714.5029 | T4: 1750.639 | U4: 1797.2181 | V4: 2259.4173 | W4: 2427.3879 | X4: 2046.7784 | Y4: 1858.4215 | Z4: 1751.5496 | AA4: 1664.9555 | AB4: 1603.4575 | AC4: 1560.4548 | AD4: 1539.6953 | AE4: 1524.5802 | AF4: 1514.5177 | AG4: 1505.7427 | AH4: 1537.1869 | AI4: 1555.8116 | AJ4: 1558.1354 | AK4: 1558.1216 | AL4: 1548.9646 | AM4: 1537.8549 | AN4: 1524.0003 | AO4: 1509.2183 | AP4: 1492.88 | AQ4: 1522.8552 | AR4: 1523.9073 | AS4: 1517.2028 | AT4: 1508.3923 | AU4: 1495.8141 | AV4: 1465.3592
A5: PAUTO_ELEC_H01_2 | B5: 32.360331 | C5: 33.007538 | D5: 33.488809 | E5: 33.839494 | F5: 34.293416 | G5: 34.811247 | H5: 34.91417 | I5: 35.171003 | J5: 35.488543 | K5: 35.912137 | L5: 36.504035 | M5: 37.069763 | N5: 37.545288 | O5: 38.395762 | P5: 38.888451 | Q5: 39.418662 | R5: 40.067961 | S5: 40.604049 | T5: 40.697631 | U5: 41.004937 | V5: 41.518786 | W5: 42.087872 | X5: 42.67351 | Y5: 43.233748 | Z5: 43.795672 | AA5: 44.374432 | AB5: 44.97027 | AC5: 45.578587 | AD5: 46.202397 | AE5: 46.846488 | AF5: 47.509486 | AG5: 48.18857 | AH5: 48.881177 | AI5: 49.587501 | AJ5: 50.321883 | AK5: 51.055704 | AL5: 51.816877 | AM5: 52.602307 | AN5: 53.415112 | AO5: 54.246389 | AP5: 55.089331 | AQ5: 55.630793 | AR5: 56.500995 | AS5: 57.387758 | AT5: 58.289707 | AU5: 59.20705 | AV5: 60.141451
A6: PNEWAUTO_TH_H01_2 | B6: 21.704143 | C6: 22.138226 | D6: 22.417243 | E6: 22.83235 | F6: 22.906497 | G6: 23.386835 | H6: 23.514262 | I6: 23.605102 | J6: 23.817102 | K6: 24.147671 | L6: 24.706833 | M6: 25.200848 | N6: 25.668231 | O6: 26.364201 | P6: 26.547282 | Q6: 26.917385 | R6: 26.979834 | S6: 27.33753 | T6: 27.257914 | U6: 27.546784 | V6: 27.982213 | W6: 28.457482 | X6: 28.967953 | Y6: 29.466058 | Z6: 29.957038 | AA6: 30.448734 | AB6: 30.950203 | AC6: 31.476986 | AD6: 32.022718 | AE6: 32.586218 | AF6: 33.165029 | AG6: 33.757751 | AH6: 34.366546 | AI6: 34.986817 | AJ6: 35.631356 | AK6: 36.27383 | AL6: 36.942317 | AM6: 37.618281 | AN6: 38.319985 | AO6: 39.036003 | AP6: 39.762793 | AQ6: 40.268768 | AR6: 41.016494 | AS6: 41.77755 | AT6: 42.552073 | AU6: 43.339953 | AV6: 44.142127
A7: PNEWAUTO_H01_2 | B7: 21.709471 | C7: 22.143661 | D7: 22.427412 | E7: 22.848307 | F7: 22.933329 | G7: 23.426142 | H7: 23.5696 | I7: 23.683093 | J7: 23.92597 | K7: 24.295553 | L7: 24.902687 | M7: 25.458078 | N7: 26.001423 | O7: 26.798664 | P7: 27.117523 | Q7: 27.65052 | R7: 27.944791 | S7: 28.553731 | T7: 28.771901 | U7: 29.385402 | V7: 30.19359 | W7: 31.080272 | X7: 32.211894 | Y7: 33.723941 | Z7: 35.718738 | AA7: 37.941913 | AB7: 40.239144 | AC7: 42.39831 | AD7: 44.244163 | AE7: 45.726626 | AF7: 46.902478 | AG7: 47.870567 | AH7: 48.717856 | AI7: 49.504498 | AJ7: 50.279922 | AK7: 51.034549 | AL7: 51.806226 | AM7: 52.596942 | AN7: 53.412412 | AO7: 54.245029 | AP7: 55.088646 | AQ7: 55.63045 | AR7: 56.500822 | AS7: 57.387671 | AT7: 58.289663 | AU7: 59.207028 | AV7: 60.14144
A8: PCH_2 | B8: 0.96116878 | C8: 0.98039216 | D8: 0.98715712 | E8: 0.99036346 | F8: 1.0043122 | G8: 1.0057988 | H8: 1.0145862 | I8: 1.0232782 | J8: 1.032617 | K8: 1.0399768 | L8: 1.0501176 | M8: 1.0574685 | N8: 1.064722 | O8: 1.0798249 | P8: 1.1017374 | Q8: 1.1217746 | R8: 1.1440126 | S8: 1.1667712 | T8: 1.1905363 | U8: 1.2147495 | V8: 1.240596 | W8: 1.2670456 | X8: 1.2920881 | Y8: 1.3176177 | Z8: 1.344049 | AA8: 1.3724534 | AB8: 1.4017752 | AC8: 1.4309954 | AD8: 1.4602649 | AE8: 1.4900211 | AF8: 1.5204956 | AG8: 1.5513668 | AH8: 1.5828024 | AI8: 1.6148732 | AJ8: 1.6480149 | AK8: 1.6817155 | AL8: 1.7165612 | AM8: 1.7519466 | AN8: 1.7883149 | AO8: 1.8256092 | AP8: 1.8636105 | AQ8: 1.9024049 | AR8: 1.9421462 | AS8: 1.9826509 | AT8: 2.0238124 | AU8: 2.0656553 | AV8: 2.1084356
A9: AUTO_ELEC_H01_2 | B9: 2.3360541 | C9: 2.3735602 | D9: 2.4116685 | E9: 5.8260427 | F9: 11.217949 | G9: 19.754257 | H9: 31.283111 | I9: 46.7093 | J9: 64.606108 | K9: 87.121228 | L9: 116.85027 | M9: 152.4768 | N9: 201.38446 | O9: 268.65003 | P9: 357.04453 | Q9: 470.57431 | R9: 589.46975 | S9: 717.17235 | T9: 874.53933 | U9: 1068.6271 | V9: 1374.8721 | W9: 1761.0806 | X9: 2141.5277 | Y9: 2589.3068 | Z9: 3164.4372 | AA9: 3871.2114 | AB9: 4701.3032 | AC9: 5626.6239 | AD9: 6613.3651 | AE9: 7616.5984 | AF9: 8602.6002 | AG9: 9548.4719 | AH9: 10481.366 | AI9: 11381.335 | AJ9: 12229.565 | AK9: 13024.281 | AL9: 13758.119 | AM9: 14435.54 | AN9: 15057.047 | AO9: 15625.065 | AP9: 16141.312 | AQ9: 16588.045 | AR9: 17006.066 | AS9: 17389.523 | AT9: 17738.609 | AU9: 18051.847 | AV9: 18313.749
A10: AUTO_TH_H01_2 | B10: 30996.094 | C10: 31493.746 | D10: 31999.389 | E10: 32682.553 | F10: 33303.577 | G10: 34123.091 | H10: 34832.554 | I10: 35442.44 | J10: 35666.707 | K10: 35752.795 | L10: 35831.214 | M10: 35758.831 | N10: 35777.117 | O10: 36052.554 | P10: 36351.842 | Q10: 36643.17 | R10: 36600.346 | S10: 36327.656 | T10: 35862.882 | U10: 35304.988 | V10: 35118.535 | W10: 35013.044 | X10: 34507.675 | Y10: 33745.44 | Z10: 32759.076 | AA10: 31570.434 | AB10: 30217.301 | AC10: 28748.905 | AD10: 27222.694 | AE10: 25689.219 | AF10: 24186.893 | AG10: 22739.244 | AH10: 21358.636 | AI10: 20049.046 | AJ10: 18810.787 | AK10: 17642.221 | AL10: 16540.692 | AM10: 15507.449 | AN10: 14538.506 | AO10: 13629.984 | AP10: 12778.177 | AQ10: 11926.333 | AR10: 11131.261 | AS10: 10389.185 | AT10: 9696.577 | AU10: 9050.1406 | AV10: 8446.7989
A11: AUTO_2 | B11: 30998.43 | C11: 31496.12 | D11: 32001.8 | E11: 32688.379 | F11: 33314.795 | G11: 34142.845 | H11: 34863.837 | I11: 35489.149 | J11: 35731.314 | K11: 35839.916 | L11: 35948.064 | M11: 35911.307 | N11: 35978.501 | O11: 36321.204 | P11: 36708.886 | Q11: 37113.744 | R11: 37189.816 | S11: 37044.828 | T11: 36737.421 | U11: 36373.615 | V11: 36493.407 | W11: 36774.124 | X11: 36649.202 | Y11: 36334.746 | Z11: 35923.513 | AA11: 35441.645 | AB11: 34918.604 | AC11: 34375.529 | AD11: 33836.059 | AE11: 33305.818 | AF11: 32789.493 | AG11: 32287.716 | AH11: 31840.002 | AI11: 31430.381 | AJ11: 31040.353 | AK11: 30666.502 | AL11: 30298.81 | AM11: 29942.989 | AN11: 29595.553 | AO11: 29255.049 | AP11: 28919.489 | AQ11: 28514.378 | AR11: 28137.327 | AS11: 27778.708 | AT11: 27435.186 | AU11: 27101.988 | AV11: 26760.548
A12: PENER_AUTOELEC_H01_CA_2 | B12: 0.25383749 | C12: 0.25891424 | D12: 0.25652822 | E12: 0.2632583 | F12: 0.26012564 | G12: 0.26053308 | H12: 0.26147498 | I12: 0.26226138 | J12: 0.26370216 | K12: 0.26522646 | L12: 0.26828614 | M12: 0.27155537 | N12: 0.27593021 | O12: 0.27923703 | P12: 0.28294175 | Q12: 0.28964151 | R12: 0.29904186 | S12: 0.3078615 | T12: 0.31713878 | U12: 0.32535004 | V12: 0.32235119 | W12: 0.3233734 | X12: 0.33727094 | Y12: 0.344107 | Z12: 0.35016654 | AA12: 0.35504499 | AB12: 0.36077188 | AC12: 0.36837437 | AD12: 0.37631434 | AE12: 0.38454192 | AF12: 0.3938538 | AG12: 0.40102935 | AH12: 0.40688144 | AI12: 0.41482027 | AJ12: 0.42288617 | AK12: 0.43119502 | AL12: 0.44099694 | AM12: 0.44933934 | AN12: 0.4578026 | AO12: 0.46640562 | AP12: 0.47511859 | AQ12: 0.48377188 | AR12: 0.49351313 | AS12: 0.50278232 | AT12: 0.51215393 | AU12: 0.52184736 | AV12: 0.5318839
A13: PEXP_AUTO_H01_2 | B13: 0.96116878 | C13: 0.98039216 | D13: 0.98801884 | E13: 0.98669645 | F13: 1.0865767 | G13: 0.92641605 | H13: 1.006402 | I13: 1.1281116 | J13: 1.2272799 | K13: 1.2038813 | L13: 1.1516351 | M13: 1.0086765 | N13: 0.93008066 | O13: 1.0053342 | P13: 1.1682937 | Q13: 1.161239 | R13: 1.198542 | S13: 1.2390652 | T13: 1.2836593 | U13: 1.3328283 | V13: 1.3842822 | W13: 1.4453659 | X13: 1.4687068 | Y13: 1.4889683 | Z13: 1.5086637 | AA13: 1.5627148 | AB13: 1.6179093 | AC13: 1.6455475 | AD13: 1.6701098 | AE13: 1.692461 | AF13: 1.7133838 | AG13: 1.7312629 | AH13: 1.7415335 | AI13: 1.7527316 | AJ13: 1.7645484 | AK13: 1.7765547 | AL13: 1.7903575 | AM13: 1.8221755 | AN13: 1.8547443 | AO13: 1.8871289 | AP13: 1.9183452 | AQ13: 1.9482991 | AR13: 1.9866191 | AS13: 2.0245731 | AT13: 2.062559 | AU13: 2.1008939 | AV13: 2.1397864
... A44: BUIL_H01_CG_2 | B44: 1.8297097e+08 | C44: 1.8590863e+08 | D44: 188893454 | E44: 1.800399e+08 | F44: 1.7103185e+08 | G44: 1.6228071e+08 | H44: 154931207 | I44: 1.4786681e+08 | J44: 1.4048552e+08 | K44: 1.3272979e+08 | L44: 1.2536576e+08 | M44: 1.1900069e+08 | N44: 1.1407377e+08 | O44: 1.0969824e+08 | P44: 1.0510932e+08 | Q44: 99294803 | R44: 93330572 | S44: 87081895 | T44: 81129942 | U44: 75317528 | V44: 69772300 | W44: 64145791 | X44: 58697289 | Y44: 53648745 | Z44: 49072799 | AA44: 44955491 | AB44: 41129231 | AC44: 37522011 | AD44: 34237101 | AE44: 31283742 | AF44: 28626476 | AG44: 26233092 | AH44: 24078571 | AI44: 22136964 | AJ44: 20388007 | AK44: 18798009 | AL44: 17299285 | AM44: 15898777 | AN44: 14618261 | AO44: 13455202 | AP44: 12401609 | AQ44: 11448581 | AR44: 10579145 | AS44: 9763681.3 | AT44: 8993692.7 | AU44: 8267101 | AV44: 7583904.4
A45: BUIL_H01_DES_2 | C45: 2182612 | D45: 2217654.6 | E45: 2253259.7 | F45: 2197348 | G45: 2135517.6 | H45: 2073850.5 | I45: 2025887.2 | J45: 1978454.7 | K45: 1924316.5 | L45: 1863141.2 | M45: 1803611.1 | N45: 1753745.6 | O45: 1720550.5 | P45: 1692851.5 | Q45: 1659938.1 | R45: 1607861.2 | S45: 1600180.9 | T45: 1582221.9 | U45: 1561512.8 | V45: 1535852.1 | W45: 1506701.1 | X45: 1467194 | Y45: 1421395.6 | Z45: 1374795.2 | AA45: 1329979.1 | AB45: 1287891.8 | AC45: 1245826.3 | AD45: 1202264.4 | AE45: 1160042.6 | AF45: 1120276.2 | AG45: 1082779.5 | AH45: 1047494.9 | AI45: 1014630 | AJ45: 983997.17 | AK45: 955475.43 | AL45: 928605.02 | AM45: 901399.43 | AN45: 874136.09 | AO45: 847912.79 | AP45: 822934.91 | AQ45: 799261.63 | AR45: 776929.88 | AS45: 755589.74 | AT45: 734173.89 | AU45: 712429.96 | AV45: 690388.21
A46: REHAB_H01_2 | B46: 27240235 | C46: 27677586 | D46: 28121958 | E46: 39354810 | F46: 45364406 | G46: 45516119 | H46: 35070344 | I46: 35012114 | J46: 39899401 | K46: 46533664 | L46: 46964548 | M46: 41281813 | N46: 28952518 | O46: 30282525 | P46: 37773608 | Q46: 62400636 | R46: 69799680 | S46: 83652349 | T46: 84518164 | U46: 91632163 | V46: 97274360 | W46: 1.1595549e+08 | X46: 1.2880736e+08 | Y46: 1.3565586e+08 | Z46: 137263444 | AA46: 1.3491452e+08 | AB46: 1.3439637e+08 | AC46: 1.3641965e+08 | AD46: 1.3439525e+08 | AE46: 1.3109101e+08 | AF46: 1.2844675e+08 | AG46: 1.2553121e+08 | AH46: 1.2183729e+08 | AI46: 1.1859032e+08 | AJ46: 115620910 | AK46: 1.1330334e+08 | AL46: 1.1467643e+08 | AM46: 1.1486883e+08 | AN46: 1.1328279e+08 | AO46: 111072346 | AP46: 1.086155e+08 | AQ46: 1.0604011e+08 | AR46: 1.0393592e+08 | AS46: 1.0343455e+08 | AT46: 1.0322588e+08 | AU46: 1.0302058e+08 | AV46: 1.0274601e+08
A47: PREHAB_H01_2 | B47: 0.00017092114 | C47: 0.00017433956 | D47: 0.00017633719 | E47: 0.00014003564 | F47: 0.00014683287 | G47: 0.00015141592 | H47: 0.00015511363 | I47: 0.00015050677 | J47: 0.00016363455 | K47: 0.00015928559 | L47: 0.00015397907 | M47: 0.00014433845 | N47: 0.00013845886 | O47: 0.00011055861 | P47: 0.00012352136 | Q47: 0.00011079756 | R47: 0.00013276872 | S47: 0.00011200677 | T47: 0.00013078063 | U47: 0.00012892418 | V47: 0.00012649794 | W47: 0.00010729722 | X47: 0.00011664318 | Y47: 0.0001208241 | Z47: 0.00012165578 | AA47: 0.00012657862 | AB47: 0.00012758377 | AC47: 0.00012573239 | AD47: 0.0001303423 | AE47: 0.00013238169 | AF47: 0.000133139 | AG47: 0.00013659325 | AH47: 0.0001390166 | AI47: 0.00013995737 | AJ47: 0.00014326831 | AK47: 0.00014640662 | AL47: 0.00014567904 | AM47: 0.00015178037 | AN47: 0.00015528484 | AO47: 0.00015900265 | AP47: 0.00016277008 | AQ47: 0.00016679302 | AR47: 0.00017118244 | AS47: 0.00017672661 | AT47: 0.00018248677 | AU47: 0.00018826636 | AV47: 0.00019412583
A48: RENOV_VAL_2 | B48: 4655.932 | C48: 4825.2982 | D48: 4958.9473 | E48: 6685.0332 | F48: 8079.8942 | G48: 8204.6011 | H48: 6325.4515 | I48: 6303.711 | J48: 7395.6572 | K48: 8536.6752 | L48: 8693.9841 | M48: 7712.534 | N48: 5313.4787 | O48: 5170.6902 | P48: 6806.4049 | Q48: 11316.814 | R48: 13348.567 | S48: 15518.483 | T48: 16503.877 | U48: 17459.256 | V48: 18547.27 | W48: 22244.757 | X48: 26036.538 | Y48: 27305.765 | Z48: 27525.502 | AA48: 27251.659 | AB48: 27297.173 | AC48: 28143.158 | AD48: 28368.514 | AE48: 27948.067 | AF48: 27728.363 | AG48: 27559.621 | AH48: 27093.875 | AI48: 26743.452 | AJ48: 26545.082 | AK48: 26411.146 | AL48: 27178.602 | AM48: 27926.444 | AN48: 27930.8 | AO48: 27838.396 | AP48: 27695.138 | AQ48: 27552.999 | AR48: 27553.339 | AS48: 28074.184 | AT48: 28700.476 | AU48: 29337.746 | AV48: 29971.538
A49: SUB_RENOV_VAL_2 | B49: 0 | C49: 0 | D49: 0 | E49: 1173.9571 | F49: 1418.9082 | G49: 1312.7362 | H49: 885.56321 | I49: 778.65691 | J49: 616.14297 | K49: 878.41651 | L49: 1198.0624 | M49: 1550.8859 | N49: 968.05518 | O49: 1025.6624 | P49: 872.60071 | Q49: 1541.5524 | R49: 1535.9671 | S49: 3033.2484 | T49: 2272.6217 | U49: 2404.1796 | V49: 2935.9589 | W49: 4004.0563 | X49: 5728.0383 | Y49: 6007.2684 | Z49: 6055.6104 | AA49: 5995.3651 | AB49: 6005.378 | AC49: 7035.7896 | AD49: 7092.1286 | AE49: 6987.0167 | AF49: 6932.0907 | AG49: 6889.9053 | AH49: 6773.4687 | AI49: 6685.863 | AJ49: 6636.2706 | AK49: 6602.7864 | AL49: 6794.6506 | AM49: 6981.6109 | AN49: 6982.6999 | AO49: 6959.5991 | AP49: 6923.7845 | AQ49: 6888.2498 | AR49: 6888.3348 | AS49: 7018.5461 | AT49: 7175.1191 | AU49: 7334.4365 | AV49: 7492.8846
A50: R_SUB_CEE_H01_CF_CA_2 | B50: 0 | C50: 0 | D50: 0 | E50: 0 | F50: 0 | G50: 0 | H50: 0 | I50: 0.040530719 | J50: 0.033883896 | K50: 0.028830481 | L50: 0.03040774 | M50: 0.02633315 | N50: 0.06336543 | O50: 0.15414461 | P50: 0.18628877 | Q50: 0.25284707 | R50: 0.19068605 | S50: 0.20076736 | T50: 0.19255578 | U50: 0.18565941 | V50: 0.17826369 | W50: 0.26069064 | X50: 0.20294557 | Y50: 0.17974226 | Z50: 0.17333017 | AA50: 0.15334846 | AB50: 0.15184723 | AC50: 0.14053149 | AD50: 0.13250606 | AE50: 0.12906081 | AF50: 0.13325706 | AG50: 0.12783195 | AH50: 0.12486217 | AI50: 0.12937746 | AJ50: 0.12597437 | AK50: 0.12191822 | AL50: 0.13532705 | AM50: 0.12568732 | AN50: 0.1201899 | AO50: 0.11559574 | AP50: 0.11164415 | AQ50: 0.10808261 | AR50: 0.10427048 | AS50: 0.098880879 | AT50: 0.093656982 | AU50: 0.088895718 | AV50: 0.084513513
A51: ER_TERTIARY_2 | B51: 21.072807 | C51: 21.411137 | D51: 21.7549 | E51: 23.111168 | F51: 23.885852 | G51: 23.444481 | H51: 24.603056 | I51: 25.441776 | J51: 25.783656 | K51: 26.232663 | L51: 27.090239 | M51: 28.31981 | N51: 27.949439 | O51: 27.547144 | P51: 26.801156 | Q51: 25.826825 | R51: 25.021981 | S51: 25.034436 | T51: 25.010957 | U51: 25.113654 | V51: 26.519548 | W51: 27.201105 | X51: 27.256033 | Y51: 27.037315 | Z51: 26.611801 | AA51: 25.903202 | AB51: 25.088331 | AC51: 24.859818 | AD51: 24.591356 | AE51: 24.320338 | AF51: 24.020209 | AG51: 23.726902 | AH51: 23.458023 | AI51: 23.189274 | AJ51: 22.92006 | AK51: 22.538032 | AL51: 22.148524 | AM51: 21.891927 | AN51: 21.650225 | AO51: 21.414706 | AP51: 21.186972 | AQ51: 20.966861 | AR51: 20.638076 | AS51: 20.304297 | AT51: 19.974269 | AU51: 19.648139 | AV51: 19.326158
A52: ER_TERTIARY_COAL_2 | B52: 0 | C52: 0 | D52: 0 | E52: 0 | F52: 0 | G52: 0 | H52: 0 | I52: 0 | J52: 0 | K52: 0 | L52: 0 | M52: 0 | N52: 0 | O52: 0 | P52: 0 | Q52: 0 | R52: 0 | S52: 0 | T52: 0 | U52: 0 | V52: 0 | W52: 0 | X52: 0 | Y52: 0 | Z52: 0 | AA52: 0 | AB52: 0 | AC52: 0 | AD52: 0 | AE52: 0 | AF52: 0 | AG52: 0 | AH52: 0 | AI52: 0 | AJ52: 0 | AK52: 0 | AL52: 0 | AM52: 0 | AN52: 0 | AO52: 0 | AP52: 0 | AQ52: 0 | AR52: 0 | AS52: 0 | AT52: 0 | AU52: 0 | AV52: 0
A53: ER_TERTIARY_OIL_2 | B53: 4.6065844 | C53: 4.6805446 | D53: 4.7556923 | E53: 4.8584285 | F53: 4.6740887 | G53: 4.613069 | H53: 4.5416749 | I53: 4.34262 | J53: 4.1268973 | K53: 4.0489182 | L53: 4.0627365 | M53: 4.1781675 | N53: 3.9170705 | O53: 3.6404446 | P53: 3.4042399 | Q53: 3.2198847 | R53: 3.0142307 | S53: 3.0092941 | T53: 3.0128964 | U53: 2.9978702 | V53: 2.5198912 | W53: 2.1738888 | X53: 1.936867 | Y53: 1.745639 | Z53: 1.5888209 | AA53: 1.4767656 | AB53: 1.3827105 | AC53: 1.3700012 | AD53: 1.3645723 | AE53: 1.3597624 | AF53: 1.3594807 | AG53: 1.3579402 | AH53: 1.3526566 | AI53: 1.3475424 | AJ53: 1.3425069 | AK53: 1.3542536 | AL53: 1.3672689 | AM53: 1.3603821 | AN53: 1.351248 | AO53: 1.3411901 | AP53: 1.3299812 | AQ53: 1.3176324 | AR53: 1.3213842 | AS53: 1.3257794 | AT53: 1.329558 | AU53: 1.3327233 | AV53: 1.3352486
A54: ER_TERTIARY_ELEC_2 | B54: 10.826676 | C54: 11.000502 | D54: 11.177119 | E54: 11.887835 | F54: 12.504639 | G54: 11.787154 | H54: 12.310258 | I54: 12.871045 | J54: 13.217653 | K54: 13.280641 | L54: 13.295465 | M54: 13.068313 | N54: 12.451329 | O54: 12.503449 | P54: 12.948172 | Q54: 12.810045 | R54: 12.634897 | S54: 12.736727 | T54: 12.766863 | U54: 12.742245 | V54: 12.828497 | W54: 12.393795 | X54: 11.740228 | Y54: 11.049657 | Z54: 10.375912 | AA54: 9.880389 | AB54: 9.423375 | AC54: 9.3467049 | AD54: 9.287598 | AE54: 9.225843 | AF54: 9.1878654 | AG54: 9.1516324 | AH54: 9.0925071 | AI54: 9.0249027 | AJ54: 8.9559184 | AK54: 8.9942901 | AL54: 9.0334262 | AM54: 8.9550656 | AN54: 8.8645256 | AO54: 8.7684864 | AP54: 8.6647257 | AQ54: 8.5542553 | AR54: 8.542791 | AS54: 8.5374617 | AT54: 8.5284833 | AU54: 8.5146733 | AV54: 8.4956784
